from mcpi.minecraft import Minecraft
mc = Minecraft.create("mc.tokyocodingclub.com")
playerId = mc.getPlayerEntityId("TCCMinecraft008")

pos_x, pos_y, pos_z = mc.entity.getPos(playerId)
block_id = 155

mc.setBlock(pos_x+129, pos_y+0, pos_z+177, block_id)
mc.setBlock(pos_x+128, pos_y+0, pos_z+177, block_id)
mc.setBlock(pos_x+127, pos_y+0, pos_z+177, block_id)
mc.setBlock(pos_x+126, pos_y+0, pos_z+177, block_id)
mc.setBlock(pos_x+125, pos_y+0, pos_z+177, block_id)
mc.setBlock(pos_x+124, pos_y+0, pos_z+177, block_id)
mc.setBlock(pos_x+123, pos_y+0, pos_z+177, block_id)
mc.setBlock(pos_x+122, pos_y+0, pos_z+177, block_id)
mc.setBlock(pos_x+121, pos_y+0, pos_z+177, block_id)
mc.setBlock(pos_x+120, pos_y+0, pos_z+177, block_id)
mc.setBlock(pos_x+119, pos_y+0, pos_z+177, block_id)
mc.setBlock(pos_x+118, pos_y+0, pos_z+177, block_id)
mc.setBlock(pos_x+117, pos_y+0, pos_z+177, block_id)
mc.setBlock(pos_x+80, pos_y+0, pos_z+177, block_id)
mc.setBlock(pos_x+79, pos_y+0, pos_z+177, block_id)
mc.setBlock(pos_x+78, pos_y+0, pos_z+177, block_id)
mc.setBlock(pos_x+77, pos_y+0, pos_z+177, block_id)
mc.setBlock(pos_x+76, pos_y+0, pos_z+177, block_id)
mc.setBlock(pos_x+75, pos_y+0, pos_z+177, block_id)
mc.setBlock(pos_x+74, pos_y+0, pos_z+177, block_id)
mc.setBlock(pos_x+73, pos_y+0, pos_z+177, block_id)
mc.setBlock(pos_x+72, pos_y+0, pos_z+177, block_id)
mc.setBlock(pos_x+71, pos_y+0, pos_z+177, block_id)
mc.setBlock(pos_x+70, pos_y+0, pos_z+177, block_id)
mc.setBlock(pos_x+69, pos_y+0, pos_z+177, block_id)
mc.setBlock(pos_x+68, pos_y+0, pos_z+177, block_id)
mc.setBlock(pos_x+67, pos_y+0, pos_z+177, block_id)
mc.setBlock(pos_x+66, pos_y+0, pos_z+177, block_id)
mc.setBlock(pos_x+65, pos_y+0, pos_z+177, block_id)
mc.setBlock(pos_x+64, pos_y+0, pos_z+177, block_id)
mc.setBlock(pos_x+63, pos_y+0, pos_z+177, block_id)
mc.setBlock(pos_x+62, pos_y+0, pos_z+177, block_id)
mc.setBlock(pos_x+61, pos_y+0, pos_z+177, block_id)
mc.setBlock(pos_x+60, pos_y+0, pos_z+177, block_id)
mc.setBlock(pos_x+147, pos_y+131, pos_z+176, block_id)
mc.setBlock(pos_x+146, pos_y+131, pos_z+176, block_id)
mc.setBlock(pos_x+145, pos_y+131, pos_z+176, block_id)
mc.setBlock(pos_x+144, pos_y+131, pos_z+176, block_id)
mc.setBlock(pos_x+52, pos_y+131, pos_z+176, block_id)
mc.setBlock(pos_x+51, pos_y+131, pos_z+176, block_id)
mc.setBlock(pos_x+50, pos_y+131, pos_z+176, block_id)
mc.setBlock(pos_x+49, pos_y+131, pos_z+176, block_id)
mc.setBlock(pos_x+148, pos_y+130, pos_z+176, block_id)
mc.setBlock(pos_x+130, pos_y+0, pos_z+177, block_id)
mc.setBlock(pos_x+146, pos_y+130, pos_z+176, block_id)
mc.setBlock(pos_x+145, pos_y+130, pos_z+176, block_id)
mc.setBlock(pos_x+144, pos_y+130, pos_z+176, block_id)
mc.setBlock(pos_x+143, pos_y+130, pos_z+176, block_id)
mc.setBlock(pos_x+142, pos_y+130, pos_z+176, block_id)
mc.setBlock(pos_x+54, pos_y+130, pos_z+176, block_id)
mc.setBlock(pos_x+53, pos_y+130, pos_z+176, block_id)
mc.setBlock(pos_x+52, pos_y+130, pos_z+176, block_id)
mc.setBlock(pos_x+51, pos_y+130, pos_z+176, block_id)
mc.setBlock(pos_x+50, pos_y+130, pos_z+176, block_id)
mc.setBlock(pos_x+131, pos_y+0, pos_z+177, block_id)
mc.setBlock(pos_x+48, pos_y+130, pos_z+176, block_id)
mc.setBlock(pos_x+149, pos_y+129, pos_z+176, block_id)
mc.setBlock(pos_x+132, pos_y+0, pos_z+177, block_id)
mc.setBlock(pos_x+133, pos_y+0, pos_z+177, block_id)
mc.setBlock(pos_x+134, pos_y+0, pos_z+177, block_id)
mc.setBlock(pos_x+135, pos_y+0, pos_z+177, block_id)
mc.setBlock(pos_x+136, pos_y+0, pos_z+177, block_id)
mc.setBlock(pos_x+142, pos_y+129, pos_z+176, block_id)
mc.setBlock(pos_x+141, pos_y+129, pos_z+176, block_id)
mc.setBlock(pos_x+140, pos_y+129, pos_z+176, block_id)
mc.setBlock(pos_x+139, pos_y+129, pos_z+176, block_id)
mc.setBlock(pos_x+57, pos_y+129, pos_z+176, block_id)
mc.setBlock(pos_x+56, pos_y+129, pos_z+176, block_id)
mc.setBlock(pos_x+55, pos_y+129, pos_z+176, block_id)
mc.setBlock(pos_x+54, pos_y+129, pos_z+176, block_id)
mc.setBlock(pos_x+60, pos_y+1, pos_z+177, block_id)
mc.setBlock(pos_x+80, pos_y+1, pos_z+177, block_id)
mc.setBlock(pos_x+116, pos_y+1, pos_z+177, block_id)
mc.setBlock(pos_x+136, pos_y+1, pos_z+177, block_id)
mc.setBlock(pos_x+47, pos_y+129, pos_z+176, block_id)
mc.setBlock(pos_x+151, pos_y+128, pos_z+176, block_id)
mc.setBlock(pos_x+150, pos_y+128, pos_z+176, block_id)
mc.setBlock(pos_x+60, pos_y+2, pos_z+177, block_id)
mc.setBlock(pos_x+80, pos_y+2, pos_z+177, block_id)
mc.setBlock(pos_x+141, pos_y+128, pos_z+176, block_id)
mc.setBlock(pos_x+140, pos_y+128, pos_z+176, block_id)
mc.setBlock(pos_x+139, pos_y+128, pos_z+176, block_id)
mc.setBlock(pos_x+138, pos_y+128, pos_z+176, block_id)
mc.setBlock(pos_x+58, pos_y+128, pos_z+176, block_id)
mc.setBlock(pos_x+57, pos_y+128, pos_z+176, block_id)
mc.setBlock(pos_x+56, pos_y+128, pos_z+176, block_id)
mc.setBlock(pos_x+55, pos_y+128, pos_z+176, block_id)
mc.setBlock(pos_x+116, pos_y+2, pos_z+177, block_id)
mc.setBlock(pos_x+136, pos_y+2, pos_z+177, block_id)
mc.setBlock(pos_x+46, pos_y+128, pos_z+176, block_id)
mc.setBlock(pos_x+45, pos_y+128, pos_z+176, block_id)
mc.setBlock(pos_x+152, pos_y+127, pos_z+176, block_id)
mc.setBlock(pos_x+60, pos_y+3, pos_z+177, block_id)
mc.setBlock(pos_x+80, pos_y+3, pos_z+177, block_id)
mc.setBlock(pos_x+116, pos_y+3, pos_z+177, block_id)
mc.setBlock(pos_x+136, pos_y+3, pos_z+177, block_id)
mc.setBlock(pos_x+138, pos_y+127, pos_z+176, block_id)
mc.setBlock(pos_x+137, pos_y+127, pos_z+176, block_id)
mc.setBlock(pos_x+136, pos_y+127, pos_z+176, block_id)
mc.setBlock(pos_x+60, pos_y+127, pos_z+176, block_id)
mc.setBlock(pos_x+59, pos_y+127, pos_z+176, block_id)
mc.setBlock(pos_x+58, pos_y+127, pos_z+176, block_id)
mc.setBlock(pos_x+57, pos_y+127, pos_z+176, block_id)
mc.setBlock(pos_x+60, pos_y+4, pos_z+177, block_id)
mc.setBlock(pos_x+80, pos_y+4, pos_z+177, block_id)
mc.setBlock(pos_x+116, pos_y+4, pos_z+177, block_id)
mc.setBlock(pos_x+44, pos_y+127, pos_z+176, block_id)
mc.setBlock(pos_x+152, pos_y+126, pos_z+176, block_id)
mc.setBlock(pos_x+136, pos_y+4, pos_z+177, block_id)
mc.setBlock(pos_x+60, pos_y+5, pos_z+177, block_id)
mc.setBlock(pos_x+80, pos_y+5, pos_z+177, block_id)
mc.setBlock(pos_x+116, pos_y+5, pos_z+177, block_id)
mc.setBlock(pos_x+136, pos_y+5, pos_z+177, block_id)
mc.setBlock(pos_x+59, pos_y+6, pos_z+177, block_id)
mc.setBlock(pos_x+80, pos_y+6, pos_z+177, block_id)
mc.setBlock(pos_x+116, pos_y+6, pos_z+177, block_id)
mc.setBlock(pos_x+137, pos_y+6, pos_z+177, block_id)
mc.setBlock(pos_x+60, pos_y+7, pos_z+177, block_id)
mc.setBlock(pos_x+136, pos_y+126, pos_z+176, block_id)
mc.setBlock(pos_x+135, pos_y+126, pos_z+176, block_id)
mc.setBlock(pos_x+134, pos_y+126, pos_z+176, block_id)
mc.setBlock(pos_x+62, pos_y+126, pos_z+176, block_id)
mc.setBlock(pos_x+61, pos_y+126, pos_z+176, block_id)
mc.setBlock(pos_x+60, pos_y+126, pos_z+176, block_id)
mc.setBlock(pos_x+79, pos_y+7, pos_z+177, block_id)
mc.setBlock(pos_x+117, pos_y+7, pos_z+177, block_id)
mc.setBlock(pos_x+136, pos_y+7, pos_z+177, block_id)
mc.setBlock(pos_x+61, pos_y+8, pos_z+177, block_id)
mc.setBlock(pos_x+79, pos_y+8, pos_z+177, block_id)
mc.setBlock(pos_x+117, pos_y+8, pos_z+177, block_id)
mc.setBlock(pos_x+135, pos_y+8, pos_z+177, block_id)
mc.setBlock(pos_x+61, pos_y+9, pos_z+177, block_id)
mc.setBlock(pos_x+78, pos_y+9, pos_z+177, block_id)
mc.setBlock(pos_x+44, pos_y+126, pos_z+176, block_id)
mc.setBlock(pos_x+154, pos_y+125, pos_z+176, block_id)
mc.setBlock(pos_x+153, pos_y+125, pos_z+176, block_id)
mc.setBlock(pos_x+152, pos_y+125, pos_z+176, block_id)
mc.setBlock(pos_x+151, pos_y+125, pos_z+176, block_id)
mc.setBlock(pos_x+150, pos_y+125, pos_z+176, block_id)
mc.setBlock(pos_x+149, pos_y+125, pos_z+176, block_id)
mc.setBlock(pos_x+148, pos_y+125, pos_z+176, block_id)
mc.setBlock(pos_x+147, pos_y+125, pos_z+176, block_id)
mc.setBlock(pos_x+146, pos_y+125, pos_z+176, block_id)
mc.setBlock(pos_x+145, pos_y+125, pos_z+176, block_id)
mc.setBlock(pos_x+144, pos_y+125, pos_z+176, block_id)
mc.setBlock(pos_x+118, pos_y+9, pos_z+177, block_id)
mc.setBlock(pos_x+135, pos_y+9, pos_z+177, block_id)
mc.setBlock(pos_x+61, pos_y+10, pos_z+177, block_id)
mc.setBlock(pos_x+134, pos_y+125, pos_z+176, block_id)
mc.setBlock(pos_x+133, pos_y+125, pos_z+176, block_id)
mc.setBlock(pos_x+63, pos_y+125, pos_z+176, block_id)
mc.setBlock(pos_x+62, pos_y+125, pos_z+176, block_id)
mc.setBlock(pos_x+61, pos_y+125, pos_z+176, block_id)
mc.setBlock(pos_x+78, pos_y+10, pos_z+177, block_id)
mc.setBlock(pos_x+118, pos_y+10, pos_z+177, block_id)
mc.setBlock(pos_x+52, pos_y+125, pos_z+176, block_id)
mc.setBlock(pos_x+51, pos_y+125, pos_z+176, block_id)
mc.setBlock(pos_x+50, pos_y+125, pos_z+176, block_id)
mc.setBlock(pos_x+49, pos_y+125, pos_z+176, block_id)
mc.setBlock(pos_x+48, pos_y+125, pos_z+176, block_id)
mc.setBlock(pos_x+47, pos_y+125, pos_z+176, block_id)
mc.setBlock(pos_x+46, pos_y+125, pos_z+176, block_id)
mc.setBlock(pos_x+45, pos_y+125, pos_z+176, block_id)
mc.setBlock(pos_x+44, pos_y+125, pos_z+176, block_id)
mc.setBlock(pos_x+43, pos_y+125, pos_z+176, block_id)
mc.setBlock(pos_x+42, pos_y+125, pos_z+176, block_id)
mc.setBlock(pos_x+150, pos_y+124, pos_z+176, block_id)
mc.setBlock(pos_x+147, pos_y+124, pos_z+176, block_id)
mc.setBlock(pos_x+146, pos_y+124, pos_z+176, block_id)
mc.setBlock(pos_x+145, pos_y+124, pos_z+176, block_id)
mc.setBlock(pos_x+144, pos_y+124, pos_z+176, block_id)
mc.setBlock(pos_x+143, pos_y+124, pos_z+176, block_id)
mc.setBlock(pos_x+135, pos_y+10, pos_z+177, block_id)
mc.setBlock(pos_x+62, pos_y+11, pos_z+177, block_id)
mc.setBlock(pos_x+78, pos_y+11, pos_z+177, block_id)
mc.setBlock(pos_x+133, pos_y+124, pos_z+176, block_id)
mc.setBlock(pos_x+63, pos_y+124, pos_z+176, block_id)
mc.setBlock(pos_x+118, pos_y+11, pos_z+177, block_id)
mc.setBlock(pos_x+134, pos_y+11, pos_z+177, block_id)
mc.setBlock(pos_x+62, pos_y+12, pos_z+177, block_id)
mc.setBlock(pos_x+78, pos_y+12, pos_z+177, block_id)
mc.setBlock(pos_x+53, pos_y+124, pos_z+176, block_id)
mc.setBlock(pos_x+52, pos_y+124, pos_z+176, block_id)
mc.setBlock(pos_x+51, pos_y+124, pos_z+176, block_id)
mc.setBlock(pos_x+50, pos_y+124, pos_z+176, block_id)
mc.setBlock(pos_x+49, pos_y+124, pos_z+176, block_id)
mc.setBlock(pos_x+48, pos_y+124, pos_z+176, block_id)
mc.setBlock(pos_x+46, pos_y+124, pos_z+176, block_id)
mc.setBlock(pos_x+143, pos_y+123, pos_z+176, block_id)
mc.setBlock(pos_x+142, pos_y+123, pos_z+176, block_id)
mc.setBlock(pos_x+141, pos_y+123, pos_z+176, block_id)
mc.setBlock(pos_x+118, pos_y+12, pos_z+177, block_id)
mc.setBlock(pos_x+134, pos_y+12, pos_z+177, block_id)
mc.setBlock(pos_x+63, pos_y+13, pos_z+177, block_id)
mc.setBlock(pos_x+132, pos_y+123, pos_z+176, block_id)
mc.setBlock(pos_x+64, pos_y+123, pos_z+176, block_id)
mc.setBlock(pos_x+78, pos_y+13, pos_z+177, block_id)
mc.setBlock(pos_x+118, pos_y+13, pos_z+177, block_id)
mc.setBlock(pos_x+134, pos_y+13, pos_z+177, block_id)
mc.setBlock(pos_x+55, pos_y+123, pos_z+176, block_id)
mc.setBlock(pos_x+54, pos_y+123, pos_z+176, block_id)
mc.setBlock(pos_x+53, pos_y+123, pos_z+176, block_id)
mc.setBlock(pos_x+142, pos_y+122, pos_z+176, block_id)
mc.setBlock(pos_x+141, pos_y+122, pos_z+176, block_id)
mc.setBlock(pos_x+140, pos_y+122, pos_z+176, block_id)
mc.setBlock(pos_x+139, pos_y+122, pos_z+176, block_id)
mc.setBlock(pos_x+62, pos_y+14, pos_z+177, block_id)
mc.setBlock(pos_x+78, pos_y+14, pos_z+177, block_id)
mc.setBlock(pos_x+132, pos_y+122, pos_z+176, block_id)
mc.setBlock(pos_x+64, pos_y+122, pos_z+176, block_id)
mc.setBlock(pos_x+118, pos_y+14, pos_z+177, block_id)
mc.setBlock(pos_x+134, pos_y+14, pos_z+177, block_id)
mc.setBlock(pos_x+57, pos_y+122, pos_z+176, block_id)
mc.setBlock(pos_x+56, pos_y+122, pos_z+176, block_id)
mc.setBlock(pos_x+55, pos_y+122, pos_z+176, block_id)
mc.setBlock(pos_x+54, pos_y+122, pos_z+176, block_id)
mc.setBlock(pos_x+140, pos_y+121, pos_z+176, block_id)
mc.setBlock(pos_x+139, pos_y+121, pos_z+176, block_id)
mc.setBlock(pos_x+138, pos_y+121, pos_z+176, block_id)
mc.setBlock(pos_x+61, pos_y+15, pos_z+177, block_id)
mc.setBlock(pos_x+79, pos_y+15, pos_z+177, block_id)
mc.setBlock(pos_x+132, pos_y+121, pos_z+176, block_id)
mc.setBlock(pos_x+64, pos_y+121, pos_z+176, block_id)
mc.setBlock(pos_x+98, pos_y+15, pos_z+177, block_id)
mc.setBlock(pos_x+117, pos_y+15, pos_z+177, block_id)
mc.setBlock(pos_x+58, pos_y+121, pos_z+176, block_id)
mc.setBlock(pos_x+57, pos_y+121, pos_z+176, block_id)
mc.setBlock(pos_x+56, pos_y+121, pos_z+176, block_id)
mc.setBlock(pos_x+138, pos_y+120, pos_z+176, block_id)
mc.setBlock(pos_x+137, pos_y+120, pos_z+176, block_id)
mc.setBlock(pos_x+135, pos_y+15, pos_z+177, block_id)
mc.setBlock(pos_x+61, pos_y+16, pos_z+177, block_id)
mc.setBlock(pos_x+79, pos_y+16, pos_z+177, block_id)
mc.setBlock(pos_x+131, pos_y+120, pos_z+176, block_id)
mc.setBlock(pos_x+65, pos_y+120, pos_z+176, block_id)
mc.setBlock(pos_x+94, pos_y+16, pos_z+177, block_id)
mc.setBlock(pos_x+95, pos_y+16, pos_z+177, block_id)
mc.setBlock(pos_x+96, pos_y+16, pos_z+177, block_id)
mc.setBlock(pos_x+59, pos_y+120, pos_z+176, block_id)
mc.setBlock(pos_x+58, pos_y+120, pos_z+176, block_id)
mc.setBlock(pos_x+136, pos_y+119, pos_z+176, block_id)
mc.setBlock(pos_x+135, pos_y+119, pos_z+176, block_id)
mc.setBlock(pos_x+97, pos_y+16, pos_z+177, block_id)
mc.setBlock(pos_x+99, pos_y+16, pos_z+177, block_id)
mc.setBlock(pos_x+131, pos_y+119, pos_z+176, block_id)
mc.setBlock(pos_x+65, pos_y+119, pos_z+176, block_id)
mc.setBlock(pos_x+100, pos_y+16, pos_z+177, block_id)
mc.setBlock(pos_x+101, pos_y+16, pos_z+177, block_id)
mc.setBlock(pos_x+102, pos_y+16, pos_z+177, block_id)
mc.setBlock(pos_x+60, pos_y+119, pos_z+176, block_id)
mc.setBlock(pos_x+135, pos_y+118, pos_z+176, block_id)
mc.setBlock(pos_x+117, pos_y+16, pos_z+177, block_id)
mc.setBlock(pos_x+135, pos_y+16, pos_z+177, block_id)
mc.setBlock(pos_x+131, pos_y+118, pos_z+176, block_id)
mc.setBlock(pos_x+65, pos_y+118, pos_z+176, block_id)
mc.setBlock(pos_x+60, pos_y+17, pos_z+177, block_id)
mc.setBlock(pos_x+80, pos_y+17, pos_z+177, block_id)
mc.setBlock(pos_x+88, pos_y+17, pos_z+177, block_id)
mc.setBlock(pos_x+61, pos_y+118, pos_z+176, block_id)
mc.setBlock(pos_x+134, pos_y+117, pos_z+176, block_id)
mc.setBlock(pos_x+133, pos_y+117, pos_z+176, block_id)
mc.setBlock(pos_x+89, pos_y+17, pos_z+177, block_id)
mc.setBlock(pos_x+90, pos_y+17, pos_z+177, block_id)
mc.setBlock(pos_x+130, pos_y+117, pos_z+176, block_id)
mc.setBlock(pos_x+66, pos_y+117, pos_z+176, block_id)
mc.setBlock(pos_x+91, pos_y+17, pos_z+177, block_id)
mc.setBlock(pos_x+92, pos_y+17, pos_z+177, block_id)
mc.setBlock(pos_x+93, pos_y+17, pos_z+177, block_id)
mc.setBlock(pos_x+62, pos_y+117, pos_z+176, block_id)
mc.setBlock(pos_x+133, pos_y+116, pos_z+176, block_id)
mc.setBlock(pos_x+132, pos_y+116, pos_z+176, block_id)
mc.setBlock(pos_x+103, pos_y+17, pos_z+177, block_id)
mc.setBlock(pos_x+130, pos_y+116, pos_z+176, block_id)
mc.setBlock(pos_x+66, pos_y+116, pos_z+176, block_id)
mc.setBlock(pos_x+104, pos_y+17, pos_z+177, block_id)
mc.setBlock(pos_x+64, pos_y+116, pos_z+176, block_id)
mc.setBlock(pos_x+63, pos_y+116, pos_z+176, block_id)
mc.setBlock(pos_x+132, pos_y+115, pos_z+176, block_id)
mc.setBlock(pos_x+131, pos_y+115, pos_z+176, block_id)
mc.setBlock(pos_x+130, pos_y+115, pos_z+176, block_id)
mc.setBlock(pos_x+66, pos_y+115, pos_z+176, block_id)
mc.setBlock(pos_x+65, pos_y+115, pos_z+176, block_id)
mc.setBlock(pos_x+64, pos_y+115, pos_z+176, block_id)
mc.setBlock(pos_x+131, pos_y+114, pos_z+176, block_id)
mc.setBlock(pos_x+130, pos_y+114, pos_z+176, block_id)
mc.setBlock(pos_x+129, pos_y+114, pos_z+176, block_id)
mc.setBlock(pos_x+67, pos_y+114, pos_z+176, block_id)
mc.setBlock(pos_x+66, pos_y+114, pos_z+176, block_id)
mc.setBlock(pos_x+65, pos_y+114, pos_z+176, block_id)
mc.setBlock(pos_x+129, pos_y+113, pos_z+176, block_id)
mc.setBlock(pos_x+67, pos_y+113, pos_z+176, block_id)
mc.setBlock(pos_x+66, pos_y+113, pos_z+176, block_id)
mc.setBlock(pos_x+99, pos_y+88, pos_z+176, block_id)
mc.setBlock(pos_x+98, pos_y+88, pos_z+176, block_id)
mc.setBlock(pos_x+97, pos_y+88, pos_z+176, block_id)
mc.setBlock(pos_x+136, pos_y+87, pos_z+176, block_id)
mc.setBlock(pos_x+135, pos_y+87, pos_z+176, block_id)
mc.setBlock(pos_x+101, pos_y+87, pos_z+176, block_id)
mc.setBlock(pos_x+100, pos_y+87, pos_z+176, block_id)
mc.setBlock(pos_x+105, pos_y+17, pos_z+177, block_id)
mc.setBlock(pos_x+106, pos_y+17, pos_z+177, block_id)
mc.setBlock(pos_x+107, pos_y+17, pos_z+177, block_id)
mc.setBlock(pos_x+96, pos_y+87, pos_z+176, block_id)
mc.setBlock(pos_x+95, pos_y+87, pos_z+176, block_id)
mc.setBlock(pos_x+61, pos_y+87, pos_z+176, block_id)
mc.setBlock(pos_x+60, pos_y+87, pos_z+176, block_id)
mc.setBlock(pos_x+137, pos_y+86, pos_z+176, block_id)
mc.setBlock(pos_x+108, pos_y+17, pos_z+177, block_id)
mc.setBlock(pos_x+135, pos_y+86, pos_z+176, block_id)
mc.setBlock(pos_x+134, pos_y+86, pos_z+176, block_id)
mc.setBlock(pos_x+103, pos_y+86, pos_z+176, block_id)
mc.setBlock(pos_x+102, pos_y+86, pos_z+176, block_id)
mc.setBlock(pos_x+116, pos_y+17, pos_z+177, block_id)
mc.setBlock(pos_x+136, pos_y+17, pos_z+177, block_id)
mc.setBlock(pos_x+60, pos_y+18, pos_z+177, block_id)
mc.setBlock(pos_x+80, pos_y+18, pos_z+177, block_id)
mc.setBlock(pos_x+94, pos_y+86, pos_z+176, block_id)
mc.setBlock(pos_x+93, pos_y+86, pos_z+176, block_id)
mc.setBlock(pos_x+92, pos_y+86, pos_z+176, block_id)
mc.setBlock(pos_x+62, pos_y+86, pos_z+176, block_id)
mc.setBlock(pos_x+87, pos_y+18, pos_z+177, block_id)
mc.setBlock(pos_x+109, pos_y+18, pos_z+177, block_id)
mc.setBlock(pos_x+59, pos_y+86, pos_z+176, block_id)
mc.setBlock(pos_x+139, pos_y+85, pos_z+176, block_id)
mc.setBlock(pos_x+138, pos_y+85, pos_z+176, block_id)
mc.setBlock(pos_x+116, pos_y+18, pos_z+177, block_id)
mc.setBlock(pos_x+136, pos_y+18, pos_z+177, block_id)
mc.setBlock(pos_x+59, pos_y+19, pos_z+177, block_id)
mc.setBlock(pos_x+133, pos_y+85, pos_z+176, block_id)
mc.setBlock(pos_x+105, pos_y+85, pos_z+176, block_id)
mc.setBlock(pos_x+104, pos_y+85, pos_z+176, block_id)
mc.setBlock(pos_x+81, pos_y+19, pos_z+177, block_id)
mc.setBlock(pos_x+85, pos_y+19, pos_z+177, block_id)
mc.setBlock(pos_x+86, pos_y+19, pos_z+177, block_id)
mc.setBlock(pos_x+92, pos_y+85, pos_z+176, block_id)
mc.setBlock(pos_x+91, pos_y+85, pos_z+176, block_id)
mc.setBlock(pos_x+63, pos_y+85, pos_z+176, block_id)
mc.setBlock(pos_x+110, pos_y+19, pos_z+177, block_id)
mc.setBlock(pos_x+111, pos_y+19, pos_z+177, block_id)
mc.setBlock(pos_x+115, pos_y+19, pos_z+177, block_id)
mc.setBlock(pos_x+58, pos_y+85, pos_z+176, block_id)
mc.setBlock(pos_x+57, pos_y+85, pos_z+176, block_id)
mc.setBlock(pos_x+139, pos_y+84, pos_z+176, block_id)
mc.setBlock(pos_x+137, pos_y+19, pos_z+177, block_id)
mc.setBlock(pos_x+133, pos_y+84, pos_z+176, block_id)
mc.setBlock(pos_x+107, pos_y+84, pos_z+176, block_id)
mc.setBlock(pos_x+106, pos_y+84, pos_z+176, block_id)
mc.setBlock(pos_x+59, pos_y+20, pos_z+177, block_id)
mc.setBlock(pos_x+82, pos_y+20, pos_z+177, block_id)
mc.setBlock(pos_x+84, pos_y+20, pos_z+177, block_id)
mc.setBlock(pos_x+112, pos_y+20, pos_z+177, block_id)
mc.setBlock(pos_x+90, pos_y+84, pos_z+176, block_id)
mc.setBlock(pos_x+89, pos_y+84, pos_z+176, block_id)
mc.setBlock(pos_x+63, pos_y+84, pos_z+176, block_id)
mc.setBlock(pos_x+114, pos_y+20, pos_z+177, block_id)
mc.setBlock(pos_x+57, pos_y+84, pos_z+176, block_id)
mc.setBlock(pos_x+138, pos_y+83, pos_z+176, block_id)
mc.setBlock(pos_x+133, pos_y+83, pos_z+176, block_id)
mc.setBlock(pos_x+107, pos_y+83, pos_z+176, block_id)
mc.setBlock(pos_x+137, pos_y+20, pos_z+177, block_id)
mc.setBlock(pos_x+89, pos_y+83, pos_z+176, block_id)
mc.setBlock(pos_x+63, pos_y+83, pos_z+176, block_id)
mc.setBlock(pos_x+58, pos_y+21, pos_z+177, block_id)
mc.setBlock(pos_x+57, pos_y+83, pos_z+176, block_id)
mc.setBlock(pos_x+145, pos_y+82, pos_z+176, block_id)
mc.setBlock(pos_x+144, pos_y+82, pos_z+176, block_id)
mc.setBlock(pos_x+138, pos_y+82, pos_z+176, block_id)
mc.setBlock(pos_x+133, pos_y+82, pos_z+176, block_id)
mc.setBlock(pos_x+108, pos_y+82, pos_z+176, block_id)
mc.setBlock(pos_x+83, pos_y+21, pos_z+177, block_id)
mc.setBlock(pos_x+88, pos_y+82, pos_z+176, block_id)
mc.setBlock(pos_x+63, pos_y+82, pos_z+176, block_id)
mc.setBlock(pos_x+58, pos_y+82, pos_z+176, block_id)
mc.setBlock(pos_x+52, pos_y+82, pos_z+176, block_id)
mc.setBlock(pos_x+51, pos_y+82, pos_z+176, block_id)
mc.setBlock(pos_x+145, pos_y+81, pos_z+176, block_id)
mc.setBlock(pos_x+113, pos_y+21, pos_z+177, block_id)
mc.setBlock(pos_x+143, pos_y+81, pos_z+176, block_id)
mc.setBlock(pos_x+142, pos_y+81, pos_z+176, block_id)
mc.setBlock(pos_x+141, pos_y+81, pos_z+176, block_id)
mc.setBlock(pos_x+139, pos_y+81, pos_z+176, block_id)
mc.setBlock(pos_x+138, pos_y+21, pos_z+177, block_id)
mc.setBlock(pos_x+58, pos_y+22, pos_z+177, block_id)
mc.setBlock(pos_x+133, pos_y+81, pos_z+176, block_id)
mc.setBlock(pos_x+109, pos_y+81, pos_z+176, block_id)
mc.setBlock(pos_x+138, pos_y+22, pos_z+177, block_id)
mc.setBlock(pos_x+58, pos_y+23, pos_z+177, block_id)
mc.setBlock(pos_x+87, pos_y+81, pos_z+176, block_id)
mc.setBlock(pos_x+63, pos_y+81, pos_z+176, block_id)
mc.setBlock(pos_x+138, pos_y+23, pos_z+177, block_id)
mc.setBlock(pos_x+58, pos_y+24, pos_z+177, block_id)
mc.setBlock(pos_x+57, pos_y+81, pos_z+176, block_id)
mc.setBlock(pos_x+55, pos_y+81, pos_z+176, block_id)
mc.setBlock(pos_x+54, pos_y+81, pos_z+176, block_id)
mc.setBlock(pos_x+53, pos_y+81, pos_z+176, block_id)
mc.setBlock(pos_x+138, pos_y+24, pos_z+177, block_id)
mc.setBlock(pos_x+51, pos_y+81, pos_z+176, block_id)
mc.setBlock(pos_x+145, pos_y+80, pos_z+176, block_id)
mc.setBlock(pos_x+58, pos_y+25, pos_z+177, block_id)
mc.setBlock(pos_x+140, pos_y+80, pos_z+176, block_id)
mc.setBlock(pos_x+138, pos_y+25, pos_z+177, block_id)
mc.setBlock(pos_x+58, pos_y+26, pos_z+177, block_id)
mc.setBlock(pos_x+138, pos_y+26, pos_z+177, block_id)
mc.setBlock(pos_x+59, pos_y+27, pos_z+177, block_id)
mc.setBlock(pos_x+132, pos_y+80, pos_z+176, block_id)
mc.setBlock(pos_x+129, pos_y+80, pos_z+176, block_id)
mc.setBlock(pos_x+113, pos_y+80, pos_z+176, block_id)
mc.setBlock(pos_x+112, pos_y+80, pos_z+176, block_id)
mc.setBlock(pos_x+110, pos_y+80, pos_z+176, block_id)
mc.setBlock(pos_x+137, pos_y+27, pos_z+177, block_id)
mc.setBlock(pos_x+59, pos_y+28, pos_z+177, block_id)
mc.setBlock(pos_x+86, pos_y+80, pos_z+176, block_id)
mc.setBlock(pos_x+84, pos_y+80, pos_z+176, block_id)
mc.setBlock(pos_x+83, pos_y+80, pos_z+176, block_id)
mc.setBlock(pos_x+64, pos_y+80, pos_z+176, block_id)
mc.setBlock(pos_x+137, pos_y+28, pos_z+177, block_id)
mc.setBlock(pos_x+59, pos_y+29, pos_z+177, block_id)
mc.setBlock(pos_x+137, pos_y+29, pos_z+177, block_id)
mc.setBlock(pos_x+59, pos_y+30, pos_z+177, block_id)
mc.setBlock(pos_x+56, pos_y+80, pos_z+176, block_id)
mc.setBlock(pos_x+137, pos_y+30, pos_z+177, block_id)
mc.setBlock(pos_x+51, pos_y+80, pos_z+176, block_id)
mc.setBlock(pos_x+145, pos_y+79, pos_z+176, block_id)
mc.setBlock(pos_x+59, pos_y+31, pos_z+177, block_id)
mc.setBlock(pos_x+137, pos_y+31, pos_z+177, block_id)
mc.setBlock(pos_x+60, pos_y+32, pos_z+177, block_id)
mc.setBlock(pos_x+136, pos_y+32, pos_z+177, block_id)
mc.setBlock(pos_x+60, pos_y+33, pos_z+177, block_id)
mc.setBlock(pos_x+131, pos_y+79, pos_z+176, block_id)
mc.setBlock(pos_x+130, pos_y+79, pos_z+176, block_id)
mc.setBlock(pos_x+136, pos_y+33, pos_z+177, block_id)
mc.setBlock(pos_x+128, pos_y+79, pos_z+176, block_id)
mc.setBlock(pos_x+127, pos_y+79, pos_z+176, block_id)
mc.setBlock(pos_x+126, pos_y+79, pos_z+176, block_id)
mc.setBlock(pos_x+115, pos_y+79, pos_z+176, block_id)
mc.setBlock(pos_x+114, pos_y+79, pos_z+176, block_id)
mc.setBlock(pos_x+60, pos_y+34, pos_z+177, block_id)
mc.setBlock(pos_x+136, pos_y+34, pos_z+177, block_id)
mc.setBlock(pos_x+111, pos_y+79, pos_z+176, block_id)
mc.setBlock(pos_x+61, pos_y+35, pos_z+177, block_id)
mc.setBlock(pos_x+135, pos_y+35, pos_z+177, block_id)
mc.setBlock(pos_x+85, pos_y+79, pos_z+176, block_id)
mc.setBlock(pos_x+61, pos_y+36, pos_z+177, block_id)
mc.setBlock(pos_x+135, pos_y+36, pos_z+177, block_id)
mc.setBlock(pos_x+82, pos_y+79, pos_z+176, block_id)
mc.setBlock(pos_x+81, pos_y+79, pos_z+176, block_id)
mc.setBlock(pos_x+70, pos_y+79, pos_z+176, block_id)
mc.setBlock(pos_x+69, pos_y+79, pos_z+176, block_id)
mc.setBlock(pos_x+68, pos_y+79, pos_z+176, block_id)
mc.setBlock(pos_x+67, pos_y+79, pos_z+176, block_id)
mc.setBlock(pos_x+66, pos_y+79, pos_z+176, block_id)
mc.setBlock(pos_x+65, pos_y+79, pos_z+176, block_id)
mc.setBlock(pos_x+62, pos_y+37, pos_z+177, block_id)
mc.setBlock(pos_x+134, pos_y+37, pos_z+177, block_id)
mc.setBlock(pos_x+63, pos_y+38, pos_z+177, block_id)
mc.setBlock(pos_x+133, pos_y+38, pos_z+177, block_id)
mc.setBlock(pos_x+51, pos_y+79, pos_z+176, block_id)
mc.setBlock(pos_x+145, pos_y+78, pos_z+176, block_id)
mc.setBlock(pos_x+63, pos_y+39, pos_z+177, block_id)
mc.setBlock(pos_x+133, pos_y+39, pos_z+177, block_id)
mc.setBlock(pos_x+64, pos_y+40, pos_z+177, block_id)
mc.setBlock(pos_x+135, pos_y+78, pos_z+176, block_id)
mc.setBlock(pos_x+132, pos_y+40, pos_z+177, block_id)
mc.setBlock(pos_x+65, pos_y+41, pos_z+177, block_id)
mc.setBlock(pos_x+131, pos_y+41, pos_z+177, block_id)
mc.setBlock(pos_x+66, pos_y+42, pos_z+177, block_id)
mc.setBlock(pos_x+130, pos_y+42, pos_z+177, block_id)
mc.setBlock(pos_x+125, pos_y+78, pos_z+176, block_id)
mc.setBlock(pos_x+117, pos_y+78, pos_z+176, block_id)
mc.setBlock(pos_x+116, pos_y+78, pos_z+176, block_id)
mc.setBlock(pos_x+67, pos_y+43, pos_z+177, block_id)
mc.setBlock(pos_x+68, pos_y+43, pos_z+177, block_id)
mc.setBlock(pos_x+80, pos_y+78, pos_z+176, block_id)
mc.setBlock(pos_x+79, pos_y+78, pos_z+176, block_id)
mc.setBlock(pos_x+71, pos_y+78, pos_z+176, block_id)
mc.setBlock(pos_x+69, pos_y+43, pos_z+177, block_id)
mc.setBlock(pos_x+127, pos_y+43, pos_z+177, block_id)
mc.setBlock(pos_x+128, pos_y+43, pos_z+177, block_id)
mc.setBlock(pos_x+129, pos_y+43, pos_z+177, block_id)
mc.setBlock(pos_x+70, pos_y+44, pos_z+177, block_id)
mc.setBlock(pos_x+71, pos_y+44, pos_z+177, block_id)
mc.setBlock(pos_x+125, pos_y+44, pos_z+177, block_id)
mc.setBlock(pos_x+126, pos_y+44, pos_z+177, block_id)
mc.setBlock(pos_x+51, pos_y+78, pos_z+176, block_id)
mc.setBlock(pos_x+144, pos_y+77, pos_z+176, block_id)
mc.setBlock(pos_x+72, pos_y+45, pos_z+177, block_id)
mc.setBlock(pos_x+73, pos_y+45, pos_z+177, block_id)
mc.setBlock(pos_x+123, pos_y+45, pos_z+177, block_id)
mc.setBlock(pos_x+124, pos_y+45, pos_z+177, block_id)
mc.setBlock(pos_x+74, pos_y+46, pos_z+177, block_id)
mc.setBlock(pos_x+125, pos_y+77, pos_z+176, block_id)
mc.setBlock(pos_x+118, pos_y+77, pos_z+176, block_id)
mc.setBlock(pos_x+122, pos_y+46, pos_z+177, block_id)
mc.setBlock(pos_x+74, pos_y+47, pos_z+177, block_id)
mc.setBlock(pos_x+78, pos_y+77, pos_z+176, block_id)
mc.setBlock(pos_x+71, pos_y+77, pos_z+176, block_id)
mc.setBlock(pos_x+122, pos_y+47, pos_z+177, block_id)
mc.setBlock(pos_x+74, pos_y+48, pos_z+177, block_id)
mc.setBlock(pos_x+122, pos_y+48, pos_z+177, block_id)
mc.setBlock(pos_x+75, pos_y+49, pos_z+177, block_id)
mc.setBlock(pos_x+121, pos_y+49, pos_z+177, block_id)
mc.setBlock(pos_x+52, pos_y+77, pos_z+176, block_id)
mc.setBlock(pos_x+143, pos_y+76, pos_z+176, block_id)
mc.setBlock(pos_x+75, pos_y+50, pos_z+177, block_id)
mc.setBlock(pos_x+121, pos_y+50, pos_z+177, block_id)
mc.setBlock(pos_x+125, pos_y+76, pos_z+176, block_id)
mc.setBlock(pos_x+118, pos_y+76, pos_z+176, block_id)
mc.setBlock(pos_x+78, pos_y+76, pos_z+176, block_id)
mc.setBlock(pos_x+71, pos_y+76, pos_z+176, block_id)
mc.setBlock(pos_x+75, pos_y+51, pos_z+177, block_id)
mc.setBlock(pos_x+121, pos_y+51, pos_z+177, block_id)
mc.setBlock(pos_x+53, pos_y+76, pos_z+176, block_id)
mc.setBlock(pos_x+143, pos_y+75, pos_z+176, block_id)
mc.setBlock(pos_x+75, pos_y+52, pos_z+177, block_id)
mc.setBlock(pos_x+121, pos_y+52, pos_z+177, block_id)
mc.setBlock(pos_x+75, pos_y+53, pos_z+177, block_id)
mc.setBlock(pos_x+121, pos_y+53, pos_z+177, block_id)
mc.setBlock(pos_x+126, pos_y+75, pos_z+176, block_id)
mc.setBlock(pos_x+119, pos_y+75, pos_z+176, block_id)
mc.setBlock(pos_x+75, pos_y+54, pos_z+177, block_id)
mc.setBlock(pos_x+121, pos_y+54, pos_z+177, block_id)
mc.setBlock(pos_x+77, pos_y+75, pos_z+176, block_id)
mc.setBlock(pos_x+70, pos_y+75, pos_z+176, block_id)
mc.setBlock(pos_x+75, pos_y+55, pos_z+177, block_id)
mc.setBlock(pos_x+121, pos_y+55, pos_z+177, block_id)
mc.setBlock(pos_x+76, pos_y+56, pos_z+177, block_id)
mc.setBlock(pos_x+120, pos_y+56, pos_z+177, block_id)
mc.setBlock(pos_x+53, pos_y+75, pos_z+176, block_id)
mc.setBlock(pos_x+142, pos_y+74, pos_z+176, block_id)
mc.setBlock(pos_x+76, pos_y+57, pos_z+177, block_id)
mc.setBlock(pos_x+120, pos_y+57, pos_z+177, block_id)
mc.setBlock(pos_x+134, pos_y+74, pos_z+176, block_id)
mc.setBlock(pos_x+77, pos_y+58, pos_z+177, block_id)
mc.setBlock(pos_x+119, pos_y+58, pos_z+177, block_id)
mc.setBlock(pos_x+127, pos_y+74, pos_z+176, block_id)
mc.setBlock(pos_x+119, pos_y+74, pos_z+176, block_id)
mc.setBlock(pos_x+77, pos_y+74, pos_z+176, block_id)
mc.setBlock(pos_x+69, pos_y+74, pos_z+176, block_id)
mc.setBlock(pos_x+77, pos_y+59, pos_z+177, block_id)
mc.setBlock(pos_x+119, pos_y+59, pos_z+177, block_id)
mc.setBlock(pos_x+77, pos_y+60, pos_z+177, block_id)
mc.setBlock(pos_x+119, pos_y+60, pos_z+177, block_id)
mc.setBlock(pos_x+78, pos_y+61, pos_z+177, block_id)
mc.setBlock(pos_x+54, pos_y+74, pos_z+176, block_id)
mc.setBlock(pos_x+141, pos_y+73, pos_z+176, block_id)
mc.setBlock(pos_x+118, pos_y+61, pos_z+177, block_id)
mc.setBlock(pos_x+78, pos_y+62, pos_z+177, block_id)
mc.setBlock(pos_x+134, pos_y+73, pos_z+176, block_id)
mc.setBlock(pos_x+118, pos_y+62, pos_z+177, block_id)
mc.setBlock(pos_x+76, pos_y+63, pos_z+177, block_id)
mc.setBlock(pos_x+77, pos_y+63, pos_z+177, block_id)
mc.setBlock(pos_x+128, pos_y+73, pos_z+176, block_id)
mc.setBlock(pos_x+120, pos_y+73, pos_z+176, block_id)
mc.setBlock(pos_x+79, pos_y+63, pos_z+177, block_id)
mc.setBlock(pos_x+117, pos_y+63, pos_z+177, block_id)
mc.setBlock(pos_x+76, pos_y+73, pos_z+176, block_id)
mc.setBlock(pos_x+68, pos_y+73, pos_z+176, block_id)
mc.setBlock(pos_x+119, pos_y+63, pos_z+177, block_id)
mc.setBlock(pos_x+120, pos_y+63, pos_z+177, block_id)
mc.setBlock(pos_x+75, pos_y+64, pos_z+177, block_id)
mc.setBlock(pos_x+62, pos_y+73, pos_z+176, block_id)
mc.setBlock(pos_x+76, pos_y+64, pos_z+177, block_id)
mc.setBlock(pos_x+78, pos_y+64, pos_z+177, block_id)
mc.setBlock(pos_x+55, pos_y+73, pos_z+176, block_id)
mc.setBlock(pos_x+140, pos_y+72, pos_z+176, block_id)
mc.setBlock(pos_x+118, pos_y+64, pos_z+177, block_id)
mc.setBlock(pos_x+120, pos_y+64, pos_z+177, block_id)
mc.setBlock(pos_x+121, pos_y+64, pos_z+177, block_id)
mc.setBlock(pos_x+75, pos_y+65, pos_z+177, block_id)
mc.setBlock(pos_x+121, pos_y+65, pos_z+177, block_id)
mc.setBlock(pos_x+134, pos_y+72, pos_z+176, block_id)
mc.setBlock(pos_x+133, pos_y+72, pos_z+176, block_id)
mc.setBlock(pos_x+122, pos_y+65, pos_z+177, block_id)
mc.setBlock(pos_x+74, pos_y+66, pos_z+177, block_id)
mc.setBlock(pos_x+129, pos_y+72, pos_z+176, block_id)
mc.setBlock(pos_x+121, pos_y+72, pos_z+176, block_id)
mc.setBlock(pos_x+75, pos_y+66, pos_z+177, block_id)
mc.setBlock(pos_x+122, pos_y+66, pos_z+177, block_id)
mc.setBlock(pos_x+75, pos_y+72, pos_z+176, block_id)
mc.setBlock(pos_x+67, pos_y+72, pos_z+176, block_id)
mc.setBlock(pos_x+74, pos_y+67, pos_z+177, block_id)
mc.setBlock(pos_x+122, pos_y+67, pos_z+177, block_id)
mc.setBlock(pos_x+73, pos_y+68, pos_z+177, block_id)
mc.setBlock(pos_x+63, pos_y+72, pos_z+176, block_id)
mc.setBlock(pos_x+62, pos_y+72, pos_z+176, block_id)
mc.setBlock(pos_x+74, pos_y+68, pos_z+177, block_id)
mc.setBlock(pos_x+122, pos_y+68, pos_z+177, block_id)
mc.setBlock(pos_x+123, pos_y+68, pos_z+177, block_id)
mc.setBlock(pos_x+73, pos_y+69, pos_z+177, block_id)
mc.setBlock(pos_x+57, pos_y+72, pos_z+176, block_id)
mc.setBlock(pos_x+56, pos_y+72, pos_z+176, block_id)
mc.setBlock(pos_x+139, pos_y+71, pos_z+176, block_id)
mc.setBlock(pos_x+138, pos_y+71, pos_z+176, block_id)
mc.setBlock(pos_x+137, pos_y+71, pos_z+176, block_id)
mc.setBlock(pos_x+136, pos_y+71, pos_z+176, block_id)
mc.setBlock(pos_x+135, pos_y+71, pos_z+176, block_id)
mc.setBlock(pos_x+134, pos_y+71, pos_z+176, block_id)
mc.setBlock(pos_x+133, pos_y+71, pos_z+176, block_id)
mc.setBlock(pos_x+132, pos_y+71, pos_z+176, block_id)
mc.setBlock(pos_x+131, pos_y+71, pos_z+176, block_id)
mc.setBlock(pos_x+130, pos_y+71, pos_z+176, block_id)
mc.setBlock(pos_x+122, pos_y+71, pos_z+176, block_id)
mc.setBlock(pos_x+123, pos_y+69, pos_z+177, block_id)
mc.setBlock(pos_x+74, pos_y+70, pos_z+177, block_id)
mc.setBlock(pos_x+74, pos_y+71, pos_z+176, block_id)
mc.setBlock(pos_x+66, pos_y+71, pos_z+176, block_id)
mc.setBlock(pos_x+65, pos_y+71, pos_z+176, block_id)
mc.setBlock(pos_x+64, pos_y+71, pos_z+176, block_id)
mc.setBlock(pos_x+63, pos_y+71, pos_z+176, block_id)
mc.setBlock(pos_x+62, pos_y+71, pos_z+176, block_id)
mc.setBlock(pos_x+61, pos_y+71, pos_z+176, block_id)
mc.setBlock(pos_x+60, pos_y+71, pos_z+176, block_id)
mc.setBlock(pos_x+59, pos_y+71, pos_z+176, block_id)
mc.setBlock(pos_x+58, pos_y+71, pos_z+176, block_id)
mc.setBlock(pos_x+122, pos_y+70, pos_z+176, block_id)
mc.setBlock(pos_x+74, pos_y+70, pos_z+176, block_id)
mc.setBlock(pos_x+123, pos_y+69, pos_z+176, block_id)
mc.setBlock(pos_x+73, pos_y+69, pos_z+176, block_id)
mc.setBlock(pos_x+124, pos_y+68, pos_z+176, block_id)
mc.setBlock(pos_x+122, pos_y+70, pos_z+177, block_id)
mc.setBlock(pos_x+65, pos_y+71, pos_z+177, block_id)
mc.setBlock(pos_x+72, pos_y+68, pos_z+176, block_id)
mc.setBlock(pos_x+124, pos_y+67, pos_z+176, block_id)
mc.setBlock(pos_x+123, pos_y+67, pos_z+176, block_id)
mc.setBlock(pos_x+73, pos_y+67, pos_z+176, block_id)
mc.setBlock(pos_x+72, pos_y+67, pos_z+176, block_id)
mc.setBlock(pos_x+124, pos_y+66, pos_z+176, block_id)
mc.setBlock(pos_x+123, pos_y+66, pos_z+176, block_id)
mc.setBlock(pos_x+75, pos_y+71, pos_z+177, block_id)
mc.setBlock(pos_x+121, pos_y+71, pos_z+177, block_id)
mc.setBlock(pos_x+73, pos_y+66, pos_z+176, block_id)
mc.setBlock(pos_x+72, pos_y+66, pos_z+176, block_id)
mc.setBlock(pos_x+123, pos_y+65, pos_z+176, block_id)
mc.setBlock(pos_x+57, pos_y+72, pos_z+177, block_id)
mc.setBlock(pos_x+58, pos_y+72, pos_z+177, block_id)
mc.setBlock(pos_x+74, pos_y+65, pos_z+176, block_id)
mc.setBlock(pos_x+73, pos_y+65, pos_z+176, block_id)
mc.setBlock(pos_x+123, pos_y+64, pos_z+176, block_id)
mc.setBlock(pos_x+122, pos_y+64, pos_z+176, block_id)
mc.setBlock(pos_x+59, pos_y+72, pos_z+177, block_id)
mc.setBlock(pos_x+60, pos_y+72, pos_z+177, block_id)
mc.setBlock(pos_x+118, pos_y+64, pos_z+176, block_id)
mc.setBlock(pos_x+61, pos_y+72, pos_z+177, block_id)
mc.setBlock(pos_x+64, pos_y+72, pos_z+177, block_id)
mc.setBlock(pos_x+78, pos_y+64, pos_z+176, block_id)
mc.setBlock(pos_x+66, pos_y+72, pos_z+177, block_id)
mc.setBlock(pos_x+75, pos_y+72, pos_z+177, block_id)
mc.setBlock(pos_x+74, pos_y+64, pos_z+176, block_id)
mc.setBlock(pos_x+122, pos_y+63, pos_z+176, block_id)
mc.setBlock(pos_x+121, pos_y+63, pos_z+176, block_id)
mc.setBlock(pos_x+120, pos_y+63, pos_z+176, block_id)
mc.setBlock(pos_x+119, pos_y+63, pos_z+176, block_id)
mc.setBlock(pos_x+117, pos_y+63, pos_z+176, block_id)
mc.setBlock(pos_x+79, pos_y+63, pos_z+176, block_id)
mc.setBlock(pos_x+77, pos_y+63, pos_z+176, block_id)
mc.setBlock(pos_x+121, pos_y+72, pos_z+177, block_id)
mc.setBlock(pos_x+75, pos_y+63, pos_z+176, block_id)
mc.setBlock(pos_x+74, pos_y+63, pos_z+176, block_id)
mc.setBlock(pos_x+121, pos_y+62, pos_z+176, block_id)
mc.setBlock(pos_x+118, pos_y+62, pos_z+176, block_id)
mc.setBlock(pos_x+130, pos_y+72, pos_z+177, block_id)
mc.setBlock(pos_x+131, pos_y+72, pos_z+177, block_id)
mc.setBlock(pos_x+78, pos_y+62, pos_z+176, block_id)
mc.setBlock(pos_x+76, pos_y+62, pos_z+176, block_id)
mc.setBlock(pos_x+75, pos_y+62, pos_z+176, block_id)
mc.setBlock(pos_x+118, pos_y+61, pos_z+176, block_id)
mc.setBlock(pos_x+78, pos_y+61, pos_z+176, block_id)
mc.setBlock(pos_x+119, pos_y+60, pos_z+176, block_id)
mc.setBlock(pos_x+132, pos_y+72, pos_z+177, block_id)
mc.setBlock(pos_x+135, pos_y+72, pos_z+177, block_id)
mc.setBlock(pos_x+77, pos_y+60, pos_z+176, block_id)
mc.setBlock(pos_x+119, pos_y+59, pos_z+176, block_id)
mc.setBlock(pos_x+77, pos_y+59, pos_z+176, block_id)
mc.setBlock(pos_x+120, pos_y+58, pos_z+176, block_id)
mc.setBlock(pos_x+136, pos_y+72, pos_z+177, block_id)
mc.setBlock(pos_x+137, pos_y+72, pos_z+177, block_id)
mc.setBlock(pos_x+76, pos_y+58, pos_z+176, block_id)
mc.setBlock(pos_x+120, pos_y+57, pos_z+176, block_id)
mc.setBlock(pos_x+76, pos_y+57, pos_z+176, block_id)
mc.setBlock(pos_x+120, pos_y+56, pos_z+176, block_id)
mc.setBlock(pos_x+76, pos_y+56, pos_z+176, block_id)
mc.setBlock(pos_x+120, pos_y+55, pos_z+176, block_id)
mc.setBlock(pos_x+76, pos_y+55, pos_z+176, block_id)
mc.setBlock(pos_x+121, pos_y+54, pos_z+176, block_id)
mc.setBlock(pos_x+75, pos_y+54, pos_z+176, block_id)
mc.setBlock(pos_x+121, pos_y+53, pos_z+176, block_id)
mc.setBlock(pos_x+75, pos_y+53, pos_z+176, block_id)
mc.setBlock(pos_x+121, pos_y+52, pos_z+176, block_id)
mc.setBlock(pos_x+75, pos_y+52, pos_z+176, block_id)
mc.setBlock(pos_x+121, pos_y+51, pos_z+176, block_id)
mc.setBlock(pos_x+75, pos_y+51, pos_z+176, block_id)
mc.setBlock(pos_x+122, pos_y+50, pos_z+176, block_id)
mc.setBlock(pos_x+138, pos_y+72, pos_z+177, block_id)
mc.setBlock(pos_x+139, pos_y+72, pos_z+177, block_id)
mc.setBlock(pos_x+74, pos_y+50, pos_z+176, block_id)
mc.setBlock(pos_x+122, pos_y+49, pos_z+176, block_id)
mc.setBlock(pos_x+56, pos_y+73, pos_z+177, block_id)
mc.setBlock(pos_x+59, pos_y+73, pos_z+177, block_id)
mc.setBlock(pos_x+74, pos_y+49, pos_z+176, block_id)
mc.setBlock(pos_x+122, pos_y+48, pos_z+176, block_id)
mc.setBlock(pos_x+74, pos_y+48, pos_z+176, block_id)
mc.setBlock(pos_x+122, pos_y+47, pos_z+176, block_id)
mc.setBlock(pos_x+74, pos_y+47, pos_z+176, block_id)
mc.setBlock(pos_x+122, pos_y+46, pos_z+176, block_id)
mc.setBlock(pos_x+74, pos_y+46, pos_z+176, block_id)
mc.setBlock(pos_x+124, pos_y+45, pos_z+176, block_id)
mc.setBlock(pos_x+123, pos_y+45, pos_z+176, block_id)
mc.setBlock(pos_x+60, pos_y+73, pos_z+177, block_id)
mc.setBlock(pos_x+61, pos_y+73, pos_z+177, block_id)
mc.setBlock(pos_x+73, pos_y+45, pos_z+176, block_id)
mc.setBlock(pos_x+72, pos_y+45, pos_z+176, block_id)
mc.setBlock(pos_x+127, pos_y+44, pos_z+176, block_id)
mc.setBlock(pos_x+126, pos_y+44, pos_z+176, block_id)
mc.setBlock(pos_x+125, pos_y+44, pos_z+176, block_id)
mc.setBlock(pos_x+63, pos_y+73, pos_z+177, block_id)
mc.setBlock(pos_x+67, pos_y+73, pos_z+177, block_id)
mc.setBlock(pos_x+71, pos_y+44, pos_z+176, block_id)
mc.setBlock(pos_x+70, pos_y+44, pos_z+176, block_id)
mc.setBlock(pos_x+69, pos_y+44, pos_z+176, block_id)
mc.setBlock(pos_x+129, pos_y+43, pos_z+176, block_id)
mc.setBlock(pos_x+128, pos_y+43, pos_z+176, block_id)
mc.setBlock(pos_x+68, pos_y+73, pos_z+177, block_id)
mc.setBlock(pos_x+76, pos_y+73, pos_z+177, block_id)
mc.setBlock(pos_x+68, pos_y+43, pos_z+176, block_id)
mc.setBlock(pos_x+67, pos_y+43, pos_z+176, block_id)
mc.setBlock(pos_x+130, pos_y+42, pos_z+176, block_id)
mc.setBlock(pos_x+120, pos_y+73, pos_z+177, block_id)
mc.setBlock(pos_x+128, pos_y+73, pos_z+177, block_id)
mc.setBlock(pos_x+66, pos_y+42, pos_z+176, block_id)
mc.setBlock(pos_x+131, pos_y+41, pos_z+176, block_id)
mc.setBlock(pos_x+129, pos_y+73, pos_z+177, block_id)
mc.setBlock(pos_x+133, pos_y+73, pos_z+177, block_id)
mc.setBlock(pos_x+65, pos_y+41, pos_z+176, block_id)
mc.setBlock(pos_x+132, pos_y+40, pos_z+176, block_id)
mc.setBlock(pos_x+135, pos_y+73, pos_z+177, block_id)
mc.setBlock(pos_x+136, pos_y+73, pos_z+177, block_id)
mc.setBlock(pos_x+64, pos_y+40, pos_z+176, block_id)
mc.setBlock(pos_x+133, pos_y+39, pos_z+176, block_id)
mc.setBlock(pos_x+137, pos_y+73, pos_z+177, block_id)
mc.setBlock(pos_x+140, pos_y+73, pos_z+177, block_id)
mc.setBlock(pos_x+63, pos_y+39, pos_z+176, block_id)
mc.setBlock(pos_x+134, pos_y+38, pos_z+176, block_id)
mc.setBlock(pos_x+55, pos_y+74, pos_z+177, block_id)
mc.setBlock(pos_x+59, pos_y+74, pos_z+177, block_id)
mc.setBlock(pos_x+62, pos_y+38, pos_z+176, block_id)
mc.setBlock(pos_x+134, pos_y+37, pos_z+176, block_id)
mc.setBlock(pos_x+62, pos_y+37, pos_z+176, block_id)
mc.setBlock(pos_x+135, pos_y+36, pos_z+176, block_id)
mc.setBlock(pos_x+60, pos_y+74, pos_z+177, block_id)
mc.setBlock(pos_x+61, pos_y+74, pos_z+177, block_id)
mc.setBlock(pos_x+61, pos_y+36, pos_z+176, block_id)
mc.setBlock(pos_x+135, pos_y+35, pos_z+176, block_id)
mc.setBlock(pos_x+61, pos_y+35, pos_z+176, block_id)
mc.setBlock(pos_x+136, pos_y+34, pos_z+176, block_id)
mc.setBlock(pos_x+62, pos_y+74, pos_z+177, block_id)
mc.setBlock(pos_x+61, pos_y+34, pos_z+176, block_id)
mc.setBlock(pos_x+136, pos_y+33, pos_z+176, block_id)
mc.setBlock(pos_x+63, pos_y+74, pos_z+177, block_id)
mc.setBlock(pos_x+60, pos_y+33, pos_z+176, block_id)
mc.setBlock(pos_x+136, pos_y+32, pos_z+176, block_id)
mc.setBlock(pos_x+60, pos_y+32, pos_z+176, block_id)
mc.setBlock(pos_x+137, pos_y+31, pos_z+176, block_id)
mc.setBlock(pos_x+68, pos_y+74, pos_z+177, block_id)
mc.setBlock(pos_x+69, pos_y+74, pos_z+177, block_id)
mc.setBlock(pos_x+59, pos_y+31, pos_z+176, block_id)
mc.setBlock(pos_x+137, pos_y+30, pos_z+176, block_id)
mc.setBlock(pos_x+59, pos_y+30, pos_z+176, block_id)
mc.setBlock(pos_x+137, pos_y+29, pos_z+176, block_id)
mc.setBlock(pos_x+59, pos_y+29, pos_z+176, block_id)
mc.setBlock(pos_x+137, pos_y+28, pos_z+176, block_id)
mc.setBlock(pos_x+59, pos_y+28, pos_z+176, block_id)
mc.setBlock(pos_x+137, pos_y+27, pos_z+176, block_id)
mc.setBlock(pos_x+59, pos_y+27, pos_z+176, block_id)
mc.setBlock(pos_x+137, pos_y+26, pos_z+176, block_id)
mc.setBlock(pos_x+59, pos_y+26, pos_z+176, block_id)
mc.setBlock(pos_x+138, pos_y+25, pos_z+176, block_id)
mc.setBlock(pos_x+77, pos_y+74, pos_z+177, block_id)
mc.setBlock(pos_x+119, pos_y+74, pos_z+177, block_id)
mc.setBlock(pos_x+58, pos_y+25, pos_z+176, block_id)
mc.setBlock(pos_x+138, pos_y+24, pos_z+176, block_id)
mc.setBlock(pos_x+58, pos_y+24, pos_z+176, block_id)
mc.setBlock(pos_x+138, pos_y+23, pos_z+176, block_id)
mc.setBlock(pos_x+127, pos_y+74, pos_z+177, block_id)
mc.setBlock(pos_x+128, pos_y+74, pos_z+177, block_id)
mc.setBlock(pos_x+133, pos_y+74, pos_z+177, block_id)
mc.setBlock(pos_x+135, pos_y+74, pos_z+177, block_id)
mc.setBlock(pos_x+58, pos_y+23, pos_z+176, block_id)
mc.setBlock(pos_x+138, pos_y+22, pos_z+176, block_id)
mc.setBlock(pos_x+136, pos_y+74, pos_z+177, block_id)
mc.setBlock(pos_x+137, pos_y+74, pos_z+177, block_id)
mc.setBlock(pos_x+141, pos_y+74, pos_z+177, block_id)
mc.setBlock(pos_x+54, pos_y+75, pos_z+177, block_id)
mc.setBlock(pos_x+55, pos_y+75, pos_z+177, block_id)
mc.setBlock(pos_x+58, pos_y+75, pos_z+177, block_id)
mc.setBlock(pos_x+58, pos_y+22, pos_z+176, block_id)
mc.setBlock(pos_x+137, pos_y+21, pos_z+176, block_id)
mc.setBlock(pos_x+59, pos_y+75, pos_z+177, block_id)
mc.setBlock(pos_x+113, pos_y+21, pos_z+176, block_id)
mc.setBlock(pos_x+60, pos_y+75, pos_z+177, block_id)
mc.setBlock(pos_x+61, pos_y+75, pos_z+177, block_id)
mc.setBlock(pos_x+83, pos_y+21, pos_z+176, block_id)
mc.setBlock(pos_x+62, pos_y+75, pos_z+177, block_id)
mc.setBlock(pos_x+59, pos_y+21, pos_z+176, block_id)
mc.setBlock(pos_x+137, pos_y+20, pos_z+176, block_id)
mc.setBlock(pos_x+70, pos_y+75, pos_z+177, block_id)
mc.setBlock(pos_x+114, pos_y+20, pos_z+176, block_id)
mc.setBlock(pos_x+112, pos_y+20, pos_z+176, block_id)
mc.setBlock(pos_x+77, pos_y+75, pos_z+177, block_id)
mc.setBlock(pos_x+119, pos_y+75, pos_z+177, block_id)
mc.setBlock(pos_x+84, pos_y+20, pos_z+176, block_id)
mc.setBlock(pos_x+82, pos_y+20, pos_z+176, block_id)
mc.setBlock(pos_x+126, pos_y+75, pos_z+177, block_id)
mc.setBlock(pos_x+59, pos_y+20, pos_z+176, block_id)
mc.setBlock(pos_x+137, pos_y+19, pos_z+176, block_id)
mc.setBlock(pos_x+134, pos_y+75, pos_z+177, block_id)
mc.setBlock(pos_x+115, pos_y+19, pos_z+176, block_id)
mc.setBlock(pos_x+111, pos_y+19, pos_z+176, block_id)
mc.setBlock(pos_x+135, pos_y+75, pos_z+177, block_id)
mc.setBlock(pos_x+136, pos_y+75, pos_z+177, block_id)
mc.setBlock(pos_x+85, pos_y+19, pos_z+176, block_id)
mc.setBlock(pos_x+81, pos_y+19, pos_z+176, block_id)
mc.setBlock(pos_x+137, pos_y+75, pos_z+177, block_id)
mc.setBlock(pos_x+59, pos_y+19, pos_z+176, block_id)
mc.setBlock(pos_x+137, pos_y+18, pos_z+176, block_id)
mc.setBlock(pos_x+138, pos_y+75, pos_z+177, block_id)
mc.setBlock(pos_x+116, pos_y+18, pos_z+176, block_id)
mc.setBlock(pos_x+110, pos_y+18, pos_z+176, block_id)
mc.setBlock(pos_x+109, pos_y+18, pos_z+176, block_id)
mc.setBlock(pos_x+141, pos_y+75, pos_z+177, block_id)
mc.setBlock(pos_x+86, pos_y+18, pos_z+176, block_id)
mc.setBlock(pos_x+80, pos_y+18, pos_z+176, block_id)
mc.setBlock(pos_x+142, pos_y+75, pos_z+177, block_id)
mc.setBlock(pos_x+59, pos_y+18, pos_z+176, block_id)
mc.setBlock(pos_x+136, pos_y+17, pos_z+176, block_id)
mc.setBlock(pos_x+53, pos_y+76, pos_z+177, block_id)
mc.setBlock(pos_x+116, pos_y+17, pos_z+176, block_id)
mc.setBlock(pos_x+108, pos_y+17, pos_z+176, block_id)
mc.setBlock(pos_x+107, pos_y+17, pos_z+176, block_id)
mc.setBlock(pos_x+54, pos_y+76, pos_z+177, block_id)
mc.setBlock(pos_x+58, pos_y+76, pos_z+177, block_id)
mc.setBlock(pos_x+59, pos_y+76, pos_z+177, block_id)
mc.setBlock(pos_x+60, pos_y+76, pos_z+177, block_id)
mc.setBlock(pos_x+61, pos_y+76, pos_z+177, block_id)
mc.setBlock(pos_x+71, pos_y+76, pos_z+177, block_id)
mc.setBlock(pos_x+78, pos_y+76, pos_z+177, block_id)
mc.setBlock(pos_x+89, pos_y+17, pos_z+176, block_id)
mc.setBlock(pos_x+88, pos_y+17, pos_z+176, block_id)
mc.setBlock(pos_x+87, pos_y+17, pos_z+176, block_id)
mc.setBlock(pos_x+80, pos_y+17, pos_z+176, block_id)
mc.setBlock(pos_x+118, pos_y+76, pos_z+177, block_id)
mc.setBlock(pos_x+60, pos_y+17, pos_z+176, block_id)
mc.setBlock(pos_x+136, pos_y+16, pos_z+176, block_id)
mc.setBlock(pos_x+125, pos_y+76, pos_z+177, block_id)
mc.setBlock(pos_x+117, pos_y+16, pos_z+176, block_id)
mc.setBlock(pos_x+106, pos_y+16, pos_z+176, block_id)
mc.setBlock(pos_x+105, pos_y+16, pos_z+176, block_id)
mc.setBlock(pos_x+104, pos_y+16, pos_z+176, block_id)
mc.setBlock(pos_x+103, pos_y+16, pos_z+176, block_id)
mc.setBlock(pos_x+102, pos_y+16, pos_z+176, block_id)
mc.setBlock(pos_x+101, pos_y+16, pos_z+176, block_id)
mc.setBlock(pos_x+135, pos_y+76, pos_z+177, block_id)
mc.setBlock(pos_x+136, pos_y+76, pos_z+177, block_id)
mc.setBlock(pos_x+137, pos_y+76, pos_z+177, block_id)
mc.setBlock(pos_x+138, pos_y+76, pos_z+177, block_id)
mc.setBlock(pos_x+95, pos_y+16, pos_z+176, block_id)
mc.setBlock(pos_x+94, pos_y+16, pos_z+176, block_id)
mc.setBlock(pos_x+93, pos_y+16, pos_z+176, block_id)
mc.setBlock(pos_x+92, pos_y+16, pos_z+176, block_id)
mc.setBlock(pos_x+91, pos_y+16, pos_z+176, block_id)
mc.setBlock(pos_x+90, pos_y+16, pos_z+176, block_id)
mc.setBlock(pos_x+79, pos_y+16, pos_z+176, block_id)
mc.setBlock(pos_x+142, pos_y+76, pos_z+177, block_id)
mc.setBlock(pos_x+60, pos_y+16, pos_z+176, block_id)
mc.setBlock(pos_x+135, pos_y+15, pos_z+176, block_id)
mc.setBlock(pos_x+143, pos_y+76, pos_z+177, block_id)
mc.setBlock(pos_x+117, pos_y+15, pos_z+176, block_id)
mc.setBlock(pos_x+100, pos_y+15, pos_z+176, block_id)
mc.setBlock(pos_x+99, pos_y+15, pos_z+176, block_id)
mc.setBlock(pos_x+98, pos_y+15, pos_z+176, block_id)
mc.setBlock(pos_x+97, pos_y+15, pos_z+176, block_id)
mc.setBlock(pos_x+96, pos_y+15, pos_z+176, block_id)
mc.setBlock(pos_x+79, pos_y+15, pos_z+176, block_id)
mc.setBlock(pos_x+53, pos_y+77, pos_z+177, block_id)
mc.setBlock(pos_x+61, pos_y+15, pos_z+176, block_id)
mc.setBlock(pos_x+134, pos_y+14, pos_z+176, block_id)
mc.setBlock(pos_x+118, pos_y+14, pos_z+176, block_id)
mc.setBlock(pos_x+78, pos_y+14, pos_z+176, block_id)
mc.setBlock(pos_x+62, pos_y+14, pos_z+176, block_id)
mc.setBlock(pos_x+134, pos_y+13, pos_z+176, block_id)
mc.setBlock(pos_x+57, pos_y+77, pos_z+177, block_id)
mc.setBlock(pos_x+118, pos_y+13, pos_z+176, block_id)
mc.setBlock(pos_x+78, pos_y+13, pos_z+176, block_id)
mc.setBlock(pos_x+58, pos_y+77, pos_z+177, block_id)
mc.setBlock(pos_x+62, pos_y+13, pos_z+176, block_id)
mc.setBlock(pos_x+134, pos_y+12, pos_z+176, block_id)
mc.setBlock(pos_x+59, pos_y+77, pos_z+177, block_id)
mc.setBlock(pos_x+118, pos_y+12, pos_z+176, block_id)
mc.setBlock(pos_x+78, pos_y+12, pos_z+176, block_id)
mc.setBlock(pos_x+60, pos_y+77, pos_z+177, block_id)
mc.setBlock(pos_x+62, pos_y+12, pos_z+176, block_id)
mc.setBlock(pos_x+134, pos_y+11, pos_z+176, block_id)
mc.setBlock(pos_x+118, pos_y+11, pos_z+176, block_id)
mc.setBlock(pos_x+78, pos_y+11, pos_z+176, block_id)
mc.setBlock(pos_x+62, pos_y+11, pos_z+176, block_id)
mc.setBlock(pos_x+135, pos_y+10, pos_z+176, block_id)
mc.setBlock(pos_x+61, pos_y+77, pos_z+177, block_id)
mc.setBlock(pos_x+118, pos_y+10, pos_z+176, block_id)
mc.setBlock(pos_x+78, pos_y+10, pos_z+176, block_id)
mc.setBlock(pos_x+62, pos_y+77, pos_z+177, block_id)
mc.setBlock(pos_x+61, pos_y+10, pos_z+176, block_id)
mc.setBlock(pos_x+135, pos_y+9, pos_z+176, block_id)
mc.setBlock(pos_x+118, pos_y+9, pos_z+176, block_id)
mc.setBlock(pos_x+78, pos_y+9, pos_z+176, block_id)
mc.setBlock(pos_x+71, pos_y+77, pos_z+177, block_id)
mc.setBlock(pos_x+61, pos_y+9, pos_z+176, block_id)
mc.setBlock(pos_x+135, pos_y+8, pos_z+176, block_id)
mc.setBlock(pos_x+78, pos_y+77, pos_z+177, block_id)
mc.setBlock(pos_x+117, pos_y+8, pos_z+176, block_id)
mc.setBlock(pos_x+79, pos_y+8, pos_z+176, block_id)
mc.setBlock(pos_x+118, pos_y+77, pos_z+177, block_id)
mc.setBlock(pos_x+61, pos_y+8, pos_z+176, block_id)
mc.setBlock(pos_x+136, pos_y+7, pos_z+176, block_id)
mc.setBlock(pos_x+125, pos_y+77, pos_z+177, block_id)
mc.setBlock(pos_x+117, pos_y+7, pos_z+176, block_id)
mc.setBlock(pos_x+79, pos_y+7, pos_z+176, block_id)
mc.setBlock(pos_x+134, pos_y+77, pos_z+177, block_id)
mc.setBlock(pos_x+60, pos_y+7, pos_z+176, block_id)
mc.setBlock(pos_x+136, pos_y+6, pos_z+176, block_id)
mc.setBlock(pos_x+117, pos_y+6, pos_z+176, block_id)
mc.setBlock(pos_x+79, pos_y+6, pos_z+176, block_id)
mc.setBlock(pos_x+60, pos_y+6, pos_z+176, block_id)
mc.setBlock(pos_x+136, pos_y+5, pos_z+176, block_id)
mc.setBlock(pos_x+117, pos_y+5, pos_z+176, block_id)
mc.setBlock(pos_x+79, pos_y+5, pos_z+176, block_id)
mc.setBlock(pos_x+60, pos_y+5, pos_z+176, block_id)
mc.setBlock(pos_x+136, pos_y+4, pos_z+176, block_id)
mc.setBlock(pos_x+117, pos_y+4, pos_z+176, block_id)
mc.setBlock(pos_x+79, pos_y+4, pos_z+176, block_id)
mc.setBlock(pos_x+60, pos_y+4, pos_z+176, block_id)
mc.setBlock(pos_x+136, pos_y+3, pos_z+176, block_id)
mc.setBlock(pos_x+117, pos_y+3, pos_z+176, block_id)
mc.setBlock(pos_x+79, pos_y+3, pos_z+176, block_id)
mc.setBlock(pos_x+60, pos_y+3, pos_z+176, block_id)
mc.setBlock(pos_x+136, pos_y+2, pos_z+176, block_id)
mc.setBlock(pos_x+117, pos_y+2, pos_z+176, block_id)
mc.setBlock(pos_x+79, pos_y+2, pos_z+176, block_id)
mc.setBlock(pos_x+60, pos_y+2, pos_z+176, block_id)
mc.setBlock(pos_x+136, pos_y+1, pos_z+176, block_id)
mc.setBlock(pos_x+117, pos_y+1, pos_z+176, block_id)
mc.setBlock(pos_x+79, pos_y+1, pos_z+176, block_id)
mc.setBlock(pos_x+60, pos_y+1, pos_z+176, block_id)
mc.setBlock(pos_x+136, pos_y+0, pos_z+176, block_id)
mc.setBlock(pos_x+135, pos_y+0, pos_z+176, block_id)
mc.setBlock(pos_x+134, pos_y+0, pos_z+176, block_id)
mc.setBlock(pos_x+133, pos_y+0, pos_z+176, block_id)
mc.setBlock(pos_x+132, pos_y+0, pos_z+176, block_id)
mc.setBlock(pos_x+131, pos_y+0, pos_z+176, block_id)
mc.setBlock(pos_x+130, pos_y+0, pos_z+176, block_id)
mc.setBlock(pos_x+129, pos_y+0, pos_z+176, block_id)
mc.setBlock(pos_x+128, pos_y+0, pos_z+176, block_id)
mc.setBlock(pos_x+127, pos_y+0, pos_z+176, block_id)
mc.setBlock(pos_x+126, pos_y+0, pos_z+176, block_id)
mc.setBlock(pos_x+125, pos_y+0, pos_z+176, block_id)
mc.setBlock(pos_x+124, pos_y+0, pos_z+176, block_id)
mc.setBlock(pos_x+123, pos_y+0, pos_z+176, block_id)
mc.setBlock(pos_x+122, pos_y+0, pos_z+176, block_id)
mc.setBlock(pos_x+121, pos_y+0, pos_z+176, block_id)
mc.setBlock(pos_x+120, pos_y+0, pos_z+176, block_id)
mc.setBlock(pos_x+119, pos_y+0, pos_z+176, block_id)
mc.setBlock(pos_x+118, pos_y+0, pos_z+176, block_id)
mc.setBlock(pos_x+117, pos_y+0, pos_z+176, block_id)
mc.setBlock(pos_x+79, pos_y+0, pos_z+176, block_id)
mc.setBlock(pos_x+78, pos_y+0, pos_z+176, block_id)
mc.setBlock(pos_x+77, pos_y+0, pos_z+176, block_id)
mc.setBlock(pos_x+76, pos_y+0, pos_z+176, block_id)
mc.setBlock(pos_x+75, pos_y+0, pos_z+176, block_id)
mc.setBlock(pos_x+74, pos_y+0, pos_z+176, block_id)
mc.setBlock(pos_x+73, pos_y+0, pos_z+176, block_id)
mc.setBlock(pos_x+72, pos_y+0, pos_z+176, block_id)
mc.setBlock(pos_x+71, pos_y+0, pos_z+176, block_id)
mc.setBlock(pos_x+70, pos_y+0, pos_z+176, block_id)
mc.setBlock(pos_x+69, pos_y+0, pos_z+176, block_id)
mc.setBlock(pos_x+68, pos_y+0, pos_z+176, block_id)
mc.setBlock(pos_x+67, pos_y+0, pos_z+176, block_id)
mc.setBlock(pos_x+66, pos_y+0, pos_z+176, block_id)
mc.setBlock(pos_x+65, pos_y+0, pos_z+176, block_id)
mc.setBlock(pos_x+64, pos_y+0, pos_z+176, block_id)
mc.setBlock(pos_x+63, pos_y+0, pos_z+176, block_id)
mc.setBlock(pos_x+62, pos_y+0, pos_z+176, block_id)
mc.setBlock(pos_x+61, pos_y+0, pos_z+176, block_id)
mc.setBlock(pos_x+60, pos_y+0, pos_z+176, block_id)
mc.setBlock(pos_x+148, pos_y+130, pos_z+175, block_id)
mc.setBlock(pos_x+147, pos_y+130, pos_z+175, block_id)
mc.setBlock(pos_x+49, pos_y+130, pos_z+175, block_id)
mc.setBlock(pos_x+48, pos_y+130, pos_z+175, block_id)
mc.setBlock(pos_x+47, pos_y+130, pos_z+175, block_id)
mc.setBlock(pos_x+150, pos_y+129, pos_z+175, block_id)
mc.setBlock(pos_x+149, pos_y+129, pos_z+175, block_id)
mc.setBlock(pos_x+148, pos_y+129, pos_z+175, block_id)
mc.setBlock(pos_x+147, pos_y+129, pos_z+175, block_id)
mc.setBlock(pos_x+146, pos_y+129, pos_z+175, block_id)
mc.setBlock(pos_x+145, pos_y+129, pos_z+175, block_id)
mc.setBlock(pos_x+144, pos_y+129, pos_z+175, block_id)
mc.setBlock(pos_x+143, pos_y+129, pos_z+175, block_id)
mc.setBlock(pos_x+53, pos_y+129, pos_z+175, block_id)
mc.setBlock(pos_x+52, pos_y+129, pos_z+175, block_id)
mc.setBlock(pos_x+51, pos_y+129, pos_z+175, block_id)
mc.setBlock(pos_x+50, pos_y+129, pos_z+175, block_id)
mc.setBlock(pos_x+49, pos_y+129, pos_z+175, block_id)
mc.setBlock(pos_x+48, pos_y+129, pos_z+175, block_id)
mc.setBlock(pos_x+47, pos_y+129, pos_z+175, block_id)
mc.setBlock(pos_x+46, pos_y+129, pos_z+175, block_id)
mc.setBlock(pos_x+151, pos_y+128, pos_z+175, block_id)
mc.setBlock(pos_x+135, pos_y+77, pos_z+177, block_id)
mc.setBlock(pos_x+136, pos_y+77, pos_z+177, block_id)
mc.setBlock(pos_x+137, pos_y+77, pos_z+177, block_id)
mc.setBlock(pos_x+138, pos_y+77, pos_z+177, block_id)
mc.setBlock(pos_x+146, pos_y+128, pos_z+175, block_id)
mc.setBlock(pos_x+145, pos_y+128, pos_z+175, block_id)
mc.setBlock(pos_x+144, pos_y+128, pos_z+175, block_id)
mc.setBlock(pos_x+143, pos_y+128, pos_z+175, block_id)
mc.setBlock(pos_x+142, pos_y+128, pos_z+175, block_id)
mc.setBlock(pos_x+54, pos_y+128, pos_z+175, block_id)
mc.setBlock(pos_x+53, pos_y+128, pos_z+175, block_id)
mc.setBlock(pos_x+52, pos_y+128, pos_z+175, block_id)
mc.setBlock(pos_x+51, pos_y+128, pos_z+175, block_id)
mc.setBlock(pos_x+143, pos_y+77, pos_z+177, block_id)
mc.setBlock(pos_x+51, pos_y+78, pos_z+177, block_id)
mc.setBlock(pos_x+52, pos_y+78, pos_z+177, block_id)
mc.setBlock(pos_x+57, pos_y+78, pos_z+177, block_id)
mc.setBlock(pos_x+58, pos_y+78, pos_z+177, block_id)
mc.setBlock(pos_x+45, pos_y+128, pos_z+175, block_id)
mc.setBlock(pos_x+152, pos_y+127, pos_z+175, block_id)
mc.setBlock(pos_x+59, pos_y+78, pos_z+177, block_id)
mc.setBlock(pos_x+60, pos_y+78, pos_z+177, block_id)
mc.setBlock(pos_x+61, pos_y+78, pos_z+177, block_id)
mc.setBlock(pos_x+62, pos_y+78, pos_z+177, block_id)
mc.setBlock(pos_x+142, pos_y+127, pos_z+175, block_id)
mc.setBlock(pos_x+141, pos_y+127, pos_z+175, block_id)
mc.setBlock(pos_x+140, pos_y+127, pos_z+175, block_id)
mc.setBlock(pos_x+139, pos_y+127, pos_z+175, block_id)
mc.setBlock(pos_x+56, pos_y+127, pos_z+175, block_id)
mc.setBlock(pos_x+55, pos_y+127, pos_z+175, block_id)
mc.setBlock(pos_x+54, pos_y+127, pos_z+175, block_id)
mc.setBlock(pos_x+63, pos_y+78, pos_z+177, block_id)
mc.setBlock(pos_x+65, pos_y+78, pos_z+177, block_id)
mc.setBlock(pos_x+66, pos_y+78, pos_z+177, block_id)
mc.setBlock(pos_x+70, pos_y+78, pos_z+177, block_id)
mc.setBlock(pos_x+44, pos_y+127, pos_z+175, block_id)
mc.setBlock(pos_x+153, pos_y+126, pos_z+175, block_id)
mc.setBlock(pos_x+79, pos_y+78, pos_z+177, block_id)
mc.setBlock(pos_x+80, pos_y+78, pos_z+177, block_id)
mc.setBlock(pos_x+141, pos_y+126, pos_z+175, block_id)
mc.setBlock(pos_x+140, pos_y+126, pos_z+175, block_id)
mc.setBlock(pos_x+139, pos_y+126, pos_z+175, block_id)
mc.setBlock(pos_x+138, pos_y+126, pos_z+175, block_id)
mc.setBlock(pos_x+137, pos_y+126, pos_z+175, block_id)
mc.setBlock(pos_x+59, pos_y+126, pos_z+175, block_id)
mc.setBlock(pos_x+58, pos_y+126, pos_z+175, block_id)
mc.setBlock(pos_x+57, pos_y+126, pos_z+175, block_id)
mc.setBlock(pos_x+56, pos_y+126, pos_z+175, block_id)
mc.setBlock(pos_x+55, pos_y+126, pos_z+175, block_id)
mc.setBlock(pos_x+54, pos_y+126, pos_z+175, block_id)
mc.setBlock(pos_x+116, pos_y+78, pos_z+177, block_id)
mc.setBlock(pos_x+43, pos_y+126, pos_z+175, block_id)
mc.setBlock(pos_x+154, pos_y+125, pos_z+175, block_id)
mc.setBlock(pos_x+117, pos_y+78, pos_z+177, block_id)
mc.setBlock(pos_x+126, pos_y+78, pos_z+177, block_id)
mc.setBlock(pos_x+130, pos_y+78, pos_z+177, block_id)
mc.setBlock(pos_x+139, pos_y+125, pos_z+175, block_id)
mc.setBlock(pos_x+138, pos_y+125, pos_z+175, block_id)
mc.setBlock(pos_x+137, pos_y+125, pos_z+175, block_id)
mc.setBlock(pos_x+136, pos_y+125, pos_z+175, block_id)
mc.setBlock(pos_x+135, pos_y+125, pos_z+175, block_id)
mc.setBlock(pos_x+60, pos_y+125, pos_z+175, block_id)
mc.setBlock(pos_x+59, pos_y+125, pos_z+175, block_id)
mc.setBlock(pos_x+58, pos_y+125, pos_z+175, block_id)
mc.setBlock(pos_x+57, pos_y+125, pos_z+175, block_id)
mc.setBlock(pos_x+131, pos_y+78, pos_z+177, block_id)
mc.setBlock(pos_x+132, pos_y+78, pos_z+177, block_id)
mc.setBlock(pos_x+133, pos_y+78, pos_z+177, block_id)
mc.setBlock(pos_x+42, pos_y+125, pos_z+175, block_id)
mc.setBlock(pos_x+155, pos_y+124, pos_z+175, block_id)
mc.setBlock(pos_x+154, pos_y+124, pos_z+175, block_id)
mc.setBlock(pos_x+153, pos_y+124, pos_z+175, block_id)
mc.setBlock(pos_x+152, pos_y+124, pos_z+175, block_id)
mc.setBlock(pos_x+151, pos_y+124, pos_z+175, block_id)
mc.setBlock(pos_x+134, pos_y+78, pos_z+177, block_id)
mc.setBlock(pos_x+149, pos_y+124, pos_z+175, block_id)
mc.setBlock(pos_x+148, pos_y+124, pos_z+175, block_id)
mc.setBlock(pos_x+136, pos_y+78, pos_z+177, block_id)
mc.setBlock(pos_x+137, pos_y+78, pos_z+177, block_id)
mc.setBlock(pos_x+138, pos_y+78, pos_z+177, block_id)
mc.setBlock(pos_x+139, pos_y+78, pos_z+177, block_id)
mc.setBlock(pos_x+144, pos_y+78, pos_z+177, block_id)
mc.setBlock(pos_x+145, pos_y+78, pos_z+177, block_id)
mc.setBlock(pos_x+51, pos_y+79, pos_z+177, block_id)
mc.setBlock(pos_x+136, pos_y+124, pos_z+175, block_id)
mc.setBlock(pos_x+135, pos_y+124, pos_z+175, block_id)
mc.setBlock(pos_x+134, pos_y+124, pos_z+175, block_id)
mc.setBlock(pos_x+62, pos_y+124, pos_z+175, block_id)
mc.setBlock(pos_x+61, pos_y+124, pos_z+175, block_id)
mc.setBlock(pos_x+60, pos_y+124, pos_z+175, block_id)
mc.setBlock(pos_x+56, pos_y+79, pos_z+177, block_id)
mc.setBlock(pos_x+57, pos_y+79, pos_z+177, block_id)
mc.setBlock(pos_x+58, pos_y+79, pos_z+177, block_id)
mc.setBlock(pos_x+59, pos_y+79, pos_z+177, block_id)
mc.setBlock(pos_x+60, pos_y+79, pos_z+177, block_id)
mc.setBlock(pos_x+61, pos_y+79, pos_z+177, block_id)
mc.setBlock(pos_x+62, pos_y+79, pos_z+177, block_id)
mc.setBlock(pos_x+63, pos_y+79, pos_z+177, block_id)
mc.setBlock(pos_x+47, pos_y+124, pos_z+175, block_id)
mc.setBlock(pos_x+64, pos_y+79, pos_z+177, block_id)
mc.setBlock(pos_x+45, pos_y+124, pos_z+175, block_id)
mc.setBlock(pos_x+44, pos_y+124, pos_z+175, block_id)
mc.setBlock(pos_x+43, pos_y+124, pos_z+175, block_id)
mc.setBlock(pos_x+42, pos_y+124, pos_z+175, block_id)
mc.setBlock(pos_x+41, pos_y+124, pos_z+175, block_id)
mc.setBlock(pos_x+156, pos_y+123, pos_z+175, block_id)
mc.setBlock(pos_x+155, pos_y+123, pos_z+175, block_id)
mc.setBlock(pos_x+154, pos_y+123, pos_z+175, block_id)
mc.setBlock(pos_x+153, pos_y+123, pos_z+175, block_id)
mc.setBlock(pos_x+152, pos_y+123, pos_z+175, block_id)
mc.setBlock(pos_x+151, pos_y+123, pos_z+175, block_id)
mc.setBlock(pos_x+150, pos_y+123, pos_z+175, block_id)
mc.setBlock(pos_x+149, pos_y+123, pos_z+175, block_id)
mc.setBlock(pos_x+148, pos_y+123, pos_z+175, block_id)
mc.setBlock(pos_x+147, pos_y+123, pos_z+175, block_id)
mc.setBlock(pos_x+146, pos_y+123, pos_z+175, block_id)
mc.setBlock(pos_x+145, pos_y+123, pos_z+175, block_id)
mc.setBlock(pos_x+144, pos_y+123, pos_z+175, block_id)
mc.setBlock(pos_x+67, pos_y+79, pos_z+177, block_id)
mc.setBlock(pos_x+68, pos_y+79, pos_z+177, block_id)
mc.setBlock(pos_x+69, pos_y+79, pos_z+177, block_id)
mc.setBlock(pos_x+134, pos_y+123, pos_z+175, block_id)
mc.setBlock(pos_x+133, pos_y+123, pos_z+175, block_id)
mc.setBlock(pos_x+132, pos_y+123, pos_z+175, block_id)
mc.setBlock(pos_x+64, pos_y+123, pos_z+175, block_id)
mc.setBlock(pos_x+63, pos_y+123, pos_z+175, block_id)
mc.setBlock(pos_x+62, pos_y+123, pos_z+175, block_id)
mc.setBlock(pos_x+61, pos_y+123, pos_z+175, block_id)
mc.setBlock(pos_x+81, pos_y+79, pos_z+177, block_id)
mc.setBlock(pos_x+82, pos_y+79, pos_z+177, block_id)
mc.setBlock(pos_x+52, pos_y+123, pos_z+175, block_id)
mc.setBlock(pos_x+51, pos_y+123, pos_z+175, block_id)
mc.setBlock(pos_x+50, pos_y+123, pos_z+175, block_id)
mc.setBlock(pos_x+49, pos_y+123, pos_z+175, block_id)
mc.setBlock(pos_x+48, pos_y+123, pos_z+175, block_id)
mc.setBlock(pos_x+47, pos_y+123, pos_z+175, block_id)
mc.setBlock(pos_x+46, pos_y+123, pos_z+175, block_id)
mc.setBlock(pos_x+45, pos_y+123, pos_z+175, block_id)
mc.setBlock(pos_x+44, pos_y+123, pos_z+175, block_id)
mc.setBlock(pos_x+43, pos_y+123, pos_z+175, block_id)
mc.setBlock(pos_x+42, pos_y+123, pos_z+175, block_id)
mc.setBlock(pos_x+41, pos_y+123, pos_z+175, block_id)
mc.setBlock(pos_x+40, pos_y+123, pos_z+175, block_id)
mc.setBlock(pos_x+144, pos_y+122, pos_z+175, block_id)
mc.setBlock(pos_x+143, pos_y+122, pos_z+175, block_id)
mc.setBlock(pos_x+83, pos_y+79, pos_z+177, block_id)
mc.setBlock(pos_x+84, pos_y+79, pos_z+177, block_id)
mc.setBlock(pos_x+85, pos_y+79, pos_z+177, block_id)
mc.setBlock(pos_x+133, pos_y+122, pos_z+175, block_id)
mc.setBlock(pos_x+132, pos_y+122, pos_z+175, block_id)
mc.setBlock(pos_x+65, pos_y+122, pos_z+175, block_id)
mc.setBlock(pos_x+64, pos_y+122, pos_z+175, block_id)
mc.setBlock(pos_x+63, pos_y+122, pos_z+175, block_id)
mc.setBlock(pos_x+111, pos_y+79, pos_z+177, block_id)
mc.setBlock(pos_x+112, pos_y+79, pos_z+177, block_id)
mc.setBlock(pos_x+113, pos_y+79, pos_z+177, block_id)
mc.setBlock(pos_x+114, pos_y+79, pos_z+177, block_id)
mc.setBlock(pos_x+53, pos_y+122, pos_z+175, block_id)
mc.setBlock(pos_x+52, pos_y+122, pos_z+175, block_id)
mc.setBlock(pos_x+143, pos_y+121, pos_z+175, block_id)
mc.setBlock(pos_x+142, pos_y+121, pos_z+175, block_id)
mc.setBlock(pos_x+141, pos_y+121, pos_z+175, block_id)
mc.setBlock(pos_x+115, pos_y+79, pos_z+177, block_id)
mc.setBlock(pos_x+127, pos_y+79, pos_z+177, block_id)
mc.setBlock(pos_x+128, pos_y+79, pos_z+177, block_id)
mc.setBlock(pos_x+129, pos_y+79, pos_z+177, block_id)
mc.setBlock(pos_x+131, pos_y+121, pos_z+175, block_id)
mc.setBlock(pos_x+65, pos_y+121, pos_z+175, block_id)
mc.setBlock(pos_x+132, pos_y+79, pos_z+177, block_id)
mc.setBlock(pos_x+133, pos_y+79, pos_z+177, block_id)
mc.setBlock(pos_x+134, pos_y+79, pos_z+177, block_id)
mc.setBlock(pos_x+55, pos_y+121, pos_z+175, block_id)
mc.setBlock(pos_x+54, pos_y+121, pos_z+175, block_id)
mc.setBlock(pos_x+53, pos_y+121, pos_z+175, block_id)
mc.setBlock(pos_x+142, pos_y+120, pos_z+175, block_id)
mc.setBlock(pos_x+141, pos_y+120, pos_z+175, block_id)
mc.setBlock(pos_x+140, pos_y+120, pos_z+175, block_id)
mc.setBlock(pos_x+139, pos_y+120, pos_z+175, block_id)
mc.setBlock(pos_x+135, pos_y+79, pos_z+177, block_id)
mc.setBlock(pos_x+136, pos_y+79, pos_z+177, block_id)
mc.setBlock(pos_x+130, pos_y+120, pos_z+175, block_id)
mc.setBlock(pos_x+66, pos_y+120, pos_z+175, block_id)
mc.setBlock(pos_x+137, pos_y+79, pos_z+177, block_id)
mc.setBlock(pos_x+138, pos_y+79, pos_z+177, block_id)
mc.setBlock(pos_x+139, pos_y+79, pos_z+177, block_id)
mc.setBlock(pos_x+57, pos_y+120, pos_z+175, block_id)
mc.setBlock(pos_x+56, pos_y+120, pos_z+175, block_id)
mc.setBlock(pos_x+55, pos_y+120, pos_z+175, block_id)
mc.setBlock(pos_x+54, pos_y+120, pos_z+175, block_id)
mc.setBlock(pos_x+139, pos_y+119, pos_z+175, block_id)
mc.setBlock(pos_x+138, pos_y+119, pos_z+175, block_id)
mc.setBlock(pos_x+137, pos_y+119, pos_z+175, block_id)
mc.setBlock(pos_x+140, pos_y+79, pos_z+177, block_id)
mc.setBlock(pos_x+145, pos_y+79, pos_z+177, block_id)
mc.setBlock(pos_x+51, pos_y+80, pos_z+177, block_id)
mc.setBlock(pos_x+130, pos_y+119, pos_z+175, block_id)
mc.setBlock(pos_x+66, pos_y+119, pos_z+175, block_id)
mc.setBlock(pos_x+56, pos_y+80, pos_z+177, block_id)
mc.setBlock(pos_x+57, pos_y+80, pos_z+177, block_id)
mc.setBlock(pos_x+59, pos_y+119, pos_z+175, block_id)
mc.setBlock(pos_x+58, pos_y+119, pos_z+175, block_id)
mc.setBlock(pos_x+57, pos_y+119, pos_z+175, block_id)
mc.setBlock(pos_x+56, pos_y+119, pos_z+175, block_id)
mc.setBlock(pos_x+137, pos_y+118, pos_z+175, block_id)
mc.setBlock(pos_x+136, pos_y+118, pos_z+175, block_id)
mc.setBlock(pos_x+58, pos_y+80, pos_z+177, block_id)
mc.setBlock(pos_x+59, pos_y+80, pos_z+177, block_id)
mc.setBlock(pos_x+60, pos_y+80, pos_z+177, block_id)
mc.setBlock(pos_x+130, pos_y+118, pos_z+175, block_id)
mc.setBlock(pos_x+66, pos_y+118, pos_z+175, block_id)
mc.setBlock(pos_x+61, pos_y+80, pos_z+177, block_id)
mc.setBlock(pos_x+62, pos_y+80, pos_z+177, block_id)
mc.setBlock(pos_x+63, pos_y+80, pos_z+177, block_id)
mc.setBlock(pos_x+60, pos_y+118, pos_z+175, block_id)
mc.setBlock(pos_x+59, pos_y+118, pos_z+175, block_id)
mc.setBlock(pos_x+58, pos_y+118, pos_z+175, block_id)
mc.setBlock(pos_x+136, pos_y+117, pos_z+175, block_id)
mc.setBlock(pos_x+135, pos_y+117, pos_z+175, block_id)
mc.setBlock(pos_x+86, pos_y+80, pos_z+177, block_id)
mc.setBlock(pos_x+110, pos_y+80, pos_z+177, block_id)
mc.setBlock(pos_x+133, pos_y+80, pos_z+177, block_id)
mc.setBlock(pos_x+129, pos_y+117, pos_z+175, block_id)
mc.setBlock(pos_x+67, pos_y+117, pos_z+175, block_id)
mc.setBlock(pos_x+134, pos_y+80, pos_z+177, block_id)
mc.setBlock(pos_x+135, pos_y+80, pos_z+177, block_id)
mc.setBlock(pos_x+136, pos_y+80, pos_z+177, block_id)
mc.setBlock(pos_x+61, pos_y+117, pos_z+175, block_id)
mc.setBlock(pos_x+60, pos_y+117, pos_z+175, block_id)
mc.setBlock(pos_x+134, pos_y+116, pos_z+175, block_id)
mc.setBlock(pos_x+137, pos_y+80, pos_z+177, block_id)
mc.setBlock(pos_x+138, pos_y+80, pos_z+177, block_id)
mc.setBlock(pos_x+139, pos_y+80, pos_z+177, block_id)
mc.setBlock(pos_x+129, pos_y+116, pos_z+175, block_id)
mc.setBlock(pos_x+67, pos_y+116, pos_z+175, block_id)
mc.setBlock(pos_x+140, pos_y+80, pos_z+177, block_id)
mc.setBlock(pos_x+145, pos_y+80, pos_z+177, block_id)
mc.setBlock(pos_x+51, pos_y+81, pos_z+177, block_id)
mc.setBlock(pos_x+62, pos_y+116, pos_z+175, block_id)
mc.setBlock(pos_x+133, pos_y+115, pos_z+175, block_id)
mc.setBlock(pos_x+54, pos_y+81, pos_z+177, block_id)
mc.setBlock(pos_x+55, pos_y+81, pos_z+177, block_id)
mc.setBlock(pos_x+58, pos_y+81, pos_z+177, block_id)
mc.setBlock(pos_x+129, pos_y+115, pos_z+175, block_id)
mc.setBlock(pos_x+67, pos_y+115, pos_z+175, block_id)
mc.setBlock(pos_x+62, pos_y+81, pos_z+177, block_id)
mc.setBlock(pos_x+87, pos_y+81, pos_z+177, block_id)
mc.setBlock(pos_x+109, pos_y+81, pos_z+177, block_id)
mc.setBlock(pos_x+63, pos_y+115, pos_z+175, block_id)
mc.setBlock(pos_x+132, pos_y+114, pos_z+175, block_id)
mc.setBlock(pos_x+134, pos_y+81, pos_z+177, block_id)
mc.setBlock(pos_x+138, pos_y+81, pos_z+177, block_id)
mc.setBlock(pos_x+141, pos_y+81, pos_z+177, block_id)
mc.setBlock(pos_x+128, pos_y+114, pos_z+175, block_id)
mc.setBlock(pos_x+68, pos_y+114, pos_z+175, block_id)
mc.setBlock(pos_x+142, pos_y+81, pos_z+177, block_id)
mc.setBlock(pos_x+145, pos_y+81, pos_z+177, block_id)
mc.setBlock(pos_x+52, pos_y+82, pos_z+177, block_id)
mc.setBlock(pos_x+64, pos_y+114, pos_z+175, block_id)
mc.setBlock(pos_x+131, pos_y+113, pos_z+175, block_id)
mc.setBlock(pos_x+130, pos_y+113, pos_z+175, block_id)
mc.setBlock(pos_x+53, pos_y+82, pos_z+177, block_id)
mc.setBlock(pos_x+128, pos_y+113, pos_z+175, block_id)
mc.setBlock(pos_x+68, pos_y+113, pos_z+175, block_id)
mc.setBlock(pos_x+58, pos_y+82, pos_z+177, block_id)
mc.setBlock(pos_x+63, pos_y+82, pos_z+177, block_id)
mc.setBlock(pos_x+65, pos_y+113, pos_z+175, block_id)
mc.setBlock(pos_x+130, pos_y+112, pos_z+175, block_id)
mc.setBlock(pos_x+129, pos_y+112, pos_z+175, block_id)
mc.setBlock(pos_x+128, pos_y+112, pos_z+175, block_id)
mc.setBlock(pos_x+68, pos_y+112, pos_z+175, block_id)
mc.setBlock(pos_x+67, pos_y+112, pos_z+175, block_id)
mc.setBlock(pos_x+66, pos_y+112, pos_z+175, block_id)
mc.setBlock(pos_x+129, pos_y+111, pos_z+175, block_id)
mc.setBlock(pos_x+128, pos_y+111, pos_z+175, block_id)
mc.setBlock(pos_x+68, pos_y+111, pos_z+175, block_id)
mc.setBlock(pos_x+67, pos_y+111, pos_z+175, block_id)
mc.setBlock(pos_x+128, pos_y+110, pos_z+175, block_id)
mc.setBlock(pos_x+127, pos_y+110, pos_z+175, block_id)
mc.setBlock(pos_x+69, pos_y+110, pos_z+175, block_id)
mc.setBlock(pos_x+68, pos_y+110, pos_z+175, block_id)
mc.setBlock(pos_x+99, pos_y+87, pos_z+175, block_id)
mc.setBlock(pos_x+98, pos_y+87, pos_z+175, block_id)
mc.setBlock(pos_x+97, pos_y+87, pos_z+175, block_id)
mc.setBlock(pos_x+136, pos_y+86, pos_z+175, block_id)
mc.setBlock(pos_x+101, pos_y+86, pos_z+175, block_id)
mc.setBlock(pos_x+100, pos_y+86, pos_z+175, block_id)
mc.setBlock(pos_x+87, pos_y+82, pos_z+177, block_id)
mc.setBlock(pos_x+108, pos_y+82, pos_z+177, block_id)
mc.setBlock(pos_x+133, pos_y+82, pos_z+177, block_id)
mc.setBlock(pos_x+96, pos_y+86, pos_z+175, block_id)
mc.setBlock(pos_x+95, pos_y+86, pos_z+175, block_id)
mc.setBlock(pos_x+61, pos_y+86, pos_z+175, block_id)
mc.setBlock(pos_x+60, pos_y+86, pos_z+175, block_id)
mc.setBlock(pos_x+137, pos_y+85, pos_z+175, block_id)
mc.setBlock(pos_x+136, pos_y+85, pos_z+175, block_id)
mc.setBlock(pos_x+135, pos_y+85, pos_z+175, block_id)
mc.setBlock(pos_x+134, pos_y+85, pos_z+175, block_id)
mc.setBlock(pos_x+133, pos_y+85, pos_z+175, block_id)
mc.setBlock(pos_x+104, pos_y+85, pos_z+175, block_id)
mc.setBlock(pos_x+103, pos_y+85, pos_z+175, block_id)
mc.setBlock(pos_x+102, pos_y+85, pos_z+175, block_id)
mc.setBlock(pos_x+138, pos_y+82, pos_z+177, block_id)
mc.setBlock(pos_x+143, pos_y+82, pos_z+177, block_id)
mc.setBlock(pos_x+144, pos_y+82, pos_z+177, block_id)
mc.setBlock(pos_x+58, pos_y+83, pos_z+177, block_id)
mc.setBlock(pos_x+94, pos_y+85, pos_z+175, block_id)
mc.setBlock(pos_x+93, pos_y+85, pos_z+175, block_id)
mc.setBlock(pos_x+63, pos_y+85, pos_z+175, block_id)
mc.setBlock(pos_x+62, pos_y+85, pos_z+175, block_id)
mc.setBlock(pos_x+61, pos_y+85, pos_z+175, block_id)
mc.setBlock(pos_x+63, pos_y+83, pos_z+177, block_id)
mc.setBlock(pos_x+59, pos_y+85, pos_z+175, block_id)
mc.setBlock(pos_x+139, pos_y+84, pos_z+175, block_id)
mc.setBlock(pos_x+138, pos_y+84, pos_z+175, block_id)
mc.setBlock(pos_x+88, pos_y+83, pos_z+177, block_id)
mc.setBlock(pos_x+108, pos_y+83, pos_z+177, block_id)
mc.setBlock(pos_x+133, pos_y+83, pos_z+177, block_id)
mc.setBlock(pos_x+138, pos_y+83, pos_z+177, block_id)
mc.setBlock(pos_x+133, pos_y+84, pos_z+175, block_id)
mc.setBlock(pos_x+132, pos_y+84, pos_z+175, block_id)
mc.setBlock(pos_x+105, pos_y+84, pos_z+175, block_id)
mc.setBlock(pos_x+104, pos_y+84, pos_z+175, block_id)
mc.setBlock(pos_x+58, pos_y+84, pos_z+177, block_id)
mc.setBlock(pos_x+63, pos_y+84, pos_z+177, block_id)
mc.setBlock(pos_x+89, pos_y+84, pos_z+177, block_id)
mc.setBlock(pos_x+107, pos_y+84, pos_z+177, block_id)
mc.setBlock(pos_x+92, pos_y+84, pos_z+175, block_id)
mc.setBlock(pos_x+91, pos_y+84, pos_z+175, block_id)
mc.setBlock(pos_x+64, pos_y+84, pos_z+175, block_id)
mc.setBlock(pos_x+133, pos_y+84, pos_z+177, block_id)
mc.setBlock(pos_x+138, pos_y+84, pos_z+177, block_id)
mc.setBlock(pos_x+57, pos_y+85, pos_z+177, block_id)
mc.setBlock(pos_x+63, pos_y+85, pos_z+177, block_id)
mc.setBlock(pos_x+90, pos_y+85, pos_z+177, block_id)
mc.setBlock(pos_x+58, pos_y+84, pos_z+175, block_id)
mc.setBlock(pos_x+57, pos_y+84, pos_z+175, block_id)
mc.setBlock(pos_x+139, pos_y+83, pos_z+175, block_id)
mc.setBlock(pos_x+106, pos_y+85, pos_z+177, block_id)
mc.setBlock(pos_x+133, pos_y+85, pos_z+177, block_id)
mc.setBlock(pos_x+132, pos_y+83, pos_z+175, block_id)
mc.setBlock(pos_x+107, pos_y+83, pos_z+175, block_id)
mc.setBlock(pos_x+106, pos_y+83, pos_z+175, block_id)
mc.setBlock(pos_x+138, pos_y+85, pos_z+177, block_id)
mc.setBlock(pos_x+58, pos_y+86, pos_z+177, block_id)
mc.setBlock(pos_x+63, pos_y+86, pos_z+177, block_id)
mc.setBlock(pos_x+90, pos_y+83, pos_z+175, block_id)
mc.setBlock(pos_x+89, pos_y+83, pos_z+175, block_id)
mc.setBlock(pos_x+64, pos_y+83, pos_z+175, block_id)
mc.setBlock(pos_x+91, pos_y+86, pos_z+177, block_id)
mc.setBlock(pos_x+92, pos_y+86, pos_z+177, block_id)
mc.setBlock(pos_x+57, pos_y+83, pos_z+175, block_id)
mc.setBlock(pos_x+139, pos_y+82, pos_z+175, block_id)
mc.setBlock(pos_x+104, pos_y+86, pos_z+177, block_id)
mc.setBlock(pos_x+105, pos_y+86, pos_z+177, block_id)
mc.setBlock(pos_x+132, pos_y+82, pos_z+175, block_id)
mc.setBlock(pos_x+108, pos_y+82, pos_z+175, block_id)
mc.setBlock(pos_x+133, pos_y+86, pos_z+177, block_id)
mc.setBlock(pos_x+138, pos_y+86, pos_z+177, block_id)
mc.setBlock(pos_x+59, pos_y+87, pos_z+177, block_id)
mc.setBlock(pos_x+88, pos_y+82, pos_z+175, block_id)
mc.setBlock(pos_x+64, pos_y+82, pos_z+175, block_id)
mc.setBlock(pos_x+61, pos_y+87, pos_z+177, block_id)
mc.setBlock(pos_x+62, pos_y+87, pos_z+177, block_id)
mc.setBlock(pos_x+57, pos_y+82, pos_z+175, block_id)
mc.setBlock(pos_x+145, pos_y+81, pos_z+175, block_id)
mc.setBlock(pos_x+144, pos_y+81, pos_z+175, block_id)
mc.setBlock(pos_x+143, pos_y+81, pos_z+175, block_id)
mc.setBlock(pos_x+142, pos_y+81, pos_z+175, block_id)
mc.setBlock(pos_x+141, pos_y+81, pos_z+175, block_id)
mc.setBlock(pos_x+139, pos_y+81, pos_z+175, block_id)
mc.setBlock(pos_x+93, pos_y+87, pos_z+177, block_id)
mc.setBlock(pos_x+132, pos_y+81, pos_z+175, block_id)
mc.setBlock(pos_x+109, pos_y+81, pos_z+175, block_id)
mc.setBlock(pos_x+94, pos_y+87, pos_z+177, block_id)
mc.setBlock(pos_x+102, pos_y+87, pos_z+177, block_id)
mc.setBlock(pos_x+87, pos_y+81, pos_z+175, block_id)
mc.setBlock(pos_x+64, pos_y+81, pos_z+175, block_id)
mc.setBlock(pos_x+103, pos_y+87, pos_z+177, block_id)
mc.setBlock(pos_x+134, pos_y+87, pos_z+177, block_id)
mc.setBlock(pos_x+57, pos_y+81, pos_z+175, block_id)
mc.setBlock(pos_x+55, pos_y+81, pos_z+175, block_id)
mc.setBlock(pos_x+54, pos_y+81, pos_z+175, block_id)
mc.setBlock(pos_x+53, pos_y+81, pos_z+175, block_id)
mc.setBlock(pos_x+52, pos_y+81, pos_z+175, block_id)
mc.setBlock(pos_x+51, pos_y+81, pos_z+175, block_id)
mc.setBlock(pos_x+145, pos_y+80, pos_z+175, block_id)
mc.setBlock(pos_x+135, pos_y+87, pos_z+177, block_id)
mc.setBlock(pos_x+140, pos_y+80, pos_z+175, block_id)
mc.setBlock(pos_x+137, pos_y+87, pos_z+177, block_id)
mc.setBlock(pos_x+60, pos_y+88, pos_z+177, block_id)
mc.setBlock(pos_x+131, pos_y+80, pos_z+175, block_id)
mc.setBlock(pos_x+130, pos_y+80, pos_z+175, block_id)
mc.setBlock(pos_x+129, pos_y+80, pos_z+175, block_id)
mc.setBlock(pos_x+114, pos_y+80, pos_z+175, block_id)
mc.setBlock(pos_x+113, pos_y+80, pos_z+175, block_id)
mc.setBlock(pos_x+112, pos_y+80, pos_z+175, block_id)
mc.setBlock(pos_x+111, pos_y+80, pos_z+175, block_id)
mc.setBlock(pos_x+110, pos_y+80, pos_z+175, block_id)
mc.setBlock(pos_x+95, pos_y+88, pos_z+177, block_id)
mc.setBlock(pos_x+96, pos_y+88, pos_z+177, block_id)
mc.setBlock(pos_x+86, pos_y+80, pos_z+175, block_id)
mc.setBlock(pos_x+85, pos_y+80, pos_z+175, block_id)
mc.setBlock(pos_x+84, pos_y+80, pos_z+175, block_id)
mc.setBlock(pos_x+83, pos_y+80, pos_z+175, block_id)
mc.setBlock(pos_x+82, pos_y+80, pos_z+175, block_id)
mc.setBlock(pos_x+67, pos_y+80, pos_z+175, block_id)
mc.setBlock(pos_x+66, pos_y+80, pos_z+175, block_id)
mc.setBlock(pos_x+65, pos_y+80, pos_z+175, block_id)
mc.setBlock(pos_x+100, pos_y+88, pos_z+177, block_id)
mc.setBlock(pos_x+101, pos_y+88, pos_z+177, block_id)
mc.setBlock(pos_x+56, pos_y+80, pos_z+175, block_id)
mc.setBlock(pos_x+136, pos_y+88, pos_z+177, block_id)
mc.setBlock(pos_x+51, pos_y+80, pos_z+175, block_id)
mc.setBlock(pos_x+145, pos_y+79, pos_z+175, block_id)
mc.setBlock(pos_x+97, pos_y+89, pos_z+177, block_id)
mc.setBlock(pos_x+98, pos_y+89, pos_z+177, block_id)
mc.setBlock(pos_x+99, pos_y+89, pos_z+177, block_id)
mc.setBlock(pos_x+65, pos_y+116, pos_z+177, block_id)
mc.setBlock(pos_x+131, pos_y+116, pos_z+177, block_id)
mc.setBlock(pos_x+128, pos_y+79, pos_z+175, block_id)
mc.setBlock(pos_x+127, pos_y+79, pos_z+175, block_id)
mc.setBlock(pos_x+126, pos_y+79, pos_z+175, block_id)
mc.setBlock(pos_x+116, pos_y+79, pos_z+175, block_id)
mc.setBlock(pos_x+115, pos_y+79, pos_z+175, block_id)
mc.setBlock(pos_x+63, pos_y+117, pos_z+177, block_id)
mc.setBlock(pos_x+64, pos_y+117, pos_z+177, block_id)
mc.setBlock(pos_x+65, pos_y+117, pos_z+177, block_id)
mc.setBlock(pos_x+131, pos_y+117, pos_z+177, block_id)
mc.setBlock(pos_x+81, pos_y+79, pos_z+175, block_id)
mc.setBlock(pos_x+80, pos_y+79, pos_z+175, block_id)
mc.setBlock(pos_x+70, pos_y+79, pos_z+175, block_id)
mc.setBlock(pos_x+69, pos_y+79, pos_z+175, block_id)
mc.setBlock(pos_x+68, pos_y+79, pos_z+175, block_id)
mc.setBlock(pos_x+132, pos_y+117, pos_z+177, block_id)
mc.setBlock(pos_x+62, pos_y+118, pos_z+177, block_id)
mc.setBlock(pos_x+63, pos_y+118, pos_z+177, block_id)
mc.setBlock(pos_x+64, pos_y+118, pos_z+177, block_id)
mc.setBlock(pos_x+132, pos_y+118, pos_z+177, block_id)
mc.setBlock(pos_x+51, pos_y+79, pos_z+175, block_id)
mc.setBlock(pos_x+145, pos_y+78, pos_z+175, block_id)
mc.setBlock(pos_x+133, pos_y+118, pos_z+177, block_id)
mc.setBlock(pos_x+134, pos_y+118, pos_z+177, block_id)
mc.setBlock(pos_x+126, pos_y+78, pos_z+175, block_id)
mc.setBlock(pos_x+118, pos_y+78, pos_z+175, block_id)
mc.setBlock(pos_x+117, pos_y+78, pos_z+175, block_id)
mc.setBlock(pos_x+61, pos_y+119, pos_z+177, block_id)
mc.setBlock(pos_x+62, pos_y+119, pos_z+177, block_id)
mc.setBlock(pos_x+79, pos_y+78, pos_z+175, block_id)
mc.setBlock(pos_x+70, pos_y+78, pos_z+175, block_id)
mc.setBlock(pos_x+64, pos_y+119, pos_z+177, block_id)
mc.setBlock(pos_x+51, pos_y+78, pos_z+175, block_id)
mc.setBlock(pos_x+144, pos_y+77, pos_z+175, block_id)
mc.setBlock(pos_x+132, pos_y+119, pos_z+177, block_id)
mc.setBlock(pos_x+126, pos_y+77, pos_z+175, block_id)
mc.setBlock(pos_x+118, pos_y+77, pos_z+175, block_id)
mc.setBlock(pos_x+134, pos_y+119, pos_z+177, block_id)
mc.setBlock(pos_x+78, pos_y+77, pos_z+175, block_id)
mc.setBlock(pos_x+70, pos_y+77, pos_z+175, block_id)
mc.setBlock(pos_x+60, pos_y+120, pos_z+177, block_id)
mc.setBlock(pos_x+52, pos_y+77, pos_z+175, block_id)
mc.setBlock(pos_x+143, pos_y+76, pos_z+175, block_id)
mc.setBlock(pos_x+126, pos_y+76, pos_z+175, block_id)
mc.setBlock(pos_x+118, pos_y+76, pos_z+175, block_id)
mc.setBlock(pos_x+78, pos_y+76, pos_z+175, block_id)
mc.setBlock(pos_x+70, pos_y+76, pos_z+175, block_id)
mc.setBlock(pos_x+53, pos_y+76, pos_z+175, block_id)
mc.setBlock(pos_x+143, pos_y+75, pos_z+175, block_id)
mc.setBlock(pos_x+61, pos_y+120, pos_z+177, block_id)
mc.setBlock(pos_x+64, pos_y+120, pos_z+177, block_id)
mc.setBlock(pos_x+126, pos_y+75, pos_z+175, block_id)
mc.setBlock(pos_x+119, pos_y+75, pos_z+175, block_id)
mc.setBlock(pos_x+132, pos_y+120, pos_z+177, block_id)
mc.setBlock(pos_x+135, pos_y+120, pos_z+177, block_id)
mc.setBlock(pos_x+77, pos_y+75, pos_z+175, block_id)
mc.setBlock(pos_x+70, pos_y+75, pos_z+175, block_id)
mc.setBlock(pos_x+136, pos_y+120, pos_z+177, block_id)
mc.setBlock(pos_x+54, pos_y+75, pos_z+175, block_id)
mc.setBlock(pos_x+142, pos_y+74, pos_z+175, block_id)
mc.setBlock(pos_x+59, pos_y+121, pos_z+177, block_id)
mc.setBlock(pos_x+63, pos_y+121, pos_z+177, block_id)
mc.setBlock(pos_x+127, pos_y+74, pos_z+175, block_id)
mc.setBlock(pos_x+119, pos_y+74, pos_z+175, block_id)
mc.setBlock(pos_x+77, pos_y+74, pos_z+175, block_id)
mc.setBlock(pos_x+69, pos_y+74, pos_z+175, block_id)
mc.setBlock(pos_x+132, pos_y+121, pos_z+177, block_id)
mc.setBlock(pos_x+136, pos_y+121, pos_z+177, block_id)
mc.setBlock(pos_x+54, pos_y+74, pos_z+175, block_id)
mc.setBlock(pos_x+141, pos_y+73, pos_z+175, block_id)
mc.setBlock(pos_x+137, pos_y+121, pos_z+177, block_id)
mc.setBlock(pos_x+58, pos_y+122, pos_z+177, block_id)
mc.setBlock(pos_x+128, pos_y+73, pos_z+175, block_id)
mc.setBlock(pos_x+120, pos_y+73, pos_z+175, block_id)
mc.setBlock(pos_x+59, pos_y+122, pos_z+177, block_id)
mc.setBlock(pos_x+63, pos_y+122, pos_z+177, block_id)
mc.setBlock(pos_x+76, pos_y+73, pos_z+175, block_id)
mc.setBlock(pos_x+68, pos_y+73, pos_z+175, block_id)
mc.setBlock(pos_x+133, pos_y+122, pos_z+177, block_id)
mc.setBlock(pos_x+137, pos_y+122, pos_z+177, block_id)
mc.setBlock(pos_x+55, pos_y+73, pos_z+175, block_id)
mc.setBlock(pos_x+140, pos_y+72, pos_z+175, block_id)
mc.setBlock(pos_x+138, pos_y+122, pos_z+177, block_id)
mc.setBlock(pos_x+56, pos_y+123, pos_z+177, block_id)
mc.setBlock(pos_x+129, pos_y+72, pos_z+175, block_id)
mc.setBlock(pos_x+121, pos_y+72, pos_z+175, block_id)
mc.setBlock(pos_x+57, pos_y+123, pos_z+177, block_id)
mc.setBlock(pos_x+63, pos_y+123, pos_z+177, block_id)
mc.setBlock(pos_x+75, pos_y+72, pos_z+175, block_id)
mc.setBlock(pos_x+67, pos_y+72, pos_z+175, block_id)
mc.setBlock(pos_x+133, pos_y+123, pos_z+177, block_id)
mc.setBlock(pos_x+138, pos_y+123, pos_z+177, block_id)
mc.setBlock(pos_x+56, pos_y+72, pos_z+175, block_id)
mc.setBlock(pos_x+140, pos_y+71, pos_z+175, block_id)
mc.setBlock(pos_x+139, pos_y+71, pos_z+175, block_id)
mc.setBlock(pos_x+138, pos_y+71, pos_z+175, block_id)
mc.setBlock(pos_x+139, pos_y+123, pos_z+177, block_id)
mc.setBlock(pos_x+136, pos_y+71, pos_z+175, block_id)
mc.setBlock(pos_x+140, pos_y+123, pos_z+177, block_id)
mc.setBlock(pos_x+54, pos_y+124, pos_z+177, block_id)
mc.setBlock(pos_x+55, pos_y+124, pos_z+177, block_id)
mc.setBlock(pos_x+56, pos_y+124, pos_z+177, block_id)
mc.setBlock(pos_x+63, pos_y+124, pos_z+177, block_id)
mc.setBlock(pos_x+130, pos_y+71, pos_z+175, block_id)
mc.setBlock(pos_x+122, pos_y+71, pos_z+175, block_id)
mc.setBlock(pos_x+134, pos_y+124, pos_z+177, block_id)
mc.setBlock(pos_x+140, pos_y+124, pos_z+177, block_id)
mc.setBlock(pos_x+74, pos_y+71, pos_z+175, block_id)
mc.setBlock(pos_x+66, pos_y+71, pos_z+175, block_id)
mc.setBlock(pos_x+141, pos_y+124, pos_z+177, block_id)
mc.setBlock(pos_x+142, pos_y+124, pos_z+177, block_id)
mc.setBlock(pos_x+53, pos_y+125, pos_z+177, block_id)
mc.setBlock(pos_x+54, pos_y+125, pos_z+177, block_id)
mc.setBlock(pos_x+55, pos_y+125, pos_z+177, block_id)
mc.setBlock(pos_x+62, pos_y+125, pos_z+177, block_id)
mc.setBlock(pos_x+134, pos_y+125, pos_z+177, block_id)
mc.setBlock(pos_x+58, pos_y+71, pos_z+175, block_id)
mc.setBlock(pos_x+57, pos_y+71, pos_z+175, block_id)
mc.setBlock(pos_x+56, pos_y+71, pos_z+175, block_id)
mc.setBlock(pos_x+137, pos_y+70, pos_z+175, block_id)
mc.setBlock(pos_x+135, pos_y+70, pos_z+175, block_id)
mc.setBlock(pos_x+134, pos_y+70, pos_z+175, block_id)
mc.setBlock(pos_x+133, pos_y+70, pos_z+175, block_id)
mc.setBlock(pos_x+132, pos_y+70, pos_z+175, block_id)
mc.setBlock(pos_x+131, pos_y+70, pos_z+175, block_id)
mc.setBlock(pos_x+122, pos_y+70, pos_z+175, block_id)
mc.setBlock(pos_x+141, pos_y+125, pos_z+177, block_id)
mc.setBlock(pos_x+73, pos_y+70, pos_z+175, block_id)
mc.setBlock(pos_x+65, pos_y+70, pos_z+175, block_id)
mc.setBlock(pos_x+64, pos_y+70, pos_z+175, block_id)
mc.setBlock(pos_x+63, pos_y+70, pos_z+175, block_id)
mc.setBlock(pos_x+62, pos_y+70, pos_z+175, block_id)
mc.setBlock(pos_x+61, pos_y+70, pos_z+175, block_id)
mc.setBlock(pos_x+60, pos_y+70, pos_z+175, block_id)
mc.setBlock(pos_x+59, pos_y+70, pos_z+175, block_id)
mc.setBlock(pos_x+123, pos_y+69, pos_z+175, block_id)
mc.setBlock(pos_x+73, pos_y+69, pos_z+175, block_id)
mc.setBlock(pos_x+124, pos_y+68, pos_z+175, block_id)
mc.setBlock(pos_x+142, pos_y+125, pos_z+177, block_id)
mc.setBlock(pos_x+72, pos_y+68, pos_z+175, block_id)
mc.setBlock(pos_x+125, pos_y+67, pos_z+175, block_id)
mc.setBlock(pos_x+143, pos_y+125, pos_z+177, block_id)
mc.setBlock(pos_x+44, pos_y+126, pos_z+177, block_id)
mc.setBlock(pos_x+71, pos_y+67, pos_z+175, block_id)
mc.setBlock(pos_x+125, pos_y+66, pos_z+175, block_id)
mc.setBlock(pos_x+45, pos_y+126, pos_z+177, block_id)
mc.setBlock(pos_x+46, pos_y+126, pos_z+177, block_id)
mc.setBlock(pos_x+71, pos_y+66, pos_z+175, block_id)
mc.setBlock(pos_x+125, pos_y+65, pos_z+175, block_id)
mc.setBlock(pos_x+124, pos_y+65, pos_z+175, block_id)
mc.setBlock(pos_x+47, pos_y+126, pos_z+177, block_id)
mc.setBlock(pos_x+48, pos_y+126, pos_z+177, block_id)
mc.setBlock(pos_x+49, pos_y+126, pos_z+177, block_id)
mc.setBlock(pos_x+50, pos_y+126, pos_z+177, block_id)
mc.setBlock(pos_x+51, pos_y+126, pos_z+177, block_id)
mc.setBlock(pos_x+52, pos_y+126, pos_z+177, block_id)
mc.setBlock(pos_x+72, pos_y+65, pos_z+175, block_id)
mc.setBlock(pos_x+71, pos_y+65, pos_z+175, block_id)
mc.setBlock(pos_x+124, pos_y+64, pos_z+175, block_id)
mc.setBlock(pos_x+53, pos_y+126, pos_z+177, block_id)
mc.setBlock(pos_x+62, pos_y+126, pos_z+177, block_id)
mc.setBlock(pos_x+119, pos_y+64, pos_z+175, block_id)
mc.setBlock(pos_x+118, pos_y+64, pos_z+175, block_id)
mc.setBlock(pos_x+134, pos_y+126, pos_z+177, block_id)
mc.setBlock(pos_x+143, pos_y+126, pos_z+177, block_id)
mc.setBlock(pos_x+78, pos_y+64, pos_z+175, block_id)
mc.setBlock(pos_x+77, pos_y+64, pos_z+175, block_id)
mc.setBlock(pos_x+144, pos_y+126, pos_z+177, block_id)
mc.setBlock(pos_x+73, pos_y+64, pos_z+175, block_id)
mc.setBlock(pos_x+72, pos_y+64, pos_z+175, block_id)
mc.setBlock(pos_x+123, pos_y+63, pos_z+175, block_id)
mc.setBlock(pos_x+145, pos_y+126, pos_z+177, block_id)
mc.setBlock(pos_x+146, pos_y+126, pos_z+177, block_id)
mc.setBlock(pos_x+120, pos_y+63, pos_z+175, block_id)
mc.setBlock(pos_x+117, pos_y+63, pos_z+175, block_id)
mc.setBlock(pos_x+79, pos_y+63, pos_z+175, block_id)
mc.setBlock(pos_x+76, pos_y+63, pos_z+175, block_id)
mc.setBlock(pos_x+147, pos_y+126, pos_z+177, block_id)
mc.setBlock(pos_x+148, pos_y+126, pos_z+177, block_id)
mc.setBlock(pos_x+73, pos_y+63, pos_z+175, block_id)
mc.setBlock(pos_x+123, pos_y+62, pos_z+175, block_id)
mc.setBlock(pos_x+122, pos_y+62, pos_z+175, block_id)
mc.setBlock(pos_x+121, pos_y+62, pos_z+175, block_id)
mc.setBlock(pos_x+118, pos_y+62, pos_z+175, block_id)
mc.setBlock(pos_x+78, pos_y+62, pos_z+175, block_id)
mc.setBlock(pos_x+75, pos_y+62, pos_z+175, block_id)
mc.setBlock(pos_x+74, pos_y+62, pos_z+175, block_id)
mc.setBlock(pos_x+73, pos_y+62, pos_z+175, block_id)
mc.setBlock(pos_x+122, pos_y+61, pos_z+175, block_id)
mc.setBlock(pos_x+118, pos_y+61, pos_z+175, block_id)
mc.setBlock(pos_x+78, pos_y+61, pos_z+175, block_id)
mc.setBlock(pos_x+74, pos_y+61, pos_z+175, block_id)
mc.setBlock(pos_x+119, pos_y+60, pos_z+175, block_id)
mc.setBlock(pos_x+149, pos_y+126, pos_z+177, block_id)
mc.setBlock(pos_x+150, pos_y+126, pos_z+177, block_id)
mc.setBlock(pos_x+77, pos_y+60, pos_z+175, block_id)
mc.setBlock(pos_x+119, pos_y+59, pos_z+175, block_id)
mc.setBlock(pos_x+77, pos_y+59, pos_z+175, block_id)
mc.setBlock(pos_x+120, pos_y+58, pos_z+175, block_id)
mc.setBlock(pos_x+151, pos_y+126, pos_z+177, block_id)
mc.setBlock(pos_x+152, pos_y+126, pos_z+177, block_id)
mc.setBlock(pos_x+76, pos_y+58, pos_z+175, block_id)
mc.setBlock(pos_x+120, pos_y+57, pos_z+175, block_id)
mc.setBlock(pos_x+76, pos_y+57, pos_z+175, block_id)
mc.setBlock(pos_x+120, pos_y+56, pos_z+175, block_id)
mc.setBlock(pos_x+76, pos_y+56, pos_z+175, block_id)
mc.setBlock(pos_x+120, pos_y+55, pos_z+175, block_id)
mc.setBlock(pos_x+76, pos_y+55, pos_z+175, block_id)
mc.setBlock(pos_x+121, pos_y+54, pos_z+175, block_id)
mc.setBlock(pos_x+45, pos_y+127, pos_z+177, block_id)
mc.setBlock(pos_x+61, pos_y+127, pos_z+177, block_id)
mc.setBlock(pos_x+75, pos_y+54, pos_z+175, block_id)
mc.setBlock(pos_x+121, pos_y+53, pos_z+175, block_id)
mc.setBlock(pos_x+75, pos_y+53, pos_z+175, block_id)
mc.setBlock(pos_x+121, pos_y+52, pos_z+175, block_id)
mc.setBlock(pos_x+75, pos_y+52, pos_z+175, block_id)
mc.setBlock(pos_x+121, pos_y+51, pos_z+175, block_id)
mc.setBlock(pos_x+75, pos_y+51, pos_z+175, block_id)
mc.setBlock(pos_x+122, pos_y+50, pos_z+175, block_id)
mc.setBlock(pos_x+135, pos_y+127, pos_z+177, block_id)
mc.setBlock(pos_x+151, pos_y+127, pos_z+177, block_id)
mc.setBlock(pos_x+74, pos_y+50, pos_z+175, block_id)
mc.setBlock(pos_x+122, pos_y+49, pos_z+175, block_id)
mc.setBlock(pos_x+74, pos_y+49, pos_z+175, block_id)
mc.setBlock(pos_x+122, pos_y+48, pos_z+175, block_id)
mc.setBlock(pos_x+74, pos_y+48, pos_z+175, block_id)
mc.setBlock(pos_x+122, pos_y+47, pos_z+175, block_id)
mc.setBlock(pos_x+74, pos_y+47, pos_z+175, block_id)
mc.setBlock(pos_x+123, pos_y+46, pos_z+175, block_id)
mc.setBlock(pos_x+46, pos_y+128, pos_z+177, block_id)
mc.setBlock(pos_x+59, pos_y+128, pos_z+177, block_id)
mc.setBlock(pos_x+73, pos_y+46, pos_z+175, block_id)
mc.setBlock(pos_x+125, pos_y+45, pos_z+175, block_id)
mc.setBlock(pos_x+124, pos_y+45, pos_z+175, block_id)
mc.setBlock(pos_x+60, pos_y+128, pos_z+177, block_id)
mc.setBlock(pos_x+61, pos_y+128, pos_z+177, block_id)
mc.setBlock(pos_x+72, pos_y+45, pos_z+175, block_id)
mc.setBlock(pos_x+71, pos_y+45, pos_z+175, block_id)
mc.setBlock(pos_x+127, pos_y+44, pos_z+175, block_id)
mc.setBlock(pos_x+126, pos_y+44, pos_z+175, block_id)
mc.setBlock(pos_x+135, pos_y+128, pos_z+177, block_id)
mc.setBlock(pos_x+136, pos_y+128, pos_z+177, block_id)
mc.setBlock(pos_x+70, pos_y+44, pos_z+175, block_id)
mc.setBlock(pos_x+69, pos_y+44, pos_z+175, block_id)
mc.setBlock(pos_x+129, pos_y+43, pos_z+175, block_id)
mc.setBlock(pos_x+128, pos_y+43, pos_z+175, block_id)
mc.setBlock(pos_x+137, pos_y+128, pos_z+177, block_id)
mc.setBlock(pos_x+150, pos_y+128, pos_z+177, block_id)
mc.setBlock(pos_x+68, pos_y+43, pos_z+175, block_id)
mc.setBlock(pos_x+67, pos_y+43, pos_z+175, block_id)
mc.setBlock(pos_x+130, pos_y+42, pos_z+175, block_id)
mc.setBlock(pos_x+66, pos_y+42, pos_z+175, block_id)
mc.setBlock(pos_x+131, pos_y+41, pos_z+175, block_id)
mc.setBlock(pos_x+65, pos_y+41, pos_z+175, block_id)
mc.setBlock(pos_x+132, pos_y+40, pos_z+175, block_id)
mc.setBlock(pos_x+47, pos_y+129, pos_z+177, block_id)
mc.setBlock(pos_x+64, pos_y+40, pos_z+175, block_id)
mc.setBlock(pos_x+133, pos_y+39, pos_z+175, block_id)
mc.setBlock(pos_x+58, pos_y+129, pos_z+177, block_id)
mc.setBlock(pos_x+59, pos_y+129, pos_z+177, block_id)
mc.setBlock(pos_x+63, pos_y+39, pos_z+175, block_id)
mc.setBlock(pos_x+134, pos_y+38, pos_z+175, block_id)
mc.setBlock(pos_x+60, pos_y+129, pos_z+177, block_id)
mc.setBlock(pos_x+136, pos_y+129, pos_z+177, block_id)
mc.setBlock(pos_x+62, pos_y+38, pos_z+175, block_id)
mc.setBlock(pos_x+134, pos_y+37, pos_z+175, block_id)
mc.setBlock(pos_x+62, pos_y+37, pos_z+175, block_id)
mc.setBlock(pos_x+135, pos_y+36, pos_z+175, block_id)
mc.setBlock(pos_x+137, pos_y+129, pos_z+177, block_id)
mc.setBlock(pos_x+138, pos_y+129, pos_z+177, block_id)
mc.setBlock(pos_x+61, pos_y+36, pos_z+175, block_id)
mc.setBlock(pos_x+135, pos_y+35, pos_z+175, block_id)
mc.setBlock(pos_x+61, pos_y+35, pos_z+175, block_id)
mc.setBlock(pos_x+135, pos_y+34, pos_z+175, block_id)
mc.setBlock(pos_x+61, pos_y+34, pos_z+175, block_id)
mc.setBlock(pos_x+136, pos_y+33, pos_z+175, block_id)
mc.setBlock(pos_x+148, pos_y+129, pos_z+177, block_id)
mc.setBlock(pos_x+149, pos_y+129, pos_z+177, block_id)
mc.setBlock(pos_x+60, pos_y+33, pos_z+175, block_id)
mc.setBlock(pos_x+136, pos_y+32, pos_z+175, block_id)
mc.setBlock(pos_x+60, pos_y+32, pos_z+175, block_id)
mc.setBlock(pos_x+137, pos_y+31, pos_z+175, block_id)
mc.setBlock(pos_x+48, pos_y+130, pos_z+177, block_id)
mc.setBlock(pos_x+60, pos_y+31, pos_z+175, block_id)
mc.setBlock(pos_x+137, pos_y+30, pos_z+175, block_id)
mc.setBlock(pos_x+59, pos_y+30, pos_z+175, block_id)
mc.setBlock(pos_x+137, pos_y+29, pos_z+175, block_id)
mc.setBlock(pos_x+59, pos_y+29, pos_z+175, block_id)
mc.setBlock(pos_x+137, pos_y+28, pos_z+175, block_id)
mc.setBlock(pos_x+59, pos_y+28, pos_z+175, block_id)
mc.setBlock(pos_x+137, pos_y+27, pos_z+175, block_id)
mc.setBlock(pos_x+59, pos_y+27, pos_z+175, block_id)
mc.setBlock(pos_x+137, pos_y+26, pos_z+175, block_id)
mc.setBlock(pos_x+59, pos_y+26, pos_z+175, block_id)
mc.setBlock(pos_x+137, pos_y+25, pos_z+175, block_id)
mc.setBlock(pos_x+59, pos_y+25, pos_z+175, block_id)
mc.setBlock(pos_x+138, pos_y+24, pos_z+175, block_id)
mc.setBlock(pos_x+49, pos_y+130, pos_z+177, block_id)
mc.setBlock(pos_x+55, pos_y+130, pos_z+177, block_id)
mc.setBlock(pos_x+58, pos_y+24, pos_z+175, block_id)
mc.setBlock(pos_x+138, pos_y+23, pos_z+175, block_id)
mc.setBlock(pos_x+56, pos_y+130, pos_z+177, block_id)
mc.setBlock(pos_x+57, pos_y+130, pos_z+177, block_id)
mc.setBlock(pos_x+58, pos_y+130, pos_z+177, block_id)
mc.setBlock(pos_x+138, pos_y+130, pos_z+177, block_id)
mc.setBlock(pos_x+139, pos_y+130, pos_z+177, block_id)
mc.setBlock(pos_x+140, pos_y+130, pos_z+177, block_id)
mc.setBlock(pos_x+58, pos_y+23, pos_z+175, block_id)
mc.setBlock(pos_x+137, pos_y+22, pos_z+175, block_id)
mc.setBlock(pos_x+141, pos_y+130, pos_z+177, block_id)
mc.setBlock(pos_x+147, pos_y+130, pos_z+177, block_id)
mc.setBlock(pos_x+50, pos_y+131, pos_z+177, block_id)
mc.setBlock(pos_x+53, pos_y+131, pos_z+177, block_id)
mc.setBlock(pos_x+59, pos_y+22, pos_z+175, block_id)
mc.setBlock(pos_x+137, pos_y+21, pos_z+175, block_id)
mc.setBlock(pos_x+54, pos_y+131, pos_z+177, block_id)
mc.setBlock(pos_x+113, pos_y+21, pos_z+175, block_id)
mc.setBlock(pos_x+55, pos_y+131, pos_z+177, block_id)
mc.setBlock(pos_x+56, pos_y+131, pos_z+177, block_id)
mc.setBlock(pos_x+83, pos_y+21, pos_z+175, block_id)
mc.setBlock(pos_x+140, pos_y+131, pos_z+177, block_id)
mc.setBlock(pos_x+59, pos_y+21, pos_z+175, block_id)
mc.setBlock(pos_x+137, pos_y+20, pos_z+175, block_id)
mc.setBlock(pos_x+141, pos_y+131, pos_z+177, block_id)
mc.setBlock(pos_x+114, pos_y+20, pos_z+175, block_id)
mc.setBlock(pos_x+112, pos_y+20, pos_z+175, block_id)
mc.setBlock(pos_x+142, pos_y+131, pos_z+177, block_id)
mc.setBlock(pos_x+143, pos_y+131, pos_z+177, block_id)
mc.setBlock(pos_x+84, pos_y+20, pos_z+175, block_id)
mc.setBlock(pos_x+82, pos_y+20, pos_z+175, block_id)
mc.setBlock(pos_x+146, pos_y+131, pos_z+177, block_id)
mc.setBlock(pos_x+59, pos_y+20, pos_z+175, block_id)
mc.setBlock(pos_x+137, pos_y+19, pos_z+175, block_id)
mc.setBlock(pos_x+51, pos_y+132, pos_z+177, block_id)
mc.setBlock(pos_x+115, pos_y+19, pos_z+175, block_id)
mc.setBlock(pos_x+111, pos_y+19, pos_z+175, block_id)
mc.setBlock(pos_x+85, pos_y+19, pos_z+175, block_id)
mc.setBlock(pos_x+81, pos_y+19, pos_z+175, block_id)
mc.setBlock(pos_x+52, pos_y+132, pos_z+177, block_id)
mc.setBlock(pos_x+59, pos_y+19, pos_z+175, block_id)
mc.setBlock(pos_x+137, pos_y+18, pos_z+175, block_id)
mc.setBlock(pos_x+53, pos_y+132, pos_z+177, block_id)
mc.setBlock(pos_x+116, pos_y+18, pos_z+175, block_id)
mc.setBlock(pos_x+111, pos_y+18, pos_z+175, block_id)
mc.setBlock(pos_x+110, pos_y+18, pos_z+175, block_id)
mc.setBlock(pos_x+54, pos_y+132, pos_z+177, block_id)
mc.setBlock(pos_x+142, pos_y+132, pos_z+177, block_id)
mc.setBlock(pos_x+86, pos_y+18, pos_z+175, block_id)
mc.setBlock(pos_x+80, pos_y+18, pos_z+175, block_id)
mc.setBlock(pos_x+143, pos_y+132, pos_z+177, block_id)
mc.setBlock(pos_x+59, pos_y+18, pos_z+175, block_id)
mc.setBlock(pos_x+136, pos_y+17, pos_z+175, block_id)
mc.setBlock(pos_x+144, pos_y+132, pos_z+177, block_id)
mc.setBlock(pos_x+116, pos_y+17, pos_z+175, block_id)
mc.setBlock(pos_x+109, pos_y+17, pos_z+175, block_id)
mc.setBlock(pos_x+145, pos_y+132, pos_z+177, block_id)
mc.setBlock(pos_x+60, pos_y+0, pos_z+178, block_id)
mc.setBlock(pos_x+61, pos_y+0, pos_z+178, block_id)
mc.setBlock(pos_x+88, pos_y+17, pos_z+175, block_id)
mc.setBlock(pos_x+87, pos_y+17, pos_z+175, block_id)
mc.setBlock(pos_x+80, pos_y+17, pos_z+175, block_id)
mc.setBlock(pos_x+60, pos_y+17, pos_z+175, block_id)
mc.setBlock(pos_x+136, pos_y+16, pos_z+175, block_id)
mc.setBlock(pos_x+62, pos_y+0, pos_z+178, block_id)
mc.setBlock(pos_x+117, pos_y+16, pos_z+175, block_id)
mc.setBlock(pos_x+108, pos_y+16, pos_z+175, block_id)
mc.setBlock(pos_x+107, pos_y+16, pos_z+175, block_id)
mc.setBlock(pos_x+106, pos_y+16, pos_z+175, block_id)
mc.setBlock(pos_x+105, pos_y+16, pos_z+175, block_id)
mc.setBlock(pos_x+104, pos_y+16, pos_z+175, block_id)
mc.setBlock(pos_x+63, pos_y+0, pos_z+178, block_id)
mc.setBlock(pos_x+64, pos_y+0, pos_z+178, block_id)
mc.setBlock(pos_x+65, pos_y+0, pos_z+178, block_id)
mc.setBlock(pos_x+66, pos_y+0, pos_z+178, block_id)
mc.setBlock(pos_x+67, pos_y+0, pos_z+178, block_id)
mc.setBlock(pos_x+68, pos_y+0, pos_z+178, block_id)
mc.setBlock(pos_x+92, pos_y+16, pos_z+175, block_id)
mc.setBlock(pos_x+91, pos_y+16, pos_z+175, block_id)
mc.setBlock(pos_x+90, pos_y+16, pos_z+175, block_id)
mc.setBlock(pos_x+89, pos_y+16, pos_z+175, block_id)
mc.setBlock(pos_x+79, pos_y+16, pos_z+175, block_id)
mc.setBlock(pos_x+69, pos_y+0, pos_z+178, block_id)
mc.setBlock(pos_x+60, pos_y+16, pos_z+175, block_id)
mc.setBlock(pos_x+135, pos_y+15, pos_z+175, block_id)
mc.setBlock(pos_x+117, pos_y+15, pos_z+175, block_id)
mc.setBlock(pos_x+103, pos_y+15, pos_z+175, block_id)
mc.setBlock(pos_x+102, pos_y+15, pos_z+175, block_id)
mc.setBlock(pos_x+101, pos_y+15, pos_z+175, block_id)
mc.setBlock(pos_x+100, pos_y+15, pos_z+175, block_id)
mc.setBlock(pos_x+99, pos_y+15, pos_z+175, block_id)
mc.setBlock(pos_x+70, pos_y+0, pos_z+178, block_id)
mc.setBlock(pos_x+97, pos_y+15, pos_z+175, block_id)
mc.setBlock(pos_x+96, pos_y+15, pos_z+175, block_id)
mc.setBlock(pos_x+95, pos_y+15, pos_z+175, block_id)
mc.setBlock(pos_x+94, pos_y+15, pos_z+175, block_id)
mc.setBlock(pos_x+93, pos_y+15, pos_z+175, block_id)
mc.setBlock(pos_x+79, pos_y+15, pos_z+175, block_id)
mc.setBlock(pos_x+61, pos_y+15, pos_z+175, block_id)
mc.setBlock(pos_x+135, pos_y+14, pos_z+175, block_id)
mc.setBlock(pos_x+71, pos_y+0, pos_z+178, block_id)
mc.setBlock(pos_x+72, pos_y+0, pos_z+178, block_id)
mc.setBlock(pos_x+117, pos_y+14, pos_z+175, block_id)
mc.setBlock(pos_x+98, pos_y+14, pos_z+175, block_id)
mc.setBlock(pos_x+79, pos_y+14, pos_z+175, block_id)
mc.setBlock(pos_x+73, pos_y+0, pos_z+178, block_id)
mc.setBlock(pos_x+62, pos_y+14, pos_z+175, block_id)
mc.setBlock(pos_x+134, pos_y+13, pos_z+175, block_id)
mc.setBlock(pos_x+74, pos_y+0, pos_z+178, block_id)
mc.setBlock(pos_x+75, pos_y+0, pos_z+178, block_id)
mc.setBlock(pos_x+117, pos_y+13, pos_z+175, block_id)
mc.setBlock(pos_x+78, pos_y+13, pos_z+175, block_id)
mc.setBlock(pos_x+76, pos_y+0, pos_z+178, block_id)
mc.setBlock(pos_x+62, pos_y+13, pos_z+175, block_id)
mc.setBlock(pos_x+133, pos_y+12, pos_z+175, block_id)
mc.setBlock(pos_x+118, pos_y+12, pos_z+175, block_id)
mc.setBlock(pos_x+78, pos_y+12, pos_z+175, block_id)
mc.setBlock(pos_x+63, pos_y+12, pos_z+175, block_id)
mc.setBlock(pos_x+134, pos_y+11, pos_z+175, block_id)
mc.setBlock(pos_x+77, pos_y+0, pos_z+178, block_id)
mc.setBlock(pos_x+118, pos_y+11, pos_z+175, block_id)
mc.setBlock(pos_x+78, pos_y+11, pos_z+175, block_id)
mc.setBlock(pos_x+62, pos_y+11, pos_z+175, block_id)
mc.setBlock(pos_x+134, pos_y+10, pos_z+175, block_id)
mc.setBlock(pos_x+118, pos_y+10, pos_z+175, block_id)
mc.setBlock(pos_x+78, pos_y+10, pos_z+175, block_id)
mc.setBlock(pos_x+62, pos_y+10, pos_z+175, block_id)
mc.setBlock(pos_x+135, pos_y+9, pos_z+175, block_id)
mc.setBlock(pos_x+78, pos_y+0, pos_z+178, block_id)
