from mcpi.minecraft import Minecraft
mc = Minecraft.create("mc2.tokyocodingclub.com")
playerId = mc.getPlayerEntityId("TCCMinecraft008")

pos_x, pos_y, pos_z = mc.entity.getPos(playerId)
block_id = 155

mc.setBlock(pos_x+32, pos_y+32, pos_z+41, block_id)
mc.setBlock(pos_x+17, pos_y+33, pos_z+41, block_id)
mc.setBlock(pos_x+18, pos_y+33, pos_z+41, block_id)
mc.setBlock(pos_x+19, pos_y+33, pos_z+41, block_id)
mc.setBlock(pos_x+20, pos_y+33, pos_z+41, block_id)
mc.setBlock(pos_x+21, pos_y+33, pos_z+41, block_id)
mc.setBlock(pos_x+28, pos_y+33, pos_z+41, block_id)
mc.setBlock(pos_x+29, pos_y+33, pos_z+41, block_id)
mc.setBlock(pos_x+30, pos_y+33, pos_z+41, block_id)
mc.setBlock(pos_x+16, pos_y+32, pos_z+41, block_id)
mc.setBlock(pos_x+33, pos_y+31, pos_z+41, block_id)
mc.setBlock(pos_x+31, pos_y+33, pos_z+41, block_id)
mc.setBlock(pos_x+32, pos_y+33, pos_z+41, block_id)
mc.setBlock(pos_x+18, pos_y+34, pos_z+41, block_id)
mc.setBlock(pos_x+19, pos_y+34, pos_z+41, block_id)
mc.setBlock(pos_x+16, pos_y+31, pos_z+41, block_id)
mc.setBlock(pos_x+34, pos_y+30, pos_z+41, block_id)
mc.setBlock(pos_x+20, pos_y+34, pos_z+41, block_id)
mc.setBlock(pos_x+21, pos_y+34, pos_z+41, block_id)
mc.setBlock(pos_x+22, pos_y+34, pos_z+41, block_id)
mc.setBlock(pos_x+23, pos_y+34, pos_z+41, block_id)
mc.setBlock(pos_x+15, pos_y+30, pos_z+41, block_id)
mc.setBlock(pos_x+34, pos_y+29, pos_z+41, block_id)
mc.setBlock(pos_x+24, pos_y+34, pos_z+41, block_id)
mc.setBlock(pos_x+25, pos_y+34, pos_z+41, block_id)
mc.setBlock(pos_x+15, pos_y+29, pos_z+41, block_id)
mc.setBlock(pos_x+34, pos_y+28, pos_z+41, block_id)
mc.setBlock(pos_x+26, pos_y+34, pos_z+41, block_id)
mc.setBlock(pos_x+27, pos_y+34, pos_z+41, block_id)
mc.setBlock(pos_x+15, pos_y+28, pos_z+41, block_id)
mc.setBlock(pos_x+34, pos_y+27, pos_z+41, block_id)
mc.setBlock(pos_x+28, pos_y+34, pos_z+41, block_id)
mc.setBlock(pos_x+14, pos_y+27, pos_z+41, block_id)
mc.setBlock(pos_x+35, pos_y+26, pos_z+41, block_id)
mc.setBlock(pos_x+29, pos_y+34, pos_z+41, block_id)
mc.setBlock(pos_x+4, pos_y+0, pos_z+42, block_id)
mc.setBlock(pos_x+14, pos_y+26, pos_z+41, block_id)
mc.setBlock(pos_x+35, pos_y+25, pos_z+41, block_id)
mc.setBlock(pos_x+5, pos_y+0, pos_z+42, block_id)
mc.setBlock(pos_x+6, pos_y+0, pos_z+42, block_id)
mc.setBlock(pos_x+14, pos_y+25, pos_z+41, block_id)
mc.setBlock(pos_x+35, pos_y+24, pos_z+41, block_id)
mc.setBlock(pos_x+7, pos_y+0, pos_z+42, block_id)
mc.setBlock(pos_x+8, pos_y+0, pos_z+42, block_id)
mc.setBlock(pos_x+14, pos_y+24, pos_z+41, block_id)
mc.setBlock(pos_x+35, pos_y+23, pos_z+41, block_id)
mc.setBlock(pos_x+9, pos_y+0, pos_z+42, block_id)
mc.setBlock(pos_x+13, pos_y+23, pos_z+41, block_id)
mc.setBlock(pos_x+36, pos_y+22, pos_z+41, block_id)
mc.setBlock(pos_x+10, pos_y+0, pos_z+42, block_id)
mc.setBlock(pos_x+11, pos_y+0, pos_z+42, block_id)
mc.setBlock(pos_x+13, pos_y+22, pos_z+41, block_id)
mc.setBlock(pos_x+36, pos_y+21, pos_z+41, block_id)
mc.setBlock(pos_x+12, pos_y+0, pos_z+42, block_id)
mc.setBlock(pos_x+13, pos_y+0, pos_z+42, block_id)
mc.setBlock(pos_x+13, pos_y+21, pos_z+41, block_id)
mc.setBlock(pos_x+36, pos_y+20, pos_z+41, block_id)
mc.setBlock(pos_x+36, pos_y+0, pos_z+42, block_id)
mc.setBlock(pos_x+13, pos_y+20, pos_z+41, block_id)
mc.setBlock(pos_x+44, pos_y+19, pos_z+41, block_id)
mc.setBlock(pos_x+43, pos_y+19, pos_z+41, block_id)
mc.setBlock(pos_x+42, pos_y+19, pos_z+41, block_id)
mc.setBlock(pos_x+41, pos_y+19, pos_z+41, block_id)
mc.setBlock(pos_x+40, pos_y+19, pos_z+41, block_id)
mc.setBlock(pos_x+39, pos_y+19, pos_z+41, block_id)
mc.setBlock(pos_x+38, pos_y+19, pos_z+41, block_id)
mc.setBlock(pos_x+37, pos_y+19, pos_z+41, block_id)
mc.setBlock(pos_x+37, pos_y+0, pos_z+42, block_id)
mc.setBlock(pos_x+38, pos_y+0, pos_z+42, block_id)
mc.setBlock(pos_x+12, pos_y+19, pos_z+41, block_id)
mc.setBlock(pos_x+11, pos_y+19, pos_z+41, block_id)
mc.setBlock(pos_x+10, pos_y+19, pos_z+41, block_id)
mc.setBlock(pos_x+9, pos_y+19, pos_z+41, block_id)
mc.setBlock(pos_x+8, pos_y+19, pos_z+41, block_id)
mc.setBlock(pos_x+7, pos_y+19, pos_z+41, block_id)
mc.setBlock(pos_x+6, pos_y+19, pos_z+41, block_id)
mc.setBlock(pos_x+5, pos_y+19, pos_z+41, block_id)
mc.setBlock(pos_x+45, pos_y+18, pos_z+41, block_id)
mc.setBlock(pos_x+39, pos_y+0, pos_z+42, block_id)
mc.setBlock(pos_x+40, pos_y+0, pos_z+42, block_id)
mc.setBlock(pos_x+41, pos_y+0, pos_z+42, block_id)
mc.setBlock(pos_x+42, pos_y+0, pos_z+42, block_id)
mc.setBlock(pos_x+43, pos_y+0, pos_z+42, block_id)
mc.setBlock(pos_x+44, pos_y+0, pos_z+42, block_id)
mc.setBlock(pos_x+45, pos_y+0, pos_z+42, block_id)
mc.setBlock(pos_x+4, pos_y+18, pos_z+41, block_id)
mc.setBlock(pos_x+45, pos_y+17, pos_z+41, block_id)
mc.setBlock(pos_x+4, pos_y+1, pos_z+42, block_id)
mc.setBlock(pos_x+13, pos_y+1, pos_z+42, block_id)
mc.setBlock(pos_x+36, pos_y+1, pos_z+42, block_id)
mc.setBlock(pos_x+45, pos_y+1, pos_z+42, block_id)
mc.setBlock(pos_x+4, pos_y+2, pos_z+42, block_id)
mc.setBlock(pos_x+3, pos_y+17, pos_z+41, block_id)
mc.setBlock(pos_x+46, pos_y+16, pos_z+41, block_id)
mc.setBlock(pos_x+13, pos_y+2, pos_z+42, block_id)
mc.setBlock(pos_x+36, pos_y+2, pos_z+42, block_id)
mc.setBlock(pos_x+45, pos_y+2, pos_z+42, block_id)
mc.setBlock(pos_x+4, pos_y+3, pos_z+42, block_id)
mc.setBlock(pos_x+3, pos_y+16, pos_z+41, block_id)
mc.setBlock(pos_x+46, pos_y+15, pos_z+41, block_id)
mc.setBlock(pos_x+13, pos_y+3, pos_z+42, block_id)
mc.setBlock(pos_x+36, pos_y+3, pos_z+42, block_id)
mc.setBlock(pos_x+45, pos_y+3, pos_z+42, block_id)
mc.setBlock(pos_x+4, pos_y+4, pos_z+42, block_id)
mc.setBlock(pos_x+3, pos_y+15, pos_z+41, block_id)
mc.setBlock(pos_x+46, pos_y+14, pos_z+41, block_id)
mc.setBlock(pos_x+13, pos_y+4, pos_z+42, block_id)
mc.setBlock(pos_x+16, pos_y+4, pos_z+42, block_id)
mc.setBlock(pos_x+3, pos_y+14, pos_z+41, block_id)
mc.setBlock(pos_x+46, pos_y+13, pos_z+41, block_id)
mc.setBlock(pos_x+17, pos_y+4, pos_z+42, block_id)
mc.setBlock(pos_x+18, pos_y+4, pos_z+42, block_id)
mc.setBlock(pos_x+19, pos_y+4, pos_z+42, block_id)
mc.setBlock(pos_x+2, pos_y+13, pos_z+41, block_id)
mc.setBlock(pos_x+47, pos_y+12, pos_z+41, block_id)
mc.setBlock(pos_x+20, pos_y+4, pos_z+42, block_id)
mc.setBlock(pos_x+21, pos_y+4, pos_z+42, block_id)
mc.setBlock(pos_x+22, pos_y+4, pos_z+42, block_id)
mc.setBlock(pos_x+23, pos_y+4, pos_z+42, block_id)
mc.setBlock(pos_x+2, pos_y+12, pos_z+41, block_id)
mc.setBlock(pos_x+47, pos_y+11, pos_z+41, block_id)
mc.setBlock(pos_x+24, pos_y+4, pos_z+42, block_id)
mc.setBlock(pos_x+25, pos_y+4, pos_z+42, block_id)
mc.setBlock(pos_x+26, pos_y+4, pos_z+42, block_id)
mc.setBlock(pos_x+27, pos_y+4, pos_z+42, block_id)
mc.setBlock(pos_x+2, pos_y+11, pos_z+41, block_id)
mc.setBlock(pos_x+47, pos_y+10, pos_z+41, block_id)
mc.setBlock(pos_x+28, pos_y+4, pos_z+42, block_id)
mc.setBlock(pos_x+29, pos_y+4, pos_z+42, block_id)
mc.setBlock(pos_x+30, pos_y+4, pos_z+42, block_id)
mc.setBlock(pos_x+31, pos_y+4, pos_z+42, block_id)
mc.setBlock(pos_x+2, pos_y+10, pos_z+41, block_id)
mc.setBlock(pos_x+46, pos_y+9, pos_z+41, block_id)
mc.setBlock(pos_x+32, pos_y+4, pos_z+42, block_id)
mc.setBlock(pos_x+33, pos_y+4, pos_z+42, block_id)
mc.setBlock(pos_x+36, pos_y+4, pos_z+42, block_id)
mc.setBlock(pos_x+45, pos_y+4, pos_z+42, block_id)
mc.setBlock(pos_x+3, pos_y+9, pos_z+41, block_id)
mc.setBlock(pos_x+46, pos_y+8, pos_z+41, block_id)
mc.setBlock(pos_x+4, pos_y+5, pos_z+42, block_id)
mc.setBlock(pos_x+14, pos_y+5, pos_z+42, block_id)
mc.setBlock(pos_x+15, pos_y+5, pos_z+42, block_id)
mc.setBlock(pos_x+34, pos_y+5, pos_z+42, block_id)
mc.setBlock(pos_x+35, pos_y+5, pos_z+42, block_id)
mc.setBlock(pos_x+45, pos_y+5, pos_z+42, block_id)
mc.setBlock(pos_x+3, pos_y+8, pos_z+41, block_id)
mc.setBlock(pos_x+46, pos_y+7, pos_z+41, block_id)
mc.setBlock(pos_x+4, pos_y+6, pos_z+42, block_id)
mc.setBlock(pos_x+45, pos_y+6, pos_z+42, block_id)
mc.setBlock(pos_x+4, pos_y+7, pos_z+42, block_id)
mc.setBlock(pos_x+45, pos_y+7, pos_z+42, block_id)
mc.setBlock(pos_x+3, pos_y+8, pos_z+42, block_id)
mc.setBlock(pos_x+46, pos_y+8, pos_z+42, block_id)
mc.setBlock(pos_x+3, pos_y+9, pos_z+42, block_id)
mc.setBlock(pos_x+3, pos_y+7, pos_z+41, block_id)
mc.setBlock(pos_x+46, pos_y+6, pos_z+41, block_id)
mc.setBlock(pos_x+46, pos_y+9, pos_z+42, block_id)
mc.setBlock(pos_x+2, pos_y+10, pos_z+42, block_id)
mc.setBlock(pos_x+46, pos_y+10, pos_z+42, block_id)
mc.setBlock(pos_x+3, pos_y+11, pos_z+42, block_id)
mc.setBlock(pos_x+46, pos_y+11, pos_z+42, block_id)
mc.setBlock(pos_x+3, pos_y+12, pos_z+42, block_id)
mc.setBlock(pos_x+46, pos_y+12, pos_z+42, block_id)
mc.setBlock(pos_x+3, pos_y+13, pos_z+42, block_id)
mc.setBlock(pos_x+46, pos_y+13, pos_z+42, block_id)
mc.setBlock(pos_x+3, pos_y+6, pos_z+41, block_id)
mc.setBlock(pos_x+45, pos_y+5, pos_z+41, block_id)
mc.setBlock(pos_x+3, pos_y+14, pos_z+42, block_id)
mc.setBlock(pos_x+46, pos_y+14, pos_z+42, block_id)
mc.setBlock(pos_x+34, pos_y+5, pos_z+41, block_id)
mc.setBlock(pos_x+33, pos_y+5, pos_z+41, block_id)
mc.setBlock(pos_x+3, pos_y+15, pos_z+42, block_id)
mc.setBlock(pos_x+46, pos_y+15, pos_z+42, block_id)
mc.setBlock(pos_x+3, pos_y+16, pos_z+42, block_id)
mc.setBlock(pos_x+46, pos_y+16, pos_z+42, block_id)
mc.setBlock(pos_x+4, pos_y+17, pos_z+42, block_id)
mc.setBlock(pos_x+45, pos_y+17, pos_z+42, block_id)
mc.setBlock(pos_x+4, pos_y+18, pos_z+42, block_id)
mc.setBlock(pos_x+5, pos_y+18, pos_z+42, block_id)
mc.setBlock(pos_x+44, pos_y+18, pos_z+42, block_id)
mc.setBlock(pos_x+6, pos_y+19, pos_z+42, block_id)
mc.setBlock(pos_x+7, pos_y+19, pos_z+42, block_id)
mc.setBlock(pos_x+8, pos_y+19, pos_z+42, block_id)
mc.setBlock(pos_x+9, pos_y+19, pos_z+42, block_id)
mc.setBlock(pos_x+10, pos_y+19, pos_z+42, block_id)
mc.setBlock(pos_x+11, pos_y+19, pos_z+42, block_id)
mc.setBlock(pos_x+12, pos_y+19, pos_z+42, block_id)
mc.setBlock(pos_x+37, pos_y+19, pos_z+42, block_id)
mc.setBlock(pos_x+15, pos_y+5, pos_z+41, block_id)
mc.setBlock(pos_x+38, pos_y+19, pos_z+42, block_id)
mc.setBlock(pos_x+39, pos_y+19, pos_z+42, block_id)
mc.setBlock(pos_x+40, pos_y+19, pos_z+42, block_id)
mc.setBlock(pos_x+3, pos_y+5, pos_z+41, block_id)
mc.setBlock(pos_x+45, pos_y+4, pos_z+41, block_id)
mc.setBlock(pos_x+41, pos_y+19, pos_z+42, block_id)
mc.setBlock(pos_x+35, pos_y+4, pos_z+41, block_id)
mc.setBlock(pos_x+32, pos_y+4, pos_z+41, block_id)
mc.setBlock(pos_x+31, pos_y+4, pos_z+41, block_id)
mc.setBlock(pos_x+30, pos_y+4, pos_z+41, block_id)
mc.setBlock(pos_x+29, pos_y+4, pos_z+41, block_id)
mc.setBlock(pos_x+28, pos_y+4, pos_z+41, block_id)
mc.setBlock(pos_x+27, pos_y+4, pos_z+41, block_id)
mc.setBlock(pos_x+26, pos_y+4, pos_z+41, block_id)
mc.setBlock(pos_x+25, pos_y+4, pos_z+41, block_id)
mc.setBlock(pos_x+24, pos_y+4, pos_z+41, block_id)
mc.setBlock(pos_x+23, pos_y+4, pos_z+41, block_id)
mc.setBlock(pos_x+22, pos_y+4, pos_z+41, block_id)
mc.setBlock(pos_x+21, pos_y+4, pos_z+41, block_id)
mc.setBlock(pos_x+20, pos_y+4, pos_z+41, block_id)
mc.setBlock(pos_x+19, pos_y+4, pos_z+41, block_id)
mc.setBlock(pos_x+18, pos_y+4, pos_z+41, block_id)
mc.setBlock(pos_x+17, pos_y+4, pos_z+41, block_id)
mc.setBlock(pos_x+16, pos_y+4, pos_z+41, block_id)
mc.setBlock(pos_x+14, pos_y+4, pos_z+41, block_id)
mc.setBlock(pos_x+42, pos_y+19, pos_z+42, block_id)
mc.setBlock(pos_x+4, pos_y+4, pos_z+41, block_id)
mc.setBlock(pos_x+45, pos_y+3, pos_z+41, block_id)
mc.setBlock(pos_x+43, pos_y+19, pos_z+42, block_id)
mc.setBlock(pos_x+35, pos_y+3, pos_z+41, block_id)
mc.setBlock(pos_x+14, pos_y+3, pos_z+41, block_id)
mc.setBlock(pos_x+13, pos_y+20, pos_z+42, block_id)
mc.setBlock(pos_x+4, pos_y+3, pos_z+41, block_id)
mc.setBlock(pos_x+45, pos_y+2, pos_z+41, block_id)
mc.setBlock(pos_x+36, pos_y+20, pos_z+42, block_id)
mc.setBlock(pos_x+35, pos_y+2, pos_z+41, block_id)
mc.setBlock(pos_x+14, pos_y+2, pos_z+41, block_id)
mc.setBlock(pos_x+13, pos_y+21, pos_z+42, block_id)
mc.setBlock(pos_x+4, pos_y+2, pos_z+41, block_id)
mc.setBlock(pos_x+45, pos_y+1, pos_z+41, block_id)
mc.setBlock(pos_x+36, pos_y+21, pos_z+42, block_id)
mc.setBlock(pos_x+35, pos_y+1, pos_z+41, block_id)
mc.setBlock(pos_x+14, pos_y+1, pos_z+41, block_id)
mc.setBlock(pos_x+13, pos_y+22, pos_z+42, block_id)
mc.setBlock(pos_x+4, pos_y+1, pos_z+41, block_id)
mc.setBlock(pos_x+45, pos_y+0, pos_z+41, block_id)
mc.setBlock(pos_x+44, pos_y+0, pos_z+41, block_id)
mc.setBlock(pos_x+43, pos_y+0, pos_z+41, block_id)
mc.setBlock(pos_x+42, pos_y+0, pos_z+41, block_id)
mc.setBlock(pos_x+41, pos_y+0, pos_z+41, block_id)
mc.setBlock(pos_x+40, pos_y+0, pos_z+41, block_id)
mc.setBlock(pos_x+39, pos_y+0, pos_z+41, block_id)
mc.setBlock(pos_x+38, pos_y+0, pos_z+41, block_id)
mc.setBlock(pos_x+37, pos_y+0, pos_z+41, block_id)
mc.setBlock(pos_x+36, pos_y+0, pos_z+41, block_id)
mc.setBlock(pos_x+35, pos_y+0, pos_z+41, block_id)
mc.setBlock(pos_x+14, pos_y+0, pos_z+41, block_id)
mc.setBlock(pos_x+13, pos_y+0, pos_z+41, block_id)
mc.setBlock(pos_x+12, pos_y+0, pos_z+41, block_id)
mc.setBlock(pos_x+11, pos_y+0, pos_z+41, block_id)
mc.setBlock(pos_x+10, pos_y+0, pos_z+41, block_id)
mc.setBlock(pos_x+9, pos_y+0, pos_z+41, block_id)
mc.setBlock(pos_x+8, pos_y+0, pos_z+41, block_id)
mc.setBlock(pos_x+7, pos_y+0, pos_z+41, block_id)
mc.setBlock(pos_x+6, pos_y+0, pos_z+41, block_id)
mc.setBlock(pos_x+5, pos_y+0, pos_z+41, block_id)
mc.setBlock(pos_x+4, pos_y+0, pos_z+41, block_id)
mc.setBlock(pos_x+30, pos_y+35, pos_z+40, block_id)
mc.setBlock(pos_x+29, pos_y+35, pos_z+40, block_id)
mc.setBlock(pos_x+28, pos_y+35, pos_z+40, block_id)
mc.setBlock(pos_x+27, pos_y+35, pos_z+40, block_id)
mc.setBlock(pos_x+26, pos_y+35, pos_z+40, block_id)
mc.setBlock(pos_x+25, pos_y+35, pos_z+40, block_id)
mc.setBlock(pos_x+24, pos_y+35, pos_z+40, block_id)
mc.setBlock(pos_x+23, pos_y+35, pos_z+40, block_id)
mc.setBlock(pos_x+22, pos_y+35, pos_z+40, block_id)
mc.setBlock(pos_x+21, pos_y+35, pos_z+40, block_id)
mc.setBlock(pos_x+20, pos_y+35, pos_z+40, block_id)
mc.setBlock(pos_x+19, pos_y+35, pos_z+40, block_id)
mc.setBlock(pos_x+18, pos_y+35, pos_z+40, block_id)
mc.setBlock(pos_x+32, pos_y+34, pos_z+40, block_id)
mc.setBlock(pos_x+31, pos_y+34, pos_z+40, block_id)
mc.setBlock(pos_x+30, pos_y+34, pos_z+40, block_id)
mc.setBlock(pos_x+36, pos_y+22, pos_z+42, block_id)
mc.setBlock(pos_x+14, pos_y+23, pos_z+42, block_id)
mc.setBlock(pos_x+35, pos_y+23, pos_z+42, block_id)
mc.setBlock(pos_x+14, pos_y+24, pos_z+42, block_id)
mc.setBlock(pos_x+35, pos_y+24, pos_z+42, block_id)
mc.setBlock(pos_x+14, pos_y+25, pos_z+42, block_id)
mc.setBlock(pos_x+35, pos_y+25, pos_z+42, block_id)
mc.setBlock(pos_x+14, pos_y+26, pos_z+42, block_id)
mc.setBlock(pos_x+35, pos_y+26, pos_z+42, block_id)
mc.setBlock(pos_x+15, pos_y+27, pos_z+42, block_id)
mc.setBlock(pos_x+34, pos_y+27, pos_z+42, block_id)
mc.setBlock(pos_x+15, pos_y+28, pos_z+42, block_id)
mc.setBlock(pos_x+17, pos_y+34, pos_z+40, block_id)
mc.setBlock(pos_x+33, pos_y+33, pos_z+40, block_id)
mc.setBlock(pos_x+34, pos_y+28, pos_z+42, block_id)
mc.setBlock(pos_x+15, pos_y+29, pos_z+42, block_id)
mc.setBlock(pos_x+34, pos_y+29, pos_z+42, block_id)
mc.setBlock(pos_x+16, pos_y+30, pos_z+42, block_id)
mc.setBlock(pos_x+33, pos_y+30, pos_z+42, block_id)
mc.setBlock(pos_x+16, pos_y+31, pos_z+42, block_id)
mc.setBlock(pos_x+32, pos_y+31, pos_z+42, block_id)
mc.setBlock(pos_x+17, pos_y+32, pos_z+42, block_id)
mc.setBlock(pos_x+18, pos_y+32, pos_z+42, block_id)
mc.setBlock(pos_x+19, pos_y+32, pos_z+42, block_id)
mc.setBlock(pos_x+20, pos_y+32, pos_z+42, block_id)
mc.setBlock(pos_x+21, pos_y+32, pos_z+42, block_id)
mc.setBlock(pos_x+22, pos_y+32, pos_z+42, block_id)
mc.setBlock(pos_x+23, pos_y+32, pos_z+42, block_id)
mc.setBlock(pos_x+24, pos_y+32, pos_z+42, block_id)
mc.setBlock(pos_x+25, pos_y+32, pos_z+42, block_id)
mc.setBlock(pos_x+16, pos_y+33, pos_z+40, block_id)
mc.setBlock(pos_x+33, pos_y+32, pos_z+40, block_id)
mc.setBlock(pos_x+26, pos_y+32, pos_z+42, block_id)
mc.setBlock(pos_x+27, pos_y+32, pos_z+42, block_id)
mc.setBlock(pos_x+28, pos_y+32, pos_z+42, block_id)
mc.setBlock(pos_x+29, pos_y+32, pos_z+42, block_id)
mc.setBlock(pos_x+16, pos_y+32, pos_z+40, block_id)
mc.setBlock(pos_x+33, pos_y+31, pos_z+40, block_id)
mc.setBlock(pos_x+30, pos_y+32, pos_z+42, block_id)
mc.setBlock(pos_x+31, pos_y+32, pos_z+42, block_id)
mc.setBlock(pos_x+32, pos_y+32, pos_z+42, block_id)
mc.setBlock(pos_x+15, pos_y+31, pos_z+40, block_id)
mc.setBlock(pos_x+34, pos_y+30, pos_z+40, block_id)
mc.setBlock(pos_x+22, pos_y+33, pos_z+42, block_id)
mc.setBlock(pos_x+23, pos_y+33, pos_z+42, block_id)
mc.setBlock(pos_x+15, pos_y+30, pos_z+40, block_id)
mc.setBlock(pos_x+34, pos_y+29, pos_z+40, block_id)
mc.setBlock(pos_x+24, pos_y+33, pos_z+42, block_id)
mc.setBlock(pos_x+25, pos_y+33, pos_z+42, block_id)
mc.setBlock(pos_x+15, pos_y+29, pos_z+40, block_id)
mc.setBlock(pos_x+34, pos_y+28, pos_z+40, block_id)
mc.setBlock(pos_x+26, pos_y+33, pos_z+42, block_id)
mc.setBlock(pos_x+15, pos_y+28, pos_z+40, block_id)
mc.setBlock(pos_x+35, pos_y+27, pos_z+40, block_id)
mc.setBlock(pos_x+27, pos_y+33, pos_z+42, block_id)
mc.setBlock(pos_x+4, pos_y+0, pos_z+43, block_id)
mc.setBlock(pos_x+14, pos_y+27, pos_z+40, block_id)
mc.setBlock(pos_x+35, pos_y+26, pos_z+40, block_id)
mc.setBlock(pos_x+5, pos_y+0, pos_z+43, block_id)
mc.setBlock(pos_x+6, pos_y+0, pos_z+43, block_id)
mc.setBlock(pos_x+14, pos_y+26, pos_z+40, block_id)
mc.setBlock(pos_x+35, pos_y+25, pos_z+40, block_id)
mc.setBlock(pos_x+7, pos_y+0, pos_z+43, block_id)
mc.setBlock(pos_x+8, pos_y+0, pos_z+43, block_id)
mc.setBlock(pos_x+14, pos_y+25, pos_z+40, block_id)
mc.setBlock(pos_x+35, pos_y+24, pos_z+40, block_id)
mc.setBlock(pos_x+9, pos_y+0, pos_z+43, block_id)
mc.setBlock(pos_x+14, pos_y+24, pos_z+40, block_id)
mc.setBlock(pos_x+36, pos_y+23, pos_z+40, block_id)
mc.setBlock(pos_x+10, pos_y+0, pos_z+43, block_id)
mc.setBlock(pos_x+11, pos_y+0, pos_z+43, block_id)
mc.setBlock(pos_x+13, pos_y+23, pos_z+40, block_id)
mc.setBlock(pos_x+36, pos_y+22, pos_z+40, block_id)
mc.setBlock(pos_x+12, pos_y+0, pos_z+43, block_id)
mc.setBlock(pos_x+13, pos_y+0, pos_z+43, block_id)
mc.setBlock(pos_x+13, pos_y+22, pos_z+40, block_id)
mc.setBlock(pos_x+36, pos_y+21, pos_z+40, block_id)
mc.setBlock(pos_x+36, pos_y+0, pos_z+43, block_id)
mc.setBlock(pos_x+37, pos_y+0, pos_z+43, block_id)
mc.setBlock(pos_x+13, pos_y+21, pos_z+40, block_id)
mc.setBlock(pos_x+36, pos_y+20, pos_z+40, block_id)
mc.setBlock(pos_x+13, pos_y+20, pos_z+40, block_id)
mc.setBlock(pos_x+44, pos_y+19, pos_z+40, block_id)
mc.setBlock(pos_x+43, pos_y+19, pos_z+40, block_id)
mc.setBlock(pos_x+42, pos_y+19, pos_z+40, block_id)
mc.setBlock(pos_x+41, pos_y+19, pos_z+40, block_id)
mc.setBlock(pos_x+40, pos_y+19, pos_z+40, block_id)
mc.setBlock(pos_x+39, pos_y+19, pos_z+40, block_id)
mc.setBlock(pos_x+38, pos_y+19, pos_z+40, block_id)
mc.setBlock(pos_x+37, pos_y+19, pos_z+40, block_id)
mc.setBlock(pos_x+38, pos_y+0, pos_z+43, block_id)
mc.setBlock(pos_x+39, pos_y+0, pos_z+43, block_id)
mc.setBlock(pos_x+12, pos_y+19, pos_z+40, block_id)
mc.setBlock(pos_x+11, pos_y+19, pos_z+40, block_id)
mc.setBlock(pos_x+10, pos_y+19, pos_z+40, block_id)
mc.setBlock(pos_x+9, pos_y+19, pos_z+40, block_id)
mc.setBlock(pos_x+8, pos_y+19, pos_z+40, block_id)
mc.setBlock(pos_x+7, pos_y+19, pos_z+40, block_id)
mc.setBlock(pos_x+6, pos_y+19, pos_z+40, block_id)
mc.setBlock(pos_x+5, pos_y+19, pos_z+40, block_id)
mc.setBlock(pos_x+45, pos_y+18, pos_z+40, block_id)
mc.setBlock(pos_x+40, pos_y+0, pos_z+43, block_id)
mc.setBlock(pos_x+41, pos_y+0, pos_z+43, block_id)
mc.setBlock(pos_x+42, pos_y+0, pos_z+43, block_id)
mc.setBlock(pos_x+43, pos_y+0, pos_z+43, block_id)
mc.setBlock(pos_x+44, pos_y+0, pos_z+43, block_id)
mc.setBlock(pos_x+4, pos_y+1, pos_z+43, block_id)
mc.setBlock(pos_x+4, pos_y+18, pos_z+40, block_id)
mc.setBlock(pos_x+45, pos_y+17, pos_z+40, block_id)
mc.setBlock(pos_x+13, pos_y+1, pos_z+43, block_id)
mc.setBlock(pos_x+36, pos_y+1, pos_z+43, block_id)
mc.setBlock(pos_x+44, pos_y+1, pos_z+43, block_id)
mc.setBlock(pos_x+5, pos_y+2, pos_z+43, block_id)
mc.setBlock(pos_x+13, pos_y+2, pos_z+43, block_id)
mc.setBlock(pos_x+3, pos_y+17, pos_z+40, block_id)
mc.setBlock(pos_x+46, pos_y+16, pos_z+40, block_id)
mc.setBlock(pos_x+36, pos_y+2, pos_z+43, block_id)
mc.setBlock(pos_x+44, pos_y+2, pos_z+43, block_id)
mc.setBlock(pos_x+5, pos_y+3, pos_z+43, block_id)
mc.setBlock(pos_x+7, pos_y+3, pos_z+43, block_id)
mc.setBlock(pos_x+3, pos_y+16, pos_z+40, block_id)
mc.setBlock(pos_x+46, pos_y+15, pos_z+40, block_id)
mc.setBlock(pos_x+13, pos_y+3, pos_z+43, block_id)
mc.setBlock(pos_x+17, pos_y+3, pos_z+43, block_id)
mc.setBlock(pos_x+31, pos_y+3, pos_z+43, block_id)
mc.setBlock(pos_x+32, pos_y+3, pos_z+43, block_id)
mc.setBlock(pos_x+3, pos_y+15, pos_z+40, block_id)
mc.setBlock(pos_x+46, pos_y+14, pos_z+40, block_id)
mc.setBlock(pos_x+36, pos_y+3, pos_z+43, block_id)
mc.setBlock(pos_x+42, pos_y+3, pos_z+43, block_id)
mc.setBlock(pos_x+44, pos_y+3, pos_z+43, block_id)
mc.setBlock(pos_x+2, pos_y+14, pos_z+40, block_id)
mc.setBlock(pos_x+47, pos_y+13, pos_z+40, block_id)
mc.setBlock(pos_x+5, pos_y+4, pos_z+43, block_id)
mc.setBlock(pos_x+6, pos_y+4, pos_z+43, block_id)
mc.setBlock(pos_x+7, pos_y+4, pos_z+43, block_id)
mc.setBlock(pos_x+11, pos_y+4, pos_z+43, block_id)
mc.setBlock(pos_x+2, pos_y+13, pos_z+40, block_id)
mc.setBlock(pos_x+47, pos_y+12, pos_z+40, block_id)
mc.setBlock(pos_x+13, pos_y+4, pos_z+43, block_id)
mc.setBlock(pos_x+15, pos_y+4, pos_z+43, block_id)
mc.setBlock(pos_x+16, pos_y+4, pos_z+43, block_id)
mc.setBlock(pos_x+2, pos_y+12, pos_z+40, block_id)
mc.setBlock(pos_x+47, pos_y+11, pos_z+40, block_id)
mc.setBlock(pos_x+18, pos_y+4, pos_z+43, block_id)
mc.setBlock(pos_x+19, pos_y+4, pos_z+43, block_id)
mc.setBlock(pos_x+2, pos_y+11, pos_z+40, block_id)
mc.setBlock(pos_x+47, pos_y+10, pos_z+40, block_id)
mc.setBlock(pos_x+20, pos_y+4, pos_z+43, block_id)
mc.setBlock(pos_x+21, pos_y+4, pos_z+43, block_id)
mc.setBlock(pos_x+22, pos_y+4, pos_z+43, block_id)
mc.setBlock(pos_x+2, pos_y+10, pos_z+40, block_id)
mc.setBlock(pos_x+46, pos_y+9, pos_z+40, block_id)
mc.setBlock(pos_x+23, pos_y+4, pos_z+43, block_id)
mc.setBlock(pos_x+24, pos_y+4, pos_z+43, block_id)
mc.setBlock(pos_x+25, pos_y+4, pos_z+43, block_id)
mc.setBlock(pos_x+2, pos_y+9, pos_z+40, block_id)
mc.setBlock(pos_x+46, pos_y+8, pos_z+40, block_id)
mc.setBlock(pos_x+26, pos_y+4, pos_z+43, block_id)
mc.setBlock(pos_x+27, pos_y+4, pos_z+43, block_id)
mc.setBlock(pos_x+28, pos_y+4, pos_z+43, block_id)
mc.setBlock(pos_x+3, pos_y+8, pos_z+40, block_id)
mc.setBlock(pos_x+46, pos_y+7, pos_z+40, block_id)
mc.setBlock(pos_x+29, pos_y+4, pos_z+43, block_id)
mc.setBlock(pos_x+30, pos_y+4, pos_z+43, block_id)
mc.setBlock(pos_x+33, pos_y+4, pos_z+43, block_id)
mc.setBlock(pos_x+34, pos_y+4, pos_z+43, block_id)
mc.setBlock(pos_x+3, pos_y+7, pos_z+40, block_id)
mc.setBlock(pos_x+46, pos_y+6, pos_z+40, block_id)
mc.setBlock(pos_x+36, pos_y+4, pos_z+43, block_id)
mc.setBlock(pos_x+38, pos_y+4, pos_z+43, block_id)
mc.setBlock(pos_x+42, pos_y+4, pos_z+43, block_id)
mc.setBlock(pos_x+43, pos_y+4, pos_z+43, block_id)
mc.setBlock(pos_x+44, pos_y+4, pos_z+43, block_id)
mc.setBlock(pos_x+5, pos_y+5, pos_z+43, block_id)
mc.setBlock(pos_x+6, pos_y+5, pos_z+43, block_id)
mc.setBlock(pos_x+7, pos_y+5, pos_z+43, block_id)
mc.setBlock(pos_x+11, pos_y+5, pos_z+43, block_id)
mc.setBlock(pos_x+12, pos_y+5, pos_z+43, block_id)
mc.setBlock(pos_x+14, pos_y+5, pos_z+43, block_id)
mc.setBlock(pos_x+35, pos_y+5, pos_z+43, block_id)
mc.setBlock(pos_x+36, pos_y+5, pos_z+43, block_id)
mc.setBlock(pos_x+37, pos_y+5, pos_z+43, block_id)
mc.setBlock(pos_x+38, pos_y+5, pos_z+43, block_id)
mc.setBlock(pos_x+42, pos_y+5, pos_z+43, block_id)
mc.setBlock(pos_x+43, pos_y+5, pos_z+43, block_id)
mc.setBlock(pos_x+44, pos_y+5, pos_z+43, block_id)
mc.setBlock(pos_x+4, pos_y+6, pos_z+43, block_id)
mc.setBlock(pos_x+5, pos_y+6, pos_z+43, block_id)
mc.setBlock(pos_x+6, pos_y+6, pos_z+43, block_id)
mc.setBlock(pos_x+7, pos_y+6, pos_z+43, block_id)
mc.setBlock(pos_x+3, pos_y+6, pos_z+40, block_id)
mc.setBlock(pos_x+46, pos_y+5, pos_z+40, block_id)
mc.setBlock(pos_x+11, pos_y+6, pos_z+43, block_id)
mc.setBlock(pos_x+12, pos_y+6, pos_z+43, block_id)
mc.setBlock(pos_x+34, pos_y+5, pos_z+40, block_id)
mc.setBlock(pos_x+33, pos_y+5, pos_z+40, block_id)
mc.setBlock(pos_x+37, pos_y+6, pos_z+43, block_id)
mc.setBlock(pos_x+31, pos_y+5, pos_z+40, block_id)
mc.setBlock(pos_x+30, pos_y+5, pos_z+40, block_id)
mc.setBlock(pos_x+29, pos_y+5, pos_z+40, block_id)
mc.setBlock(pos_x+28, pos_y+5, pos_z+40, block_id)
mc.setBlock(pos_x+27, pos_y+5, pos_z+40, block_id)
mc.setBlock(pos_x+26, pos_y+5, pos_z+40, block_id)
mc.setBlock(pos_x+25, pos_y+5, pos_z+40, block_id)
mc.setBlock(pos_x+24, pos_y+5, pos_z+40, block_id)
mc.setBlock(pos_x+23, pos_y+5, pos_z+40, block_id)
mc.setBlock(pos_x+22, pos_y+5, pos_z+40, block_id)
mc.setBlock(pos_x+21, pos_y+5, pos_z+40, block_id)
mc.setBlock(pos_x+20, pos_y+5, pos_z+40, block_id)
mc.setBlock(pos_x+19, pos_y+5, pos_z+40, block_id)
mc.setBlock(pos_x+38, pos_y+6, pos_z+43, block_id)
mc.setBlock(pos_x+42, pos_y+6, pos_z+43, block_id)
mc.setBlock(pos_x+16, pos_y+5, pos_z+40, block_id)
mc.setBlock(pos_x+15, pos_y+5, pos_z+40, block_id)
mc.setBlock(pos_x+43, pos_y+6, pos_z+43, block_id)
mc.setBlock(pos_x+3, pos_y+5, pos_z+40, block_id)
mc.setBlock(pos_x+46, pos_y+4, pos_z+40, block_id)
mc.setBlock(pos_x+44, pos_y+6, pos_z+43, block_id)
mc.setBlock(pos_x+35, pos_y+4, pos_z+40, block_id)
mc.setBlock(pos_x+32, pos_y+4, pos_z+40, block_id)
mc.setBlock(pos_x+18, pos_y+4, pos_z+40, block_id)
mc.setBlock(pos_x+17, pos_y+4, pos_z+40, block_id)
mc.setBlock(pos_x+14, pos_y+4, pos_z+40, block_id)
mc.setBlock(pos_x+4, pos_y+7, pos_z+43, block_id)
mc.setBlock(pos_x+3, pos_y+4, pos_z+40, block_id)
mc.setBlock(pos_x+46, pos_y+3, pos_z+40, block_id)
mc.setBlock(pos_x+5, pos_y+7, pos_z+43, block_id)
mc.setBlock(pos_x+35, pos_y+3, pos_z+40, block_id)
mc.setBlock(pos_x+14, pos_y+3, pos_z+40, block_id)
mc.setBlock(pos_x+6, pos_y+7, pos_z+43, block_id)
mc.setBlock(pos_x+3, pos_y+3, pos_z+40, block_id)
mc.setBlock(pos_x+46, pos_y+2, pos_z+40, block_id)
mc.setBlock(pos_x+11, pos_y+7, pos_z+43, block_id)
mc.setBlock(pos_x+35, pos_y+2, pos_z+40, block_id)
mc.setBlock(pos_x+14, pos_y+2, pos_z+40, block_id)
mc.setBlock(pos_x+43, pos_y+7, pos_z+43, block_id)
mc.setBlock(pos_x+3, pos_y+2, pos_z+40, block_id)
mc.setBlock(pos_x+45, pos_y+1, pos_z+40, block_id)
mc.setBlock(pos_x+35, pos_y+1, pos_z+40, block_id)
mc.setBlock(pos_x+14, pos_y+1, pos_z+40, block_id)
mc.setBlock(pos_x+44, pos_y+7, pos_z+43, block_id)
mc.setBlock(pos_x+3, pos_y+1, pos_z+40, block_id)
mc.setBlock(pos_x+45, pos_y+0, pos_z+40, block_id)
mc.setBlock(pos_x+44, pos_y+0, pos_z+40, block_id)
mc.setBlock(pos_x+43, pos_y+0, pos_z+40, block_id)
mc.setBlock(pos_x+42, pos_y+0, pos_z+40, block_id)
mc.setBlock(pos_x+41, pos_y+0, pos_z+40, block_id)
mc.setBlock(pos_x+40, pos_y+0, pos_z+40, block_id)
mc.setBlock(pos_x+39, pos_y+0, pos_z+40, block_id)
mc.setBlock(pos_x+38, pos_y+0, pos_z+40, block_id)
mc.setBlock(pos_x+37, pos_y+0, pos_z+40, block_id)
mc.setBlock(pos_x+36, pos_y+0, pos_z+40, block_id)
mc.setBlock(pos_x+35, pos_y+0, pos_z+40, block_id)
mc.setBlock(pos_x+14, pos_y+0, pos_z+40, block_id)
mc.setBlock(pos_x+13, pos_y+0, pos_z+40, block_id)
mc.setBlock(pos_x+12, pos_y+0, pos_z+40, block_id)
mc.setBlock(pos_x+11, pos_y+0, pos_z+40, block_id)
mc.setBlock(pos_x+10, pos_y+0, pos_z+40, block_id)
mc.setBlock(pos_x+9, pos_y+0, pos_z+40, block_id)
mc.setBlock(pos_x+8, pos_y+0, pos_z+40, block_id)
mc.setBlock(pos_x+7, pos_y+0, pos_z+40, block_id)
mc.setBlock(pos_x+6, pos_y+0, pos_z+40, block_id)
mc.setBlock(pos_x+5, pos_y+0, pos_z+40, block_id)
mc.setBlock(pos_x+4, pos_y+0, pos_z+40, block_id)
mc.setBlock(pos_x+3, pos_y+0, pos_z+40, block_id)
mc.setBlock(pos_x+31, pos_y+36, pos_z+39, block_id)
mc.setBlock(pos_x+30, pos_y+36, pos_z+39, block_id)
mc.setBlock(pos_x+29, pos_y+36, pos_z+39, block_id)
mc.setBlock(pos_x+28, pos_y+36, pos_z+39, block_id)
mc.setBlock(pos_x+27, pos_y+36, pos_z+39, block_id)
mc.setBlock(pos_x+26, pos_y+36, pos_z+39, block_id)
mc.setBlock(pos_x+25, pos_y+36, pos_z+39, block_id)
mc.setBlock(pos_x+24, pos_y+36, pos_z+39, block_id)
mc.setBlock(pos_x+23, pos_y+36, pos_z+39, block_id)
mc.setBlock(pos_x+22, pos_y+36, pos_z+39, block_id)
mc.setBlock(pos_x+21, pos_y+36, pos_z+39, block_id)
mc.setBlock(pos_x+20, pos_y+36, pos_z+39, block_id)
mc.setBlock(pos_x+19, pos_y+36, pos_z+39, block_id)
mc.setBlock(pos_x+18, pos_y+36, pos_z+39, block_id)
mc.setBlock(pos_x+32, pos_y+35, pos_z+39, block_id)
mc.setBlock(pos_x+31, pos_y+35, pos_z+39, block_id)
mc.setBlock(pos_x+45, pos_y+7, pos_z+43, block_id)
mc.setBlock(pos_x+4, pos_y+8, pos_z+43, block_id)
mc.setBlock(pos_x+45, pos_y+8, pos_z+43, block_id)
mc.setBlock(pos_x+3, pos_y+9, pos_z+43, block_id)
mc.setBlock(pos_x+46, pos_y+9, pos_z+43, block_id)
mc.setBlock(pos_x+3, pos_y+10, pos_z+43, block_id)
mc.setBlock(pos_x+46, pos_y+10, pos_z+43, block_id)
mc.setBlock(pos_x+3, pos_y+11, pos_z+43, block_id)
mc.setBlock(pos_x+46, pos_y+11, pos_z+43, block_id)
mc.setBlock(pos_x+3, pos_y+12, pos_z+43, block_id)
mc.setBlock(pos_x+46, pos_y+12, pos_z+43, block_id)
mc.setBlock(pos_x+3, pos_y+13, pos_z+43, block_id)
mc.setBlock(pos_x+46, pos_y+13, pos_z+43, block_id)
mc.setBlock(pos_x+17, pos_y+35, pos_z+39, block_id)
mc.setBlock(pos_x+32, pos_y+34, pos_z+39, block_id)
mc.setBlock(pos_x+3, pos_y+14, pos_z+43, block_id)
mc.setBlock(pos_x+46, pos_y+14, pos_z+43, block_id)
mc.setBlock(pos_x+3, pos_y+15, pos_z+43, block_id)
mc.setBlock(pos_x+46, pos_y+15, pos_z+43, block_id)
mc.setBlock(pos_x+3, pos_y+16, pos_z+43, block_id)
mc.setBlock(pos_x+45, pos_y+16, pos_z+43, block_id)
mc.setBlock(pos_x+4, pos_y+17, pos_z+43, block_id)
mc.setBlock(pos_x+45, pos_y+17, pos_z+43, block_id)
mc.setBlock(pos_x+5, pos_y+18, pos_z+43, block_id)
mc.setBlock(pos_x+12, pos_y+18, pos_z+43, block_id)
mc.setBlock(pos_x+37, pos_y+18, pos_z+43, block_id)
mc.setBlock(pos_x+44, pos_y+18, pos_z+43, block_id)
mc.setBlock(pos_x+6, pos_y+19, pos_z+43, block_id)
mc.setBlock(pos_x+7, pos_y+19, pos_z+43, block_id)
mc.setBlock(pos_x+8, pos_y+19, pos_z+43, block_id)
mc.setBlock(pos_x+16, pos_y+34, pos_z+39, block_id)
mc.setBlock(pos_x+33, pos_y+33, pos_z+39, block_id)
mc.setBlock(pos_x+9, pos_y+19, pos_z+43, block_id)
mc.setBlock(pos_x+10, pos_y+19, pos_z+43, block_id)
mc.setBlock(pos_x+11, pos_y+19, pos_z+43, block_id)
mc.setBlock(pos_x+13, pos_y+19, pos_z+43, block_id)
mc.setBlock(pos_x+16, pos_y+33, pos_z+39, block_id)
mc.setBlock(pos_x+33, pos_y+32, pos_z+39, block_id)
mc.setBlock(pos_x+36, pos_y+19, pos_z+43, block_id)
mc.setBlock(pos_x+38, pos_y+19, pos_z+43, block_id)
mc.setBlock(pos_x+16, pos_y+32, pos_z+39, block_id)
mc.setBlock(pos_x+34, pos_y+31, pos_z+39, block_id)
mc.setBlock(pos_x+39, pos_y+19, pos_z+43, block_id)
mc.setBlock(pos_x+40, pos_y+19, pos_z+43, block_id)
mc.setBlock(pos_x+15, pos_y+31, pos_z+39, block_id)
mc.setBlock(pos_x+34, pos_y+30, pos_z+39, block_id)
mc.setBlock(pos_x+41, pos_y+19, pos_z+43, block_id)
mc.setBlock(pos_x+42, pos_y+19, pos_z+43, block_id)
mc.setBlock(pos_x+15, pos_y+30, pos_z+39, block_id)
mc.setBlock(pos_x+34, pos_y+29, pos_z+39, block_id)
mc.setBlock(pos_x+43, pos_y+19, pos_z+43, block_id)
mc.setBlock(pos_x+13, pos_y+20, pos_z+43, block_id)
mc.setBlock(pos_x+15, pos_y+29, pos_z+39, block_id)
mc.setBlock(pos_x+34, pos_y+28, pos_z+39, block_id)
mc.setBlock(pos_x+36, pos_y+20, pos_z+43, block_id)
mc.setBlock(pos_x+14, pos_y+28, pos_z+39, block_id)
mc.setBlock(pos_x+35, pos_y+27, pos_z+39, block_id)
mc.setBlock(pos_x+13, pos_y+21, pos_z+43, block_id)
mc.setBlock(pos_x+36, pos_y+21, pos_z+43, block_id)
mc.setBlock(pos_x+14, pos_y+27, pos_z+39, block_id)
mc.setBlock(pos_x+35, pos_y+26, pos_z+39, block_id)
mc.setBlock(pos_x+13, pos_y+22, pos_z+43, block_id)
mc.setBlock(pos_x+35, pos_y+22, pos_z+43, block_id)
mc.setBlock(pos_x+14, pos_y+26, pos_z+39, block_id)
mc.setBlock(pos_x+35, pos_y+25, pos_z+39, block_id)
mc.setBlock(pos_x+14, pos_y+23, pos_z+43, block_id)
mc.setBlock(pos_x+14, pos_y+25, pos_z+39, block_id)
mc.setBlock(pos_x+36, pos_y+24, pos_z+39, block_id)
mc.setBlock(pos_x+35, pos_y+23, pos_z+43, block_id)
mc.setBlock(pos_x+14, pos_y+24, pos_z+43, block_id)
mc.setBlock(pos_x+35, pos_y+24, pos_z+43, block_id)
mc.setBlock(pos_x+13, pos_y+24, pos_z+39, block_id)
mc.setBlock(pos_x+36, pos_y+23, pos_z+39, block_id)
mc.setBlock(pos_x+14, pos_y+25, pos_z+43, block_id)
mc.setBlock(pos_x+35, pos_y+25, pos_z+43, block_id)
mc.setBlock(pos_x+15, pos_y+26, pos_z+43, block_id)
mc.setBlock(pos_x+13, pos_y+23, pos_z+39, block_id)
mc.setBlock(pos_x+36, pos_y+22, pos_z+39, block_id)
mc.setBlock(pos_x+34, pos_y+26, pos_z+43, block_id)
mc.setBlock(pos_x+15, pos_y+27, pos_z+43, block_id)
mc.setBlock(pos_x+13, pos_y+22, pos_z+39, block_id)
mc.setBlock(pos_x+36, pos_y+21, pos_z+39, block_id)
mc.setBlock(pos_x+34, pos_y+27, pos_z+43, block_id)
mc.setBlock(pos_x+13, pos_y+21, pos_z+39, block_id)
mc.setBlock(pos_x+36, pos_y+20, pos_z+39, block_id)
mc.setBlock(pos_x+15, pos_y+28, pos_z+43, block_id)
mc.setBlock(pos_x+12, pos_y+20, pos_z+39, block_id)
mc.setBlock(pos_x+44, pos_y+19, pos_z+39, block_id)
mc.setBlock(pos_x+43, pos_y+19, pos_z+39, block_id)
mc.setBlock(pos_x+42, pos_y+19, pos_z+39, block_id)
mc.setBlock(pos_x+41, pos_y+19, pos_z+39, block_id)
mc.setBlock(pos_x+40, pos_y+19, pos_z+39, block_id)
mc.setBlock(pos_x+39, pos_y+19, pos_z+39, block_id)
mc.setBlock(pos_x+38, pos_y+19, pos_z+39, block_id)
mc.setBlock(pos_x+37, pos_y+19, pos_z+39, block_id)
mc.setBlock(pos_x+34, pos_y+28, pos_z+43, block_id)
mc.setBlock(pos_x+16, pos_y+29, pos_z+43, block_id)
mc.setBlock(pos_x+33, pos_y+29, pos_z+43, block_id)
mc.setBlock(pos_x+11, pos_y+19, pos_z+39, block_id)
mc.setBlock(pos_x+10, pos_y+19, pos_z+39, block_id)
mc.setBlock(pos_x+9, pos_y+19, pos_z+39, block_id)
mc.setBlock(pos_x+8, pos_y+19, pos_z+39, block_id)
mc.setBlock(pos_x+7, pos_y+19, pos_z+39, block_id)
mc.setBlock(pos_x+6, pos_y+19, pos_z+39, block_id)
mc.setBlock(pos_x+5, pos_y+19, pos_z+39, block_id)
mc.setBlock(pos_x+45, pos_y+18, pos_z+39, block_id)
mc.setBlock(pos_x+16, pos_y+30, pos_z+43, block_id)
mc.setBlock(pos_x+32, pos_y+30, pos_z+43, block_id)
mc.setBlock(pos_x+17, pos_y+31, pos_z+43, block_id)
mc.setBlock(pos_x+18, pos_y+31, pos_z+43, block_id)
mc.setBlock(pos_x+19, pos_y+31, pos_z+43, block_id)
mc.setBlock(pos_x+20, pos_y+31, pos_z+43, block_id)
mc.setBlock(pos_x+21, pos_y+31, pos_z+43, block_id)
mc.setBlock(pos_x+4, pos_y+18, pos_z+39, block_id)
mc.setBlock(pos_x+45, pos_y+17, pos_z+39, block_id)
mc.setBlock(pos_x+22, pos_y+31, pos_z+43, block_id)
mc.setBlock(pos_x+23, pos_y+31, pos_z+43, block_id)
mc.setBlock(pos_x+24, pos_y+31, pos_z+43, block_id)
mc.setBlock(pos_x+25, pos_y+31, pos_z+43, block_id)
mc.setBlock(pos_x+4, pos_y+17, pos_z+39, block_id)
mc.setBlock(pos_x+46, pos_y+16, pos_z+39, block_id)
mc.setBlock(pos_x+26, pos_y+31, pos_z+43, block_id)
mc.setBlock(pos_x+27, pos_y+31, pos_z+43, block_id)
mc.setBlock(pos_x+28, pos_y+31, pos_z+43, block_id)
mc.setBlock(pos_x+29, pos_y+31, pos_z+43, block_id)
mc.setBlock(pos_x+3, pos_y+16, pos_z+39, block_id)
mc.setBlock(pos_x+46, pos_y+15, pos_z+39, block_id)
mc.setBlock(pos_x+30, pos_y+31, pos_z+43, block_id)
mc.setBlock(pos_x+31, pos_y+31, pos_z+43, block_id)
mc.setBlock(pos_x+32, pos_y+31, pos_z+43, block_id)
mc.setBlock(pos_x+5, pos_y+0, pos_z+44, block_id)
mc.setBlock(pos_x+3, pos_y+15, pos_z+39, block_id)
mc.setBlock(pos_x+46, pos_y+14, pos_z+39, block_id)
mc.setBlock(pos_x+6, pos_y+0, pos_z+44, block_id)
mc.setBlock(pos_x+7, pos_y+0, pos_z+44, block_id)
mc.setBlock(pos_x+8, pos_y+0, pos_z+44, block_id)
mc.setBlock(pos_x+2, pos_y+14, pos_z+39, block_id)
mc.setBlock(pos_x+47, pos_y+13, pos_z+39, block_id)
mc.setBlock(pos_x+9, pos_y+0, pos_z+44, block_id)
mc.setBlock(pos_x+10, pos_y+0, pos_z+44, block_id)
mc.setBlock(pos_x+11, pos_y+0, pos_z+44, block_id)
mc.setBlock(pos_x+12, pos_y+0, pos_z+44, block_id)
mc.setBlock(pos_x+2, pos_y+13, pos_z+39, block_id)
mc.setBlock(pos_x+47, pos_y+12, pos_z+39, block_id)
mc.setBlock(pos_x+13, pos_y+0, pos_z+44, block_id)
mc.setBlock(pos_x+36, pos_y+0, pos_z+44, block_id)
mc.setBlock(pos_x+37, pos_y+0, pos_z+44, block_id)
mc.setBlock(pos_x+2, pos_y+12, pos_z+39, block_id)
mc.setBlock(pos_x+47, pos_y+11, pos_z+39, block_id)
mc.setBlock(pos_x+38, pos_y+0, pos_z+44, block_id)
mc.setBlock(pos_x+39, pos_y+0, pos_z+44, block_id)
mc.setBlock(pos_x+2, pos_y+11, pos_z+39, block_id)
mc.setBlock(pos_x+47, pos_y+10, pos_z+39, block_id)
mc.setBlock(pos_x+40, pos_y+0, pos_z+44, block_id)
mc.setBlock(pos_x+41, pos_y+0, pos_z+44, block_id)
mc.setBlock(pos_x+42, pos_y+0, pos_z+44, block_id)
mc.setBlock(pos_x+2, pos_y+10, pos_z+39, block_id)
mc.setBlock(pos_x+47, pos_y+9, pos_z+39, block_id)
mc.setBlock(pos_x+43, pos_y+0, pos_z+44, block_id)
mc.setBlock(pos_x+44, pos_y+0, pos_z+44, block_id)
mc.setBlock(pos_x+5, pos_y+1, pos_z+44, block_id)
mc.setBlock(pos_x+6, pos_y+1, pos_z+44, block_id)
mc.setBlock(pos_x+2, pos_y+9, pos_z+39, block_id)
mc.setBlock(pos_x+46, pos_y+8, pos_z+39, block_id)
mc.setBlock(pos_x+7, pos_y+1, pos_z+44, block_id)
mc.setBlock(pos_x+10, pos_y+1, pos_z+44, block_id)
mc.setBlock(pos_x+11, pos_y+1, pos_z+44, block_id)
mc.setBlock(pos_x+2, pos_y+8, pos_z+39, block_id)
mc.setBlock(pos_x+46, pos_y+7, pos_z+39, block_id)
mc.setBlock(pos_x+13, pos_y+1, pos_z+44, block_id)
mc.setBlock(pos_x+36, pos_y+1, pos_z+44, block_id)
mc.setBlock(pos_x+38, pos_y+1, pos_z+44, block_id)
mc.setBlock(pos_x+39, pos_y+1, pos_z+44, block_id)
mc.setBlock(pos_x+42, pos_y+1, pos_z+44, block_id)
mc.setBlock(pos_x+44, pos_y+1, pos_z+44, block_id)
mc.setBlock(pos_x+5, pos_y+2, pos_z+44, block_id)
mc.setBlock(pos_x+6, pos_y+2, pos_z+44, block_id)
mc.setBlock(pos_x+7, pos_y+2, pos_z+44, block_id)
mc.setBlock(pos_x+10, pos_y+2, pos_z+44, block_id)
mc.setBlock(pos_x+11, pos_y+2, pos_z+44, block_id)
mc.setBlock(pos_x+12, pos_y+2, pos_z+44, block_id)
mc.setBlock(pos_x+37, pos_y+2, pos_z+44, block_id)
mc.setBlock(pos_x+38, pos_y+2, pos_z+44, block_id)
mc.setBlock(pos_x+39, pos_y+2, pos_z+44, block_id)
mc.setBlock(pos_x+42, pos_y+2, pos_z+44, block_id)
mc.setBlock(pos_x+43, pos_y+2, pos_z+44, block_id)
mc.setBlock(pos_x+3, pos_y+7, pos_z+39, block_id)
mc.setBlock(pos_x+46, pos_y+6, pos_z+39, block_id)
mc.setBlock(pos_x+44, pos_y+2, pos_z+44, block_id)
mc.setBlock(pos_x+5, pos_y+3, pos_z+44, block_id)
mc.setBlock(pos_x+6, pos_y+3, pos_z+44, block_id)
mc.setBlock(pos_x+8, pos_y+3, pos_z+44, block_id)
mc.setBlock(pos_x+10, pos_y+3, pos_z+44, block_id)
mc.setBlock(pos_x+11, pos_y+3, pos_z+44, block_id)
mc.setBlock(pos_x+12, pos_y+3, pos_z+44, block_id)
mc.setBlock(pos_x+17, pos_y+3, pos_z+44, block_id)
mc.setBlock(pos_x+18, pos_y+3, pos_z+44, block_id)
mc.setBlock(pos_x+19, pos_y+3, pos_z+44, block_id)
mc.setBlock(pos_x+20, pos_y+3, pos_z+44, block_id)
mc.setBlock(pos_x+21, pos_y+3, pos_z+44, block_id)
mc.setBlock(pos_x+22, pos_y+3, pos_z+44, block_id)
mc.setBlock(pos_x+23, pos_y+3, pos_z+44, block_id)
mc.setBlock(pos_x+24, pos_y+3, pos_z+44, block_id)
mc.setBlock(pos_x+25, pos_y+3, pos_z+44, block_id)
mc.setBlock(pos_x+26, pos_y+3, pos_z+44, block_id)
mc.setBlock(pos_x+27, pos_y+3, pos_z+44, block_id)
mc.setBlock(pos_x+28, pos_y+3, pos_z+44, block_id)
mc.setBlock(pos_x+29, pos_y+3, pos_z+44, block_id)
mc.setBlock(pos_x+15, pos_y+6, pos_z+39, block_id)
mc.setBlock(pos_x+30, pos_y+3, pos_z+44, block_id)
mc.setBlock(pos_x+3, pos_y+6, pos_z+39, block_id)
mc.setBlock(pos_x+46, pos_y+5, pos_z+39, block_id)
mc.setBlock(pos_x+31, pos_y+3, pos_z+44, block_id)
mc.setBlock(pos_x+32, pos_y+3, pos_z+44, block_id)
mc.setBlock(pos_x+33, pos_y+5, pos_z+39, block_id)
mc.setBlock(pos_x+32, pos_y+5, pos_z+39, block_id)
mc.setBlock(pos_x+31, pos_y+5, pos_z+39, block_id)
mc.setBlock(pos_x+30, pos_y+5, pos_z+39, block_id)
mc.setBlock(pos_x+29, pos_y+5, pos_z+39, block_id)
mc.setBlock(pos_x+28, pos_y+5, pos_z+39, block_id)
mc.setBlock(pos_x+27, pos_y+5, pos_z+39, block_id)
mc.setBlock(pos_x+26, pos_y+5, pos_z+39, block_id)
mc.setBlock(pos_x+25, pos_y+5, pos_z+39, block_id)
mc.setBlock(pos_x+24, pos_y+5, pos_z+39, block_id)
mc.setBlock(pos_x+23, pos_y+5, pos_z+39, block_id)
mc.setBlock(pos_x+22, pos_y+5, pos_z+39, block_id)
mc.setBlock(pos_x+21, pos_y+5, pos_z+39, block_id)
mc.setBlock(pos_x+20, pos_y+5, pos_z+39, block_id)
mc.setBlock(pos_x+19, pos_y+5, pos_z+39, block_id)
mc.setBlock(pos_x+18, pos_y+5, pos_z+39, block_id)
mc.setBlock(pos_x+17, pos_y+5, pos_z+39, block_id)
mc.setBlock(pos_x+16, pos_y+5, pos_z+39, block_id)
mc.setBlock(pos_x+14, pos_y+5, pos_z+39, block_id)
mc.setBlock(pos_x+3, pos_y+5, pos_z+39, block_id)
mc.setBlock(pos_x+46, pos_y+4, pos_z+39, block_id)
mc.setBlock(pos_x+37, pos_y+3, pos_z+44, block_id)
mc.setBlock(pos_x+34, pos_y+4, pos_z+39, block_id)
mc.setBlock(pos_x+14, pos_y+4, pos_z+39, block_id)
mc.setBlock(pos_x+3, pos_y+4, pos_z+39, block_id)
mc.setBlock(pos_x+46, pos_y+3, pos_z+39, block_id)
mc.setBlock(pos_x+35, pos_y+3, pos_z+39, block_id)
mc.setBlock(pos_x+14, pos_y+3, pos_z+39, block_id)
mc.setBlock(pos_x+3, pos_y+3, pos_z+39, block_id)
mc.setBlock(pos_x+46, pos_y+2, pos_z+39, block_id)
mc.setBlock(pos_x+38, pos_y+3, pos_z+44, block_id)
mc.setBlock(pos_x+35, pos_y+2, pos_z+39, block_id)
mc.setBlock(pos_x+14, pos_y+2, pos_z+39, block_id)
mc.setBlock(pos_x+3, pos_y+2, pos_z+39, block_id)
mc.setBlock(pos_x+46, pos_y+1, pos_z+39, block_id)
mc.setBlock(pos_x+39, pos_y+3, pos_z+44, block_id)
mc.setBlock(pos_x+35, pos_y+1, pos_z+39, block_id)
mc.setBlock(pos_x+14, pos_y+1, pos_z+39, block_id)
mc.setBlock(pos_x+3, pos_y+1, pos_z+39, block_id)
mc.setBlock(pos_x+46, pos_y+0, pos_z+39, block_id)
mc.setBlock(pos_x+45, pos_y+0, pos_z+39, block_id)
mc.setBlock(pos_x+44, pos_y+0, pos_z+39, block_id)
mc.setBlock(pos_x+43, pos_y+0, pos_z+39, block_id)
mc.setBlock(pos_x+42, pos_y+0, pos_z+39, block_id)
mc.setBlock(pos_x+41, pos_y+0, pos_z+39, block_id)
mc.setBlock(pos_x+40, pos_y+0, pos_z+39, block_id)
mc.setBlock(pos_x+39, pos_y+0, pos_z+39, block_id)
mc.setBlock(pos_x+38, pos_y+0, pos_z+39, block_id)
mc.setBlock(pos_x+37, pos_y+0, pos_z+39, block_id)
mc.setBlock(pos_x+36, pos_y+0, pos_z+39, block_id)
mc.setBlock(pos_x+35, pos_y+0, pos_z+39, block_id)
mc.setBlock(pos_x+14, pos_y+0, pos_z+39, block_id)
mc.setBlock(pos_x+13, pos_y+0, pos_z+39, block_id)
mc.setBlock(pos_x+12, pos_y+0, pos_z+39, block_id)
mc.setBlock(pos_x+11, pos_y+0, pos_z+39, block_id)
mc.setBlock(pos_x+10, pos_y+0, pos_z+39, block_id)
mc.setBlock(pos_x+9, pos_y+0, pos_z+39, block_id)
mc.setBlock(pos_x+8, pos_y+0, pos_z+39, block_id)
mc.setBlock(pos_x+7, pos_y+0, pos_z+39, block_id)
mc.setBlock(pos_x+6, pos_y+0, pos_z+39, block_id)
mc.setBlock(pos_x+5, pos_y+0, pos_z+39, block_id)
mc.setBlock(pos_x+4, pos_y+0, pos_z+39, block_id)
mc.setBlock(pos_x+3, pos_y+0, pos_z+39, block_id)
mc.setBlock(pos_x+30, pos_y+37, pos_z+38, block_id)
mc.setBlock(pos_x+29, pos_y+37, pos_z+38, block_id)
mc.setBlock(pos_x+28, pos_y+37, pos_z+38, block_id)
mc.setBlock(pos_x+27, pos_y+37, pos_z+38, block_id)
mc.setBlock(pos_x+26, pos_y+37, pos_z+38, block_id)
mc.setBlock(pos_x+25, pos_y+37, pos_z+38, block_id)
mc.setBlock(pos_x+24, pos_y+37, pos_z+38, block_id)
mc.setBlock(pos_x+23, pos_y+37, pos_z+38, block_id)
mc.setBlock(pos_x+22, pos_y+37, pos_z+38, block_id)
mc.setBlock(pos_x+21, pos_y+37, pos_z+38, block_id)
mc.setBlock(pos_x+20, pos_y+37, pos_z+38, block_id)
mc.setBlock(pos_x+19, pos_y+37, pos_z+38, block_id)
mc.setBlock(pos_x+31, pos_y+36, pos_z+38, block_id)
mc.setBlock(pos_x+41, pos_y+3, pos_z+44, block_id)
mc.setBlock(pos_x+43, pos_y+3, pos_z+44, block_id)
mc.setBlock(pos_x+44, pos_y+3, pos_z+44, block_id)
mc.setBlock(pos_x+5, pos_y+4, pos_z+44, block_id)
mc.setBlock(pos_x+8, pos_y+4, pos_z+44, block_id)
mc.setBlock(pos_x+10, pos_y+4, pos_z+44, block_id)
mc.setBlock(pos_x+12, pos_y+4, pos_z+44, block_id)
mc.setBlock(pos_x+14, pos_y+4, pos_z+44, block_id)
mc.setBlock(pos_x+15, pos_y+4, pos_z+44, block_id)
mc.setBlock(pos_x+16, pos_y+4, pos_z+44, block_id)
mc.setBlock(pos_x+33, pos_y+4, pos_z+44, block_id)
mc.setBlock(pos_x+34, pos_y+4, pos_z+44, block_id)
mc.setBlock(pos_x+18, pos_y+36, pos_z+38, block_id)
mc.setBlock(pos_x+17, pos_y+36, pos_z+38, block_id)
mc.setBlock(pos_x+32, pos_y+35, pos_z+38, block_id)
mc.setBlock(pos_x+35, pos_y+4, pos_z+44, block_id)
mc.setBlock(pos_x+37, pos_y+4, pos_z+44, block_id)
mc.setBlock(pos_x+39, pos_y+4, pos_z+44, block_id)
mc.setBlock(pos_x+41, pos_y+4, pos_z+44, block_id)
mc.setBlock(pos_x+44, pos_y+4, pos_z+44, block_id)
mc.setBlock(pos_x+8, pos_y+5, pos_z+44, block_id)
mc.setBlock(pos_x+10, pos_y+5, pos_z+44, block_id)
mc.setBlock(pos_x+13, pos_y+5, pos_z+44, block_id)
mc.setBlock(pos_x+35, pos_y+5, pos_z+44, block_id)
mc.setBlock(pos_x+39, pos_y+5, pos_z+44, block_id)
mc.setBlock(pos_x+41, pos_y+5, pos_z+44, block_id)
mc.setBlock(pos_x+8, pos_y+6, pos_z+44, block_id)
mc.setBlock(pos_x+9, pos_y+6, pos_z+44, block_id)
mc.setBlock(pos_x+10, pos_y+6, pos_z+44, block_id)
mc.setBlock(pos_x+17, pos_y+35, pos_z+38, block_id)
mc.setBlock(pos_x+33, pos_y+34, pos_z+38, block_id)
mc.setBlock(pos_x+13, pos_y+6, pos_z+44, block_id)
mc.setBlock(pos_x+36, pos_y+6, pos_z+44, block_id)
mc.setBlock(pos_x+39, pos_y+6, pos_z+44, block_id)
mc.setBlock(pos_x+40, pos_y+6, pos_z+44, block_id)
mc.setBlock(pos_x+16, pos_y+34, pos_z+38, block_id)
mc.setBlock(pos_x+33, pos_y+33, pos_z+38, block_id)
mc.setBlock(pos_x+41, pos_y+6, pos_z+44, block_id)
mc.setBlock(pos_x+7, pos_y+7, pos_z+44, block_id)
mc.setBlock(pos_x+16, pos_y+33, pos_z+38, block_id)
mc.setBlock(pos_x+33, pos_y+32, pos_z+38, block_id)
mc.setBlock(pos_x+8, pos_y+7, pos_z+44, block_id)
mc.setBlock(pos_x+15, pos_y+32, pos_z+38, block_id)
mc.setBlock(pos_x+34, pos_y+31, pos_z+38, block_id)
mc.setBlock(pos_x+10, pos_y+7, pos_z+44, block_id)
mc.setBlock(pos_x+12, pos_y+7, pos_z+44, block_id)
mc.setBlock(pos_x+15, pos_y+31, pos_z+38, block_id)
mc.setBlock(pos_x+34, pos_y+30, pos_z+38, block_id)
mc.setBlock(pos_x+37, pos_y+7, pos_z+44, block_id)
mc.setBlock(pos_x+38, pos_y+7, pos_z+44, block_id)
mc.setBlock(pos_x+15, pos_y+30, pos_z+38, block_id)
mc.setBlock(pos_x+34, pos_y+29, pos_z+38, block_id)
mc.setBlock(pos_x+39, pos_y+7, pos_z+44, block_id)
mc.setBlock(pos_x+15, pos_y+29, pos_z+38, block_id)
mc.setBlock(pos_x+35, pos_y+28, pos_z+38, block_id)
mc.setBlock(pos_x+41, pos_y+7, pos_z+44, block_id)
mc.setBlock(pos_x+42, pos_y+7, pos_z+44, block_id)
mc.setBlock(pos_x+14, pos_y+28, pos_z+38, block_id)
mc.setBlock(pos_x+35, pos_y+27, pos_z+38, block_id)
mc.setBlock(pos_x+5, pos_y+8, pos_z+44, block_id)
mc.setBlock(pos_x+6, pos_y+8, pos_z+44, block_id)
mc.setBlock(pos_x+14, pos_y+27, pos_z+38, block_id)
mc.setBlock(pos_x+35, pos_y+26, pos_z+38, block_id)
mc.setBlock(pos_x+11, pos_y+8, pos_z+44, block_id)
mc.setBlock(pos_x+43, pos_y+8, pos_z+44, block_id)
mc.setBlock(pos_x+14, pos_y+26, pos_z+38, block_id)
mc.setBlock(pos_x+38, pos_y+25, pos_z+38, block_id)
mc.setBlock(pos_x+37, pos_y+25, pos_z+38, block_id)
mc.setBlock(pos_x+36, pos_y+25, pos_z+38, block_id)
mc.setBlock(pos_x+44, pos_y+8, pos_z+44, block_id)
mc.setBlock(pos_x+4, pos_y+9, pos_z+44, block_id)
mc.setBlock(pos_x+45, pos_y+9, pos_z+44, block_id)
mc.setBlock(pos_x+13, pos_y+25, pos_z+38, block_id)
mc.setBlock(pos_x+12, pos_y+25, pos_z+38, block_id)
mc.setBlock(pos_x+11, pos_y+25, pos_z+38, block_id)
mc.setBlock(pos_x+10, pos_y+25, pos_z+38, block_id)
mc.setBlock(pos_x+40, pos_y+24, pos_z+38, block_id)
mc.setBlock(pos_x+39, pos_y+24, pos_z+38, block_id)
mc.setBlock(pos_x+38, pos_y+24, pos_z+38, block_id)
mc.setBlock(pos_x+37, pos_y+24, pos_z+38, block_id)
mc.setBlock(pos_x+3, pos_y+10, pos_z+44, block_id)
mc.setBlock(pos_x+45, pos_y+10, pos_z+44, block_id)
mc.setBlock(pos_x+3, pos_y+11, pos_z+44, block_id)
mc.setBlock(pos_x+46, pos_y+11, pos_z+44, block_id)
mc.setBlock(pos_x+12, pos_y+24, pos_z+38, block_id)
mc.setBlock(pos_x+11, pos_y+24, pos_z+38, block_id)
mc.setBlock(pos_x+10, pos_y+24, pos_z+38, block_id)
mc.setBlock(pos_x+9, pos_y+24, pos_z+38, block_id)
mc.setBlock(pos_x+40, pos_y+23, pos_z+38, block_id)
mc.setBlock(pos_x+39, pos_y+23, pos_z+38, block_id)
mc.setBlock(pos_x+38, pos_y+23, pos_z+38, block_id)
mc.setBlock(pos_x+37, pos_y+23, pos_z+38, block_id)
mc.setBlock(pos_x+3, pos_y+12, pos_z+44, block_id)
mc.setBlock(pos_x+46, pos_y+12, pos_z+44, block_id)
mc.setBlock(pos_x+3, pos_y+13, pos_z+44, block_id)
mc.setBlock(pos_x+46, pos_y+13, pos_z+44, block_id)
mc.setBlock(pos_x+12, pos_y+23, pos_z+38, block_id)
mc.setBlock(pos_x+11, pos_y+23, pos_z+38, block_id)
mc.setBlock(pos_x+10, pos_y+23, pos_z+38, block_id)
mc.setBlock(pos_x+9, pos_y+23, pos_z+38, block_id)
mc.setBlock(pos_x+37, pos_y+22, pos_z+38, block_id)
mc.setBlock(pos_x+3, pos_y+14, pos_z+44, block_id)
mc.setBlock(pos_x+46, pos_y+14, pos_z+44, block_id)
mc.setBlock(pos_x+3, pos_y+15, pos_z+44, block_id)
mc.setBlock(pos_x+45, pos_y+15, pos_z+44, block_id)
mc.setBlock(pos_x+4, pos_y+16, pos_z+44, block_id)
mc.setBlock(pos_x+12, pos_y+22, pos_z+38, block_id)
mc.setBlock(pos_x+36, pos_y+21, pos_z+38, block_id)
mc.setBlock(pos_x+13, pos_y+21, pos_z+38, block_id)
mc.setBlock(pos_x+37, pos_y+20, pos_z+38, block_id)
mc.setBlock(pos_x+45, pos_y+16, pos_z+44, block_id)
mc.setBlock(pos_x+4, pos_y+17, pos_z+44, block_id)
mc.setBlock(pos_x+12, pos_y+20, pos_z+38, block_id)
mc.setBlock(pos_x+43, pos_y+19, pos_z+38, block_id)
mc.setBlock(pos_x+42, pos_y+19, pos_z+38, block_id)
mc.setBlock(pos_x+41, pos_y+19, pos_z+38, block_id)
mc.setBlock(pos_x+40, pos_y+19, pos_z+38, block_id)
mc.setBlock(pos_x+39, pos_y+19, pos_z+38, block_id)
mc.setBlock(pos_x+38, pos_y+19, pos_z+38, block_id)
mc.setBlock(pos_x+45, pos_y+17, pos_z+44, block_id)
mc.setBlock(pos_x+5, pos_y+18, pos_z+44, block_id)
mc.setBlock(pos_x+6, pos_y+18, pos_z+44, block_id)
mc.setBlock(pos_x+7, pos_y+18, pos_z+44, block_id)
mc.setBlock(pos_x+11, pos_y+19, pos_z+38, block_id)
mc.setBlock(pos_x+10, pos_y+19, pos_z+38, block_id)
mc.setBlock(pos_x+9, pos_y+19, pos_z+38, block_id)
mc.setBlock(pos_x+8, pos_y+19, pos_z+38, block_id)
mc.setBlock(pos_x+7, pos_y+19, pos_z+38, block_id)
mc.setBlock(pos_x+6, pos_y+19, pos_z+38, block_id)
mc.setBlock(pos_x+45, pos_y+18, pos_z+38, block_id)
mc.setBlock(pos_x+44, pos_y+18, pos_z+38, block_id)
mc.setBlock(pos_x+10, pos_y+18, pos_z+44, block_id)
mc.setBlock(pos_x+11, pos_y+18, pos_z+44, block_id)
mc.setBlock(pos_x+12, pos_y+18, pos_z+44, block_id)
mc.setBlock(pos_x+37, pos_y+18, pos_z+44, block_id)
mc.setBlock(pos_x+38, pos_y+18, pos_z+44, block_id)
mc.setBlock(pos_x+39, pos_y+18, pos_z+44, block_id)
mc.setBlock(pos_x+42, pos_y+18, pos_z+44, block_id)
mc.setBlock(pos_x+43, pos_y+18, pos_z+44, block_id)
mc.setBlock(pos_x+5, pos_y+18, pos_z+38, block_id)
mc.setBlock(pos_x+4, pos_y+18, pos_z+38, block_id)
mc.setBlock(pos_x+45, pos_y+17, pos_z+38, block_id)
mc.setBlock(pos_x+44, pos_y+18, pos_z+44, block_id)
mc.setBlock(pos_x+8, pos_y+19, pos_z+44, block_id)
mc.setBlock(pos_x+9, pos_y+19, pos_z+44, block_id)
mc.setBlock(pos_x+13, pos_y+19, pos_z+44, block_id)
mc.setBlock(pos_x+36, pos_y+19, pos_z+44, block_id)
mc.setBlock(pos_x+4, pos_y+17, pos_z+38, block_id)
mc.setBlock(pos_x+46, pos_y+16, pos_z+38, block_id)
mc.setBlock(pos_x+40, pos_y+19, pos_z+44, block_id)
mc.setBlock(pos_x+41, pos_y+19, pos_z+44, block_id)
mc.setBlock(pos_x+13, pos_y+20, pos_z+44, block_id)
mc.setBlock(pos_x+36, pos_y+20, pos_z+44, block_id)
mc.setBlock(pos_x+13, pos_y+21, pos_z+44, block_id)
mc.setBlock(pos_x+3, pos_y+16, pos_z+38, block_id)
mc.setBlock(pos_x+46, pos_y+15, pos_z+38, block_id)
mc.setBlock(pos_x+35, pos_y+21, pos_z+44, block_id)
mc.setBlock(pos_x+14, pos_y+22, pos_z+44, block_id)
mc.setBlock(pos_x+35, pos_y+22, pos_z+44, block_id)
mc.setBlock(pos_x+14, pos_y+23, pos_z+44, block_id)
mc.setBlock(pos_x+3, pos_y+15, pos_z+38, block_id)
mc.setBlock(pos_x+46, pos_y+14, pos_z+38, block_id)
mc.setBlock(pos_x+35, pos_y+23, pos_z+44, block_id)
mc.setBlock(pos_x+14, pos_y+24, pos_z+44, block_id)
mc.setBlock(pos_x+35, pos_y+24, pos_z+44, block_id)
mc.setBlock(pos_x+14, pos_y+25, pos_z+44, block_id)
mc.setBlock(pos_x+3, pos_y+14, pos_z+38, block_id)
mc.setBlock(pos_x+46, pos_y+13, pos_z+38, block_id)
mc.setBlock(pos_x+34, pos_y+25, pos_z+44, block_id)
mc.setBlock(pos_x+15, pos_y+26, pos_z+44, block_id)
mc.setBlock(pos_x+34, pos_y+26, pos_z+44, block_id)
mc.setBlock(pos_x+2, pos_y+13, pos_z+38, block_id)
mc.setBlock(pos_x+47, pos_y+12, pos_z+38, block_id)
mc.setBlock(pos_x+15, pos_y+27, pos_z+44, block_id)
mc.setBlock(pos_x+34, pos_y+27, pos_z+44, block_id)
mc.setBlock(pos_x+16, pos_y+28, pos_z+44, block_id)
mc.setBlock(pos_x+33, pos_y+28, pos_z+44, block_id)
mc.setBlock(pos_x+2, pos_y+12, pos_z+38, block_id)
mc.setBlock(pos_x+47, pos_y+11, pos_z+38, block_id)
mc.setBlock(pos_x+16, pos_y+29, pos_z+44, block_id)
mc.setBlock(pos_x+17, pos_y+29, pos_z+44, block_id)
mc.setBlock(pos_x+27, pos_y+29, pos_z+44, block_id)
mc.setBlock(pos_x+2, pos_y+11, pos_z+38, block_id)
mc.setBlock(pos_x+47, pos_y+10, pos_z+38, block_id)
mc.setBlock(pos_x+31, pos_y+29, pos_z+44, block_id)
mc.setBlock(pos_x+32, pos_y+29, pos_z+44, block_id)
mc.setBlock(pos_x+2, pos_y+10, pos_z+38, block_id)
mc.setBlock(pos_x+47, pos_y+9, pos_z+38, block_id)
mc.setBlock(pos_x+17, pos_y+30, pos_z+44, block_id)
mc.setBlock(pos_x+18, pos_y+30, pos_z+44, block_id)
mc.setBlock(pos_x+19, pos_y+30, pos_z+44, block_id)
mc.setBlock(pos_x+2, pos_y+9, pos_z+38, block_id)
mc.setBlock(pos_x+47, pos_y+8, pos_z+38, block_id)
mc.setBlock(pos_x+20, pos_y+30, pos_z+44, block_id)
mc.setBlock(pos_x+21, pos_y+30, pos_z+44, block_id)
mc.setBlock(pos_x+22, pos_y+30, pos_z+44, block_id)
mc.setBlock(pos_x+23, pos_y+30, pos_z+44, block_id)
mc.setBlock(pos_x+24, pos_y+30, pos_z+44, block_id)
mc.setBlock(pos_x+25, pos_y+30, pos_z+44, block_id)
mc.setBlock(pos_x+26, pos_y+30, pos_z+44, block_id)
mc.setBlock(pos_x+27, pos_y+30, pos_z+44, block_id)
mc.setBlock(pos_x+28, pos_y+30, pos_z+44, block_id)
mc.setBlock(pos_x+29, pos_y+30, pos_z+44, block_id)
mc.setBlock(pos_x+2, pos_y+8, pos_z+38, block_id)
mc.setBlock(pos_x+46, pos_y+7, pos_z+38, block_id)
mc.setBlock(pos_x+30, pos_y+30, pos_z+44, block_id)
mc.setBlock(pos_x+31, pos_y+30, pos_z+44, block_id)
mc.setBlock(pos_x+32, pos_y+30, pos_z+44, block_id)
mc.setBlock(pos_x+5, pos_y+0, pos_z+45, block_id)
mc.setBlock(pos_x+6, pos_y+0, pos_z+45, block_id)
mc.setBlock(pos_x+8, pos_y+0, pos_z+45, block_id)
mc.setBlock(pos_x+9, pos_y+0, pos_z+45, block_id)
mc.setBlock(pos_x+12, pos_y+0, pos_z+45, block_id)
mc.setBlock(pos_x+37, pos_y+0, pos_z+45, block_id)
mc.setBlock(pos_x+39, pos_y+0, pos_z+45, block_id)
mc.setBlock(pos_x+40, pos_y+0, pos_z+45, block_id)
mc.setBlock(pos_x+41, pos_y+0, pos_z+45, block_id)
mc.setBlock(pos_x+43, pos_y+0, pos_z+45, block_id)
mc.setBlock(pos_x+44, pos_y+0, pos_z+45, block_id)
mc.setBlock(pos_x+5, pos_y+1, pos_z+45, block_id)
mc.setBlock(pos_x+8, pos_y+1, pos_z+45, block_id)
mc.setBlock(pos_x+9, pos_y+1, pos_z+45, block_id)
mc.setBlock(pos_x+12, pos_y+1, pos_z+45, block_id)
mc.setBlock(pos_x+37, pos_y+1, pos_z+45, block_id)
mc.setBlock(pos_x+40, pos_y+1, pos_z+45, block_id)
mc.setBlock(pos_x+41, pos_y+1, pos_z+45, block_id)
mc.setBlock(pos_x+2, pos_y+7, pos_z+38, block_id)
mc.setBlock(pos_x+46, pos_y+6, pos_z+38, block_id)
mc.setBlock(pos_x+43, pos_y+1, pos_z+45, block_id)
mc.setBlock(pos_x+33, pos_y+6, pos_z+38, block_id)
mc.setBlock(pos_x+32, pos_y+6, pos_z+38, block_id)
mc.setBlock(pos_x+31, pos_y+6, pos_z+38, block_id)
mc.setBlock(pos_x+30, pos_y+6, pos_z+38, block_id)
mc.setBlock(pos_x+29, pos_y+6, pos_z+38, block_id)
mc.setBlock(pos_x+28, pos_y+6, pos_z+38, block_id)
mc.setBlock(pos_x+27, pos_y+6, pos_z+38, block_id)
mc.setBlock(pos_x+26, pos_y+6, pos_z+38, block_id)
mc.setBlock(pos_x+25, pos_y+6, pos_z+38, block_id)
mc.setBlock(pos_x+24, pos_y+6, pos_z+38, block_id)
mc.setBlock(pos_x+23, pos_y+6, pos_z+38, block_id)
mc.setBlock(pos_x+22, pos_y+6, pos_z+38, block_id)
mc.setBlock(pos_x+21, pos_y+6, pos_z+38, block_id)
mc.setBlock(pos_x+20, pos_y+6, pos_z+38, block_id)
mc.setBlock(pos_x+19, pos_y+6, pos_z+38, block_id)
mc.setBlock(pos_x+18, pos_y+6, pos_z+38, block_id)
mc.setBlock(pos_x+17, pos_y+6, pos_z+38, block_id)
mc.setBlock(pos_x+16, pos_y+6, pos_z+38, block_id)
mc.setBlock(pos_x+44, pos_y+1, pos_z+45, block_id)
mc.setBlock(pos_x+3, pos_y+6, pos_z+38, block_id)
mc.setBlock(pos_x+46, pos_y+5, pos_z+38, block_id)
mc.setBlock(pos_x+34, pos_y+5, pos_z+38, block_id)
mc.setBlock(pos_x+15, pos_y+5, pos_z+38, block_id)
mc.setBlock(pos_x+8, pos_y+2, pos_z+45, block_id)
mc.setBlock(pos_x+3, pos_y+5, pos_z+38, block_id)
mc.setBlock(pos_x+46, pos_y+4, pos_z+38, block_id)
mc.setBlock(pos_x+9, pos_y+2, pos_z+45, block_id)
mc.setBlock(pos_x+34, pos_y+4, pos_z+38, block_id)
mc.setBlock(pos_x+15, pos_y+4, pos_z+38, block_id)
mc.setBlock(pos_x+40, pos_y+2, pos_z+45, block_id)
mc.setBlock(pos_x+3, pos_y+4, pos_z+38, block_id)
mc.setBlock(pos_x+46, pos_y+3, pos_z+38, block_id)
mc.setBlock(pos_x+41, pos_y+2, pos_z+45, block_id)
mc.setBlock(pos_x+34, pos_y+3, pos_z+38, block_id)
mc.setBlock(pos_x+14, pos_y+3, pos_z+38, block_id)
mc.setBlock(pos_x+3, pos_y+3, pos_z+38, block_id)
mc.setBlock(pos_x+46, pos_y+2, pos_z+38, block_id)
mc.setBlock(pos_x+35, pos_y+2, pos_z+38, block_id)
mc.setBlock(pos_x+14, pos_y+2, pos_z+38, block_id)
mc.setBlock(pos_x+3, pos_y+2, pos_z+38, block_id)
mc.setBlock(pos_x+46, pos_y+1, pos_z+38, block_id)
mc.setBlock(pos_x+35, pos_y+1, pos_z+38, block_id)
mc.setBlock(pos_x+14, pos_y+1, pos_z+38, block_id)
mc.setBlock(pos_x+3, pos_y+1, pos_z+38, block_id)
mc.setBlock(pos_x+46, pos_y+0, pos_z+38, block_id)
mc.setBlock(pos_x+45, pos_y+0, pos_z+38, block_id)
mc.setBlock(pos_x+44, pos_y+0, pos_z+38, block_id)
mc.setBlock(pos_x+43, pos_y+0, pos_z+38, block_id)
mc.setBlock(pos_x+42, pos_y+0, pos_z+38, block_id)
mc.setBlock(pos_x+41, pos_y+0, pos_z+38, block_id)
mc.setBlock(pos_x+40, pos_y+0, pos_z+38, block_id)
mc.setBlock(pos_x+39, pos_y+0, pos_z+38, block_id)
mc.setBlock(pos_x+38, pos_y+0, pos_z+38, block_id)
mc.setBlock(pos_x+37, pos_y+0, pos_z+38, block_id)
mc.setBlock(pos_x+36, pos_y+0, pos_z+38, block_id)
mc.setBlock(pos_x+35, pos_y+0, pos_z+38, block_id)
mc.setBlock(pos_x+14, pos_y+0, pos_z+38, block_id)
mc.setBlock(pos_x+13, pos_y+0, pos_z+38, block_id)
mc.setBlock(pos_x+12, pos_y+0, pos_z+38, block_id)
mc.setBlock(pos_x+11, pos_y+0, pos_z+38, block_id)
mc.setBlock(pos_x+10, pos_y+0, pos_z+38, block_id)
mc.setBlock(pos_x+9, pos_y+0, pos_z+38, block_id)
mc.setBlock(pos_x+8, pos_y+0, pos_z+38, block_id)
mc.setBlock(pos_x+7, pos_y+0, pos_z+38, block_id)
mc.setBlock(pos_x+6, pos_y+0, pos_z+38, block_id)
mc.setBlock(pos_x+5, pos_y+0, pos_z+38, block_id)
mc.setBlock(pos_x+4, pos_y+0, pos_z+38, block_id)
mc.setBlock(pos_x+3, pos_y+0, pos_z+38, block_id)
mc.setBlock(pos_x+29, pos_y+38, pos_z+37, block_id)
mc.setBlock(pos_x+28, pos_y+38, pos_z+37, block_id)
mc.setBlock(pos_x+27, pos_y+38, pos_z+37, block_id)
mc.setBlock(pos_x+26, pos_y+38, pos_z+37, block_id)
mc.setBlock(pos_x+25, pos_y+38, pos_z+37, block_id)
mc.setBlock(pos_x+24, pos_y+38, pos_z+37, block_id)
mc.setBlock(pos_x+23, pos_y+38, pos_z+37, block_id)
mc.setBlock(pos_x+22, pos_y+38, pos_z+37, block_id)
mc.setBlock(pos_x+21, pos_y+38, pos_z+37, block_id)
mc.setBlock(pos_x+20, pos_y+38, pos_z+37, block_id)
mc.setBlock(pos_x+31, pos_y+37, pos_z+37, block_id)
mc.setBlock(pos_x+30, pos_y+37, pos_z+37, block_id)
mc.setBlock(pos_x+8, pos_y+3, pos_z+45, block_id)
mc.setBlock(pos_x+9, pos_y+3, pos_z+45, block_id)
mc.setBlock(pos_x+16, pos_y+3, pos_z+45, block_id)
mc.setBlock(pos_x+17, pos_y+3, pos_z+45, block_id)
mc.setBlock(pos_x+18, pos_y+3, pos_z+45, block_id)
mc.setBlock(pos_x+19, pos_y+3, pos_z+45, block_id)
mc.setBlock(pos_x+20, pos_y+3, pos_z+45, block_id)
mc.setBlock(pos_x+21, pos_y+3, pos_z+45, block_id)
mc.setBlock(pos_x+22, pos_y+3, pos_z+45, block_id)
mc.setBlock(pos_x+23, pos_y+3, pos_z+45, block_id)
mc.setBlock(pos_x+19, pos_y+37, pos_z+37, block_id)
mc.setBlock(pos_x+18, pos_y+37, pos_z+37, block_id)
mc.setBlock(pos_x+32, pos_y+36, pos_z+37, block_id)
mc.setBlock(pos_x+24, pos_y+3, pos_z+45, block_id)
mc.setBlock(pos_x+25, pos_y+3, pos_z+45, block_id)
mc.setBlock(pos_x+26, pos_y+3, pos_z+45, block_id)
mc.setBlock(pos_x+27, pos_y+3, pos_z+45, block_id)
mc.setBlock(pos_x+28, pos_y+3, pos_z+45, block_id)
mc.setBlock(pos_x+29, pos_y+3, pos_z+45, block_id)
mc.setBlock(pos_x+30, pos_y+3, pos_z+45, block_id)
mc.setBlock(pos_x+31, pos_y+3, pos_z+45, block_id)
mc.setBlock(pos_x+32, pos_y+3, pos_z+45, block_id)
mc.setBlock(pos_x+33, pos_y+3, pos_z+45, block_id)
mc.setBlock(pos_x+40, pos_y+3, pos_z+45, block_id)
mc.setBlock(pos_x+41, pos_y+3, pos_z+45, block_id)
mc.setBlock(pos_x+9, pos_y+4, pos_z+45, block_id)
mc.setBlock(pos_x+14, pos_y+4, pos_z+45, block_id)
mc.setBlock(pos_x+17, pos_y+36, pos_z+37, block_id)
mc.setBlock(pos_x+33, pos_y+35, pos_z+37, block_id)
mc.setBlock(pos_x+15, pos_y+4, pos_z+45, block_id)
mc.setBlock(pos_x+34, pos_y+4, pos_z+45, block_id)
mc.setBlock(pos_x+35, pos_y+4, pos_z+45, block_id)
mc.setBlock(pos_x+40, pos_y+4, pos_z+45, block_id)
mc.setBlock(pos_x+16, pos_y+35, pos_z+37, block_id)
mc.setBlock(pos_x+33, pos_y+34, pos_z+37, block_id)
mc.setBlock(pos_x+9, pos_y+5, pos_z+45, block_id)
mc.setBlock(pos_x+13, pos_y+5, pos_z+45, block_id)
mc.setBlock(pos_x+16, pos_y+34, pos_z+37, block_id)
mc.setBlock(pos_x+33, pos_y+33, pos_z+37, block_id)
mc.setBlock(pos_x+36, pos_y+5, pos_z+45, block_id)
mc.setBlock(pos_x+16, pos_y+33, pos_z+37, block_id)
mc.setBlock(pos_x+34, pos_y+32, pos_z+37, block_id)
mc.setBlock(pos_x+40, pos_y+5, pos_z+45, block_id)
mc.setBlock(pos_x+12, pos_y+6, pos_z+45, block_id)
mc.setBlock(pos_x+15, pos_y+32, pos_z+37, block_id)
mc.setBlock(pos_x+34, pos_y+31, pos_z+37, block_id)
mc.setBlock(pos_x+36, pos_y+6, pos_z+45, block_id)
mc.setBlock(pos_x+9, pos_y+7, pos_z+45, block_id)
mc.setBlock(pos_x+15, pos_y+31, pos_z+37, block_id)
mc.setBlock(pos_x+34, pos_y+30, pos_z+37, block_id)
mc.setBlock(pos_x+12, pos_y+7, pos_z+45, block_id)
mc.setBlock(pos_x+37, pos_y+7, pos_z+45, block_id)
mc.setBlock(pos_x+15, pos_y+30, pos_z+37, block_id)
mc.setBlock(pos_x+34, pos_y+29, pos_z+37, block_id)
mc.setBlock(pos_x+40, pos_y+7, pos_z+45, block_id)
mc.setBlock(pos_x+14, pos_y+29, pos_z+37, block_id)
mc.setBlock(pos_x+35, pos_y+28, pos_z+37, block_id)
mc.setBlock(pos_x+7, pos_y+8, pos_z+45, block_id)
mc.setBlock(pos_x+8, pos_y+8, pos_z+45, block_id)
mc.setBlock(pos_x+14, pos_y+28, pos_z+37, block_id)
mc.setBlock(pos_x+35, pos_y+27, pos_z+37, block_id)
mc.setBlock(pos_x+9, pos_y+8, pos_z+45, block_id)
mc.setBlock(pos_x+10, pos_y+8, pos_z+45, block_id)
mc.setBlock(pos_x+14, pos_y+27, pos_z+37, block_id)
mc.setBlock(pos_x+36, pos_y+26, pos_z+37, block_id)
mc.setBlock(pos_x+12, pos_y+8, pos_z+45, block_id)
mc.setBlock(pos_x+38, pos_y+8, pos_z+45, block_id)
mc.setBlock(pos_x+39, pos_y+8, pos_z+45, block_id)
mc.setBlock(pos_x+13, pos_y+26, pos_z+37, block_id)
mc.setBlock(pos_x+39, pos_y+25, pos_z+37, block_id)
mc.setBlock(pos_x+38, pos_y+25, pos_z+37, block_id)
mc.setBlock(pos_x+37, pos_y+25, pos_z+37, block_id)
mc.setBlock(pos_x+40, pos_y+8, pos_z+45, block_id)
mc.setBlock(pos_x+41, pos_y+8, pos_z+45, block_id)
mc.setBlock(pos_x+42, pos_y+8, pos_z+45, block_id)
mc.setBlock(pos_x+5, pos_y+9, pos_z+45, block_id)
mc.setBlock(pos_x+12, pos_y+25, pos_z+37, block_id)
mc.setBlock(pos_x+11, pos_y+25, pos_z+37, block_id)
mc.setBlock(pos_x+10, pos_y+25, pos_z+37, block_id)
mc.setBlock(pos_x+42, pos_y+24, pos_z+37, block_id)
mc.setBlock(pos_x+41, pos_y+24, pos_z+37, block_id)
mc.setBlock(pos_x+40, pos_y+24, pos_z+37, block_id)
mc.setBlock(pos_x+6, pos_y+9, pos_z+45, block_id)
mc.setBlock(pos_x+7, pos_y+9, pos_z+45, block_id)
mc.setBlock(pos_x+10, pos_y+9, pos_z+45, block_id)
mc.setBlock(pos_x+11, pos_y+9, pos_z+45, block_id)
mc.setBlock(pos_x+38, pos_y+9, pos_z+45, block_id)
mc.setBlock(pos_x+42, pos_y+9, pos_z+45, block_id)
mc.setBlock(pos_x+9, pos_y+24, pos_z+37, block_id)
mc.setBlock(pos_x+8, pos_y+24, pos_z+37, block_id)
mc.setBlock(pos_x+7, pos_y+24, pos_z+37, block_id)
mc.setBlock(pos_x+41, pos_y+23, pos_z+37, block_id)
mc.setBlock(pos_x+40, pos_y+23, pos_z+37, block_id)
mc.setBlock(pos_x+39, pos_y+23, pos_z+37, block_id)
mc.setBlock(pos_x+43, pos_y+9, pos_z+45, block_id)
mc.setBlock(pos_x+44, pos_y+9, pos_z+45, block_id)
mc.setBlock(pos_x+4, pos_y+10, pos_z+45, block_id)
mc.setBlock(pos_x+5, pos_y+10, pos_z+45, block_id)
mc.setBlock(pos_x+44, pos_y+10, pos_z+45, block_id)
mc.setBlock(pos_x+45, pos_y+10, pos_z+45, block_id)
mc.setBlock(pos_x+4, pos_y+11, pos_z+45, block_id)
mc.setBlock(pos_x+10, pos_y+23, pos_z+37, block_id)
mc.setBlock(pos_x+9, pos_y+23, pos_z+37, block_id)
mc.setBlock(pos_x+8, pos_y+23, pos_z+37, block_id)
mc.setBlock(pos_x+38, pos_y+22, pos_z+37, block_id)
mc.setBlock(pos_x+37, pos_y+22, pos_z+37, block_id)
mc.setBlock(pos_x+45, pos_y+11, pos_z+45, block_id)
mc.setBlock(pos_x+4, pos_y+12, pos_z+45, block_id)
mc.setBlock(pos_x+45, pos_y+12, pos_z+45, block_id)
mc.setBlock(pos_x+4, pos_y+13, pos_z+45, block_id)
mc.setBlock(pos_x+45, pos_y+13, pos_z+45, block_id)
mc.setBlock(pos_x+4, pos_y+14, pos_z+45, block_id)
mc.setBlock(pos_x+11, pos_y+22, pos_z+37, block_id)
mc.setBlock(pos_x+36, pos_y+21, pos_z+37, block_id)
mc.setBlock(pos_x+45, pos_y+14, pos_z+45, block_id)
mc.setBlock(pos_x+12, pos_y+21, pos_z+37, block_id)
mc.setBlock(pos_x+37, pos_y+20, pos_z+37, block_id)
mc.setBlock(pos_x+4, pos_y+15, pos_z+45, block_id)
mc.setBlock(pos_x+45, pos_y+15, pos_z+45, block_id)
mc.setBlock(pos_x+12, pos_y+20, pos_z+37, block_id)
mc.setBlock(pos_x+43, pos_y+19, pos_z+37, block_id)
mc.setBlock(pos_x+42, pos_y+19, pos_z+37, block_id)
mc.setBlock(pos_x+41, pos_y+19, pos_z+37, block_id)
mc.setBlock(pos_x+40, pos_y+19, pos_z+37, block_id)
mc.setBlock(pos_x+39, pos_y+19, pos_z+37, block_id)
mc.setBlock(pos_x+38, pos_y+19, pos_z+37, block_id)
mc.setBlock(pos_x+4, pos_y+16, pos_z+45, block_id)
mc.setBlock(pos_x+45, pos_y+16, pos_z+45, block_id)
mc.setBlock(pos_x+5, pos_y+17, pos_z+45, block_id)
mc.setBlock(pos_x+6, pos_y+17, pos_z+45, block_id)
mc.setBlock(pos_x+11, pos_y+19, pos_z+37, block_id)
mc.setBlock(pos_x+10, pos_y+19, pos_z+37, block_id)
mc.setBlock(pos_x+9, pos_y+19, pos_z+37, block_id)
mc.setBlock(pos_x+8, pos_y+19, pos_z+37, block_id)
mc.setBlock(pos_x+7, pos_y+19, pos_z+37, block_id)
mc.setBlock(pos_x+6, pos_y+19, pos_z+37, block_id)
mc.setBlock(pos_x+44, pos_y+18, pos_z+37, block_id)
mc.setBlock(pos_x+12, pos_y+17, pos_z+45, block_id)
mc.setBlock(pos_x+37, pos_y+17, pos_z+45, block_id)
mc.setBlock(pos_x+43, pos_y+17, pos_z+45, block_id)
mc.setBlock(pos_x+44, pos_y+17, pos_z+45, block_id)
mc.setBlock(pos_x+6, pos_y+18, pos_z+45, block_id)
mc.setBlock(pos_x+7, pos_y+18, pos_z+45, block_id)
mc.setBlock(pos_x+8, pos_y+18, pos_z+45, block_id)
mc.setBlock(pos_x+9, pos_y+18, pos_z+45, block_id)
mc.setBlock(pos_x+10, pos_y+18, pos_z+45, block_id)
mc.setBlock(pos_x+11, pos_y+18, pos_z+45, block_id)
mc.setBlock(pos_x+13, pos_y+18, pos_z+45, block_id)
mc.setBlock(pos_x+36, pos_y+18, pos_z+45, block_id)
mc.setBlock(pos_x+38, pos_y+18, pos_z+45, block_id)
mc.setBlock(pos_x+39, pos_y+18, pos_z+45, block_id)
mc.setBlock(pos_x+40, pos_y+18, pos_z+45, block_id)
mc.setBlock(pos_x+41, pos_y+18, pos_z+45, block_id)
mc.setBlock(pos_x+5, pos_y+18, pos_z+37, block_id)
mc.setBlock(pos_x+45, pos_y+17, pos_z+37, block_id)
mc.setBlock(pos_x+42, pos_y+18, pos_z+45, block_id)
mc.setBlock(pos_x+43, pos_y+18, pos_z+45, block_id)
mc.setBlock(pos_x+13, pos_y+19, pos_z+45, block_id)
mc.setBlock(pos_x+36, pos_y+19, pos_z+45, block_id)
mc.setBlock(pos_x+13, pos_y+20, pos_z+45, block_id)
mc.setBlock(pos_x+36, pos_y+20, pos_z+45, block_id)
mc.setBlock(pos_x+14, pos_y+21, pos_z+45, block_id)
mc.setBlock(pos_x+4, pos_y+17, pos_z+37, block_id)
mc.setBlock(pos_x+45, pos_y+16, pos_z+37, block_id)
mc.setBlock(pos_x+35, pos_y+21, pos_z+45, block_id)
mc.setBlock(pos_x+14, pos_y+22, pos_z+45, block_id)
mc.setBlock(pos_x+35, pos_y+22, pos_z+45, block_id)
mc.setBlock(pos_x+14, pos_y+23, pos_z+45, block_id)
mc.setBlock(pos_x+35, pos_y+23, pos_z+45, block_id)
mc.setBlock(pos_x+3, pos_y+16, pos_z+37, block_id)
mc.setBlock(pos_x+46, pos_y+15, pos_z+37, block_id)
mc.setBlock(pos_x+14, pos_y+24, pos_z+45, block_id)
mc.setBlock(pos_x+34, pos_y+24, pos_z+45, block_id)
mc.setBlock(pos_x+15, pos_y+25, pos_z+45, block_id)
mc.setBlock(pos_x+34, pos_y+25, pos_z+45, block_id)
mc.setBlock(pos_x+3, pos_y+15, pos_z+37, block_id)
mc.setBlock(pos_x+46, pos_y+14, pos_z+37, block_id)
mc.setBlock(pos_x+15, pos_y+26, pos_z+45, block_id)
mc.setBlock(pos_x+34, pos_y+26, pos_z+45, block_id)
mc.setBlock(pos_x+16, pos_y+27, pos_z+45, block_id)
mc.setBlock(pos_x+33, pos_y+27, pos_z+45, block_id)
mc.setBlock(pos_x+3, pos_y+14, pos_z+37, block_id)
mc.setBlock(pos_x+46, pos_y+13, pos_z+37, block_id)
mc.setBlock(pos_x+17, pos_y+28, pos_z+45, block_id)
mc.setBlock(pos_x+18, pos_y+28, pos_z+45, block_id)
mc.setBlock(pos_x+3, pos_y+13, pos_z+37, block_id)
mc.setBlock(pos_x+46, pos_y+12, pos_z+37, block_id)
mc.setBlock(pos_x+19, pos_y+28, pos_z+45, block_id)
mc.setBlock(pos_x+20, pos_y+28, pos_z+45, block_id)
mc.setBlock(pos_x+21, pos_y+28, pos_z+45, block_id)
mc.setBlock(pos_x+2, pos_y+12, pos_z+37, block_id)
mc.setBlock(pos_x+47, pos_y+11, pos_z+37, block_id)
mc.setBlock(pos_x+22, pos_y+28, pos_z+45, block_id)
mc.setBlock(pos_x+23, pos_y+28, pos_z+45, block_id)
mc.setBlock(pos_x+24, pos_y+28, pos_z+45, block_id)
mc.setBlock(pos_x+2, pos_y+11, pos_z+37, block_id)
mc.setBlock(pos_x+47, pos_y+10, pos_z+37, block_id)
mc.setBlock(pos_x+25, pos_y+28, pos_z+45, block_id)
mc.setBlock(pos_x+26, pos_y+28, pos_z+45, block_id)
mc.setBlock(pos_x+27, pos_y+28, pos_z+45, block_id)
mc.setBlock(pos_x+28, pos_y+28, pos_z+45, block_id)
mc.setBlock(pos_x+2, pos_y+10, pos_z+37, block_id)
mc.setBlock(pos_x+47, pos_y+9, pos_z+37, block_id)
mc.setBlock(pos_x+29, pos_y+28, pos_z+45, block_id)
mc.setBlock(pos_x+30, pos_y+28, pos_z+45, block_id)
mc.setBlock(pos_x+31, pos_y+28, pos_z+45, block_id)
mc.setBlock(pos_x+32, pos_y+28, pos_z+45, block_id)
mc.setBlock(pos_x+18, pos_y+29, pos_z+45, block_id)
mc.setBlock(pos_x+19, pos_y+29, pos_z+45, block_id)
mc.setBlock(pos_x+20, pos_y+29, pos_z+45, block_id)
mc.setBlock(pos_x+2, pos_y+9, pos_z+37, block_id)
mc.setBlock(pos_x+46, pos_y+8, pos_z+37, block_id)
mc.setBlock(pos_x+21, pos_y+29, pos_z+45, block_id)
mc.setBlock(pos_x+22, pos_y+29, pos_z+45, block_id)
mc.setBlock(pos_x+23, pos_y+29, pos_z+45, block_id)
mc.setBlock(pos_x+24, pos_y+29, pos_z+45, block_id)
mc.setBlock(pos_x+25, pos_y+29, pos_z+45, block_id)
mc.setBlock(pos_x+26, pos_y+29, pos_z+45, block_id)
mc.setBlock(pos_x+28, pos_y+29, pos_z+45, block_id)
mc.setBlock(pos_x+29, pos_y+29, pos_z+45, block_id)
mc.setBlock(pos_x+30, pos_y+29, pos_z+45, block_id)
mc.setBlock(pos_x+8, pos_y+0, pos_z+46, block_id)
mc.setBlock(pos_x+9, pos_y+0, pos_z+46, block_id)
mc.setBlock(pos_x+40, pos_y+0, pos_z+46, block_id)
mc.setBlock(pos_x+41, pos_y+0, pos_z+46, block_id)
mc.setBlock(pos_x+8, pos_y+1, pos_z+46, block_id)
mc.setBlock(pos_x+9, pos_y+1, pos_z+46, block_id)
mc.setBlock(pos_x+40, pos_y+1, pos_z+46, block_id)
mc.setBlock(pos_x+9, pos_y+2, pos_z+46, block_id)
mc.setBlock(pos_x+40, pos_y+2, pos_z+46, block_id)
mc.setBlock(pos_x+16, pos_y+3, pos_z+46, block_id)
mc.setBlock(pos_x+17, pos_y+3, pos_z+46, block_id)
mc.setBlock(pos_x+18, pos_y+3, pos_z+46, block_id)
mc.setBlock(pos_x+2, pos_y+8, pos_z+37, block_id)
mc.setBlock(pos_x+46, pos_y+7, pos_z+37, block_id)
mc.setBlock(pos_x+19, pos_y+3, pos_z+46, block_id)
mc.setBlock(pos_x+33, pos_y+7, pos_z+37, block_id)
mc.setBlock(pos_x+20, pos_y+3, pos_z+46, block_id)
mc.setBlock(pos_x+21, pos_y+3, pos_z+46, block_id)
mc.setBlock(pos_x+22, pos_y+3, pos_z+46, block_id)
mc.setBlock(pos_x+29, pos_y+7, pos_z+37, block_id)
mc.setBlock(pos_x+28, pos_y+7, pos_z+37, block_id)
mc.setBlock(pos_x+27, pos_y+7, pos_z+37, block_id)
mc.setBlock(pos_x+26, pos_y+7, pos_z+37, block_id)
mc.setBlock(pos_x+25, pos_y+7, pos_z+37, block_id)
mc.setBlock(pos_x+24, pos_y+7, pos_z+37, block_id)
mc.setBlock(pos_x+23, pos_y+7, pos_z+37, block_id)
mc.setBlock(pos_x+22, pos_y+7, pos_z+37, block_id)
mc.setBlock(pos_x+21, pos_y+7, pos_z+37, block_id)
mc.setBlock(pos_x+20, pos_y+7, pos_z+37, block_id)
mc.setBlock(pos_x+19, pos_y+7, pos_z+37, block_id)
mc.setBlock(pos_x+23, pos_y+3, pos_z+46, block_id)
mc.setBlock(pos_x+24, pos_y+3, pos_z+46, block_id)
mc.setBlock(pos_x+16, pos_y+7, pos_z+37, block_id)
mc.setBlock(pos_x+25, pos_y+3, pos_z+46, block_id)
mc.setBlock(pos_x+3, pos_y+7, pos_z+37, block_id)
mc.setBlock(pos_x+46, pos_y+6, pos_z+37, block_id)
mc.setBlock(pos_x+34, pos_y+6, pos_z+37, block_id)
mc.setBlock(pos_x+32, pos_y+6, pos_z+37, block_id)
mc.setBlock(pos_x+31, pos_y+6, pos_z+37, block_id)
mc.setBlock(pos_x+30, pos_y+6, pos_z+37, block_id)
mc.setBlock(pos_x+18, pos_y+6, pos_z+37, block_id)
mc.setBlock(pos_x+17, pos_y+6, pos_z+37, block_id)
mc.setBlock(pos_x+15, pos_y+6, pos_z+37, block_id)
mc.setBlock(pos_x+26, pos_y+3, pos_z+46, block_id)
mc.setBlock(pos_x+3, pos_y+6, pos_z+37, block_id)
mc.setBlock(pos_x+46, pos_y+5, pos_z+37, block_id)
mc.setBlock(pos_x+27, pos_y+3, pos_z+46, block_id)
mc.setBlock(pos_x+34, pos_y+5, pos_z+37, block_id)
mc.setBlock(pos_x+15, pos_y+5, pos_z+37, block_id)
mc.setBlock(pos_x+28, pos_y+3, pos_z+46, block_id)
mc.setBlock(pos_x+3, pos_y+5, pos_z+37, block_id)
mc.setBlock(pos_x+46, pos_y+4, pos_z+37, block_id)
mc.setBlock(pos_x+29, pos_y+3, pos_z+46, block_id)
mc.setBlock(pos_x+34, pos_y+4, pos_z+37, block_id)
mc.setBlock(pos_x+14, pos_y+4, pos_z+37, block_id)
mc.setBlock(pos_x+3, pos_y+4, pos_z+37, block_id)
mc.setBlock(pos_x+46, pos_y+3, pos_z+37, block_id)
mc.setBlock(pos_x+30, pos_y+3, pos_z+46, block_id)
mc.setBlock(pos_x+34, pos_y+3, pos_z+37, block_id)
mc.setBlock(pos_x+14, pos_y+3, pos_z+37, block_id)
mc.setBlock(pos_x+3, pos_y+3, pos_z+37, block_id)
mc.setBlock(pos_x+46, pos_y+2, pos_z+37, block_id)
mc.setBlock(pos_x+35, pos_y+2, pos_z+37, block_id)
mc.setBlock(pos_x+14, pos_y+2, pos_z+37, block_id)
mc.setBlock(pos_x+3, pos_y+2, pos_z+37, block_id)
mc.setBlock(pos_x+46, pos_y+1, pos_z+37, block_id)
mc.setBlock(pos_x+35, pos_y+1, pos_z+37, block_id)
mc.setBlock(pos_x+14, pos_y+1, pos_z+37, block_id)
mc.setBlock(pos_x+3, pos_y+1, pos_z+37, block_id)
mc.setBlock(pos_x+46, pos_y+0, pos_z+37, block_id)
mc.setBlock(pos_x+45, pos_y+0, pos_z+37, block_id)
mc.setBlock(pos_x+44, pos_y+0, pos_z+37, block_id)
mc.setBlock(pos_x+43, pos_y+0, pos_z+37, block_id)
mc.setBlock(pos_x+42, pos_y+0, pos_z+37, block_id)
mc.setBlock(pos_x+41, pos_y+0, pos_z+37, block_id)
mc.setBlock(pos_x+40, pos_y+0, pos_z+37, block_id)
mc.setBlock(pos_x+39, pos_y+0, pos_z+37, block_id)
mc.setBlock(pos_x+38, pos_y+0, pos_z+37, block_id)
mc.setBlock(pos_x+37, pos_y+0, pos_z+37, block_id)
mc.setBlock(pos_x+36, pos_y+0, pos_z+37, block_id)
mc.setBlock(pos_x+35, pos_y+0, pos_z+37, block_id)
mc.setBlock(pos_x+14, pos_y+0, pos_z+37, block_id)
mc.setBlock(pos_x+13, pos_y+0, pos_z+37, block_id)
mc.setBlock(pos_x+12, pos_y+0, pos_z+37, block_id)
mc.setBlock(pos_x+11, pos_y+0, pos_z+37, block_id)
mc.setBlock(pos_x+10, pos_y+0, pos_z+37, block_id)
mc.setBlock(pos_x+9, pos_y+0, pos_z+37, block_id)
mc.setBlock(pos_x+8, pos_y+0, pos_z+37, block_id)
mc.setBlock(pos_x+7, pos_y+0, pos_z+37, block_id)
mc.setBlock(pos_x+6, pos_y+0, pos_z+37, block_id)
mc.setBlock(pos_x+5, pos_y+0, pos_z+37, block_id)
mc.setBlock(pos_x+4, pos_y+0, pos_z+37, block_id)
mc.setBlock(pos_x+3, pos_y+0, pos_z+37, block_id)
mc.setBlock(pos_x+27, pos_y+39, pos_z+36, block_id)
mc.setBlock(pos_x+26, pos_y+39, pos_z+36, block_id)
mc.setBlock(pos_x+25, pos_y+39, pos_z+36, block_id)
mc.setBlock(pos_x+24, pos_y+39, pos_z+36, block_id)
mc.setBlock(pos_x+23, pos_y+39, pos_z+36, block_id)
mc.setBlock(pos_x+31, pos_y+38, pos_z+36, block_id)
mc.setBlock(pos_x+30, pos_y+38, pos_z+36, block_id)
mc.setBlock(pos_x+29, pos_y+38, pos_z+36, block_id)
mc.setBlock(pos_x+28, pos_y+38, pos_z+36, block_id)
mc.setBlock(pos_x+31, pos_y+3, pos_z+46, block_id)
mc.setBlock(pos_x+32, pos_y+3, pos_z+46, block_id)
mc.setBlock(pos_x+33, pos_y+3, pos_z+46, block_id)
mc.setBlock(pos_x+14, pos_y+4, pos_z+46, block_id)
mc.setBlock(pos_x+15, pos_y+4, pos_z+46, block_id)
mc.setBlock(pos_x+22, pos_y+38, pos_z+36, block_id)
mc.setBlock(pos_x+21, pos_y+38, pos_z+36, block_id)
mc.setBlock(pos_x+20, pos_y+38, pos_z+36, block_id)
mc.setBlock(pos_x+19, pos_y+38, pos_z+36, block_id)
mc.setBlock(pos_x+18, pos_y+38, pos_z+36, block_id)
mc.setBlock(pos_x+32, pos_y+37, pos_z+36, block_id)
mc.setBlock(pos_x+34, pos_y+4, pos_z+46, block_id)
mc.setBlock(pos_x+35, pos_y+4, pos_z+46, block_id)
mc.setBlock(pos_x+13, pos_y+5, pos_z+46, block_id)
mc.setBlock(pos_x+36, pos_y+5, pos_z+46, block_id)
mc.setBlock(pos_x+12, pos_y+6, pos_z+46, block_id)
mc.setBlock(pos_x+36, pos_y+6, pos_z+46, block_id)
mc.setBlock(pos_x+12, pos_y+7, pos_z+46, block_id)
mc.setBlock(pos_x+37, pos_y+7, pos_z+46, block_id)
mc.setBlock(pos_x+12, pos_y+8, pos_z+46, block_id)
mc.setBlock(pos_x+37, pos_y+8, pos_z+46, block_id)
mc.setBlock(pos_x+8, pos_y+9, pos_z+46, block_id)
mc.setBlock(pos_x+9, pos_y+9, pos_z+46, block_id)
mc.setBlock(pos_x+12, pos_y+9, pos_z+46, block_id)
mc.setBlock(pos_x+37, pos_y+9, pos_z+46, block_id)
mc.setBlock(pos_x+17, pos_y+37, pos_z+36, block_id)
mc.setBlock(pos_x+33, pos_y+36, pos_z+36, block_id)
mc.setBlock(pos_x+39, pos_y+9, pos_z+46, block_id)
mc.setBlock(pos_x+40, pos_y+9, pos_z+46, block_id)
mc.setBlock(pos_x+41, pos_y+9, pos_z+46, block_id)
mc.setBlock(pos_x+6, pos_y+10, pos_z+46, block_id)
mc.setBlock(pos_x+16, pos_y+36, pos_z+36, block_id)
mc.setBlock(pos_x+33, pos_y+35, pos_z+36, block_id)
mc.setBlock(pos_x+7, pos_y+10, pos_z+46, block_id)
mc.setBlock(pos_x+8, pos_y+10, pos_z+46, block_id)
mc.setBlock(pos_x+16, pos_y+35, pos_z+36, block_id)
mc.setBlock(pos_x+33, pos_y+34, pos_z+36, block_id)
mc.setBlock(pos_x+9, pos_y+10, pos_z+46, block_id)
mc.setBlock(pos_x+10, pos_y+10, pos_z+46, block_id)
mc.setBlock(pos_x+16, pos_y+34, pos_z+36, block_id)
mc.setBlock(pos_x+33, pos_y+33, pos_z+36, block_id)
mc.setBlock(pos_x+11, pos_y+10, pos_z+46, block_id)
mc.setBlock(pos_x+15, pos_y+33, pos_z+36, block_id)
mc.setBlock(pos_x+34, pos_y+32, pos_z+36, block_id)
mc.setBlock(pos_x+38, pos_y+10, pos_z+46, block_id)
mc.setBlock(pos_x+39, pos_y+10, pos_z+46, block_id)
mc.setBlock(pos_x+15, pos_y+32, pos_z+36, block_id)
mc.setBlock(pos_x+34, pos_y+31, pos_z+36, block_id)
mc.setBlock(pos_x+40, pos_y+10, pos_z+46, block_id)
mc.setBlock(pos_x+41, pos_y+10, pos_z+46, block_id)
mc.setBlock(pos_x+15, pos_y+31, pos_z+36, block_id)
mc.setBlock(pos_x+35, pos_y+30, pos_z+36, block_id)
mc.setBlock(pos_x+42, pos_y+10, pos_z+46, block_id)
mc.setBlock(pos_x+43, pos_y+10, pos_z+46, block_id)
mc.setBlock(pos_x+5, pos_y+11, pos_z+46, block_id)
mc.setBlock(pos_x+14, pos_y+30, pos_z+36, block_id)
mc.setBlock(pos_x+37, pos_y+29, pos_z+36, block_id)
mc.setBlock(pos_x+36, pos_y+29, pos_z+36, block_id)
mc.setBlock(pos_x+35, pos_y+29, pos_z+36, block_id)
mc.setBlock(pos_x+6, pos_y+11, pos_z+46, block_id)
mc.setBlock(pos_x+7, pos_y+11, pos_z+46, block_id)
mc.setBlock(pos_x+10, pos_y+11, pos_z+46, block_id)
mc.setBlock(pos_x+13, pos_y+29, pos_z+36, block_id)
mc.setBlock(pos_x+12, pos_y+29, pos_z+36, block_id)
mc.setBlock(pos_x+37, pos_y+28, pos_z+36, block_id)
mc.setBlock(pos_x+36, pos_y+28, pos_z+36, block_id)
mc.setBlock(pos_x+11, pos_y+11, pos_z+46, block_id)
mc.setBlock(pos_x+38, pos_y+11, pos_z+46, block_id)
mc.setBlock(pos_x+39, pos_y+11, pos_z+46, block_id)
mc.setBlock(pos_x+42, pos_y+11, pos_z+46, block_id)
mc.setBlock(pos_x+13, pos_y+28, pos_z+36, block_id)
mc.setBlock(pos_x+12, pos_y+28, pos_z+36, block_id)
mc.setBlock(pos_x+36, pos_y+27, pos_z+36, block_id)
mc.setBlock(pos_x+43, pos_y+11, pos_z+46, block_id)
mc.setBlock(pos_x+44, pos_y+11, pos_z+46, block_id)
mc.setBlock(pos_x+5, pos_y+12, pos_z+46, block_id)
mc.setBlock(pos_x+6, pos_y+12, pos_z+46, block_id)
mc.setBlock(pos_x+13, pos_y+27, pos_z+36, block_id)
mc.setBlock(pos_x+35, pos_y+26, pos_z+36, block_id)
mc.setBlock(pos_x+11, pos_y+12, pos_z+46, block_id)
mc.setBlock(pos_x+38, pos_y+12, pos_z+46, block_id)
mc.setBlock(pos_x+14, pos_y+26, pos_z+36, block_id)
mc.setBlock(pos_x+38, pos_y+25, pos_z+36, block_id)
mc.setBlock(pos_x+37, pos_y+25, pos_z+36, block_id)
mc.setBlock(pos_x+36, pos_y+25, pos_z+36, block_id)
mc.setBlock(pos_x+43, pos_y+12, pos_z+46, block_id)
mc.setBlock(pos_x+44, pos_y+12, pos_z+46, block_id)
mc.setBlock(pos_x+5, pos_y+13, pos_z+46, block_id)
mc.setBlock(pos_x+13, pos_y+25, pos_z+36, block_id)
mc.setBlock(pos_x+12, pos_y+25, pos_z+36, block_id)
mc.setBlock(pos_x+11, pos_y+25, pos_z+36, block_id)
mc.setBlock(pos_x+10, pos_y+25, pos_z+36, block_id)
mc.setBlock(pos_x+40, pos_y+24, pos_z+36, block_id)
mc.setBlock(pos_x+39, pos_y+24, pos_z+36, block_id)
mc.setBlock(pos_x+44, pos_y+13, pos_z+46, block_id)
mc.setBlock(pos_x+5, pos_y+14, pos_z+46, block_id)
mc.setBlock(pos_x+6, pos_y+14, pos_z+46, block_id)
mc.setBlock(pos_x+43, pos_y+14, pos_z+46, block_id)
mc.setBlock(pos_x+44, pos_y+14, pos_z+46, block_id)
mc.setBlock(pos_x+5, pos_y+15, pos_z+46, block_id)
mc.setBlock(pos_x+6, pos_y+15, pos_z+46, block_id)
mc.setBlock(pos_x+7, pos_y+15, pos_z+46, block_id)
mc.setBlock(pos_x+10, pos_y+24, pos_z+36, block_id)
mc.setBlock(pos_x+9, pos_y+24, pos_z+36, block_id)
mc.setBlock(pos_x+40, pos_y+23, pos_z+36, block_id)
mc.setBlock(pos_x+39, pos_y+23, pos_z+36, block_id)
mc.setBlock(pos_x+38, pos_y+23, pos_z+36, block_id)
mc.setBlock(pos_x+11, pos_y+15, pos_z+46, block_id)
mc.setBlock(pos_x+37, pos_y+15, pos_z+46, block_id)
mc.setBlock(pos_x+38, pos_y+15, pos_z+46, block_id)
mc.setBlock(pos_x+42, pos_y+15, pos_z+46, block_id)
mc.setBlock(pos_x+43, pos_y+15, pos_z+46, block_id)
mc.setBlock(pos_x+44, pos_y+15, pos_z+46, block_id)
mc.setBlock(pos_x+5, pos_y+16, pos_z+46, block_id)
mc.setBlock(pos_x+11, pos_y+23, pos_z+36, block_id)
mc.setBlock(pos_x+10, pos_y+23, pos_z+36, block_id)
mc.setBlock(pos_x+9, pos_y+23, pos_z+36, block_id)
mc.setBlock(pos_x+37, pos_y+22, pos_z+36, block_id)
mc.setBlock(pos_x+6, pos_y+16, pos_z+46, block_id)
mc.setBlock(pos_x+7, pos_y+16, pos_z+46, block_id)
mc.setBlock(pos_x+8, pos_y+16, pos_z+46, block_id)
mc.setBlock(pos_x+10, pos_y+16, pos_z+46, block_id)
mc.setBlock(pos_x+11, pos_y+16, pos_z+46, block_id)
mc.setBlock(pos_x+12, pos_y+22, pos_z+36, block_id)
mc.setBlock(pos_x+36, pos_y+21, pos_z+36, block_id)
mc.setBlock(pos_x+13, pos_y+21, pos_z+36, block_id)
mc.setBlock(pos_x+37, pos_y+20, pos_z+36, block_id)
mc.setBlock(pos_x+12, pos_y+16, pos_z+46, block_id)
mc.setBlock(pos_x+37, pos_y+16, pos_z+46, block_id)
mc.setBlock(pos_x+12, pos_y+20, pos_z+36, block_id)
mc.setBlock(pos_x+37, pos_y+19, pos_z+36, block_id)
mc.setBlock(pos_x+38, pos_y+16, pos_z+46, block_id)
mc.setBlock(pos_x+39, pos_y+16, pos_z+46, block_id)
mc.setBlock(pos_x+12, pos_y+19, pos_z+36, block_id)
mc.setBlock(pos_x+43, pos_y+18, pos_z+36, block_id)
mc.setBlock(pos_x+42, pos_y+18, pos_z+36, block_id)
mc.setBlock(pos_x+41, pos_y+18, pos_z+36, block_id)
mc.setBlock(pos_x+40, pos_y+18, pos_z+36, block_id)
mc.setBlock(pos_x+39, pos_y+18, pos_z+36, block_id)
mc.setBlock(pos_x+38, pos_y+18, pos_z+36, block_id)
mc.setBlock(pos_x+41, pos_y+16, pos_z+46, block_id)
mc.setBlock(pos_x+42, pos_y+16, pos_z+46, block_id)
mc.setBlock(pos_x+43, pos_y+16, pos_z+46, block_id)
mc.setBlock(pos_x+44, pos_y+16, pos_z+46, block_id)
mc.setBlock(pos_x+11, pos_y+18, pos_z+36, block_id)
mc.setBlock(pos_x+10, pos_y+18, pos_z+36, block_id)
mc.setBlock(pos_x+9, pos_y+18, pos_z+36, block_id)
mc.setBlock(pos_x+8, pos_y+18, pos_z+36, block_id)
mc.setBlock(pos_x+7, pos_y+18, pos_z+36, block_id)
mc.setBlock(pos_x+6, pos_y+18, pos_z+36, block_id)
mc.setBlock(pos_x+44, pos_y+17, pos_z+36, block_id)
mc.setBlock(pos_x+7, pos_y+17, pos_z+46, block_id)
mc.setBlock(pos_x+8, pos_y+17, pos_z+46, block_id)
mc.setBlock(pos_x+9, pos_y+17, pos_z+46, block_id)
mc.setBlock(pos_x+10, pos_y+17, pos_z+46, block_id)
mc.setBlock(pos_x+11, pos_y+17, pos_z+46, block_id)
mc.setBlock(pos_x+13, pos_y+17, pos_z+46, block_id)
mc.setBlock(pos_x+36, pos_y+17, pos_z+46, block_id)
mc.setBlock(pos_x+38, pos_y+17, pos_z+46, block_id)
mc.setBlock(pos_x+39, pos_y+17, pos_z+46, block_id)
mc.setBlock(pos_x+40, pos_y+17, pos_z+46, block_id)
mc.setBlock(pos_x+41, pos_y+17, pos_z+46, block_id)
mc.setBlock(pos_x+42, pos_y+17, pos_z+46, block_id)
mc.setBlock(pos_x+13, pos_y+18, pos_z+46, block_id)
mc.setBlock(pos_x+5, pos_y+17, pos_z+36, block_id)
mc.setBlock(pos_x+45, pos_y+16, pos_z+36, block_id)
mc.setBlock(pos_x+36, pos_y+18, pos_z+46, block_id)
mc.setBlock(pos_x+13, pos_y+19, pos_z+46, block_id)
mc.setBlock(pos_x+36, pos_y+19, pos_z+46, block_id)
mc.setBlock(pos_x+14, pos_y+20, pos_z+46, block_id)
mc.setBlock(pos_x+35, pos_y+20, pos_z+46, block_id)
mc.setBlock(pos_x+14, pos_y+21, pos_z+46, block_id)
mc.setBlock(pos_x+35, pos_y+21, pos_z+46, block_id)
mc.setBlock(pos_x+14, pos_y+22, pos_z+46, block_id)
mc.setBlock(pos_x+4, pos_y+16, pos_z+36, block_id)
mc.setBlock(pos_x+45, pos_y+15, pos_z+36, block_id)
mc.setBlock(pos_x+35, pos_y+22, pos_z+46, block_id)
mc.setBlock(pos_x+14, pos_y+23, pos_z+46, block_id)
mc.setBlock(pos_x+35, pos_y+23, pos_z+46, block_id)
mc.setBlock(pos_x+15, pos_y+24, pos_z+46, block_id)
mc.setBlock(pos_x+34, pos_y+24, pos_z+46, block_id)
mc.setBlock(pos_x+15, pos_y+25, pos_z+46, block_id)
mc.setBlock(pos_x+3, pos_y+15, pos_z+36, block_id)
mc.setBlock(pos_x+46, pos_y+14, pos_z+36, block_id)
mc.setBlock(pos_x+34, pos_y+25, pos_z+46, block_id)
mc.setBlock(pos_x+16, pos_y+26, pos_z+46, block_id)
mc.setBlock(pos_x+33, pos_y+26, pos_z+46, block_id)
mc.setBlock(pos_x+17, pos_y+27, pos_z+46, block_id)
mc.setBlock(pos_x+18, pos_y+27, pos_z+46, block_id)
mc.setBlock(pos_x+19, pos_y+27, pos_z+46, block_id)
mc.setBlock(pos_x+20, pos_y+27, pos_z+46, block_id)
mc.setBlock(pos_x+3, pos_y+14, pos_z+36, block_id)
mc.setBlock(pos_x+46, pos_y+13, pos_z+36, block_id)
mc.setBlock(pos_x+21, pos_y+27, pos_z+46, block_id)
mc.setBlock(pos_x+22, pos_y+27, pos_z+46, block_id)
mc.setBlock(pos_x+23, pos_y+27, pos_z+46, block_id)
mc.setBlock(pos_x+24, pos_y+27, pos_z+46, block_id)
mc.setBlock(pos_x+3, pos_y+13, pos_z+36, block_id)
mc.setBlock(pos_x+46, pos_y+12, pos_z+36, block_id)
mc.setBlock(pos_x+25, pos_y+27, pos_z+46, block_id)
mc.setBlock(pos_x+26, pos_y+27, pos_z+46, block_id)
mc.setBlock(pos_x+27, pos_y+27, pos_z+46, block_id)
mc.setBlock(pos_x+28, pos_y+27, pos_z+46, block_id)
mc.setBlock(pos_x+3, pos_y+12, pos_z+36, block_id)
mc.setBlock(pos_x+47, pos_y+11, pos_z+36, block_id)
mc.setBlock(pos_x+29, pos_y+27, pos_z+46, block_id)
mc.setBlock(pos_x+30, pos_y+27, pos_z+46, block_id)
mc.setBlock(pos_x+31, pos_y+27, pos_z+46, block_id)
mc.setBlock(pos_x+32, pos_y+27, pos_z+46, block_id)
mc.setBlock(pos_x+15, pos_y+3, pos_z+47, block_id)
mc.setBlock(pos_x+16, pos_y+3, pos_z+47, block_id)
mc.setBlock(pos_x+2, pos_y+11, pos_z+36, block_id)
mc.setBlock(pos_x+46, pos_y+10, pos_z+36, block_id)
mc.setBlock(pos_x+17, pos_y+3, pos_z+47, block_id)
mc.setBlock(pos_x+18, pos_y+3, pos_z+47, block_id)
mc.setBlock(pos_x+19, pos_y+3, pos_z+47, block_id)
mc.setBlock(pos_x+20, pos_y+3, pos_z+47, block_id)
mc.setBlock(pos_x+21, pos_y+3, pos_z+47, block_id)
mc.setBlock(pos_x+22, pos_y+3, pos_z+47, block_id)
mc.setBlock(pos_x+23, pos_y+3, pos_z+47, block_id)
mc.setBlock(pos_x+24, pos_y+3, pos_z+47, block_id)
mc.setBlock(pos_x+25, pos_y+3, pos_z+47, block_id)
mc.setBlock(pos_x+2, pos_y+10, pos_z+36, block_id)
mc.setBlock(pos_x+46, pos_y+9, pos_z+36, block_id)
mc.setBlock(pos_x+26, pos_y+3, pos_z+47, block_id)
mc.setBlock(pos_x+27, pos_y+3, pos_z+47, block_id)
mc.setBlock(pos_x+28, pos_y+3, pos_z+47, block_id)
mc.setBlock(pos_x+29, pos_y+3, pos_z+47, block_id)
mc.setBlock(pos_x+30, pos_y+3, pos_z+47, block_id)
mc.setBlock(pos_x+31, pos_y+3, pos_z+47, block_id)
mc.setBlock(pos_x+32, pos_y+3, pos_z+47, block_id)
mc.setBlock(pos_x+33, pos_y+3, pos_z+47, block_id)
mc.setBlock(pos_x+34, pos_y+3, pos_z+47, block_id)
mc.setBlock(pos_x+14, pos_y+4, pos_z+47, block_id)
mc.setBlock(pos_x+35, pos_y+4, pos_z+47, block_id)
mc.setBlock(pos_x+13, pos_y+5, pos_z+47, block_id)
mc.setBlock(pos_x+36, pos_y+5, pos_z+47, block_id)
mc.setBlock(pos_x+12, pos_y+6, pos_z+47, block_id)
mc.setBlock(pos_x+37, pos_y+6, pos_z+47, block_id)
mc.setBlock(pos_x+12, pos_y+7, pos_z+47, block_id)
mc.setBlock(pos_x+37, pos_y+7, pos_z+47, block_id)
mc.setBlock(pos_x+12, pos_y+8, pos_z+47, block_id)
mc.setBlock(pos_x+37, pos_y+8, pos_z+47, block_id)
mc.setBlock(pos_x+12, pos_y+9, pos_z+47, block_id)
mc.setBlock(pos_x+37, pos_y+9, pos_z+47, block_id)
mc.setBlock(pos_x+3, pos_y+9, pos_z+36, block_id)
mc.setBlock(pos_x+46, pos_y+8, pos_z+36, block_id)
mc.setBlock(pos_x+12, pos_y+10, pos_z+47, block_id)
mc.setBlock(pos_x+37, pos_y+10, pos_z+47, block_id)
mc.setBlock(pos_x+33, pos_y+8, pos_z+36, block_id)
mc.setBlock(pos_x+8, pos_y+11, pos_z+47, block_id)
mc.setBlock(pos_x+9, pos_y+11, pos_z+47, block_id)
mc.setBlock(pos_x+12, pos_y+11, pos_z+47, block_id)
mc.setBlock(pos_x+29, pos_y+8, pos_z+36, block_id)
mc.setBlock(pos_x+28, pos_y+8, pos_z+36, block_id)
mc.setBlock(pos_x+27, pos_y+8, pos_z+36, block_id)
mc.setBlock(pos_x+26, pos_y+8, pos_z+36, block_id)
mc.setBlock(pos_x+25, pos_y+8, pos_z+36, block_id)
mc.setBlock(pos_x+24, pos_y+8, pos_z+36, block_id)
mc.setBlock(pos_x+23, pos_y+8, pos_z+36, block_id)
mc.setBlock(pos_x+22, pos_y+8, pos_z+36, block_id)
mc.setBlock(pos_x+21, pos_y+8, pos_z+36, block_id)
mc.setBlock(pos_x+20, pos_y+8, pos_z+36, block_id)
mc.setBlock(pos_x+37, pos_y+11, pos_z+47, block_id)
mc.setBlock(pos_x+40, pos_y+11, pos_z+47, block_id)
mc.setBlock(pos_x+41, pos_y+11, pos_z+47, block_id)
mc.setBlock(pos_x+16, pos_y+8, pos_z+36, block_id)
mc.setBlock(pos_x+15, pos_y+8, pos_z+36, block_id)
mc.setBlock(pos_x+7, pos_y+12, pos_z+47, block_id)
mc.setBlock(pos_x+3, pos_y+8, pos_z+36, block_id)
mc.setBlock(pos_x+46, pos_y+7, pos_z+36, block_id)
mc.setBlock(pos_x+8, pos_y+12, pos_z+47, block_id)
mc.setBlock(pos_x+34, pos_y+7, pos_z+36, block_id)
mc.setBlock(pos_x+32, pos_y+7, pos_z+36, block_id)
mc.setBlock(pos_x+31, pos_y+7, pos_z+36, block_id)
mc.setBlock(pos_x+30, pos_y+7, pos_z+36, block_id)
mc.setBlock(pos_x+19, pos_y+7, pos_z+36, block_id)
mc.setBlock(pos_x+18, pos_y+7, pos_z+36, block_id)
mc.setBlock(pos_x+17, pos_y+7, pos_z+36, block_id)
mc.setBlock(pos_x+15, pos_y+7, pos_z+36, block_id)
mc.setBlock(pos_x+9, pos_y+12, pos_z+47, block_id)
mc.setBlock(pos_x+3, pos_y+7, pos_z+36, block_id)
mc.setBlock(pos_x+46, pos_y+6, pos_z+36, block_id)
mc.setBlock(pos_x+10, pos_y+12, pos_z+47, block_id)
mc.setBlock(pos_x+34, pos_y+6, pos_z+36, block_id)
mc.setBlock(pos_x+14, pos_y+6, pos_z+36, block_id)
mc.setBlock(pos_x+3, pos_y+6, pos_z+36, block_id)
mc.setBlock(pos_x+46, pos_y+5, pos_z+36, block_id)
mc.setBlock(pos_x+12, pos_y+12, pos_z+47, block_id)
mc.setBlock(pos_x+34, pos_y+5, pos_z+36, block_id)
mc.setBlock(pos_x+14, pos_y+5, pos_z+36, block_id)
mc.setBlock(pos_x+3, pos_y+5, pos_z+36, block_id)
mc.setBlock(pos_x+46, pos_y+4, pos_z+36, block_id)
mc.setBlock(pos_x+35, pos_y+4, pos_z+36, block_id)
mc.setBlock(pos_x+14, pos_y+4, pos_z+36, block_id)
mc.setBlock(pos_x+3, pos_y+4, pos_z+36, block_id)
mc.setBlock(pos_x+46, pos_y+3, pos_z+36, block_id)
mc.setBlock(pos_x+35, pos_y+3, pos_z+36, block_id)
mc.setBlock(pos_x+14, pos_y+3, pos_z+36, block_id)
mc.setBlock(pos_x+3, pos_y+3, pos_z+36, block_id)
mc.setBlock(pos_x+46, pos_y+2, pos_z+36, block_id)
mc.setBlock(pos_x+35, pos_y+2, pos_z+36, block_id)
mc.setBlock(pos_x+14, pos_y+2, pos_z+36, block_id)
mc.setBlock(pos_x+3, pos_y+2, pos_z+36, block_id)
mc.setBlock(pos_x+46, pos_y+1, pos_z+36, block_id)
mc.setBlock(pos_x+35, pos_y+1, pos_z+36, block_id)
mc.setBlock(pos_x+14, pos_y+1, pos_z+36, block_id)
mc.setBlock(pos_x+3, pos_y+1, pos_z+36, block_id)
mc.setBlock(pos_x+46, pos_y+0, pos_z+36, block_id)
mc.setBlock(pos_x+45, pos_y+0, pos_z+36, block_id)
mc.setBlock(pos_x+44, pos_y+0, pos_z+36, block_id)
mc.setBlock(pos_x+43, pos_y+0, pos_z+36, block_id)
mc.setBlock(pos_x+42, pos_y+0, pos_z+36, block_id)
mc.setBlock(pos_x+41, pos_y+0, pos_z+36, block_id)
mc.setBlock(pos_x+40, pos_y+0, pos_z+36, block_id)
mc.setBlock(pos_x+39, pos_y+0, pos_z+36, block_id)
mc.setBlock(pos_x+38, pos_y+0, pos_z+36, block_id)
mc.setBlock(pos_x+37, pos_y+0, pos_z+36, block_id)
mc.setBlock(pos_x+36, pos_y+0, pos_z+36, block_id)
mc.setBlock(pos_x+35, pos_y+0, pos_z+36, block_id)
mc.setBlock(pos_x+14, pos_y+0, pos_z+36, block_id)
mc.setBlock(pos_x+13, pos_y+0, pos_z+36, block_id)
mc.setBlock(pos_x+12, pos_y+0, pos_z+36, block_id)
mc.setBlock(pos_x+11, pos_y+0, pos_z+36, block_id)
mc.setBlock(pos_x+10, pos_y+0, pos_z+36, block_id)
mc.setBlock(pos_x+9, pos_y+0, pos_z+36, block_id)
mc.setBlock(pos_x+8, pos_y+0, pos_z+36, block_id)
mc.setBlock(pos_x+7, pos_y+0, pos_z+36, block_id)
mc.setBlock(pos_x+6, pos_y+0, pos_z+36, block_id)
mc.setBlock(pos_x+5, pos_y+0, pos_z+36, block_id)
mc.setBlock(pos_x+4, pos_y+0, pos_z+36, block_id)
mc.setBlock(pos_x+3, pos_y+0, pos_z+36, block_id)
mc.setBlock(pos_x+31, pos_y+39, pos_z+35, block_id)
mc.setBlock(pos_x+30, pos_y+39, pos_z+35, block_id)
mc.setBlock(pos_x+29, pos_y+39, pos_z+35, block_id)
mc.setBlock(pos_x+28, pos_y+39, pos_z+35, block_id)
mc.setBlock(pos_x+27, pos_y+39, pos_z+35, block_id)
mc.setBlock(pos_x+26, pos_y+39, pos_z+35, block_id)
mc.setBlock(pos_x+25, pos_y+39, pos_z+35, block_id)
mc.setBlock(pos_x+24, pos_y+39, pos_z+35, block_id)
mc.setBlock(pos_x+23, pos_y+39, pos_z+35, block_id)
mc.setBlock(pos_x+22, pos_y+39, pos_z+35, block_id)
mc.setBlock(pos_x+21, pos_y+39, pos_z+35, block_id)
mc.setBlock(pos_x+20, pos_y+39, pos_z+35, block_id)
mc.setBlock(pos_x+19, pos_y+39, pos_z+35, block_id)
mc.setBlock(pos_x+18, pos_y+39, pos_z+35, block_id)
mc.setBlock(pos_x+32, pos_y+38, pos_z+35, block_id)
mc.setBlock(pos_x+37, pos_y+12, pos_z+47, block_id)
mc.setBlock(pos_x+39, pos_y+12, pos_z+47, block_id)
mc.setBlock(pos_x+40, pos_y+12, pos_z+47, block_id)
mc.setBlock(pos_x+41, pos_y+12, pos_z+47, block_id)
mc.setBlock(pos_x+42, pos_y+12, pos_z+47, block_id)
mc.setBlock(pos_x+6, pos_y+13, pos_z+47, block_id)
mc.setBlock(pos_x+7, pos_y+13, pos_z+47, block_id)
mc.setBlock(pos_x+8, pos_y+13, pos_z+47, block_id)
mc.setBlock(pos_x+9, pos_y+13, pos_z+47, block_id)
mc.setBlock(pos_x+10, pos_y+13, pos_z+47, block_id)
mc.setBlock(pos_x+11, pos_y+13, pos_z+47, block_id)
mc.setBlock(pos_x+38, pos_y+13, pos_z+47, block_id)
mc.setBlock(pos_x+39, pos_y+13, pos_z+47, block_id)
mc.setBlock(pos_x+40, pos_y+13, pos_z+47, block_id)
mc.setBlock(pos_x+17, pos_y+38, pos_z+35, block_id)
mc.setBlock(pos_x+32, pos_y+37, pos_z+35, block_id)
mc.setBlock(pos_x+41, pos_y+13, pos_z+47, block_id)
mc.setBlock(pos_x+42, pos_y+13, pos_z+47, block_id)
mc.setBlock(pos_x+43, pos_y+13, pos_z+47, block_id)
mc.setBlock(pos_x+16, pos_y+37, pos_z+35, block_id)
mc.setBlock(pos_x+33, pos_y+36, pos_z+35, block_id)
mc.setBlock(pos_x+7, pos_y+14, pos_z+47, block_id)
mc.setBlock(pos_x+8, pos_y+14, pos_z+47, block_id)
mc.setBlock(pos_x+9, pos_y+14, pos_z+47, block_id)
mc.setBlock(pos_x+16, pos_y+36, pos_z+35, block_id)
mc.setBlock(pos_x+33, pos_y+35, pos_z+35, block_id)
mc.setBlock(pos_x+10, pos_y+14, pos_z+47, block_id)
mc.setBlock(pos_x+11, pos_y+14, pos_z+47, block_id)
mc.setBlock(pos_x+16, pos_y+35, pos_z+35, block_id)
mc.setBlock(pos_x+33, pos_y+34, pos_z+35, block_id)
mc.setBlock(pos_x+37, pos_y+14, pos_z+47, block_id)
mc.setBlock(pos_x+16, pos_y+34, pos_z+35, block_id)
mc.setBlock(pos_x+34, pos_y+33, pos_z+35, block_id)
mc.setBlock(pos_x+38, pos_y+14, pos_z+47, block_id)
mc.setBlock(pos_x+39, pos_y+14, pos_z+47, block_id)
mc.setBlock(pos_x+15, pos_y+33, pos_z+35, block_id)
mc.setBlock(pos_x+34, pos_y+32, pos_z+35, block_id)
mc.setBlock(pos_x+40, pos_y+14, pos_z+47, block_id)
mc.setBlock(pos_x+41, pos_y+14, pos_z+47, block_id)
mc.setBlock(pos_x+15, pos_y+32, pos_z+35, block_id)
mc.setBlock(pos_x+34, pos_y+31, pos_z+35, block_id)
mc.setBlock(pos_x+42, pos_y+14, pos_z+47, block_id)
mc.setBlock(pos_x+8, pos_y+15, pos_z+47, block_id)
mc.setBlock(pos_x+15, pos_y+31, pos_z+35, block_id)
mc.setBlock(pos_x+37, pos_y+30, pos_z+35, block_id)
mc.setBlock(pos_x+36, pos_y+30, pos_z+35, block_id)
mc.setBlock(pos_x+35, pos_y+30, pos_z+35, block_id)
mc.setBlock(pos_x+9, pos_y+15, pos_z+47, block_id)
mc.setBlock(pos_x+10, pos_y+15, pos_z+47, block_id)
mc.setBlock(pos_x+14, pos_y+30, pos_z+35, block_id)
mc.setBlock(pos_x+13, pos_y+30, pos_z+35, block_id)
mc.setBlock(pos_x+12, pos_y+30, pos_z+35, block_id)
mc.setBlock(pos_x+40, pos_y+29, pos_z+35, block_id)
mc.setBlock(pos_x+39, pos_y+29, pos_z+35, block_id)
mc.setBlock(pos_x+38, pos_y+29, pos_z+35, block_id)
mc.setBlock(pos_x+12, pos_y+15, pos_z+47, block_id)
mc.setBlock(pos_x+36, pos_y+15, pos_z+47, block_id)
mc.setBlock(pos_x+39, pos_y+15, pos_z+47, block_id)
mc.setBlock(pos_x+40, pos_y+15, pos_z+47, block_id)
mc.setBlock(pos_x+41, pos_y+15, pos_z+47, block_id)
mc.setBlock(pos_x+9, pos_y+16, pos_z+47, block_id)
mc.setBlock(pos_x+13, pos_y+16, pos_z+47, block_id)
mc.setBlock(pos_x+36, pos_y+16, pos_z+47, block_id)
mc.setBlock(pos_x+11, pos_y+29, pos_z+35, block_id)
mc.setBlock(pos_x+10, pos_y+29, pos_z+35, block_id)
mc.setBlock(pos_x+9, pos_y+29, pos_z+35, block_id)
mc.setBlock(pos_x+40, pos_y+28, pos_z+35, block_id)
mc.setBlock(pos_x+39, pos_y+28, pos_z+35, block_id)
mc.setBlock(pos_x+38, pos_y+28, pos_z+35, block_id)
mc.setBlock(pos_x+40, pos_y+16, pos_z+47, block_id)
mc.setBlock(pos_x+13, pos_y+17, pos_z+47, block_id)
mc.setBlock(pos_x+36, pos_y+17, pos_z+47, block_id)
mc.setBlock(pos_x+13, pos_y+18, pos_z+47, block_id)
mc.setBlock(pos_x+36, pos_y+18, pos_z+47, block_id)
mc.setBlock(pos_x+13, pos_y+19, pos_z+47, block_id)
mc.setBlock(pos_x+35, pos_y+19, pos_z+47, block_id)
mc.setBlock(pos_x+14, pos_y+20, pos_z+47, block_id)
mc.setBlock(pos_x+11, pos_y+28, pos_z+35, block_id)
mc.setBlock(pos_x+10, pos_y+28, pos_z+35, block_id)
mc.setBlock(pos_x+9, pos_y+28, pos_z+35, block_id)
mc.setBlock(pos_x+8, pos_y+28, pos_z+35, block_id)
mc.setBlock(pos_x+38, pos_y+27, pos_z+35, block_id)
mc.setBlock(pos_x+37, pos_y+27, pos_z+35, block_id)
