from mcpi.minecraft import Minecraft
mc = Minecraft.create("mc.tokyocodingclub.com")
playerId = mc.getPlayerEntityId("TCCMinecraft008")

pos_x, pos_y, pos_z = mc.entity.getPos(playerId)
block_id = 155

mc.setBlock(pos_x+27, pos_y+31, pos_z+22, block_id)
mc.setBlock(pos_x+26, pos_y+31, pos_z+22, block_id)
mc.setBlock(pos_x+25, pos_y+31, pos_z+22, block_id)
mc.setBlock(pos_x+24, pos_y+31, pos_z+22, block_id)
mc.setBlock(pos_x+23, pos_y+31, pos_z+22, block_id)
mc.setBlock(pos_x+22, pos_y+31, pos_z+22, block_id)
mc.setBlock(pos_x+21, pos_y+31, pos_z+22, block_id)
mc.setBlock(pos_x+20, pos_y+31, pos_z+22, block_id)
mc.setBlock(pos_x+46, pos_y+29, pos_z+22, block_id)
mc.setBlock(pos_x+10, pos_y+29, pos_z+22, block_id)
mc.setBlock(pos_x+48, pos_y+28, pos_z+22, block_id)
mc.setBlock(pos_x+47, pos_y+28, pos_z+22, block_id)
mc.setBlock(pos_x+28, pos_y+31, pos_z+22, block_id)
mc.setBlock(pos_x+45, pos_y+28, pos_z+22, block_id)
mc.setBlock(pos_x+10, pos_y+28, pos_z+22, block_id)
mc.setBlock(pos_x+9, pos_y+28, pos_z+22, block_id)
mc.setBlock(pos_x+8, pos_y+28, pos_z+22, block_id)
mc.setBlock(pos_x+50, pos_y+27, pos_z+22, block_id)
mc.setBlock(pos_x+49, pos_y+27, pos_z+22, block_id)
mc.setBlock(pos_x+29, pos_y+31, pos_z+22, block_id)
mc.setBlock(pos_x+30, pos_y+31, pos_z+22, block_id)
mc.setBlock(pos_x+31, pos_y+31, pos_z+22, block_id)
mc.setBlock(pos_x+45, pos_y+27, pos_z+22, block_id)
mc.setBlock(pos_x+11, pos_y+27, pos_z+22, block_id)
mc.setBlock(pos_x+32, pos_y+31, pos_z+22, block_id)
mc.setBlock(pos_x+33, pos_y+31, pos_z+22, block_id)
mc.setBlock(pos_x+34, pos_y+31, pos_z+22, block_id)
mc.setBlock(pos_x+7, pos_y+27, pos_z+22, block_id)
mc.setBlock(pos_x+6, pos_y+27, pos_z+22, block_id)
mc.setBlock(pos_x+50, pos_y+26, pos_z+22, block_id)
mc.setBlock(pos_x+35, pos_y+31, pos_z+22, block_id)
mc.setBlock(pos_x+36, pos_y+31, pos_z+22, block_id)
mc.setBlock(pos_x+45, pos_y+26, pos_z+22, block_id)
mc.setBlock(pos_x+11, pos_y+26, pos_z+22, block_id)
mc.setBlock(pos_x+19, pos_y+32, pos_z+22, block_id)
mc.setBlock(pos_x+37, pos_y+32, pos_z+22, block_id)
mc.setBlock(pos_x+6, pos_y+26, pos_z+22, block_id)
mc.setBlock(pos_x+50, pos_y+25, pos_z+22, block_id)
mc.setBlock(pos_x+18, pos_y+33, pos_z+22, block_id)
mc.setBlock(pos_x+38, pos_y+33, pos_z+22, block_id)
mc.setBlock(pos_x+45, pos_y+25, pos_z+22, block_id)
mc.setBlock(pos_x+11, pos_y+25, pos_z+22, block_id)
mc.setBlock(pos_x+17, pos_y+34, pos_z+22, block_id)
mc.setBlock(pos_x+39, pos_y+34, pos_z+22, block_id)
mc.setBlock(pos_x+6, pos_y+25, pos_z+22, block_id)
mc.setBlock(pos_x+50, pos_y+24, pos_z+22, block_id)
mc.setBlock(pos_x+16, pos_y+35, pos_z+22, block_id)
mc.setBlock(pos_x+40, pos_y+35, pos_z+22, block_id)
mc.setBlock(pos_x+45, pos_y+24, pos_z+22, block_id)
mc.setBlock(pos_x+11, pos_y+24, pos_z+22, block_id)
mc.setBlock(pos_x+16, pos_y+36, pos_z+22, block_id)
mc.setBlock(pos_x+40, pos_y+36, pos_z+22, block_id)
mc.setBlock(pos_x+6, pos_y+24, pos_z+22, block_id)
mc.setBlock(pos_x+49, pos_y+23, pos_z+22, block_id)
mc.setBlock(pos_x+15, pos_y+37, pos_z+22, block_id)
mc.setBlock(pos_x+41, pos_y+37, pos_z+22, block_id)
mc.setBlock(pos_x+15, pos_y+38, pos_z+22, block_id)
mc.setBlock(pos_x+45, pos_y+23, pos_z+22, block_id)
mc.setBlock(pos_x+11, pos_y+23, pos_z+22, block_id)
mc.setBlock(pos_x+41, pos_y+38, pos_z+22, block_id)
mc.setBlock(pos_x+15, pos_y+39, pos_z+22, block_id)
mc.setBlock(pos_x+41, pos_y+39, pos_z+22, block_id)
mc.setBlock(pos_x+7, pos_y+23, pos_z+22, block_id)
mc.setBlock(pos_x+48, pos_y+22, pos_z+22, block_id)
mc.setBlock(pos_x+14, pos_y+40, pos_z+22, block_id)
mc.setBlock(pos_x+46, pos_y+22, pos_z+22, block_id)
mc.setBlock(pos_x+10, pos_y+22, pos_z+22, block_id)
mc.setBlock(pos_x+42, pos_y+40, pos_z+22, block_id)
mc.setBlock(pos_x+8, pos_y+22, pos_z+22, block_id)
mc.setBlock(pos_x+48, pos_y+21, pos_z+22, block_id)
mc.setBlock(pos_x+14, pos_y+41, pos_z+22, block_id)
mc.setBlock(pos_x+46, pos_y+21, pos_z+22, block_id)
mc.setBlock(pos_x+10, pos_y+21, pos_z+22, block_id)
mc.setBlock(pos_x+42, pos_y+41, pos_z+22, block_id)
mc.setBlock(pos_x+8, pos_y+21, pos_z+22, block_id)
mc.setBlock(pos_x+48, pos_y+20, pos_z+22, block_id)
mc.setBlock(pos_x+14, pos_y+42, pos_z+22, block_id)
mc.setBlock(pos_x+42, pos_y+42, pos_z+22, block_id)
mc.setBlock(pos_x+45, pos_y+20, pos_z+22, block_id)
mc.setBlock(pos_x+11, pos_y+20, pos_z+22, block_id)
mc.setBlock(pos_x+13, pos_y+43, pos_z+22, block_id)
mc.setBlock(pos_x+43, pos_y+43, pos_z+22, block_id)
mc.setBlock(pos_x+8, pos_y+20, pos_z+22, block_id)
mc.setBlock(pos_x+48, pos_y+19, pos_z+22, block_id)
mc.setBlock(pos_x+47, pos_y+19, pos_z+22, block_id)
mc.setBlock(pos_x+11, pos_y+44, pos_z+22, block_id)
mc.setBlock(pos_x+45, pos_y+19, pos_z+22, block_id)
mc.setBlock(pos_x+11, pos_y+19, pos_z+22, block_id)
mc.setBlock(pos_x+12, pos_y+44, pos_z+22, block_id)
mc.setBlock(pos_x+43, pos_y+44, pos_z+22, block_id)
mc.setBlock(pos_x+8, pos_y+19, pos_z+22, block_id)
mc.setBlock(pos_x+46, pos_y+18, pos_z+22, block_id)
mc.setBlock(pos_x+45, pos_y+18, pos_z+22, block_id)
mc.setBlock(pos_x+11, pos_y+18, pos_z+22, block_id)
mc.setBlock(pos_x+10, pos_y+18, pos_z+22, block_id)
mc.setBlock(pos_x+9, pos_y+18, pos_z+22, block_id)
mc.setBlock(pos_x+44, pos_y+15, pos_z+22, block_id)
mc.setBlock(pos_x+12, pos_y+15, pos_z+22, block_id)
mc.setBlock(pos_x+44, pos_y+14, pos_z+22, block_id)
mc.setBlock(pos_x+43, pos_y+14, pos_z+22, block_id)
mc.setBlock(pos_x+13, pos_y+14, pos_z+22, block_id)
mc.setBlock(pos_x+12, pos_y+14, pos_z+22, block_id)
mc.setBlock(pos_x+39, pos_y+63, pos_z+21, block_id)
mc.setBlock(pos_x+38, pos_y+63, pos_z+21, block_id)
mc.setBlock(pos_x+37, pos_y+63, pos_z+21, block_id)
mc.setBlock(pos_x+36, pos_y+63, pos_z+21, block_id)
mc.setBlock(pos_x+35, pos_y+63, pos_z+21, block_id)
mc.setBlock(pos_x+34, pos_y+63, pos_z+21, block_id)
mc.setBlock(pos_x+21, pos_y+63, pos_z+21, block_id)
mc.setBlock(pos_x+20, pos_y+63, pos_z+21, block_id)
mc.setBlock(pos_x+19, pos_y+63, pos_z+21, block_id)
mc.setBlock(pos_x+18, pos_y+63, pos_z+21, block_id)
mc.setBlock(pos_x+17, pos_y+63, pos_z+21, block_id)
mc.setBlock(pos_x+40, pos_y+62, pos_z+21, block_id)
mc.setBlock(pos_x+44, pos_y+44, pos_z+22, block_id)
mc.setBlock(pos_x+45, pos_y+44, pos_z+22, block_id)
mc.setBlock(pos_x+11, pos_y+45, pos_z+22, block_id)
mc.setBlock(pos_x+36, pos_y+62, pos_z+21, block_id)
mc.setBlock(pos_x+35, pos_y+62, pos_z+21, block_id)
mc.setBlock(pos_x+34, pos_y+62, pos_z+21, block_id)
mc.setBlock(pos_x+33, pos_y+62, pos_z+21, block_id)
mc.setBlock(pos_x+32, pos_y+62, pos_z+21, block_id)
mc.setBlock(pos_x+31, pos_y+62, pos_z+21, block_id)
mc.setBlock(pos_x+30, pos_y+62, pos_z+21, block_id)
mc.setBlock(pos_x+29, pos_y+62, pos_z+21, block_id)
mc.setBlock(pos_x+28, pos_y+62, pos_z+21, block_id)
mc.setBlock(pos_x+27, pos_y+62, pos_z+21, block_id)
mc.setBlock(pos_x+26, pos_y+62, pos_z+21, block_id)
mc.setBlock(pos_x+25, pos_y+62, pos_z+21, block_id)
mc.setBlock(pos_x+24, pos_y+62, pos_z+21, block_id)
mc.setBlock(pos_x+23, pos_y+62, pos_z+21, block_id)
mc.setBlock(pos_x+22, pos_y+62, pos_z+21, block_id)
mc.setBlock(pos_x+21, pos_y+62, pos_z+21, block_id)
mc.setBlock(pos_x+20, pos_y+62, pos_z+21, block_id)
mc.setBlock(pos_x+45, pos_y+45, pos_z+22, block_id)
mc.setBlock(pos_x+11, pos_y+46, pos_z+22, block_id)
mc.setBlock(pos_x+44, pos_y+46, pos_z+22, block_id)
mc.setBlock(pos_x+16, pos_y+62, pos_z+21, block_id)
mc.setBlock(pos_x+40, pos_y+61, pos_z+21, block_id)
mc.setBlock(pos_x+10, pos_y+47, pos_z+22, block_id)
mc.setBlock(pos_x+11, pos_y+47, pos_z+22, block_id)
mc.setBlock(pos_x+45, pos_y+47, pos_z+22, block_id)
mc.setBlock(pos_x+46, pos_y+47, pos_z+22, block_id)
mc.setBlock(pos_x+9, pos_y+48, pos_z+22, block_id)
mc.setBlock(pos_x+10, pos_y+48, pos_z+22, block_id)
mc.setBlock(pos_x+11, pos_y+48, pos_z+22, block_id)
mc.setBlock(pos_x+45, pos_y+48, pos_z+22, block_id)
mc.setBlock(pos_x+46, pos_y+48, pos_z+22, block_id)
mc.setBlock(pos_x+47, pos_y+48, pos_z+22, block_id)
mc.setBlock(pos_x+29, pos_y+61, pos_z+21, block_id)
mc.setBlock(pos_x+28, pos_y+61, pos_z+21, block_id)
mc.setBlock(pos_x+27, pos_y+61, pos_z+21, block_id)
mc.setBlock(pos_x+9, pos_y+49, pos_z+22, block_id)
mc.setBlock(pos_x+10, pos_y+49, pos_z+22, block_id)
mc.setBlock(pos_x+11, pos_y+49, pos_z+22, block_id)
mc.setBlock(pos_x+45, pos_y+49, pos_z+22, block_id)
mc.setBlock(pos_x+46, pos_y+49, pos_z+22, block_id)
mc.setBlock(pos_x+47, pos_y+49, pos_z+22, block_id)
mc.setBlock(pos_x+9, pos_y+50, pos_z+22, block_id)
mc.setBlock(pos_x+10, pos_y+50, pos_z+22, block_id)
mc.setBlock(pos_x+11, pos_y+50, pos_z+22, block_id)
mc.setBlock(pos_x+45, pos_y+50, pos_z+22, block_id)
mc.setBlock(pos_x+46, pos_y+50, pos_z+22, block_id)
mc.setBlock(pos_x+15, pos_y+61, pos_z+21, block_id)
mc.setBlock(pos_x+41, pos_y+60, pos_z+21, block_id)
mc.setBlock(pos_x+47, pos_y+50, pos_z+22, block_id)
mc.setBlock(pos_x+10, pos_y+51, pos_z+22, block_id)
mc.setBlock(pos_x+11, pos_y+51, pos_z+22, block_id)
mc.setBlock(pos_x+44, pos_y+51, pos_z+22, block_id)
mc.setBlock(pos_x+45, pos_y+51, pos_z+22, block_id)
mc.setBlock(pos_x+46, pos_y+51, pos_z+22, block_id)
mc.setBlock(pos_x+12, pos_y+52, pos_z+22, block_id)
mc.setBlock(pos_x+43, pos_y+52, pos_z+22, block_id)
mc.setBlock(pos_x+13, pos_y+53, pos_z+22, block_id)
mc.setBlock(pos_x+43, pos_y+53, pos_z+22, block_id)
mc.setBlock(pos_x+13, pos_y+54, pos_z+22, block_id)
mc.setBlock(pos_x+43, pos_y+54, pos_z+22, block_id)
mc.setBlock(pos_x+13, pos_y+55, pos_z+22, block_id)
mc.setBlock(pos_x+43, pos_y+55, pos_z+22, block_id)
mc.setBlock(pos_x+13, pos_y+56, pos_z+22, block_id)
mc.setBlock(pos_x+43, pos_y+56, pos_z+22, block_id)
mc.setBlock(pos_x+14, pos_y+57, pos_z+22, block_id)
mc.setBlock(pos_x+42, pos_y+57, pos_z+22, block_id)
mc.setBlock(pos_x+14, pos_y+58, pos_z+22, block_id)
mc.setBlock(pos_x+42, pos_y+58, pos_z+22, block_id)
mc.setBlock(pos_x+15, pos_y+59, pos_z+22, block_id)
mc.setBlock(pos_x+41, pos_y+59, pos_z+22, block_id)
mc.setBlock(pos_x+16, pos_y+60, pos_z+22, block_id)
mc.setBlock(pos_x+24, pos_y+60, pos_z+22, block_id)
mc.setBlock(pos_x+25, pos_y+60, pos_z+22, block_id)
mc.setBlock(pos_x+15, pos_y+60, pos_z+21, block_id)
mc.setBlock(pos_x+42, pos_y+59, pos_z+21, block_id)
mc.setBlock(pos_x+26, pos_y+60, pos_z+22, block_id)
mc.setBlock(pos_x+27, pos_y+60, pos_z+22, block_id)
mc.setBlock(pos_x+28, pos_y+60, pos_z+22, block_id)
mc.setBlock(pos_x+29, pos_y+60, pos_z+22, block_id)
mc.setBlock(pos_x+30, pos_y+60, pos_z+22, block_id)
mc.setBlock(pos_x+31, pos_y+60, pos_z+22, block_id)
mc.setBlock(pos_x+32, pos_y+60, pos_z+22, block_id)
mc.setBlock(pos_x+40, pos_y+60, pos_z+22, block_id)
mc.setBlock(pos_x+16, pos_y+61, pos_z+22, block_id)
mc.setBlock(pos_x+17, pos_y+61, pos_z+22, block_id)
mc.setBlock(pos_x+18, pos_y+61, pos_z+22, block_id)
mc.setBlock(pos_x+19, pos_y+61, pos_z+22, block_id)
mc.setBlock(pos_x+20, pos_y+61, pos_z+22, block_id)
mc.setBlock(pos_x+21, pos_y+61, pos_z+22, block_id)
mc.setBlock(pos_x+22, pos_y+61, pos_z+22, block_id)
mc.setBlock(pos_x+23, pos_y+61, pos_z+22, block_id)
mc.setBlock(pos_x+24, pos_y+61, pos_z+22, block_id)
mc.setBlock(pos_x+25, pos_y+61, pos_z+22, block_id)
mc.setBlock(pos_x+26, pos_y+61, pos_z+22, block_id)
mc.setBlock(pos_x+30, pos_y+61, pos_z+22, block_id)
mc.setBlock(pos_x+31, pos_y+61, pos_z+22, block_id)
mc.setBlock(pos_x+32, pos_y+61, pos_z+22, block_id)
mc.setBlock(pos_x+33, pos_y+61, pos_z+22, block_id)
mc.setBlock(pos_x+14, pos_y+59, pos_z+21, block_id)
mc.setBlock(pos_x+42, pos_y+58, pos_z+21, block_id)
mc.setBlock(pos_x+34, pos_y+61, pos_z+22, block_id)
mc.setBlock(pos_x+35, pos_y+61, pos_z+22, block_id)
mc.setBlock(pos_x+36, pos_y+61, pos_z+22, block_id)
mc.setBlock(pos_x+37, pos_y+61, pos_z+22, block_id)
mc.setBlock(pos_x+38, pos_y+61, pos_z+22, block_id)
mc.setBlock(pos_x+14, pos_y+58, pos_z+21, block_id)
mc.setBlock(pos_x+43, pos_y+57, pos_z+21, block_id)
mc.setBlock(pos_x+39, pos_y+61, pos_z+22, block_id)
mc.setBlock(pos_x+40, pos_y+61, pos_z+22, block_id)
mc.setBlock(pos_x+17, pos_y+62, pos_z+22, block_id)
mc.setBlock(pos_x+18, pos_y+62, pos_z+22, block_id)
mc.setBlock(pos_x+19, pos_y+62, pos_z+22, block_id)
mc.setBlock(pos_x+37, pos_y+62, pos_z+22, block_id)
mc.setBlock(pos_x+13, pos_y+57, pos_z+21, block_id)
mc.setBlock(pos_x+43, pos_y+56, pos_z+21, block_id)
mc.setBlock(pos_x+38, pos_y+62, pos_z+22, block_id)
mc.setBlock(pos_x+39, pos_y+62, pos_z+22, block_id)
mc.setBlock(pos_x+12, pos_y+14, pos_z+23, block_id)
mc.setBlock(pos_x+43, pos_y+14, pos_z+23, block_id)
mc.setBlock(pos_x+44, pos_y+14, pos_z+23, block_id)
mc.setBlock(pos_x+13, pos_y+56, pos_z+21, block_id)
mc.setBlock(pos_x+43, pos_y+55, pos_z+21, block_id)
mc.setBlock(pos_x+11, pos_y+15, pos_z+23, block_id)
mc.setBlock(pos_x+12, pos_y+15, pos_z+23, block_id)
mc.setBlock(pos_x+44, pos_y+15, pos_z+23, block_id)
mc.setBlock(pos_x+45, pos_y+15, pos_z+23, block_id)
mc.setBlock(pos_x+13, pos_y+55, pos_z+21, block_id)
mc.setBlock(pos_x+43, pos_y+54, pos_z+21, block_id)
mc.setBlock(pos_x+11, pos_y+16, pos_z+23, block_id)
mc.setBlock(pos_x+12, pos_y+16, pos_z+23, block_id)
mc.setBlock(pos_x+13, pos_y+54, pos_z+21, block_id)
mc.setBlock(pos_x+47, pos_y+53, pos_z+21, block_id)
mc.setBlock(pos_x+46, pos_y+53, pos_z+21, block_id)
mc.setBlock(pos_x+45, pos_y+53, pos_z+21, block_id)
mc.setBlock(pos_x+44, pos_y+53, pos_z+21, block_id)
mc.setBlock(pos_x+44, pos_y+16, pos_z+23, block_id)
mc.setBlock(pos_x+45, pos_y+16, pos_z+23, block_id)
mc.setBlock(pos_x+11, pos_y+17, pos_z+23, block_id)
mc.setBlock(pos_x+12, pos_y+17, pos_z+23, block_id)
mc.setBlock(pos_x+12, pos_y+53, pos_z+21, block_id)
mc.setBlock(pos_x+11, pos_y+53, pos_z+21, block_id)
mc.setBlock(pos_x+10, pos_y+53, pos_z+21, block_id)
mc.setBlock(pos_x+9, pos_y+53, pos_z+21, block_id)
mc.setBlock(pos_x+8, pos_y+53, pos_z+21, block_id)
mc.setBlock(pos_x+49, pos_y+52, pos_z+21, block_id)
mc.setBlock(pos_x+48, pos_y+52, pos_z+21, block_id)
mc.setBlock(pos_x+47, pos_y+52, pos_z+21, block_id)
mc.setBlock(pos_x+46, pos_y+52, pos_z+21, block_id)
mc.setBlock(pos_x+45, pos_y+52, pos_z+21, block_id)
mc.setBlock(pos_x+44, pos_y+52, pos_z+21, block_id)
mc.setBlock(pos_x+44, pos_y+17, pos_z+23, block_id)
mc.setBlock(pos_x+45, pos_y+17, pos_z+23, block_id)
mc.setBlock(pos_x+10, pos_y+18, pos_z+23, block_id)
mc.setBlock(pos_x+11, pos_y+18, pos_z+23, block_id)
mc.setBlock(pos_x+45, pos_y+18, pos_z+23, block_id)
mc.setBlock(pos_x+11, pos_y+52, pos_z+21, block_id)
mc.setBlock(pos_x+10, pos_y+52, pos_z+21, block_id)
mc.setBlock(pos_x+9, pos_y+52, pos_z+21, block_id)
mc.setBlock(pos_x+8, pos_y+52, pos_z+21, block_id)
mc.setBlock(pos_x+7, pos_y+52, pos_z+21, block_id)
mc.setBlock(pos_x+49, pos_y+51, pos_z+21, block_id)
mc.setBlock(pos_x+48, pos_y+51, pos_z+21, block_id)
mc.setBlock(pos_x+47, pos_y+51, pos_z+21, block_id)
mc.setBlock(pos_x+46, pos_y+18, pos_z+23, block_id)
mc.setBlock(pos_x+8, pos_y+19, pos_z+23, block_id)
mc.setBlock(pos_x+9, pos_y+19, pos_z+23, block_id)
mc.setBlock(pos_x+11, pos_y+19, pos_z+23, block_id)
mc.setBlock(pos_x+45, pos_y+19, pos_z+23, block_id)
mc.setBlock(pos_x+47, pos_y+19, pos_z+23, block_id)
mc.setBlock(pos_x+48, pos_y+19, pos_z+23, block_id)
mc.setBlock(pos_x+7, pos_y+20, pos_z+23, block_id)
mc.setBlock(pos_x+11, pos_y+20, pos_z+23, block_id)
mc.setBlock(pos_x+45, pos_y+20, pos_z+23, block_id)
mc.setBlock(pos_x+49, pos_y+20, pos_z+23, block_id)
mc.setBlock(pos_x+7, pos_y+21, pos_z+23, block_id)
mc.setBlock(pos_x+9, pos_y+51, pos_z+21, block_id)
mc.setBlock(pos_x+8, pos_y+51, pos_z+21, block_id)
mc.setBlock(pos_x+7, pos_y+51, pos_z+21, block_id)
mc.setBlock(pos_x+49, pos_y+50, pos_z+21, block_id)
mc.setBlock(pos_x+48, pos_y+50, pos_z+21, block_id)
mc.setBlock(pos_x+11, pos_y+21, pos_z+23, block_id)
mc.setBlock(pos_x+45, pos_y+21, pos_z+23, block_id)
mc.setBlock(pos_x+49, pos_y+21, pos_z+23, block_id)
mc.setBlock(pos_x+7, pos_y+22, pos_z+23, block_id)
mc.setBlock(pos_x+11, pos_y+22, pos_z+23, block_id)
mc.setBlock(pos_x+45, pos_y+22, pos_z+23, block_id)
mc.setBlock(pos_x+49, pos_y+22, pos_z+23, block_id)
mc.setBlock(pos_x+6, pos_y+23, pos_z+23, block_id)
mc.setBlock(pos_x+11, pos_y+23, pos_z+23, block_id)
mc.setBlock(pos_x+44, pos_y+23, pos_z+23, block_id)
mc.setBlock(pos_x+50, pos_y+23, pos_z+23, block_id)
mc.setBlock(pos_x+6, pos_y+24, pos_z+23, block_id)
mc.setBlock(pos_x+8, pos_y+50, pos_z+21, block_id)
mc.setBlock(pos_x+7, pos_y+50, pos_z+21, block_id)
mc.setBlock(pos_x+49, pos_y+49, pos_z+21, block_id)
mc.setBlock(pos_x+48, pos_y+49, pos_z+21, block_id)
mc.setBlock(pos_x+12, pos_y+24, pos_z+23, block_id)
mc.setBlock(pos_x+44, pos_y+24, pos_z+23, block_id)
mc.setBlock(pos_x+50, pos_y+24, pos_z+23, block_id)
mc.setBlock(pos_x+6, pos_y+25, pos_z+23, block_id)
mc.setBlock(pos_x+12, pos_y+25, pos_z+23, block_id)
mc.setBlock(pos_x+44, pos_y+25, pos_z+23, block_id)
mc.setBlock(pos_x+50, pos_y+25, pos_z+23, block_id)
mc.setBlock(pos_x+6, pos_y+26, pos_z+23, block_id)
mc.setBlock(pos_x+12, pos_y+26, pos_z+23, block_id)
mc.setBlock(pos_x+8, pos_y+49, pos_z+21, block_id)
mc.setBlock(pos_x+7, pos_y+49, pos_z+21, block_id)
mc.setBlock(pos_x+6, pos_y+49, pos_z+21, block_id)
mc.setBlock(pos_x+49, pos_y+48, pos_z+21, block_id)
mc.setBlock(pos_x+48, pos_y+48, pos_z+21, block_id)
mc.setBlock(pos_x+44, pos_y+26, pos_z+23, block_id)
mc.setBlock(pos_x+50, pos_y+26, pos_z+23, block_id)
mc.setBlock(pos_x+6, pos_y+27, pos_z+23, block_id)
mc.setBlock(pos_x+12, pos_y+27, pos_z+23, block_id)
mc.setBlock(pos_x+44, pos_y+27, pos_z+23, block_id)
mc.setBlock(pos_x+50, pos_y+27, pos_z+23, block_id)
mc.setBlock(pos_x+7, pos_y+28, pos_z+23, block_id)
mc.setBlock(pos_x+8, pos_y+28, pos_z+23, block_id)
mc.setBlock(pos_x+11, pos_y+28, pos_z+23, block_id)
mc.setBlock(pos_x+45, pos_y+28, pos_z+23, block_id)
mc.setBlock(pos_x+48, pos_y+28, pos_z+23, block_id)
mc.setBlock(pos_x+8, pos_y+48, pos_z+21, block_id)
mc.setBlock(pos_x+7, pos_y+48, pos_z+21, block_id)
mc.setBlock(pos_x+6, pos_y+48, pos_z+21, block_id)
mc.setBlock(pos_x+49, pos_y+47, pos_z+21, block_id)
mc.setBlock(pos_x+48, pos_y+47, pos_z+21, block_id)
mc.setBlock(pos_x+47, pos_y+47, pos_z+21, block_id)
mc.setBlock(pos_x+49, pos_y+28, pos_z+23, block_id)
mc.setBlock(pos_x+9, pos_y+29, pos_z+23, block_id)
mc.setBlock(pos_x+10, pos_y+29, pos_z+23, block_id)
mc.setBlock(pos_x+11, pos_y+29, pos_z+23, block_id)
mc.setBlock(pos_x+45, pos_y+29, pos_z+23, block_id)
mc.setBlock(pos_x+46, pos_y+29, pos_z+23, block_id)
mc.setBlock(pos_x+47, pos_y+29, pos_z+23, block_id)
mc.setBlock(pos_x+20, pos_y+30, pos_z+23, block_id)
mc.setBlock(pos_x+21, pos_y+30, pos_z+23, block_id)
mc.setBlock(pos_x+22, pos_y+30, pos_z+23, block_id)
mc.setBlock(pos_x+23, pos_y+30, pos_z+23, block_id)
mc.setBlock(pos_x+33, pos_y+30, pos_z+23, block_id)
mc.setBlock(pos_x+9, pos_y+47, pos_z+21, block_id)
mc.setBlock(pos_x+8, pos_y+47, pos_z+21, block_id)
mc.setBlock(pos_x+7, pos_y+47, pos_z+21, block_id)
mc.setBlock(pos_x+49, pos_y+46, pos_z+21, block_id)
mc.setBlock(pos_x+48, pos_y+46, pos_z+21, block_id)
mc.setBlock(pos_x+47, pos_y+46, pos_z+21, block_id)
mc.setBlock(pos_x+46, pos_y+46, pos_z+21, block_id)
mc.setBlock(pos_x+45, pos_y+46, pos_z+21, block_id)
mc.setBlock(pos_x+34, pos_y+30, pos_z+23, block_id)
mc.setBlock(pos_x+35, pos_y+30, pos_z+23, block_id)
mc.setBlock(pos_x+36, pos_y+30, pos_z+23, block_id)
mc.setBlock(pos_x+19, pos_y+31, pos_z+23, block_id)
mc.setBlock(pos_x+24, pos_y+31, pos_z+23, block_id)
mc.setBlock(pos_x+25, pos_y+31, pos_z+23, block_id)
mc.setBlock(pos_x+26, pos_y+31, pos_z+23, block_id)
mc.setBlock(pos_x+10, pos_y+46, pos_z+21, block_id)
mc.setBlock(pos_x+9, pos_y+46, pos_z+21, block_id)
mc.setBlock(pos_x+8, pos_y+46, pos_z+21, block_id)
mc.setBlock(pos_x+7, pos_y+46, pos_z+21, block_id)
mc.setBlock(pos_x+48, pos_y+45, pos_z+21, block_id)
mc.setBlock(pos_x+47, pos_y+45, pos_z+21, block_id)
mc.setBlock(pos_x+46, pos_y+45, pos_z+21, block_id)
mc.setBlock(pos_x+27, pos_y+31, pos_z+23, block_id)
mc.setBlock(pos_x+28, pos_y+31, pos_z+23, block_id)
mc.setBlock(pos_x+43, pos_y+45, pos_z+21, block_id)
mc.setBlock(pos_x+29, pos_y+31, pos_z+23, block_id)
mc.setBlock(pos_x+30, pos_y+31, pos_z+23, block_id)
mc.setBlock(pos_x+31, pos_y+31, pos_z+23, block_id)
mc.setBlock(pos_x+32, pos_y+31, pos_z+23, block_id)
mc.setBlock(pos_x+37, pos_y+31, pos_z+23, block_id)
mc.setBlock(pos_x+10, pos_y+45, pos_z+21, block_id)
mc.setBlock(pos_x+9, pos_y+45, pos_z+21, block_id)
mc.setBlock(pos_x+8, pos_y+45, pos_z+21, block_id)
mc.setBlock(pos_x+47, pos_y+44, pos_z+21, block_id)
mc.setBlock(pos_x+46, pos_y+44, pos_z+21, block_id)
mc.setBlock(pos_x+45, pos_y+44, pos_z+21, block_id)
mc.setBlock(pos_x+44, pos_y+44, pos_z+21, block_id)
mc.setBlock(pos_x+42, pos_y+44, pos_z+21, block_id)
mc.setBlock(pos_x+18, pos_y+32, pos_z+23, block_id)
mc.setBlock(pos_x+13, pos_y+44, pos_z+21, block_id)
mc.setBlock(pos_x+12, pos_y+44, pos_z+21, block_id)
mc.setBlock(pos_x+11, pos_y+44, pos_z+21, block_id)
mc.setBlock(pos_x+10, pos_y+44, pos_z+21, block_id)
mc.setBlock(pos_x+9, pos_y+44, pos_z+21, block_id)
mc.setBlock(pos_x+42, pos_y+43, pos_z+21, block_id)
mc.setBlock(pos_x+14, pos_y+43, pos_z+21, block_id)
mc.setBlock(pos_x+42, pos_y+42, pos_z+21, block_id)
mc.setBlock(pos_x+14, pos_y+42, pos_z+21, block_id)
mc.setBlock(pos_x+42, pos_y+41, pos_z+21, block_id)
mc.setBlock(pos_x+38, pos_y+32, pos_z+23, block_id)
mc.setBlock(pos_x+14, pos_y+41, pos_z+21, block_id)
mc.setBlock(pos_x+42, pos_y+40, pos_z+21, block_id)
mc.setBlock(pos_x+18, pos_y+33, pos_z+23, block_id)
mc.setBlock(pos_x+38, pos_y+33, pos_z+23, block_id)
mc.setBlock(pos_x+14, pos_y+40, pos_z+21, block_id)
mc.setBlock(pos_x+41, pos_y+39, pos_z+21, block_id)
mc.setBlock(pos_x+15, pos_y+39, pos_z+21, block_id)
mc.setBlock(pos_x+41, pos_y+38, pos_z+21, block_id)
mc.setBlock(pos_x+17, pos_y+34, pos_z+23, block_id)
mc.setBlock(pos_x+39, pos_y+34, pos_z+23, block_id)
mc.setBlock(pos_x+15, pos_y+38, pos_z+21, block_id)
mc.setBlock(pos_x+40, pos_y+37, pos_z+21, block_id)
mc.setBlock(pos_x+16, pos_y+37, pos_z+21, block_id)
mc.setBlock(pos_x+40, pos_y+36, pos_z+21, block_id)
mc.setBlock(pos_x+16, pos_y+35, pos_z+23, block_id)
mc.setBlock(pos_x+40, pos_y+35, pos_z+23, block_id)
mc.setBlock(pos_x+16, pos_y+36, pos_z+21, block_id)
mc.setBlock(pos_x+39, pos_y+35, pos_z+21, block_id)
mc.setBlock(pos_x+16, pos_y+36, pos_z+23, block_id)
mc.setBlock(pos_x+40, pos_y+36, pos_z+23, block_id)
mc.setBlock(pos_x+17, pos_y+35, pos_z+21, block_id)
mc.setBlock(pos_x+38, pos_y+34, pos_z+21, block_id)
mc.setBlock(pos_x+15, pos_y+37, pos_z+23, block_id)
mc.setBlock(pos_x+41, pos_y+37, pos_z+23, block_id)
mc.setBlock(pos_x+15, pos_y+38, pos_z+23, block_id)
mc.setBlock(pos_x+17, pos_y+34, pos_z+21, block_id)
mc.setBlock(pos_x+38, pos_y+33, pos_z+21, block_id)
mc.setBlock(pos_x+41, pos_y+38, pos_z+23, block_id)
mc.setBlock(pos_x+14, pos_y+39, pos_z+23, block_id)
mc.setBlock(pos_x+41, pos_y+39, pos_z+23, block_id)
mc.setBlock(pos_x+14, pos_y+40, pos_z+23, block_id)
mc.setBlock(pos_x+18, pos_y+33, pos_z+21, block_id)
mc.setBlock(pos_x+37, pos_y+32, pos_z+21, block_id)
mc.setBlock(pos_x+42, pos_y+40, pos_z+23, block_id)
mc.setBlock(pos_x+14, pos_y+41, pos_z+23, block_id)
mc.setBlock(pos_x+42, pos_y+41, pos_z+23, block_id)
mc.setBlock(pos_x+33, pos_y+32, pos_z+21, block_id)
mc.setBlock(pos_x+32, pos_y+32, pos_z+21, block_id)
mc.setBlock(pos_x+31, pos_y+32, pos_z+21, block_id)
mc.setBlock(pos_x+30, pos_y+32, pos_z+21, block_id)
mc.setBlock(pos_x+29, pos_y+32, pos_z+21, block_id)
mc.setBlock(pos_x+28, pos_y+32, pos_z+21, block_id)
mc.setBlock(pos_x+27, pos_y+32, pos_z+21, block_id)
mc.setBlock(pos_x+26, pos_y+32, pos_z+21, block_id)
mc.setBlock(pos_x+25, pos_y+32, pos_z+21, block_id)
mc.setBlock(pos_x+24, pos_y+32, pos_z+21, block_id)
mc.setBlock(pos_x+23, pos_y+32, pos_z+21, block_id)
mc.setBlock(pos_x+14, pos_y+42, pos_z+23, block_id)
mc.setBlock(pos_x+42, pos_y+42, pos_z+23, block_id)
mc.setBlock(pos_x+12, pos_y+43, pos_z+23, block_id)
mc.setBlock(pos_x+19, pos_y+32, pos_z+21, block_id)
mc.setBlock(pos_x+36, pos_y+31, pos_z+21, block_id)
mc.setBlock(pos_x+35, pos_y+31, pos_z+21, block_id)
mc.setBlock(pos_x+34, pos_y+31, pos_z+21, block_id)
mc.setBlock(pos_x+22, pos_y+31, pos_z+21, block_id)
mc.setBlock(pos_x+21, pos_y+31, pos_z+21, block_id)
mc.setBlock(pos_x+20, pos_y+31, pos_z+21, block_id)
mc.setBlock(pos_x+47, pos_y+28, pos_z+21, block_id)
mc.setBlock(pos_x+46, pos_y+28, pos_z+21, block_id)
mc.setBlock(pos_x+10, pos_y+28, pos_z+21, block_id)
mc.setBlock(pos_x+9, pos_y+28, pos_z+21, block_id)
mc.setBlock(pos_x+49, pos_y+27, pos_z+21, block_id)
mc.setBlock(pos_x+48, pos_y+27, pos_z+21, block_id)
mc.setBlock(pos_x+13, pos_y+43, pos_z+23, block_id)
mc.setBlock(pos_x+46, pos_y+27, pos_z+21, block_id)
mc.setBlock(pos_x+10, pos_y+27, pos_z+21, block_id)
mc.setBlock(pos_x+43, pos_y+43, pos_z+23, block_id)
mc.setBlock(pos_x+8, pos_y+27, pos_z+21, block_id)
mc.setBlock(pos_x+7, pos_y+27, pos_z+21, block_id)
mc.setBlock(pos_x+49, pos_y+26, pos_z+21, block_id)
mc.setBlock(pos_x+44, pos_y+43, pos_z+23, block_id)
mc.setBlock(pos_x+9, pos_y+44, pos_z+23, block_id)
mc.setBlock(pos_x+46, pos_y+26, pos_z+21, block_id)
mc.setBlock(pos_x+10, pos_y+26, pos_z+21, block_id)
mc.setBlock(pos_x+10, pos_y+44, pos_z+23, block_id)
mc.setBlock(pos_x+11, pos_y+44, pos_z+23, block_id)
mc.setBlock(pos_x+45, pos_y+44, pos_z+23, block_id)
mc.setBlock(pos_x+6, pos_y+26, pos_z+21, block_id)
mc.setBlock(pos_x+49, pos_y+25, pos_z+21, block_id)
mc.setBlock(pos_x+46, pos_y+44, pos_z+23, block_id)
mc.setBlock(pos_x+47, pos_y+44, pos_z+23, block_id)
mc.setBlock(pos_x+46, pos_y+25, pos_z+21, block_id)
mc.setBlock(pos_x+10, pos_y+25, pos_z+21, block_id)
mc.setBlock(pos_x+9, pos_y+45, pos_z+23, block_id)
mc.setBlock(pos_x+7, pos_y+25, pos_z+21, block_id)
mc.setBlock(pos_x+49, pos_y+24, pos_z+21, block_id)
mc.setBlock(pos_x+10, pos_y+45, pos_z+23, block_id)
mc.setBlock(pos_x+46, pos_y+24, pos_z+21, block_id)
mc.setBlock(pos_x+10, pos_y+24, pos_z+21, block_id)
mc.setBlock(pos_x+46, pos_y+45, pos_z+23, block_id)
mc.setBlock(pos_x+7, pos_y+24, pos_z+21, block_id)
mc.setBlock(pos_x+49, pos_y+23, pos_z+21, block_id)
mc.setBlock(pos_x+47, pos_y+45, pos_z+23, block_id)
mc.setBlock(pos_x+9, pos_y+46, pos_z+23, block_id)
mc.setBlock(pos_x+46, pos_y+23, pos_z+21, block_id)
mc.setBlock(pos_x+10, pos_y+23, pos_z+21, block_id)
mc.setBlock(pos_x+10, pos_y+46, pos_z+23, block_id)
mc.setBlock(pos_x+11, pos_y+46, pos_z+23, block_id)
mc.setBlock(pos_x+7, pos_y+23, pos_z+21, block_id)
mc.setBlock(pos_x+48, pos_y+22, pos_z+21, block_id)
mc.setBlock(pos_x+45, pos_y+46, pos_z+23, block_id)
mc.setBlock(pos_x+46, pos_y+22, pos_z+21, block_id)
mc.setBlock(pos_x+10, pos_y+22, pos_z+21, block_id)
mc.setBlock(pos_x+46, pos_y+46, pos_z+23, block_id)
mc.setBlock(pos_x+8, pos_y+22, pos_z+21, block_id)
mc.setBlock(pos_x+47, pos_y+21, pos_z+21, block_id)
mc.setBlock(pos_x+46, pos_y+21, pos_z+21, block_id)
mc.setBlock(pos_x+10, pos_y+21, pos_z+21, block_id)
mc.setBlock(pos_x+9, pos_y+21, pos_z+21, block_id)
mc.setBlock(pos_x+47, pos_y+20, pos_z+21, block_id)
mc.setBlock(pos_x+47, pos_y+46, pos_z+23, block_id)
mc.setBlock(pos_x+45, pos_y+20, pos_z+21, block_id)
mc.setBlock(pos_x+10, pos_y+20, pos_z+21, block_id)
mc.setBlock(pos_x+9, pos_y+20, pos_z+21, block_id)
mc.setBlock(pos_x+47, pos_y+19, pos_z+21, block_id)
mc.setBlock(pos_x+12, pos_y+47, pos_z+23, block_id)
mc.setBlock(pos_x+45, pos_y+19, pos_z+21, block_id)
mc.setBlock(pos_x+11, pos_y+19, pos_z+21, block_id)
mc.setBlock(pos_x+44, pos_y+47, pos_z+23, block_id)
mc.setBlock(pos_x+9, pos_y+19, pos_z+21, block_id)
mc.setBlock(pos_x+47, pos_y+18, pos_z+21, block_id)
mc.setBlock(pos_x+46, pos_y+18, pos_z+21, block_id)
mc.setBlock(pos_x+45, pos_y+18, pos_z+21, block_id)
mc.setBlock(pos_x+11, pos_y+18, pos_z+21, block_id)
mc.setBlock(pos_x+10, pos_y+18, pos_z+21, block_id)
mc.setBlock(pos_x+9, pos_y+18, pos_z+21, block_id)
mc.setBlock(pos_x+45, pos_y+17, pos_z+21, block_id)
mc.setBlock(pos_x+11, pos_y+17, pos_z+21, block_id)
mc.setBlock(pos_x+39, pos_y+65, pos_z+20, block_id)
mc.setBlock(pos_x+38, pos_y+65, pos_z+20, block_id)
mc.setBlock(pos_x+37, pos_y+65, pos_z+20, block_id)
mc.setBlock(pos_x+36, pos_y+65, pos_z+20, block_id)
mc.setBlock(pos_x+20, pos_y+65, pos_z+20, block_id)
mc.setBlock(pos_x+19, pos_y+65, pos_z+20, block_id)
mc.setBlock(pos_x+18, pos_y+65, pos_z+20, block_id)
mc.setBlock(pos_x+17, pos_y+65, pos_z+20, block_id)
mc.setBlock(pos_x+39, pos_y+64, pos_z+20, block_id)
mc.setBlock(pos_x+38, pos_y+64, pos_z+20, block_id)
mc.setBlock(pos_x+37, pos_y+64, pos_z+20, block_id)
mc.setBlock(pos_x+36, pos_y+64, pos_z+20, block_id)
mc.setBlock(pos_x+35, pos_y+64, pos_z+20, block_id)
mc.setBlock(pos_x+34, pos_y+64, pos_z+20, block_id)
mc.setBlock(pos_x+33, pos_y+64, pos_z+20, block_id)
mc.setBlock(pos_x+32, pos_y+64, pos_z+20, block_id)
mc.setBlock(pos_x+31, pos_y+64, pos_z+20, block_id)
mc.setBlock(pos_x+30, pos_y+64, pos_z+20, block_id)
mc.setBlock(pos_x+26, pos_y+64, pos_z+20, block_id)
mc.setBlock(pos_x+25, pos_y+64, pos_z+20, block_id)
mc.setBlock(pos_x+24, pos_y+64, pos_z+20, block_id)
mc.setBlock(pos_x+23, pos_y+64, pos_z+20, block_id)
mc.setBlock(pos_x+22, pos_y+64, pos_z+20, block_id)
mc.setBlock(pos_x+21, pos_y+64, pos_z+20, block_id)
mc.setBlock(pos_x+20, pos_y+64, pos_z+20, block_id)
mc.setBlock(pos_x+19, pos_y+64, pos_z+20, block_id)
mc.setBlock(pos_x+18, pos_y+64, pos_z+20, block_id)
mc.setBlock(pos_x+17, pos_y+64, pos_z+20, block_id)
mc.setBlock(pos_x+40, pos_y+63, pos_z+20, block_id)
mc.setBlock(pos_x+12, pos_y+48, pos_z+23, block_id)
mc.setBlock(pos_x+44, pos_y+48, pos_z+23, block_id)
mc.setBlock(pos_x+12, pos_y+49, pos_z+23, block_id)
mc.setBlock(pos_x+44, pos_y+49, pos_z+23, block_id)
mc.setBlock(pos_x+12, pos_y+50, pos_z+23, block_id)
mc.setBlock(pos_x+44, pos_y+50, pos_z+23, block_id)
mc.setBlock(pos_x+33, pos_y+63, pos_z+20, block_id)
mc.setBlock(pos_x+32, pos_y+63, pos_z+20, block_id)
mc.setBlock(pos_x+31, pos_y+63, pos_z+20, block_id)
mc.setBlock(pos_x+30, pos_y+63, pos_z+20, block_id)
mc.setBlock(pos_x+29, pos_y+63, pos_z+20, block_id)
mc.setBlock(pos_x+28, pos_y+63, pos_z+20, block_id)
mc.setBlock(pos_x+27, pos_y+63, pos_z+20, block_id)
mc.setBlock(pos_x+26, pos_y+63, pos_z+20, block_id)
mc.setBlock(pos_x+25, pos_y+63, pos_z+20, block_id)
mc.setBlock(pos_x+24, pos_y+63, pos_z+20, block_id)
mc.setBlock(pos_x+23, pos_y+63, pos_z+20, block_id)
mc.setBlock(pos_x+22, pos_y+63, pos_z+20, block_id)
mc.setBlock(pos_x+12, pos_y+51, pos_z+23, block_id)
mc.setBlock(pos_x+43, pos_y+51, pos_z+23, block_id)
mc.setBlock(pos_x+13, pos_y+52, pos_z+23, block_id)
mc.setBlock(pos_x+43, pos_y+52, pos_z+23, block_id)
mc.setBlock(pos_x+13, pos_y+53, pos_z+23, block_id)
mc.setBlock(pos_x+16, pos_y+63, pos_z+20, block_id)
mc.setBlock(pos_x+41, pos_y+62, pos_z+20, block_id)
mc.setBlock(pos_x+43, pos_y+53, pos_z+23, block_id)
mc.setBlock(pos_x+13, pos_y+54, pos_z+23, block_id)
mc.setBlock(pos_x+43, pos_y+54, pos_z+23, block_id)
mc.setBlock(pos_x+13, pos_y+55, pos_z+23, block_id)
mc.setBlock(pos_x+43, pos_y+55, pos_z+23, block_id)
mc.setBlock(pos_x+14, pos_y+56, pos_z+23, block_id)
mc.setBlock(pos_x+42, pos_y+56, pos_z+23, block_id)
mc.setBlock(pos_x+14, pos_y+57, pos_z+23, block_id)
mc.setBlock(pos_x+42, pos_y+57, pos_z+23, block_id)
mc.setBlock(pos_x+15, pos_y+58, pos_z+23, block_id)
mc.setBlock(pos_x+41, pos_y+58, pos_z+23, block_id)
mc.setBlock(pos_x+16, pos_y+59, pos_z+23, block_id)
mc.setBlock(pos_x+23, pos_y+59, pos_z+23, block_id)
mc.setBlock(pos_x+24, pos_y+59, pos_z+23, block_id)
mc.setBlock(pos_x+25, pos_y+59, pos_z+23, block_id)
mc.setBlock(pos_x+26, pos_y+59, pos_z+23, block_id)
mc.setBlock(pos_x+27, pos_y+59, pos_z+23, block_id)
mc.setBlock(pos_x+28, pos_y+59, pos_z+23, block_id)
mc.setBlock(pos_x+29, pos_y+59, pos_z+23, block_id)
mc.setBlock(pos_x+30, pos_y+59, pos_z+23, block_id)
mc.setBlock(pos_x+31, pos_y+59, pos_z+23, block_id)
mc.setBlock(pos_x+32, pos_y+59, pos_z+23, block_id)
mc.setBlock(pos_x+33, pos_y+59, pos_z+23, block_id)
mc.setBlock(pos_x+40, pos_y+59, pos_z+23, block_id)
mc.setBlock(pos_x+17, pos_y+60, pos_z+23, block_id)
mc.setBlock(pos_x+15, pos_y+62, pos_z+20, block_id)
mc.setBlock(pos_x+41, pos_y+61, pos_z+20, block_id)
mc.setBlock(pos_x+18, pos_y+60, pos_z+23, block_id)
mc.setBlock(pos_x+19, pos_y+60, pos_z+23, block_id)
mc.setBlock(pos_x+20, pos_y+60, pos_z+23, block_id)
mc.setBlock(pos_x+21, pos_y+60, pos_z+23, block_id)
mc.setBlock(pos_x+22, pos_y+60, pos_z+23, block_id)
mc.setBlock(pos_x+23, pos_y+60, pos_z+23, block_id)
mc.setBlock(pos_x+33, pos_y+60, pos_z+23, block_id)
mc.setBlock(pos_x+34, pos_y+60, pos_z+23, block_id)
mc.setBlock(pos_x+35, pos_y+60, pos_z+23, block_id)
mc.setBlock(pos_x+36, pos_y+60, pos_z+23, block_id)
mc.setBlock(pos_x+37, pos_y+60, pos_z+23, block_id)
mc.setBlock(pos_x+38, pos_y+60, pos_z+23, block_id)
mc.setBlock(pos_x+39, pos_y+60, pos_z+23, block_id)
mc.setBlock(pos_x+11, pos_y+15, pos_z+24, block_id)
mc.setBlock(pos_x+12, pos_y+15, pos_z+24, block_id)
mc.setBlock(pos_x+44, pos_y+15, pos_z+24, block_id)
mc.setBlock(pos_x+45, pos_y+15, pos_z+24, block_id)
mc.setBlock(pos_x+10, pos_y+16, pos_z+24, block_id)
mc.setBlock(pos_x+12, pos_y+16, pos_z+24, block_id)
mc.setBlock(pos_x+44, pos_y+16, pos_z+24, block_id)
mc.setBlock(pos_x+46, pos_y+16, pos_z+24, block_id)
mc.setBlock(pos_x+10, pos_y+17, pos_z+24, block_id)
mc.setBlock(pos_x+12, pos_y+17, pos_z+24, block_id)
mc.setBlock(pos_x+44, pos_y+17, pos_z+24, block_id)
mc.setBlock(pos_x+46, pos_y+17, pos_z+24, block_id)
mc.setBlock(pos_x+15, pos_y+61, pos_z+20, block_id)
mc.setBlock(pos_x+42, pos_y+60, pos_z+20, block_id)
mc.setBlock(pos_x+10, pos_y+18, pos_z+24, block_id)
mc.setBlock(pos_x+11, pos_y+18, pos_z+24, block_id)
mc.setBlock(pos_x+44, pos_y+18, pos_z+24, block_id)
mc.setBlock(pos_x+46, pos_y+18, pos_z+24, block_id)
mc.setBlock(pos_x+9, pos_y+19, pos_z+24, block_id)
mc.setBlock(pos_x+11, pos_y+19, pos_z+24, block_id)
mc.setBlock(pos_x+45, pos_y+19, pos_z+24, block_id)
mc.setBlock(pos_x+47, pos_y+19, pos_z+24, block_id)
mc.setBlock(pos_x+7, pos_y+20, pos_z+24, block_id)
mc.setBlock(pos_x+8, pos_y+20, pos_z+24, block_id)
mc.setBlock(pos_x+11, pos_y+20, pos_z+24, block_id)
mc.setBlock(pos_x+45, pos_y+20, pos_z+24, block_id)
mc.setBlock(pos_x+48, pos_y+20, pos_z+24, block_id)
mc.setBlock(pos_x+49, pos_y+20, pos_z+24, block_id)
mc.setBlock(pos_x+7, pos_y+21, pos_z+24, block_id)
mc.setBlock(pos_x+12, pos_y+21, pos_z+24, block_id)
mc.setBlock(pos_x+44, pos_y+21, pos_z+24, block_id)
mc.setBlock(pos_x+49, pos_y+21, pos_z+24, block_id)
mc.setBlock(pos_x+7, pos_y+22, pos_z+24, block_id)
mc.setBlock(pos_x+12, pos_y+22, pos_z+24, block_id)
mc.setBlock(pos_x+44, pos_y+22, pos_z+24, block_id)
mc.setBlock(pos_x+49, pos_y+22, pos_z+24, block_id)
mc.setBlock(pos_x+6, pos_y+23, pos_z+24, block_id)
mc.setBlock(pos_x+12, pos_y+23, pos_z+24, block_id)
mc.setBlock(pos_x+44, pos_y+23, pos_z+24, block_id)
mc.setBlock(pos_x+50, pos_y+23, pos_z+24, block_id)
mc.setBlock(pos_x+6, pos_y+24, pos_z+24, block_id)
mc.setBlock(pos_x+14, pos_y+60, pos_z+20, block_id)
mc.setBlock(pos_x+42, pos_y+59, pos_z+20, block_id)
mc.setBlock(pos_x+12, pos_y+24, pos_z+24, block_id)
mc.setBlock(pos_x+43, pos_y+24, pos_z+24, block_id)
mc.setBlock(pos_x+50, pos_y+24, pos_z+24, block_id)
mc.setBlock(pos_x+5, pos_y+25, pos_z+24, block_id)
mc.setBlock(pos_x+12, pos_y+25, pos_z+24, block_id)
mc.setBlock(pos_x+43, pos_y+25, pos_z+24, block_id)
mc.setBlock(pos_x+14, pos_y+59, pos_z+20, block_id)
mc.setBlock(pos_x+43, pos_y+58, pos_z+20, block_id)
mc.setBlock(pos_x+50, pos_y+25, pos_z+24, block_id)
mc.setBlock(pos_x+6, pos_y+26, pos_z+24, block_id)
mc.setBlock(pos_x+12, pos_y+26, pos_z+24, block_id)
mc.setBlock(pos_x+44, pos_y+26, pos_z+24, block_id)
mc.setBlock(pos_x+50, pos_y+26, pos_z+24, block_id)
mc.setBlock(pos_x+6, pos_y+27, pos_z+24, block_id)
mc.setBlock(pos_x+13, pos_y+58, pos_z+20, block_id)
mc.setBlock(pos_x+43, pos_y+57, pos_z+20, block_id)
mc.setBlock(pos_x+12, pos_y+27, pos_z+24, block_id)
mc.setBlock(pos_x+44, pos_y+27, pos_z+24, block_id)
mc.setBlock(pos_x+50, pos_y+27, pos_z+24, block_id)
mc.setBlock(pos_x+6, pos_y+28, pos_z+24, block_id)
mc.setBlock(pos_x+13, pos_y+57, pos_z+20, block_id)
mc.setBlock(pos_x+43, pos_y+56, pos_z+20, block_id)
mc.setBlock(pos_x+12, pos_y+28, pos_z+24, block_id)
mc.setBlock(pos_x+44, pos_y+28, pos_z+24, block_id)
mc.setBlock(pos_x+49, pos_y+28, pos_z+24, block_id)
mc.setBlock(pos_x+7, pos_y+29, pos_z+24, block_id)
mc.setBlock(pos_x+13, pos_y+56, pos_z+20, block_id)
mc.setBlock(pos_x+46, pos_y+55, pos_z+20, block_id)
mc.setBlock(pos_x+45, pos_y+55, pos_z+20, block_id)
mc.setBlock(pos_x+44, pos_y+55, pos_z+20, block_id)
mc.setBlock(pos_x+8, pos_y+29, pos_z+24, block_id)
mc.setBlock(pos_x+9, pos_y+29, pos_z+24, block_id)
mc.setBlock(pos_x+11, pos_y+29, pos_z+24, block_id)
mc.setBlock(pos_x+44, pos_y+29, pos_z+24, block_id)
mc.setBlock(pos_x+47, pos_y+29, pos_z+24, block_id)
mc.setBlock(pos_x+12, pos_y+55, pos_z+20, block_id)
mc.setBlock(pos_x+11, pos_y+55, pos_z+20, block_id)
mc.setBlock(pos_x+10, pos_y+55, pos_z+20, block_id)
mc.setBlock(pos_x+48, pos_y+54, pos_z+20, block_id)
mc.setBlock(pos_x+47, pos_y+54, pos_z+20, block_id)
mc.setBlock(pos_x+46, pos_y+54, pos_z+20, block_id)
mc.setBlock(pos_x+45, pos_y+54, pos_z+20, block_id)
mc.setBlock(pos_x+44, pos_y+54, pos_z+20, block_id)
mc.setBlock(pos_x+48, pos_y+29, pos_z+24, block_id)
mc.setBlock(pos_x+10, pos_y+30, pos_z+24, block_id)
mc.setBlock(pos_x+11, pos_y+30, pos_z+24, block_id)
mc.setBlock(pos_x+20, pos_y+30, pos_z+24, block_id)
mc.setBlock(pos_x+12, pos_y+54, pos_z+20, block_id)
mc.setBlock(pos_x+11, pos_y+54, pos_z+20, block_id)
mc.setBlock(pos_x+10, pos_y+54, pos_z+20, block_id)
mc.setBlock(pos_x+9, pos_y+54, pos_z+20, block_id)
mc.setBlock(pos_x+8, pos_y+54, pos_z+20, block_id)
mc.setBlock(pos_x+7, pos_y+54, pos_z+20, block_id)
mc.setBlock(pos_x+49, pos_y+53, pos_z+20, block_id)
mc.setBlock(pos_x+48, pos_y+53, pos_z+20, block_id)
mc.setBlock(pos_x+21, pos_y+30, pos_z+24, block_id)
mc.setBlock(pos_x+22, pos_y+30, pos_z+24, block_id)
mc.setBlock(pos_x+23, pos_y+30, pos_z+24, block_id)
mc.setBlock(pos_x+24, pos_y+30, pos_z+24, block_id)
mc.setBlock(pos_x+25, pos_y+30, pos_z+24, block_id)
mc.setBlock(pos_x+26, pos_y+30, pos_z+24, block_id)
mc.setBlock(pos_x+27, pos_y+30, pos_z+24, block_id)
mc.setBlock(pos_x+28, pos_y+30, pos_z+24, block_id)
mc.setBlock(pos_x+29, pos_y+30, pos_z+24, block_id)
mc.setBlock(pos_x+30, pos_y+30, pos_z+24, block_id)
mc.setBlock(pos_x+31, pos_y+30, pos_z+24, block_id)
mc.setBlock(pos_x+32, pos_y+30, pos_z+24, block_id)
mc.setBlock(pos_x+33, pos_y+30, pos_z+24, block_id)
mc.setBlock(pos_x+34, pos_y+30, pos_z+24, block_id)
mc.setBlock(pos_x+35, pos_y+30, pos_z+24, block_id)
mc.setBlock(pos_x+7, pos_y+53, pos_z+20, block_id)
mc.setBlock(pos_x+50, pos_y+52, pos_z+20, block_id)
mc.setBlock(pos_x+36, pos_y+30, pos_z+24, block_id)
mc.setBlock(pos_x+45, pos_y+30, pos_z+24, block_id)
mc.setBlock(pos_x+46, pos_y+30, pos_z+24, block_id)
mc.setBlock(pos_x+19, pos_y+31, pos_z+24, block_id)
mc.setBlock(pos_x+37, pos_y+31, pos_z+24, block_id)
mc.setBlock(pos_x+18, pos_y+32, pos_z+24, block_id)
mc.setBlock(pos_x+38, pos_y+32, pos_z+24, block_id)
mc.setBlock(pos_x+17, pos_y+33, pos_z+24, block_id)
mc.setBlock(pos_x+39, pos_y+33, pos_z+24, block_id)
mc.setBlock(pos_x+17, pos_y+34, pos_z+24, block_id)
mc.setBlock(pos_x+39, pos_y+34, pos_z+24, block_id)
mc.setBlock(pos_x+16, pos_y+35, pos_z+24, block_id)
mc.setBlock(pos_x+6, pos_y+52, pos_z+20, block_id)
mc.setBlock(pos_x+50, pos_y+51, pos_z+20, block_id)
mc.setBlock(pos_x+40, pos_y+35, pos_z+24, block_id)
mc.setBlock(pos_x+16, pos_y+36, pos_z+24, block_id)
mc.setBlock(pos_x+40, pos_y+36, pos_z+24, block_id)
mc.setBlock(pos_x+15, pos_y+37, pos_z+24, block_id)
mc.setBlock(pos_x+41, pos_y+37, pos_z+24, block_id)
mc.setBlock(pos_x+15, pos_y+38, pos_z+24, block_id)
mc.setBlock(pos_x+41, pos_y+38, pos_z+24, block_id)
mc.setBlock(pos_x+14, pos_y+39, pos_z+24, block_id)
mc.setBlock(pos_x+42, pos_y+39, pos_z+24, block_id)
mc.setBlock(pos_x+6, pos_y+51, pos_z+20, block_id)
mc.setBlock(pos_x+50, pos_y+50, pos_z+20, block_id)
mc.setBlock(pos_x+14, pos_y+40, pos_z+24, block_id)
mc.setBlock(pos_x+42, pos_y+40, pos_z+24, block_id)
mc.setBlock(pos_x+14, pos_y+41, pos_z+24, block_id)
mc.setBlock(pos_x+42, pos_y+41, pos_z+24, block_id)
mc.setBlock(pos_x+14, pos_y+42, pos_z+24, block_id)
mc.setBlock(pos_x+42, pos_y+42, pos_z+24, block_id)
mc.setBlock(pos_x+12, pos_y+43, pos_z+24, block_id)
mc.setBlock(pos_x+13, pos_y+43, pos_z+24, block_id)
mc.setBlock(pos_x+43, pos_y+43, pos_z+24, block_id)
mc.setBlock(pos_x+6, pos_y+50, pos_z+20, block_id)
mc.setBlock(pos_x+51, pos_y+49, pos_z+20, block_id)
mc.setBlock(pos_x+50, pos_y+49, pos_z+20, block_id)
mc.setBlock(pos_x+44, pos_y+43, pos_z+24, block_id)
mc.setBlock(pos_x+8, pos_y+44, pos_z+24, block_id)
mc.setBlock(pos_x+9, pos_y+44, pos_z+24, block_id)
mc.setBlock(pos_x+10, pos_y+44, pos_z+24, block_id)
mc.setBlock(pos_x+11, pos_y+44, pos_z+24, block_id)
mc.setBlock(pos_x+45, pos_y+44, pos_z+24, block_id)
mc.setBlock(pos_x+46, pos_y+44, pos_z+24, block_id)
mc.setBlock(pos_x+47, pos_y+44, pos_z+24, block_id)
mc.setBlock(pos_x+48, pos_y+44, pos_z+24, block_id)
mc.setBlock(pos_x+8, pos_y+45, pos_z+24, block_id)
mc.setBlock(pos_x+48, pos_y+45, pos_z+24, block_id)
mc.setBlock(pos_x+5, pos_y+49, pos_z+20, block_id)
mc.setBlock(pos_x+50, pos_y+48, pos_z+20, block_id)
mc.setBlock(pos_x+9, pos_y+46, pos_z+24, block_id)
mc.setBlock(pos_x+10, pos_y+46, pos_z+24, block_id)
mc.setBlock(pos_x+45, pos_y+46, pos_z+24, block_id)
mc.setBlock(pos_x+46, pos_y+46, pos_z+24, block_id)
mc.setBlock(pos_x+47, pos_y+46, pos_z+24, block_id)
mc.setBlock(pos_x+11, pos_y+47, pos_z+24, block_id)
mc.setBlock(pos_x+44, pos_y+47, pos_z+24, block_id)
mc.setBlock(pos_x+12, pos_y+48, pos_z+24, block_id)
mc.setBlock(pos_x+44, pos_y+48, pos_z+24, block_id)
mc.setBlock(pos_x+12, pos_y+49, pos_z+24, block_id)
mc.setBlock(pos_x+5, pos_y+48, pos_z+20, block_id)
mc.setBlock(pos_x+50, pos_y+47, pos_z+20, block_id)
mc.setBlock(pos_x+44, pos_y+49, pos_z+24, block_id)
mc.setBlock(pos_x+13, pos_y+50, pos_z+24, block_id)
mc.setBlock(pos_x+43, pos_y+50, pos_z+24, block_id)
mc.setBlock(pos_x+13, pos_y+51, pos_z+24, block_id)
mc.setBlock(pos_x+43, pos_y+51, pos_z+24, block_id)
mc.setBlock(pos_x+13, pos_y+52, pos_z+24, block_id)
mc.setBlock(pos_x+43, pos_y+52, pos_z+24, block_id)
mc.setBlock(pos_x+13, pos_y+53, pos_z+24, block_id)
mc.setBlock(pos_x+6, pos_y+47, pos_z+20, block_id)
mc.setBlock(pos_x+5, pos_y+47, pos_z+20, block_id)
mc.setBlock(pos_x+50, pos_y+46, pos_z+20, block_id)
mc.setBlock(pos_x+43, pos_y+53, pos_z+24, block_id)
mc.setBlock(pos_x+13, pos_y+54, pos_z+24, block_id)
mc.setBlock(pos_x+43, pos_y+54, pos_z+24, block_id)
mc.setBlock(pos_x+14, pos_y+55, pos_z+24, block_id)
mc.setBlock(pos_x+42, pos_y+55, pos_z+24, block_id)
mc.setBlock(pos_x+15, pos_y+56, pos_z+24, block_id)
mc.setBlock(pos_x+41, pos_y+56, pos_z+24, block_id)
mc.setBlock(pos_x+15, pos_y+57, pos_z+24, block_id)
mc.setBlock(pos_x+41, pos_y+57, pos_z+24, block_id)
mc.setBlock(pos_x+16, pos_y+58, pos_z+24, block_id)
mc.setBlock(pos_x+22, pos_y+58, pos_z+24, block_id)
mc.setBlock(pos_x+23, pos_y+58, pos_z+24, block_id)
mc.setBlock(pos_x+6, pos_y+46, pos_z+20, block_id)
mc.setBlock(pos_x+50, pos_y+45, pos_z+20, block_id)
mc.setBlock(pos_x+49, pos_y+45, pos_z+20, block_id)
mc.setBlock(pos_x+24, pos_y+58, pos_z+24, block_id)
mc.setBlock(pos_x+25, pos_y+58, pos_z+24, block_id)
mc.setBlock(pos_x+26, pos_y+58, pos_z+24, block_id)
mc.setBlock(pos_x+27, pos_y+58, pos_z+24, block_id)
mc.setBlock(pos_x+28, pos_y+58, pos_z+24, block_id)
mc.setBlock(pos_x+29, pos_y+58, pos_z+24, block_id)
mc.setBlock(pos_x+30, pos_y+58, pos_z+24, block_id)
mc.setBlock(pos_x+31, pos_y+58, pos_z+24, block_id)
mc.setBlock(pos_x+32, pos_y+58, pos_z+24, block_id)
mc.setBlock(pos_x+33, pos_y+58, pos_z+24, block_id)
mc.setBlock(pos_x+34, pos_y+58, pos_z+24, block_id)
mc.setBlock(pos_x+40, pos_y+58, pos_z+24, block_id)
mc.setBlock(pos_x+7, pos_y+45, pos_z+20, block_id)
mc.setBlock(pos_x+6, pos_y+45, pos_z+20, block_id)
mc.setBlock(pos_x+49, pos_y+44, pos_z+20, block_id)
mc.setBlock(pos_x+48, pos_y+44, pos_z+20, block_id)
mc.setBlock(pos_x+17, pos_y+59, pos_z+24, block_id)
mc.setBlock(pos_x+18, pos_y+59, pos_z+24, block_id)
mc.setBlock(pos_x+19, pos_y+59, pos_z+24, block_id)
mc.setBlock(pos_x+20, pos_y+59, pos_z+24, block_id)
mc.setBlock(pos_x+43, pos_y+44, pos_z+20, block_id)
mc.setBlock(pos_x+21, pos_y+59, pos_z+24, block_id)
mc.setBlock(pos_x+22, pos_y+59, pos_z+24, block_id)
mc.setBlock(pos_x+34, pos_y+59, pos_z+24, block_id)
mc.setBlock(pos_x+35, pos_y+59, pos_z+24, block_id)
mc.setBlock(pos_x+36, pos_y+59, pos_z+24, block_id)
mc.setBlock(pos_x+37, pos_y+59, pos_z+24, block_id)
mc.setBlock(pos_x+38, pos_y+59, pos_z+24, block_id)
mc.setBlock(pos_x+39, pos_y+59, pos_z+24, block_id)
mc.setBlock(pos_x+11, pos_y+15, pos_z+25, block_id)
mc.setBlock(pos_x+8, pos_y+44, pos_z+20, block_id)
mc.setBlock(pos_x+7, pos_y+44, pos_z+20, block_id)
mc.setBlock(pos_x+48, pos_y+43, pos_z+20, block_id)
mc.setBlock(pos_x+47, pos_y+43, pos_z+20, block_id)
mc.setBlock(pos_x+46, pos_y+43, pos_z+20, block_id)
mc.setBlock(pos_x+45, pos_y+43, pos_z+20, block_id)
mc.setBlock(pos_x+44, pos_y+43, pos_z+20, block_id)
mc.setBlock(pos_x+43, pos_y+43, pos_z+20, block_id)
mc.setBlock(pos_x+12, pos_y+15, pos_z+25, block_id)
mc.setBlock(pos_x+44, pos_y+15, pos_z+25, block_id)
mc.setBlock(pos_x+13, pos_y+43, pos_z+20, block_id)
mc.setBlock(pos_x+12, pos_y+43, pos_z+20, block_id)
mc.setBlock(pos_x+11, pos_y+43, pos_z+20, block_id)
mc.setBlock(pos_x+10, pos_y+43, pos_z+20, block_id)
mc.setBlock(pos_x+9, pos_y+43, pos_z+20, block_id)
mc.setBlock(pos_x+8, pos_y+43, pos_z+20, block_id)
mc.setBlock(pos_x+42, pos_y+42, pos_z+20, block_id)
mc.setBlock(pos_x+14, pos_y+42, pos_z+20, block_id)
mc.setBlock(pos_x+42, pos_y+41, pos_z+20, block_id)
mc.setBlock(pos_x+45, pos_y+15, pos_z+25, block_id)
mc.setBlock(pos_x+10, pos_y+16, pos_z+25, block_id)
mc.setBlock(pos_x+14, pos_y+41, pos_z+20, block_id)
mc.setBlock(pos_x+41, pos_y+40, pos_z+20, block_id)
mc.setBlock(pos_x+12, pos_y+16, pos_z+25, block_id)
mc.setBlock(pos_x+14, pos_y+40, pos_z+20, block_id)
mc.setBlock(pos_x+41, pos_y+39, pos_z+20, block_id)
mc.setBlock(pos_x+44, pos_y+16, pos_z+25, block_id)
mc.setBlock(pos_x+15, pos_y+39, pos_z+20, block_id)
mc.setBlock(pos_x+41, pos_y+38, pos_z+20, block_id)
mc.setBlock(pos_x+46, pos_y+16, pos_z+25, block_id)
mc.setBlock(pos_x+9, pos_y+17, pos_z+25, block_id)
mc.setBlock(pos_x+15, pos_y+38, pos_z+20, block_id)
mc.setBlock(pos_x+40, pos_y+37, pos_z+20, block_id)
mc.setBlock(pos_x+12, pos_y+17, pos_z+25, block_id)
mc.setBlock(pos_x+44, pos_y+17, pos_z+25, block_id)
mc.setBlock(pos_x+16, pos_y+37, pos_z+20, block_id)
mc.setBlock(pos_x+40, pos_y+36, pos_z+20, block_id)
mc.setBlock(pos_x+46, pos_y+17, pos_z+25, block_id)
mc.setBlock(pos_x+9, pos_y+18, pos_z+25, block_id)
mc.setBlock(pos_x+16, pos_y+36, pos_z+20, block_id)
mc.setBlock(pos_x+39, pos_y+35, pos_z+20, block_id)
mc.setBlock(pos_x+12, pos_y+18, pos_z+25, block_id)
mc.setBlock(pos_x+44, pos_y+18, pos_z+25, block_id)
mc.setBlock(pos_x+17, pos_y+35, pos_z+20, block_id)
mc.setBlock(pos_x+38, pos_y+34, pos_z+20, block_id)
mc.setBlock(pos_x+46, pos_y+18, pos_z+25, block_id)
mc.setBlock(pos_x+9, pos_y+19, pos_z+25, block_id)
mc.setBlock(pos_x+18, pos_y+34, pos_z+20, block_id)
mc.setBlock(pos_x+37, pos_y+33, pos_z+20, block_id)
mc.setBlock(pos_x+12, pos_y+19, pos_z+25, block_id)
mc.setBlock(pos_x+44, pos_y+19, pos_z+25, block_id)
mc.setBlock(pos_x+47, pos_y+19, pos_z+25, block_id)
mc.setBlock(pos_x+8, pos_y+20, pos_z+25, block_id)
mc.setBlock(pos_x+12, pos_y+20, pos_z+25, block_id)
mc.setBlock(pos_x+44, pos_y+20, pos_z+25, block_id)
mc.setBlock(pos_x+48, pos_y+20, pos_z+25, block_id)
mc.setBlock(pos_x+7, pos_y+21, pos_z+25, block_id)
mc.setBlock(pos_x+12, pos_y+21, pos_z+25, block_id)
mc.setBlock(pos_x+43, pos_y+21, pos_z+25, block_id)
mc.setBlock(pos_x+49, pos_y+21, pos_z+25, block_id)
mc.setBlock(pos_x+6, pos_y+22, pos_z+25, block_id)
mc.setBlock(pos_x+13, pos_y+22, pos_z+25, block_id)
mc.setBlock(pos_x+43, pos_y+22, pos_z+25, block_id)
mc.setBlock(pos_x+49, pos_y+22, pos_z+25, block_id)
mc.setBlock(pos_x+6, pos_y+23, pos_z+25, block_id)
mc.setBlock(pos_x+13, pos_y+23, pos_z+25, block_id)
mc.setBlock(pos_x+19, pos_y+33, pos_z+20, block_id)
mc.setBlock(pos_x+36, pos_y+32, pos_z+20, block_id)
mc.setBlock(pos_x+35, pos_y+32, pos_z+20, block_id)
mc.setBlock(pos_x+34, pos_y+32, pos_z+20, block_id)
mc.setBlock(pos_x+33, pos_y+32, pos_z+20, block_id)
mc.setBlock(pos_x+32, pos_y+32, pos_z+20, block_id)
mc.setBlock(pos_x+31, pos_y+32, pos_z+20, block_id)
mc.setBlock(pos_x+30, pos_y+32, pos_z+20, block_id)
mc.setBlock(pos_x+29, pos_y+32, pos_z+20, block_id)
mc.setBlock(pos_x+28, pos_y+32, pos_z+20, block_id)
mc.setBlock(pos_x+27, pos_y+32, pos_z+20, block_id)
mc.setBlock(pos_x+26, pos_y+32, pos_z+20, block_id)
mc.setBlock(pos_x+25, pos_y+32, pos_z+20, block_id)
mc.setBlock(pos_x+24, pos_y+32, pos_z+20, block_id)
mc.setBlock(pos_x+23, pos_y+32, pos_z+20, block_id)
mc.setBlock(pos_x+22, pos_y+32, pos_z+20, block_id)
mc.setBlock(pos_x+21, pos_y+32, pos_z+20, block_id)
mc.setBlock(pos_x+20, pos_y+32, pos_z+20, block_id)
mc.setBlock(pos_x+48, pos_y+27, pos_z+20, block_id)
mc.setBlock(pos_x+47, pos_y+27, pos_z+20, block_id)
mc.setBlock(pos_x+9, pos_y+27, pos_z+20, block_id)
mc.setBlock(pos_x+8, pos_y+27, pos_z+20, block_id)
mc.setBlock(pos_x+48, pos_y+26, pos_z+20, block_id)
mc.setBlock(pos_x+47, pos_y+26, pos_z+20, block_id)
mc.setBlock(pos_x+9, pos_y+26, pos_z+20, block_id)
mc.setBlock(pos_x+43, pos_y+23, pos_z+25, block_id)
mc.setBlock(pos_x+7, pos_y+26, pos_z+20, block_id)
mc.setBlock(pos_x+49, pos_y+25, pos_z+20, block_id)
mc.setBlock(pos_x+50, pos_y+23, pos_z+25, block_id)
mc.setBlock(pos_x+47, pos_y+25, pos_z+20, block_id)
mc.setBlock(pos_x+9, pos_y+25, pos_z+20, block_id)
mc.setBlock(pos_x+6, pos_y+24, pos_z+25, block_id)
mc.setBlock(pos_x+7, pos_y+25, pos_z+20, block_id)
mc.setBlock(pos_x+49, pos_y+24, pos_z+20, block_id)
mc.setBlock(pos_x+13, pos_y+24, pos_z+25, block_id)
mc.setBlock(pos_x+47, pos_y+24, pos_z+20, block_id)
mc.setBlock(pos_x+9, pos_y+24, pos_z+20, block_id)
mc.setBlock(pos_x+43, pos_y+24, pos_z+25, block_id)
mc.setBlock(pos_x+7, pos_y+24, pos_z+20, block_id)
mc.setBlock(pos_x+49, pos_y+23, pos_z+20, block_id)
mc.setBlock(pos_x+50, pos_y+24, pos_z+25, block_id)
mc.setBlock(pos_x+5, pos_y+25, pos_z+25, block_id)
mc.setBlock(pos_x+46, pos_y+23, pos_z+20, block_id)
mc.setBlock(pos_x+10, pos_y+23, pos_z+20, block_id)
mc.setBlock(pos_x+13, pos_y+25, pos_z+25, block_id)
mc.setBlock(pos_x+43, pos_y+25, pos_z+25, block_id)
mc.setBlock(pos_x+7, pos_y+23, pos_z+20, block_id)
mc.setBlock(pos_x+48, pos_y+22, pos_z+20, block_id)
mc.setBlock(pos_x+47, pos_y+22, pos_z+20, block_id)
mc.setBlock(pos_x+46, pos_y+22, pos_z+20, block_id)
mc.setBlock(pos_x+10, pos_y+22, pos_z+20, block_id)
mc.setBlock(pos_x+9, pos_y+22, pos_z+20, block_id)
mc.setBlock(pos_x+8, pos_y+22, pos_z+20, block_id)
mc.setBlock(pos_x+46, pos_y+21, pos_z+20, block_id)
mc.setBlock(pos_x+10, pos_y+21, pos_z+20, block_id)
mc.setBlock(pos_x+46, pos_y+20, pos_z+20, block_id)
mc.setBlock(pos_x+10, pos_y+20, pos_z+20, block_id)
mc.setBlock(pos_x+9, pos_y+20, pos_z+20, block_id)
mc.setBlock(pos_x+46, pos_y+19, pos_z+20, block_id)
mc.setBlock(pos_x+45, pos_y+19, pos_z+20, block_id)
mc.setBlock(pos_x+11, pos_y+19, pos_z+20, block_id)
mc.setBlock(pos_x+50, pos_y+25, pos_z+25, block_id)
mc.setBlock(pos_x+9, pos_y+19, pos_z+20, block_id)
mc.setBlock(pos_x+46, pos_y+18, pos_z+20, block_id)
mc.setBlock(pos_x+45, pos_y+18, pos_z+20, block_id)
mc.setBlock(pos_x+11, pos_y+18, pos_z+20, block_id)
mc.setBlock(pos_x+5, pos_y+26, pos_z+25, block_id)
mc.setBlock(pos_x+9, pos_y+18, pos_z+20, block_id)
mc.setBlock(pos_x+46, pos_y+17, pos_z+20, block_id)
mc.setBlock(pos_x+45, pos_y+17, pos_z+20, block_id)
mc.setBlock(pos_x+11, pos_y+17, pos_z+20, block_id)
mc.setBlock(pos_x+10, pos_y+17, pos_z+20, block_id)
mc.setBlock(pos_x+38, pos_y+67, pos_z+19, block_id)
mc.setBlock(pos_x+37, pos_y+67, pos_z+19, block_id)
mc.setBlock(pos_x+36, pos_y+67, pos_z+19, block_id)
mc.setBlock(pos_x+20, pos_y+67, pos_z+19, block_id)
mc.setBlock(pos_x+19, pos_y+67, pos_z+19, block_id)
mc.setBlock(pos_x+18, pos_y+67, pos_z+19, block_id)
mc.setBlock(pos_x+38, pos_y+66, pos_z+19, block_id)
mc.setBlock(pos_x+18, pos_y+66, pos_z+19, block_id)
mc.setBlock(pos_x+39, pos_y+65, pos_z+19, block_id)
mc.setBlock(pos_x+13, pos_y+26, pos_z+25, block_id)
mc.setBlock(pos_x+37, pos_y+65, pos_z+19, block_id)
mc.setBlock(pos_x+36, pos_y+65, pos_z+19, block_id)
mc.setBlock(pos_x+35, pos_y+65, pos_z+19, block_id)
mc.setBlock(pos_x+34, pos_y+65, pos_z+19, block_id)
mc.setBlock(pos_x+33, pos_y+65, pos_z+19, block_id)
mc.setBlock(pos_x+32, pos_y+65, pos_z+19, block_id)
mc.setBlock(pos_x+31, pos_y+65, pos_z+19, block_id)
mc.setBlock(pos_x+30, pos_y+65, pos_z+19, block_id)
mc.setBlock(pos_x+29, pos_y+65, pos_z+19, block_id)
mc.setBlock(pos_x+28, pos_y+65, pos_z+19, block_id)
mc.setBlock(pos_x+27, pos_y+65, pos_z+19, block_id)
mc.setBlock(pos_x+26, pos_y+65, pos_z+19, block_id)
mc.setBlock(pos_x+25, pos_y+65, pos_z+19, block_id)
mc.setBlock(pos_x+24, pos_y+65, pos_z+19, block_id)
mc.setBlock(pos_x+23, pos_y+65, pos_z+19, block_id)
mc.setBlock(pos_x+22, pos_y+65, pos_z+19, block_id)
mc.setBlock(pos_x+21, pos_y+65, pos_z+19, block_id)
mc.setBlock(pos_x+20, pos_y+65, pos_z+19, block_id)
mc.setBlock(pos_x+19, pos_y+65, pos_z+19, block_id)
mc.setBlock(pos_x+43, pos_y+26, pos_z+25, block_id)
mc.setBlock(pos_x+17, pos_y+65, pos_z+19, block_id)
mc.setBlock(pos_x+40, pos_y+64, pos_z+19, block_id)
mc.setBlock(pos_x+50, pos_y+26, pos_z+25, block_id)
mc.setBlock(pos_x+6, pos_y+27, pos_z+25, block_id)
mc.setBlock(pos_x+13, pos_y+27, pos_z+25, block_id)
mc.setBlock(pos_x+43, pos_y+27, pos_z+25, block_id)
mc.setBlock(pos_x+50, pos_y+27, pos_z+25, block_id)
mc.setBlock(pos_x+6, pos_y+28, pos_z+25, block_id)
mc.setBlock(pos_x+13, pos_y+28, pos_z+25, block_id)
mc.setBlock(pos_x+43, pos_y+28, pos_z+25, block_id)
mc.setBlock(pos_x+50, pos_y+28, pos_z+25, block_id)
mc.setBlock(pos_x+7, pos_y+29, pos_z+25, block_id)
mc.setBlock(pos_x+29, pos_y+64, pos_z+19, block_id)
mc.setBlock(pos_x+28, pos_y+64, pos_z+19, block_id)
mc.setBlock(pos_x+27, pos_y+64, pos_z+19, block_id)
mc.setBlock(pos_x+12, pos_y+29, pos_z+25, block_id)
mc.setBlock(pos_x+21, pos_y+29, pos_z+25, block_id)
mc.setBlock(pos_x+22, pos_y+29, pos_z+25, block_id)
mc.setBlock(pos_x+34, pos_y+29, pos_z+25, block_id)
mc.setBlock(pos_x+35, pos_y+29, pos_z+25, block_id)
mc.setBlock(pos_x+44, pos_y+29, pos_z+25, block_id)
mc.setBlock(pos_x+49, pos_y+29, pos_z+25, block_id)
mc.setBlock(pos_x+8, pos_y+30, pos_z+25, block_id)
mc.setBlock(pos_x+9, pos_y+30, pos_z+25, block_id)
mc.setBlock(pos_x+10, pos_y+30, pos_z+25, block_id)
mc.setBlock(pos_x+16, pos_y+64, pos_z+19, block_id)
mc.setBlock(pos_x+41, pos_y+63, pos_z+19, block_id)
mc.setBlock(pos_x+12, pos_y+30, pos_z+25, block_id)
mc.setBlock(pos_x+20, pos_y+30, pos_z+25, block_id)
mc.setBlock(pos_x+23, pos_y+30, pos_z+25, block_id)
mc.setBlock(pos_x+24, pos_y+30, pos_z+25, block_id)
mc.setBlock(pos_x+25, pos_y+30, pos_z+25, block_id)
mc.setBlock(pos_x+26, pos_y+30, pos_z+25, block_id)
mc.setBlock(pos_x+27, pos_y+30, pos_z+25, block_id)
mc.setBlock(pos_x+28, pos_y+30, pos_z+25, block_id)
mc.setBlock(pos_x+29, pos_y+30, pos_z+25, block_id)
mc.setBlock(pos_x+30, pos_y+30, pos_z+25, block_id)
mc.setBlock(pos_x+31, pos_y+30, pos_z+25, block_id)
mc.setBlock(pos_x+32, pos_y+30, pos_z+25, block_id)
mc.setBlock(pos_x+33, pos_y+30, pos_z+25, block_id)
mc.setBlock(pos_x+36, pos_y+30, pos_z+25, block_id)
mc.setBlock(pos_x+44, pos_y+30, pos_z+25, block_id)
mc.setBlock(pos_x+46, pos_y+30, pos_z+25, block_id)
mc.setBlock(pos_x+47, pos_y+30, pos_z+25, block_id)
mc.setBlock(pos_x+48, pos_y+30, pos_z+25, block_id)
mc.setBlock(pos_x+11, pos_y+31, pos_z+25, block_id)
mc.setBlock(pos_x+19, pos_y+31, pos_z+25, block_id)
mc.setBlock(pos_x+37, pos_y+31, pos_z+25, block_id)
mc.setBlock(pos_x+45, pos_y+31, pos_z+25, block_id)
mc.setBlock(pos_x+18, pos_y+32, pos_z+25, block_id)
mc.setBlock(pos_x+38, pos_y+32, pos_z+25, block_id)
mc.setBlock(pos_x+17, pos_y+33, pos_z+25, block_id)
mc.setBlock(pos_x+15, pos_y+63, pos_z+19, block_id)
mc.setBlock(pos_x+41, pos_y+62, pos_z+19, block_id)
mc.setBlock(pos_x+39, pos_y+33, pos_z+25, block_id)
mc.setBlock(pos_x+16, pos_y+34, pos_z+25, block_id)
mc.setBlock(pos_x+39, pos_y+34, pos_z+25, block_id)
mc.setBlock(pos_x+16, pos_y+35, pos_z+25, block_id)
mc.setBlock(pos_x+40, pos_y+35, pos_z+25, block_id)
mc.setBlock(pos_x+15, pos_y+36, pos_z+25, block_id)
mc.setBlock(pos_x+41, pos_y+36, pos_z+25, block_id)
mc.setBlock(pos_x+15, pos_y+37, pos_z+25, block_id)
mc.setBlock(pos_x+41, pos_y+37, pos_z+25, block_id)
mc.setBlock(pos_x+15, pos_y+38, pos_z+25, block_id)
mc.setBlock(pos_x+41, pos_y+38, pos_z+25, block_id)
mc.setBlock(pos_x+14, pos_y+39, pos_z+25, block_id)
mc.setBlock(pos_x+42, pos_y+39, pos_z+25, block_id)
mc.setBlock(pos_x+15, pos_y+62, pos_z+19, block_id)
mc.setBlock(pos_x+41, pos_y+61, pos_z+19, block_id)
mc.setBlock(pos_x+14, pos_y+40, pos_z+25, block_id)
mc.setBlock(pos_x+42, pos_y+40, pos_z+25, block_id)
mc.setBlock(pos_x+14, pos_y+41, pos_z+25, block_id)
mc.setBlock(pos_x+42, pos_y+41, pos_z+25, block_id)
mc.setBlock(pos_x+14, pos_y+42, pos_z+25, block_id)
mc.setBlock(pos_x+42, pos_y+42, pos_z+25, block_id)
mc.setBlock(pos_x+12, pos_y+43, pos_z+25, block_id)
mc.setBlock(pos_x+13, pos_y+43, pos_z+25, block_id)
mc.setBlock(pos_x+43, pos_y+43, pos_z+25, block_id)
mc.setBlock(pos_x+9, pos_y+44, pos_z+25, block_id)
mc.setBlock(pos_x+10, pos_y+44, pos_z+25, block_id)
mc.setBlock(pos_x+11, pos_y+44, pos_z+25, block_id)
mc.setBlock(pos_x+44, pos_y+44, pos_z+25, block_id)
mc.setBlock(pos_x+45, pos_y+44, pos_z+25, block_id)
mc.setBlock(pos_x+46, pos_y+44, pos_z+25, block_id)
mc.setBlock(pos_x+47, pos_y+44, pos_z+25, block_id)
mc.setBlock(pos_x+9, pos_y+45, pos_z+25, block_id)
mc.setBlock(pos_x+10, pos_y+45, pos_z+25, block_id)
mc.setBlock(pos_x+11, pos_y+45, pos_z+25, block_id)
mc.setBlock(pos_x+45, pos_y+45, pos_z+25, block_id)
mc.setBlock(pos_x+46, pos_y+45, pos_z+25, block_id)
mc.setBlock(pos_x+47, pos_y+45, pos_z+25, block_id)
mc.setBlock(pos_x+10, pos_y+46, pos_z+25, block_id)
mc.setBlock(pos_x+11, pos_y+46, pos_z+25, block_id)
mc.setBlock(pos_x+45, pos_y+46, pos_z+25, block_id)
mc.setBlock(pos_x+15, pos_y+61, pos_z+19, block_id)
mc.setBlock(pos_x+43, pos_y+60, pos_z+19, block_id)
mc.setBlock(pos_x+42, pos_y+60, pos_z+19, block_id)
mc.setBlock(pos_x+46, pos_y+46, pos_z+25, block_id)
mc.setBlock(pos_x+12, pos_y+47, pos_z+25, block_id)
mc.setBlock(pos_x+44, pos_y+47, pos_z+25, block_id)
mc.setBlock(pos_x+12, pos_y+48, pos_z+25, block_id)
mc.setBlock(pos_x+44, pos_y+48, pos_z+25, block_id)
mc.setBlock(pos_x+12, pos_y+49, pos_z+25, block_id)
mc.setBlock(pos_x+43, pos_y+49, pos_z+25, block_id)
mc.setBlock(pos_x+13, pos_y+50, pos_z+25, block_id)
mc.setBlock(pos_x+43, pos_y+50, pos_z+25, block_id)
mc.setBlock(pos_x+13, pos_y+51, pos_z+25, block_id)
mc.setBlock(pos_x+43, pos_y+51, pos_z+25, block_id)
mc.setBlock(pos_x+13, pos_y+52, pos_z+25, block_id)
mc.setBlock(pos_x+14, pos_y+60, pos_z+19, block_id)
mc.setBlock(pos_x+13, pos_y+60, pos_z+19, block_id)
mc.setBlock(pos_x+43, pos_y+59, pos_z+19, block_id)
mc.setBlock(pos_x+43, pos_y+52, pos_z+25, block_id)
mc.setBlock(pos_x+13, pos_y+53, pos_z+25, block_id)
mc.setBlock(pos_x+43, pos_y+53, pos_z+25, block_id)
mc.setBlock(pos_x+14, pos_y+54, pos_z+25, block_id)
mc.setBlock(pos_x+42, pos_y+54, pos_z+25, block_id)
mc.setBlock(pos_x+14, pos_y+55, pos_z+25, block_id)
mc.setBlock(pos_x+13, pos_y+59, pos_z+19, block_id)
mc.setBlock(pos_x+43, pos_y+58, pos_z+19, block_id)
mc.setBlock(pos_x+42, pos_y+55, pos_z+25, block_id)
mc.setBlock(pos_x+15, pos_y+56, pos_z+25, block_id)
mc.setBlock(pos_x+41, pos_y+56, pos_z+25, block_id)
mc.setBlock(pos_x+16, pos_y+57, pos_z+25, block_id)
mc.setBlock(pos_x+13, pos_y+58, pos_z+19, block_id)
mc.setBlock(pos_x+43, pos_y+57, pos_z+19, block_id)
mc.setBlock(pos_x+22, pos_y+57, pos_z+25, block_id)
mc.setBlock(pos_x+23, pos_y+57, pos_z+25, block_id)
mc.setBlock(pos_x+24, pos_y+57, pos_z+25, block_id)
mc.setBlock(pos_x+25, pos_y+57, pos_z+25, block_id)
mc.setBlock(pos_x+13, pos_y+57, pos_z+19, block_id)
mc.setBlock(pos_x+43, pos_y+56, pos_z+19, block_id)
mc.setBlock(pos_x+26, pos_y+57, pos_z+25, block_id)
mc.setBlock(pos_x+27, pos_y+57, pos_z+25, block_id)
mc.setBlock(pos_x+13, pos_y+56, pos_z+19, block_id)
mc.setBlock(pos_x+48, pos_y+55, pos_z+19, block_id)
mc.setBlock(pos_x+47, pos_y+55, pos_z+19, block_id)
mc.setBlock(pos_x+46, pos_y+55, pos_z+19, block_id)
mc.setBlock(pos_x+45, pos_y+55, pos_z+19, block_id)
mc.setBlock(pos_x+44, pos_y+55, pos_z+19, block_id)
mc.setBlock(pos_x+28, pos_y+57, pos_z+25, block_id)
mc.setBlock(pos_x+29, pos_y+57, pos_z+25, block_id)
mc.setBlock(pos_x+30, pos_y+57, pos_z+25, block_id)
mc.setBlock(pos_x+31, pos_y+57, pos_z+25, block_id)
mc.setBlock(pos_x+12, pos_y+55, pos_z+19, block_id)
mc.setBlock(pos_x+11, pos_y+55, pos_z+19, block_id)
mc.setBlock(pos_x+10, pos_y+55, pos_z+19, block_id)
mc.setBlock(pos_x+9, pos_y+55, pos_z+19, block_id)
mc.setBlock(pos_x+8, pos_y+55, pos_z+19, block_id)
mc.setBlock(pos_x+49, pos_y+54, pos_z+19, block_id)
mc.setBlock(pos_x+32, pos_y+57, pos_z+25, block_id)
mc.setBlock(pos_x+33, pos_y+57, pos_z+25, block_id)
mc.setBlock(pos_x+34, pos_y+57, pos_z+25, block_id)
mc.setBlock(pos_x+40, pos_y+57, pos_z+25, block_id)
mc.setBlock(pos_x+16, pos_y+58, pos_z+25, block_id)
mc.setBlock(pos_x+17, pos_y+58, pos_z+25, block_id)
mc.setBlock(pos_x+18, pos_y+58, pos_z+25, block_id)
mc.setBlock(pos_x+19, pos_y+58, pos_z+25, block_id)
mc.setBlock(pos_x+20, pos_y+58, pos_z+25, block_id)
mc.setBlock(pos_x+21, pos_y+58, pos_z+25, block_id)
mc.setBlock(pos_x+35, pos_y+58, pos_z+25, block_id)
mc.setBlock(pos_x+36, pos_y+58, pos_z+25, block_id)
mc.setBlock(pos_x+37, pos_y+58, pos_z+25, block_id)
mc.setBlock(pos_x+7, pos_y+54, pos_z+19, block_id)
mc.setBlock(pos_x+6, pos_y+54, pos_z+19, block_id)
mc.setBlock(pos_x+50, pos_y+53, pos_z+19, block_id)
mc.setBlock(pos_x+38, pos_y+58, pos_z+25, block_id)
mc.setBlock(pos_x+39, pos_y+58, pos_z+25, block_id)
mc.setBlock(pos_x+12, pos_y+15, pos_z+26, block_id)
mc.setBlock(pos_x+44, pos_y+15, pos_z+26, block_id)
mc.setBlock(pos_x+10, pos_y+16, pos_z+26, block_id)
mc.setBlock(pos_x+11, pos_y+16, pos_z+26, block_id)
mc.setBlock(pos_x+12, pos_y+16, pos_z+26, block_id)
mc.setBlock(pos_x+44, pos_y+16, pos_z+26, block_id)
mc.setBlock(pos_x+45, pos_y+16, pos_z+26, block_id)
mc.setBlock(pos_x+46, pos_y+16, pos_z+26, block_id)
mc.setBlock(pos_x+6, pos_y+53, pos_z+19, block_id)
mc.setBlock(pos_x+51, pos_y+52, pos_z+19, block_id)
mc.setBlock(pos_x+9, pos_y+17, pos_z+26, block_id)
mc.setBlock(pos_x+12, pos_y+17, pos_z+26, block_id)
mc.setBlock(pos_x+44, pos_y+17, pos_z+26, block_id)
mc.setBlock(pos_x+47, pos_y+17, pos_z+26, block_id)
mc.setBlock(pos_x+9, pos_y+18, pos_z+26, block_id)
mc.setBlock(pos_x+12, pos_y+18, pos_z+26, block_id)
mc.setBlock(pos_x+44, pos_y+18, pos_z+26, block_id)
mc.setBlock(pos_x+47, pos_y+18, pos_z+26, block_id)
mc.setBlock(pos_x+8, pos_y+19, pos_z+26, block_id)
mc.setBlock(pos_x+13, pos_y+19, pos_z+26, block_id)
mc.setBlock(pos_x+43, pos_y+19, pos_z+26, block_id)
mc.setBlock(pos_x+5, pos_y+52, pos_z+19, block_id)
mc.setBlock(pos_x+51, pos_y+51, pos_z+19, block_id)
mc.setBlock(pos_x+48, pos_y+19, pos_z+26, block_id)
mc.setBlock(pos_x+7, pos_y+20, pos_z+26, block_id)
mc.setBlock(pos_x+13, pos_y+20, pos_z+26, block_id)
mc.setBlock(pos_x+43, pos_y+20, pos_z+26, block_id)
mc.setBlock(pos_x+49, pos_y+20, pos_z+26, block_id)
mc.setBlock(pos_x+7, pos_y+21, pos_z+26, block_id)
mc.setBlock(pos_x+13, pos_y+21, pos_z+26, block_id)
mc.setBlock(pos_x+43, pos_y+21, pos_z+26, block_id)
mc.setBlock(pos_x+5, pos_y+51, pos_z+19, block_id)
mc.setBlock(pos_x+51, pos_y+50, pos_z+19, block_id)
mc.setBlock(pos_x+49, pos_y+21, pos_z+26, block_id)
mc.setBlock(pos_x+6, pos_y+22, pos_z+26, block_id)
mc.setBlock(pos_x+13, pos_y+22, pos_z+26, block_id)
mc.setBlock(pos_x+42, pos_y+22, pos_z+26, block_id)
mc.setBlock(pos_x+50, pos_y+22, pos_z+26, block_id)
mc.setBlock(pos_x+6, pos_y+23, pos_z+26, block_id)
mc.setBlock(pos_x+14, pos_y+23, pos_z+26, block_id)
mc.setBlock(pos_x+42, pos_y+23, pos_z+26, block_id)
mc.setBlock(pos_x+5, pos_y+50, pos_z+19, block_id)
mc.setBlock(pos_x+51, pos_y+49, pos_z+19, block_id)
mc.setBlock(pos_x+50, pos_y+23, pos_z+26, block_id)
mc.setBlock(pos_x+6, pos_y+24, pos_z+26, block_id)
mc.setBlock(pos_x+14, pos_y+24, pos_z+26, block_id)
mc.setBlock(pos_x+42, pos_y+24, pos_z+26, block_id)
mc.setBlock(pos_x+50, pos_y+24, pos_z+26, block_id)
mc.setBlock(pos_x+5, pos_y+25, pos_z+26, block_id)
mc.setBlock(pos_x+5, pos_y+49, pos_z+19, block_id)
mc.setBlock(pos_x+51, pos_y+48, pos_z+19, block_id)
mc.setBlock(pos_x+14, pos_y+25, pos_z+26, block_id)
mc.setBlock(pos_x+42, pos_y+25, pos_z+26, block_id)
mc.setBlock(pos_x+50, pos_y+25, pos_z+26, block_id)
mc.setBlock(pos_x+5, pos_y+26, pos_z+26, block_id)
mc.setBlock(pos_x+14, pos_y+26, pos_z+26, block_id)
mc.setBlock(pos_x+42, pos_y+26, pos_z+26, block_id)
mc.setBlock(pos_x+50, pos_y+26, pos_z+26, block_id)
mc.setBlock(pos_x+5, pos_y+48, pos_z+19, block_id)
mc.setBlock(pos_x+51, pos_y+47, pos_z+19, block_id)
mc.setBlock(pos_x+6, pos_y+27, pos_z+26, block_id)
mc.setBlock(pos_x+13, pos_y+27, pos_z+26, block_id)
mc.setBlock(pos_x+43, pos_y+27, pos_z+26, block_id)
mc.setBlock(pos_x+50, pos_y+27, pos_z+26, block_id)
mc.setBlock(pos_x+6, pos_y+28, pos_z+26, block_id)
mc.setBlock(pos_x+13, pos_y+28, pos_z+26, block_id)
mc.setBlock(pos_x+43, pos_y+28, pos_z+26, block_id)
mc.setBlock(pos_x+50, pos_y+28, pos_z+26, block_id)
mc.setBlock(pos_x+5, pos_y+47, pos_z+19, block_id)
mc.setBlock(pos_x+51, pos_y+46, pos_z+19, block_id)
mc.setBlock(pos_x+7, pos_y+29, pos_z+26, block_id)
mc.setBlock(pos_x+13, pos_y+29, pos_z+26, block_id)
mc.setBlock(pos_x+21, pos_y+29, pos_z+26, block_id)
mc.setBlock(pos_x+22, pos_y+29, pos_z+26, block_id)
mc.setBlock(pos_x+23, pos_y+29, pos_z+26, block_id)
mc.setBlock(pos_x+24, pos_y+29, pos_z+26, block_id)
mc.setBlock(pos_x+25, pos_y+29, pos_z+26, block_id)
mc.setBlock(pos_x+26, pos_y+29, pos_z+26, block_id)
mc.setBlock(pos_x+29, pos_y+29, pos_z+26, block_id)
mc.setBlock(pos_x+30, pos_y+29, pos_z+26, block_id)
mc.setBlock(pos_x+5, pos_y+46, pos_z+19, block_id)
mc.setBlock(pos_x+51, pos_y+45, pos_z+19, block_id)
mc.setBlock(pos_x+31, pos_y+29, pos_z+26, block_id)
mc.setBlock(pos_x+32, pos_y+29, pos_z+26, block_id)
mc.setBlock(pos_x+33, pos_y+29, pos_z+26, block_id)
mc.setBlock(pos_x+34, pos_y+29, pos_z+26, block_id)
mc.setBlock(pos_x+35, pos_y+29, pos_z+26, block_id)
mc.setBlock(pos_x+43, pos_y+29, pos_z+26, block_id)
mc.setBlock(pos_x+49, pos_y+29, pos_z+26, block_id)
mc.setBlock(pos_x+8, pos_y+30, pos_z+26, block_id)
mc.setBlock(pos_x+12, pos_y+30, pos_z+26, block_id)
mc.setBlock(pos_x+20, pos_y+30, pos_z+26, block_id)
mc.setBlock(pos_x+27, pos_y+30, pos_z+26, block_id)
mc.setBlock(pos_x+5, pos_y+45, pos_z+19, block_id)
mc.setBlock(pos_x+50, pos_y+44, pos_z+19, block_id)
mc.setBlock(pos_x+28, pos_y+30, pos_z+26, block_id)
mc.setBlock(pos_x+36, pos_y+30, pos_z+26, block_id)
mc.setBlock(pos_x+44, pos_y+30, pos_z+26, block_id)
mc.setBlock(pos_x+48, pos_y+30, pos_z+26, block_id)
mc.setBlock(pos_x+9, pos_y+31, pos_z+26, block_id)
mc.setBlock(pos_x+10, pos_y+31, pos_z+26, block_id)
mc.setBlock(pos_x+11, pos_y+31, pos_z+26, block_id)
mc.setBlock(pos_x+12, pos_y+31, pos_z+26, block_id)
mc.setBlock(pos_x+19, pos_y+31, pos_z+26, block_id)
mc.setBlock(pos_x+37, pos_y+31, pos_z+26, block_id)
mc.setBlock(pos_x+6, pos_y+44, pos_z+19, block_id)
mc.setBlock(pos_x+5, pos_y+44, pos_z+19, block_id)
mc.setBlock(pos_x+50, pos_y+43, pos_z+19, block_id)
mc.setBlock(pos_x+49, pos_y+43, pos_z+19, block_id)
mc.setBlock(pos_x+44, pos_y+31, pos_z+26, block_id)
mc.setBlock(pos_x+45, pos_y+31, pos_z+26, block_id)
mc.setBlock(pos_x+46, pos_y+31, pos_z+26, block_id)
mc.setBlock(pos_x+47, pos_y+31, pos_z+26, block_id)
mc.setBlock(pos_x+18, pos_y+32, pos_z+26, block_id)
mc.setBlock(pos_x+38, pos_y+32, pos_z+26, block_id)
mc.setBlock(pos_x+17, pos_y+33, pos_z+26, block_id)
mc.setBlock(pos_x+39, pos_y+33, pos_z+26, block_id)
mc.setBlock(pos_x+16, pos_y+34, pos_z+26, block_id)
mc.setBlock(pos_x+40, pos_y+34, pos_z+26, block_id)
mc.setBlock(pos_x+16, pos_y+35, pos_z+26, block_id)
mc.setBlock(pos_x+40, pos_y+35, pos_z+26, block_id)
mc.setBlock(pos_x+15, pos_y+36, pos_z+26, block_id)
mc.setBlock(pos_x+41, pos_y+36, pos_z+26, block_id)
mc.setBlock(pos_x+15, pos_y+37, pos_z+26, block_id)
mc.setBlock(pos_x+41, pos_y+37, pos_z+26, block_id)
mc.setBlock(pos_x+7, pos_y+43, pos_z+19, block_id)
mc.setBlock(pos_x+6, pos_y+43, pos_z+19, block_id)
mc.setBlock(pos_x+49, pos_y+42, pos_z+19, block_id)
mc.setBlock(pos_x+48, pos_y+42, pos_z+19, block_id)
mc.setBlock(pos_x+47, pos_y+42, pos_z+19, block_id)
mc.setBlock(pos_x+46, pos_y+42, pos_z+19, block_id)
mc.setBlock(pos_x+45, pos_y+42, pos_z+19, block_id)
mc.setBlock(pos_x+44, pos_y+42, pos_z+19, block_id)
mc.setBlock(pos_x+43, pos_y+42, pos_z+19, block_id)
mc.setBlock(pos_x+15, pos_y+38, pos_z+26, block_id)
mc.setBlock(pos_x+41, pos_y+38, pos_z+26, block_id)
mc.setBlock(pos_x+14, pos_y+39, pos_z+26, block_id)
mc.setBlock(pos_x+13, pos_y+42, pos_z+19, block_id)
mc.setBlock(pos_x+12, pos_y+42, pos_z+19, block_id)
mc.setBlock(pos_x+11, pos_y+42, pos_z+19, block_id)
mc.setBlock(pos_x+10, pos_y+42, pos_z+19, block_id)
mc.setBlock(pos_x+9, pos_y+42, pos_z+19, block_id)
mc.setBlock(pos_x+8, pos_y+42, pos_z+19, block_id)
mc.setBlock(pos_x+7, pos_y+42, pos_z+19, block_id)
mc.setBlock(pos_x+47, pos_y+41, pos_z+19, block_id)
mc.setBlock(pos_x+46, pos_y+41, pos_z+19, block_id)
mc.setBlock(pos_x+45, pos_y+41, pos_z+19, block_id)
mc.setBlock(pos_x+42, pos_y+41, pos_z+19, block_id)
mc.setBlock(pos_x+42, pos_y+39, pos_z+26, block_id)
mc.setBlock(pos_x+14, pos_y+40, pos_z+26, block_id)
mc.setBlock(pos_x+14, pos_y+41, pos_z+19, block_id)
mc.setBlock(pos_x+11, pos_y+41, pos_z+19, block_id)
mc.setBlock(pos_x+10, pos_y+41, pos_z+19, block_id)
mc.setBlock(pos_x+9, pos_y+41, pos_z+19, block_id)
mc.setBlock(pos_x+8, pos_y+41, pos_z+19, block_id)
mc.setBlock(pos_x+41, pos_y+40, pos_z+19, block_id)
mc.setBlock(pos_x+15, pos_y+40, pos_z+19, block_id)
mc.setBlock(pos_x+41, pos_y+39, pos_z+19, block_id)
mc.setBlock(pos_x+42, pos_y+40, pos_z+26, block_id)
mc.setBlock(pos_x+14, pos_y+41, pos_z+26, block_id)
mc.setBlock(pos_x+15, pos_y+39, pos_z+19, block_id)
mc.setBlock(pos_x+40, pos_y+38, pos_z+19, block_id)
mc.setBlock(pos_x+42, pos_y+41, pos_z+26, block_id)
mc.setBlock(pos_x+15, pos_y+38, pos_z+19, block_id)
mc.setBlock(pos_x+40, pos_y+37, pos_z+19, block_id)
mc.setBlock(pos_x+14, pos_y+42, pos_z+26, block_id)
mc.setBlock(pos_x+42, pos_y+42, pos_z+26, block_id)
mc.setBlock(pos_x+16, pos_y+37, pos_z+19, block_id)
mc.setBlock(pos_x+39, pos_y+36, pos_z+19, block_id)
mc.setBlock(pos_x+14, pos_y+43, pos_z+26, block_id)
mc.setBlock(pos_x+42, pos_y+43, pos_z+26, block_id)
mc.setBlock(pos_x+17, pos_y+36, pos_z+19, block_id)
mc.setBlock(pos_x+38, pos_y+35, pos_z+19, block_id)
mc.setBlock(pos_x+12, pos_y+44, pos_z+26, block_id)
mc.setBlock(pos_x+13, pos_y+44, pos_z+26, block_id)
mc.setBlock(pos_x+18, pos_y+35, pos_z+19, block_id)
mc.setBlock(pos_x+38, pos_y+34, pos_z+19, block_id)
mc.setBlock(pos_x+43, pos_y+44, pos_z+26, block_id)
mc.setBlock(pos_x+12, pos_y+45, pos_z+26, block_id)
mc.setBlock(pos_x+44, pos_y+45, pos_z+26, block_id)
mc.setBlock(pos_x+12, pos_y+46, pos_z+26, block_id)
mc.setBlock(pos_x+44, pos_y+46, pos_z+26, block_id)
mc.setBlock(pos_x+12, pos_y+47, pos_z+26, block_id)
mc.setBlock(pos_x+44, pos_y+47, pos_z+26, block_id)
mc.setBlock(pos_x+13, pos_y+48, pos_z+26, block_id)
mc.setBlock(pos_x+43, pos_y+48, pos_z+26, block_id)
mc.setBlock(pos_x+13, pos_y+49, pos_z+26, block_id)
mc.setBlock(pos_x+43, pos_y+49, pos_z+26, block_id)
mc.setBlock(pos_x+13, pos_y+50, pos_z+26, block_id)
mc.setBlock(pos_x+43, pos_y+50, pos_z+26, block_id)
mc.setBlock(pos_x+13, pos_y+51, pos_z+26, block_id)
mc.setBlock(pos_x+43, pos_y+51, pos_z+26, block_id)
mc.setBlock(pos_x+13, pos_y+52, pos_z+26, block_id)
mc.setBlock(pos_x+43, pos_y+52, pos_z+26, block_id)
mc.setBlock(pos_x+18, pos_y+34, pos_z+19, block_id)
mc.setBlock(pos_x+37, pos_y+33, pos_z+19, block_id)
mc.setBlock(pos_x+36, pos_y+33, pos_z+19, block_id)
mc.setBlock(pos_x+35, pos_y+33, pos_z+19, block_id)
mc.setBlock(pos_x+34, pos_y+33, pos_z+19, block_id)
mc.setBlock(pos_x+33, pos_y+33, pos_z+19, block_id)
mc.setBlock(pos_x+32, pos_y+33, pos_z+19, block_id)
mc.setBlock(pos_x+31, pos_y+33, pos_z+19, block_id)
mc.setBlock(pos_x+30, pos_y+33, pos_z+19, block_id)
mc.setBlock(pos_x+29, pos_y+33, pos_z+19, block_id)
mc.setBlock(pos_x+28, pos_y+33, pos_z+19, block_id)
mc.setBlock(pos_x+27, pos_y+33, pos_z+19, block_id)
mc.setBlock(pos_x+26, pos_y+33, pos_z+19, block_id)
mc.setBlock(pos_x+25, pos_y+33, pos_z+19, block_id)
mc.setBlock(pos_x+24, pos_y+33, pos_z+19, block_id)
mc.setBlock(pos_x+23, pos_y+33, pos_z+19, block_id)
mc.setBlock(pos_x+22, pos_y+33, pos_z+19, block_id)
mc.setBlock(pos_x+21, pos_y+33, pos_z+19, block_id)
mc.setBlock(pos_x+20, pos_y+33, pos_z+19, block_id)
mc.setBlock(pos_x+19, pos_y+33, pos_z+19, block_id)
mc.setBlock(pos_x+48, pos_y+26, pos_z+19, block_id)
mc.setBlock(pos_x+47, pos_y+26, pos_z+19, block_id)
mc.setBlock(pos_x+9, pos_y+26, pos_z+19, block_id)
mc.setBlock(pos_x+8, pos_y+26, pos_z+19, block_id)
mc.setBlock(pos_x+48, pos_y+25, pos_z+19, block_id)
mc.setBlock(pos_x+47, pos_y+25, pos_z+19, block_id)
mc.setBlock(pos_x+9, pos_y+25, pos_z+19, block_id)
mc.setBlock(pos_x+8, pos_y+25, pos_z+19, block_id)
mc.setBlock(pos_x+48, pos_y+24, pos_z+19, block_id)
mc.setBlock(pos_x+47, pos_y+24, pos_z+19, block_id)
mc.setBlock(pos_x+9, pos_y+24, pos_z+19, block_id)
mc.setBlock(pos_x+8, pos_y+24, pos_z+19, block_id)
mc.setBlock(pos_x+48, pos_y+23, pos_z+19, block_id)
mc.setBlock(pos_x+47, pos_y+23, pos_z+19, block_id)
mc.setBlock(pos_x+9, pos_y+23, pos_z+19, block_id)
mc.setBlock(pos_x+8, pos_y+23, pos_z+19, block_id)
mc.setBlock(pos_x+48, pos_y+22, pos_z+19, block_id)
mc.setBlock(pos_x+14, pos_y+53, pos_z+26, block_id)
mc.setBlock(pos_x+46, pos_y+22, pos_z+19, block_id)
mc.setBlock(pos_x+10, pos_y+22, pos_z+19, block_id)
mc.setBlock(pos_x+42, pos_y+53, pos_z+26, block_id)
mc.setBlock(pos_x+8, pos_y+22, pos_z+19, block_id)
mc.setBlock(pos_x+47, pos_y+21, pos_z+19, block_id)
mc.setBlock(pos_x+46, pos_y+21, pos_z+19, block_id)
mc.setBlock(pos_x+10, pos_y+21, pos_z+19, block_id)
mc.setBlock(pos_x+9, pos_y+21, pos_z+19, block_id)
mc.setBlock(pos_x+46, pos_y+19, pos_z+19, block_id)
mc.setBlock(pos_x+45, pos_y+19, pos_z+19, block_id)
mc.setBlock(pos_x+11, pos_y+19, pos_z+19, block_id)
mc.setBlock(pos_x+10, pos_y+19, pos_z+19, block_id)
mc.setBlock(pos_x+46, pos_y+18, pos_z+19, block_id)
mc.setBlock(pos_x+45, pos_y+18, pos_z+19, block_id)
mc.setBlock(pos_x+11, pos_y+18, pos_z+19, block_id)
mc.setBlock(pos_x+10, pos_y+18, pos_z+19, block_id)
mc.setBlock(pos_x+46, pos_y+17, pos_z+19, block_id)
mc.setBlock(pos_x+45, pos_y+17, pos_z+19, block_id)
mc.setBlock(pos_x+44, pos_y+17, pos_z+19, block_id)
mc.setBlock(pos_x+11, pos_y+17, pos_z+19, block_id)
mc.setBlock(pos_x+10, pos_y+17, pos_z+19, block_id)
mc.setBlock(pos_x+35, pos_y+99, pos_z+18, block_id)
mc.setBlock(pos_x+34, pos_y+99, pos_z+18, block_id)
mc.setBlock(pos_x+31, pos_y+99, pos_z+18, block_id)
mc.setBlock(pos_x+30, pos_y+99, pos_z+18, block_id)
mc.setBlock(pos_x+29, pos_y+99, pos_z+18, block_id)
mc.setBlock(pos_x+27, pos_y+99, pos_z+18, block_id)
mc.setBlock(pos_x+26, pos_y+99, pos_z+18, block_id)
mc.setBlock(pos_x+25, pos_y+99, pos_z+18, block_id)
mc.setBlock(pos_x+22, pos_y+99, pos_z+18, block_id)
mc.setBlock(pos_x+21, pos_y+99, pos_z+18, block_id)
mc.setBlock(pos_x+37, pos_y+70, pos_z+18, block_id)
mc.setBlock(pos_x+19, pos_y+70, pos_z+18, block_id)
mc.setBlock(pos_x+18, pos_y+70, pos_z+18, block_id)
mc.setBlock(pos_x+38, pos_y+69, pos_z+18, block_id)
mc.setBlock(pos_x+37, pos_y+69, pos_z+18, block_id)
mc.setBlock(pos_x+36, pos_y+69, pos_z+18, block_id)
mc.setBlock(pos_x+35, pos_y+69, pos_z+18, block_id)
mc.setBlock(pos_x+34, pos_y+69, pos_z+18, block_id)
mc.setBlock(pos_x+22, pos_y+69, pos_z+18, block_id)
mc.setBlock(pos_x+21, pos_y+69, pos_z+18, block_id)
mc.setBlock(pos_x+20, pos_y+69, pos_z+18, block_id)
mc.setBlock(pos_x+19, pos_y+69, pos_z+18, block_id)
mc.setBlock(pos_x+18, pos_y+69, pos_z+18, block_id)
mc.setBlock(pos_x+39, pos_y+68, pos_z+18, block_id)
mc.setBlock(pos_x+38, pos_y+68, pos_z+18, block_id)
mc.setBlock(pos_x+37, pos_y+68, pos_z+18, block_id)
mc.setBlock(pos_x+36, pos_y+68, pos_z+18, block_id)
mc.setBlock(pos_x+35, pos_y+68, pos_z+18, block_id)
mc.setBlock(pos_x+34, pos_y+68, pos_z+18, block_id)
mc.setBlock(pos_x+33, pos_y+68, pos_z+18, block_id)
mc.setBlock(pos_x+32, pos_y+68, pos_z+18, block_id)
mc.setBlock(pos_x+31, pos_y+68, pos_z+18, block_id)
mc.setBlock(pos_x+30, pos_y+68, pos_z+18, block_id)
mc.setBlock(pos_x+25, pos_y+68, pos_z+18, block_id)
mc.setBlock(pos_x+24, pos_y+68, pos_z+18, block_id)
mc.setBlock(pos_x+23, pos_y+68, pos_z+18, block_id)
mc.setBlock(pos_x+22, pos_y+68, pos_z+18, block_id)
mc.setBlock(pos_x+21, pos_y+68, pos_z+18, block_id)
mc.setBlock(pos_x+20, pos_y+68, pos_z+18, block_id)
mc.setBlock(pos_x+19, pos_y+68, pos_z+18, block_id)
mc.setBlock(pos_x+18, pos_y+68, pos_z+18, block_id)
mc.setBlock(pos_x+17, pos_y+68, pos_z+18, block_id)
mc.setBlock(pos_x+39, pos_y+67, pos_z+18, block_id)
mc.setBlock(pos_x+14, pos_y+54, pos_z+26, block_id)
mc.setBlock(pos_x+42, pos_y+54, pos_z+26, block_id)
mc.setBlock(pos_x+14, pos_y+55, pos_z+26, block_id)
mc.setBlock(pos_x+35, pos_y+67, pos_z+18, block_id)
mc.setBlock(pos_x+34, pos_y+67, pos_z+18, block_id)
mc.setBlock(pos_x+33, pos_y+67, pos_z+18, block_id)
mc.setBlock(pos_x+32, pos_y+67, pos_z+18, block_id)
mc.setBlock(pos_x+31, pos_y+67, pos_z+18, block_id)
mc.setBlock(pos_x+30, pos_y+67, pos_z+18, block_id)
mc.setBlock(pos_x+29, pos_y+67, pos_z+18, block_id)
mc.setBlock(pos_x+28, pos_y+67, pos_z+18, block_id)
mc.setBlock(pos_x+27, pos_y+67, pos_z+18, block_id)
mc.setBlock(pos_x+26, pos_y+67, pos_z+18, block_id)
mc.setBlock(pos_x+25, pos_y+67, pos_z+18, block_id)
mc.setBlock(pos_x+24, pos_y+67, pos_z+18, block_id)
mc.setBlock(pos_x+23, pos_y+67, pos_z+18, block_id)
mc.setBlock(pos_x+22, pos_y+67, pos_z+18, block_id)
mc.setBlock(pos_x+21, pos_y+67, pos_z+18, block_id)
mc.setBlock(pos_x+41, pos_y+55, pos_z+26, block_id)
mc.setBlock(pos_x+15, pos_y+56, pos_z+26, block_id)
mc.setBlock(pos_x+26, pos_y+56, pos_z+26, block_id)
mc.setBlock(pos_x+17, pos_y+67, pos_z+18, block_id)
mc.setBlock(pos_x+39, pos_y+66, pos_z+18, block_id)
mc.setBlock(pos_x+27, pos_y+56, pos_z+26, block_id)
mc.setBlock(pos_x+37, pos_y+66, pos_z+18, block_id)
mc.setBlock(pos_x+36, pos_y+66, pos_z+18, block_id)
mc.setBlock(pos_x+35, pos_y+66, pos_z+18, block_id)
mc.setBlock(pos_x+34, pos_y+66, pos_z+18, block_id)
mc.setBlock(pos_x+33, pos_y+66, pos_z+18, block_id)
mc.setBlock(pos_x+32, pos_y+66, pos_z+18, block_id)
mc.setBlock(pos_x+31, pos_y+66, pos_z+18, block_id)
mc.setBlock(pos_x+30, pos_y+66, pos_z+18, block_id)
mc.setBlock(pos_x+29, pos_y+66, pos_z+18, block_id)
mc.setBlock(pos_x+28, pos_y+66, pos_z+18, block_id)
mc.setBlock(pos_x+27, pos_y+66, pos_z+18, block_id)
mc.setBlock(pos_x+26, pos_y+66, pos_z+18, block_id)
mc.setBlock(pos_x+25, pos_y+66, pos_z+18, block_id)
mc.setBlock(pos_x+24, pos_y+66, pos_z+18, block_id)
mc.setBlock(pos_x+23, pos_y+66, pos_z+18, block_id)
mc.setBlock(pos_x+22, pos_y+66, pos_z+18, block_id)
mc.setBlock(pos_x+21, pos_y+66, pos_z+18, block_id)
mc.setBlock(pos_x+20, pos_y+66, pos_z+18, block_id)
mc.setBlock(pos_x+19, pos_y+66, pos_z+18, block_id)
mc.setBlock(pos_x+28, pos_y+56, pos_z+26, block_id)
mc.setBlock(pos_x+17, pos_y+66, pos_z+18, block_id)
mc.setBlock(pos_x+40, pos_y+65, pos_z+18, block_id)
mc.setBlock(pos_x+29, pos_y+56, pos_z+26, block_id)
mc.setBlock(pos_x+30, pos_y+56, pos_z+26, block_id)
mc.setBlock(pos_x+41, pos_y+56, pos_z+26, block_id)
mc.setBlock(pos_x+16, pos_y+57, pos_z+26, block_id)
mc.setBlock(pos_x+17, pos_y+57, pos_z+26, block_id)
mc.setBlock(pos_x+18, pos_y+57, pos_z+26, block_id)
mc.setBlock(pos_x+19, pos_y+57, pos_z+26, block_id)
mc.setBlock(pos_x+20, pos_y+57, pos_z+26, block_id)
mc.setBlock(pos_x+21, pos_y+57, pos_z+26, block_id)
mc.setBlock(pos_x+22, pos_y+57, pos_z+26, block_id)
mc.setBlock(pos_x+23, pos_y+57, pos_z+26, block_id)
mc.setBlock(pos_x+24, pos_y+57, pos_z+26, block_id)
mc.setBlock(pos_x+25, pos_y+57, pos_z+26, block_id)
mc.setBlock(pos_x+31, pos_y+57, pos_z+26, block_id)
mc.setBlock(pos_x+32, pos_y+57, pos_z+26, block_id)
mc.setBlock(pos_x+33, pos_y+57, pos_z+26, block_id)
mc.setBlock(pos_x+34, pos_y+57, pos_z+26, block_id)
mc.setBlock(pos_x+35, pos_y+57, pos_z+26, block_id)
mc.setBlock(pos_x+36, pos_y+57, pos_z+26, block_id)
mc.setBlock(pos_x+37, pos_y+57, pos_z+26, block_id)
mc.setBlock(pos_x+38, pos_y+57, pos_z+26, block_id)
mc.setBlock(pos_x+39, pos_y+57, pos_z+26, block_id)
mc.setBlock(pos_x+40, pos_y+57, pos_z+26, block_id)
mc.setBlock(pos_x+16, pos_y+65, pos_z+18, block_id)
mc.setBlock(pos_x+41, pos_y+64, pos_z+18, block_id)
mc.setBlock(pos_x+13, pos_y+14, pos_z+27, block_id)
mc.setBlock(pos_x+14, pos_y+14, pos_z+27, block_id)
mc.setBlock(pos_x+42, pos_y+14, pos_z+27, block_id)
mc.setBlock(pos_x+43, pos_y+14, pos_z+27, block_id)
mc.setBlock(pos_x+13, pos_y+15, pos_z+27, block_id)
mc.setBlock(pos_x+14, pos_y+15, pos_z+27, block_id)
mc.setBlock(pos_x+42, pos_y+15, pos_z+27, block_id)
mc.setBlock(pos_x+43, pos_y+15, pos_z+27, block_id)
mc.setBlock(pos_x+11, pos_y+16, pos_z+27, block_id)
mc.setBlock(pos_x+12, pos_y+16, pos_z+27, block_id)
mc.setBlock(pos_x+14, pos_y+16, pos_z+27, block_id)
mc.setBlock(pos_x+42, pos_y+16, pos_z+27, block_id)
mc.setBlock(pos_x+44, pos_y+16, pos_z+27, block_id)
mc.setBlock(pos_x+45, pos_y+16, pos_z+27, block_id)
mc.setBlock(pos_x+9, pos_y+17, pos_z+27, block_id)
mc.setBlock(pos_x+10, pos_y+17, pos_z+27, block_id)
mc.setBlock(pos_x+13, pos_y+17, pos_z+27, block_id)
mc.setBlock(pos_x+43, pos_y+17, pos_z+27, block_id)
mc.setBlock(pos_x+15, pos_y+64, pos_z+18, block_id)
mc.setBlock(pos_x+41, pos_y+63, pos_z+18, block_id)
mc.setBlock(pos_x+46, pos_y+17, pos_z+27, block_id)
mc.setBlock(pos_x+47, pos_y+17, pos_z+27, block_id)
mc.setBlock(pos_x+9, pos_y+18, pos_z+27, block_id)
mc.setBlock(pos_x+13, pos_y+18, pos_z+27, block_id)
mc.setBlock(pos_x+15, pos_y+63, pos_z+18, block_id)
mc.setBlock(pos_x+42, pos_y+62, pos_z+18, block_id)
mc.setBlock(pos_x+43, pos_y+18, pos_z+27, block_id)
mc.setBlock(pos_x+47, pos_y+18, pos_z+27, block_id)
mc.setBlock(pos_x+8, pos_y+19, pos_z+27, block_id)
mc.setBlock(pos_x+13, pos_y+19, pos_z+27, block_id)
mc.setBlock(pos_x+43, pos_y+19, pos_z+27, block_id)
mc.setBlock(pos_x+48, pos_y+19, pos_z+27, block_id)
mc.setBlock(pos_x+7, pos_y+20, pos_z+27, block_id)
mc.setBlock(pos_x+14, pos_y+20, pos_z+27, block_id)
mc.setBlock(pos_x+42, pos_y+20, pos_z+27, block_id)
mc.setBlock(pos_x+49, pos_y+20, pos_z+27, block_id)
mc.setBlock(pos_x+7, pos_y+21, pos_z+27, block_id)
mc.setBlock(pos_x+14, pos_y+21, pos_z+27, block_id)
mc.setBlock(pos_x+42, pos_y+21, pos_z+27, block_id)
mc.setBlock(pos_x+49, pos_y+21, pos_z+27, block_id)
mc.setBlock(pos_x+6, pos_y+22, pos_z+27, block_id)
mc.setBlock(pos_x+14, pos_y+22, pos_z+27, block_id)
mc.setBlock(pos_x+42, pos_y+22, pos_z+27, block_id)
mc.setBlock(pos_x+50, pos_y+22, pos_z+27, block_id)
mc.setBlock(pos_x+6, pos_y+23, pos_z+27, block_id)
mc.setBlock(pos_x+14, pos_y+23, pos_z+27, block_id)
mc.setBlock(pos_x+42, pos_y+23, pos_z+27, block_id)
mc.setBlock(pos_x+50, pos_y+23, pos_z+27, block_id)
mc.setBlock(pos_x+6, pos_y+24, pos_z+27, block_id)
mc.setBlock(pos_x+14, pos_y+24, pos_z+27, block_id)
mc.setBlock(pos_x+42, pos_y+24, pos_z+27, block_id)
mc.setBlock(pos_x+50, pos_y+24, pos_z+27, block_id)
mc.setBlock(pos_x+6, pos_y+25, pos_z+27, block_id)
mc.setBlock(pos_x+14, pos_y+62, pos_z+18, block_id)
mc.setBlock(pos_x+42, pos_y+61, pos_z+18, block_id)
mc.setBlock(pos_x+14, pos_y+25, pos_z+27, block_id)
mc.setBlock(pos_x+42, pos_y+25, pos_z+27, block_id)
mc.setBlock(pos_x+50, pos_y+25, pos_z+27, block_id)
mc.setBlock(pos_x+6, pos_y+26, pos_z+27, block_id)
mc.setBlock(pos_x+14, pos_y+26, pos_z+27, block_id)
mc.setBlock(pos_x+42, pos_y+26, pos_z+27, block_id)
mc.setBlock(pos_x+50, pos_y+26, pos_z+27, block_id)
mc.setBlock(pos_x+6, pos_y+27, pos_z+27, block_id)
mc.setBlock(pos_x+14, pos_y+27, pos_z+27, block_id)
mc.setBlock(pos_x+42, pos_y+27, pos_z+27, block_id)
mc.setBlock(pos_x+50, pos_y+27, pos_z+27, block_id)
mc.setBlock(pos_x+7, pos_y+28, pos_z+27, block_id)
mc.setBlock(pos_x+13, pos_y+28, pos_z+27, block_id)
mc.setBlock(pos_x+43, pos_y+28, pos_z+27, block_id)
mc.setBlock(pos_x+49, pos_y+28, pos_z+27, block_id)
mc.setBlock(pos_x+7, pos_y+29, pos_z+27, block_id)
mc.setBlock(pos_x+13, pos_y+29, pos_z+27, block_id)
mc.setBlock(pos_x+20, pos_y+29, pos_z+27, block_id)
mc.setBlock(pos_x+21, pos_y+29, pos_z+27, block_id)
mc.setBlock(pos_x+22, pos_y+29, pos_z+27, block_id)
mc.setBlock(pos_x+23, pos_y+29, pos_z+27, block_id)
mc.setBlock(pos_x+24, pos_y+29, pos_z+27, block_id)
mc.setBlock(pos_x+25, pos_y+29, pos_z+27, block_id)
mc.setBlock(pos_x+26, pos_y+29, pos_z+27, block_id)
mc.setBlock(pos_x+27, pos_y+29, pos_z+27, block_id)
mc.setBlock(pos_x+28, pos_y+29, pos_z+27, block_id)
mc.setBlock(pos_x+29, pos_y+29, pos_z+27, block_id)
mc.setBlock(pos_x+14, pos_y+61, pos_z+18, block_id)
mc.setBlock(pos_x+13, pos_y+61, pos_z+18, block_id)
mc.setBlock(pos_x+43, pos_y+60, pos_z+18, block_id)
mc.setBlock(pos_x+30, pos_y+29, pos_z+27, block_id)
mc.setBlock(pos_x+31, pos_y+29, pos_z+27, block_id)
mc.setBlock(pos_x+32, pos_y+29, pos_z+27, block_id)
mc.setBlock(pos_x+33, pos_y+29, pos_z+27, block_id)
mc.setBlock(pos_x+13, pos_y+60, pos_z+18, block_id)
mc.setBlock(pos_x+43, pos_y+59, pos_z+18, block_id)
mc.setBlock(pos_x+34, pos_y+29, pos_z+27, block_id)
mc.setBlock(pos_x+35, pos_y+29, pos_z+27, block_id)
mc.setBlock(pos_x+43, pos_y+29, pos_z+27, block_id)
mc.setBlock(pos_x+49, pos_y+29, pos_z+27, block_id)
mc.setBlock(pos_x+13, pos_y+59, pos_z+18, block_id)
mc.setBlock(pos_x+43, pos_y+58, pos_z+18, block_id)
mc.setBlock(pos_x+7, pos_y+30, pos_z+27, block_id)
mc.setBlock(pos_x+13, pos_y+30, pos_z+27, block_id)
mc.setBlock(pos_x+19, pos_y+30, pos_z+27, block_id)
mc.setBlock(pos_x+36, pos_y+30, pos_z+27, block_id)
mc.setBlock(pos_x+13, pos_y+58, pos_z+18, block_id)
mc.setBlock(pos_x+43, pos_y+57, pos_z+18, block_id)
mc.setBlock(pos_x+43, pos_y+30, pos_z+27, block_id)
mc.setBlock(pos_x+49, pos_y+30, pos_z+27, block_id)
mc.setBlock(pos_x+8, pos_y+31, pos_z+27, block_id)
mc.setBlock(pos_x+13, pos_y+57, pos_z+18, block_id)
mc.setBlock(pos_x+48, pos_y+56, pos_z+18, block_id)
mc.setBlock(pos_x+47, pos_y+56, pos_z+18, block_id)
mc.setBlock(pos_x+46, pos_y+56, pos_z+18, block_id)
mc.setBlock(pos_x+45, pos_y+56, pos_z+18, block_id)
mc.setBlock(pos_x+44, pos_y+56, pos_z+18, block_id)
mc.setBlock(pos_x+9, pos_y+31, pos_z+27, block_id)
mc.setBlock(pos_x+10, pos_y+31, pos_z+27, block_id)
mc.setBlock(pos_x+12, pos_y+31, pos_z+27, block_id)
mc.setBlock(pos_x+18, pos_y+31, pos_z+27, block_id)
mc.setBlock(pos_x+12, pos_y+56, pos_z+18, block_id)
mc.setBlock(pos_x+11, pos_y+56, pos_z+18, block_id)
mc.setBlock(pos_x+10, pos_y+56, pos_z+18, block_id)
mc.setBlock(pos_x+9, pos_y+56, pos_z+18, block_id)
mc.setBlock(pos_x+8, pos_y+56, pos_z+18, block_id)
mc.setBlock(pos_x+49, pos_y+55, pos_z+18, block_id)
mc.setBlock(pos_x+37, pos_y+31, pos_z+27, block_id)
mc.setBlock(pos_x+44, pos_y+31, pos_z+27, block_id)
mc.setBlock(pos_x+46, pos_y+31, pos_z+27, block_id)
mc.setBlock(pos_x+47, pos_y+31, pos_z+27, block_id)
mc.setBlock(pos_x+48, pos_y+31, pos_z+27, block_id)
mc.setBlock(pos_x+11, pos_y+32, pos_z+27, block_id)
mc.setBlock(pos_x+18, pos_y+32, pos_z+27, block_id)
mc.setBlock(pos_x+38, pos_y+32, pos_z+27, block_id)
mc.setBlock(pos_x+44, pos_y+32, pos_z+27, block_id)
mc.setBlock(pos_x+45, pos_y+32, pos_z+27, block_id)
mc.setBlock(pos_x+17, pos_y+33, pos_z+27, block_id)
mc.setBlock(pos_x+39, pos_y+33, pos_z+27, block_id)
mc.setBlock(pos_x+16, pos_y+34, pos_z+27, block_id)
mc.setBlock(pos_x+40, pos_y+34, pos_z+27, block_id)
mc.setBlock(pos_x+16, pos_y+35, pos_z+27, block_id)
mc.setBlock(pos_x+40, pos_y+35, pos_z+27, block_id)
mc.setBlock(pos_x+7, pos_y+55, pos_z+18, block_id)
mc.setBlock(pos_x+50, pos_y+54, pos_z+18, block_id)
mc.setBlock(pos_x+15, pos_y+36, pos_z+27, block_id)
mc.setBlock(pos_x+41, pos_y+36, pos_z+27, block_id)
mc.setBlock(pos_x+15, pos_y+37, pos_z+27, block_id)
mc.setBlock(pos_x+41, pos_y+37, pos_z+27, block_id)
mc.setBlock(pos_x+15, pos_y+38, pos_z+27, block_id)
mc.setBlock(pos_x+41, pos_y+38, pos_z+27, block_id)
mc.setBlock(pos_x+14, pos_y+39, pos_z+27, block_id)
mc.setBlock(pos_x+42, pos_y+39, pos_z+27, block_id)
mc.setBlock(pos_x+14, pos_y+40, pos_z+27, block_id)
mc.setBlock(pos_x+42, pos_y+40, pos_z+27, block_id)
mc.setBlock(pos_x+6, pos_y+54, pos_z+18, block_id)
mc.setBlock(pos_x+51, pos_y+53, pos_z+18, block_id)
mc.setBlock(pos_x+14, pos_y+41, pos_z+27, block_id)
mc.setBlock(pos_x+42, pos_y+41, pos_z+27, block_id)
mc.setBlock(pos_x+14, pos_y+42, pos_z+27, block_id)
mc.setBlock(pos_x+42, pos_y+42, pos_z+27, block_id)
mc.setBlock(pos_x+14, pos_y+43, pos_z+27, block_id)
mc.setBlock(pos_x+42, pos_y+43, pos_z+27, block_id)
mc.setBlock(pos_x+13, pos_y+44, pos_z+27, block_id)
mc.setBlock(pos_x+42, pos_y+44, pos_z+27, block_id)
mc.setBlock(pos_x+13, pos_y+45, pos_z+27, block_id)
mc.setBlock(pos_x+5, pos_y+53, pos_z+18, block_id)
mc.setBlock(pos_x+51, pos_y+52, pos_z+18, block_id)
mc.setBlock(pos_x+43, pos_y+45, pos_z+27, block_id)
mc.setBlock(pos_x+12, pos_y+46, pos_z+27, block_id)
mc.setBlock(pos_x+43, pos_y+46, pos_z+27, block_id)
mc.setBlock(pos_x+12, pos_y+47, pos_z+27, block_id)
mc.setBlock(pos_x+43, pos_y+47, pos_z+27, block_id)
mc.setBlock(pos_x+13, pos_y+48, pos_z+27, block_id)
mc.setBlock(pos_x+43, pos_y+48, pos_z+27, block_id)
mc.setBlock(pos_x+13, pos_y+49, pos_z+27, block_id)
mc.setBlock(pos_x+5, pos_y+52, pos_z+18, block_id)
mc.setBlock(pos_x+51, pos_y+51, pos_z+18, block_id)
mc.setBlock(pos_x+43, pos_y+49, pos_z+27, block_id)
mc.setBlock(pos_x+13, pos_y+50, pos_z+27, block_id)
mc.setBlock(pos_x+43, pos_y+50, pos_z+27, block_id)
mc.setBlock(pos_x+13, pos_y+51, pos_z+27, block_id)
mc.setBlock(pos_x+43, pos_y+51, pos_z+27, block_id)
mc.setBlock(pos_x+13, pos_y+52, pos_z+27, block_id)
mc.setBlock(pos_x+5, pos_y+51, pos_z+18, block_id)
mc.setBlock(pos_x+51, pos_y+50, pos_z+18, block_id)
mc.setBlock(pos_x+43, pos_y+52, pos_z+27, block_id)
mc.setBlock(pos_x+14, pos_y+53, pos_z+27, block_id)
mc.setBlock(pos_x+42, pos_y+53, pos_z+27, block_id)
mc.setBlock(pos_x+14, pos_y+54, pos_z+27, block_id)
mc.setBlock(pos_x+42, pos_y+54, pos_z+27, block_id)
mc.setBlock(pos_x+15, pos_y+55, pos_z+27, block_id)
mc.setBlock(pos_x+5, pos_y+50, pos_z+18, block_id)
mc.setBlock(pos_x+51, pos_y+49, pos_z+18, block_id)
mc.setBlock(pos_x+41, pos_y+55, pos_z+27, block_id)
mc.setBlock(pos_x+16, pos_y+56, pos_z+27, block_id)
mc.setBlock(pos_x+19, pos_y+56, pos_z+27, block_id)
mc.setBlock(pos_x+20, pos_y+56, pos_z+27, block_id)
mc.setBlock(pos_x+21, pos_y+56, pos_z+27, block_id)
mc.setBlock(pos_x+22, pos_y+56, pos_z+27, block_id)
mc.setBlock(pos_x+5, pos_y+49, pos_z+18, block_id)
mc.setBlock(pos_x+52, pos_y+48, pos_z+18, block_id)
mc.setBlock(pos_x+23, pos_y+56, pos_z+27, block_id)
mc.setBlock(pos_x+24, pos_y+56, pos_z+27, block_id)
mc.setBlock(pos_x+25, pos_y+56, pos_z+27, block_id)
mc.setBlock(pos_x+26, pos_y+56, pos_z+27, block_id)
mc.setBlock(pos_x+27, pos_y+56, pos_z+27, block_id)
mc.setBlock(pos_x+28, pos_y+56, pos_z+27, block_id)
mc.setBlock(pos_x+29, pos_y+56, pos_z+27, block_id)
mc.setBlock(pos_x+30, pos_y+56, pos_z+27, block_id)
mc.setBlock(pos_x+4, pos_y+48, pos_z+18, block_id)
mc.setBlock(pos_x+52, pos_y+47, pos_z+18, block_id)
mc.setBlock(pos_x+31, pos_y+56, pos_z+27, block_id)
mc.setBlock(pos_x+32, pos_y+56, pos_z+27, block_id)
mc.setBlock(pos_x+33, pos_y+56, pos_z+27, block_id)
mc.setBlock(pos_x+34, pos_y+56, pos_z+27, block_id)
mc.setBlock(pos_x+35, pos_y+56, pos_z+27, block_id)
mc.setBlock(pos_x+36, pos_y+56, pos_z+27, block_id)
mc.setBlock(pos_x+37, pos_y+56, pos_z+27, block_id)
mc.setBlock(pos_x+40, pos_y+56, pos_z+27, block_id)
mc.setBlock(pos_x+16, pos_y+57, pos_z+27, block_id)
mc.setBlock(pos_x+4, pos_y+47, pos_z+18, block_id)
mc.setBlock(pos_x+52, pos_y+46, pos_z+18, block_id)
mc.setBlock(pos_x+17, pos_y+57, pos_z+27, block_id)
mc.setBlock(pos_x+18, pos_y+57, pos_z+27, block_id)
mc.setBlock(pos_x+38, pos_y+57, pos_z+27, block_id)
mc.setBlock(pos_x+39, pos_y+57, pos_z+27, block_id)
mc.setBlock(pos_x+40, pos_y+57, pos_z+27, block_id)
mc.setBlock(pos_x+13, pos_y+14, pos_z+28, block_id)
mc.setBlock(pos_x+14, pos_y+14, pos_z+28, block_id)
mc.setBlock(pos_x+42, pos_y+14, pos_z+28, block_id)
mc.setBlock(pos_x+43, pos_y+14, pos_z+28, block_id)
mc.setBlock(pos_x+4, pos_y+46, pos_z+18, block_id)
mc.setBlock(pos_x+52, pos_y+45, pos_z+18, block_id)
mc.setBlock(pos_x+13, pos_y+15, pos_z+28, block_id)
mc.setBlock(pos_x+14, pos_y+15, pos_z+28, block_id)
mc.setBlock(pos_x+42, pos_y+15, pos_z+28, block_id)
mc.setBlock(pos_x+43, pos_y+15, pos_z+28, block_id)
mc.setBlock(pos_x+13, pos_y+16, pos_z+28, block_id)
mc.setBlock(pos_x+14, pos_y+16, pos_z+28, block_id)
mc.setBlock(pos_x+42, pos_y+16, pos_z+28, block_id)
mc.setBlock(pos_x+43, pos_y+16, pos_z+28, block_id)
mc.setBlock(pos_x+10, pos_y+17, pos_z+28, block_id)
mc.setBlock(pos_x+11, pos_y+17, pos_z+28, block_id)
mc.setBlock(pos_x+4, pos_y+45, pos_z+18, block_id)
mc.setBlock(pos_x+51, pos_y+44, pos_z+18, block_id)
mc.setBlock(pos_x+12, pos_y+17, pos_z+28, block_id)
mc.setBlock(pos_x+14, pos_y+17, pos_z+28, block_id)
mc.setBlock(pos_x+42, pos_y+17, pos_z+28, block_id)
mc.setBlock(pos_x+44, pos_y+17, pos_z+28, block_id)
mc.setBlock(pos_x+45, pos_y+17, pos_z+28, block_id)
mc.setBlock(pos_x+46, pos_y+17, pos_z+28, block_id)
mc.setBlock(pos_x+8, pos_y+18, pos_z+28, block_id)
mc.setBlock(pos_x+9, pos_y+18, pos_z+28, block_id)
mc.setBlock(pos_x+5, pos_y+44, pos_z+18, block_id)
mc.setBlock(pos_x+51, pos_y+43, pos_z+18, block_id)
mc.setBlock(pos_x+14, pos_y+18, pos_z+28, block_id)
mc.setBlock(pos_x+15, pos_y+18, pos_z+28, block_id)
mc.setBlock(pos_x+41, pos_y+18, pos_z+28, block_id)
mc.setBlock(pos_x+42, pos_y+18, pos_z+28, block_id)
mc.setBlock(pos_x+47, pos_y+18, pos_z+28, block_id)
mc.setBlock(pos_x+8, pos_y+19, pos_z+28, block_id)
mc.setBlock(pos_x+14, pos_y+19, pos_z+28, block_id)
mc.setBlock(pos_x+15, pos_y+19, pos_z+28, block_id)
mc.setBlock(pos_x+41, pos_y+19, pos_z+28, block_id)
mc.setBlock(pos_x+42, pos_y+19, pos_z+28, block_id)
mc.setBlock(pos_x+48, pos_y+19, pos_z+28, block_id)
mc.setBlock(pos_x+5, pos_y+43, pos_z+18, block_id)
mc.setBlock(pos_x+51, pos_y+42, pos_z+18, block_id)
mc.setBlock(pos_x+50, pos_y+42, pos_z+18, block_id)
mc.setBlock(pos_x+7, pos_y+20, pos_z+28, block_id)
mc.setBlock(pos_x+14, pos_y+20, pos_z+28, block_id)
mc.setBlock(pos_x+41, pos_y+20, pos_z+28, block_id)
mc.setBlock(pos_x+49, pos_y+20, pos_z+28, block_id)
mc.setBlock(pos_x+42, pos_y+42, pos_z+18, block_id)
mc.setBlock(pos_x+7, pos_y+21, pos_z+28, block_id)
mc.setBlock(pos_x+15, pos_y+21, pos_z+28, block_id)
mc.setBlock(pos_x+14, pos_y+42, pos_z+18, block_id)
mc.setBlock(pos_x+41, pos_y+21, pos_z+28, block_id)
mc.setBlock(pos_x+49, pos_y+21, pos_z+28, block_id)
mc.setBlock(pos_x+6, pos_y+22, pos_z+28, block_id)
mc.setBlock(pos_x+15, pos_y+22, pos_z+28, block_id)
mc.setBlock(pos_x+41, pos_y+22, pos_z+28, block_id)
mc.setBlock(pos_x+6, pos_y+42, pos_z+18, block_id)
mc.setBlock(pos_x+5, pos_y+42, pos_z+18, block_id)
mc.setBlock(pos_x+50, pos_y+41, pos_z+18, block_id)
mc.setBlock(pos_x+49, pos_y+41, pos_z+18, block_id)
mc.setBlock(pos_x+48, pos_y+41, pos_z+18, block_id)
mc.setBlock(pos_x+50, pos_y+22, pos_z+28, block_id)
mc.setBlock(pos_x+6, pos_y+23, pos_z+28, block_id)
mc.setBlock(pos_x+15, pos_y+23, pos_z+28, block_id)
mc.setBlock(pos_x+44, pos_y+41, pos_z+18, block_id)
mc.setBlock(pos_x+43, pos_y+41, pos_z+18, block_id)
mc.setBlock(pos_x+41, pos_y+41, pos_z+18, block_id)
mc.setBlock(pos_x+15, pos_y+41, pos_z+18, block_id)
mc.setBlock(pos_x+13, pos_y+41, pos_z+18, block_id)
mc.setBlock(pos_x+12, pos_y+41, pos_z+18, block_id)
mc.setBlock(pos_x+41, pos_y+23, pos_z+28, block_id)
mc.setBlock(pos_x+50, pos_y+23, pos_z+28, block_id)
mc.setBlock(pos_x+6, pos_y+24, pos_z+28, block_id)
mc.setBlock(pos_x+8, pos_y+41, pos_z+18, block_id)
mc.setBlock(pos_x+7, pos_y+41, pos_z+18, block_id)
mc.setBlock(pos_x+6, pos_y+41, pos_z+18, block_id)
mc.setBlock(pos_x+47, pos_y+40, pos_z+18, block_id)
mc.setBlock(pos_x+46, pos_y+40, pos_z+18, block_id)
mc.setBlock(pos_x+45, pos_y+40, pos_z+18, block_id)
mc.setBlock(pos_x+41, pos_y+40, pos_z+18, block_id)
mc.setBlock(pos_x+15, pos_y+24, pos_z+28, block_id)
mc.setBlock(pos_x+41, pos_y+24, pos_z+28, block_id)
mc.setBlock(pos_x+15, pos_y+40, pos_z+18, block_id)
mc.setBlock(pos_x+11, pos_y+40, pos_z+18, block_id)
mc.setBlock(pos_x+10, pos_y+40, pos_z+18, block_id)
mc.setBlock(pos_x+9, pos_y+40, pos_z+18, block_id)
mc.setBlock(pos_x+41, pos_y+39, pos_z+18, block_id)
mc.setBlock(pos_x+49, pos_y+24, pos_z+28, block_id)
mc.setBlock(pos_x+6, pos_y+25, pos_z+28, block_id)
mc.setBlock(pos_x+15, pos_y+39, pos_z+18, block_id)
mc.setBlock(pos_x+40, pos_y+38, pos_z+18, block_id)
mc.setBlock(pos_x+14, pos_y+25, pos_z+28, block_id)
mc.setBlock(pos_x+41, pos_y+25, pos_z+28, block_id)
mc.setBlock(pos_x+16, pos_y+38, pos_z+18, block_id)
mc.setBlock(pos_x+39, pos_y+37, pos_z+18, block_id)
mc.setBlock(pos_x+50, pos_y+25, pos_z+28, block_id)
mc.setBlock(pos_x+6, pos_y+26, pos_z+28, block_id)
mc.setBlock(pos_x+14, pos_y+26, pos_z+28, block_id)
mc.setBlock(pos_x+16, pos_y+37, pos_z+18, block_id)
mc.setBlock(pos_x+39, pos_y+36, pos_z+18, block_id)
mc.setBlock(pos_x+42, pos_y+26, pos_z+28, block_id)
mc.setBlock(pos_x+50, pos_y+26, pos_z+28, block_id)
mc.setBlock(pos_x+6, pos_y+27, pos_z+28, block_id)
mc.setBlock(pos_x+17, pos_y+36, pos_z+18, block_id)
mc.setBlock(pos_x+38, pos_y+35, pos_z+18, block_id)
mc.setBlock(pos_x+14, pos_y+27, pos_z+28, block_id)
mc.setBlock(pos_x+42, pos_y+27, pos_z+28, block_id)
mc.setBlock(pos_x+50, pos_y+27, pos_z+28, block_id)
mc.setBlock(pos_x+7, pos_y+28, pos_z+28, block_id)
mc.setBlock(pos_x+14, pos_y+28, pos_z+28, block_id)
mc.setBlock(pos_x+42, pos_y+28, pos_z+28, block_id)
mc.setBlock(pos_x+49, pos_y+28, pos_z+28, block_id)
mc.setBlock(pos_x+7, pos_y+29, pos_z+28, block_id)
mc.setBlock(pos_x+13, pos_y+29, pos_z+28, block_id)
mc.setBlock(pos_x+20, pos_y+29, pos_z+28, block_id)
mc.setBlock(pos_x+21, pos_y+29, pos_z+28, block_id)
mc.setBlock(pos_x+22, pos_y+29, pos_z+28, block_id)
mc.setBlock(pos_x+23, pos_y+29, pos_z+28, block_id)
mc.setBlock(pos_x+18, pos_y+35, pos_z+18, block_id)
mc.setBlock(pos_x+37, pos_y+34, pos_z+18, block_id)
mc.setBlock(pos_x+24, pos_y+29, pos_z+28, block_id)
mc.setBlock(pos_x+25, pos_y+29, pos_z+28, block_id)
mc.setBlock(pos_x+26, pos_y+29, pos_z+28, block_id)
mc.setBlock(pos_x+33, pos_y+34, pos_z+18, block_id)
mc.setBlock(pos_x+32, pos_y+34, pos_z+18, block_id)
mc.setBlock(pos_x+31, pos_y+34, pos_z+18, block_id)
mc.setBlock(pos_x+30, pos_y+34, pos_z+18, block_id)
mc.setBlock(pos_x+29, pos_y+34, pos_z+18, block_id)
mc.setBlock(pos_x+28, pos_y+34, pos_z+18, block_id)
mc.setBlock(pos_x+27, pos_y+34, pos_z+18, block_id)
mc.setBlock(pos_x+26, pos_y+34, pos_z+18, block_id)
mc.setBlock(pos_x+25, pos_y+34, pos_z+18, block_id)
mc.setBlock(pos_x+24, pos_y+34, pos_z+18, block_id)
mc.setBlock(pos_x+23, pos_y+34, pos_z+18, block_id)
mc.setBlock(pos_x+22, pos_y+34, pos_z+18, block_id)
mc.setBlock(pos_x+27, pos_y+29, pos_z+28, block_id)
mc.setBlock(pos_x+28, pos_y+29, pos_z+28, block_id)
