from mcpi.minecraft import Minecraft
mc = Minecraft.create("mc.tokyocodingclub.com")
playerId = mc.getPlayerEntityId("TCCMinecraft008")

pos_x, pos_y, pos_z = mc.entity.getPos(playerId)
block_id = 155

mc.setBlock(pos_x+77, pos_y+10, pos_z+66, block_id)
mc.setBlock(pos_x+76, pos_y+10, pos_z+66, block_id)
mc.setBlock(pos_x+75, pos_y+10, pos_z+66, block_id)
mc.setBlock(pos_x+74, pos_y+10, pos_z+66, block_id)
mc.setBlock(pos_x+73, pos_y+10, pos_z+66, block_id)
mc.setBlock(pos_x+72, pos_y+10, pos_z+66, block_id)
mc.setBlock(pos_x+71, pos_y+10, pos_z+66, block_id)
mc.setBlock(pos_x+70, pos_y+10, pos_z+66, block_id)
mc.setBlock(pos_x+69, pos_y+10, pos_z+66, block_id)
mc.setBlock(pos_x+68, pos_y+10, pos_z+66, block_id)
mc.setBlock(pos_x+67, pos_y+10, pos_z+66, block_id)
mc.setBlock(pos_x+66, pos_y+10, pos_z+66, block_id)
mc.setBlock(pos_x+65, pos_y+10, pos_z+66, block_id)
mc.setBlock(pos_x+64, pos_y+10, pos_z+66, block_id)
mc.setBlock(pos_x+63, pos_y+10, pos_z+66, block_id)
mc.setBlock(pos_x+62, pos_y+10, pos_z+66, block_id)
mc.setBlock(pos_x+78, pos_y+10, pos_z+66, block_id)
mc.setBlock(pos_x+79, pos_y+10, pos_z+66, block_id)
mc.setBlock(pos_x+80, pos_y+10, pos_z+66, block_id)
mc.setBlock(pos_x+81, pos_y+10, pos_z+66, block_id)
mc.setBlock(pos_x+82, pos_y+10, pos_z+66, block_id)
mc.setBlock(pos_x+83, pos_y+10, pos_z+66, block_id)
mc.setBlock(pos_x+84, pos_y+10, pos_z+66, block_id)
mc.setBlock(pos_x+85, pos_y+10, pos_z+66, block_id)
mc.setBlock(pos_x+37, pos_y+10, pos_z+66, block_id)
mc.setBlock(pos_x+36, pos_y+10, pos_z+66, block_id)
mc.setBlock(pos_x+35, pos_y+10, pos_z+66, block_id)
mc.setBlock(pos_x+34, pos_y+10, pos_z+66, block_id)
mc.setBlock(pos_x+33, pos_y+10, pos_z+66, block_id)
mc.setBlock(pos_x+32, pos_y+10, pos_z+66, block_id)
mc.setBlock(pos_x+31, pos_y+10, pos_z+66, block_id)
mc.setBlock(pos_x+30, pos_y+10, pos_z+66, block_id)
mc.setBlock(pos_x+29, pos_y+10, pos_z+66, block_id)
mc.setBlock(pos_x+28, pos_y+10, pos_z+66, block_id)
mc.setBlock(pos_x+27, pos_y+10, pos_z+66, block_id)
mc.setBlock(pos_x+26, pos_y+10, pos_z+66, block_id)
mc.setBlock(pos_x+25, pos_y+10, pos_z+66, block_id)
mc.setBlock(pos_x+24, pos_y+10, pos_z+66, block_id)
mc.setBlock(pos_x+23, pos_y+10, pos_z+66, block_id)
mc.setBlock(pos_x+22, pos_y+10, pos_z+66, block_id)
mc.setBlock(pos_x+21, pos_y+10, pos_z+66, block_id)
mc.setBlock(pos_x+20, pos_y+10, pos_z+66, block_id)
mc.setBlock(pos_x+19, pos_y+10, pos_z+66, block_id)
mc.setBlock(pos_x+18, pos_y+10, pos_z+66, block_id)
mc.setBlock(pos_x+17, pos_y+10, pos_z+66, block_id)
mc.setBlock(pos_x+16, pos_y+10, pos_z+66, block_id)
mc.setBlock(pos_x+15, pos_y+10, pos_z+66, block_id)
mc.setBlock(pos_x+14, pos_y+10, pos_z+66, block_id)
mc.setBlock(pos_x+13, pos_y+10, pos_z+66, block_id)
mc.setBlock(pos_x+12, pos_y+10, pos_z+66, block_id)
mc.setBlock(pos_x+11, pos_y+10, pos_z+66, block_id)
mc.setBlock(pos_x+10, pos_y+10, pos_z+66, block_id)
mc.setBlock(pos_x+9, pos_y+10, pos_z+66, block_id)
mc.setBlock(pos_x+8, pos_y+10, pos_z+66, block_id)
mc.setBlock(pos_x+7, pos_y+10, pos_z+66, block_id)
mc.setBlock(pos_x+6, pos_y+10, pos_z+66, block_id)
mc.setBlock(pos_x+5, pos_y+10, pos_z+66, block_id)
mc.setBlock(pos_x+99, pos_y+9, pos_z+66, block_id)
mc.setBlock(pos_x+98, pos_y+9, pos_z+66, block_id)
mc.setBlock(pos_x+97, pos_y+9, pos_z+66, block_id)
mc.setBlock(pos_x+96, pos_y+9, pos_z+66, block_id)
mc.setBlock(pos_x+95, pos_y+9, pos_z+66, block_id)
mc.setBlock(pos_x+94, pos_y+9, pos_z+66, block_id)
mc.setBlock(pos_x+86, pos_y+10, pos_z+66, block_id)
mc.setBlock(pos_x+87, pos_y+10, pos_z+66, block_id)
mc.setBlock(pos_x+88, pos_y+10, pos_z+66, block_id)
mc.setBlock(pos_x+89, pos_y+10, pos_z+66, block_id)
mc.setBlock(pos_x+90, pos_y+10, pos_z+66, block_id)
mc.setBlock(pos_x+91, pos_y+10, pos_z+66, block_id)
mc.setBlock(pos_x+92, pos_y+10, pos_z+66, block_id)
mc.setBlock(pos_x+93, pos_y+10, pos_z+66, block_id)
mc.setBlock(pos_x+38, pos_y+11, pos_z+66, block_id)
mc.setBlock(pos_x+61, pos_y+11, pos_z+66, block_id)
mc.setBlock(pos_x+38, pos_y+12, pos_z+66, block_id)
mc.setBlock(pos_x+61, pos_y+12, pos_z+66, block_id)
mc.setBlock(pos_x+39, pos_y+13, pos_z+66, block_id)
mc.setBlock(pos_x+60, pos_y+13, pos_z+66, block_id)
mc.setBlock(pos_x+39, pos_y+14, pos_z+66, block_id)
mc.setBlock(pos_x+60, pos_y+14, pos_z+66, block_id)
mc.setBlock(pos_x+40, pos_y+15, pos_z+66, block_id)
mc.setBlock(pos_x+59, pos_y+15, pos_z+66, block_id)
mc.setBlock(pos_x+41, pos_y+16, pos_z+66, block_id)
mc.setBlock(pos_x+57, pos_y+16, pos_z+66, block_id)
mc.setBlock(pos_x+58, pos_y+16, pos_z+66, block_id)
mc.setBlock(pos_x+42, pos_y+17, pos_z+66, block_id)
mc.setBlock(pos_x+43, pos_y+17, pos_z+66, block_id)
mc.setBlock(pos_x+56, pos_y+17, pos_z+66, block_id)
mc.setBlock(pos_x+44, pos_y+18, pos_z+66, block_id)
mc.setBlock(pos_x+45, pos_y+18, pos_z+66, block_id)
mc.setBlock(pos_x+46, pos_y+18, pos_z+66, block_id)
mc.setBlock(pos_x+53, pos_y+18, pos_z+66, block_id)
mc.setBlock(pos_x+54, pos_y+18, pos_z+66, block_id)
mc.setBlock(pos_x+55, pos_y+18, pos_z+66, block_id)
mc.setBlock(pos_x+47, pos_y+19, pos_z+66, block_id)
mc.setBlock(pos_x+48, pos_y+19, pos_z+66, block_id)
mc.setBlock(pos_x+49, pos_y+19, pos_z+66, block_id)
mc.setBlock(pos_x+50, pos_y+19, pos_z+66, block_id)
mc.setBlock(pos_x+51, pos_y+19, pos_z+66, block_id)
mc.setBlock(pos_x+52, pos_y+19, pos_z+66, block_id)
mc.setBlock(pos_x+45, pos_y+0, pos_z+67, block_id)
mc.setBlock(pos_x+46, pos_y+0, pos_z+67, block_id)
mc.setBlock(pos_x+4, pos_y+9, pos_z+66, block_id)
mc.setBlock(pos_x+3, pos_y+9, pos_z+66, block_id)
mc.setBlock(pos_x+2, pos_y+9, pos_z+66, block_id)
mc.setBlock(pos_x+1, pos_y+9, pos_z+66, block_id)
mc.setBlock(pos_x+0, pos_y+9, pos_z+66, block_id)
mc.setBlock(pos_x+98, pos_y+8, pos_z+66, block_id)
mc.setBlock(pos_x+97, pos_y+8, pos_z+66, block_id)
mc.setBlock(pos_x+96, pos_y+8, pos_z+66, block_id)
mc.setBlock(pos_x+95, pos_y+8, pos_z+66, block_id)
mc.setBlock(pos_x+94, pos_y+8, pos_z+66, block_id)
mc.setBlock(pos_x+93, pos_y+8, pos_z+66, block_id)
mc.setBlock(pos_x+92, pos_y+8, pos_z+66, block_id)
mc.setBlock(pos_x+91, pos_y+8, pos_z+66, block_id)
mc.setBlock(pos_x+90, pos_y+8, pos_z+66, block_id)
mc.setBlock(pos_x+89, pos_y+8, pos_z+66, block_id)
mc.setBlock(pos_x+88, pos_y+8, pos_z+66, block_id)
mc.setBlock(pos_x+87, pos_y+8, pos_z+66, block_id)
mc.setBlock(pos_x+47, pos_y+0, pos_z+67, block_id)
mc.setBlock(pos_x+48, pos_y+0, pos_z+67, block_id)
mc.setBlock(pos_x+49, pos_y+0, pos_z+67, block_id)
mc.setBlock(pos_x+50, pos_y+0, pos_z+67, block_id)
mc.setBlock(pos_x+51, pos_y+0, pos_z+67, block_id)
mc.setBlock(pos_x+52, pos_y+0, pos_z+67, block_id)
mc.setBlock(pos_x+53, pos_y+0, pos_z+67, block_id)
mc.setBlock(pos_x+54, pos_y+0, pos_z+67, block_id)
mc.setBlock(pos_x+42, pos_y+1, pos_z+67, block_id)
mc.setBlock(pos_x+43, pos_y+1, pos_z+67, block_id)
mc.setBlock(pos_x+44, pos_y+1, pos_z+67, block_id)
mc.setBlock(pos_x+55, pos_y+1, pos_z+67, block_id)
mc.setBlock(pos_x+56, pos_y+1, pos_z+67, block_id)
mc.setBlock(pos_x+41, pos_y+2, pos_z+67, block_id)
mc.setBlock(pos_x+57, pos_y+2, pos_z+67, block_id)
mc.setBlock(pos_x+58, pos_y+2, pos_z+67, block_id)
mc.setBlock(pos_x+40, pos_y+3, pos_z+67, block_id)
mc.setBlock(pos_x+59, pos_y+3, pos_z+67, block_id)
mc.setBlock(pos_x+39, pos_y+4, pos_z+67, block_id)
mc.setBlock(pos_x+60, pos_y+4, pos_z+67, block_id)
mc.setBlock(pos_x+39, pos_y+5, pos_z+67, block_id)
mc.setBlock(pos_x+60, pos_y+5, pos_z+67, block_id)
mc.setBlock(pos_x+38, pos_y+6, pos_z+67, block_id)
mc.setBlock(pos_x+61, pos_y+6, pos_z+67, block_id)
mc.setBlock(pos_x+13, pos_y+7, pos_z+67, block_id)
mc.setBlock(pos_x+14, pos_y+7, pos_z+67, block_id)
mc.setBlock(pos_x+15, pos_y+7, pos_z+67, block_id)
mc.setBlock(pos_x+16, pos_y+7, pos_z+67, block_id)
mc.setBlock(pos_x+17, pos_y+7, pos_z+67, block_id)
mc.setBlock(pos_x+18, pos_y+7, pos_z+67, block_id)
mc.setBlock(pos_x+19, pos_y+7, pos_z+67, block_id)
mc.setBlock(pos_x+20, pos_y+7, pos_z+67, block_id)
mc.setBlock(pos_x+21, pos_y+7, pos_z+67, block_id)
mc.setBlock(pos_x+22, pos_y+7, pos_z+67, block_id)
mc.setBlock(pos_x+23, pos_y+7, pos_z+67, block_id)
mc.setBlock(pos_x+24, pos_y+7, pos_z+67, block_id)
mc.setBlock(pos_x+25, pos_y+7, pos_z+67, block_id)
mc.setBlock(pos_x+26, pos_y+7, pos_z+67, block_id)
mc.setBlock(pos_x+12, pos_y+8, pos_z+66, block_id)
mc.setBlock(pos_x+11, pos_y+8, pos_z+66, block_id)
mc.setBlock(pos_x+10, pos_y+8, pos_z+66, block_id)
mc.setBlock(pos_x+9, pos_y+8, pos_z+66, block_id)
mc.setBlock(pos_x+8, pos_y+8, pos_z+66, block_id)
mc.setBlock(pos_x+7, pos_y+8, pos_z+66, block_id)
mc.setBlock(pos_x+6, pos_y+8, pos_z+66, block_id)
mc.setBlock(pos_x+5, pos_y+8, pos_z+66, block_id)
mc.setBlock(pos_x+4, pos_y+8, pos_z+66, block_id)
mc.setBlock(pos_x+3, pos_y+8, pos_z+66, block_id)
mc.setBlock(pos_x+2, pos_y+8, pos_z+66, block_id)
mc.setBlock(pos_x+1, pos_y+8, pos_z+66, block_id)
mc.setBlock(pos_x+86, pos_y+7, pos_z+66, block_id)
mc.setBlock(pos_x+85, pos_y+7, pos_z+66, block_id)
mc.setBlock(pos_x+84, pos_y+7, pos_z+66, block_id)
mc.setBlock(pos_x+83, pos_y+7, pos_z+66, block_id)
mc.setBlock(pos_x+82, pos_y+7, pos_z+66, block_id)
mc.setBlock(pos_x+81, pos_y+7, pos_z+66, block_id)
mc.setBlock(pos_x+80, pos_y+7, pos_z+66, block_id)
mc.setBlock(pos_x+79, pos_y+7, pos_z+66, block_id)
mc.setBlock(pos_x+78, pos_y+7, pos_z+66, block_id)
mc.setBlock(pos_x+77, pos_y+7, pos_z+66, block_id)
mc.setBlock(pos_x+76, pos_y+7, pos_z+66, block_id)
mc.setBlock(pos_x+75, pos_y+7, pos_z+66, block_id)
mc.setBlock(pos_x+74, pos_y+7, pos_z+66, block_id)
mc.setBlock(pos_x+73, pos_y+7, pos_z+66, block_id)
mc.setBlock(pos_x+72, pos_y+7, pos_z+66, block_id)
mc.setBlock(pos_x+71, pos_y+7, pos_z+66, block_id)
mc.setBlock(pos_x+70, pos_y+7, pos_z+66, block_id)
mc.setBlock(pos_x+69, pos_y+7, pos_z+66, block_id)
mc.setBlock(pos_x+68, pos_y+7, pos_z+66, block_id)
mc.setBlock(pos_x+67, pos_y+7, pos_z+66, block_id)
mc.setBlock(pos_x+66, pos_y+7, pos_z+66, block_id)
mc.setBlock(pos_x+65, pos_y+7, pos_z+66, block_id)
mc.setBlock(pos_x+64, pos_y+7, pos_z+66, block_id)
mc.setBlock(pos_x+63, pos_y+7, pos_z+66, block_id)
mc.setBlock(pos_x+62, pos_y+7, pos_z+66, block_id)
mc.setBlock(pos_x+27, pos_y+7, pos_z+67, block_id)
mc.setBlock(pos_x+28, pos_y+7, pos_z+67, block_id)
mc.setBlock(pos_x+29, pos_y+7, pos_z+67, block_id)
mc.setBlock(pos_x+30, pos_y+7, pos_z+67, block_id)
mc.setBlock(pos_x+31, pos_y+7, pos_z+67, block_id)
mc.setBlock(pos_x+32, pos_y+7, pos_z+67, block_id)
mc.setBlock(pos_x+33, pos_y+7, pos_z+67, block_id)
mc.setBlock(pos_x+34, pos_y+7, pos_z+67, block_id)
mc.setBlock(pos_x+35, pos_y+7, pos_z+67, block_id)
mc.setBlock(pos_x+36, pos_y+7, pos_z+67, block_id)
mc.setBlock(pos_x+37, pos_y+7, pos_z+66, block_id)
mc.setBlock(pos_x+36, pos_y+7, pos_z+66, block_id)
mc.setBlock(pos_x+35, pos_y+7, pos_z+66, block_id)
mc.setBlock(pos_x+34, pos_y+7, pos_z+66, block_id)
mc.setBlock(pos_x+33, pos_y+7, pos_z+66, block_id)
mc.setBlock(pos_x+32, pos_y+7, pos_z+66, block_id)
mc.setBlock(pos_x+31, pos_y+7, pos_z+66, block_id)
mc.setBlock(pos_x+30, pos_y+7, pos_z+66, block_id)
mc.setBlock(pos_x+29, pos_y+7, pos_z+66, block_id)
mc.setBlock(pos_x+28, pos_y+7, pos_z+66, block_id)
mc.setBlock(pos_x+27, pos_y+7, pos_z+66, block_id)
mc.setBlock(pos_x+26, pos_y+7, pos_z+66, block_id)
mc.setBlock(pos_x+25, pos_y+7, pos_z+66, block_id)
mc.setBlock(pos_x+24, pos_y+7, pos_z+66, block_id)
mc.setBlock(pos_x+23, pos_y+7, pos_z+66, block_id)
mc.setBlock(pos_x+22, pos_y+7, pos_z+66, block_id)
mc.setBlock(pos_x+21, pos_y+7, pos_z+66, block_id)
mc.setBlock(pos_x+20, pos_y+7, pos_z+66, block_id)
mc.setBlock(pos_x+19, pos_y+7, pos_z+66, block_id)
mc.setBlock(pos_x+18, pos_y+7, pos_z+66, block_id)
mc.setBlock(pos_x+17, pos_y+7, pos_z+66, block_id)
mc.setBlock(pos_x+16, pos_y+7, pos_z+66, block_id)
mc.setBlock(pos_x+15, pos_y+7, pos_z+66, block_id)
mc.setBlock(pos_x+14, pos_y+7, pos_z+66, block_id)
mc.setBlock(pos_x+13, pos_y+7, pos_z+66, block_id)
mc.setBlock(pos_x+61, pos_y+6, pos_z+66, block_id)
mc.setBlock(pos_x+37, pos_y+7, pos_z+67, block_id)
mc.setBlock(pos_x+62, pos_y+7, pos_z+67, block_id)
mc.setBlock(pos_x+63, pos_y+7, pos_z+67, block_id)
mc.setBlock(pos_x+64, pos_y+7, pos_z+67, block_id)
mc.setBlock(pos_x+65, pos_y+7, pos_z+67, block_id)
mc.setBlock(pos_x+66, pos_y+7, pos_z+67, block_id)
mc.setBlock(pos_x+67, pos_y+7, pos_z+67, block_id)
mc.setBlock(pos_x+68, pos_y+7, pos_z+67, block_id)
mc.setBlock(pos_x+69, pos_y+7, pos_z+67, block_id)
mc.setBlock(pos_x+70, pos_y+7, pos_z+67, block_id)
mc.setBlock(pos_x+38, pos_y+6, pos_z+66, block_id)
mc.setBlock(pos_x+60, pos_y+5, pos_z+66, block_id)
mc.setBlock(pos_x+71, pos_y+7, pos_z+67, block_id)
mc.setBlock(pos_x+72, pos_y+7, pos_z+67, block_id)
mc.setBlock(pos_x+73, pos_y+7, pos_z+67, block_id)
mc.setBlock(pos_x+74, pos_y+7, pos_z+67, block_id)
mc.setBlock(pos_x+75, pos_y+7, pos_z+67, block_id)
mc.setBlock(pos_x+76, pos_y+7, pos_z+67, block_id)
mc.setBlock(pos_x+77, pos_y+7, pos_z+67, block_id)
mc.setBlock(pos_x+78, pos_y+7, pos_z+67, block_id)
mc.setBlock(pos_x+79, pos_y+7, pos_z+67, block_id)
mc.setBlock(pos_x+38, pos_y+5, pos_z+66, block_id)
mc.setBlock(pos_x+60, pos_y+4, pos_z+66, block_id)
mc.setBlock(pos_x+80, pos_y+7, pos_z+67, block_id)
mc.setBlock(pos_x+81, pos_y+7, pos_z+67, block_id)
mc.setBlock(pos_x+82, pos_y+7, pos_z+67, block_id)
mc.setBlock(pos_x+83, pos_y+7, pos_z+67, block_id)
mc.setBlock(pos_x+84, pos_y+7, pos_z+67, block_id)
mc.setBlock(pos_x+85, pos_y+7, pos_z+67, block_id)
mc.setBlock(pos_x+86, pos_y+7, pos_z+67, block_id)
mc.setBlock(pos_x+0, pos_y+8, pos_z+67, block_id)
mc.setBlock(pos_x+39, pos_y+4, pos_z+66, block_id)
mc.setBlock(pos_x+59, pos_y+3, pos_z+66, block_id)
mc.setBlock(pos_x+1, pos_y+8, pos_z+67, block_id)
mc.setBlock(pos_x+2, pos_y+8, pos_z+67, block_id)
mc.setBlock(pos_x+3, pos_y+8, pos_z+67, block_id)
mc.setBlock(pos_x+4, pos_y+8, pos_z+67, block_id)
mc.setBlock(pos_x+5, pos_y+8, pos_z+67, block_id)
mc.setBlock(pos_x+6, pos_y+8, pos_z+67, block_id)
mc.setBlock(pos_x+40, pos_y+3, pos_z+66, block_id)
mc.setBlock(pos_x+58, pos_y+2, pos_z+66, block_id)
mc.setBlock(pos_x+57, pos_y+2, pos_z+66, block_id)
mc.setBlock(pos_x+7, pos_y+8, pos_z+67, block_id)
mc.setBlock(pos_x+8, pos_y+8, pos_z+67, block_id)
mc.setBlock(pos_x+9, pos_y+8, pos_z+67, block_id)
mc.setBlock(pos_x+41, pos_y+2, pos_z+66, block_id)
mc.setBlock(pos_x+56, pos_y+1, pos_z+66, block_id)
mc.setBlock(pos_x+55, pos_y+1, pos_z+66, block_id)
mc.setBlock(pos_x+10, pos_y+8, pos_z+67, block_id)
mc.setBlock(pos_x+11, pos_y+8, pos_z+67, block_id)
mc.setBlock(pos_x+44, pos_y+1, pos_z+66, block_id)
mc.setBlock(pos_x+43, pos_y+1, pos_z+66, block_id)
mc.setBlock(pos_x+42, pos_y+1, pos_z+66, block_id)
mc.setBlock(pos_x+54, pos_y+0, pos_z+66, block_id)
mc.setBlock(pos_x+53, pos_y+0, pos_z+66, block_id)
mc.setBlock(pos_x+52, pos_y+0, pos_z+66, block_id)
mc.setBlock(pos_x+51, pos_y+0, pos_z+66, block_id)
mc.setBlock(pos_x+50, pos_y+0, pos_z+66, block_id)
mc.setBlock(pos_x+49, pos_y+0, pos_z+66, block_id)
mc.setBlock(pos_x+48, pos_y+0, pos_z+66, block_id)
mc.setBlock(pos_x+47, pos_y+0, pos_z+66, block_id)
mc.setBlock(pos_x+46, pos_y+0, pos_z+66, block_id)
mc.setBlock(pos_x+45, pos_y+0, pos_z+66, block_id)
mc.setBlock(pos_x+52, pos_y+19, pos_z+65, block_id)
mc.setBlock(pos_x+51, pos_y+19, pos_z+65, block_id)
mc.setBlock(pos_x+50, pos_y+19, pos_z+65, block_id)
mc.setBlock(pos_x+49, pos_y+19, pos_z+65, block_id)
mc.setBlock(pos_x+48, pos_y+19, pos_z+65, block_id)
mc.setBlock(pos_x+47, pos_y+19, pos_z+65, block_id)
mc.setBlock(pos_x+55, pos_y+18, pos_z+65, block_id)
mc.setBlock(pos_x+54, pos_y+18, pos_z+65, block_id)
mc.setBlock(pos_x+53, pos_y+18, pos_z+65, block_id)
mc.setBlock(pos_x+12, pos_y+8, pos_z+67, block_id)
mc.setBlock(pos_x+87, pos_y+8, pos_z+67, block_id)
mc.setBlock(pos_x+46, pos_y+18, pos_z+65, block_id)
mc.setBlock(pos_x+45, pos_y+18, pos_z+65, block_id)
mc.setBlock(pos_x+44, pos_y+18, pos_z+65, block_id)
mc.setBlock(pos_x+57, pos_y+17, pos_z+65, block_id)
mc.setBlock(pos_x+56, pos_y+17, pos_z+65, block_id)
mc.setBlock(pos_x+88, pos_y+8, pos_z+67, block_id)
mc.setBlock(pos_x+89, pos_y+8, pos_z+67, block_id)
mc.setBlock(pos_x+43, pos_y+17, pos_z+65, block_id)
mc.setBlock(pos_x+42, pos_y+17, pos_z+65, block_id)
mc.setBlock(pos_x+58, pos_y+16, pos_z+65, block_id)
mc.setBlock(pos_x+90, pos_y+8, pos_z+67, block_id)
mc.setBlock(pos_x+91, pos_y+8, pos_z+67, block_id)
mc.setBlock(pos_x+41, pos_y+16, pos_z+65, block_id)
mc.setBlock(pos_x+59, pos_y+15, pos_z+65, block_id)
mc.setBlock(pos_x+92, pos_y+8, pos_z+67, block_id)
mc.setBlock(pos_x+93, pos_y+8, pos_z+67, block_id)
mc.setBlock(pos_x+40, pos_y+15, pos_z+65, block_id)
mc.setBlock(pos_x+60, pos_y+14, pos_z+65, block_id)
mc.setBlock(pos_x+94, pos_y+8, pos_z+67, block_id)
mc.setBlock(pos_x+95, pos_y+8, pos_z+67, block_id)
mc.setBlock(pos_x+39, pos_y+14, pos_z+65, block_id)
mc.setBlock(pos_x+60, pos_y+13, pos_z+65, block_id)
mc.setBlock(pos_x+96, pos_y+8, pos_z+67, block_id)
mc.setBlock(pos_x+97, pos_y+8, pos_z+67, block_id)
mc.setBlock(pos_x+98, pos_y+8, pos_z+67, block_id)
mc.setBlock(pos_x+99, pos_y+8, pos_z+67, block_id)
mc.setBlock(pos_x+0, pos_y+9, pos_z+67, block_id)
mc.setBlock(pos_x+1, pos_y+9, pos_z+67, block_id)
mc.setBlock(pos_x+39, pos_y+13, pos_z+65, block_id)
mc.setBlock(pos_x+61, pos_y+12, pos_z+65, block_id)
mc.setBlock(pos_x+2, pos_y+9, pos_z+67, block_id)
mc.setBlock(pos_x+3, pos_y+9, pos_z+67, block_id)
mc.setBlock(pos_x+4, pos_y+9, pos_z+67, block_id)
mc.setBlock(pos_x+94, pos_y+9, pos_z+67, block_id)
mc.setBlock(pos_x+95, pos_y+9, pos_z+67, block_id)
mc.setBlock(pos_x+96, pos_y+9, pos_z+67, block_id)
mc.setBlock(pos_x+38, pos_y+12, pos_z+65, block_id)
mc.setBlock(pos_x+61, pos_y+11, pos_z+65, block_id)
mc.setBlock(pos_x+97, pos_y+9, pos_z+67, block_id)
mc.setBlock(pos_x+98, pos_y+9, pos_z+67, block_id)
mc.setBlock(pos_x+99, pos_y+9, pos_z+67, block_id)
mc.setBlock(pos_x+5, pos_y+10, pos_z+67, block_id)
mc.setBlock(pos_x+6, pos_y+10, pos_z+67, block_id)
mc.setBlock(pos_x+7, pos_y+10, pos_z+67, block_id)
mc.setBlock(pos_x+8, pos_y+10, pos_z+67, block_id)
mc.setBlock(pos_x+9, pos_y+10, pos_z+67, block_id)
mc.setBlock(pos_x+38, pos_y+11, pos_z+65, block_id)
mc.setBlock(pos_x+93, pos_y+10, pos_z+65, block_id)
mc.setBlock(pos_x+92, pos_y+10, pos_z+65, block_id)
mc.setBlock(pos_x+91, pos_y+10, pos_z+65, block_id)
mc.setBlock(pos_x+90, pos_y+10, pos_z+65, block_id)
mc.setBlock(pos_x+89, pos_y+10, pos_z+65, block_id)
mc.setBlock(pos_x+88, pos_y+10, pos_z+65, block_id)
mc.setBlock(pos_x+87, pos_y+10, pos_z+65, block_id)
mc.setBlock(pos_x+86, pos_y+10, pos_z+65, block_id)
mc.setBlock(pos_x+85, pos_y+10, pos_z+65, block_id)
mc.setBlock(pos_x+84, pos_y+10, pos_z+65, block_id)
mc.setBlock(pos_x+83, pos_y+10, pos_z+65, block_id)
mc.setBlock(pos_x+82, pos_y+10, pos_z+65, block_id)
mc.setBlock(pos_x+81, pos_y+10, pos_z+65, block_id)
mc.setBlock(pos_x+80, pos_y+10, pos_z+65, block_id)
mc.setBlock(pos_x+79, pos_y+10, pos_z+65, block_id)
mc.setBlock(pos_x+78, pos_y+10, pos_z+65, block_id)
mc.setBlock(pos_x+77, pos_y+10, pos_z+65, block_id)
mc.setBlock(pos_x+76, pos_y+10, pos_z+65, block_id)
mc.setBlock(pos_x+75, pos_y+10, pos_z+65, block_id)
mc.setBlock(pos_x+74, pos_y+10, pos_z+65, block_id)
mc.setBlock(pos_x+73, pos_y+10, pos_z+65, block_id)
mc.setBlock(pos_x+72, pos_y+10, pos_z+65, block_id)
mc.setBlock(pos_x+71, pos_y+10, pos_z+65, block_id)
mc.setBlock(pos_x+70, pos_y+10, pos_z+65, block_id)
mc.setBlock(pos_x+69, pos_y+10, pos_z+65, block_id)
mc.setBlock(pos_x+68, pos_y+10, pos_z+65, block_id)
mc.setBlock(pos_x+67, pos_y+10, pos_z+65, block_id)
mc.setBlock(pos_x+66, pos_y+10, pos_z+65, block_id)
mc.setBlock(pos_x+65, pos_y+10, pos_z+65, block_id)
mc.setBlock(pos_x+64, pos_y+10, pos_z+65, block_id)
mc.setBlock(pos_x+63, pos_y+10, pos_z+65, block_id)
mc.setBlock(pos_x+62, pos_y+10, pos_z+65, block_id)
mc.setBlock(pos_x+10, pos_y+10, pos_z+67, block_id)
mc.setBlock(pos_x+11, pos_y+10, pos_z+67, block_id)
mc.setBlock(pos_x+12, pos_y+10, pos_z+67, block_id)
mc.setBlock(pos_x+13, pos_y+10, pos_z+67, block_id)
mc.setBlock(pos_x+14, pos_y+10, pos_z+67, block_id)
mc.setBlock(pos_x+15, pos_y+10, pos_z+67, block_id)
mc.setBlock(pos_x+16, pos_y+10, pos_z+67, block_id)
mc.setBlock(pos_x+17, pos_y+10, pos_z+67, block_id)
mc.setBlock(pos_x+37, pos_y+10, pos_z+65, block_id)
mc.setBlock(pos_x+36, pos_y+10, pos_z+65, block_id)
mc.setBlock(pos_x+35, pos_y+10, pos_z+65, block_id)
mc.setBlock(pos_x+34, pos_y+10, pos_z+65, block_id)
mc.setBlock(pos_x+33, pos_y+10, pos_z+65, block_id)
mc.setBlock(pos_x+32, pos_y+10, pos_z+65, block_id)
mc.setBlock(pos_x+31, pos_y+10, pos_z+65, block_id)
mc.setBlock(pos_x+30, pos_y+10, pos_z+65, block_id)
mc.setBlock(pos_x+29, pos_y+10, pos_z+65, block_id)
mc.setBlock(pos_x+28, pos_y+10, pos_z+65, block_id)
mc.setBlock(pos_x+27, pos_y+10, pos_z+65, block_id)
mc.setBlock(pos_x+26, pos_y+10, pos_z+65, block_id)
mc.setBlock(pos_x+25, pos_y+10, pos_z+65, block_id)
mc.setBlock(pos_x+24, pos_y+10, pos_z+65, block_id)
mc.setBlock(pos_x+23, pos_y+10, pos_z+65, block_id)
mc.setBlock(pos_x+22, pos_y+10, pos_z+65, block_id)
mc.setBlock(pos_x+21, pos_y+10, pos_z+65, block_id)
mc.setBlock(pos_x+20, pos_y+10, pos_z+65, block_id)
mc.setBlock(pos_x+19, pos_y+10, pos_z+65, block_id)
mc.setBlock(pos_x+18, pos_y+10, pos_z+65, block_id)
mc.setBlock(pos_x+17, pos_y+10, pos_z+65, block_id)
mc.setBlock(pos_x+16, pos_y+10, pos_z+65, block_id)
mc.setBlock(pos_x+15, pos_y+10, pos_z+65, block_id)
mc.setBlock(pos_x+14, pos_y+10, pos_z+65, block_id)
mc.setBlock(pos_x+13, pos_y+10, pos_z+65, block_id)
mc.setBlock(pos_x+12, pos_y+10, pos_z+65, block_id)
mc.setBlock(pos_x+11, pos_y+10, pos_z+65, block_id)
mc.setBlock(pos_x+10, pos_y+10, pos_z+65, block_id)
mc.setBlock(pos_x+9, pos_y+10, pos_z+65, block_id)
mc.setBlock(pos_x+8, pos_y+10, pos_z+65, block_id)
mc.setBlock(pos_x+7, pos_y+10, pos_z+65, block_id)
mc.setBlock(pos_x+6, pos_y+10, pos_z+65, block_id)
mc.setBlock(pos_x+5, pos_y+10, pos_z+65, block_id)
mc.setBlock(pos_x+94, pos_y+9, pos_z+65, block_id)
mc.setBlock(pos_x+18, pos_y+10, pos_z+67, block_id)
mc.setBlock(pos_x+19, pos_y+10, pos_z+67, block_id)
mc.setBlock(pos_x+20, pos_y+10, pos_z+67, block_id)
mc.setBlock(pos_x+21, pos_y+10, pos_z+67, block_id)
mc.setBlock(pos_x+22, pos_y+10, pos_z+67, block_id)
mc.setBlock(pos_x+23, pos_y+10, pos_z+67, block_id)
mc.setBlock(pos_x+24, pos_y+10, pos_z+67, block_id)
mc.setBlock(pos_x+25, pos_y+10, pos_z+67, block_id)
mc.setBlock(pos_x+26, pos_y+10, pos_z+67, block_id)
mc.setBlock(pos_x+27, pos_y+10, pos_z+67, block_id)
mc.setBlock(pos_x+28, pos_y+10, pos_z+67, block_id)
mc.setBlock(pos_x+29, pos_y+10, pos_z+67, block_id)
mc.setBlock(pos_x+30, pos_y+10, pos_z+67, block_id)
mc.setBlock(pos_x+31, pos_y+10, pos_z+67, block_id)
mc.setBlock(pos_x+32, pos_y+10, pos_z+67, block_id)
mc.setBlock(pos_x+33, pos_y+10, pos_z+67, block_id)
mc.setBlock(pos_x+34, pos_y+10, pos_z+67, block_id)
mc.setBlock(pos_x+35, pos_y+10, pos_z+67, block_id)
mc.setBlock(pos_x+36, pos_y+10, pos_z+67, block_id)
mc.setBlock(pos_x+37, pos_y+10, pos_z+67, block_id)
mc.setBlock(pos_x+62, pos_y+10, pos_z+67, block_id)
mc.setBlock(pos_x+63, pos_y+10, pos_z+67, block_id)
mc.setBlock(pos_x+64, pos_y+10, pos_z+67, block_id)
mc.setBlock(pos_x+65, pos_y+10, pos_z+67, block_id)
mc.setBlock(pos_x+66, pos_y+10, pos_z+67, block_id)
mc.setBlock(pos_x+67, pos_y+10, pos_z+67, block_id)
mc.setBlock(pos_x+68, pos_y+10, pos_z+67, block_id)
mc.setBlock(pos_x+69, pos_y+10, pos_z+67, block_id)
mc.setBlock(pos_x+70, pos_y+10, pos_z+67, block_id)
mc.setBlock(pos_x+71, pos_y+10, pos_z+67, block_id)
mc.setBlock(pos_x+72, pos_y+10, pos_z+67, block_id)
mc.setBlock(pos_x+73, pos_y+10, pos_z+67, block_id)
mc.setBlock(pos_x+74, pos_y+10, pos_z+67, block_id)
mc.setBlock(pos_x+75, pos_y+10, pos_z+67, block_id)
mc.setBlock(pos_x+76, pos_y+10, pos_z+67, block_id)
mc.setBlock(pos_x+77, pos_y+10, pos_z+67, block_id)
mc.setBlock(pos_x+78, pos_y+10, pos_z+67, block_id)
mc.setBlock(pos_x+79, pos_y+10, pos_z+67, block_id)
mc.setBlock(pos_x+80, pos_y+10, pos_z+67, block_id)
mc.setBlock(pos_x+81, pos_y+10, pos_z+67, block_id)
mc.setBlock(pos_x+82, pos_y+10, pos_z+67, block_id)
mc.setBlock(pos_x+83, pos_y+10, pos_z+67, block_id)
mc.setBlock(pos_x+84, pos_y+10, pos_z+67, block_id)
mc.setBlock(pos_x+85, pos_y+10, pos_z+67, block_id)
mc.setBlock(pos_x+86, pos_y+10, pos_z+67, block_id)
mc.setBlock(pos_x+4, pos_y+9, pos_z+65, block_id)
mc.setBlock(pos_x+94, pos_y+8, pos_z+65, block_id)
mc.setBlock(pos_x+93, pos_y+8, pos_z+65, block_id)
mc.setBlock(pos_x+92, pos_y+8, pos_z+65, block_id)
mc.setBlock(pos_x+91, pos_y+8, pos_z+65, block_id)
mc.setBlock(pos_x+90, pos_y+8, pos_z+65, block_id)
mc.setBlock(pos_x+89, pos_y+8, pos_z+65, block_id)
mc.setBlock(pos_x+88, pos_y+8, pos_z+65, block_id)
mc.setBlock(pos_x+87, pos_y+8, pos_z+65, block_id)
mc.setBlock(pos_x+87, pos_y+10, pos_z+67, block_id)
mc.setBlock(pos_x+88, pos_y+10, pos_z+67, block_id)
mc.setBlock(pos_x+89, pos_y+10, pos_z+67, block_id)
mc.setBlock(pos_x+90, pos_y+10, pos_z+67, block_id)
mc.setBlock(pos_x+91, pos_y+10, pos_z+67, block_id)
mc.setBlock(pos_x+92, pos_y+10, pos_z+67, block_id)
mc.setBlock(pos_x+93, pos_y+10, pos_z+67, block_id)
mc.setBlock(pos_x+38, pos_y+11, pos_z+67, block_id)
mc.setBlock(pos_x+61, pos_y+11, pos_z+67, block_id)
mc.setBlock(pos_x+38, pos_y+12, pos_z+67, block_id)
mc.setBlock(pos_x+61, pos_y+12, pos_z+67, block_id)
mc.setBlock(pos_x+39, pos_y+13, pos_z+67, block_id)
mc.setBlock(pos_x+60, pos_y+13, pos_z+67, block_id)
mc.setBlock(pos_x+39, pos_y+14, pos_z+67, block_id)
mc.setBlock(pos_x+59, pos_y+14, pos_z+67, block_id)
mc.setBlock(pos_x+40, pos_y+15, pos_z+67, block_id)
mc.setBlock(pos_x+59, pos_y+15, pos_z+67, block_id)
mc.setBlock(pos_x+41, pos_y+16, pos_z+67, block_id)
mc.setBlock(pos_x+42, pos_y+16, pos_z+67, block_id)
mc.setBlock(pos_x+57, pos_y+16, pos_z+67, block_id)
mc.setBlock(pos_x+58, pos_y+16, pos_z+67, block_id)
mc.setBlock(pos_x+43, pos_y+17, pos_z+67, block_id)
mc.setBlock(pos_x+56, pos_y+17, pos_z+67, block_id)
mc.setBlock(pos_x+44, pos_y+18, pos_z+67, block_id)
mc.setBlock(pos_x+45, pos_y+18, pos_z+67, block_id)
mc.setBlock(pos_x+46, pos_y+18, pos_z+67, block_id)
mc.setBlock(pos_x+53, pos_y+18, pos_z+67, block_id)
mc.setBlock(pos_x+54, pos_y+18, pos_z+67, block_id)
mc.setBlock(pos_x+55, pos_y+18, pos_z+67, block_id)
mc.setBlock(pos_x+47, pos_y+19, pos_z+67, block_id)
mc.setBlock(pos_x+48, pos_y+19, pos_z+67, block_id)
mc.setBlock(pos_x+49, pos_y+19, pos_z+67, block_id)
mc.setBlock(pos_x+50, pos_y+19, pos_z+67, block_id)
mc.setBlock(pos_x+51, pos_y+19, pos_z+67, block_id)
mc.setBlock(pos_x+52, pos_y+19, pos_z+67, block_id)
mc.setBlock(pos_x+45, pos_y+0, pos_z+68, block_id)
mc.setBlock(pos_x+46, pos_y+0, pos_z+68, block_id)
mc.setBlock(pos_x+47, pos_y+0, pos_z+68, block_id)
mc.setBlock(pos_x+12, pos_y+8, pos_z+65, block_id)
mc.setBlock(pos_x+11, pos_y+8, pos_z+65, block_id)
mc.setBlock(pos_x+10, pos_y+8, pos_z+65, block_id)
mc.setBlock(pos_x+9, pos_y+8, pos_z+65, block_id)
mc.setBlock(pos_x+8, pos_y+8, pos_z+65, block_id)
mc.setBlock(pos_x+7, pos_y+8, pos_z+65, block_id)
mc.setBlock(pos_x+6, pos_y+8, pos_z+65, block_id)
mc.setBlock(pos_x+5, pos_y+8, pos_z+65, block_id)
mc.setBlock(pos_x+86, pos_y+7, pos_z+65, block_id)
mc.setBlock(pos_x+85, pos_y+7, pos_z+65, block_id)
mc.setBlock(pos_x+84, pos_y+7, pos_z+65, block_id)
mc.setBlock(pos_x+83, pos_y+7, pos_z+65, block_id)
mc.setBlock(pos_x+82, pos_y+7, pos_z+65, block_id)
mc.setBlock(pos_x+81, pos_y+7, pos_z+65, block_id)
mc.setBlock(pos_x+80, pos_y+7, pos_z+65, block_id)
mc.setBlock(pos_x+79, pos_y+7, pos_z+65, block_id)
mc.setBlock(pos_x+78, pos_y+7, pos_z+65, block_id)
mc.setBlock(pos_x+77, pos_y+7, pos_z+65, block_id)
mc.setBlock(pos_x+76, pos_y+7, pos_z+65, block_id)
mc.setBlock(pos_x+75, pos_y+7, pos_z+65, block_id)
mc.setBlock(pos_x+74, pos_y+7, pos_z+65, block_id)
mc.setBlock(pos_x+73, pos_y+7, pos_z+65, block_id)
mc.setBlock(pos_x+72, pos_y+7, pos_z+65, block_id)
mc.setBlock(pos_x+71, pos_y+7, pos_z+65, block_id)
mc.setBlock(pos_x+70, pos_y+7, pos_z+65, block_id)
mc.setBlock(pos_x+69, pos_y+7, pos_z+65, block_id)
mc.setBlock(pos_x+68, pos_y+7, pos_z+65, block_id)
mc.setBlock(pos_x+67, pos_y+7, pos_z+65, block_id)
mc.setBlock(pos_x+66, pos_y+7, pos_z+65, block_id)
mc.setBlock(pos_x+65, pos_y+7, pos_z+65, block_id)
mc.setBlock(pos_x+64, pos_y+7, pos_z+65, block_id)
mc.setBlock(pos_x+63, pos_y+7, pos_z+65, block_id)
mc.setBlock(pos_x+62, pos_y+7, pos_z+65, block_id)
mc.setBlock(pos_x+48, pos_y+0, pos_z+68, block_id)
mc.setBlock(pos_x+49, pos_y+0, pos_z+68, block_id)
mc.setBlock(pos_x+50, pos_y+0, pos_z+68, block_id)
mc.setBlock(pos_x+51, pos_y+0, pos_z+68, block_id)
mc.setBlock(pos_x+52, pos_y+0, pos_z+68, block_id)
mc.setBlock(pos_x+53, pos_y+0, pos_z+68, block_id)
mc.setBlock(pos_x+54, pos_y+0, pos_z+68, block_id)
mc.setBlock(pos_x+43, pos_y+1, pos_z+68, block_id)
mc.setBlock(pos_x+44, pos_y+1, pos_z+68, block_id)
mc.setBlock(pos_x+55, pos_y+1, pos_z+68, block_id)
mc.setBlock(pos_x+56, pos_y+1, pos_z+68, block_id)
mc.setBlock(pos_x+41, pos_y+2, pos_z+68, block_id)
mc.setBlock(pos_x+42, pos_y+2, pos_z+68, block_id)
mc.setBlock(pos_x+57, pos_y+2, pos_z+68, block_id)
mc.setBlock(pos_x+37, pos_y+7, pos_z+65, block_id)
mc.setBlock(pos_x+36, pos_y+7, pos_z+65, block_id)
mc.setBlock(pos_x+35, pos_y+7, pos_z+65, block_id)
mc.setBlock(pos_x+34, pos_y+7, pos_z+65, block_id)
mc.setBlock(pos_x+33, pos_y+7, pos_z+65, block_id)
mc.setBlock(pos_x+32, pos_y+7, pos_z+65, block_id)
mc.setBlock(pos_x+31, pos_y+7, pos_z+65, block_id)
mc.setBlock(pos_x+30, pos_y+7, pos_z+65, block_id)
mc.setBlock(pos_x+29, pos_y+7, pos_z+65, block_id)
mc.setBlock(pos_x+28, pos_y+7, pos_z+65, block_id)
mc.setBlock(pos_x+27, pos_y+7, pos_z+65, block_id)
mc.setBlock(pos_x+26, pos_y+7, pos_z+65, block_id)
mc.setBlock(pos_x+25, pos_y+7, pos_z+65, block_id)
mc.setBlock(pos_x+24, pos_y+7, pos_z+65, block_id)
mc.setBlock(pos_x+23, pos_y+7, pos_z+65, block_id)
mc.setBlock(pos_x+22, pos_y+7, pos_z+65, block_id)
mc.setBlock(pos_x+21, pos_y+7, pos_z+65, block_id)
mc.setBlock(pos_x+20, pos_y+7, pos_z+65, block_id)
mc.setBlock(pos_x+19, pos_y+7, pos_z+65, block_id)
mc.setBlock(pos_x+18, pos_y+7, pos_z+65, block_id)
mc.setBlock(pos_x+17, pos_y+7, pos_z+65, block_id)
mc.setBlock(pos_x+16, pos_y+7, pos_z+65, block_id)
mc.setBlock(pos_x+15, pos_y+7, pos_z+65, block_id)
mc.setBlock(pos_x+14, pos_y+7, pos_z+65, block_id)
mc.setBlock(pos_x+13, pos_y+7, pos_z+65, block_id)
mc.setBlock(pos_x+61, pos_y+6, pos_z+65, block_id)
mc.setBlock(pos_x+58, pos_y+2, pos_z+68, block_id)
mc.setBlock(pos_x+40, pos_y+3, pos_z+68, block_id)
mc.setBlock(pos_x+59, pos_y+3, pos_z+68, block_id)
mc.setBlock(pos_x+39, pos_y+4, pos_z+68, block_id)
mc.setBlock(pos_x+60, pos_y+4, pos_z+68, block_id)
mc.setBlock(pos_x+39, pos_y+5, pos_z+68, block_id)
mc.setBlock(pos_x+60, pos_y+5, pos_z+68, block_id)
mc.setBlock(pos_x+38, pos_y+6, pos_z+68, block_id)
mc.setBlock(pos_x+38, pos_y+6, pos_z+65, block_id)
mc.setBlock(pos_x+60, pos_y+5, pos_z+65, block_id)
mc.setBlock(pos_x+61, pos_y+6, pos_z+68, block_id)
mc.setBlock(pos_x+23, pos_y+7, pos_z+68, block_id)
mc.setBlock(pos_x+24, pos_y+7, pos_z+68, block_id)
mc.setBlock(pos_x+25, pos_y+7, pos_z+68, block_id)
mc.setBlock(pos_x+26, pos_y+7, pos_z+68, block_id)
mc.setBlock(pos_x+27, pos_y+7, pos_z+68, block_id)
mc.setBlock(pos_x+28, pos_y+7, pos_z+68, block_id)
mc.setBlock(pos_x+29, pos_y+7, pos_z+68, block_id)
mc.setBlock(pos_x+39, pos_y+5, pos_z+65, block_id)
mc.setBlock(pos_x+60, pos_y+4, pos_z+65, block_id)
mc.setBlock(pos_x+30, pos_y+7, pos_z+68, block_id)
mc.setBlock(pos_x+31, pos_y+7, pos_z+68, block_id)
mc.setBlock(pos_x+32, pos_y+7, pos_z+68, block_id)
mc.setBlock(pos_x+33, pos_y+7, pos_z+68, block_id)
mc.setBlock(pos_x+34, pos_y+7, pos_z+68, block_id)
mc.setBlock(pos_x+35, pos_y+7, pos_z+68, block_id)
mc.setBlock(pos_x+39, pos_y+4, pos_z+65, block_id)
mc.setBlock(pos_x+59, pos_y+3, pos_z+65, block_id)
mc.setBlock(pos_x+36, pos_y+7, pos_z+68, block_id)
mc.setBlock(pos_x+37, pos_y+7, pos_z+68, block_id)
mc.setBlock(pos_x+62, pos_y+7, pos_z+68, block_id)
mc.setBlock(pos_x+63, pos_y+7, pos_z+68, block_id)
mc.setBlock(pos_x+64, pos_y+7, pos_z+68, block_id)
mc.setBlock(pos_x+65, pos_y+7, pos_z+68, block_id)
mc.setBlock(pos_x+66, pos_y+7, pos_z+68, block_id)
mc.setBlock(pos_x+67, pos_y+7, pos_z+68, block_id)
mc.setBlock(pos_x+40, pos_y+3, pos_z+65, block_id)
mc.setBlock(pos_x+58, pos_y+2, pos_z+65, block_id)
mc.setBlock(pos_x+57, pos_y+2, pos_z+65, block_id)
mc.setBlock(pos_x+68, pos_y+7, pos_z+68, block_id)
mc.setBlock(pos_x+42, pos_y+2, pos_z+65, block_id)
mc.setBlock(pos_x+41, pos_y+2, pos_z+65, block_id)
mc.setBlock(pos_x+56, pos_y+1, pos_z+65, block_id)
mc.setBlock(pos_x+55, pos_y+1, pos_z+65, block_id)
mc.setBlock(pos_x+69, pos_y+7, pos_z+68, block_id)
mc.setBlock(pos_x+70, pos_y+7, pos_z+68, block_id)
mc.setBlock(pos_x+44, pos_y+1, pos_z+65, block_id)
mc.setBlock(pos_x+43, pos_y+1, pos_z+65, block_id)
mc.setBlock(pos_x+54, pos_y+0, pos_z+65, block_id)
mc.setBlock(pos_x+53, pos_y+0, pos_z+65, block_id)
mc.setBlock(pos_x+52, pos_y+0, pos_z+65, block_id)
mc.setBlock(pos_x+51, pos_y+0, pos_z+65, block_id)
mc.setBlock(pos_x+50, pos_y+0, pos_z+65, block_id)
mc.setBlock(pos_x+49, pos_y+0, pos_z+65, block_id)
mc.setBlock(pos_x+48, pos_y+0, pos_z+65, block_id)
mc.setBlock(pos_x+47, pos_y+0, pos_z+65, block_id)
mc.setBlock(pos_x+46, pos_y+0, pos_z+65, block_id)
mc.setBlock(pos_x+45, pos_y+0, pos_z+65, block_id)
mc.setBlock(pos_x+52, pos_y+19, pos_z+64, block_id)
mc.setBlock(pos_x+51, pos_y+19, pos_z+64, block_id)
mc.setBlock(pos_x+50, pos_y+19, pos_z+64, block_id)
mc.setBlock(pos_x+49, pos_y+19, pos_z+64, block_id)
mc.setBlock(pos_x+48, pos_y+19, pos_z+64, block_id)
mc.setBlock(pos_x+47, pos_y+19, pos_z+64, block_id)
mc.setBlock(pos_x+55, pos_y+18, pos_z+64, block_id)
mc.setBlock(pos_x+54, pos_y+18, pos_z+64, block_id)
mc.setBlock(pos_x+53, pos_y+18, pos_z+64, block_id)
mc.setBlock(pos_x+71, pos_y+7, pos_z+68, block_id)
mc.setBlock(pos_x+72, pos_y+7, pos_z+68, block_id)
mc.setBlock(pos_x+73, pos_y+7, pos_z+68, block_id)
mc.setBlock(pos_x+74, pos_y+7, pos_z+68, block_id)
mc.setBlock(pos_x+46, pos_y+18, pos_z+64, block_id)
mc.setBlock(pos_x+45, pos_y+18, pos_z+64, block_id)
mc.setBlock(pos_x+44, pos_y+18, pos_z+64, block_id)
mc.setBlock(pos_x+57, pos_y+17, pos_z+64, block_id)
mc.setBlock(pos_x+56, pos_y+17, pos_z+64, block_id)
mc.setBlock(pos_x+75, pos_y+7, pos_z+68, block_id)
mc.setBlock(pos_x+76, pos_y+7, pos_z+68, block_id)
mc.setBlock(pos_x+43, pos_y+17, pos_z+64, block_id)
mc.setBlock(pos_x+42, pos_y+17, pos_z+64, block_id)
mc.setBlock(pos_x+58, pos_y+16, pos_z+64, block_id)
mc.setBlock(pos_x+0, pos_y+8, pos_z+68, block_id)
mc.setBlock(pos_x+1, pos_y+8, pos_z+68, block_id)
mc.setBlock(pos_x+41, pos_y+16, pos_z+64, block_id)
mc.setBlock(pos_x+59, pos_y+15, pos_z+64, block_id)
mc.setBlock(pos_x+2, pos_y+8, pos_z+68, block_id)
mc.setBlock(pos_x+3, pos_y+8, pos_z+68, block_id)
mc.setBlock(pos_x+40, pos_y+15, pos_z+64, block_id)
mc.setBlock(pos_x+60, pos_y+14, pos_z+64, block_id)
mc.setBlock(pos_x+4, pos_y+8, pos_z+68, block_id)
mc.setBlock(pos_x+5, pos_y+8, pos_z+68, block_id)
mc.setBlock(pos_x+39, pos_y+14, pos_z+64, block_id)
mc.setBlock(pos_x+60, pos_y+13, pos_z+64, block_id)
mc.setBlock(pos_x+6, pos_y+8, pos_z+68, block_id)
mc.setBlock(pos_x+7, pos_y+8, pos_z+68, block_id)
mc.setBlock(pos_x+8, pos_y+8, pos_z+68, block_id)
mc.setBlock(pos_x+9, pos_y+8, pos_z+68, block_id)
mc.setBlock(pos_x+10, pos_y+8, pos_z+68, block_id)
mc.setBlock(pos_x+11, pos_y+8, pos_z+68, block_id)
mc.setBlock(pos_x+39, pos_y+13, pos_z+64, block_id)
mc.setBlock(pos_x+61, pos_y+12, pos_z+64, block_id)
mc.setBlock(pos_x+12, pos_y+8, pos_z+68, block_id)
mc.setBlock(pos_x+13, pos_y+8, pos_z+68, block_id)
mc.setBlock(pos_x+14, pos_y+8, pos_z+68, block_id)
mc.setBlock(pos_x+15, pos_y+8, pos_z+68, block_id)
mc.setBlock(pos_x+16, pos_y+8, pos_z+68, block_id)
mc.setBlock(pos_x+17, pos_y+8, pos_z+68, block_id)
mc.setBlock(pos_x+38, pos_y+12, pos_z+64, block_id)
mc.setBlock(pos_x+61, pos_y+11, pos_z+64, block_id)
mc.setBlock(pos_x+18, pos_y+8, pos_z+68, block_id)
mc.setBlock(pos_x+19, pos_y+8, pos_z+68, block_id)
mc.setBlock(pos_x+20, pos_y+8, pos_z+68, block_id)
mc.setBlock(pos_x+21, pos_y+8, pos_z+68, block_id)
mc.setBlock(pos_x+22, pos_y+8, pos_z+68, block_id)
mc.setBlock(pos_x+77, pos_y+8, pos_z+68, block_id)
mc.setBlock(pos_x+78, pos_y+8, pos_z+68, block_id)
mc.setBlock(pos_x+79, pos_y+8, pos_z+68, block_id)
mc.setBlock(pos_x+38, pos_y+11, pos_z+64, block_id)
mc.setBlock(pos_x+93, pos_y+10, pos_z+64, block_id)
mc.setBlock(pos_x+92, pos_y+10, pos_z+64, block_id)
mc.setBlock(pos_x+91, pos_y+10, pos_z+64, block_id)
mc.setBlock(pos_x+90, pos_y+10, pos_z+64, block_id)
mc.setBlock(pos_x+89, pos_y+10, pos_z+64, block_id)
mc.setBlock(pos_x+88, pos_y+10, pos_z+64, block_id)
mc.setBlock(pos_x+87, pos_y+10, pos_z+64, block_id)
mc.setBlock(pos_x+86, pos_y+10, pos_z+64, block_id)
mc.setBlock(pos_x+85, pos_y+10, pos_z+64, block_id)
mc.setBlock(pos_x+84, pos_y+10, pos_z+64, block_id)
mc.setBlock(pos_x+83, pos_y+10, pos_z+64, block_id)
mc.setBlock(pos_x+82, pos_y+10, pos_z+64, block_id)
mc.setBlock(pos_x+81, pos_y+10, pos_z+64, block_id)
mc.setBlock(pos_x+80, pos_y+10, pos_z+64, block_id)
mc.setBlock(pos_x+79, pos_y+10, pos_z+64, block_id)
mc.setBlock(pos_x+78, pos_y+10, pos_z+64, block_id)
mc.setBlock(pos_x+77, pos_y+10, pos_z+64, block_id)
mc.setBlock(pos_x+76, pos_y+10, pos_z+64, block_id)
mc.setBlock(pos_x+75, pos_y+10, pos_z+64, block_id)
mc.setBlock(pos_x+74, pos_y+10, pos_z+64, block_id)
mc.setBlock(pos_x+73, pos_y+10, pos_z+64, block_id)
mc.setBlock(pos_x+72, pos_y+10, pos_z+64, block_id)
mc.setBlock(pos_x+71, pos_y+10, pos_z+64, block_id)
mc.setBlock(pos_x+70, pos_y+10, pos_z+64, block_id)
mc.setBlock(pos_x+69, pos_y+10, pos_z+64, block_id)
mc.setBlock(pos_x+68, pos_y+10, pos_z+64, block_id)
mc.setBlock(pos_x+67, pos_y+10, pos_z+64, block_id)
mc.setBlock(pos_x+66, pos_y+10, pos_z+64, block_id)
mc.setBlock(pos_x+65, pos_y+10, pos_z+64, block_id)
mc.setBlock(pos_x+64, pos_y+10, pos_z+64, block_id)
mc.setBlock(pos_x+63, pos_y+10, pos_z+64, block_id)
mc.setBlock(pos_x+62, pos_y+10, pos_z+64, block_id)
mc.setBlock(pos_x+80, pos_y+8, pos_z+68, block_id)
mc.setBlock(pos_x+81, pos_y+8, pos_z+68, block_id)
mc.setBlock(pos_x+82, pos_y+8, pos_z+68, block_id)
mc.setBlock(pos_x+83, pos_y+8, pos_z+68, block_id)
mc.setBlock(pos_x+84, pos_y+8, pos_z+68, block_id)
mc.setBlock(pos_x+85, pos_y+8, pos_z+68, block_id)
mc.setBlock(pos_x+86, pos_y+8, pos_z+68, block_id)
mc.setBlock(pos_x+87, pos_y+8, pos_z+68, block_id)
mc.setBlock(pos_x+37, pos_y+10, pos_z+64, block_id)
mc.setBlock(pos_x+36, pos_y+10, pos_z+64, block_id)
mc.setBlock(pos_x+35, pos_y+10, pos_z+64, block_id)
mc.setBlock(pos_x+34, pos_y+10, pos_z+64, block_id)
mc.setBlock(pos_x+33, pos_y+10, pos_z+64, block_id)
mc.setBlock(pos_x+32, pos_y+10, pos_z+64, block_id)
mc.setBlock(pos_x+31, pos_y+10, pos_z+64, block_id)
mc.setBlock(pos_x+30, pos_y+10, pos_z+64, block_id)
mc.setBlock(pos_x+29, pos_y+10, pos_z+64, block_id)
mc.setBlock(pos_x+28, pos_y+10, pos_z+64, block_id)
mc.setBlock(pos_x+27, pos_y+10, pos_z+64, block_id)
mc.setBlock(pos_x+26, pos_y+10, pos_z+64, block_id)
mc.setBlock(pos_x+25, pos_y+10, pos_z+64, block_id)
mc.setBlock(pos_x+24, pos_y+10, pos_z+64, block_id)
mc.setBlock(pos_x+23, pos_y+10, pos_z+64, block_id)
mc.setBlock(pos_x+22, pos_y+10, pos_z+64, block_id)
mc.setBlock(pos_x+21, pos_y+10, pos_z+64, block_id)
mc.setBlock(pos_x+20, pos_y+10, pos_z+64, block_id)
mc.setBlock(pos_x+19, pos_y+10, pos_z+64, block_id)
mc.setBlock(pos_x+18, pos_y+10, pos_z+64, block_id)
mc.setBlock(pos_x+17, pos_y+10, pos_z+64, block_id)
mc.setBlock(pos_x+16, pos_y+10, pos_z+64, block_id)
mc.setBlock(pos_x+15, pos_y+10, pos_z+64, block_id)
mc.setBlock(pos_x+14, pos_y+10, pos_z+64, block_id)
mc.setBlock(pos_x+13, pos_y+10, pos_z+64, block_id)
mc.setBlock(pos_x+12, pos_y+10, pos_z+64, block_id)
mc.setBlock(pos_x+11, pos_y+10, pos_z+64, block_id)
mc.setBlock(pos_x+10, pos_y+10, pos_z+64, block_id)
mc.setBlock(pos_x+9, pos_y+10, pos_z+64, block_id)
mc.setBlock(pos_x+8, pos_y+10, pos_z+64, block_id)
mc.setBlock(pos_x+7, pos_y+10, pos_z+64, block_id)
mc.setBlock(pos_x+6, pos_y+10, pos_z+64, block_id)
mc.setBlock(pos_x+98, pos_y+9, pos_z+64, block_id)
mc.setBlock(pos_x+97, pos_y+9, pos_z+64, block_id)
mc.setBlock(pos_x+96, pos_y+9, pos_z+64, block_id)
mc.setBlock(pos_x+95, pos_y+9, pos_z+64, block_id)
mc.setBlock(pos_x+94, pos_y+9, pos_z+64, block_id)
mc.setBlock(pos_x+88, pos_y+8, pos_z+68, block_id)
mc.setBlock(pos_x+89, pos_y+8, pos_z+68, block_id)
mc.setBlock(pos_x+90, pos_y+8, pos_z+68, block_id)
mc.setBlock(pos_x+91, pos_y+8, pos_z+68, block_id)
mc.setBlock(pos_x+92, pos_y+8, pos_z+68, block_id)
mc.setBlock(pos_x+93, pos_y+8, pos_z+68, block_id)
mc.setBlock(pos_x+94, pos_y+8, pos_z+68, block_id)
mc.setBlock(pos_x+95, pos_y+8, pos_z+68, block_id)
mc.setBlock(pos_x+96, pos_y+8, pos_z+68, block_id)
mc.setBlock(pos_x+97, pos_y+8, pos_z+68, block_id)
mc.setBlock(pos_x+98, pos_y+8, pos_z+68, block_id)
mc.setBlock(pos_x+99, pos_y+8, pos_z+68, block_id)
mc.setBlock(pos_x+0, pos_y+9, pos_z+68, block_id)
mc.setBlock(pos_x+1, pos_y+9, pos_z+68, block_id)
mc.setBlock(pos_x+2, pos_y+9, pos_z+68, block_id)
mc.setBlock(pos_x+3, pos_y+9, pos_z+68, block_id)
mc.setBlock(pos_x+4, pos_y+9, pos_z+68, block_id)
mc.setBlock(pos_x+95, pos_y+9, pos_z+68, block_id)
mc.setBlock(pos_x+96, pos_y+9, pos_z+68, block_id)
mc.setBlock(pos_x+97, pos_y+9, pos_z+68, block_id)
mc.setBlock(pos_x+98, pos_y+9, pos_z+68, block_id)
mc.setBlock(pos_x+99, pos_y+9, pos_z+68, block_id)
mc.setBlock(pos_x+5, pos_y+10, pos_z+68, block_id)
mc.setBlock(pos_x+6, pos_y+10, pos_z+68, block_id)
mc.setBlock(pos_x+7, pos_y+10, pos_z+68, block_id)
mc.setBlock(pos_x+8, pos_y+10, pos_z+68, block_id)
mc.setBlock(pos_x+9, pos_y+10, pos_z+68, block_id)
mc.setBlock(pos_x+10, pos_y+10, pos_z+68, block_id)
mc.setBlock(pos_x+11, pos_y+10, pos_z+68, block_id)
mc.setBlock(pos_x+12, pos_y+10, pos_z+68, block_id)
mc.setBlock(pos_x+13, pos_y+10, pos_z+68, block_id)
mc.setBlock(pos_x+14, pos_y+10, pos_z+68, block_id)
mc.setBlock(pos_x+15, pos_y+10, pos_z+68, block_id)
mc.setBlock(pos_x+5, pos_y+9, pos_z+64, block_id)
mc.setBlock(pos_x+4, pos_y+9, pos_z+64, block_id)
mc.setBlock(pos_x+3, pos_y+9, pos_z+64, block_id)
mc.setBlock(pos_x+2, pos_y+9, pos_z+64, block_id)
mc.setBlock(pos_x+1, pos_y+9, pos_z+64, block_id)
mc.setBlock(pos_x+0, pos_y+9, pos_z+64, block_id)
mc.setBlock(pos_x+97, pos_y+8, pos_z+64, block_id)
mc.setBlock(pos_x+96, pos_y+8, pos_z+64, block_id)
mc.setBlock(pos_x+95, pos_y+8, pos_z+64, block_id)
mc.setBlock(pos_x+94, pos_y+8, pos_z+64, block_id)
mc.setBlock(pos_x+93, pos_y+8, pos_z+64, block_id)
mc.setBlock(pos_x+92, pos_y+8, pos_z+64, block_id)
mc.setBlock(pos_x+91, pos_y+8, pos_z+64, block_id)
mc.setBlock(pos_x+90, pos_y+8, pos_z+64, block_id)
mc.setBlock(pos_x+89, pos_y+8, pos_z+64, block_id)
mc.setBlock(pos_x+88, pos_y+8, pos_z+64, block_id)
mc.setBlock(pos_x+87, pos_y+8, pos_z+64, block_id)
mc.setBlock(pos_x+16, pos_y+10, pos_z+68, block_id)
mc.setBlock(pos_x+17, pos_y+10, pos_z+68, block_id)
mc.setBlock(pos_x+18, pos_y+10, pos_z+68, block_id)
mc.setBlock(pos_x+19, pos_y+10, pos_z+68, block_id)
mc.setBlock(pos_x+20, pos_y+10, pos_z+68, block_id)
mc.setBlock(pos_x+21, pos_y+10, pos_z+68, block_id)
mc.setBlock(pos_x+22, pos_y+10, pos_z+68, block_id)
mc.setBlock(pos_x+23, pos_y+10, pos_z+68, block_id)
mc.setBlock(pos_x+24, pos_y+10, pos_z+68, block_id)
mc.setBlock(pos_x+25, pos_y+10, pos_z+68, block_id)
mc.setBlock(pos_x+26, pos_y+10, pos_z+68, block_id)
mc.setBlock(pos_x+27, pos_y+10, pos_z+68, block_id)
mc.setBlock(pos_x+28, pos_y+10, pos_z+68, block_id)
mc.setBlock(pos_x+29, pos_y+10, pos_z+68, block_id)
mc.setBlock(pos_x+30, pos_y+10, pos_z+68, block_id)
mc.setBlock(pos_x+31, pos_y+10, pos_z+68, block_id)
mc.setBlock(pos_x+32, pos_y+10, pos_z+68, block_id)
mc.setBlock(pos_x+33, pos_y+10, pos_z+68, block_id)
mc.setBlock(pos_x+34, pos_y+10, pos_z+68, block_id)
mc.setBlock(pos_x+35, pos_y+10, pos_z+68, block_id)
mc.setBlock(pos_x+36, pos_y+10, pos_z+68, block_id)
mc.setBlock(pos_x+37, pos_y+10, pos_z+68, block_id)
mc.setBlock(pos_x+62, pos_y+10, pos_z+68, block_id)
mc.setBlock(pos_x+63, pos_y+10, pos_z+68, block_id)
mc.setBlock(pos_x+64, pos_y+10, pos_z+68, block_id)
mc.setBlock(pos_x+65, pos_y+10, pos_z+68, block_id)
mc.setBlock(pos_x+66, pos_y+10, pos_z+68, block_id)
mc.setBlock(pos_x+67, pos_y+10, pos_z+68, block_id)
mc.setBlock(pos_x+68, pos_y+10, pos_z+68, block_id)
mc.setBlock(pos_x+69, pos_y+10, pos_z+68, block_id)
mc.setBlock(pos_x+70, pos_y+10, pos_z+68, block_id)
mc.setBlock(pos_x+71, pos_y+10, pos_z+68, block_id)
mc.setBlock(pos_x+72, pos_y+10, pos_z+68, block_id)
mc.setBlock(pos_x+73, pos_y+10, pos_z+68, block_id)
mc.setBlock(pos_x+74, pos_y+10, pos_z+68, block_id)
mc.setBlock(pos_x+75, pos_y+10, pos_z+68, block_id)
mc.setBlock(pos_x+76, pos_y+10, pos_z+68, block_id)
mc.setBlock(pos_x+77, pos_y+10, pos_z+68, block_id)
mc.setBlock(pos_x+78, pos_y+10, pos_z+68, block_id)
mc.setBlock(pos_x+12, pos_y+8, pos_z+64, block_id)
mc.setBlock(pos_x+11, pos_y+8, pos_z+64, block_id)
mc.setBlock(pos_x+10, pos_y+8, pos_z+64, block_id)
mc.setBlock(pos_x+9, pos_y+8, pos_z+64, block_id)
mc.setBlock(pos_x+8, pos_y+8, pos_z+64, block_id)
mc.setBlock(pos_x+7, pos_y+8, pos_z+64, block_id)
mc.setBlock(pos_x+6, pos_y+8, pos_z+64, block_id)
mc.setBlock(pos_x+5, pos_y+8, pos_z+64, block_id)
mc.setBlock(pos_x+4, pos_y+8, pos_z+64, block_id)
mc.setBlock(pos_x+3, pos_y+8, pos_z+64, block_id)
mc.setBlock(pos_x+2, pos_y+8, pos_z+64, block_id)
mc.setBlock(pos_x+1, pos_y+8, pos_z+64, block_id)
mc.setBlock(pos_x+86, pos_y+7, pos_z+64, block_id)
mc.setBlock(pos_x+85, pos_y+7, pos_z+64, block_id)
mc.setBlock(pos_x+84, pos_y+7, pos_z+64, block_id)
mc.setBlock(pos_x+83, pos_y+7, pos_z+64, block_id)
mc.setBlock(pos_x+82, pos_y+7, pos_z+64, block_id)
mc.setBlock(pos_x+81, pos_y+7, pos_z+64, block_id)
mc.setBlock(pos_x+80, pos_y+7, pos_z+64, block_id)
mc.setBlock(pos_x+79, pos_y+7, pos_z+64, block_id)
mc.setBlock(pos_x+78, pos_y+7, pos_z+64, block_id)
mc.setBlock(pos_x+77, pos_y+7, pos_z+64, block_id)
mc.setBlock(pos_x+76, pos_y+7, pos_z+64, block_id)
mc.setBlock(pos_x+75, pos_y+7, pos_z+64, block_id)
mc.setBlock(pos_x+74, pos_y+7, pos_z+64, block_id)
mc.setBlock(pos_x+73, pos_y+7, pos_z+64, block_id)
mc.setBlock(pos_x+72, pos_y+7, pos_z+64, block_id)
mc.setBlock(pos_x+71, pos_y+7, pos_z+64, block_id)
mc.setBlock(pos_x+70, pos_y+7, pos_z+64, block_id)
mc.setBlock(pos_x+69, pos_y+7, pos_z+64, block_id)
mc.setBlock(pos_x+68, pos_y+7, pos_z+64, block_id)
mc.setBlock(pos_x+67, pos_y+7, pos_z+64, block_id)
mc.setBlock(pos_x+66, pos_y+7, pos_z+64, block_id)
mc.setBlock(pos_x+65, pos_y+7, pos_z+64, block_id)
mc.setBlock(pos_x+64, pos_y+7, pos_z+64, block_id)
mc.setBlock(pos_x+63, pos_y+7, pos_z+64, block_id)
mc.setBlock(pos_x+62, pos_y+7, pos_z+64, block_id)
mc.setBlock(pos_x+79, pos_y+10, pos_z+68, block_id)
mc.setBlock(pos_x+80, pos_y+10, pos_z+68, block_id)
mc.setBlock(pos_x+81, pos_y+10, pos_z+68, block_id)
mc.setBlock(pos_x+82, pos_y+10, pos_z+68, block_id)
mc.setBlock(pos_x+83, pos_y+10, pos_z+68, block_id)
mc.setBlock(pos_x+84, pos_y+10, pos_z+68, block_id)
mc.setBlock(pos_x+85, pos_y+10, pos_z+68, block_id)
mc.setBlock(pos_x+86, pos_y+10, pos_z+68, block_id)
mc.setBlock(pos_x+37, pos_y+7, pos_z+64, block_id)
mc.setBlock(pos_x+36, pos_y+7, pos_z+64, block_id)
mc.setBlock(pos_x+35, pos_y+7, pos_z+64, block_id)
mc.setBlock(pos_x+34, pos_y+7, pos_z+64, block_id)
mc.setBlock(pos_x+33, pos_y+7, pos_z+64, block_id)
mc.setBlock(pos_x+32, pos_y+7, pos_z+64, block_id)
mc.setBlock(pos_x+31, pos_y+7, pos_z+64, block_id)
mc.setBlock(pos_x+30, pos_y+7, pos_z+64, block_id)
mc.setBlock(pos_x+29, pos_y+7, pos_z+64, block_id)
mc.setBlock(pos_x+28, pos_y+7, pos_z+64, block_id)
mc.setBlock(pos_x+27, pos_y+7, pos_z+64, block_id)
mc.setBlock(pos_x+26, pos_y+7, pos_z+64, block_id)
mc.setBlock(pos_x+25, pos_y+7, pos_z+64, block_id)
mc.setBlock(pos_x+24, pos_y+7, pos_z+64, block_id)
mc.setBlock(pos_x+23, pos_y+7, pos_z+64, block_id)
mc.setBlock(pos_x+22, pos_y+7, pos_z+64, block_id)
mc.setBlock(pos_x+21, pos_y+7, pos_z+64, block_id)
mc.setBlock(pos_x+20, pos_y+7, pos_z+64, block_id)
mc.setBlock(pos_x+19, pos_y+7, pos_z+64, block_id)
mc.setBlock(pos_x+18, pos_y+7, pos_z+64, block_id)
mc.setBlock(pos_x+17, pos_y+7, pos_z+64, block_id)
mc.setBlock(pos_x+16, pos_y+7, pos_z+64, block_id)
mc.setBlock(pos_x+15, pos_y+7, pos_z+64, block_id)
mc.setBlock(pos_x+14, pos_y+7, pos_z+64, block_id)
mc.setBlock(pos_x+13, pos_y+7, pos_z+64, block_id)
mc.setBlock(pos_x+61, pos_y+6, pos_z+64, block_id)
mc.setBlock(pos_x+87, pos_y+10, pos_z+68, block_id)
mc.setBlock(pos_x+88, pos_y+10, pos_z+68, block_id)
mc.setBlock(pos_x+89, pos_y+10, pos_z+68, block_id)
mc.setBlock(pos_x+90, pos_y+10, pos_z+68, block_id)
mc.setBlock(pos_x+91, pos_y+10, pos_z+68, block_id)
mc.setBlock(pos_x+92, pos_y+10, pos_z+68, block_id)
mc.setBlock(pos_x+93, pos_y+10, pos_z+68, block_id)
mc.setBlock(pos_x+94, pos_y+10, pos_z+68, block_id)
mc.setBlock(pos_x+38, pos_y+6, pos_z+64, block_id)
mc.setBlock(pos_x+60, pos_y+5, pos_z+64, block_id)
mc.setBlock(pos_x+38, pos_y+11, pos_z+68, block_id)
mc.setBlock(pos_x+61, pos_y+11, pos_z+68, block_id)
mc.setBlock(pos_x+38, pos_y+12, pos_z+68, block_id)
mc.setBlock(pos_x+61, pos_y+12, pos_z+68, block_id)
mc.setBlock(pos_x+39, pos_y+13, pos_z+68, block_id)
mc.setBlock(pos_x+60, pos_y+13, pos_z+68, block_id)
mc.setBlock(pos_x+40, pos_y+14, pos_z+68, block_id)
mc.setBlock(pos_x+59, pos_y+14, pos_z+68, block_id)
mc.setBlock(pos_x+40, pos_y+15, pos_z+68, block_id)
mc.setBlock(pos_x+38, pos_y+5, pos_z+64, block_id)
mc.setBlock(pos_x+60, pos_y+4, pos_z+64, block_id)
mc.setBlock(pos_x+59, pos_y+15, pos_z+68, block_id)
mc.setBlock(pos_x+41, pos_y+16, pos_z+68, block_id)
mc.setBlock(pos_x+42, pos_y+16, pos_z+68, block_id)
mc.setBlock(pos_x+57, pos_y+16, pos_z+68, block_id)
mc.setBlock(pos_x+58, pos_y+16, pos_z+68, block_id)
mc.setBlock(pos_x+43, pos_y+17, pos_z+68, block_id)
mc.setBlock(pos_x+39, pos_y+4, pos_z+64, block_id)
mc.setBlock(pos_x+59, pos_y+3, pos_z+64, block_id)
mc.setBlock(pos_x+56, pos_y+17, pos_z+68, block_id)
mc.setBlock(pos_x+44, pos_y+18, pos_z+68, block_id)
mc.setBlock(pos_x+45, pos_y+18, pos_z+68, block_id)
mc.setBlock(pos_x+46, pos_y+18, pos_z+68, block_id)
mc.setBlock(pos_x+53, pos_y+18, pos_z+68, block_id)
mc.setBlock(pos_x+54, pos_y+18, pos_z+68, block_id)
mc.setBlock(pos_x+55, pos_y+18, pos_z+68, block_id)
mc.setBlock(pos_x+47, pos_y+19, pos_z+68, block_id)
mc.setBlock(pos_x+40, pos_y+3, pos_z+64, block_id)
mc.setBlock(pos_x+58, pos_y+2, pos_z+64, block_id)
mc.setBlock(pos_x+57, pos_y+2, pos_z+64, block_id)
mc.setBlock(pos_x+48, pos_y+19, pos_z+68, block_id)
mc.setBlock(pos_x+49, pos_y+19, pos_z+68, block_id)
mc.setBlock(pos_x+42, pos_y+2, pos_z+64, block_id)
mc.setBlock(pos_x+41, pos_y+2, pos_z+64, block_id)
mc.setBlock(pos_x+56, pos_y+1, pos_z+64, block_id)
mc.setBlock(pos_x+55, pos_y+1, pos_z+64, block_id)
mc.setBlock(pos_x+50, pos_y+19, pos_z+68, block_id)
mc.setBlock(pos_x+51, pos_y+19, pos_z+68, block_id)
mc.setBlock(pos_x+44, pos_y+1, pos_z+64, block_id)
mc.setBlock(pos_x+43, pos_y+1, pos_z+64, block_id)
mc.setBlock(pos_x+54, pos_y+0, pos_z+64, block_id)
mc.setBlock(pos_x+53, pos_y+0, pos_z+64, block_id)
mc.setBlock(pos_x+52, pos_y+0, pos_z+64, block_id)
mc.setBlock(pos_x+51, pos_y+0, pos_z+64, block_id)
mc.setBlock(pos_x+50, pos_y+0, pos_z+64, block_id)
mc.setBlock(pos_x+49, pos_y+0, pos_z+64, block_id)
mc.setBlock(pos_x+48, pos_y+0, pos_z+64, block_id)
mc.setBlock(pos_x+47, pos_y+0, pos_z+64, block_id)
mc.setBlock(pos_x+46, pos_y+0, pos_z+64, block_id)
mc.setBlock(pos_x+45, pos_y+0, pos_z+64, block_id)
mc.setBlock(pos_x+51, pos_y+19, pos_z+63, block_id)
mc.setBlock(pos_x+50, pos_y+19, pos_z+63, block_id)
mc.setBlock(pos_x+49, pos_y+19, pos_z+63, block_id)
mc.setBlock(pos_x+48, pos_y+19, pos_z+63, block_id)
mc.setBlock(pos_x+55, pos_y+18, pos_z+63, block_id)
mc.setBlock(pos_x+54, pos_y+18, pos_z+63, block_id)
mc.setBlock(pos_x+53, pos_y+18, pos_z+63, block_id)
mc.setBlock(pos_x+52, pos_y+18, pos_z+63, block_id)
mc.setBlock(pos_x+52, pos_y+19, pos_z+68, block_id)
mc.setBlock(pos_x+45, pos_y+0, pos_z+69, block_id)
mc.setBlock(pos_x+47, pos_y+18, pos_z+63, block_id)
mc.setBlock(pos_x+46, pos_y+18, pos_z+63, block_id)
mc.setBlock(pos_x+45, pos_y+18, pos_z+63, block_id)
mc.setBlock(pos_x+44, pos_y+18, pos_z+63, block_id)
mc.setBlock(pos_x+57, pos_y+17, pos_z+63, block_id)
mc.setBlock(pos_x+56, pos_y+17, pos_z+63, block_id)
mc.setBlock(pos_x+46, pos_y+0, pos_z+69, block_id)
mc.setBlock(pos_x+47, pos_y+0, pos_z+69, block_id)
mc.setBlock(pos_x+43, pos_y+17, pos_z+63, block_id)
mc.setBlock(pos_x+42, pos_y+17, pos_z+63, block_id)
mc.setBlock(pos_x+58, pos_y+16, pos_z+63, block_id)
mc.setBlock(pos_x+48, pos_y+0, pos_z+69, block_id)
mc.setBlock(pos_x+49, pos_y+0, pos_z+69, block_id)
mc.setBlock(pos_x+41, pos_y+16, pos_z+63, block_id)
mc.setBlock(pos_x+59, pos_y+15, pos_z+63, block_id)
mc.setBlock(pos_x+50, pos_y+0, pos_z+69, block_id)
mc.setBlock(pos_x+51, pos_y+0, pos_z+69, block_id)
mc.setBlock(pos_x+40, pos_y+15, pos_z+63, block_id)
mc.setBlock(pos_x+60, pos_y+14, pos_z+63, block_id)
mc.setBlock(pos_x+52, pos_y+0, pos_z+69, block_id)
mc.setBlock(pos_x+53, pos_y+0, pos_z+69, block_id)
mc.setBlock(pos_x+39, pos_y+14, pos_z+63, block_id)
mc.setBlock(pos_x+60, pos_y+13, pos_z+63, block_id)
mc.setBlock(pos_x+54, pos_y+0, pos_z+69, block_id)
mc.setBlock(pos_x+43, pos_y+1, pos_z+69, block_id)
mc.setBlock(pos_x+44, pos_y+1, pos_z+69, block_id)
mc.setBlock(pos_x+55, pos_y+1, pos_z+69, block_id)
mc.setBlock(pos_x+56, pos_y+1, pos_z+69, block_id)
mc.setBlock(pos_x+41, pos_y+2, pos_z+69, block_id)
mc.setBlock(pos_x+39, pos_y+13, pos_z+63, block_id)
mc.setBlock(pos_x+61, pos_y+12, pos_z+63, block_id)
mc.setBlock(pos_x+42, pos_y+2, pos_z+69, block_id)
mc.setBlock(pos_x+57, pos_y+2, pos_z+69, block_id)
mc.setBlock(pos_x+58, pos_y+2, pos_z+69, block_id)
mc.setBlock(pos_x+40, pos_y+3, pos_z+69, block_id)
mc.setBlock(pos_x+59, pos_y+3, pos_z+69, block_id)
mc.setBlock(pos_x+39, pos_y+4, pos_z+69, block_id)
mc.setBlock(pos_x+38, pos_y+12, pos_z+63, block_id)
mc.setBlock(pos_x+61, pos_y+11, pos_z+63, block_id)
mc.setBlock(pos_x+60, pos_y+4, pos_z+69, block_id)
mc.setBlock(pos_x+39, pos_y+5, pos_z+69, block_id)
mc.setBlock(pos_x+60, pos_y+5, pos_z+69, block_id)
mc.setBlock(pos_x+38, pos_y+6, pos_z+69, block_id)
mc.setBlock(pos_x+61, pos_y+6, pos_z+69, block_id)
mc.setBlock(pos_x+25, pos_y+7, pos_z+69, block_id)
mc.setBlock(pos_x+26, pos_y+7, pos_z+69, block_id)
mc.setBlock(pos_x+27, pos_y+7, pos_z+69, block_id)
mc.setBlock(pos_x+38, pos_y+11, pos_z+63, block_id)
mc.setBlock(pos_x+93, pos_y+10, pos_z+63, block_id)
mc.setBlock(pos_x+92, pos_y+10, pos_z+63, block_id)
mc.setBlock(pos_x+91, pos_y+10, pos_z+63, block_id)
mc.setBlock(pos_x+90, pos_y+10, pos_z+63, block_id)
mc.setBlock(pos_x+89, pos_y+10, pos_z+63, block_id)
mc.setBlock(pos_x+88, pos_y+10, pos_z+63, block_id)
mc.setBlock(pos_x+87, pos_y+10, pos_z+63, block_id)
mc.setBlock(pos_x+86, pos_y+10, pos_z+63, block_id)
mc.setBlock(pos_x+85, pos_y+10, pos_z+63, block_id)
mc.setBlock(pos_x+84, pos_y+10, pos_z+63, block_id)
mc.setBlock(pos_x+83, pos_y+10, pos_z+63, block_id)
mc.setBlock(pos_x+82, pos_y+10, pos_z+63, block_id)
mc.setBlock(pos_x+81, pos_y+10, pos_z+63, block_id)
mc.setBlock(pos_x+80, pos_y+10, pos_z+63, block_id)
mc.setBlock(pos_x+79, pos_y+10, pos_z+63, block_id)
mc.setBlock(pos_x+78, pos_y+10, pos_z+63, block_id)
mc.setBlock(pos_x+77, pos_y+10, pos_z+63, block_id)
mc.setBlock(pos_x+76, pos_y+10, pos_z+63, block_id)
mc.setBlock(pos_x+75, pos_y+10, pos_z+63, block_id)
mc.setBlock(pos_x+74, pos_y+10, pos_z+63, block_id)
mc.setBlock(pos_x+73, pos_y+10, pos_z+63, block_id)
mc.setBlock(pos_x+72, pos_y+10, pos_z+63, block_id)
mc.setBlock(pos_x+71, pos_y+10, pos_z+63, block_id)
mc.setBlock(pos_x+70, pos_y+10, pos_z+63, block_id)
mc.setBlock(pos_x+69, pos_y+10, pos_z+63, block_id)
mc.setBlock(pos_x+68, pos_y+10, pos_z+63, block_id)
mc.setBlock(pos_x+67, pos_y+10, pos_z+63, block_id)
mc.setBlock(pos_x+66, pos_y+10, pos_z+63, block_id)
mc.setBlock(pos_x+65, pos_y+10, pos_z+63, block_id)
mc.setBlock(pos_x+64, pos_y+10, pos_z+63, block_id)
mc.setBlock(pos_x+63, pos_y+10, pos_z+63, block_id)
mc.setBlock(pos_x+62, pos_y+10, pos_z+63, block_id)
mc.setBlock(pos_x+28, pos_y+7, pos_z+69, block_id)
mc.setBlock(pos_x+33, pos_y+7, pos_z+69, block_id)
mc.setBlock(pos_x+34, pos_y+7, pos_z+69, block_id)
mc.setBlock(pos_x+35, pos_y+7, pos_z+69, block_id)
mc.setBlock(pos_x+36, pos_y+7, pos_z+69, block_id)
mc.setBlock(pos_x+37, pos_y+7, pos_z+69, block_id)
mc.setBlock(pos_x+62, pos_y+7, pos_z+69, block_id)
mc.setBlock(pos_x+63, pos_y+7, pos_z+69, block_id)
mc.setBlock(pos_x+37, pos_y+10, pos_z+63, block_id)
mc.setBlock(pos_x+36, pos_y+10, pos_z+63, block_id)
mc.setBlock(pos_x+35, pos_y+10, pos_z+63, block_id)
mc.setBlock(pos_x+34, pos_y+10, pos_z+63, block_id)
mc.setBlock(pos_x+33, pos_y+10, pos_z+63, block_id)
mc.setBlock(pos_x+32, pos_y+10, pos_z+63, block_id)
mc.setBlock(pos_x+31, pos_y+10, pos_z+63, block_id)
mc.setBlock(pos_x+30, pos_y+10, pos_z+63, block_id)
mc.setBlock(pos_x+29, pos_y+10, pos_z+63, block_id)
mc.setBlock(pos_x+28, pos_y+10, pos_z+63, block_id)
mc.setBlock(pos_x+27, pos_y+10, pos_z+63, block_id)
mc.setBlock(pos_x+26, pos_y+10, pos_z+63, block_id)
mc.setBlock(pos_x+25, pos_y+10, pos_z+63, block_id)
mc.setBlock(pos_x+24, pos_y+10, pos_z+63, block_id)
mc.setBlock(pos_x+23, pos_y+10, pos_z+63, block_id)
mc.setBlock(pos_x+22, pos_y+10, pos_z+63, block_id)
mc.setBlock(pos_x+21, pos_y+10, pos_z+63, block_id)
mc.setBlock(pos_x+20, pos_y+10, pos_z+63, block_id)
mc.setBlock(pos_x+19, pos_y+10, pos_z+63, block_id)
mc.setBlock(pos_x+18, pos_y+10, pos_z+63, block_id)
mc.setBlock(pos_x+17, pos_y+10, pos_z+63, block_id)
mc.setBlock(pos_x+16, pos_y+10, pos_z+63, block_id)
mc.setBlock(pos_x+15, pos_y+10, pos_z+63, block_id)
mc.setBlock(pos_x+14, pos_y+10, pos_z+63, block_id)
mc.setBlock(pos_x+13, pos_y+10, pos_z+63, block_id)
mc.setBlock(pos_x+12, pos_y+10, pos_z+63, block_id)
mc.setBlock(pos_x+11, pos_y+10, pos_z+63, block_id)
mc.setBlock(pos_x+10, pos_y+10, pos_z+63, block_id)
mc.setBlock(pos_x+9, pos_y+10, pos_z+63, block_id)
mc.setBlock(pos_x+8, pos_y+10, pos_z+63, block_id)
mc.setBlock(pos_x+7, pos_y+10, pos_z+63, block_id)
mc.setBlock(pos_x+6, pos_y+10, pos_z+63, block_id)
mc.setBlock(pos_x+99, pos_y+9, pos_z+63, block_id)
mc.setBlock(pos_x+98, pos_y+9, pos_z+63, block_id)
mc.setBlock(pos_x+97, pos_y+9, pos_z+63, block_id)
mc.setBlock(pos_x+96, pos_y+9, pos_z+63, block_id)
mc.setBlock(pos_x+95, pos_y+9, pos_z+63, block_id)
mc.setBlock(pos_x+94, pos_y+9, pos_z+63, block_id)
mc.setBlock(pos_x+64, pos_y+7, pos_z+69, block_id)
mc.setBlock(pos_x+65, pos_y+7, pos_z+69, block_id)
mc.setBlock(pos_x+66, pos_y+7, pos_z+69, block_id)
mc.setBlock(pos_x+71, pos_y+7, pos_z+69, block_id)
mc.setBlock(pos_x+72, pos_y+7, pos_z+69, block_id)
mc.setBlock(pos_x+73, pos_y+7, pos_z+69, block_id)
mc.setBlock(pos_x+74, pos_y+7, pos_z+69, block_id)
mc.setBlock(pos_x+0, pos_y+8, pos_z+69, block_id)
mc.setBlock(pos_x+1, pos_y+8, pos_z+69, block_id)
mc.setBlock(pos_x+2, pos_y+8, pos_z+69, block_id)
mc.setBlock(pos_x+3, pos_y+8, pos_z+69, block_id)
mc.setBlock(pos_x+4, pos_y+8, pos_z+69, block_id)
mc.setBlock(pos_x+5, pos_y+8, pos_z+69, block_id)
mc.setBlock(pos_x+6, pos_y+8, pos_z+69, block_id)
mc.setBlock(pos_x+7, pos_y+8, pos_z+69, block_id)
mc.setBlock(pos_x+8, pos_y+8, pos_z+69, block_id)
mc.setBlock(pos_x+9, pos_y+8, pos_z+69, block_id)
mc.setBlock(pos_x+10, pos_y+8, pos_z+69, block_id)
mc.setBlock(pos_x+11, pos_y+8, pos_z+69, block_id)
mc.setBlock(pos_x+12, pos_y+8, pos_z+69, block_id)
mc.setBlock(pos_x+13, pos_y+8, pos_z+69, block_id)
mc.setBlock(pos_x+14, pos_y+8, pos_z+69, block_id)
mc.setBlock(pos_x+15, pos_y+8, pos_z+69, block_id)
mc.setBlock(pos_x+16, pos_y+8, pos_z+69, block_id)
mc.setBlock(pos_x+17, pos_y+8, pos_z+69, block_id)
mc.setBlock(pos_x+18, pos_y+8, pos_z+69, block_id)
mc.setBlock(pos_x+19, pos_y+8, pos_z+69, block_id)
mc.setBlock(pos_x+20, pos_y+8, pos_z+69, block_id)
mc.setBlock(pos_x+21, pos_y+8, pos_z+69, block_id)
mc.setBlock(pos_x+22, pos_y+8, pos_z+69, block_id)
mc.setBlock(pos_x+23, pos_y+8, pos_z+69, block_id)
mc.setBlock(pos_x+24, pos_y+8, pos_z+69, block_id)
mc.setBlock(pos_x+29, pos_y+8, pos_z+69, block_id)
mc.setBlock(pos_x+30, pos_y+8, pos_z+69, block_id)
mc.setBlock(pos_x+31, pos_y+8, pos_z+69, block_id)
mc.setBlock(pos_x+5, pos_y+9, pos_z+63, block_id)
mc.setBlock(pos_x+4, pos_y+9, pos_z+63, block_id)
mc.setBlock(pos_x+3, pos_y+9, pos_z+63, block_id)
mc.setBlock(pos_x+2, pos_y+9, pos_z+63, block_id)
mc.setBlock(pos_x+1, pos_y+9, pos_z+63, block_id)
mc.setBlock(pos_x+0, pos_y+9, pos_z+63, block_id)
mc.setBlock(pos_x+99, pos_y+8, pos_z+63, block_id)
mc.setBlock(pos_x+98, pos_y+8, pos_z+63, block_id)
mc.setBlock(pos_x+97, pos_y+8, pos_z+63, block_id)
mc.setBlock(pos_x+96, pos_y+8, pos_z+63, block_id)
mc.setBlock(pos_x+95, pos_y+8, pos_z+63, block_id)
mc.setBlock(pos_x+94, pos_y+8, pos_z+63, block_id)
mc.setBlock(pos_x+93, pos_y+8, pos_z+63, block_id)
mc.setBlock(pos_x+92, pos_y+8, pos_z+63, block_id)
mc.setBlock(pos_x+91, pos_y+8, pos_z+63, block_id)
mc.setBlock(pos_x+90, pos_y+8, pos_z+63, block_id)
mc.setBlock(pos_x+89, pos_y+8, pos_z+63, block_id)
mc.setBlock(pos_x+88, pos_y+8, pos_z+63, block_id)
mc.setBlock(pos_x+87, pos_y+8, pos_z+63, block_id)
mc.setBlock(pos_x+86, pos_y+8, pos_z+63, block_id)
mc.setBlock(pos_x+32, pos_y+8, pos_z+69, block_id)
mc.setBlock(pos_x+84, pos_y+8, pos_z+63, block_id)
mc.setBlock(pos_x+83, pos_y+8, pos_z+63, block_id)
mc.setBlock(pos_x+82, pos_y+8, pos_z+63, block_id)
mc.setBlock(pos_x+81, pos_y+8, pos_z+63, block_id)
mc.setBlock(pos_x+80, pos_y+8, pos_z+63, block_id)
mc.setBlock(pos_x+37, pos_y+8, pos_z+69, block_id)
mc.setBlock(pos_x+62, pos_y+8, pos_z+69, block_id)
mc.setBlock(pos_x+67, pos_y+8, pos_z+69, block_id)
mc.setBlock(pos_x+74, pos_y+8, pos_z+63, block_id)
mc.setBlock(pos_x+68, pos_y+8, pos_z+69, block_id)
mc.setBlock(pos_x+69, pos_y+8, pos_z+69, block_id)
mc.setBlock(pos_x+70, pos_y+8, pos_z+69, block_id)
mc.setBlock(pos_x+75, pos_y+8, pos_z+69, block_id)
mc.setBlock(pos_x+76, pos_y+8, pos_z+69, block_id)
mc.setBlock(pos_x+77, pos_y+8, pos_z+69, block_id)
mc.setBlock(pos_x+78, pos_y+8, pos_z+69, block_id)
mc.setBlock(pos_x+79, pos_y+8, pos_z+69, block_id)
mc.setBlock(pos_x+80, pos_y+8, pos_z+69, block_id)
mc.setBlock(pos_x+81, pos_y+8, pos_z+69, block_id)
mc.setBlock(pos_x+82, pos_y+8, pos_z+69, block_id)
mc.setBlock(pos_x+83, pos_y+8, pos_z+69, block_id)
mc.setBlock(pos_x+84, pos_y+8, pos_z+69, block_id)
mc.setBlock(pos_x+85, pos_y+8, pos_z+69, block_id)
mc.setBlock(pos_x+86, pos_y+8, pos_z+69, block_id)
mc.setBlock(pos_x+87, pos_y+8, pos_z+69, block_id)
mc.setBlock(pos_x+88, pos_y+8, pos_z+69, block_id)
mc.setBlock(pos_x+89, pos_y+8, pos_z+69, block_id)
mc.setBlock(pos_x+90, pos_y+8, pos_z+69, block_id)
mc.setBlock(pos_x+91, pos_y+8, pos_z+69, block_id)
mc.setBlock(pos_x+92, pos_y+8, pos_z+69, block_id)
mc.setBlock(pos_x+93, pos_y+8, pos_z+69, block_id)
mc.setBlock(pos_x+94, pos_y+8, pos_z+69, block_id)
mc.setBlock(pos_x+95, pos_y+8, pos_z+69, block_id)
mc.setBlock(pos_x+96, pos_y+8, pos_z+69, block_id)
mc.setBlock(pos_x+25, pos_y+8, pos_z+63, block_id)
mc.setBlock(pos_x+97, pos_y+8, pos_z+69, block_id)
mc.setBlock(pos_x+98, pos_y+8, pos_z+69, block_id)
mc.setBlock(pos_x+99, pos_y+8, pos_z+69, block_id)
mc.setBlock(pos_x+0, pos_y+9, pos_z+69, block_id)
mc.setBlock(pos_x+19, pos_y+8, pos_z+63, block_id)
mc.setBlock(pos_x+18, pos_y+8, pos_z+63, block_id)
mc.setBlock(pos_x+17, pos_y+8, pos_z+63, block_id)
mc.setBlock(pos_x+16, pos_y+8, pos_z+63, block_id)
mc.setBlock(pos_x+15, pos_y+8, pos_z+63, block_id)
mc.setBlock(pos_x+14, pos_y+8, pos_z+63, block_id)
mc.setBlock(pos_x+1, pos_y+9, pos_z+69, block_id)
mc.setBlock(pos_x+12, pos_y+8, pos_z+63, block_id)
mc.setBlock(pos_x+11, pos_y+8, pos_z+63, block_id)
mc.setBlock(pos_x+10, pos_y+8, pos_z+63, block_id)
mc.setBlock(pos_x+9, pos_y+8, pos_z+63, block_id)
mc.setBlock(pos_x+8, pos_y+8, pos_z+63, block_id)
mc.setBlock(pos_x+7, pos_y+8, pos_z+63, block_id)
mc.setBlock(pos_x+6, pos_y+8, pos_z+63, block_id)
mc.setBlock(pos_x+5, pos_y+8, pos_z+63, block_id)
mc.setBlock(pos_x+4, pos_y+8, pos_z+63, block_id)
mc.setBlock(pos_x+3, pos_y+8, pos_z+63, block_id)
mc.setBlock(pos_x+2, pos_y+8, pos_z+63, block_id)
mc.setBlock(pos_x+1, pos_y+8, pos_z+63, block_id)
mc.setBlock(pos_x+0, pos_y+8, pos_z+63, block_id)
mc.setBlock(pos_x+85, pos_y+7, pos_z+63, block_id)
mc.setBlock(pos_x+79, pos_y+7, pos_z+63, block_id)
mc.setBlock(pos_x+78, pos_y+7, pos_z+63, block_id)
mc.setBlock(pos_x+77, pos_y+7, pos_z+63, block_id)
mc.setBlock(pos_x+76, pos_y+7, pos_z+63, block_id)
mc.setBlock(pos_x+75, pos_y+7, pos_z+63, block_id)
mc.setBlock(pos_x+73, pos_y+7, pos_z+63, block_id)
mc.setBlock(pos_x+72, pos_y+7, pos_z+63, block_id)
mc.setBlock(pos_x+71, pos_y+7, pos_z+63, block_id)
mc.setBlock(pos_x+70, pos_y+7, pos_z+63, block_id)
mc.setBlock(pos_x+69, pos_y+7, pos_z+63, block_id)
mc.setBlock(pos_x+68, pos_y+7, pos_z+63, block_id)
mc.setBlock(pos_x+67, pos_y+7, pos_z+63, block_id)
mc.setBlock(pos_x+66, pos_y+7, pos_z+63, block_id)
mc.setBlock(pos_x+65, pos_y+7, pos_z+63, block_id)
mc.setBlock(pos_x+64, pos_y+7, pos_z+63, block_id)
mc.setBlock(pos_x+63, pos_y+7, pos_z+63, block_id)
mc.setBlock(pos_x+62, pos_y+7, pos_z+63, block_id)
mc.setBlock(pos_x+2, pos_y+9, pos_z+69, block_id)
mc.setBlock(pos_x+3, pos_y+9, pos_z+69, block_id)
mc.setBlock(pos_x+4, pos_y+9, pos_z+69, block_id)
mc.setBlock(pos_x+94, pos_y+9, pos_z+69, block_id)
mc.setBlock(pos_x+95, pos_y+9, pos_z+69, block_id)
mc.setBlock(pos_x+96, pos_y+9, pos_z+69, block_id)
mc.setBlock(pos_x+97, pos_y+9, pos_z+69, block_id)
mc.setBlock(pos_x+98, pos_y+9, pos_z+69, block_id)
mc.setBlock(pos_x+99, pos_y+9, pos_z+69, block_id)
mc.setBlock(pos_x+37, pos_y+7, pos_z+63, block_id)
mc.setBlock(pos_x+36, pos_y+7, pos_z+63, block_id)
mc.setBlock(pos_x+35, pos_y+7, pos_z+63, block_id)
mc.setBlock(pos_x+34, pos_y+7, pos_z+63, block_id)
mc.setBlock(pos_x+33, pos_y+7, pos_z+63, block_id)
mc.setBlock(pos_x+32, pos_y+7, pos_z+63, block_id)
mc.setBlock(pos_x+31, pos_y+7, pos_z+63, block_id)
mc.setBlock(pos_x+30, pos_y+7, pos_z+63, block_id)
mc.setBlock(pos_x+29, pos_y+7, pos_z+63, block_id)
mc.setBlock(pos_x+28, pos_y+7, pos_z+63, block_id)
mc.setBlock(pos_x+27, pos_y+7, pos_z+63, block_id)
mc.setBlock(pos_x+26, pos_y+7, pos_z+63, block_id)
mc.setBlock(pos_x+24, pos_y+7, pos_z+63, block_id)
mc.setBlock(pos_x+23, pos_y+7, pos_z+63, block_id)
mc.setBlock(pos_x+22, pos_y+7, pos_z+63, block_id)
mc.setBlock(pos_x+21, pos_y+7, pos_z+63, block_id)
mc.setBlock(pos_x+20, pos_y+7, pos_z+63, block_id)
mc.setBlock(pos_x+13, pos_y+7, pos_z+63, block_id)
mc.setBlock(pos_x+61, pos_y+6, pos_z+63, block_id)
mc.setBlock(pos_x+5, pos_y+10, pos_z+69, block_id)
mc.setBlock(pos_x+6, pos_y+10, pos_z+69, block_id)
mc.setBlock(pos_x+7, pos_y+10, pos_z+69, block_id)
mc.setBlock(pos_x+8, pos_y+10, pos_z+69, block_id)
mc.setBlock(pos_x+9, pos_y+10, pos_z+69, block_id)
mc.setBlock(pos_x+10, pos_y+10, pos_z+69, block_id)
mc.setBlock(pos_x+11, pos_y+10, pos_z+69, block_id)
mc.setBlock(pos_x+12, pos_y+10, pos_z+69, block_id)
mc.setBlock(pos_x+38, pos_y+6, pos_z+63, block_id)
mc.setBlock(pos_x+60, pos_y+5, pos_z+63, block_id)
mc.setBlock(pos_x+13, pos_y+10, pos_z+69, block_id)
mc.setBlock(pos_x+14, pos_y+10, pos_z+69, block_id)
mc.setBlock(pos_x+15, pos_y+10, pos_z+69, block_id)
mc.setBlock(pos_x+16, pos_y+10, pos_z+69, block_id)
mc.setBlock(pos_x+17, pos_y+10, pos_z+69, block_id)
mc.setBlock(pos_x+18, pos_y+10, pos_z+69, block_id)
mc.setBlock(pos_x+19, pos_y+10, pos_z+69, block_id)
mc.setBlock(pos_x+20, pos_y+10, pos_z+69, block_id)
mc.setBlock(pos_x+21, pos_y+10, pos_z+69, block_id)
mc.setBlock(pos_x+38, pos_y+5, pos_z+63, block_id)
mc.setBlock(pos_x+60, pos_y+4, pos_z+63, block_id)
mc.setBlock(pos_x+22, pos_y+10, pos_z+69, block_id)
mc.setBlock(pos_x+23, pos_y+10, pos_z+69, block_id)
mc.setBlock(pos_x+24, pos_y+10, pos_z+69, block_id)
mc.setBlock(pos_x+25, pos_y+10, pos_z+69, block_id)
mc.setBlock(pos_x+26, pos_y+10, pos_z+69, block_id)
mc.setBlock(pos_x+27, pos_y+10, pos_z+69, block_id)
mc.setBlock(pos_x+39, pos_y+4, pos_z+63, block_id)
mc.setBlock(pos_x+59, pos_y+3, pos_z+63, block_id)
mc.setBlock(pos_x+28, pos_y+10, pos_z+69, block_id)
mc.setBlock(pos_x+29, pos_y+10, pos_z+69, block_id)
mc.setBlock(pos_x+30, pos_y+10, pos_z+69, block_id)
mc.setBlock(pos_x+31, pos_y+10, pos_z+69, block_id)
mc.setBlock(pos_x+32, pos_y+10, pos_z+69, block_id)
mc.setBlock(pos_x+33, pos_y+10, pos_z+69, block_id)
mc.setBlock(pos_x+34, pos_y+10, pos_z+69, block_id)
mc.setBlock(pos_x+35, pos_y+10, pos_z+69, block_id)
mc.setBlock(pos_x+40, pos_y+3, pos_z+63, block_id)
mc.setBlock(pos_x+58, pos_y+2, pos_z+63, block_id)
mc.setBlock(pos_x+57, pos_y+2, pos_z+63, block_id)
mc.setBlock(pos_x+36, pos_y+10, pos_z+69, block_id)
mc.setBlock(pos_x+37, pos_y+10, pos_z+69, block_id)
mc.setBlock(pos_x+42, pos_y+2, pos_z+63, block_id)
mc.setBlock(pos_x+41, pos_y+2, pos_z+63, block_id)
mc.setBlock(pos_x+56, pos_y+1, pos_z+63, block_id)
mc.setBlock(pos_x+55, pos_y+1, pos_z+63, block_id)
mc.setBlock(pos_x+62, pos_y+10, pos_z+69, block_id)
mc.setBlock(pos_x+63, pos_y+10, pos_z+69, block_id)
mc.setBlock(pos_x+44, pos_y+1, pos_z+63, block_id)
mc.setBlock(pos_x+43, pos_y+1, pos_z+63, block_id)
mc.setBlock(pos_x+54, pos_y+0, pos_z+63, block_id)
mc.setBlock(pos_x+53, pos_y+0, pos_z+63, block_id)
mc.setBlock(pos_x+52, pos_y+0, pos_z+63, block_id)
mc.setBlock(pos_x+51, pos_y+0, pos_z+63, block_id)
mc.setBlock(pos_x+50, pos_y+0, pos_z+63, block_id)
mc.setBlock(pos_x+49, pos_y+0, pos_z+63, block_id)
mc.setBlock(pos_x+48, pos_y+0, pos_z+63, block_id)
mc.setBlock(pos_x+47, pos_y+0, pos_z+63, block_id)
mc.setBlock(pos_x+46, pos_y+0, pos_z+63, block_id)
mc.setBlock(pos_x+45, pos_y+0, pos_z+63, block_id)
mc.setBlock(pos_x+51, pos_y+19, pos_z+62, block_id)
mc.setBlock(pos_x+50, pos_y+19, pos_z+62, block_id)
mc.setBlock(pos_x+49, pos_y+19, pos_z+62, block_id)
mc.setBlock(pos_x+48, pos_y+19, pos_z+62, block_id)
mc.setBlock(pos_x+54, pos_y+18, pos_z+62, block_id)
mc.setBlock(pos_x+53, pos_y+18, pos_z+62, block_id)
mc.setBlock(pos_x+52, pos_y+18, pos_z+62, block_id)
mc.setBlock(pos_x+64, pos_y+10, pos_z+69, block_id)
mc.setBlock(pos_x+65, pos_y+10, pos_z+69, block_id)
mc.setBlock(pos_x+66, pos_y+10, pos_z+69, block_id)
mc.setBlock(pos_x+67, pos_y+10, pos_z+69, block_id)
mc.setBlock(pos_x+47, pos_y+18, pos_z+62, block_id)
mc.setBlock(pos_x+46, pos_y+18, pos_z+62, block_id)
mc.setBlock(pos_x+45, pos_y+18, pos_z+62, block_id)
mc.setBlock(pos_x+44, pos_y+18, pos_z+62, block_id)
mc.setBlock(pos_x+57, pos_y+17, pos_z+62, block_id)
mc.setBlock(pos_x+56, pos_y+17, pos_z+62, block_id)
mc.setBlock(pos_x+55, pos_y+17, pos_z+62, block_id)
mc.setBlock(pos_x+68, pos_y+10, pos_z+69, block_id)
mc.setBlock(pos_x+69, pos_y+10, pos_z+69, block_id)
mc.setBlock(pos_x+43, pos_y+17, pos_z+62, block_id)
mc.setBlock(pos_x+42, pos_y+17, pos_z+62, block_id)
mc.setBlock(pos_x+58, pos_y+16, pos_z+62, block_id)
mc.setBlock(pos_x+70, pos_y+10, pos_z+69, block_id)
mc.setBlock(pos_x+71, pos_y+10, pos_z+69, block_id)
mc.setBlock(pos_x+72, pos_y+10, pos_z+69, block_id)
mc.setBlock(pos_x+41, pos_y+16, pos_z+62, block_id)
mc.setBlock(pos_x+59, pos_y+15, pos_z+62, block_id)
mc.setBlock(pos_x+73, pos_y+10, pos_z+69, block_id)
mc.setBlock(pos_x+74, pos_y+10, pos_z+69, block_id)
mc.setBlock(pos_x+40, pos_y+15, pos_z+62, block_id)
mc.setBlock(pos_x+60, pos_y+14, pos_z+62, block_id)
mc.setBlock(pos_x+75, pos_y+10, pos_z+69, block_id)
mc.setBlock(pos_x+76, pos_y+10, pos_z+69, block_id)
mc.setBlock(pos_x+39, pos_y+14, pos_z+62, block_id)
mc.setBlock(pos_x+60, pos_y+13, pos_z+62, block_id)
mc.setBlock(pos_x+77, pos_y+10, pos_z+69, block_id)
mc.setBlock(pos_x+78, pos_y+10, pos_z+69, block_id)
mc.setBlock(pos_x+79, pos_y+10, pos_z+69, block_id)
mc.setBlock(pos_x+80, pos_y+10, pos_z+69, block_id)
mc.setBlock(pos_x+81, pos_y+10, pos_z+69, block_id)
mc.setBlock(pos_x+82, pos_y+10, pos_z+69, block_id)
mc.setBlock(pos_x+83, pos_y+10, pos_z+69, block_id)
mc.setBlock(pos_x+39, pos_y+13, pos_z+62, block_id)
mc.setBlock(pos_x+61, pos_y+12, pos_z+62, block_id)
mc.setBlock(pos_x+84, pos_y+10, pos_z+69, block_id)
mc.setBlock(pos_x+85, pos_y+10, pos_z+69, block_id)
mc.setBlock(pos_x+86, pos_y+10, pos_z+69, block_id)
mc.setBlock(pos_x+87, pos_y+10, pos_z+69, block_id)
mc.setBlock(pos_x+88, pos_y+10, pos_z+69, block_id)
mc.setBlock(pos_x+89, pos_y+10, pos_z+69, block_id)
mc.setBlock(pos_x+38, pos_y+12, pos_z+62, block_id)
mc.setBlock(pos_x+61, pos_y+11, pos_z+62, block_id)
mc.setBlock(pos_x+90, pos_y+10, pos_z+69, block_id)
mc.setBlock(pos_x+91, pos_y+10, pos_z+69, block_id)
mc.setBlock(pos_x+92, pos_y+10, pos_z+69, block_id)
mc.setBlock(pos_x+93, pos_y+10, pos_z+69, block_id)
mc.setBlock(pos_x+38, pos_y+11, pos_z+69, block_id)
mc.setBlock(pos_x+61, pos_y+11, pos_z+69, block_id)
mc.setBlock(pos_x+38, pos_y+12, pos_z+69, block_id)
mc.setBlock(pos_x+61, pos_y+12, pos_z+69, block_id)
mc.setBlock(pos_x+39, pos_y+13, pos_z+69, block_id)
mc.setBlock(pos_x+38, pos_y+11, pos_z+62, block_id)
mc.setBlock(pos_x+93, pos_y+10, pos_z+62, block_id)
mc.setBlock(pos_x+92, pos_y+10, pos_z+62, block_id)
mc.setBlock(pos_x+91, pos_y+10, pos_z+62, block_id)
mc.setBlock(pos_x+90, pos_y+10, pos_z+62, block_id)
mc.setBlock(pos_x+89, pos_y+10, pos_z+62, block_id)
mc.setBlock(pos_x+88, pos_y+10, pos_z+62, block_id)
mc.setBlock(pos_x+87, pos_y+10, pos_z+62, block_id)
mc.setBlock(pos_x+86, pos_y+10, pos_z+62, block_id)
mc.setBlock(pos_x+85, pos_y+10, pos_z+62, block_id)
mc.setBlock(pos_x+84, pos_y+10, pos_z+62, block_id)
mc.setBlock(pos_x+83, pos_y+10, pos_z+62, block_id)
mc.setBlock(pos_x+82, pos_y+10, pos_z+62, block_id)
mc.setBlock(pos_x+81, pos_y+10, pos_z+62, block_id)
mc.setBlock(pos_x+80, pos_y+10, pos_z+62, block_id)
mc.setBlock(pos_x+79, pos_y+10, pos_z+62, block_id)
mc.setBlock(pos_x+78, pos_y+10, pos_z+62, block_id)
mc.setBlock(pos_x+77, pos_y+10, pos_z+62, block_id)
mc.setBlock(pos_x+76, pos_y+10, pos_z+62, block_id)
mc.setBlock(pos_x+75, pos_y+10, pos_z+62, block_id)
mc.setBlock(pos_x+74, pos_y+10, pos_z+62, block_id)
mc.setBlock(pos_x+73, pos_y+10, pos_z+62, block_id)
mc.setBlock(pos_x+72, pos_y+10, pos_z+62, block_id)
mc.setBlock(pos_x+71, pos_y+10, pos_z+62, block_id)
mc.setBlock(pos_x+70, pos_y+10, pos_z+62, block_id)
mc.setBlock(pos_x+69, pos_y+10, pos_z+62, block_id)
mc.setBlock(pos_x+68, pos_y+10, pos_z+62, block_id)
mc.setBlock(pos_x+67, pos_y+10, pos_z+62, block_id)
mc.setBlock(pos_x+66, pos_y+10, pos_z+62, block_id)
mc.setBlock(pos_x+65, pos_y+10, pos_z+62, block_id)
mc.setBlock(pos_x+64, pos_y+10, pos_z+62, block_id)
mc.setBlock(pos_x+63, pos_y+10, pos_z+62, block_id)
mc.setBlock(pos_x+62, pos_y+10, pos_z+62, block_id)
mc.setBlock(pos_x+60, pos_y+13, pos_z+69, block_id)
mc.setBlock(pos_x+40, pos_y+14, pos_z+69, block_id)
mc.setBlock(pos_x+59, pos_y+14, pos_z+69, block_id)
mc.setBlock(pos_x+40, pos_y+15, pos_z+69, block_id)
mc.setBlock(pos_x+58, pos_y+15, pos_z+69, block_id)
mc.setBlock(pos_x+41, pos_y+16, pos_z+69, block_id)
mc.setBlock(pos_x+42, pos_y+16, pos_z+69, block_id)
mc.setBlock(pos_x+57, pos_y+16, pos_z+69, block_id)
mc.setBlock(pos_x+37, pos_y+10, pos_z+62, block_id)
mc.setBlock(pos_x+36, pos_y+10, pos_z+62, block_id)
mc.setBlock(pos_x+35, pos_y+10, pos_z+62, block_id)
mc.setBlock(pos_x+34, pos_y+10, pos_z+62, block_id)
mc.setBlock(pos_x+33, pos_y+10, pos_z+62, block_id)
mc.setBlock(pos_x+32, pos_y+10, pos_z+62, block_id)
mc.setBlock(pos_x+31, pos_y+10, pos_z+62, block_id)
mc.setBlock(pos_x+30, pos_y+10, pos_z+62, block_id)
mc.setBlock(pos_x+29, pos_y+10, pos_z+62, block_id)
mc.setBlock(pos_x+28, pos_y+10, pos_z+62, block_id)
mc.setBlock(pos_x+27, pos_y+10, pos_z+62, block_id)
mc.setBlock(pos_x+26, pos_y+10, pos_z+62, block_id)
mc.setBlock(pos_x+25, pos_y+10, pos_z+62, block_id)
mc.setBlock(pos_x+24, pos_y+10, pos_z+62, block_id)
mc.setBlock(pos_x+23, pos_y+10, pos_z+62, block_id)
mc.setBlock(pos_x+22, pos_y+10, pos_z+62, block_id)
mc.setBlock(pos_x+21, pos_y+10, pos_z+62, block_id)
mc.setBlock(pos_x+20, pos_y+10, pos_z+62, block_id)
mc.setBlock(pos_x+19, pos_y+10, pos_z+62, block_id)
mc.setBlock(pos_x+18, pos_y+10, pos_z+62, block_id)
mc.setBlock(pos_x+17, pos_y+10, pos_z+62, block_id)
mc.setBlock(pos_x+16, pos_y+10, pos_z+62, block_id)
mc.setBlock(pos_x+15, pos_y+10, pos_z+62, block_id)
mc.setBlock(pos_x+14, pos_y+10, pos_z+62, block_id)
mc.setBlock(pos_x+13, pos_y+10, pos_z+62, block_id)
mc.setBlock(pos_x+12, pos_y+10, pos_z+62, block_id)
mc.setBlock(pos_x+11, pos_y+10, pos_z+62, block_id)
mc.setBlock(pos_x+10, pos_y+10, pos_z+62, block_id)
mc.setBlock(pos_x+9, pos_y+10, pos_z+62, block_id)
mc.setBlock(pos_x+8, pos_y+10, pos_z+62, block_id)
mc.setBlock(pos_x+7, pos_y+10, pos_z+62, block_id)
mc.setBlock(pos_x+6, pos_y+10, pos_z+62, block_id)
mc.setBlock(pos_x+99, pos_y+9, pos_z+62, block_id)
mc.setBlock(pos_x+98, pos_y+9, pos_z+62, block_id)
mc.setBlock(pos_x+97, pos_y+9, pos_z+62, block_id)
mc.setBlock(pos_x+96, pos_y+9, pos_z+62, block_id)
mc.setBlock(pos_x+95, pos_y+9, pos_z+62, block_id)
mc.setBlock(pos_x+94, pos_y+9, pos_z+62, block_id)
mc.setBlock(pos_x+43, pos_y+17, pos_z+69, block_id)
mc.setBlock(pos_x+44, pos_y+17, pos_z+69, block_id)
mc.setBlock(pos_x+55, pos_y+17, pos_z+69, block_id)
mc.setBlock(pos_x+56, pos_y+17, pos_z+69, block_id)
mc.setBlock(pos_x+45, pos_y+18, pos_z+69, block_id)
mc.setBlock(pos_x+46, pos_y+18, pos_z+69, block_id)
mc.setBlock(pos_x+53, pos_y+18, pos_z+69, block_id)
mc.setBlock(pos_x+54, pos_y+18, pos_z+69, block_id)
mc.setBlock(pos_x+47, pos_y+19, pos_z+69, block_id)
mc.setBlock(pos_x+48, pos_y+19, pos_z+69, block_id)
mc.setBlock(pos_x+49, pos_y+19, pos_z+69, block_id)
mc.setBlock(pos_x+50, pos_y+19, pos_z+69, block_id)
mc.setBlock(pos_x+51, pos_y+19, pos_z+69, block_id)
mc.setBlock(pos_x+52, pos_y+19, pos_z+69, block_id)
mc.setBlock(pos_x+45, pos_y+0, pos_z+70, block_id)
mc.setBlock(pos_x+46, pos_y+0, pos_z+70, block_id)
mc.setBlock(pos_x+62, pos_y+9, pos_z+62, block_id)
mc.setBlock(pos_x+47, pos_y+0, pos_z+70, block_id)
mc.setBlock(pos_x+48, pos_y+0, pos_z+70, block_id)
mc.setBlock(pos_x+49, pos_y+0, pos_z+70, block_id)
mc.setBlock(pos_x+50, pos_y+0, pos_z+70, block_id)
mc.setBlock(pos_x+51, pos_y+0, pos_z+70, block_id)
mc.setBlock(pos_x+52, pos_y+0, pos_z+70, block_id)
mc.setBlock(pos_x+53, pos_y+0, pos_z+70, block_id)
mc.setBlock(pos_x+43, pos_y+1, pos_z+70, block_id)
mc.setBlock(pos_x+44, pos_y+1, pos_z+70, block_id)
mc.setBlock(pos_x+37, pos_y+9, pos_z+62, block_id)
mc.setBlock(pos_x+36, pos_y+9, pos_z+62, block_id)
mc.setBlock(pos_x+54, pos_y+1, pos_z+70, block_id)
mc.setBlock(pos_x+55, pos_y+1, pos_z+70, block_id)
mc.setBlock(pos_x+56, pos_y+1, pos_z+70, block_id)
mc.setBlock(pos_x+41, pos_y+2, pos_z+70, block_id)
mc.setBlock(pos_x+42, pos_y+2, pos_z+70, block_id)
mc.setBlock(pos_x+57, pos_y+2, pos_z+70, block_id)
mc.setBlock(pos_x+58, pos_y+2, pos_z+70, block_id)
mc.setBlock(pos_x+40, pos_y+3, pos_z+70, block_id)
mc.setBlock(pos_x+59, pos_y+3, pos_z+70, block_id)
mc.setBlock(pos_x+39, pos_y+4, pos_z+70, block_id)
mc.setBlock(pos_x+60, pos_y+4, pos_z+70, block_id)
mc.setBlock(pos_x+39, pos_y+5, pos_z+70, block_id)
mc.setBlock(pos_x+60, pos_y+5, pos_z+70, block_id)
mc.setBlock(pos_x+38, pos_y+6, pos_z+70, block_id)
mc.setBlock(pos_x+60, pos_y+6, pos_z+70, block_id)
mc.setBlock(pos_x+5, pos_y+9, pos_z+62, block_id)
mc.setBlock(pos_x+4, pos_y+9, pos_z+62, block_id)
mc.setBlock(pos_x+3, pos_y+9, pos_z+62, block_id)
mc.setBlock(pos_x+2, pos_y+9, pos_z+62, block_id)
mc.setBlock(pos_x+1, pos_y+9, pos_z+62, block_id)
mc.setBlock(pos_x+0, pos_y+9, pos_z+62, block_id)
mc.setBlock(pos_x+99, pos_y+8, pos_z+62, block_id)
mc.setBlock(pos_x+98, pos_y+8, pos_z+62, block_id)
mc.setBlock(pos_x+97, pos_y+8, pos_z+62, block_id)
mc.setBlock(pos_x+96, pos_y+8, pos_z+62, block_id)
mc.setBlock(pos_x+95, pos_y+8, pos_z+62, block_id)
mc.setBlock(pos_x+94, pos_y+8, pos_z+62, block_id)
mc.setBlock(pos_x+93, pos_y+8, pos_z+62, block_id)
mc.setBlock(pos_x+92, pos_y+8, pos_z+62, block_id)
mc.setBlock(pos_x+91, pos_y+8, pos_z+62, block_id)
mc.setBlock(pos_x+90, pos_y+8, pos_z+62, block_id)
mc.setBlock(pos_x+89, pos_y+8, pos_z+62, block_id)
mc.setBlock(pos_x+88, pos_y+8, pos_z+62, block_id)
mc.setBlock(pos_x+87, pos_y+8, pos_z+62, block_id)
mc.setBlock(pos_x+86, pos_y+8, pos_z+62, block_id)
mc.setBlock(pos_x+85, pos_y+8, pos_z+62, block_id)
mc.setBlock(pos_x+84, pos_y+8, pos_z+62, block_id)
mc.setBlock(pos_x+83, pos_y+8, pos_z+62, block_id)
mc.setBlock(pos_x+82, pos_y+8, pos_z+62, block_id)
mc.setBlock(pos_x+81, pos_y+8, pos_z+62, block_id)
mc.setBlock(pos_x+80, pos_y+8, pos_z+62, block_id)
mc.setBlock(pos_x+38, pos_y+7, pos_z+70, block_id)
mc.setBlock(pos_x+61, pos_y+7, pos_z+70, block_id)
mc.setBlock(pos_x+0, pos_y+8, pos_z+70, block_id)
mc.setBlock(pos_x+1, pos_y+8, pos_z+70, block_id)
mc.setBlock(pos_x+2, pos_y+8, pos_z+70, block_id)
mc.setBlock(pos_x+74, pos_y+8, pos_z+62, block_id)
mc.setBlock(pos_x+73, pos_y+8, pos_z+62, block_id)
mc.setBlock(pos_x+3, pos_y+8, pos_z+70, block_id)
mc.setBlock(pos_x+4, pos_y+8, pos_z+70, block_id)
mc.setBlock(pos_x+5, pos_y+8, pos_z+70, block_id)
mc.setBlock(pos_x+6, pos_y+8, pos_z+70, block_id)
mc.setBlock(pos_x+68, pos_y+8, pos_z+62, block_id)
mc.setBlock(pos_x+67, pos_y+8, pos_z+62, block_id)
mc.setBlock(pos_x+66, pos_y+8, pos_z+62, block_id)
mc.setBlock(pos_x+65, pos_y+8, pos_z+62, block_id)
mc.setBlock(pos_x+64, pos_y+8, pos_z+62, block_id)
mc.setBlock(pos_x+63, pos_y+8, pos_z+62, block_id)
mc.setBlock(pos_x+62, pos_y+8, pos_z+62, block_id)
mc.setBlock(pos_x+7, pos_y+8, pos_z+70, block_id)
mc.setBlock(pos_x+8, pos_y+8, pos_z+70, block_id)
mc.setBlock(pos_x+9, pos_y+8, pos_z+70, block_id)
mc.setBlock(pos_x+10, pos_y+8, pos_z+70, block_id)
mc.setBlock(pos_x+11, pos_y+8, pos_z+70, block_id)
mc.setBlock(pos_x+12, pos_y+8, pos_z+70, block_id)
mc.setBlock(pos_x+13, pos_y+8, pos_z+70, block_id)
mc.setBlock(pos_x+37, pos_y+8, pos_z+62, block_id)
mc.setBlock(pos_x+36, pos_y+8, pos_z+62, block_id)
mc.setBlock(pos_x+35, pos_y+8, pos_z+62, block_id)
mc.setBlock(pos_x+34, pos_y+8, pos_z+62, block_id)
mc.setBlock(pos_x+33, pos_y+8, pos_z+62, block_id)
mc.setBlock(pos_x+32, pos_y+8, pos_z+62, block_id)
mc.setBlock(pos_x+31, pos_y+8, pos_z+62, block_id)
mc.setBlock(pos_x+14, pos_y+8, pos_z+70, block_id)
mc.setBlock(pos_x+15, pos_y+8, pos_z+70, block_id)
mc.setBlock(pos_x+16, pos_y+8, pos_z+70, block_id)
mc.setBlock(pos_x+17, pos_y+8, pos_z+70, block_id)
mc.setBlock(pos_x+26, pos_y+8, pos_z+62, block_id)
mc.setBlock(pos_x+25, pos_y+8, pos_z+62, block_id)
mc.setBlock(pos_x+18, pos_y+8, pos_z+70, block_id)
mc.setBlock(pos_x+19, pos_y+8, pos_z+70, block_id)
mc.setBlock(pos_x+20, pos_y+8, pos_z+70, block_id)
mc.setBlock(pos_x+21, pos_y+8, pos_z+70, block_id)
mc.setBlock(pos_x+22, pos_y+8, pos_z+70, block_id)
mc.setBlock(pos_x+19, pos_y+8, pos_z+62, block_id)
mc.setBlock(pos_x+18, pos_y+8, pos_z+62, block_id)
mc.setBlock(pos_x+17, pos_y+8, pos_z+62, block_id)
mc.setBlock(pos_x+16, pos_y+8, pos_z+62, block_id)
mc.setBlock(pos_x+15, pos_y+8, pos_z+62, block_id)
mc.setBlock(pos_x+14, pos_y+8, pos_z+62, block_id)
mc.setBlock(pos_x+13, pos_y+8, pos_z+62, block_id)
mc.setBlock(pos_x+12, pos_y+8, pos_z+62, block_id)
mc.setBlock(pos_x+11, pos_y+8, pos_z+62, block_id)
mc.setBlock(pos_x+10, pos_y+8, pos_z+62, block_id)
mc.setBlock(pos_x+9, pos_y+8, pos_z+62, block_id)
mc.setBlock(pos_x+8, pos_y+8, pos_z+62, block_id)
mc.setBlock(pos_x+7, pos_y+8, pos_z+62, block_id)
mc.setBlock(pos_x+6, pos_y+8, pos_z+62, block_id)
mc.setBlock(pos_x+5, pos_y+8, pos_z+62, block_id)
mc.setBlock(pos_x+4, pos_y+8, pos_z+62, block_id)
mc.setBlock(pos_x+3, pos_y+8, pos_z+62, block_id)
mc.setBlock(pos_x+2, pos_y+8, pos_z+62, block_id)
mc.setBlock(pos_x+1, pos_y+8, pos_z+62, block_id)
mc.setBlock(pos_x+0, pos_y+8, pos_z+62, block_id)
mc.setBlock(pos_x+79, pos_y+7, pos_z+62, block_id)
mc.setBlock(pos_x+78, pos_y+7, pos_z+62, block_id)
mc.setBlock(pos_x+77, pos_y+7, pos_z+62, block_id)
mc.setBlock(pos_x+76, pos_y+7, pos_z+62, block_id)
mc.setBlock(pos_x+75, pos_y+7, pos_z+62, block_id)
mc.setBlock(pos_x+72, pos_y+7, pos_z+62, block_id)
mc.setBlock(pos_x+71, pos_y+7, pos_z+62, block_id)
mc.setBlock(pos_x+70, pos_y+7, pos_z+62, block_id)
mc.setBlock(pos_x+69, pos_y+7, pos_z+62, block_id)
mc.setBlock(pos_x+61, pos_y+7, pos_z+62, block_id)
mc.setBlock(pos_x+23, pos_y+8, pos_z+70, block_id)
mc.setBlock(pos_x+24, pos_y+8, pos_z+70, block_id)
mc.setBlock(pos_x+25, pos_y+8, pos_z+70, block_id)
mc.setBlock(pos_x+26, pos_y+8, pos_z+70, block_id)
mc.setBlock(pos_x+27, pos_y+8, pos_z+70, block_id)
mc.setBlock(pos_x+28, pos_y+8, pos_z+70, block_id)
mc.setBlock(pos_x+29, pos_y+8, pos_z+70, block_id)
mc.setBlock(pos_x+38, pos_y+7, pos_z+62, block_id)
mc.setBlock(pos_x+30, pos_y+7, pos_z+62, block_id)
mc.setBlock(pos_x+29, pos_y+7, pos_z+62, block_id)
mc.setBlock(pos_x+28, pos_y+7, pos_z+62, block_id)
mc.setBlock(pos_x+27, pos_y+7, pos_z+62, block_id)
mc.setBlock(pos_x+24, pos_y+7, pos_z+62, block_id)
mc.setBlock(pos_x+23, pos_y+7, pos_z+62, block_id)
mc.setBlock(pos_x+22, pos_y+7, pos_z+62, block_id)
mc.setBlock(pos_x+21, pos_y+7, pos_z+62, block_id)
mc.setBlock(pos_x+20, pos_y+7, pos_z+62, block_id)
mc.setBlock(pos_x+61, pos_y+6, pos_z+62, block_id)
mc.setBlock(pos_x+30, pos_y+8, pos_z+70, block_id)
mc.setBlock(pos_x+31, pos_y+8, pos_z+70, block_id)
mc.setBlock(pos_x+32, pos_y+8, pos_z+70, block_id)
mc.setBlock(pos_x+33, pos_y+8, pos_z+70, block_id)
mc.setBlock(pos_x+34, pos_y+8, pos_z+70, block_id)
mc.setBlock(pos_x+35, pos_y+8, pos_z+70, block_id)
mc.setBlock(pos_x+36, pos_y+8, pos_z+70, block_id)
mc.setBlock(pos_x+38, pos_y+8, pos_z+70, block_id)
mc.setBlock(pos_x+38, pos_y+6, pos_z+62, block_id)
mc.setBlock(pos_x+60, pos_y+5, pos_z+62, block_id)
mc.setBlock(pos_x+61, pos_y+8, pos_z+70, block_id)
mc.setBlock(pos_x+63, pos_y+8, pos_z+70, block_id)
mc.setBlock(pos_x+64, pos_y+8, pos_z+70, block_id)
mc.setBlock(pos_x+65, pos_y+8, pos_z+70, block_id)
mc.setBlock(pos_x+66, pos_y+8, pos_z+70, block_id)
mc.setBlock(pos_x+67, pos_y+8, pos_z+70, block_id)
mc.setBlock(pos_x+68, pos_y+8, pos_z+70, block_id)
mc.setBlock(pos_x+69, pos_y+8, pos_z+70, block_id)
mc.setBlock(pos_x+70, pos_y+8, pos_z+70, block_id)
mc.setBlock(pos_x+39, pos_y+5, pos_z+62, block_id)
mc.setBlock(pos_x+60, pos_y+4, pos_z+62, block_id)
mc.setBlock(pos_x+71, pos_y+8, pos_z+70, block_id)
mc.setBlock(pos_x+72, pos_y+8, pos_z+70, block_id)
mc.setBlock(pos_x+73, pos_y+8, pos_z+70, block_id)
mc.setBlock(pos_x+74, pos_y+8, pos_z+70, block_id)
mc.setBlock(pos_x+75, pos_y+8, pos_z+70, block_id)
mc.setBlock(pos_x+76, pos_y+8, pos_z+70, block_id)
mc.setBlock(pos_x+39, pos_y+4, pos_z+62, block_id)
mc.setBlock(pos_x+59, pos_y+3, pos_z+62, block_id)
mc.setBlock(pos_x+77, pos_y+8, pos_z+70, block_id)
mc.setBlock(pos_x+78, pos_y+8, pos_z+70, block_id)
mc.setBlock(pos_x+79, pos_y+8, pos_z+70, block_id)
mc.setBlock(pos_x+80, pos_y+8, pos_z+70, block_id)
mc.setBlock(pos_x+81, pos_y+8, pos_z+70, block_id)
mc.setBlock(pos_x+82, pos_y+8, pos_z+70, block_id)
mc.setBlock(pos_x+83, pos_y+8, pos_z+70, block_id)
mc.setBlock(pos_x+84, pos_y+8, pos_z+70, block_id)
mc.setBlock(pos_x+40, pos_y+3, pos_z+62, block_id)
mc.setBlock(pos_x+58, pos_y+2, pos_z+62, block_id)
mc.setBlock(pos_x+57, pos_y+2, pos_z+62, block_id)
mc.setBlock(pos_x+85, pos_y+8, pos_z+70, block_id)
mc.setBlock(pos_x+86, pos_y+8, pos_z+70, block_id)
mc.setBlock(pos_x+42, pos_y+2, pos_z+62, block_id)
mc.setBlock(pos_x+41, pos_y+2, pos_z+62, block_id)
mc.setBlock(pos_x+56, pos_y+1, pos_z+62, block_id)
mc.setBlock(pos_x+55, pos_y+1, pos_z+62, block_id)
mc.setBlock(pos_x+87, pos_y+8, pos_z+70, block_id)
mc.setBlock(pos_x+88, pos_y+8, pos_z+70, block_id)
mc.setBlock(pos_x+44, pos_y+1, pos_z+62, block_id)
mc.setBlock(pos_x+43, pos_y+1, pos_z+62, block_id)
mc.setBlock(pos_x+54, pos_y+0, pos_z+62, block_id)
mc.setBlock(pos_x+53, pos_y+0, pos_z+62, block_id)
mc.setBlock(pos_x+52, pos_y+0, pos_z+62, block_id)
mc.setBlock(pos_x+51, pos_y+0, pos_z+62, block_id)
mc.setBlock(pos_x+50, pos_y+0, pos_z+62, block_id)
mc.setBlock(pos_x+49, pos_y+0, pos_z+62, block_id)
mc.setBlock(pos_x+48, pos_y+0, pos_z+62, block_id)
mc.setBlock(pos_x+47, pos_y+0, pos_z+62, block_id)
mc.setBlock(pos_x+46, pos_y+0, pos_z+62, block_id)
mc.setBlock(pos_x+45, pos_y+0, pos_z+62, block_id)
mc.setBlock(pos_x+50, pos_y+19, pos_z+61, block_id)
mc.setBlock(pos_x+49, pos_y+19, pos_z+61, block_id)
mc.setBlock(pos_x+54, pos_y+18, pos_z+61, block_id)
mc.setBlock(pos_x+53, pos_y+18, pos_z+61, block_id)
mc.setBlock(pos_x+52, pos_y+18, pos_z+61, block_id)
mc.setBlock(pos_x+51, pos_y+18, pos_z+61, block_id)
mc.setBlock(pos_x+89, pos_y+8, pos_z+70, block_id)
mc.setBlock(pos_x+90, pos_y+8, pos_z+70, block_id)
mc.setBlock(pos_x+48, pos_y+18, pos_z+61, block_id)
mc.setBlock(pos_x+47, pos_y+18, pos_z+61, block_id)
mc.setBlock(pos_x+46, pos_y+18, pos_z+61, block_id)
mc.setBlock(pos_x+45, pos_y+18, pos_z+61, block_id)
mc.setBlock(pos_x+57, pos_y+17, pos_z+61, block_id)
mc.setBlock(pos_x+56, pos_y+17, pos_z+61, block_id)
mc.setBlock(pos_x+55, pos_y+17, pos_z+61, block_id)
mc.setBlock(pos_x+91, pos_y+8, pos_z+70, block_id)
mc.setBlock(pos_x+92, pos_y+8, pos_z+70, block_id)
mc.setBlock(pos_x+44, pos_y+17, pos_z+61, block_id)
mc.setBlock(pos_x+43, pos_y+17, pos_z+61, block_id)
mc.setBlock(pos_x+42, pos_y+17, pos_z+61, block_id)
mc.setBlock(pos_x+58, pos_y+16, pos_z+61, block_id)
mc.setBlock(pos_x+93, pos_y+8, pos_z+70, block_id)
mc.setBlock(pos_x+94, pos_y+8, pos_z+70, block_id)
mc.setBlock(pos_x+41, pos_y+16, pos_z+61, block_id)
mc.setBlock(pos_x+59, pos_y+15, pos_z+61, block_id)
mc.setBlock(pos_x+95, pos_y+8, pos_z+70, block_id)
mc.setBlock(pos_x+96, pos_y+8, pos_z+70, block_id)
mc.setBlock(pos_x+40, pos_y+15, pos_z+61, block_id)
mc.setBlock(pos_x+59, pos_y+14, pos_z+61, block_id)
mc.setBlock(pos_x+97, pos_y+8, pos_z+70, block_id)
mc.setBlock(pos_x+39, pos_y+14, pos_z+61, block_id)
mc.setBlock(pos_x+60, pos_y+13, pos_z+61, block_id)
mc.setBlock(pos_x+98, pos_y+8, pos_z+70, block_id)
mc.setBlock(pos_x+99, pos_y+8, pos_z+70, block_id)
mc.setBlock(pos_x+0, pos_y+9, pos_z+70, block_id)
mc.setBlock(pos_x+1, pos_y+9, pos_z+70, block_id)
mc.setBlock(pos_x+2, pos_y+9, pos_z+70, block_id)
mc.setBlock(pos_x+3, pos_y+9, pos_z+70, block_id)
mc.setBlock(pos_x+4, pos_y+9, pos_z+70, block_id)
mc.setBlock(pos_x+5, pos_y+9, pos_z+70, block_id)
mc.setBlock(pos_x+39, pos_y+13, pos_z+61, block_id)
mc.setBlock(pos_x+60, pos_y+12, pos_z+61, block_id)
mc.setBlock(pos_x+34, pos_y+9, pos_z+70, block_id)
mc.setBlock(pos_x+35, pos_y+9, pos_z+70, block_id)
mc.setBlock(pos_x+36, pos_y+9, pos_z+70, block_id)
mc.setBlock(pos_x+37, pos_y+9, pos_z+70, block_id)
mc.setBlock(pos_x+62, pos_y+9, pos_z+70, block_id)
mc.setBlock(pos_x+38, pos_y+12, pos_z+61, block_id)
mc.setBlock(pos_x+61, pos_y+11, pos_z+61, block_id)
mc.setBlock(pos_x+63, pos_y+9, pos_z+70, block_id)
mc.setBlock(pos_x+64, pos_y+9, pos_z+70, block_id)
mc.setBlock(pos_x+65, pos_y+9, pos_z+70, block_id)
mc.setBlock(pos_x+94, pos_y+9, pos_z+70, block_id)
mc.setBlock(pos_x+95, pos_y+9, pos_z+70, block_id)
mc.setBlock(pos_x+96, pos_y+9, pos_z+70, block_id)
mc.setBlock(pos_x+97, pos_y+9, pos_z+70, block_id)
mc.setBlock(pos_x+98, pos_y+9, pos_z+70, block_id)
mc.setBlock(pos_x+99, pos_y+9, pos_z+70, block_id)
mc.setBlock(pos_x+6, pos_y+10, pos_z+70, block_id)
mc.setBlock(pos_x+38, pos_y+11, pos_z+61, block_id)
mc.setBlock(pos_x+93, pos_y+10, pos_z+61, block_id)
mc.setBlock(pos_x+92, pos_y+10, pos_z+61, block_id)
mc.setBlock(pos_x+91, pos_y+10, pos_z+61, block_id)
mc.setBlock(pos_x+90, pos_y+10, pos_z+61, block_id)
mc.setBlock(pos_x+89, pos_y+10, pos_z+61, block_id)
mc.setBlock(pos_x+88, pos_y+10, pos_z+61, block_id)
mc.setBlock(pos_x+87, pos_y+10, pos_z+61, block_id)
mc.setBlock(pos_x+86, pos_y+10, pos_z+61, block_id)
mc.setBlock(pos_x+85, pos_y+10, pos_z+61, block_id)
mc.setBlock(pos_x+84, pos_y+10, pos_z+61, block_id)
mc.setBlock(pos_x+83, pos_y+10, pos_z+61, block_id)
mc.setBlock(pos_x+82, pos_y+10, pos_z+61, block_id)
mc.setBlock(pos_x+81, pos_y+10, pos_z+61, block_id)
mc.setBlock(pos_x+80, pos_y+10, pos_z+61, block_id)
mc.setBlock(pos_x+79, pos_y+10, pos_z+61, block_id)
mc.setBlock(pos_x+78, pos_y+10, pos_z+61, block_id)
mc.setBlock(pos_x+77, pos_y+10, pos_z+61, block_id)
mc.setBlock(pos_x+76, pos_y+10, pos_z+61, block_id)
mc.setBlock(pos_x+75, pos_y+10, pos_z+61, block_id)
mc.setBlock(pos_x+74, pos_y+10, pos_z+61, block_id)
mc.setBlock(pos_x+73, pos_y+10, pos_z+61, block_id)
mc.setBlock(pos_x+72, pos_y+10, pos_z+61, block_id)
mc.setBlock(pos_x+71, pos_y+10, pos_z+61, block_id)
mc.setBlock(pos_x+70, pos_y+10, pos_z+61, block_id)
mc.setBlock(pos_x+69, pos_y+10, pos_z+61, block_id)
mc.setBlock(pos_x+68, pos_y+10, pos_z+61, block_id)
mc.setBlock(pos_x+67, pos_y+10, pos_z+61, block_id)
mc.setBlock(pos_x+66, pos_y+10, pos_z+61, block_id)
mc.setBlock(pos_x+65, pos_y+10, pos_z+61, block_id)
mc.setBlock(pos_x+61, pos_y+10, pos_z+61, block_id)
mc.setBlock(pos_x+7, pos_y+10, pos_z+70, block_id)
mc.setBlock(pos_x+8, pos_y+10, pos_z+70, block_id)
mc.setBlock(pos_x+9, pos_y+10, pos_z+70, block_id)
mc.setBlock(pos_x+10, pos_y+10, pos_z+70, block_id)
mc.setBlock(pos_x+11, pos_y+10, pos_z+70, block_id)
mc.setBlock(pos_x+12, pos_y+10, pos_z+70, block_id)
mc.setBlock(pos_x+13, pos_y+10, pos_z+70, block_id)
mc.setBlock(pos_x+38, pos_y+10, pos_z+61, block_id)
mc.setBlock(pos_x+34, pos_y+10, pos_z+61, block_id)
mc.setBlock(pos_x+33, pos_y+10, pos_z+61, block_id)
mc.setBlock(pos_x+32, pos_y+10, pos_z+61, block_id)
mc.setBlock(pos_x+31, pos_y+10, pos_z+61, block_id)
mc.setBlock(pos_x+30, pos_y+10, pos_z+61, block_id)
mc.setBlock(pos_x+29, pos_y+10, pos_z+61, block_id)
mc.setBlock(pos_x+28, pos_y+10, pos_z+61, block_id)
mc.setBlock(pos_x+27, pos_y+10, pos_z+61, block_id)
mc.setBlock(pos_x+26, pos_y+10, pos_z+61, block_id)
mc.setBlock(pos_x+25, pos_y+10, pos_z+61, block_id)
mc.setBlock(pos_x+24, pos_y+10, pos_z+61, block_id)
mc.setBlock(pos_x+23, pos_y+10, pos_z+61, block_id)
mc.setBlock(pos_x+22, pos_y+10, pos_z+61, block_id)
mc.setBlock(pos_x+21, pos_y+10, pos_z+61, block_id)
mc.setBlock(pos_x+20, pos_y+10, pos_z+61, block_id)
mc.setBlock(pos_x+19, pos_y+10, pos_z+61, block_id)
mc.setBlock(pos_x+18, pos_y+10, pos_z+61, block_id)
mc.setBlock(pos_x+17, pos_y+10, pos_z+61, block_id)
mc.setBlock(pos_x+16, pos_y+10, pos_z+61, block_id)
mc.setBlock(pos_x+15, pos_y+10, pos_z+61, block_id)
mc.setBlock(pos_x+14, pos_y+10, pos_z+61, block_id)
mc.setBlock(pos_x+13, pos_y+10, pos_z+61, block_id)
mc.setBlock(pos_x+12, pos_y+10, pos_z+61, block_id)
mc.setBlock(pos_x+11, pos_y+10, pos_z+61, block_id)
mc.setBlock(pos_x+10, pos_y+10, pos_z+61, block_id)
mc.setBlock(pos_x+9, pos_y+10, pos_z+61, block_id)
mc.setBlock(pos_x+8, pos_y+10, pos_z+61, block_id)
mc.setBlock(pos_x+7, pos_y+10, pos_z+61, block_id)
mc.setBlock(pos_x+6, pos_y+10, pos_z+61, block_id)
mc.setBlock(pos_x+99, pos_y+9, pos_z+61, block_id)
mc.setBlock(pos_x+98, pos_y+9, pos_z+61, block_id)
mc.setBlock(pos_x+97, pos_y+9, pos_z+61, block_id)
mc.setBlock(pos_x+96, pos_y+9, pos_z+61, block_id)
mc.setBlock(pos_x+95, pos_y+9, pos_z+61, block_id)
mc.setBlock(pos_x+94, pos_y+9, pos_z+61, block_id)
mc.setBlock(pos_x+14, pos_y+10, pos_z+70, block_id)
mc.setBlock(pos_x+15, pos_y+10, pos_z+70, block_id)
mc.setBlock(pos_x+16, pos_y+10, pos_z+70, block_id)
mc.setBlock(pos_x+17, pos_y+10, pos_z+70, block_id)
mc.setBlock(pos_x+18, pos_y+10, pos_z+70, block_id)
mc.setBlock(pos_x+19, pos_y+10, pos_z+70, block_id)
mc.setBlock(pos_x+20, pos_y+10, pos_z+70, block_id)
mc.setBlock(pos_x+21, pos_y+10, pos_z+70, block_id)
mc.setBlock(pos_x+22, pos_y+10, pos_z+70, block_id)
mc.setBlock(pos_x+23, pos_y+10, pos_z+70, block_id)
mc.setBlock(pos_x+65, pos_y+9, pos_z+61, block_id)
mc.setBlock(pos_x+64, pos_y+9, pos_z+61, block_id)
mc.setBlock(pos_x+63, pos_y+9, pos_z+61, block_id)
mc.setBlock(pos_x+61, pos_y+9, pos_z+61, block_id)
mc.setBlock(pos_x+24, pos_y+10, pos_z+70, block_id)
mc.setBlock(pos_x+25, pos_y+10, pos_z+70, block_id)
mc.setBlock(pos_x+26, pos_y+10, pos_z+70, block_id)
mc.setBlock(pos_x+27, pos_y+10, pos_z+70, block_id)
mc.setBlock(pos_x+28, pos_y+10, pos_z+70, block_id)
mc.setBlock(pos_x+29, pos_y+10, pos_z+70, block_id)
mc.setBlock(pos_x+30, pos_y+10, pos_z+70, block_id)
mc.setBlock(pos_x+31, pos_y+10, pos_z+70, block_id)
mc.setBlock(pos_x+38, pos_y+9, pos_z+61, block_id)
mc.setBlock(pos_x+35, pos_y+9, pos_z+61, block_id)
mc.setBlock(pos_x+34, pos_y+9, pos_z+61, block_id)
mc.setBlock(pos_x+32, pos_y+10, pos_z+70, block_id)
mc.setBlock(pos_x+33, pos_y+10, pos_z+70, block_id)
mc.setBlock(pos_x+34, pos_y+10, pos_z+70, block_id)
mc.setBlock(pos_x+38, pos_y+10, pos_z+70, block_id)
mc.setBlock(pos_x+61, pos_y+10, pos_z+70, block_id)
mc.setBlock(pos_x+64, pos_y+10, pos_z+70, block_id)
mc.setBlock(pos_x+65, pos_y+10, pos_z+70, block_id)
mc.setBlock(pos_x+66, pos_y+10, pos_z+70, block_id)
mc.setBlock(pos_x+67, pos_y+10, pos_z+70, block_id)
mc.setBlock(pos_x+68, pos_y+10, pos_z+70, block_id)
mc.setBlock(pos_x+69, pos_y+10, pos_z+70, block_id)
mc.setBlock(pos_x+5, pos_y+9, pos_z+61, block_id)
mc.setBlock(pos_x+4, pos_y+9, pos_z+61, block_id)
mc.setBlock(pos_x+3, pos_y+9, pos_z+61, block_id)
mc.setBlock(pos_x+2, pos_y+9, pos_z+61, block_id)
mc.setBlock(pos_x+1, pos_y+9, pos_z+61, block_id)
mc.setBlock(pos_x+0, pos_y+9, pos_z+61, block_id)
mc.setBlock(pos_x+99, pos_y+8, pos_z+61, block_id)
mc.setBlock(pos_x+98, pos_y+8, pos_z+61, block_id)
mc.setBlock(pos_x+97, pos_y+8, pos_z+61, block_id)
mc.setBlock(pos_x+96, pos_y+8, pos_z+61, block_id)
mc.setBlock(pos_x+95, pos_y+8, pos_z+61, block_id)
mc.setBlock(pos_x+94, pos_y+8, pos_z+61, block_id)
mc.setBlock(pos_x+93, pos_y+8, pos_z+61, block_id)
mc.setBlock(pos_x+92, pos_y+8, pos_z+61, block_id)
mc.setBlock(pos_x+91, pos_y+8, pos_z+61, block_id)
mc.setBlock(pos_x+90, pos_y+8, pos_z+61, block_id)
mc.setBlock(pos_x+89, pos_y+8, pos_z+61, block_id)
mc.setBlock(pos_x+88, pos_y+8, pos_z+61, block_id)
mc.setBlock(pos_x+87, pos_y+8, pos_z+61, block_id)
mc.setBlock(pos_x+86, pos_y+8, pos_z+61, block_id)
mc.setBlock(pos_x+85, pos_y+8, pos_z+61, block_id)
mc.setBlock(pos_x+84, pos_y+8, pos_z+61, block_id)
mc.setBlock(pos_x+83, pos_y+8, pos_z+61, block_id)
mc.setBlock(pos_x+82, pos_y+8, pos_z+61, block_id)
mc.setBlock(pos_x+81, pos_y+8, pos_z+61, block_id)
mc.setBlock(pos_x+80, pos_y+8, pos_z+61, block_id)
mc.setBlock(pos_x+79, pos_y+8, pos_z+61, block_id)
mc.setBlock(pos_x+78, pos_y+8, pos_z+61, block_id)
mc.setBlock(pos_x+77, pos_y+8, pos_z+61, block_id)
mc.setBlock(pos_x+76, pos_y+8, pos_z+61, block_id)
mc.setBlock(pos_x+75, pos_y+8, pos_z+61, block_id)
mc.setBlock(pos_x+74, pos_y+8, pos_z+61, block_id)
mc.setBlock(pos_x+73, pos_y+8, pos_z+61, block_id)
mc.setBlock(pos_x+72, pos_y+8, pos_z+61, block_id)
mc.setBlock(pos_x+71, pos_y+8, pos_z+61, block_id)
mc.setBlock(pos_x+70, pos_y+8, pos_z+61, block_id)
mc.setBlock(pos_x+69, pos_y+8, pos_z+61, block_id)
mc.setBlock(pos_x+68, pos_y+8, pos_z+61, block_id)
mc.setBlock(pos_x+67, pos_y+8, pos_z+61, block_id)
mc.setBlock(pos_x+66, pos_y+8, pos_z+61, block_id)
mc.setBlock(pos_x+65, pos_y+8, pos_z+61, block_id)
mc.setBlock(pos_x+64, pos_y+8, pos_z+61, block_id)
mc.setBlock(pos_x+61, pos_y+8, pos_z+61, block_id)
mc.setBlock(pos_x+70, pos_y+10, pos_z+70, block_id)
mc.setBlock(pos_x+71, pos_y+10, pos_z+70, block_id)
mc.setBlock(pos_x+72, pos_y+10, pos_z+70, block_id)
mc.setBlock(pos_x+73, pos_y+10, pos_z+70, block_id)
mc.setBlock(pos_x+74, pos_y+10, pos_z+70, block_id)
mc.setBlock(pos_x+38, pos_y+8, pos_z+61, block_id)
mc.setBlock(pos_x+35, pos_y+8, pos_z+61, block_id)
mc.setBlock(pos_x+34, pos_y+8, pos_z+61, block_id)
mc.setBlock(pos_x+33, pos_y+8, pos_z+61, block_id)
