from mcpi.minecraft import Minecraft
mc = Minecraft.create()
x = 100
y = 30
z = 100
a = 42
mc.setBlock(x+1,y+ 47,z+ 65, a)
mc.setBlock(x+87,y+ 46,z+ 65, a)
mc.setBlock(x+1,y+ 46,z+ 65, a)
mc.setBlock(x+87,y+ 45,z+ 65, a)
mc.setBlock(x+1,y+ 45,z+ 65, a)
mc.setBlock(x+87,y+ 44,z+ 65, a)
mc.setBlock(x+1,y+ 44,z+ 65, a)
mc.setBlock(x+87,y+ 43,z+ 65, a)
mc.setBlock(x+1,y+ 43,z+ 65, a)
mc.setBlock(x+87,y+ 42,z+ 65, a)
mc.setBlock(x+1,y+ 42,z+ 65, a)
mc.setBlock(x+87,y+ 41,z+ 65, a)
mc.setBlock(x+1,y+ 41,z+ 65, a)
mc.setBlock(x+87,y+ 40,z+ 65, a)
mc.setBlock(x+1,y+ 40,z+ 65, a)
mc.setBlock(x+87,y+ 39,z+ 65, a)
mc.setBlock(x+87,y+ 47,z+ 65, a)
mc.setBlock(x+1,y+ 48,z+ 65, a)
mc.setBlock(x+1,y+ 39,z+ 65, a)
mc.setBlock(x+87,y+ 38,z+ 65, a)
mc.setBlock(x+87,y+ 48,z+ 65, a)
mc.setBlock(x+1,y+ 49,z+ 65, a)
mc.setBlock(x+1,y+ 38,z+ 65, a)
mc.setBlock(x+87,y+ 37,z+ 65, a)
mc.setBlock(x+87,y+ 49,z+ 65, a)
mc.setBlock(x+1,y+ 50,z+ 65, a)
mc.setBlock(x+1,y+ 37,z+ 65, a)
mc.setBlock(x+86,y+ 36,z+ 65, a)
mc.setBlock(x+2,y+ 36,z+ 65, a)
mc.setBlock(x+86,y+ 35,z+ 65, a)
mc.setBlock(x+2,y+ 35,z+ 65, a)
mc.setBlock(x+86,y+ 34,z+ 65, a)
mc.setBlock(x+2,y+ 34,z+ 65, a)
mc.setBlock(x+86,y+ 33,z+ 65, a)
mc.setBlock(x+87,y+ 50,z+ 65, a)
mc.setBlock(x+1,y+ 51,z+ 65, a)
mc.setBlock(x+2,y+ 33,z+ 65, a)
mc.setBlock(x+86,y+ 32,z+ 65, a)
mc.setBlock(x+87,y+ 51,z+ 65, a)
mc.setBlock(x+2,y+ 52,z+ 65, a)
mc.setBlock(x+2,y+ 32,z+ 65, a)
mc.setBlock(x+85,y+ 31,z+ 65, a)
mc.setBlock(x+3,y+ 31,z+ 65, a)
mc.setBlock(x+85,y+ 30,z+ 65, a)
mc.setBlock(x+3,y+ 30,z+ 65, a)
mc.setBlock(x+85,y+ 29,z+ 65, a)
mc.setBlock(x+86,y+ 52,z+ 65, a)
mc.setBlock(x+2,y+ 53,z+ 65, a)
mc.setBlock(x+3,y+ 29,z+ 65, a)
mc.setBlock(x+84,y+ 28,z+ 65, a)
mc.setBlock(x+4,y+ 28,z+ 65, a)
mc.setBlock(x+84,y+ 27,z+ 65, a)
mc.setBlock(x+4,y+ 27,z+ 65, a)
mc.setBlock(x+84,y+ 26,z+ 65, a)
mc.setBlock(x+86,y+ 53,z+ 65, a)
mc.setBlock(x+2,y+ 54,z+ 65, a)
mc.setBlock(x+4,y+ 26,z+ 65, a)
mc.setBlock(x+83,y+ 25,z+ 65, a)
mc.setBlock(x+5,y+ 25,z+ 65, a)
mc.setBlock(x+83,y+ 24,z+ 65, a)
mc.setBlock(x+86,y+ 54,z+ 65, a)
mc.setBlock(x+2,y+ 55,z+ 65, a)
mc.setBlock(x+5,y+ 24,z+ 65, a)
mc.setBlock(x+83,y+ 23,z+ 65, a)
mc.setBlock(x+86,y+ 55,z+ 65, a)
mc.setBlock(x+2,y+ 56,z+ 65, a)
mc.setBlock(x+5,y+ 23,z+ 65, a)
mc.setBlock(x+82,y+ 22,z+ 65, a)
mc.setBlock(x+86,y+ 56,z+ 65, a)
mc.setBlock(x+3,y+ 57,z+ 65, a)
mc.setBlock(x+6,y+ 22,z+ 65, a)
mc.setBlock(x+81,y+ 21,z+ 65, a)
mc.setBlock(x+7,y+ 21,z+ 65, a)
mc.setBlock(x+81,y+ 20,z+ 65, a)
mc.setBlock(x+85,y+ 57,z+ 65, a)
mc.setBlock(x+3,y+ 58,z+ 65, a)
mc.setBlock(x+7,y+ 20,z+ 65, a)
mc.setBlock(x+80,y+ 19,z+ 65, a)
mc.setBlock(x+85,y+ 58,z+ 65, a)
mc.setBlock(x+8,y+ 19,z+ 65, a)
mc.setBlock(x+80,y+ 18,z+ 65, a)
mc.setBlock(x+3,y+ 59,z+ 65, a)
mc.setBlock(x+85,y+ 59,z+ 65, a)
mc.setBlock(x+8,y+ 18,z+ 65, a)
mc.setBlock(x+79,y+ 17,z+ 65, a)
mc.setBlock(x+4,y+ 60,z+ 65, a)
mc.setBlock(x+84,y+ 60,z+ 65, a)
mc.setBlock(x+9,y+ 17,z+ 65, a)
mc.setBlock(x+78,y+ 16,z+ 65, a)
mc.setBlock(x+4,y+ 61,z+ 65, a)
mc.setBlock(x+84,y+ 61,z+ 65, a)
mc.setBlock(x+10,y+ 16,z+ 65, a)
mc.setBlock(x+77,y+ 15,z+ 65, a)
mc.setBlock(x+4,y+ 62,z+ 65, a)
mc.setBlock(x+84,y+ 62,z+ 65, a)
mc.setBlock(x+11,y+ 15,z+ 65, a)
mc.setBlock(x+77,y+ 14,z+ 65, a)
mc.setBlock(x+5,y+ 63,z+ 65, a)
mc.setBlock(x+83,y+ 63,z+ 65, a)
mc.setBlock(x+11,y+ 14,z+ 65, a)
mc.setBlock(x+76,y+ 13,z+ 65, a)
mc.setBlock(x+5,y+ 64,z+ 65, a)
mc.setBlock(x+83,y+ 64,z+ 65, a)
mc.setBlock(x+12,y+ 13,z+ 65, a)
mc.setBlock(x+75,y+ 12,z+ 65, a)
mc.setBlock(x+5,y+ 65,z+ 65, a)
mc.setBlock(x+83,y+ 65,z+ 65, a)
mc.setBlock(x+6,y+ 66,z+ 65, a)
mc.setBlock(x+82,y+ 66,z+ 65, a)
mc.setBlock(x+13,y+ 12,z+ 65, a)
mc.setBlock(x+74,y+ 11,z+ 65, a)
mc.setBlock(x+7,y+ 67,z+ 65, a)
mc.setBlock(x+81,y+ 67,z+ 65, a)
mc.setBlock(x+7,y+ 68,z+ 65, a)
mc.setBlock(x+81,y+ 68,z+ 65, a)
mc.setBlock(x+14,y+ 11,z+ 65, a)
mc.setBlock(x+73,y+ 10,z+ 65, a)
mc.setBlock(x+72,y+ 10,z+ 65, a)
mc.setBlock(x+8,y+ 69,z+ 65, a)
mc.setBlock(x+80,y+ 69,z+ 65, a)
mc.setBlock(x+16,y+ 10,z+ 65, a)
mc.setBlock(x+15,y+ 10,z+ 65, a)
mc.setBlock(x+71,y+ 9,z+ 65, a)
mc.setBlock(x+8,y+ 70,z+ 65, a)
mc.setBlock(x+80,y+ 70,z+ 65, a)
mc.setBlock(x+17,y+ 9,z+ 65, a)
mc.setBlock(x+70,y+ 8,z+ 65, a)
mc.setBlock(x+69,y+ 8,z+ 65, a)
mc.setBlock(x+9,y+ 71,z+ 65, a)
mc.setBlock(x+79,y+ 71,z+ 65, a)
mc.setBlock(x+19,y+ 8,z+ 65, a)
mc.setBlock(x+18,y+ 8,z+ 65, a)
mc.setBlock(x+68,y+ 7,z+ 65, a)
mc.setBlock(x+10,y+ 72,z+ 65, a)
mc.setBlock(x+78,y+ 72,z+ 65, a)
mc.setBlock(x+11,y+ 73,z+ 65, a)
mc.setBlock(x+77,y+ 73,z+ 65, a)
mc.setBlock(x+20,y+ 7,z+ 65, a)
mc.setBlock(x+67,y+ 6,z+ 65, a)
mc.setBlock(x+66,y+ 6,z+ 65, a)
mc.setBlock(x+11,y+ 74,z+ 65, a)
mc.setBlock(x+77,y+ 74,z+ 65, a)
mc.setBlock(x+12,y+ 75,z+ 65, a)
mc.setBlock(x+76,y+ 75,z+ 65, a)
mc.setBlock(x+22,y+ 6,z+ 65, a)
mc.setBlock(x+21,y+ 6,z+ 65, a)
mc.setBlock(x+65,y+ 5,z+ 65, a)
mc.setBlock(x+64,y+ 5,z+ 65, a)
mc.setBlock(x+13,y+ 76,z+ 65, a)
mc.setBlock(x+75,y+ 76,z+ 65, a)
mc.setBlock(x+14,y+ 77,z+ 65, a)
mc.setBlock(x+74,y+ 77,z+ 65, a)
mc.setBlock(x+24,y+ 5,z+ 65, a)
mc.setBlock(x+23,y+ 5,z+ 65, a)
mc.setBlock(x+63,y+ 4,z+ 65, a)
mc.setBlock(x+62,y+ 4,z+ 65, a)
mc.setBlock(x+61,y+ 4,z+ 65, a)
mc.setBlock(x+15,y+ 78,z+ 65, a)
mc.setBlock(x+16,y+ 78,z+ 65, a)
mc.setBlock(x+72,y+ 78,z+ 65, a)
mc.setBlock(x+73,y+ 78,z+ 65, a)
mc.setBlock(x+27,y+ 4,z+ 65, a)
mc.setBlock(x+26,y+ 4,z+ 65, a)
mc.setBlock(x+25,y+ 4,z+ 65, a)
mc.setBlock(x+60,y+ 3,z+ 65, a)
mc.setBlock(x+59,y+ 3,z+ 65, a)
mc.setBlock(x+58,y+ 3,z+ 65, a)
mc.setBlock(x+17,y+ 79,z+ 65, a)
mc.setBlock(x+71,y+ 79,z+ 65, a)
mc.setBlock(x+18,y+ 80,z+ 65, a)
mc.setBlock(x+19,y+ 80,z+ 65, a)
mc.setBlock(x+30,y+ 3,z+ 65, a)
mc.setBlock(x+29,y+ 3,z+ 65, a)
mc.setBlock(x+28,y+ 3,z+ 65, a)
mc.setBlock(x+57,y+ 2,z+ 65, a)
mc.setBlock(x+56,y+ 2,z+ 65, a)
mc.setBlock(x+55,y+ 2,z+ 65, a)
mc.setBlock(x+54,y+ 2,z+ 65, a)
mc.setBlock(x+53,y+ 2,z+ 65, a)
mc.setBlock(x+69,y+ 80,z+ 65, a)
mc.setBlock(x+70,y+ 80,z+ 65, a)
mc.setBlock(x+20,y+ 81,z+ 65, a)
mc.setBlock(x+68,y+ 81,z+ 65, a)
mc.setBlock(x+35,y+ 2,z+ 65, a)
mc.setBlock(x+34,y+ 2,z+ 65, a)
mc.setBlock(x+33,y+ 2,z+ 65, a)
mc.setBlock(x+32,y+ 2,z+ 65, a)
mc.setBlock(x+31,y+ 2,z+ 65, a)
mc.setBlock(x+52,y+ 1,z+ 65, a)
mc.setBlock(x+51,y+ 1,z+ 65, a)
mc.setBlock(x+50,y+ 1,z+ 65, a)
mc.setBlock(x+49,y+ 1,z+ 65, a)
mc.setBlock(x+48,y+ 1,z+ 65, a)
mc.setBlock(x+47,y+ 1,z+ 65, a)
mc.setBlock(x+46,y+ 1,z+ 65, a)
mc.setBlock(x+45,y+ 1,z+ 65, a)
mc.setBlock(x+44,y+ 1,z+ 65, a)
mc.setBlock(x+43,y+ 1,z+ 65, a)
mc.setBlock(x+42,y+ 1,z+ 65, a)
mc.setBlock(x+41,y+ 1,z+ 65, a)
mc.setBlock(x+40,y+ 1,z+ 65, a)
mc.setBlock(x+39,y+ 1,z+ 65, a)
mc.setBlock(x+38,y+ 1,z+ 65, a)
mc.setBlock(x+37,y+ 1,z+ 65, a)
mc.setBlock(x+36,y+ 1,z+ 65, a)
mc.setBlock(x+53,y+ 87,z+ 64, a)
mc.setBlock(x+52,y+ 87,z+ 64, a)
mc.setBlock(x+51,y+ 87,z+ 64, a)
mc.setBlock(x+50,y+ 87,z+ 64, a)
mc.setBlock(x+49,y+ 87,z+ 64, a)
mc.setBlock(x+48,y+ 87,z+ 64, a)
mc.setBlock(x+47,y+ 87,z+ 64, a)
mc.setBlock(x+46,y+ 87,z+ 64, a)
mc.setBlock(x+45,y+ 87,z+ 64, a)
mc.setBlock(x+44,y+ 87,z+ 64, a)
mc.setBlock(x+43,y+ 87,z+ 64, a)
mc.setBlock(x+42,y+ 87,z+ 64, a)
mc.setBlock(x+41,y+ 87,z+ 64, a)
mc.setBlock(x+40,y+ 87,z+ 64, a)
mc.setBlock(x+39,y+ 87,z+ 64, a)
mc.setBlock(x+38,y+ 87,z+ 64, a)
mc.setBlock(x+37,y+ 87,z+ 64, a)
mc.setBlock(x+36,y+ 87,z+ 64, a)
mc.setBlock(x+35,y+ 87,z+ 64, a)
mc.setBlock(x+57,y+ 86,z+ 64, a)
mc.setBlock(x+56,y+ 86,z+ 64, a)
mc.setBlock(x+55,y+ 86,z+ 64, a)
mc.setBlock(x+54,y+ 86,z+ 64, a)
mc.setBlock(x+21,y+ 82,z+ 65, a)
mc.setBlock(x+22,y+ 82,z+ 65, a)
mc.setBlock(x+66,y+ 82,z+ 65, a)
mc.setBlock(x+67,y+ 82,z+ 65, a)
mc.setBlock(x+34,y+ 86,z+ 64, a)
mc.setBlock(x+33,y+ 86,z+ 64, a)
mc.setBlock(x+32,y+ 86,z+ 64, a)
mc.setBlock(x+31,y+ 86,z+ 64, a)
mc.setBlock(x+60,y+ 85,z+ 64, a)
mc.setBlock(x+59,y+ 85,z+ 64, a)
mc.setBlock(x+58,y+ 85,z+ 64, a)
mc.setBlock(x+23,y+ 83,z+ 65, a)
mc.setBlock(x+24,y+ 83,z+ 65, a)
mc.setBlock(x+30,y+ 85,z+ 64, a)
mc.setBlock(x+29,y+ 85,z+ 64, a)
mc.setBlock(x+28,y+ 85,z+ 64, a)
mc.setBlock(x+63,y+ 84,z+ 64, a)
mc.setBlock(x+62,y+ 84,z+ 64, a)
mc.setBlock(x+61,y+ 84,z+ 64, a)
mc.setBlock(x+64,y+ 83,z+ 65, a)
mc.setBlock(x+65,y+ 83,z+ 65, a)
mc.setBlock(x+27,y+ 84,z+ 64, a)
mc.setBlock(x+26,y+ 84,z+ 64, a)
mc.setBlock(x+25,y+ 84,z+ 64, a)
mc.setBlock(x+65,y+ 83,z+ 64, a)
mc.setBlock(x+64,y+ 83,z+ 64, a)
mc.setBlock(x+25,y+ 84,z+ 65, a)
mc.setBlock(x+26,y+ 84,z+ 65, a)
mc.setBlock(x+24,y+ 83,z+ 64, a)
mc.setBlock(x+23,y+ 83,z+ 64, a)
mc.setBlock(x+67,y+ 82,z+ 64, a)
mc.setBlock(x+66,y+ 82,z+ 64, a)
mc.setBlock(x+27,y+ 84,z+ 65, a)
mc.setBlock(x+61,y+ 84,z+ 65, a)
mc.setBlock(x+22,y+ 82,z+ 64, a)
mc.setBlock(x+21,y+ 82,z+ 64, a)
mc.setBlock(x+69,y+ 81,z+ 64, a)
mc.setBlock(x+68,y+ 81,z+ 64, a)
mc.setBlock(x+62,y+ 84,z+ 65, a)
mc.setBlock(x+63,y+ 84,z+ 65, a)
mc.setBlock(x+20,y+ 81,z+ 64, a)
mc.setBlock(x+19,y+ 81,z+ 64, a)
mc.setBlock(x+70,y+ 80,z+ 64, a)
mc.setBlock(x+28,y+ 85,z+ 65, a)
mc.setBlock(x+29,y+ 85,z+ 65, a)
mc.setBlock(x+18,y+ 80,z+ 64, a)
mc.setBlock(x+72,y+ 79,z+ 64, a)
mc.setBlock(x+71,y+ 79,z+ 64, a)
mc.setBlock(x+30,y+ 85,z+ 65, a)
mc.setBlock(x+58,y+ 85,z+ 65, a)
mc.setBlock(x+17,y+ 79,z+ 64, a)
mc.setBlock(x+16,y+ 79,z+ 64, a)
mc.setBlock(x+73,y+ 78,z+ 64, a)
mc.setBlock(x+59,y+ 85,z+ 65, a)
mc.setBlock(x+60,y+ 85,z+ 65, a)
mc.setBlock(x+31,y+ 86,z+ 65, a)
mc.setBlock(x+32,y+ 86,z+ 65, a)
mc.setBlock(x+15,y+ 78,z+ 64, a)
mc.setBlock(x+74,y+ 77,z+ 64, a)
mc.setBlock(x+33,y+ 86,z+ 65, a)
mc.setBlock(x+34,y+ 86,z+ 65, a)
mc.setBlock(x+14,y+ 77,z+ 64, a)
mc.setBlock(x+75,y+ 76,z+ 64, a)
mc.setBlock(x+35,y+ 86,z+ 65, a)
mc.setBlock(x+53,y+ 86,z+ 65, a)
mc.setBlock(x+13,y+ 76,z+ 64, a)
mc.setBlock(x+76,y+ 75,z+ 64, a)
mc.setBlock(x+54,y+ 86,z+ 65, a)
mc.setBlock(x+55,y+ 86,z+ 65, a)
mc.setBlock(x+12,y+ 75,z+ 64, a)
mc.setBlock(x+77,y+ 74,z+ 64, a)
mc.setBlock(x+56,y+ 86,z+ 65, a)
mc.setBlock(x+57,y+ 86,z+ 65, a)
mc.setBlock(x+11,y+ 74,z+ 64, a)
mc.setBlock(x+78,y+ 73,z+ 64, a)
mc.setBlock(x+36,y+ 87,z+ 65, a)
mc.setBlock(x+37,y+ 87,z+ 65, a)
mc.setBlock(x+10,y+ 73,z+ 64, a)
mc.setBlock(x+79,y+ 72,z+ 64, a)
mc.setBlock(x+38,y+ 87,z+ 65, a)
mc.setBlock(x+39,y+ 87,z+ 65, a)
mc.setBlock(x+9,y+ 72,z+ 64, a)
mc.setBlock(x+79,y+ 71,z+ 64, a)
mc.setBlock(x+40,y+ 87,z+ 65, a)
mc.setBlock(x+41,y+ 87,z+ 65, a)
mc.setBlock(x+9,y+ 71,z+ 64, a)
mc.setBlock(x+80,y+ 70,z+ 64, a)
mc.setBlock(x+42,y+ 87,z+ 65, a)
mc.setBlock(x+43,y+ 87,z+ 65, a)
mc.setBlock(x+8,y+ 70,z+ 64, a)
mc.setBlock(x+81,y+ 69,z+ 64, a)
mc.setBlock(x+44,y+ 87,z+ 65, a)
mc.setBlock(x+45,y+ 87,z+ 65, a)
mc.setBlock(x+7,y+ 69,z+ 64, a)
mc.setBlock(x+81,y+ 68,z+ 64, a)
mc.setBlock(x+46,y+ 87,z+ 65, a)
mc.setBlock(x+47,y+ 87,z+ 65, a)
mc.setBlock(x+7,y+ 68,z+ 64, a)
mc.setBlock(x+82,y+ 67,z+ 64, a)
mc.setBlock(x+48,y+ 87,z+ 65, a)
mc.setBlock(x+49,y+ 87,z+ 65, a)
mc.setBlock(x+6,y+ 67,z+ 64, a)
mc.setBlock(x+82,y+ 66,z+ 64, a)
mc.setBlock(x+6,y+ 66,z+ 64, a)
mc.setBlock(x+83,y+ 65,z+ 64, a)
mc.setBlock(x+50,y+ 87,z+ 65, a)
mc.setBlock(x+51,y+ 87,z+ 65, a)
mc.setBlock(x+5,y+ 65,z+ 64, a)
mc.setBlock(x+83,y+ 64,z+ 64, a)
mc.setBlock(x+5,y+ 64,z+ 64, a)
mc.setBlock(x+84,y+ 63,z+ 64, a)
mc.setBlock(x+52,y+ 87,z+ 65, a)
mc.setBlock(x+37,y+ 1,z+ 66, a)
mc.setBlock(x+4,y+ 63,z+ 64, a)
mc.setBlock(x+84,y+ 62,z+ 64, a)
mc.setBlock(x+38,y+ 1,z+ 66, a)
mc.setBlock(x+39,y+ 1,z+ 66, a)
mc.setBlock(x+4,y+ 62,z+ 64, a)
mc.setBlock(x+84,y+ 61,z+ 64, a)
mc.setBlock(x+4,y+ 61,z+ 64, a)
mc.setBlock(x+85,y+ 60,z+ 64, a)
mc.setBlock(x+40,y+ 1,z+ 66, a)
mc.setBlock(x+41,y+ 1,z+ 66, a)
mc.setBlock(x+3,y+ 60,z+ 64, a)
mc.setBlock(x+85,y+ 59,z+ 64, a)
mc.setBlock(x+3,y+ 59,z+ 64, a)
mc.setBlock(x+85,y+ 58,z+ 64, a)
mc.setBlock(x+3,y+ 58,z+ 64, a)
mc.setBlock(x+86,y+ 57,z+ 64, a)
mc.setBlock(x+42,y+ 1,z+ 66, a)
mc.setBlock(x+43,y+ 1,z+ 66, a)
mc.setBlock(x+2,y+ 57,z+ 64, a)
mc.setBlock(x+86,y+ 56,z+ 64, a)
mc.setBlock(x+44,y+ 1,z+ 66, a)
mc.setBlock(x+45,y+ 1,z+ 66, a)
mc.setBlock(x+2,y+ 56,z+ 64, a)
mc.setBlock(x+86,y+ 55,z+ 64, a)
mc.setBlock(x+2,y+ 55,z+ 64, a)
mc.setBlock(x+86,y+ 54,z+ 64, a)
mc.setBlock(x+2,y+ 54,z+ 64, a)
mc.setBlock(x+86,y+ 53,z+ 64, a)
mc.setBlock(x+2,y+ 53,z+ 64, a)
mc.setBlock(x+87,y+ 52,z+ 64, a)
mc.setBlock(x+46,y+ 1,z+ 66, a)
mc.setBlock(x+47,y+ 1,z+ 66, a)
mc.setBlock(x+1,y+ 52,z+ 64, a)
mc.setBlock(x+87,y+ 51,z+ 64, a)
mc.setBlock(x+48,y+ 1,z+ 66, a)
mc.setBlock(x+49,y+ 1,z+ 66, a)
mc.setBlock(x+1,y+ 51,z+ 64, a)
mc.setBlock(x+87,y+ 50,z+ 64, a)
mc.setBlock(x+1,y+ 50,z+ 64, a)
mc.setBlock(x+87,y+ 49,z+ 64, a)
mc.setBlock(x+1,y+ 49,z+ 64, a)
mc.setBlock(x+87,y+ 48,z+ 64, a)
mc.setBlock(x+1,y+ 48,z+ 64, a)
mc.setBlock(x+87,y+ 47,z+ 64, a)
mc.setBlock(x+1,y+ 47,z+ 64, a)
mc.setBlock(x+87,y+ 46,z+ 64, a)
mc.setBlock(x+1,y+ 46,z+ 64, a)
mc.setBlock(x+87,y+ 45,z+ 64, a)
mc.setBlock(x+1,y+ 45,z+ 64, a)
mc.setBlock(x+87,y+ 44,z+ 64, a)
mc.setBlock(x+1,y+ 44,z+ 64, a)
mc.setBlock(x+87,y+ 43,z+ 64, a)
mc.setBlock(x+1,y+ 43,z+ 64, a)
mc.setBlock(x+87,y+ 42,z+ 64, a)
mc.setBlock(x+1,y+ 42,z+ 64, a)
mc.setBlock(x+87,y+ 41,z+ 64, a)
mc.setBlock(x+1,y+ 41,z+ 64, a)
mc.setBlock(x+87,y+ 40,z+ 64, a)
mc.setBlock(x+1,y+ 40,z+ 64, a)
mc.setBlock(x+87,y+ 39,z+ 64, a)
mc.setBlock(x+1,y+ 39,z+ 64, a)
mc.setBlock(x+87,y+ 38,z+ 64, a)
mc.setBlock(x+1,y+ 38,z+ 64, a)
mc.setBlock(x+87,y+ 37,z+ 64, a)
mc.setBlock(x+50,y+ 1,z+ 66, a)
mc.setBlock(x+51,y+ 1,z+ 66, a)
mc.setBlock(x+1,y+ 37,z+ 64, a)
mc.setBlock(x+87,y+ 36,z+ 64, a)
mc.setBlock(x+32,y+ 2,z+ 66, a)
mc.setBlock(x+33,y+ 2,z+ 66, a)
mc.setBlock(x+1,y+ 36,z+ 64, a)
mc.setBlock(x+86,y+ 35,z+ 64, a)
mc.setBlock(x+2,y+ 35,z+ 64, a)
mc.setBlock(x+86,y+ 34,z+ 64, a)
mc.setBlock(x+2,y+ 34,z+ 64, a)
mc.setBlock(x+86,y+ 33,z+ 64, a)
mc.setBlock(x+2,y+ 33,z+ 64, a)
mc.setBlock(x+86,y+ 32,z+ 64, a)
mc.setBlock(x+34,y+ 2,z+ 66, a)
mc.setBlock(x+35,y+ 2,z+ 66, a)
mc.setBlock(x+2,y+ 32,z+ 64, a)
mc.setBlock(x+86,y+ 31,z+ 64, a)
mc.setBlock(x+36,y+ 2,z+ 66, a)
mc.setBlock(x+52,y+ 2,z+ 66, a)
mc.setBlock(x+2,y+ 31,z+ 64, a)
mc.setBlock(x+85,y+ 30,z+ 64, a)
mc.setBlock(x+3,y+ 30,z+ 64, a)
mc.setBlock(x+85,y+ 29,z+ 64, a)
mc.setBlock(x+3,y+ 29,z+ 64, a)
mc.setBlock(x+85,y+ 28,z+ 64, a)
mc.setBlock(x+53,y+ 2,z+ 66, a)
mc.setBlock(x+54,y+ 2,z+ 66, a)
mc.setBlock(x+3,y+ 28,z+ 64, a)
mc.setBlock(x+84,y+ 27,z+ 64, a)
mc.setBlock(x+4,y+ 27,z+ 64, a)
mc.setBlock(x+84,y+ 26,z+ 64, a)
mc.setBlock(x+55,y+ 2,z+ 66, a)
mc.setBlock(x+56,y+ 2,z+ 66, a)
mc.setBlock(x+4,y+ 26,z+ 64, a)
mc.setBlock(x+84,y+ 25,z+ 64, a)
mc.setBlock(x+29,y+ 3,z+ 66, a)
mc.setBlock(x+30,y+ 3,z+ 66, a)
mc.setBlock(x+4,y+ 25,z+ 64, a)
mc.setBlock(x+83,y+ 24,z+ 64, a)
mc.setBlock(x+5,y+ 24,z+ 64, a)
mc.setBlock(x+83,y+ 23,z+ 64, a)
mc.setBlock(x+31,y+ 3,z+ 66, a)
mc.setBlock(x+57,y+ 3,z+ 66, a)
mc.setBlock(x+5,y+ 23,z+ 64, a)
mc.setBlock(x+82,y+ 22,z+ 64, a)
mc.setBlock(x+6,y+ 22,z+ 64, a)
mc.setBlock(x+82,y+ 21,z+ 64, a)
mc.setBlock(x+58,y+ 3,z+ 66, a)
mc.setBlock(x+59,y+ 3,z+ 66, a)
mc.setBlock(x+6,y+ 21,z+ 64, a)
mc.setBlock(x+81,y+ 20,z+ 64, a)
mc.setBlock(x+26,y+ 4,z+ 66, a)
mc.setBlock(x+27,y+ 4,z+ 66, a)
mc.setBlock(x+7,y+ 20,z+ 64, a)
mc.setBlock(x+81,y+ 19,z+ 64, a)
mc.setBlock(x+28,y+ 4,z+ 66, a)
mc.setBlock(x+60,y+ 4,z+ 66, a)
mc.setBlock(x+7,y+ 19,z+ 64, a)
mc.setBlock(x+80,y+ 18,z+ 64, a)
mc.setBlock(x+61,y+ 4,z+ 66, a)
mc.setBlock(x+62,y+ 4,z+ 66, a)
mc.setBlock(x+8,y+ 18,z+ 64, a)
mc.setBlock(x+79,y+ 17,z+ 64, a)
mc.setBlock(x+24,y+ 5,z+ 66, a)
mc.setBlock(x+25,y+ 5,z+ 66, a)
mc.setBlock(x+9,y+ 17,z+ 64, a)
mc.setBlock(x+79,y+ 16,z+ 64, a)
mc.setBlock(x+63,y+ 5,z+ 66, a)
mc.setBlock(x+64,y+ 5,z+ 66, a)
mc.setBlock(x+9,y+ 16,z+ 64, a)
mc.setBlock(x+78,y+ 15,z+ 64, a)
mc.setBlock(x+22,y+ 6,z+ 66, a)
mc.setBlock(x+23,y+ 6,z+ 66, a)
mc.setBlock(x+10,y+ 15,z+ 64, a)
mc.setBlock(x+77,y+ 14,z+ 64, a)
mc.setBlock(x+65,y+ 6,z+ 66, a)
mc.setBlock(x+66,y+ 6,z+ 66, a)
mc.setBlock(x+11,y+ 14,z+ 64, a)
mc.setBlock(x+76,y+ 13,z+ 64, a)
mc.setBlock(x+20,y+ 7,z+ 66, a)
mc.setBlock(x+21,y+ 7,z+ 66, a)
mc.setBlock(x+12,y+ 13,z+ 64, a)
mc.setBlock(x+75,y+ 12,z+ 64, a)
mc.setBlock(x+67,y+ 7,z+ 66, a)
mc.setBlock(x+68,y+ 7,z+ 66, a)
mc.setBlock(x+13,y+ 12,z+ 64, a)
mc.setBlock(x+74,y+ 11,z+ 64, a)
mc.setBlock(x+19,y+ 8,z+ 66, a)
mc.setBlock(x+69,y+ 8,z+ 66, a)
mc.setBlock(x+14,y+ 11,z+ 64, a)
mc.setBlock(x+73,y+ 10,z+ 64, a)
mc.setBlock(x+70,y+ 8,z+ 66, a)
mc.setBlock(x+17,y+ 9,z+ 66, a)
mc.setBlock(x+18,y+ 9,z+ 66, a)
mc.setBlock(x+71,y+ 9,z+ 66, a)
mc.setBlock(x+15,y+ 10,z+ 64, a)
mc.setBlock(x+72,y+ 9,z+ 64, a)
mc.setBlock(x+71,y+ 9,z+ 64, a)
mc.setBlock(x+16,y+ 10,z+ 66, a)
mc.setBlock(x+72,y+ 10,z+ 66, a)
mc.setBlock(x+17,y+ 9,z+ 64, a)
mc.setBlock(x+16,y+ 9,z+ 64, a)
mc.setBlock(x+70,y+ 8,z+ 64, a)
mc.setBlock(x+15,y+ 11,z+ 66, a)
mc.setBlock(x+73,y+ 11,z+ 66, a)
mc.setBlock(x+18,y+ 8,z+ 64, a)
mc.setBlock(x+69,y+ 7,z+ 64, a)
mc.setBlock(x+68,y+ 7,z+ 64, a)
mc.setBlock(x+14,y+ 12,z+ 66, a)
mc.setBlock(x+74,y+ 12,z+ 66, a)
mc.setBlock(x+20,y+ 7,z+ 64, a)
mc.setBlock(x+19,y+ 7,z+ 64, a)
mc.setBlock(x+67,y+ 6,z+ 64, a)
mc.setBlock(x+66,y+ 6,z+ 64, a)
mc.setBlock(x+13,y+ 13,z+ 66, a)
mc.setBlock(x+75,y+ 13,z+ 66, a)
mc.setBlock(x+22,y+ 6,z+ 64, a)
mc.setBlock(x+21,y+ 6,z+ 64, a)
mc.setBlock(x+65,y+ 5,z+ 64, a)
mc.setBlock(x+64,y+ 5,z+ 64, a)
mc.setBlock(x+12,y+ 14,z+ 66, a)
mc.setBlock(x+76,y+ 14,z+ 66, a)
mc.setBlock(x+24,y+ 5,z+ 64, a)
mc.setBlock(x+23,y+ 5,z+ 64, a)
mc.setBlock(x+63,y+ 4,z+ 64, a)
mc.setBlock(x+62,y+ 4,z+ 64, a)
mc.setBlock(x+61,y+ 4,z+ 64, a)
mc.setBlock(x+11,y+ 15,z+ 66, a)
mc.setBlock(x+77,y+ 15,z+ 66, a)
mc.setBlock(x+27,y+ 4,z+ 64, a)
mc.setBlock(x+26,y+ 4,z+ 64, a)
mc.setBlock(x+25,y+ 4,z+ 64, a)
mc.setBlock(x+60,y+ 3,z+ 64, a)
mc.setBlock(x+59,y+ 3,z+ 64, a)
mc.setBlock(x+58,y+ 3,z+ 64, a)
mc.setBlock(x+10,y+ 16,z+ 66, a)
mc.setBlock(x+78,y+ 16,z+ 66, a)
mc.setBlock(x+30,y+ 3,z+ 64, a)
mc.setBlock(x+29,y+ 3,z+ 64, a)
mc.setBlock(x+28,y+ 3,z+ 64, a)
mc.setBlock(x+57,y+ 2,z+ 64, a)
mc.setBlock(x+56,y+ 2,z+ 64, a)
mc.setBlock(x+55,y+ 2,z+ 64, a)
mc.setBlock(x+54,y+ 2,z+ 64, a)
mc.setBlock(x+9,y+ 17,z+ 66, a)
mc.setBlock(x+79,y+ 17,z+ 66, a)
mc.setBlock(x+9,y+ 18,z+ 66, a)
mc.setBlock(x+79,y+ 18,z+ 66, a)
mc.setBlock(x+34,y+ 2,z+ 64, a)
mc.setBlock(x+33,y+ 2,z+ 64, a)
mc.setBlock(x+32,y+ 2,z+ 64, a)
mc.setBlock(x+31,y+ 2,z+ 64, a)
mc.setBlock(x+53,y+ 1,z+ 64, a)
mc.setBlock(x+52,y+ 1,z+ 64, a)
mc.setBlock(x+51,y+ 1,z+ 64, a)
mc.setBlock(x+50,y+ 1,z+ 64, a)
mc.setBlock(x+49,y+ 1,z+ 64, a)
mc.setBlock(x+48,y+ 1,z+ 64, a)
mc.setBlock(x+47,y+ 1,z+ 64, a)
mc.setBlock(x+46,y+ 1,z+ 64, a)
mc.setBlock(x+45,y+ 1,z+ 64, a)
mc.setBlock(x+44,y+ 1,z+ 64, a)
mc.setBlock(x+43,y+ 1,z+ 64, a)
mc.setBlock(x+42,y+ 1,z+ 64, a)
mc.setBlock(x+41,y+ 1,z+ 64, a)
mc.setBlock(x+40,y+ 1,z+ 64, a)
mc.setBlock(x+39,y+ 1,z+ 64, a)
mc.setBlock(x+38,y+ 1,z+ 64, a)
mc.setBlock(x+37,y+ 1,z+ 64, a)
mc.setBlock(x+36,y+ 1,z+ 64, a)
mc.setBlock(x+35,y+ 1,z+ 64, a)
mc.setBlock(x+54,y+ 87,z+ 63, a)
mc.setBlock(x+53,y+ 87,z+ 63, a)
mc.setBlock(x+52,y+ 87,z+ 63, a)
mc.setBlock(x+51,y+ 87,z+ 63, a)
mc.setBlock(x+50,y+ 87,z+ 63, a)
mc.setBlock(x+49,y+ 87,z+ 63, a)
mc.setBlock(x+48,y+ 87,z+ 63, a)
mc.setBlock(x+47,y+ 87,z+ 63, a)
mc.setBlock(x+46,y+ 87,z+ 63, a)
mc.setBlock(x+45,y+ 87,z+ 63, a)
mc.setBlock(x+44,y+ 87,z+ 63, a)
mc.setBlock(x+43,y+ 87,z+ 63, a)
mc.setBlock(x+42,y+ 87,z+ 63, a)
mc.setBlock(x+41,y+ 87,z+ 63, a)
mc.setBlock(x+40,y+ 87,z+ 63, a)
mc.setBlock(x+39,y+ 87,z+ 63, a)
mc.setBlock(x+38,y+ 87,z+ 63, a)
mc.setBlock(x+37,y+ 87,z+ 63, a)
mc.setBlock(x+36,y+ 87,z+ 63, a)
mc.setBlock(x+35,y+ 87,z+ 63, a)
mc.setBlock(x+34,y+ 87,z+ 63, a)
mc.setBlock(x+58,y+ 86,z+ 63, a)
mc.setBlock(x+57,y+ 86,z+ 63, a)
mc.setBlock(x+56,y+ 86,z+ 63, a)
mc.setBlock(x+55,y+ 86,z+ 63, a)
mc.setBlock(x+8,y+ 19,z+ 66, a)
mc.setBlock(x+80,y+ 19,z+ 66, a)
mc.setBlock(x+7,y+ 20,z+ 66, a)
mc.setBlock(x+81,y+ 20,z+ 66, a)
mc.setBlock(x+33,y+ 86,z+ 63, a)
mc.setBlock(x+32,y+ 86,z+ 63, a)
mc.setBlock(x+31,y+ 86,z+ 63, a)
mc.setBlock(x+30,y+ 86,z+ 63, a)
mc.setBlock(x+61,y+ 85,z+ 63, a)
mc.setBlock(x+60,y+ 85,z+ 63, a)
mc.setBlock(x+59,y+ 85,z+ 63, a)
mc.setBlock(x+7,y+ 21,z+ 66, a)
mc.setBlock(x+81,y+ 21,z+ 66, a)
mc.setBlock(x+6,y+ 22,z+ 66, a)
mc.setBlock(x+82,y+ 22,z+ 66, a)
mc.setBlock(x+29,y+ 85,z+ 63, a)
mc.setBlock(x+28,y+ 85,z+ 63, a)
mc.setBlock(x+27,y+ 85,z+ 63, a)
mc.setBlock(x+63,y+ 84,z+ 63, a)
mc.setBlock(x+62,y+ 84,z+ 63, a)
mc.setBlock(x+6,y+ 23,z+ 66, a)
mc.setBlock(x+82,y+ 23,z+ 66, a)
mc.setBlock(x+26,y+ 84,z+ 63, a)
mc.setBlock(x+25,y+ 84,z+ 63, a)
mc.setBlock(x+65,y+ 83,z+ 63, a)
mc.setBlock(x+64,y+ 83,z+ 63, a)
mc.setBlock(x+5,y+ 24,z+ 66, a)
mc.setBlock(x+83,y+ 24,z+ 66, a)
mc.setBlock(x+24,y+ 83,z+ 63, a)
mc.setBlock(x+23,y+ 83,z+ 63, a)
mc.setBlock(x+22,y+ 83,z+ 63, a)
mc.setBlock(x+67,y+ 82,z+ 63, a)
mc.setBlock(x+66,y+ 82,z+ 63, a)
mc.setBlock(x+5,y+ 25,z+ 66, a)
mc.setBlock(x+83,y+ 25,z+ 66, a)
mc.setBlock(x+4,y+ 26,z+ 66, a)
mc.setBlock(x+21,y+ 82,z+ 63, a)
mc.setBlock(x+69,y+ 81,z+ 63, a)
mc.setBlock(x+68,y+ 81,z+ 63, a)
mc.setBlock(x+84,y+ 26,z+ 66, a)
mc.setBlock(x+4,y+ 27,z+ 66, a)
mc.setBlock(x+20,y+ 81,z+ 63, a)
mc.setBlock(x+19,y+ 81,z+ 63, a)
mc.setBlock(x+70,y+ 80,z+ 63, a)
mc.setBlock(x+84,y+ 27,z+ 66, a)
mc.setBlock(x+4,y+ 28,z+ 66, a)
mc.setBlock(x+18,y+ 80,z+ 63, a)
mc.setBlock(x+72,y+ 79,z+ 63, a)
mc.setBlock(x+71,y+ 79,z+ 63, a)
mc.setBlock(x+84,y+ 28,z+ 66, a)
mc.setBlock(x+3,y+ 29,z+ 66, a)
mc.setBlock(x+17,y+ 79,z+ 63, a)
mc.setBlock(x+16,y+ 79,z+ 63, a)
mc.setBlock(x+73,y+ 78,z+ 63, a)
mc.setBlock(x+85,y+ 29,z+ 66, a)
mc.setBlock(x+3,y+ 30,z+ 66, a)
mc.setBlock(x+15,y+ 78,z+ 63, a)
mc.setBlock(x+74,y+ 77,z+ 63, a)
mc.setBlock(x+85,y+ 30,z+ 66, a)
mc.setBlock(x+3,y+ 31,z+ 66, a)
mc.setBlock(x+14,y+ 77,z+ 63, a)
mc.setBlock(x+75,y+ 76,z+ 63, a)
mc.setBlock(x+85,y+ 31,z+ 66, a)
mc.setBlock(x+3,y+ 32,z+ 66, a)
mc.setBlock(x+13,y+ 76,z+ 63, a)
mc.setBlock(x+76,y+ 75,z+ 63, a)
mc.setBlock(x+85,y+ 32,z+ 66, a)
mc.setBlock(x+2,y+ 33,z+ 66, a)
mc.setBlock(x+12,y+ 75,z+ 63, a)
mc.setBlock(x+77,y+ 74,z+ 63, a)
mc.setBlock(x+86,y+ 33,z+ 66, a)
mc.setBlock(x+2,y+ 34,z+ 66, a)
mc.setBlock(x+11,y+ 74,z+ 63, a)
mc.setBlock(x+78,y+ 73,z+ 63, a)
mc.setBlock(x+86,y+ 34,z+ 66, a)
mc.setBlock(x+2,y+ 35,z+ 66, a)
mc.setBlock(x+10,y+ 73,z+ 63, a)
mc.setBlock(x+79,y+ 72,z+ 63, a)
mc.setBlock(x+86,y+ 35,z+ 66, a)
mc.setBlock(x+2,y+ 36,z+ 66, a)
mc.setBlock(x+9,y+ 72,z+ 63, a)
mc.setBlock(x+79,y+ 71,z+ 63, a)
mc.setBlock(x+9,y+ 71,z+ 63, a)
mc.setBlock(x+80,y+ 70,z+ 63, a)
mc.setBlock(x+86,y+ 36,z+ 66, a)
mc.setBlock(x+2,y+ 37,z+ 66, a)
mc.setBlock(x+8,y+ 70,z+ 63, a)
mc.setBlock(x+81,y+ 69,z+ 63, a)
mc.setBlock(x+86,y+ 37,z+ 66, a)
mc.setBlock(x+2,y+ 38,z+ 66, a)
mc.setBlock(x+7,y+ 69,z+ 63, a)
mc.setBlock(x+81,y+ 68,z+ 63, a)
mc.setBlock(x+7,y+ 68,z+ 63, a)
mc.setBlock(x+82,y+ 67,z+ 63, a)
mc.setBlock(x+86,y+ 38,z+ 66, a)
mc.setBlock(x+1,y+ 39,z+ 66, a)
mc.setBlock(x+6,y+ 67,z+ 63, a)
mc.setBlock(x+82,y+ 66,z+ 63, a)
mc.setBlock(x+6,y+ 66,z+ 63, a)
mc.setBlock(x+83,y+ 65,z+ 63, a)
mc.setBlock(x+87,y+ 39,z+ 66, a)
mc.setBlock(x+1,y+ 40,z+ 66, a)
mc.setBlock(x+5,y+ 65,z+ 63, a)
mc.setBlock(x+83,y+ 64,z+ 63, a)
mc.setBlock(x+5,y+ 64,z+ 63, a)
mc.setBlock(x+84,y+ 63,z+ 63, a)
mc.setBlock(x+87,y+ 40,z+ 66, a)
mc.setBlock(x+1,y+ 41,z+ 66, a)
mc.setBlock(x+4,y+ 63,z+ 63, a)
mc.setBlock(x+84,y+ 62,z+ 63, a)
mc.setBlock(x+4,y+ 62,z+ 63, a)
mc.setBlock(x+85,y+ 61,z+ 63, a)
mc.setBlock(x+87,y+ 41,z+ 66, a)
mc.setBlock(x+1,y+ 42,z+ 66, a)
mc.setBlock(x+3,y+ 61,z+ 63, a)
mc.setBlock(x+85,y+ 60,z+ 63, a)
mc.setBlock(x+87,y+ 42,z+ 66, a)
mc.setBlock(x+1,y+ 43,z+ 66, a)
mc.setBlock(x+3,y+ 60,z+ 63, a)
mc.setBlock(x+85,y+ 59,z+ 63, a)
mc.setBlock(x+3,y+ 59,z+ 63, a)
mc.setBlock(x+85,y+ 58,z+ 63, a)
mc.setBlock(x+3,y+ 58,z+ 63, a)
mc.setBlock(x+86,y+ 57,z+ 63, a)
mc.setBlock(x+87,y+ 43,z+ 66, a)
mc.setBlock(x+1,y+ 44,z+ 66, a)
mc.setBlock(x+2,y+ 57,z+ 63, a)
mc.setBlock(x+86,y+ 56,z+ 63, a)
mc.setBlock(x+2,y+ 56,z+ 63, a)
mc.setBlock(x+86,y+ 55,z+ 63, a)
mc.setBlock(x+2,y+ 55,z+ 63, a)
mc.setBlock(x+86,y+ 54,z+ 63, a)
mc.setBlock(x+2,y+ 54,z+ 63, a)
mc.setBlock(x+87,y+ 53,z+ 63, a)
mc.setBlock(x+87,y+ 44,z+ 66, a)
mc.setBlock(x+1,y+ 45,z+ 66, a)
mc.setBlock(x+1,y+ 53,z+ 63, a)
mc.setBlock(x+87,y+ 52,z+ 63, a)
mc.setBlock(x+87,y+ 45,z+ 66, a)
mc.setBlock(x+1,y+ 46,z+ 66, a)
mc.setBlock(x+1,y+ 52,z+ 63, a)
mc.setBlock(x+87,y+ 51,z+ 63, a)
mc.setBlock(x+1,y+ 51,z+ 63, a)
mc.setBlock(x+87,y+ 50,z+ 63, a)
mc.setBlock(x+1,y+ 50,z+ 63, a)
mc.setBlock(x+87,y+ 49,z+ 63, a)
mc.setBlock(x+1,y+ 49,z+ 63, a)
mc.setBlock(x+87,y+ 48,z+ 63, a)
mc.setBlock(x+1,y+ 48,z+ 63, a)
mc.setBlock(x+87,y+ 47,z+ 63, a)
mc.setBlock(x+1,y+ 47,z+ 63, a)
mc.setBlock(x+87,y+ 46,z+ 63, a)
mc.setBlock(x+1,y+ 46,z+ 63, a)
mc.setBlock(x+87,y+ 45,z+ 63, a)
mc.setBlock(x+1,y+ 45,z+ 63, a)
mc.setBlock(x+87,y+ 44,z+ 63, a)
mc.setBlock(x+1,y+ 44,z+ 63, a)
mc.setBlock(x+87,y+ 43,z+ 63, a)
mc.setBlock(x+1,y+ 43,z+ 63, a)
mc.setBlock(x+87,y+ 42,z+ 63, a)
mc.setBlock(x+1,y+ 42,z+ 63, a)
mc.setBlock(x+87,y+ 41,z+ 63, a)
mc.setBlock(x+1,y+ 41,z+ 63, a)
mc.setBlock(x+87,y+ 40,z+ 63, a)
mc.setBlock(x+1,y+ 40,z+ 63, a)
mc.setBlock(x+87,y+ 39,z+ 63, a)
mc.setBlock(x+1,y+ 39,z+ 63, a)
mc.setBlock(x+87,y+ 38,z+ 63, a)
mc.setBlock(x+1,y+ 38,z+ 63, a)
mc.setBlock(x+87,y+ 37,z+ 63, a)
mc.setBlock(x+1,y+ 37,z+ 63, a)
mc.setBlock(x+87,y+ 36,z+ 63, a)
mc.setBlock(x+87,y+ 46,z+ 66, a)
mc.setBlock(x+1,y+ 47,z+ 66, a)
mc.setBlock(x+1,y+ 36,z+ 63, a)
mc.setBlock(x+87,y+ 35,z+ 63, a)
mc.setBlock(x+87,y+ 47,z+ 66, a)
mc.setBlock(x+1,y+ 48,z+ 66, a)
mc.setBlock(x+1,y+ 35,z+ 63, a)
mc.setBlock(x+86,y+ 34,z+ 63, a)
mc.setBlock(x+2,y+ 34,z+ 63, a)
mc.setBlock(x+86,y+ 33,z+ 63, a)
mc.setBlock(x+2,y+ 33,z+ 63, a)
mc.setBlock(x+86,y+ 32,z+ 63, a)
mc.setBlock(x+2,y+ 32,z+ 63, a)
mc.setBlock(x+86,y+ 31,z+ 63, a)
mc.setBlock(x+87,y+ 48,z+ 66, a)
mc.setBlock(x+1,y+ 49,z+ 66, a)
mc.setBlock(x+2,y+ 31,z+ 63, a)
mc.setBlock(x+85,y+ 30,z+ 63, a)
mc.setBlock(x+3,y+ 30,z+ 63, a)
mc.setBlock(x+85,y+ 29,z+ 63, a)
mc.setBlock(x+3,y+ 29,z+ 63, a)
mc.setBlock(x+85,y+ 28,z+ 63, a)
mc.setBlock(x+87,y+ 49,z+ 66, a)
mc.setBlock(x+2,y+ 50,z+ 66, a)
mc.setBlock(x+3,y+ 28,z+ 63, a)
mc.setBlock(x+85,y+ 27,z+ 63, a)
mc.setBlock(x+86,y+ 50,z+ 66, a)
mc.setBlock(x+2,y+ 51,z+ 66, a)
mc.setBlock(x+3,y+ 27,z+ 63, a)
mc.setBlock(x+84,y+ 26,z+ 63, a)
mc.setBlock(x+4,y+ 26,z+ 63, a)
mc.setBlock(x+84,y+ 25,z+ 63, a)
mc.setBlock(x+86,y+ 51,z+ 66, a)
mc.setBlock(x+2,y+ 52,z+ 66, a)
mc.setBlock(x+4,y+ 25,z+ 63, a)
mc.setBlock(x+83,y+ 24,z+ 63, a)
mc.setBlock(x+5,y+ 24,z+ 63, a)
mc.setBlock(x+83,y+ 23,z+ 63, a)
mc.setBlock(x+86,y+ 52,z+ 66, a)
mc.setBlock(x+2,y+ 53,z+ 66, a)
mc.setBlock(x+5,y+ 23,z+ 63, a)
mc.setBlock(x+82,y+ 22,z+ 63, a)
mc.setBlock(x+6,y+ 22,z+ 63, a)
mc.setBlock(x+82,y+ 21,z+ 63, a)
mc.setBlock(x+86,y+ 53,z+ 66, a)
mc.setBlock(x+2,y+ 54,z+ 66, a)
mc.setBlock(x+6,y+ 21,z+ 63, a)
mc.setBlock(x+81,y+ 20,z+ 63, a)
mc.setBlock(x+7,y+ 20,z+ 63, a)
mc.setBlock(x+81,y+ 19,z+ 63, a)
mc.setBlock(x+86,y+ 54,z+ 66, a)
mc.setBlock(x+2,y+ 55,z+ 66, a)
mc.setBlock(x+7,y+ 19,z+ 63, a)
mc.setBlock(x+80,y+ 18,z+ 63, a)
mc.setBlock(x+86,y+ 55,z+ 66, a)
mc.setBlock(x+3,y+ 56,z+ 66, a)
mc.setBlock(x+8,y+ 18,z+ 63, a)
mc.setBlock(x+79,y+ 17,z+ 63, a)
mc.setBlock(x+9,y+ 17,z+ 63, a)
mc.setBlock(x+79,y+ 16,z+ 63, a)
mc.setBlock(x+85,y+ 56,z+ 66, a)
mc.setBlock(x+3,y+ 57,z+ 66, a)
mc.setBlock(x+9,y+ 16,z+ 63, a)
mc.setBlock(x+78,y+ 15,z+ 63, a)
mc.setBlock(x+85,y+ 57,z+ 66, a)
mc.setBlock(x+3,y+ 58,z+ 66, a)
mc.setBlock(x+10,y+ 15,z+ 63, a)
mc.setBlock(x+77,y+ 14,z+ 63, a)
mc.setBlock(x+85,y+ 58,z+ 66, a)
mc.setBlock(x+3,y+ 59,z+ 66, a)
mc.setBlock(x+11,y+ 14,z+ 63, a)
mc.setBlock(x+76,y+ 13,z+ 63, a)
mc.setBlock(x+85,y+ 59,z+ 66, a)
mc.setBlock(x+4,y+ 60,z+ 66, a)
mc.setBlock(x+12,y+ 13,z+ 63, a)
mc.setBlock(x+75,y+ 12,z+ 63, a)
mc.setBlock(x+84,y+ 60,z+ 66, a)
mc.setBlock(x+4,y+ 61,z+ 66, a)
mc.setBlock(x+13,y+ 12,z+ 63, a)
mc.setBlock(x+74,y+ 11,z+ 63, a)
mc.setBlock(x+84,y+ 61,z+ 66, a)
mc.setBlock(x+4,y+ 62,z+ 66, a)
mc.setBlock(x+14,y+ 11,z+ 63, a)
mc.setBlock(x+73,y+ 10,z+ 63, a)
mc.setBlock(x+84,y+ 62,z+ 66, a)
mc.setBlock(x+5,y+ 63,z+ 66, a)
mc.setBlock(x+15,y+ 10,z+ 63, a)
mc.setBlock(x+72,y+ 9,z+ 63, a)
mc.setBlock(x+71,y+ 9,z+ 63, a)
mc.setBlock(x+83,y+ 63,z+ 66, a)
mc.setBlock(x+5,y+ 64,z+ 66, a)
mc.setBlock(x+17,y+ 9,z+ 63, a)
mc.setBlock(x+16,y+ 9,z+ 63, a)
mc.setBlock(x+70,y+ 8,z+ 63, a)
mc.setBlock(x+83,y+ 64,z+ 66, a)
mc.setBlock(x+6,y+ 65,z+ 66, a)
mc.setBlock(x+18,y+ 8,z+ 63, a)
mc.setBlock(x+69,y+ 7,z+ 63, a)
mc.setBlock(x+68,y+ 7,z+ 63, a)
mc.setBlock(x+82,y+ 65,z+ 66, a)
mc.setBlock(x+6,y+ 66,z+ 66, a)
mc.setBlock(x+20,y+ 7,z+ 63, a)
mc.setBlock(x+19,y+ 7,z+ 63, a)
mc.setBlock(x+67,y+ 6,z+ 63, a)
mc.setBlock(x+82,y+ 66,z+ 66, a)
mc.setBlock(x+7,y+ 67,z+ 66, a)
mc.setBlock(x+81,y+ 67,z+ 66, a)
mc.setBlock(x+22,y+ 6,z+ 63, a)
mc.setBlock(x+21,y+ 6,z+ 63, a)
mc.setBlock(x+66,y+ 5,z+ 63, a)
mc.setBlock(x+65,y+ 5,z+ 63, a)
mc.setBlock(x+64,y+ 5,z+ 63, a)
mc.setBlock(x+7,y+ 68,z+ 66, a)
mc.setBlock(x+81,y+ 68,z+ 66, a)
mc.setBlock(x+24,y+ 5,z+ 63, a)
mc.setBlock(x+23,y+ 5,z+ 63, a)
mc.setBlock(x+63,y+ 4,z+ 63, a)
mc.setBlock(x+62,y+ 4,z+ 63, a)
mc.setBlock(x+8,y+ 69,z+ 66, a)
mc.setBlock(x+80,y+ 69,z+ 66, a)
mc.setBlock(x+26,y+ 4,z+ 63, a)
mc.setBlock(x+25,y+ 4,z+ 63, a)
mc.setBlock(x+61,y+ 3,z+ 63, a)
mc.setBlock(x+60,y+ 3,z+ 63, a)
mc.setBlock(x+59,y+ 3,z+ 63, a)
mc.setBlock(x+9,y+ 70,z+ 66, a)
mc.setBlock(x+79,y+ 70,z+ 66, a)
mc.setBlock(x+9,y+ 71,z+ 66, a)
mc.setBlock(x+79,y+ 71,z+ 66, a)
mc.setBlock(x+29,y+ 3,z+ 63, a)
mc.setBlock(x+28,y+ 3,z+ 63, a)
mc.setBlock(x+27,y+ 3,z+ 63, a)
mc.setBlock(x+58,y+ 2,z+ 63, a)
mc.setBlock(x+57,y+ 2,z+ 63, a)
mc.setBlock(x+56,y+ 2,z+ 63, a)
mc.setBlock(x+55,y+ 2,z+ 63, a)
mc.setBlock(x+10,y+ 72,z+ 66, a)
mc.setBlock(x+78,y+ 72,z+ 66, a)
mc.setBlock(x+11,y+ 73,z+ 66, a)
mc.setBlock(x+77,y+ 73,z+ 66, a)
mc.setBlock(x+33,y+ 2,z+ 63, a)
mc.setBlock(x+32,y+ 2,z+ 63, a)
mc.setBlock(x+31,y+ 2,z+ 63, a)
mc.setBlock(x+30,y+ 2,z+ 63, a)
mc.setBlock(x+54,y+ 1,z+ 63, a)
mc.setBlock(x+53,y+ 1,z+ 63, a)
mc.setBlock(x+52,y+ 1,z+ 63, a)
mc.setBlock(x+51,y+ 1,z+ 63, a)
mc.setBlock(x+50,y+ 1,z+ 63, a)
mc.setBlock(x+49,y+ 1,z+ 63, a)
mc.setBlock(x+48,y+ 1,z+ 63, a)
mc.setBlock(x+47,y+ 1,z+ 63, a)
mc.setBlock(x+46,y+ 1,z+ 63, a)
mc.setBlock(x+45,y+ 1,z+ 63, a)
mc.setBlock(x+44,y+ 1,z+ 63, a)
mc.setBlock(x+43,y+ 1,z+ 63, a)
mc.setBlock(x+42,y+ 1,z+ 63, a)
mc.setBlock(x+41,y+ 1,z+ 63, a)
mc.setBlock(x+40,y+ 1,z+ 63, a)
mc.setBlock(x+39,y+ 1,z+ 63, a)
mc.setBlock(x+38,y+ 1,z+ 63, a)
mc.setBlock(x+37,y+ 1,z+ 63, a)
mc.setBlock(x+36,y+ 1,z+ 63, a)
mc.setBlock(x+35,y+ 1,z+ 63, a)
mc.setBlock(x+34,y+ 1,z+ 63, a)
mc.setBlock(x+47,y+ 88,z+ 62, a)
mc.setBlock(x+46,y+ 88,z+ 62, a)
mc.setBlock(x+45,y+ 88,z+ 62, a)
mc.setBlock(x+44,y+ 88,z+ 62, a)
mc.setBlock(x+43,y+ 88,z+ 62, a)
mc.setBlock(x+42,y+ 88,z+ 62, a)
mc.setBlock(x+41,y+ 88,z+ 62, a)
mc.setBlock(x+54,y+ 87,z+ 62, a)
mc.setBlock(x+53,y+ 87,z+ 62, a)
mc.setBlock(x+52,y+ 87,z+ 62, a)
mc.setBlock(x+51,y+ 87,z+ 62, a)
mc.setBlock(x+50,y+ 87,z+ 62, a)
mc.setBlock(x+49,y+ 87,z+ 62, a)
mc.setBlock(x+48,y+ 87,z+ 62, a)
mc.setBlock(x+12,y+ 74,z+ 66, a)
mc.setBlock(x+76,y+ 74,z+ 66, a)
mc.setBlock(x+13,y+ 75,z+ 66, a)
mc.setBlock(x+75,y+ 75,z+ 66, a)
mc.setBlock(x+14,y+ 76,z+ 66, a)
mc.setBlock(x+74,y+ 76,z+ 66, a)
mc.setBlock(x+15,y+ 77,z+ 66, a)
mc.setBlock(x+40,y+ 87,z+ 62, a)
mc.setBlock(x+39,y+ 87,z+ 62, a)
mc.setBlock(x+38,y+ 87,z+ 62, a)
mc.setBlock(x+37,y+ 87,z+ 62, a)
mc.setBlock(x+36,y+ 87,z+ 62, a)
mc.setBlock(x+35,y+ 87,z+ 62, a)
mc.setBlock(x+34,y+ 87,z+ 62, a)
mc.setBlock(x+58,y+ 86,z+ 62, a)
mc.setBlock(x+57,y+ 86,z+ 62, a)
mc.setBlock(x+56,y+ 86,z+ 62, a)
mc.setBlock(x+55,y+ 86,z+ 62, a)
mc.setBlock(x+73,y+ 77,z+ 66, a)
mc.setBlock(x+16,y+ 78,z+ 66, a)
mc.setBlock(x+33,y+ 86,z+ 62, a)
mc.setBlock(x+32,y+ 86,z+ 62, a)
mc.setBlock(x+31,y+ 86,z+ 62, a)
mc.setBlock(x+30,y+ 86,z+ 62, a)
mc.setBlock(x+61,y+ 85,z+ 62, a)
mc.setBlock(x+60,y+ 85,z+ 62, a)
mc.setBlock(x+59,y+ 85,z+ 62, a)
mc.setBlock(x+72,y+ 78,z+ 66, a)
mc.setBlock(x+17,y+ 79,z+ 66, a)
mc.setBlock(x+29,y+ 85,z+ 62, a)
mc.setBlock(x+28,y+ 85,z+ 62, a)
mc.setBlock(x+27,y+ 85,z+ 62, a)
mc.setBlock(x+64,y+ 84,z+ 62, a)
mc.setBlock(x+63,y+ 84,z+ 62, a)
mc.setBlock(x+62,y+ 84,z+ 62, a)
mc.setBlock(x+70,y+ 79,z+ 66, a)
mc.setBlock(x+71,y+ 79,z+ 66, a)
mc.setBlock(x+26,y+ 84,z+ 62, a)
mc.setBlock(x+25,y+ 84,z+ 62, a)
mc.setBlock(x+24,y+ 84,z+ 62, a)
mc.setBlock(x+66,y+ 83,z+ 62, a)
mc.setBlock(x+65,y+ 83,z+ 62, a)
mc.setBlock(x+18,y+ 80,z+ 66, a)
mc.setBlock(x+19,y+ 80,z+ 66, a)
mc.setBlock(x+69,y+ 80,z+ 66, a)
mc.setBlock(x+20,y+ 81,z+ 66, a)
mc.setBlock(x+23,y+ 83,z+ 62, a)
mc.setBlock(x+22,y+ 83,z+ 62, a)
mc.setBlock(x+68,y+ 82,z+ 62, a)
mc.setBlock(x+67,y+ 82,z+ 62, a)
mc.setBlock(x+21,y+ 81,z+ 66, a)
mc.setBlock(x+67,y+ 81,z+ 66, a)
mc.setBlock(x+21,y+ 82,z+ 62, a)
mc.setBlock(x+20,y+ 82,z+ 62, a)
mc.setBlock(x+69,y+ 81,z+ 62, a)
mc.setBlock(x+68,y+ 81,z+ 66, a)
mc.setBlock(x+22,y+ 82,z+ 66, a)
mc.setBlock(x+23,y+ 82,z+ 66, a)
mc.setBlock(x+65,y+ 82,z+ 66, a)
mc.setBlock(x+19,y+ 81,z+ 62, a)
mc.setBlock(x+71,y+ 80,z+ 62, a)
mc.setBlock(x+70,y+ 80,z+ 62, a)
mc.setBlock(x+66,y+ 82,z+ 66, a)
mc.setBlock(x+24,y+ 83,z+ 66, a)
mc.setBlock(x+18,y+ 80,z+ 62, a)
mc.setBlock(x+17,y+ 80,z+ 62, a)
mc.setBlock(x+72,y+ 79,z+ 62, a)
mc.setBlock(x+25,y+ 83,z+ 66, a)
mc.setBlock(x+63,y+ 83,z+ 66, a)
mc.setBlock(x+16,y+ 79,z+ 62, a)
mc.setBlock(x+73,y+ 78,z+ 62, a)
mc.setBlock(x+64,y+ 83,z+ 66, a)
mc.setBlock(x+26,y+ 84,z+ 66, a)
mc.setBlock(x+15,y+ 78,z+ 62, a)
mc.setBlock(x+75,y+ 77,z+ 62, a)
mc.setBlock(x+74,y+ 77,z+ 62, a)
mc.setBlock(x+27,y+ 84,z+ 66, a)
mc.setBlock(x+28,y+ 84,z+ 66, a)
mc.setBlock(x+14,y+ 77,z+ 62, a)
mc.setBlock(x+76,y+ 76,z+ 62, a)
mc.setBlock(x+60,y+ 84,z+ 66, a)
mc.setBlock(x+61,y+ 84,z+ 66, a)
mc.setBlock(x+62,y+ 84,z+ 66, a)
mc.setBlock(x+13,y+ 76,z+ 62, a)
mc.setBlock(x+12,y+ 76,z+ 62, a)
mc.setBlock(x+76,y+ 75,z+ 62, a)
mc.setBlock(x+29,y+ 85,z+ 66, a)
mc.setBlock(x+30,y+ 85,z+ 66, a)
mc.setBlock(x+12,y+ 75,z+ 62, a)
mc.setBlock(x+77,y+ 74,z+ 62, a)
mc.setBlock(x+31,y+ 85,z+ 66, a)
mc.setBlock(x+57,y+ 85,z+ 66, a)
mc.setBlock(x+11,y+ 74,z+ 62, a)
mc.setBlock(x+78,y+ 73,z+ 62, a)
mc.setBlock(x+58,y+ 85,z+ 66, a)
mc.setBlock(x+59,y+ 85,z+ 66, a)
mc.setBlock(x+10,y+ 73,z+ 62, a)
mc.setBlock(x+79,y+ 72,z+ 62, a)
mc.setBlock(x+32,y+ 86,z+ 66, a)
mc.setBlock(x+33,y+ 86,z+ 66, a)
mc.setBlock(x+9,y+ 72,z+ 62, a)
mc.setBlock(x+80,y+ 71,z+ 62, a)
mc.setBlock(x+34,y+ 86,z+ 66, a)
mc.setBlock(x+35,y+ 86,z+ 66, a)
mc.setBlock(x+8,y+ 71,z+ 62, a)
mc.setBlock(x+80,y+ 70,z+ 62, a)
mc.setBlock(x+36,y+ 86,z+ 66, a)
mc.setBlock(x+52,y+ 86,z+ 66, a)
mc.setBlock(x+8,y+ 70,z+ 62, a)
mc.setBlock(x+81,y+ 69,z+ 62, a)
mc.setBlock(x+53,y+ 86,z+ 66, a)
mc.setBlock(x+54,y+ 86,z+ 66, a)
mc.setBlock(x+7,y+ 69,z+ 62, a)
mc.setBlock(x+82,y+ 68,z+ 62, a)
mc.setBlock(x+55,y+ 86,z+ 66, a)
mc.setBlock(x+56,y+ 86,z+ 66, a)
mc.setBlock(x+6,y+ 68,z+ 62, a)
mc.setBlock(x+82,y+ 67,z+ 62, a)
mc.setBlock(x+37,y+ 87,z+ 66, a)
mc.setBlock(x+38,y+ 87,z+ 66, a)
mc.setBlock(x+6,y+ 67,z+ 62, a)
mc.setBlock(x+83,y+ 66,z+ 62, a)
mc.setBlock(x+39,y+ 87,z+ 66, a)
mc.setBlock(x+40,y+ 87,z+ 66, a)
mc.setBlock(x+5,y+ 66,z+ 62, a)
mc.setBlock(x+83,y+ 65,z+ 62, a)
mc.setBlock(x+41,y+ 87,z+ 66, a)
mc.setBlock(x+42,y+ 87,z+ 66, a)
mc.setBlock(x+5,y+ 65,z+ 62, a)
mc.setBlock(x+83,y+ 64,z+ 62, a)
mc.setBlock(x+5,y+ 64,z+ 62, a)
mc.setBlock(x+84,y+ 63,z+ 62, a)
mc.setBlock(x+43,y+ 87,z+ 66, a)
mc.setBlock(x+44,y+ 87,z+ 66, a)
mc.setBlock(x+4,y+ 63,z+ 62, a)
mc.setBlock(x+84,y+ 62,z+ 62, a)
mc.setBlock(x+4,y+ 62,z+ 62, a)
mc.setBlock(x+85,y+ 61,z+ 62, a)
mc.setBlock(x+45,y+ 87,z+ 66, a)
mc.setBlock(x+46,y+ 87,z+ 66, a)
mc.setBlock(x+3,y+ 61,z+ 62, a)
mc.setBlock(x+85,y+ 60,z+ 62, a)
mc.setBlock(x+3,y+ 60,z+ 62, a)
mc.setBlock(x+85,y+ 59,z+ 62, a)
mc.setBlock(x+3,y+ 59,z+ 62, a)
mc.setBlock(x+86,y+ 58,z+ 62, a)
mc.setBlock(x+47,y+ 87,z+ 66, a)
mc.setBlock(x+48,y+ 87,z+ 66, a)
mc.setBlock(x+2,y+ 58,z+ 62, a)
mc.setBlock(x+86,y+ 57,z+ 62, a)
mc.setBlock(x+2,y+ 57,z+ 62, a)
mc.setBlock(x+86,y+ 56,z+ 62, a)
mc.setBlock(x+2,y+ 56,z+ 62, a)
mc.setBlock(x+86,y+ 55,z+ 62, a)
mc.setBlock(x+2,y+ 55,z+ 62, a)
mc.setBlock(x+87,y+ 54,z+ 62, a)
mc.setBlock(x+49,y+ 87,z+ 66, a)
mc.setBlock(x+50,y+ 87,z+ 66, a)
mc.setBlock(x+1,y+ 54,z+ 62, a)
mc.setBlock(x+87,y+ 53,z+ 62, a)
mc.setBlock(x+51,y+ 87,z+ 66, a)
mc.setBlock(x+39,y+ 1,z+ 67, a)
mc.setBlock(x+1,y+ 53,z+ 62, a)
mc.setBlock(x+87,y+ 52,z+ 62, a)
mc.setBlock(x+1,y+ 52,z+ 62, a)
mc.setBlock(x+87,y+ 51,z+ 62, a)
mc.setBlock(x+1,y+ 51,z+ 62, a)
mc.setBlock(x+87,y+ 50,z+ 62, a)
mc.setBlock(x+1,y+ 50,z+ 62, a)
mc.setBlock(x+87,y+ 49,z+ 62, a)
mc.setBlock(x+1,y+ 49,z+ 62, a)
mc.setBlock(x+87,y+ 48,z+ 62, a)
mc.setBlock(x+1,y+ 48,z+ 62, a)
mc.setBlock(x+87,y+ 47,z+ 62, a)
mc.setBlock(x+1,y+ 47,z+ 62, a)
mc.setBlock(x+87,y+ 46,z+ 62, a)
mc.setBlock(x+1,y+ 46,z+ 62, a)
mc.setBlock(x+87,y+ 45,z+ 62, a)
mc.setBlock(x+1,y+ 45,z+ 62, a)
mc.setBlock(x+87,y+ 44,z+ 62, a)
mc.setBlock(x+1,y+ 44,z+ 62, a)
mc.setBlock(x+87,y+ 43,z+ 62, a)
mc.setBlock(x+1,y+ 43,z+ 62, a)
mc.setBlock(x+87,y+ 42,z+ 62, a)
mc.setBlock(x+1,y+ 42,z+ 62, a)
mc.setBlock(x+87,y+ 41,z+ 62, a)
mc.setBlock(x+1,y+ 41,z+ 62, a)
mc.setBlock(x+87,y+ 40,z+ 62, a)
mc.setBlock(x+1,y+ 40,z+ 62, a)
mc.setBlock(x+87,y+ 39,z+ 62, a)
mc.setBlock(x+1,y+ 39,z+ 62, a)
mc.setBlock(x+87,y+ 38,z+ 62, a)
mc.setBlock(x+1,y+ 38,z+ 62, a)
mc.setBlock(x+87,y+ 37,z+ 62, a)
mc.setBlock(x+1,y+ 37,z+ 62, a)
mc.setBlock(x+87,y+ 36,z+ 62, a)
mc.setBlock(x+1,y+ 36,z+ 62, a)
mc.setBlock(x+87,y+ 35,z+ 62, a)
mc.setBlock(x+40,y+ 1,z+ 67, a)
mc.setBlock(x+41,y+ 1,z+ 67, a)
mc.setBlock(x+1,y+ 35,z+ 62, a)
mc.setBlock(x+87,y+ 34,z+ 62, a)
mc.setBlock(x+42,y+ 1,z+ 67, a)
mc.setBlock(x+43,y+ 1,z+ 67, a)
mc.setBlock(x+1,y+ 34,z+ 62, a)
mc.setBlock(x+86,y+ 33,z+ 62, a)
mc.setBlock(x+2,y+ 33,z+ 62, a)
mc.setBlock(x+86,y+ 32,z+ 62, a)
mc.setBlock(x+2,y+ 32,z+ 62, a)
mc.setBlock(x+86,y+ 31,z+ 62, a)
mc.setBlock(x+2,y+ 31,z+ 62, a)
mc.setBlock(x+86,y+ 30,z+ 62, a)
mc.setBlock(x+44,y+ 1,z+ 67, a)
mc.setBlock(x+45,y+ 1,z+ 67, a)
mc.setBlock(x+2,y+ 30,z+ 62, a)
mc.setBlock(x+85,y+ 29,z+ 62, a)
mc.setBlock(x+3,y+ 29,z+ 62, a)
mc.setBlock(x+85,y+ 28,z+ 62, a)
mc.setBlock(x+3,y+ 28,z+ 62, a)
mc.setBlock(x+85,y+ 27,z+ 62, a)
mc.setBlock(x+46,y+ 1,z+ 67, a)
mc.setBlock(x+47,y+ 1,z+ 67, a)
mc.setBlock(x+3,y+ 27,z+ 62, a)
mc.setBlock(x+84,y+ 26,z+ 62, a)
mc.setBlock(x+4,y+ 26,z+ 62, a)
mc.setBlock(x+84,y+ 25,z+ 62, a)
mc.setBlock(x+48,y+ 1,z+ 67, a)
mc.setBlock(x+49,y+ 1,z+ 67, a)
mc.setBlock(x+4,y+ 25,z+ 62, a)
mc.setBlock(x+83,y+ 24,z+ 62, a)
mc.setBlock(x+5,y+ 24,z+ 62, a)
mc.setBlock(x+83,y+ 23,z+ 62, a)
mc.setBlock(x+33,y+ 2,z+ 67, a)
mc.setBlock(x+34,y+ 2,z+ 67, a)
mc.setBlock(x+5,y+ 23,z+ 62, a)
mc.setBlock(x+83,y+ 22,z+ 62, a)
mc.setBlock(x+35,y+ 2,z+ 67, a)
mc.setBlock(x+36,y+ 2,z+ 67, a)
mc.setBlock(x+5,y+ 22,z+ 62, a)
mc.setBlock(x+82,y+ 21,z+ 62, a)
mc.setBlock(x+37,y+ 2,z+ 67, a)
mc.setBlock(x+38,y+ 2,z+ 67, a)
mc.setBlock(x+6,y+ 21,z+ 62, a)
mc.setBlock(x+82,y+ 20,z+ 62, a)
mc.setBlock(x+50,y+ 2,z+ 67, a)
mc.setBlock(x+51,y+ 2,z+ 67, a)
mc.setBlock(x+6,y+ 20,z+ 62, a)
mc.setBlock(x+81,y+ 19,z+ 62, a)
mc.setBlock(x+52,y+ 2,z+ 67, a)
mc.setBlock(x+53,y+ 2,z+ 67, a)
mc.setBlock(x+7,y+ 19,z+ 62, a)
mc.setBlock(x+80,y+ 18,z+ 62, a)
mc.setBlock(x+54,y+ 2,z+ 67, a)
mc.setBlock(x+55,y+ 2,z+ 67, a)
mc.setBlock(x+8,y+ 18,z+ 62, a)
mc.setBlock(x+80,y+ 17,z+ 62, a)
mc.setBlock(x+29,y+ 3,z+ 67, a)
mc.setBlock(x+30,y+ 3,z+ 67, a)
mc.setBlock(x+8,y+ 17,z+ 62, a)
mc.setBlock(x+79,y+ 16,z+ 62, a)
mc.setBlock(x+31,y+ 3,z+ 67, a)
mc.setBlock(x+32,y+ 3,z+ 67, a)
mc.setBlock(x+9,y+ 16,z+ 62, a)
mc.setBlock(x+78,y+ 15,z+ 62, a)
mc.setBlock(x+56,y+ 3,z+ 67, a)
mc.setBlock(x+57,y+ 3,z+ 67, a)
mc.setBlock(x+10,y+ 15,z+ 62, a)
mc.setBlock(x+77,y+ 14,z+ 62, a)
mc.setBlock(x+58,y+ 3,z+ 67, a)
mc.setBlock(x+59,y+ 3,z+ 67, a)
mc.setBlock(x+11,y+ 14,z+ 62, a)
mc.setBlock(x+76,y+ 13,z+ 62, a)
mc.setBlock(x+27,y+ 4,z+ 67, a)
mc.setBlock(x+28,y+ 4,z+ 67, a)
mc.setBlock(x+12,y+ 13,z+ 62, a)
mc.setBlock(x+76,y+ 12,z+ 62, a)
mc.setBlock(x+75,y+ 12,z+ 62, a)
mc.setBlock(x+60,y+ 4,z+ 67, a)
mc.setBlock(x+61,y+ 4,z+ 67, a)
mc.setBlock(x+24,y+ 5,z+ 67, a)
mc.setBlock(x+12,y+ 12,z+ 62, a)
mc.setBlock(x+74,y+ 11,z+ 62, a)
mc.setBlock(x+25,y+ 5,z+ 67, a)
mc.setBlock(x+26,y+ 5,z+ 67, a)
mc.setBlock(x+14,y+ 11,z+ 62, a)
mc.setBlock(x+13,y+ 11,z+ 62, a)
mc.setBlock(x+73,y+ 10,z+ 62, a)
mc.setBlock(x+62,y+ 5,z+ 67, a)
mc.setBlock(x+63,y+ 5,z+ 67, a)
mc.setBlock(x+15,y+ 10,z+ 62, a)
mc.setBlock(x+72,y+ 9,z+ 62, a)
mc.setBlock(x+64,y+ 5,z+ 67, a)
mc.setBlock(x+22,y+ 6,z+ 67, a)
mc.setBlock(x+16,y+ 9,z+ 62, a)
mc.setBlock(x+71,y+ 8,z+ 62, a)
mc.setBlock(x+70,y+ 8,z+ 62, a)
mc.setBlock(x+23,y+ 6,z+ 67, a)
mc.setBlock(x+65,y+ 6,z+ 67, a)
mc.setBlock(x+18,y+ 8,z+ 62, a)
mc.setBlock(x+17,y+ 8,z+ 62, a)
mc.setBlock(x+69,y+ 7,z+ 62, a)
mc.setBlock(x+66,y+ 6,z+ 67, a)
mc.setBlock(x+20,y+ 7,z+ 67, a)
mc.setBlock(x+21,y+ 7,z+ 67, a)
mc.setBlock(x+67,y+ 7,z+ 67, a)
mc.setBlock(x+19,y+ 7,z+ 62, a)
mc.setBlock(x+68,y+ 6,z+ 62, a)
mc.setBlock(x+67,y+ 6,z+ 62, a)
mc.setBlock(x+68,y+ 7,z+ 67, a)
mc.setBlock(x+19,y+ 8,z+ 67, a)
mc.setBlock(x+21,y+ 6,z+ 62, a)
mc.setBlock(x+20,y+ 6,z+ 62, a)
mc.setBlock(x+66,y+ 5,z+ 62, a)
mc.setBlock(x+65,y+ 5,z+ 62, a)
mc.setBlock(x+69,y+ 8,z+ 67, a)
mc.setBlock(x+18,y+ 9,z+ 67, a)
mc.setBlock(x+70,y+ 9,z+ 67, a)
mc.setBlock(x+71,y+ 9,z+ 67, a)
mc.setBlock(x+23,y+ 5,z+ 62, a)
mc.setBlock(x+22,y+ 5,z+ 62, a)
mc.setBlock(x+64,y+ 4,z+ 62, a)
mc.setBlock(x+63,y+ 4,z+ 62, a)
mc.setBlock(x+62,y+ 4,z+ 62, a)
mc.setBlock(x+16,y+ 10,z+ 67, a)
mc.setBlock(x+17,y+ 10,z+ 67, a)
mc.setBlock(x+26,y+ 4,z+ 62, a)
mc.setBlock(x+25,y+ 4,z+ 62, a)
mc.setBlock(x+24,y+ 4,z+ 62, a)
mc.setBlock(x+61,y+ 3,z+ 62, a)
mc.setBlock(x+60,y+ 3,z+ 62, a)
mc.setBlock(x+59,y+ 3,z+ 62, a)
mc.setBlock(x+72,y+ 10,z+ 67, a)
mc.setBlock(x+15,y+ 11,z+ 67, a)
mc.setBlock(x+29,y+ 3,z+ 62, a)
mc.setBlock(x+28,y+ 3,z+ 62, a)
mc.setBlock(x+27,y+ 3,z+ 62, a)
mc.setBlock(x+58,y+ 2,z+ 62, a)
mc.setBlock(x+57,y+ 2,z+ 62, a)
mc.setBlock(x+56,y+ 2,z+ 62, a)
mc.setBlock(x+55,y+ 2,z+ 62, a)
mc.setBlock(x+73,y+ 11,z+ 67, a)
mc.setBlock(x+14,y+ 12,z+ 67, a)
mc.setBlock(x+33,y+ 2,z+ 62, a)
mc.setBlock(x+32,y+ 2,z+ 62, a)
mc.setBlock(x+31,y+ 2,z+ 62, a)
mc.setBlock(x+30,y+ 2,z+ 62, a)
mc.setBlock(x+54,y+ 1,z+ 62, a)
mc.setBlock(x+53,y+ 1,z+ 62, a)
mc.setBlock(x+52,y+ 1,z+ 62, a)
mc.setBlock(x+51,y+ 1,z+ 62, a)
mc.setBlock(x+50,y+ 1,z+ 62, a)
mc.setBlock(x+49,y+ 1,z+ 62, a)
mc.setBlock(x+48,y+ 1,z+ 62, a)
mc.setBlock(x+74,y+ 12,z+ 67, a)
mc.setBlock(x+13,y+ 13,z+ 67, a)
mc.setBlock(x+75,y+ 13,z+ 67, a)
mc.setBlock(x+12,y+ 14,z+ 67, a)
mc.setBlock(x+76,y+ 14,z+ 67, a)
mc.setBlock(x+11,y+ 15,z+ 67, a)
mc.setBlock(x+77,y+ 15,z+ 67, a)
mc.setBlock(x+40,y+ 1,z+ 62, a)
mc.setBlock(x+39,y+ 1,z+ 62, a)
mc.setBlock(x+38,y+ 1,z+ 62, a)
mc.setBlock(x+37,y+ 1,z+ 62, a)
mc.setBlock(x+36,y+ 1,z+ 62, a)
mc.setBlock(x+35,y+ 1,z+ 62, a)
mc.setBlock(x+34,y+ 1,z+ 62, a)
mc.setBlock(x+47,y+ 0,z+ 62, a)
mc.setBlock(x+46,y+ 0,z+ 62, a)
mc.setBlock(x+45,y+ 0,z+ 62, a)
mc.setBlock(x+44,y+ 0,z+ 62, a)
mc.setBlock(x+43,y+ 0,z+ 62, a)
mc.setBlock(x+42,y+ 0,z+ 62, a)
mc.setBlock(x+41,y+ 0,z+ 62, a)
mc.setBlock(x+49,y+ 88,z+ 61, a)
mc.setBlock(x+48,y+ 88,z+ 61, a)
mc.setBlock(x+47,y+ 88,z+ 61, a)
mc.setBlock(x+46,y+ 88,z+ 61, a)
mc.setBlock(x+45,y+ 88,z+ 61, a)
mc.setBlock(x+44,y+ 88,z+ 61, a)
mc.setBlock(x+43,y+ 88,z+ 61, a)
mc.setBlock(x+42,y+ 88,z+ 61, a)
mc.setBlock(x+41,y+ 88,z+ 61, a)
mc.setBlock(x+40,y+ 88,z+ 61, a)
mc.setBlock(x+39,y+ 88,z+ 61, a)
mc.setBlock(x+55,y+ 87,z+ 61, a)
mc.setBlock(x+54,y+ 87,z+ 61, a)
mc.setBlock(x+53,y+ 87,z+ 61, a)
mc.setBlock(x+52,y+ 87,z+ 61, a)
mc.setBlock(x+51,y+ 87,z+ 61, a)
mc.setBlock(x+50,y+ 87,z+ 61, a)
mc.setBlock(x+10,y+ 16,z+ 67, a)
mc.setBlock(x+78,y+ 16,z+ 67, a)
mc.setBlock(x+10,y+ 17,z+ 67, a)
mc.setBlock(x+78,y+ 17,z+ 67, a)
mc.setBlock(x+9,y+ 18,z+ 67, a)
mc.setBlock(x+79,y+ 18,z+ 67, a)
mc.setBlock(x+38,y+ 87,z+ 61, a)
mc.setBlock(x+37,y+ 87,z+ 61, a)
mc.setBlock(x+36,y+ 87,z+ 61, a)
mc.setBlock(x+35,y+ 87,z+ 61, a)
mc.setBlock(x+34,y+ 87,z+ 61, a)
mc.setBlock(x+33,y+ 87,z+ 61, a)
mc.setBlock(x+59,y+ 86,z+ 61, a)
mc.setBlock(x+58,y+ 86,z+ 61, a)
mc.setBlock(x+57,y+ 86,z+ 61, a)
mc.setBlock(x+56,y+ 86,z+ 61, a)
mc.setBlock(x+8,y+ 19,z+ 67, a)
mc.setBlock(x+80,y+ 19,z+ 67, a)
mc.setBlock(x+32,y+ 86,z+ 61, a)
mc.setBlock(x+31,y+ 86,z+ 61, a)
mc.setBlock(x+30,y+ 86,z+ 61, a)
mc.setBlock(x+29,y+ 86,z+ 61, a)
mc.setBlock(x+62,y+ 85,z+ 61, a)
mc.setBlock(x+61,y+ 85,z+ 61, a)
mc.setBlock(x+60,y+ 85,z+ 61, a)
mc.setBlock(x+8,y+ 20,z+ 67, a)
mc.setBlock(x+80,y+ 20,z+ 67, a)
mc.setBlock(x+7,y+ 21,z+ 67, a)
mc.setBlock(x+81,y+ 21,z+ 67, a)
mc.setBlock(x+28,y+ 85,z+ 61, a)
mc.setBlock(x+27,y+ 85,z+ 61, a)
mc.setBlock(x+26,y+ 85,z+ 61, a)
mc.setBlock(x+64,y+ 84,z+ 61, a)
mc.setBlock(x+63,y+ 84,z+ 61, a)
mc.setBlock(x+7,y+ 22,z+ 67, a)
mc.setBlock(x+81,y+ 22,z+ 67, a)
mc.setBlock(x+6,y+ 23,z+ 67, a)
mc.setBlock(x+25,y+ 84,z+ 61, a)
mc.setBlock(x+24,y+ 84,z+ 61, a)
mc.setBlock(x+66,y+ 83,z+ 61, a)
mc.setBlock(x+65,y+ 83,z+ 61, a)
mc.setBlock(x+82,y+ 23,z+ 67, a)
mc.setBlock(x+6,y+ 24,z+ 67, a)
mc.setBlock(x+23,y+ 83,z+ 61, a)
mc.setBlock(x+22,y+ 83,z+ 61, a)
mc.setBlock(x+68,y+ 82,z+ 61, a)
mc.setBlock(x+67,y+ 82,z+ 61, a)
mc.setBlock(x+82,y+ 24,z+ 67, a)
mc.setBlock(x+5,y+ 25,z+ 67, a)
mc.setBlock(x+21,y+ 82,z+ 61, a)
mc.setBlock(x+20,y+ 82,z+ 61, a)
mc.setBlock(x+70,y+ 81,z+ 61, a)
mc.setBlock(x+69,y+ 81,z+ 61, a)
mc.setBlock(x+83,y+ 25,z+ 67, a)
mc.setBlock(x+5,y+ 26,z+ 67, a)
mc.setBlock(x+19,y+ 81,z+ 61, a)
mc.setBlock(x+18,y+ 81,z+ 61, a)
mc.setBlock(x+71,y+ 80,z+ 61, a)
mc.setBlock(x+83,y+ 26,z+ 67, a)
mc.setBlock(x+4,y+ 27,z+ 67, a)
mc.setBlock(x+84,y+ 27,z+ 67, a)
mc.setBlock(x+4,y+ 28,z+ 67, a)
mc.setBlock(x+17,y+ 80,z+ 61, a)
mc.setBlock(x+72,y+ 79,z+ 61, a)
mc.setBlock(x+84,y+ 28,z+ 67, a)
mc.setBlock(x+4,y+ 29,z+ 67, a)
mc.setBlock(x+16,y+ 79,z+ 61, a)
mc.setBlock(x+74,y+ 78,z+ 61, a)
mc.setBlock(x+73,y+ 78,z+ 61, a)
mc.setBlock(x+84,y+ 29,z+ 67, a)
mc.setBlock(x+3,y+ 30,z+ 67, a)
mc.setBlock(x+15,y+ 78,z+ 61, a)
mc.setBlock(x+14,y+ 78,z+ 61, a)
mc.setBlock(x+75,y+ 77,z+ 61, a)
mc.setBlock(x+85,y+ 30,z+ 67, a)
mc.setBlock(x+3,y+ 31,z+ 67, a)
mc.setBlock(x+85,y+ 31,z+ 67, a)
mc.setBlock(x+3,y+ 32,z+ 67, a)
mc.setBlock(x+13,y+ 77,z+ 61, a)
mc.setBlock(x+76,y+ 76,z+ 61, a)
mc.setBlock(x+85,y+ 32,z+ 67, a)
mc.setBlock(x+3,y+ 33,z+ 67, a)
mc.setBlock(x+12,y+ 76,z+ 61, a)
mc.setBlock(x+77,y+ 75,z+ 61, a)
mc.setBlock(x+85,y+ 33,z+ 67, a)
mc.setBlock(x+2,y+ 34,z+ 67, a)
mc.setBlock(x+11,y+ 75,z+ 61, a)
mc.setBlock(x+78,y+ 74,z+ 61, a)
mc.setBlock(x+86,y+ 34,z+ 67, a)
mc.setBlock(x+2,y+ 35,z+ 67, a)
mc.setBlock(x+10,y+ 74,z+ 61, a)
mc.setBlock(x+78,y+ 73,z+ 61, a)
mc.setBlock(x+86,y+ 35,z+ 67, a)
mc.setBlock(x+2,y+ 36,z+ 67, a)
mc.setBlock(x+10,y+ 73,z+ 61, a)
mc.setBlock(x+79,y+ 72,z+ 61, a)
mc.setBlock(x+86,y+ 36,z+ 67, a)
mc.setBlock(x+2,y+ 37,z+ 67, a)
mc.setBlock(x+9,y+ 72,z+ 61, a)
mc.setBlock(x+80,y+ 71,z+ 61, a)
mc.setBlock(x+86,y+ 37,z+ 67, a)
mc.setBlock(x+2,y+ 38,z+ 67, a)
mc.setBlock(x+8,y+ 71,z+ 61, a)
mc.setBlock(x+80,y+ 70,z+ 61, a)
mc.setBlock(x+86,y+ 38,z+ 67, a)
mc.setBlock(x+7,y+ 70,z+ 61, a)
mc.setBlock(x+81,y+ 69,z+ 61, a)
mc.setBlock(x+2,y+ 39,z+ 67, a)
mc.setBlock(x+86,y+ 39,z+ 67, a)
mc.setBlock(x+7,y+ 69,z+ 61, a)
mc.setBlock(x+82,y+ 68,z+ 61, a)
mc.setBlock(x+2,y+ 40,z+ 67, a)
mc.setBlock(x+86,y+ 40,z+ 67, a)
mc.setBlock(x+6,y+ 68,z+ 61, a)
mc.setBlock(x+82,y+ 67,z+ 61, a)
mc.setBlock(x+6,y+ 67,z+ 61, a)
mc.setBlock(x+83,y+ 66,z+ 61, a)
mc.setBlock(x+2,y+ 41,z+ 67, a)
mc.setBlock(x+86,y+ 41,z+ 67, a)
mc.setBlock(x+5,y+ 66,z+ 61, a)
mc.setBlock(x+83,y+ 65,z+ 61, a)
mc.setBlock(x+5,y+ 65,z+ 61, a)
mc.setBlock(x+84,y+ 64,z+ 61, a)
mc.setBlock(x+2,y+ 42,z+ 67, a)
mc.setBlock(x+86,y+ 42,z+ 67, a)
mc.setBlock(x+4,y+ 64,z+ 61, a)
mc.setBlock(x+84,y+ 63,z+ 61, a)
mc.setBlock(x+4,y+ 63,z+ 61, a)
mc.setBlock(x+84,y+ 62,z+ 61, a)
mc.setBlock(x+4,y+ 62,z+ 61, a)
mc.setBlock(x+85,y+ 61,z+ 61, a)
mc.setBlock(x+1,y+ 43,z+ 67, a)
mc.setBlock(x+87,y+ 43,z+ 67, a)
mc.setBlock(x+3,y+ 61,z+ 61, a)
mc.setBlock(x+85,y+ 60,z+ 61, a)
mc.setBlock(x+3,y+ 60,z+ 61, a)
mc.setBlock(x+85,y+ 59,z+ 61, a)
mc.setBlock(x+3,y+ 59,z+ 61, a)
mc.setBlock(x+86,y+ 58,z+ 61, a)
mc.setBlock(x+1,y+ 44,z+ 67, a)
mc.setBlock(x+87,y+ 44,z+ 67, a)
mc.setBlock(x+2,y+ 58,z+ 61, a)
mc.setBlock(x+86,y+ 57,z+ 61, a)
mc.setBlock(x+2,y+ 57,z+ 61, a)
mc.setBlock(x+86,y+ 56,z+ 61, a)
mc.setBlock(x+2,y+ 56,z+ 61, a)
mc.setBlock(x+86,y+ 55,z+ 61, a)
mc.setBlock(x+2,y+ 55,z+ 61, a)
mc.setBlock(x+87,y+ 54,z+ 61, a)
mc.setBlock(x+1,y+ 45,z+ 67, a)
mc.setBlock(x+87,y+ 45,z+ 67, a)
mc.setBlock(x+1,y+ 54,z+ 61, a)
mc.setBlock(x+87,y+ 53,z+ 61, a)
mc.setBlock(x+1,y+ 53,z+ 61, a)
mc.setBlock(x+87,y+ 52,z+ 61, a)
mc.setBlock(x+1,y+ 52,z+ 61, a)
mc.setBlock(x+87,y+ 51,z+ 61, a)
mc.setBlock(x+1,y+ 51,z+ 61, a)
mc.setBlock(x+87,y+ 50,z+ 61, a)
mc.setBlock(x+1,y+ 50,z+ 61, a)
mc.setBlock(x+87,y+ 49,z+ 61, a)
mc.setBlock(x+1,y+ 49,z+ 61, a)
mc.setBlock(x+87,y+ 48,z+ 61, a)
mc.setBlock(x+1,y+ 48,z+ 61, a)
mc.setBlock(x+88,y+ 47,z+ 61, a)
mc.setBlock(x+2,y+ 46,z+ 67, a)
mc.setBlock(x+86,y+ 46,z+ 67, a)
mc.setBlock(x+0,y+ 47,z+ 61, a)
mc.setBlock(x+88,y+ 46,z+ 61, a)
mc.setBlock(x+2,y+ 47,z+ 67, a)
mc.setBlock(x+86,y+ 47,z+ 67, a)
mc.setBlock(x+0,y+ 46,z+ 61, a)
mc.setBlock(x+88,y+ 45,z+ 61, a)
mc.setBlock(x+2,y+ 48,z+ 67, a)
mc.setBlock(x+86,y+ 48,z+ 67, a)
mc.setBlock(x+0,y+ 45,z+ 61, a)
mc.setBlock(x+88,y+ 44,z+ 61, a)
mc.setBlock(x+2,y+ 49,z+ 67, a)
mc.setBlock(x+86,y+ 49,z+ 67, a)
mc.setBlock(x+0,y+ 44,z+ 61, a)
mc.setBlock(x+88,y+ 43,z+ 61, a)
mc.setBlock(x+2,y+ 50,z+ 67, a)
mc.setBlock(x+86,y+ 50,z+ 67, a)
mc.setBlock(x+0,y+ 43,z+ 61, a)
mc.setBlock(x+88,y+ 42,z+ 61, a)
mc.setBlock(x+2,y+ 51,z+ 67, a)
mc.setBlock(x+86,y+ 51,z+ 67, a)
mc.setBlock(x+0,y+ 42,z+ 61, a)
mc.setBlock(x+88,y+ 41,z+ 61, a)
mc.setBlock(x+2,y+ 52,z+ 67, a)
mc.setBlock(x+86,y+ 52,z+ 67, a)
mc.setBlock(x+0,y+ 41,z+ 61, a)
mc.setBlock(x+87,y+ 40,z+ 61, a)
mc.setBlock(x+1,y+ 40,z+ 61, a)
mc.setBlock(x+87,y+ 39,z+ 61, a)
mc.setBlock(x+1,y+ 39,z+ 61, a)
mc.setBlock(x+87,y+ 38,z+ 61, a)
mc.setBlock(x+1,y+ 38,z+ 61, a)
mc.setBlock(x+87,y+ 37,z+ 61, a)
mc.setBlock(x+1,y+ 37,z+ 61, a)
mc.setBlock(x+87,y+ 36,z+ 61, a)
mc.setBlock(x+1,y+ 36,z+ 61, a)
mc.setBlock(x+87,y+ 35,z+ 61, a)
mc.setBlock(x+1,y+ 35,z+ 61, a)
mc.setBlock(x+87,y+ 34,z+ 61, a)
mc.setBlock(x+2,y+ 53,z+ 67, a)
mc.setBlock(x+86,y+ 53,z+ 67, a)
mc.setBlock(x+1,y+ 34,z+ 61, a)
mc.setBlock(x+87,y+ 33,z+ 61, a)
mc.setBlock(x+2,y+ 54,z+ 67, a)
mc.setBlock(x+86,y+ 54,z+ 67, a)
mc.setBlock(x+1,y+ 33,z+ 61, a)
mc.setBlock(x+86,y+ 32,z+ 61, a)
mc.setBlock(x+2,y+ 32,z+ 61, a)
mc.setBlock(x+86,y+ 31,z+ 61, a)
mc.setBlock(x+2,y+ 31,z+ 61, a)
mc.setBlock(x+86,y+ 30,z+ 61, a)
mc.setBlock(x+3,y+ 55,z+ 67, a)
mc.setBlock(x+85,y+ 55,z+ 67, a)
mc.setBlock(x+2,y+ 30,z+ 61, a)
mc.setBlock(x+85,y+ 29,z+ 61, a)
mc.setBlock(x+3,y+ 29,z+ 61, a)
mc.setBlock(x+85,y+ 28,z+ 61, a)
mc.setBlock(x+3,y+ 28,z+ 61, a)
mc.setBlock(x+85,y+ 27,z+ 61, a)
mc.setBlock(x+3,y+ 56,z+ 67, a)
mc.setBlock(x+85,y+ 56,z+ 67, a)
mc.setBlock(x+3,y+ 27,z+ 61, a)
mc.setBlock(x+84,y+ 26,z+ 61, a)
mc.setBlock(x+4,y+ 26,z+ 61, a)
mc.setBlock(x+84,y+ 25,z+ 61, a)
mc.setBlock(x+4,y+ 25,z+ 61, a)
mc.setBlock(x+84,y+ 24,z+ 61, a)
mc.setBlock(x+3,y+ 57,z+ 67, a)
mc.setBlock(x+85,y+ 57,z+ 67, a)
mc.setBlock(x+4,y+ 24,z+ 61, a)
mc.setBlock(x+83,y+ 23,z+ 61, a)
mc.setBlock(x+5,y+ 23,z+ 61, a)
mc.setBlock(x+83,y+ 22,z+ 61, a)
mc.setBlock(x+3,y+ 58,z+ 67, a)
mc.setBlock(x+85,y+ 58,z+ 67, a)
mc.setBlock(x+5,y+ 22,z+ 61, a)
mc.setBlock(x+82,y+ 21,z+ 61, a)
mc.setBlock(x+6,y+ 21,z+ 61, a)
mc.setBlock(x+82,y+ 20,z+ 61, a)
mc.setBlock(x+4,y+ 59,z+ 67, a)
mc.setBlock(x+84,y+ 59,z+ 67, a)
mc.setBlock(x+6,y+ 20,z+ 61, a)
mc.setBlock(x+81,y+ 19,z+ 61, a)
mc.setBlock(x+4,y+ 60,z+ 67, a)
mc.setBlock(x+84,y+ 60,z+ 67, a)
mc.setBlock(x+7,y+ 19,z+ 61, a)
mc.setBlock(x+81,y+ 18,z+ 61, a)
mc.setBlock(x+4,y+ 61,z+ 67, a)
mc.setBlock(x+8,y+ 18,z+ 61, a)
mc.setBlock(x+80,y+ 17,z+ 61, a)
mc.setBlock(x+84,y+ 61,z+ 67, a)
mc.setBlock(x+5,y+ 62,z+ 67, a)
mc.setBlock(x+8,y+ 17,z+ 61, a)
mc.setBlock(x+79,y+ 16,z+ 61, a)
mc.setBlock(x+83,y+ 62,z+ 67, a)
mc.setBlock(x+5,y+ 63,z+ 67, a)
mc.setBlock(x+9,y+ 16,z+ 61, a)
mc.setBlock(x+78,y+ 15,z+ 61, a)
mc.setBlock(x+83,y+ 63,z+ 67, a)
mc.setBlock(x+6,y+ 64,z+ 67, a)
mc.setBlock(x+10,y+ 15,z+ 61, a)
mc.setBlock(x+78,y+ 14,z+ 61, a)
mc.setBlock(x+82,y+ 64,z+ 67, a)
mc.setBlock(x+6,y+ 65,z+ 67, a)
mc.setBlock(x+10,y+ 14,z+ 61, a)
mc.setBlock(x+77,y+ 13,z+ 61, a)
mc.setBlock(x+82,y+ 65,z+ 67, a)
mc.setBlock(x+7,y+ 66,z+ 67, a)
mc.setBlock(x+11,y+ 13,z+ 61, a)
mc.setBlock(x+76,y+ 12,z+ 61, a)
mc.setBlock(x+81,y+ 66,z+ 67, a)
mc.setBlock(x+7,y+ 67,z+ 67, a)
mc.setBlock(x+12,y+ 12,z+ 61, a)
mc.setBlock(x+75,y+ 11,z+ 61, a)
mc.setBlock(x+81,y+ 67,z+ 67, a)
mc.setBlock(x+8,y+ 68,z+ 67, a)
mc.setBlock(x+80,y+ 68,z+ 67, a)
mc.setBlock(x+8,y+ 69,z+ 67, a)
mc.setBlock(x+13,y+ 11,z+ 61, a)
mc.setBlock(x+74,y+ 10,z+ 61, a)
mc.setBlock(x+73,y+ 10,z+ 61, a)
mc.setBlock(x+80,y+ 69,z+ 67, a)
mc.setBlock(x+9,y+ 70,z+ 67, a)
mc.setBlock(x+15,y+ 10,z+ 61, a)
mc.setBlock(x+14,y+ 10,z+ 61, a)
mc.setBlock(x+72,y+ 9,z+ 61, a)
mc.setBlock(x+79,y+ 70,z+ 67, a)
mc.setBlock(x+10,y+ 71,z+ 67, a)
mc.setBlock(x+16,y+ 9,z+ 61, a)
mc.setBlock(x+71,y+ 8,z+ 61, a)
mc.setBlock(x+78,y+ 71,z+ 67, a)
mc.setBlock(x+10,y+ 72,z+ 67, a)
mc.setBlock(x+78,y+ 72,z+ 67, a)
mc.setBlock(x+11,y+ 73,z+ 67, a)
mc.setBlock(x+17,y+ 8,z+ 61, a)
mc.setBlock(x+70,y+ 7,z+ 61, a)
mc.setBlock(x+69,y+ 7,z+ 61, a)
mc.setBlock(x+77,y+ 73,z+ 67, a)
mc.setBlock(x+12,y+ 74,z+ 67, a)
mc.setBlock(x+19,y+ 7,z+ 61, a)
mc.setBlock(x+18,y+ 7,z+ 61, a)
mc.setBlock(x+68,y+ 6,z+ 61, a)
mc.setBlock(x+67,y+ 6,z+ 61, a)
mc.setBlock(x+76,y+ 74,z+ 67, a)
mc.setBlock(x+13,y+ 75,z+ 67, a)
mc.setBlock(x+21,y+ 6,z+ 61, a)
mc.setBlock(x+20,y+ 6,z+ 61, a)
mc.setBlock(x+66,y+ 5,z+ 61, a)
mc.setBlock(x+65,y+ 5,z+ 61, a)
mc.setBlock(x+75,y+ 75,z+ 67, a)
mc.setBlock(x+14,y+ 76,z+ 67, a)
mc.setBlock(x+23,y+ 5,z+ 61, a)
mc.setBlock(x+22,y+ 5,z+ 61, a)
mc.setBlock(x+64,y+ 4,z+ 61, a)
mc.setBlock(x+63,y+ 4,z+ 61, a)
mc.setBlock(x+74,y+ 76,z+ 67, a)
mc.setBlock(x+15,y+ 77,z+ 67, a)
mc.setBlock(x+73,y+ 77,z+ 67, a)
mc.setBlock(x+25,y+ 4,z+ 61, a)
mc.setBlock(x+24,y+ 4,z+ 61, a)
mc.setBlock(x+62,y+ 3,z+ 61, a)
mc.setBlock(x+61,y+ 3,z+ 61, a)
mc.setBlock(x+60,y+ 3,z+ 61, a)
mc.setBlock(x+16,y+ 78,z+ 67, a)
mc.setBlock(x+71,y+ 78,z+ 67, a)
mc.setBlock(x+72,y+ 78,z+ 67, a)
mc.setBlock(x+17,y+ 79,z+ 67, a)
mc.setBlock(x+28,y+ 3,z+ 61, a)
mc.setBlock(x+27,y+ 3,z+ 61, a)
mc.setBlock(x+26,y+ 3,z+ 61, a)
mc.setBlock(x+59,y+ 2,z+ 61, a)
mc.setBlock(x+58,y+ 2,z+ 61, a)
mc.setBlock(x+57,y+ 2,z+ 61, a)
mc.setBlock(x+56,y+ 2,z+ 61, a)
mc.setBlock(x+18,y+ 79,z+ 67, a)
mc.setBlock(x+70,y+ 79,z+ 67, a)
mc.setBlock(x+32,y+ 2,z+ 61, a)
mc.setBlock(x+31,y+ 2,z+ 61, a)
mc.setBlock(x+30,y+ 2,z+ 61, a)
mc.setBlock(x+29,y+ 2,z+ 61, a)
mc.setBlock(x+55,y+ 1,z+ 61, a)
mc.setBlock(x+54,y+ 1,z+ 61, a)
mc.setBlock(x+53,y+ 1,z+ 61, a)
mc.setBlock(x+52,y+ 1,z+ 61, a)
mc.setBlock(x+51,y+ 1,z+ 61, a)
mc.setBlock(x+50,y+ 1,z+ 61, a)
mc.setBlock(x+19,y+ 80,z+ 67, a)
mc.setBlock(x+69,y+ 80,z+ 67, a)
mc.setBlock(x+20,y+ 81,z+ 67, a)
mc.setBlock(x+21,y+ 81,z+ 67, a)
mc.setBlock(x+67,y+ 81,z+ 67, a)
mc.setBlock(x+68,y+ 81,z+ 67, a)
mc.setBlock(x+38,y+ 1,z+ 61, a)
mc.setBlock(x+37,y+ 1,z+ 61, a)
mc.setBlock(x+36,y+ 1,z+ 61, a)
mc.setBlock(x+35,y+ 1,z+ 61, a)
mc.setBlock(x+34,y+ 1,z+ 61, a)
mc.setBlock(x+33,y+ 1,z+ 61, a)
mc.setBlock(x+49,y+ 0,z+ 61, a)
mc.setBlock(x+48,y+ 0,z+ 61, a)
mc.setBlock(x+47,y+ 0,z+ 61, a)
mc.setBlock(x+46,y+ 0,z+ 61, a)
mc.setBlock(x+45,y+ 0,z+ 61, a)
mc.setBlock(x+44,y+ 0,z+ 61, a)
mc.setBlock(x+43,y+ 0,z+ 61, a)
mc.setBlock(x+42,y+ 0,z+ 61, a)
mc.setBlock(x+41,y+ 0,z+ 61, a)
mc.setBlock(x+40,y+ 0,z+ 61, a)
mc.setBlock(x+39,y+ 0,z+ 61, a)
mc.setBlock(x+50,y+ 88,z+ 60, a)
mc.setBlock(x+49,y+ 88,z+ 60, a)
mc.setBlock(x+48,y+ 88,z+ 60, a)
mc.setBlock(x+47,y+ 88,z+ 60, a)
mc.setBlock(x+46,y+ 88,z+ 60, a)
mc.setBlock(x+45,y+ 88,z+ 60, a)
mc.setBlock(x+44,y+ 88,z+ 60, a)
mc.setBlock(x+43,y+ 88,z+ 60, a)
mc.setBlock(x+42,y+ 88,z+ 60, a)
mc.setBlock(x+41,y+ 88,z+ 60, a)
mc.setBlock(x+40,y+ 88,z+ 60, a)
mc.setBlock(x+39,y+ 88,z+ 60, a)
mc.setBlock(x+38,y+ 88,z+ 60, a)
mc.setBlock(x+56,y+ 87,z+ 60, a)
mc.setBlock(x+55,y+ 87,z+ 60, a)
mc.setBlock(x+54,y+ 87,z+ 60, a)
mc.setBlock(x+53,y+ 87,z+ 60, a)
mc.setBlock(x+52,y+ 87,z+ 60, a)
mc.setBlock(x+51,y+ 87,z+ 60, a)
mc.setBlock(x+22,y+ 82,z+ 67, a)
mc.setBlock(x+23,y+ 82,z+ 67, a)
mc.setBlock(x+65,y+ 82,z+ 67, a)
mc.setBlock(x+66,y+ 82,z+ 67, a)
mc.setBlock(x+37,y+ 87,z+ 60, a)
mc.setBlock(x+36,y+ 87,z+ 60, a)
mc.setBlock(x+35,y+ 87,z+ 60, a)
mc.setBlock(x+34,y+ 87,z+ 60, a)
mc.setBlock(x+33,y+ 87,z+ 60, a)
mc.setBlock(x+32,y+ 87,z+ 60, a)
mc.setBlock(x+59,y+ 86,z+ 60, a)
mc.setBlock(x+58,y+ 86,z+ 60, a)
mc.setBlock(x+57,y+ 86,z+ 60, a)
mc.setBlock(x+24,y+ 83,z+ 67, a)
mc.setBlock(x+25,y+ 83,z+ 67, a)
mc.setBlock(x+26,y+ 83,z+ 67, a)
mc.setBlock(x+62,y+ 83,z+ 67, a)
mc.setBlock(x+31,y+ 86,z+ 60, a)
mc.setBlock(x+30,y+ 86,z+ 60, a)
mc.setBlock(x+29,y+ 86,z+ 60, a)
mc.setBlock(x+62,y+ 85,z+ 60, a)
mc.setBlock(x+61,y+ 85,z+ 60, a)
mc.setBlock(x+60,y+ 85,z+ 60, a)
mc.setBlock(x+63,y+ 83,z+ 67, a)
mc.setBlock(x+64,y+ 83,z+ 67, a)
mc.setBlock(x+28,y+ 85,z+ 60, a)
mc.setBlock(x+27,y+ 85,z+ 60, a)
mc.setBlock(x+26,y+ 85,z+ 60, a)
mc.setBlock(x+64,y+ 84,z+ 60, a)
mc.setBlock(x+63,y+ 84,z+ 60, a)
mc.setBlock(x+27,y+ 84,z+ 67, a)
mc.setBlock(x+28,y+ 84,z+ 67, a)
mc.setBlock(x+25,y+ 84,z+ 60, a)
mc.setBlock(x+24,y+ 84,z+ 60, a)
mc.setBlock(x+23,y+ 84,z+ 60, a)
mc.setBlock(x+66,y+ 83,z+ 60, a)
mc.setBlock(x+65,y+ 83,z+ 60, a)
mc.setBlock(x+60,y+ 84,z+ 67, a)
mc.setBlock(x+61,y+ 84,z+ 67, a)
mc.setBlock(x+29,y+ 85,z+ 67, a)
mc.setBlock(x+22,y+ 83,z+ 60, a)
mc.setBlock(x+68,y+ 82,z+ 60, a)
mc.setBlock(x+67,y+ 82,z+ 60, a)
mc.setBlock(x+30,y+ 85,z+ 67, a)
mc.setBlock(x+31,y+ 85,z+ 67, a)
mc.setBlock(x+21,y+ 82,z+ 60, a)
mc.setBlock(x+20,y+ 82,z+ 60, a)
mc.setBlock(x+70,y+ 81,z+ 60, a)
mc.setBlock(x+69,y+ 81,z+ 60, a)
mc.setBlock(x+32,y+ 85,z+ 67, a)
mc.setBlock(x+56,y+ 85,z+ 67, a)
mc.setBlock(x+19,y+ 81,z+ 60, a)
mc.setBlock(x+18,y+ 81,z+ 60, a)
mc.setBlock(x+71,y+ 80,z+ 60, a)
mc.setBlock(x+57,y+ 85,z+ 67, a)
mc.setBlock(x+58,y+ 85,z+ 67, a)
mc.setBlock(x+17,y+ 80,z+ 60, a)
mc.setBlock(x+73,y+ 79,z+ 60, a)
mc.setBlock(x+72,y+ 79,z+ 60, a)
mc.setBlock(x+59,y+ 85,z+ 67, a)
mc.setBlock(x+33,y+ 86,z+ 67, a)
mc.setBlock(x+16,y+ 79,z+ 60, a)
mc.setBlock(x+15,y+ 79,z+ 60, a)
mc.setBlock(x+74,y+ 78,z+ 60, a)
mc.setBlock(x+34,y+ 86,z+ 67, a)
mc.setBlock(x+35,y+ 86,z+ 67, a)
mc.setBlock(x+14,y+ 78,z+ 60, a)
mc.setBlock(x+75,y+ 77,z+ 60, a)
mc.setBlock(x+36,y+ 86,z+ 67, a)
mc.setBlock(x+37,y+ 86,z+ 67, a)
mc.setBlock(x+13,y+ 77,z+ 60, a)
mc.setBlock(x+76,y+ 76,z+ 60, a)
mc.setBlock(x+38,y+ 86,z+ 67, a)
mc.setBlock(x+50,y+ 86,z+ 67, a)
mc.setBlock(x+12,y+ 76,z+ 60, a)
mc.setBlock(x+77,y+ 75,z+ 60, a)
mc.setBlock(x+51,y+ 86,z+ 67, a)
mc.setBlock(x+52,y+ 86,z+ 67, a)
mc.setBlock(x+11,y+ 75,z+ 60, a)
mc.setBlock(x+78,y+ 74,z+ 60, a)
mc.setBlock(x+53,y+ 86,z+ 67, a)
mc.setBlock(x+54,y+ 86,z+ 67, a)
mc.setBlock(x+10,y+ 74,z+ 60, a)
mc.setBlock(x+79,y+ 73,z+ 60, a)
mc.setBlock(x+55,y+ 86,z+ 67, a)
mc.setBlock(x+39,y+ 87,z+ 67, a)
mc.setBlock(x+9,y+ 73,z+ 60, a)
mc.setBlock(x+79,y+ 72,z+ 60, a)
mc.setBlock(x+9,y+ 72,z+ 60, a)
mc.setBlock(x+80,y+ 71,z+ 60, a)
mc.setBlock(x+40,y+ 87,z+ 67, a)
mc.setBlock(x+41,y+ 87,z+ 67, a)
mc.setBlock(x+8,y+ 71,z+ 60, a)
mc.setBlock(x+81,y+ 70,z+ 60, a)
mc.setBlock(x+42,y+ 87,z+ 67, a)
mc.setBlock(x+43,y+ 87,z+ 67, a)
mc.setBlock(x+7,y+ 70,z+ 60, a)
mc.setBlock(x+81,y+ 69,z+ 60, a)
mc.setBlock(x+7,y+ 69,z+ 60, a)
mc.setBlock(x+82,y+ 68,z+ 60, a)
mc.setBlock(x+44,y+ 87,z+ 67, a)
mc.setBlock(x+45,y+ 87,z+ 67, a)
mc.setBlock(x+6,y+ 68,z+ 60, a)
mc.setBlock(x+82,y+ 67,z+ 60, a)
mc.setBlock(x+6,y+ 67,z+ 60, a)
mc.setBlock(x+83,y+ 66,z+ 60, a)
mc.setBlock(x+46,y+ 87,z+ 67, a)
mc.setBlock(x+47,y+ 87,z+ 67, a)
mc.setBlock(x+5,y+ 66,z+ 60, a)
mc.setBlock(x+83,y+ 65,z+ 60, a)
mc.setBlock(x+5,y+ 65,z+ 60, a)
mc.setBlock(x+84,y+ 64,z+ 60, a)
mc.setBlock(x+48,y+ 87,z+ 67, a)
mc.setBlock(x+49,y+ 87,z+ 67, a)
mc.setBlock(x+4,y+ 64,z+ 60, a)
mc.setBlock(x+84,y+ 63,z+ 60, a)
mc.setBlock(x+4,y+ 63,z+ 60, a)
mc.setBlock(x+85,y+ 62,z+ 60, a)
mc.setBlock(x+42,y+ 1,z+ 68, a)
mc.setBlock(x+43,y+ 1,z+ 68, a)
mc.setBlock(x+3,y+ 62,z+ 60, a)
mc.setBlock(x+85,y+ 61,z+ 60, a)
mc.setBlock(x+3,y+ 61,z+ 60, a)
mc.setBlock(x+85,y+ 60,z+ 60, a)
mc.setBlock(x+3,y+ 60,z+ 60, a)
mc.setBlock(x+86,y+ 59,z+ 60, a)
mc.setBlock(x+44,y+ 1,z+ 68, a)
mc.setBlock(x+45,y+ 1,z+ 68, a)
mc.setBlock(x+2,y+ 59,z+ 60, a)
mc.setBlock(x+86,y+ 58,z+ 60, a)
mc.setBlock(x+2,y+ 58,z+ 60, a)
mc.setBlock(x+86,y+ 57,z+ 60, a)
mc.setBlock(x+2,y+ 57,z+ 60, a)
mc.setBlock(x+86,y+ 56,z+ 60, a)
mc.setBlock(x+2,y+ 56,z+ 60, a)
mc.setBlock(x+87,y+ 55,z+ 60, a)
mc.setBlock(x+46,y+ 1,z+ 68, a)
mc.setBlock(x+34,y+ 2,z+ 68, a)
mc.setBlock(x+1,y+ 55,z+ 60, a)
mc.setBlock(x+87,y+ 54,z+ 60, a)
mc.setBlock(x+1,y+ 54,z+ 60, a)
mc.setBlock(x+87,y+ 53,z+ 60, a)
mc.setBlock(x+1,y+ 53,z+ 60, a)
mc.setBlock(x+87,y+ 52,z+ 60, a)
mc.setBlock(x+1,y+ 52,z+ 60, a)
mc.setBlock(x+87,y+ 51,z+ 60, a)
mc.setBlock(x+1,y+ 51,z+ 60, a)
mc.setBlock(x+87,y+ 50,z+ 60, a)
mc.setBlock(x+1,y+ 50,z+ 60, a)
mc.setBlock(x+88,y+ 49,z+ 60, a)
mc.setBlock(x+35,y+ 2,z+ 68, a)
mc.setBlock(x+36,y+ 2,z+ 68, a)
mc.setBlock(x+0,y+ 49,z+ 60, a)
mc.setBlock(x+88,y+ 48,z+ 60, a)
mc.setBlock(x+37,y+ 2,z+ 68, a)
mc.setBlock(x+38,y+ 2,z+ 68, a)
mc.setBlock(x+0,y+ 48,z+ 60, a)
mc.setBlock(x+88,y+ 47,z+ 60, a)
mc.setBlock(x+39,y+ 2,z+ 68, a)
mc.setBlock(x+0,y+ 47,z+ 60, a)
mc.setBlock(x+88,y+ 46,z+ 60, a)
mc.setBlock(x+0,y+ 46,z+ 60, a)
mc.setBlock(x+88,y+ 45,z+ 60, a)
mc.setBlock(x+0,y+ 45,z+ 60, a)
mc.setBlock(x+88,y+ 44,z+ 60, a)
mc.setBlock(x+0,y+ 44,z+ 60, a)
mc.setBlock(x+88,y+ 43,z+ 60, a)
mc.setBlock(x+0,y+ 43,z+ 60, a)
mc.setBlock(x+88,y+ 42,z+ 60, a)
mc.setBlock(x+0,y+ 42,z+ 60, a)
mc.setBlock(x+88,y+ 41,z+ 60, a)
mc.setBlock(x+40,y+ 2,z+ 68, a)
mc.setBlock(x+0,y+ 41,z+ 60, a)
mc.setBlock(x+88,y+ 40,z+ 60, a)
mc.setBlock(x+41,y+ 2,z+ 68, a)
mc.setBlock(x+47,y+ 2,z+ 68, a)
mc.setBlock(x+0,y+ 40,z+ 60, a)
mc.setBlock(x+88,y+ 39,z+ 60, a)
mc.setBlock(x+48,y+ 2,z+ 68, a)
mc.setBlock(x+49,y+ 2,z+ 68, a)
mc.setBlock(x+0,y+ 39,z+ 60, a)
mc.setBlock(x+87,y+ 38,z+ 60, a)
mc.setBlock(x+1,y+ 38,z+ 60, a)
mc.setBlock(x+87,y+ 37,z+ 60, a)
mc.setBlock(x+1,y+ 37,z+ 60, a)
mc.setBlock(x+87,y+ 36,z+ 60, a)
mc.setBlock(x+1,y+ 36,z+ 60, a)
mc.setBlock(x+87,y+ 35,z+ 60, a)
mc.setBlock(x+1,y+ 35,z+ 60, a)
mc.setBlock(x+87,y+ 34,z+ 60, a)
mc.setBlock(x+1,y+ 34,z+ 60, a)
mc.setBlock(x+87,y+ 33,z+ 60, a)
mc.setBlock(x+50,y+ 2,z+ 68, a)
mc.setBlock(x+51,y+ 2,z+ 68, a)
mc.setBlock(x+1,y+ 33,z+ 60, a)
mc.setBlock(x+86,y+ 32,z+ 60, a)
mc.setBlock(x+2,y+ 32,z+ 60, a)
mc.setBlock(x+86,y+ 31,z+ 60, a)
mc.setBlock(x+2,y+ 31,z+ 60, a)
mc.setBlock(x+86,y+ 30,z+ 60, a)
mc.setBlock(x+2,y+ 30,z+ 60, a)
mc.setBlock(x+86,y+ 29,z+ 60, a)
mc.setBlock(x+52,y+ 2,z+ 68, a)
mc.setBlock(x+53,y+ 2,z+ 68, a)
mc.setBlock(x+2,y+ 29,z+ 60, a)
mc.setBlock(x+85,y+ 28,z+ 60, a)
mc.setBlock(x+3,y+ 28,z+ 60, a)
mc.setBlock(x+85,y+ 27,z+ 60, a)
mc.setBlock(x+3,y+ 27,z+ 60, a)
mc.setBlock(x+85,y+ 26,z+ 60, a)
mc.setBlock(x+54,y+ 2,z+ 68, a)
mc.setBlock(x+30,y+ 3,z+ 68, a)
mc.setBlock(x+3,y+ 26,z+ 60, a)
mc.setBlock(x+84,y+ 25,z+ 60, a)
mc.setBlock(x+4,y+ 25,z+ 60, a)
mc.setBlock(x+84,y+ 24,z+ 60, a)
mc.setBlock(x+31,y+ 3,z+ 68, a)
mc.setBlock(x+32,y+ 3,z+ 68, a)
mc.setBlock(x+4,y+ 24,z+ 60, a)
mc.setBlock(x+83,y+ 23,z+ 60, a)
mc.setBlock(x+5,y+ 23,z+ 60, a)
mc.setBlock(x+83,y+ 22,z+ 60, a)
mc.setBlock(x+33,y+ 3,z+ 68, a)
mc.setBlock(x+55,y+ 3,z+ 68, a)
mc.setBlock(x+5,y+ 22,z+ 60, a)
mc.setBlock(x+82,y+ 21,z+ 60, a)
mc.setBlock(x+6,y+ 21,z+ 60, a)
mc.setBlock(x+82,y+ 20,z+ 60, a)
mc.setBlock(x+56,y+ 3,z+ 68, a)
mc.setBlock(x+57,y+ 3,z+ 68, a)
mc.setBlock(x+6,y+ 20,z+ 60, a)
mc.setBlock(x+81,y+ 19,z+ 60, a)
mc.setBlock(x+7,y+ 19,z+ 60, a)
mc.setBlock(x+81,y+ 18,z+ 60, a)
mc.setBlock(x+58,y+ 3,z+ 68, a)
mc.setBlock(x+27,y+ 4,z+ 68, a)
mc.setBlock(x+7,y+ 18,z+ 60, a)
mc.setBlock(x+80,y+ 17,z+ 60, a)
mc.setBlock(x+28,y+ 4,z+ 68, a)
mc.setBlock(x+29,y+ 4,z+ 68, a)
mc.setBlock(x+8,y+ 17,z+ 60, a)
mc.setBlock(x+79,y+ 16,z+ 60, a)
mc.setBlock(x+9,y+ 16,z+ 60, a)
mc.setBlock(x+79,y+ 15,z+ 60, a)
mc.setBlock(x+59,y+ 4,z+ 68, a)
mc.setBlock(x+60,y+ 4,z+ 68, a)
mc.setBlock(x+9,y+ 15,z+ 60, a)
mc.setBlock(x+78,y+ 14,z+ 60, a)
mc.setBlock(x+61,y+ 4,z+ 68, a)
mc.setBlock(x+25,y+ 5,z+ 68, a)
mc.setBlock(x+10,y+ 14,z+ 60, a)
mc.setBlock(x+77,y+ 13,z+ 60, a)
mc.setBlock(x+26,y+ 5,z+ 68, a)
mc.setBlock(x+62,y+ 5,z+ 68, a)
mc.setBlock(x+11,y+ 13,z+ 60, a)
mc.setBlock(x+76,y+ 12,z+ 60, a)
mc.setBlock(x+63,y+ 5,z+ 68, a)
mc.setBlock(x+23,y+ 6,z+ 68, a)
mc.setBlock(x+12,y+ 12,z+ 60, a)
mc.setBlock(x+75,y+ 11,z+ 60, a)
mc.setBlock(x+24,y+ 6,z+ 68, a)
mc.setBlock(x+64,y+ 6,z+ 68, a)
mc.setBlock(x+13,y+ 11,z+ 60, a)
mc.setBlock(x+74,y+ 10,z+ 60, a)
mc.setBlock(x+65,y+ 6,z+ 68, a)
mc.setBlock(x+21,y+ 7,z+ 68, a)
mc.setBlock(x+14,y+ 10,z+ 60, a)
mc.setBlock(x+73,y+ 9,z+ 60, a)
mc.setBlock(x+72,y+ 9,z+ 60, a)
mc.setBlock(x+22,y+ 7,z+ 68, a)
mc.setBlock(x+66,y+ 7,z+ 68, a)
mc.setBlock(x+16,y+ 9,z+ 60, a)
mc.setBlock(x+15,y+ 9,z+ 60, a)
mc.setBlock(x+71,y+ 8,z+ 60, a)
mc.setBlock(x+67,y+ 7,z+ 68, a)
mc.setBlock(x+19,y+ 8,z+ 68, a)
mc.setBlock(x+17,y+ 8,z+ 60, a)
mc.setBlock(x+70,y+ 7,z+ 60, a)
mc.setBlock(x+69,y+ 7,z+ 60, a)
mc.setBlock(x+20,y+ 8,z+ 68, a)
mc.setBlock(x+68,y+ 8,z+ 68, a)
mc.setBlock(x+19,y+ 7,z+ 60, a)
mc.setBlock(x+18,y+ 7,z+ 60, a)
mc.setBlock(x+68,y+ 6,z+ 60, a)
mc.setBlock(x+67,y+ 6,z+ 60, a)
mc.setBlock(x+69,y+ 8,z+ 68, a)
mc.setBlock(x+18,y+ 9,z+ 68, a)
mc.setBlock(x+21,y+ 6,z+ 60, a)
mc.setBlock(x+20,y+ 6,z+ 60, a)
mc.setBlock(x+66,y+ 5,z+ 60, a)
mc.setBlock(x+70,y+ 9,z+ 68, a)
mc.setBlock(x+17,y+ 10,z+ 68, a)
mc.setBlock(x+71,y+ 10,z+ 68, a)
mc.setBlock(x+23,y+ 5,z+ 60, a)
mc.setBlock(x+22,y+ 5,z+ 60, a)
mc.setBlock(x+65,y+ 4,z+ 60, a)
mc.setBlock(x+64,y+ 4,z+ 60, a)
mc.setBlock(x+63,y+ 4,z+ 60, a)
mc.setBlock(x+15,y+ 11,z+ 68, a)
mc.setBlock(x+16,y+ 11,z+ 68, a)
mc.setBlock(x+25,y+ 4,z+ 60, a)
mc.setBlock(x+24,y+ 4,z+ 60, a)
mc.setBlock(x+62,y+ 3,z+ 60, a)
mc.setBlock(x+61,y+ 3,z+ 60, a)
mc.setBlock(x+60,y+ 3,z+ 60, a)
mc.setBlock(x+72,y+ 11,z+ 68, a)
mc.setBlock(x+73,y+ 11,z+ 68, a)
mc.setBlock(x+28,y+ 3,z+ 60, a)
mc.setBlock(x+27,y+ 3,z+ 60, a)
mc.setBlock(x+26,y+ 3,z+ 60, a)
mc.setBlock(x+59,y+ 2,z+ 60, a)
mc.setBlock(x+58,y+ 2,z+ 60, a)
mc.setBlock(x+57,y+ 2,z+ 60, a)
mc.setBlock(x+14,y+ 12,z+ 68, a)
mc.setBlock(x+74,y+ 12,z+ 68, a)
mc.setBlock(x+13,y+ 13,z+ 68, a)
mc.setBlock(x+75,y+ 13,z+ 68, a)
mc.setBlock(x+31,y+ 2,z+ 60, a)
mc.setBlock(x+30,y+ 2,z+ 60, a)
mc.setBlock(x+29,y+ 2,z+ 60, a)
mc.setBlock(x+56,y+ 1,z+ 60, a)
mc.setBlock(x+55,y+ 1,z+ 60, a)
mc.setBlock(x+54,y+ 1,z+ 60, a)
mc.setBlock(x+53,y+ 1,z+ 60, a)
mc.setBlock(x+52,y+ 1,z+ 60, a)
mc.setBlock(x+51,y+ 1,z+ 60, a)
mc.setBlock(x+12,y+ 14,z+ 68, a)
mc.setBlock(x+76,y+ 14,z+ 68, a)
mc.setBlock(x+11,y+ 15,z+ 68, a)
mc.setBlock(x+77,y+ 15,z+ 68, a)
mc.setBlock(x+37,y+ 1,z+ 60, a)
mc.setBlock(x+36,y+ 1,z+ 60, a)
mc.setBlock(x+35,y+ 1,z+ 60, a)
mc.setBlock(x+34,y+ 1,z+ 60, a)
mc.setBlock(x+33,y+ 1,z+ 60, a)
mc.setBlock(x+32,y+ 1,z+ 60, a)
mc.setBlock(x+50,y+ 0,z+ 60, a)
mc.setBlock(x+49,y+ 0,z+ 60, a)
mc.setBlock(x+48,y+ 0,z+ 60, a)
mc.setBlock(x+47,y+ 0,z+ 60, a)
mc.setBlock(x+46,y+ 0,z+ 60, a)
mc.setBlock(x+45,y+ 0,z+ 60, a)
mc.setBlock(x+44,y+ 0,z+ 60, a)
mc.setBlock(x+43,y+ 0,z+ 60, a)
mc.setBlock(x+42,y+ 0,z+ 60, a)
mc.setBlock(x+41,y+ 0,z+ 60, a)
mc.setBlock(x+40,y+ 0,z+ 60, a)
mc.setBlock(x+39,y+ 0,z+ 60, a)
mc.setBlock(x+38,y+ 0,z+ 60, a)
mc.setBlock(x+50,y+ 88,z+ 59, a)
mc.setBlock(x+49,y+ 88,z+ 59, a)
mc.setBlock(x+48,y+ 88,z+ 59, a)
mc.setBlock(x+47,y+ 88,z+ 59, a)
mc.setBlock(x+46,y+ 88,z+ 59, a)
mc.setBlock(x+45,y+ 88,z+ 59, a)
mc.setBlock(x+44,y+ 88,z+ 59, a)
mc.setBlock(x+43,y+ 88,z+ 59, a)
mc.setBlock(x+42,y+ 88,z+ 59, a)
mc.setBlock(x+41,y+ 88,z+ 59, a)
mc.setBlock(x+40,y+ 88,z+ 59, a)
mc.setBlock(x+39,y+ 88,z+ 59, a)
mc.setBlock(x+38,y+ 88,z+ 59, a)
mc.setBlock(x+56,y+ 87,z+ 59, a)
mc.setBlock(x+55,y+ 87,z+ 59, a)
mc.setBlock(x+54,y+ 87,z+ 59, a)
mc.setBlock(x+53,y+ 87,z+ 59, a)
mc.setBlock(x+52,y+ 87,z+ 59, a)
mc.setBlock(x+51,y+ 87,z+ 59, a)
mc.setBlock(x+11,y+ 16,z+ 68, a)
mc.setBlock(x+77,y+ 16,z+ 68, a)
mc.setBlock(x+37,y+ 87,z+ 59, a)
mc.setBlock(x+36,y+ 87,z+ 59, a)
mc.setBlock(x+35,y+ 87,z+ 59, a)
mc.setBlock(x+34,y+ 87,z+ 59, a)
mc.setBlock(x+33,y+ 87,z+ 59, a)
mc.setBlock(x+32,y+ 87,z+ 59, a)
mc.setBlock(x+60,y+ 86,z+ 59, a)
mc.setBlock(x+59,y+ 86,z+ 59, a)
mc.setBlock(x+58,y+ 86,z+ 59, a)
mc.setBlock(x+57,y+ 86,z+ 59, a)
mc.setBlock(x+10,y+ 17,z+ 68, a)
mc.setBlock(x+78,y+ 17,z+ 68, a)
mc.setBlock(x+31,y+ 86,z+ 59, a)
mc.setBlock(x+30,y+ 86,z+ 59, a)
mc.setBlock(x+29,y+ 86,z+ 59, a)
mc.setBlock(x+28,y+ 86,z+ 59, a)
mc.setBlock(x+62,y+ 85,z+ 59, a)
mc.setBlock(x+61,y+ 85,z+ 59, a)
mc.setBlock(x+9,y+ 18,z+ 68, a)
mc.setBlock(x+79,y+ 18,z+ 68, a)
mc.setBlock(x+8,y+ 19,z+ 68, a)
mc.setBlock(x+80,y+ 19,z+ 68, a)
mc.setBlock(x+27,y+ 85,z+ 59, a)
mc.setBlock(x+26,y+ 85,z+ 59, a)
mc.setBlock(x+65,y+ 84,z+ 59, a)
mc.setBlock(x+64,y+ 84,z+ 59, a)
mc.setBlock(x+63,y+ 84,z+ 59, a)
mc.setBlock(x+8,y+ 20,z+ 68, a)
mc.setBlock(x+80,y+ 20,z+ 68, a)
mc.setBlock(x+25,y+ 84,z+ 59, a)
mc.setBlock(x+24,y+ 84,z+ 59, a)
mc.setBlock(x+23,y+ 84,z+ 59, a)
mc.setBlock(x+67,y+ 83,z+ 59, a)
mc.setBlock(x+66,y+ 83,z+ 59, a)
mc.setBlock(x+7,y+ 21,z+ 68, a)
mc.setBlock(x+81,y+ 21,z+ 68, a)
mc.setBlock(x+22,y+ 83,z+ 59, a)
mc.setBlock(x+21,y+ 83,z+ 59, a)
mc.setBlock(x+69,y+ 82,z+ 59, a)
mc.setBlock(x+68,y+ 82,z+ 59, a)
mc.setBlock(x+7,y+ 22,z+ 68, a)
mc.setBlock(x+81,y+ 22,z+ 68, a)
mc.setBlock(x+20,y+ 82,z+ 59, a)
mc.setBlock(x+19,y+ 82,z+ 59, a)
mc.setBlock(x+70,y+ 81,z+ 59, a)
mc.setBlock(x+6,y+ 23,z+ 68, a)
mc.setBlock(x+82,y+ 23,z+ 68, a)
mc.setBlock(x+6,y+ 24,z+ 68, a)
mc.setBlock(x+82,y+ 24,z+ 68, a)
mc.setBlock(x+18,y+ 81,z+ 59, a)
mc.setBlock(x+72,y+ 80,z+ 59, a)
mc.setBlock(x+71,y+ 80,z+ 59, a)
mc.setBlock(x+5,y+ 25,z+ 68, a)
mc.setBlock(x+83,y+ 25,z+ 68, a)
mc.setBlock(x+17,y+ 80,z+ 59, a)
mc.setBlock(x+16,y+ 80,z+ 59, a)
mc.setBlock(x+73,y+ 79,z+ 59, a)
mc.setBlock(x+5,y+ 26,z+ 68, a)
mc.setBlock(x+83,y+ 26,z+ 68, a)
mc.setBlock(x+5,y+ 27,z+ 68, a)
mc.setBlock(x+83,y+ 27,z+ 68, a)
mc.setBlock(x+15,y+ 79,z+ 59, a)
mc.setBlock(x+74,y+ 78,z+ 59, a)
mc.setBlock(x+4,y+ 28,z+ 68, a)
mc.setBlock(x+84,y+ 28,z+ 68, a)
mc.setBlock(x+14,y+ 78,z+ 59, a)
mc.setBlock(x+75,y+ 77,z+ 59, a)
mc.setBlock(x+4,y+ 29,z+ 68, a)
mc.setBlock(x+84,y+ 29,z+ 68, a)
mc.setBlock(x+13,y+ 77,z+ 59, a)
mc.setBlock(x+76,y+ 76,z+ 59, a)
mc.setBlock(x+4,y+ 30,z+ 68, a)
mc.setBlock(x+84,y+ 30,z+ 68, a)
mc.setBlock(x+12,y+ 76,z+ 59, a)
mc.setBlock(x+77,y+ 75,z+ 59, a)
mc.setBlock(x+3,y+ 31,z+ 68, a)
mc.setBlock(x+85,y+ 31,z+ 68, a)
mc.setBlock(x+11,y+ 75,z+ 59, a)
mc.setBlock(x+78,y+ 74,z+ 59, a)
mc.setBlock(x+3,y+ 32,z+ 68, a)
mc.setBlock(x+85,y+ 32,z+ 68, a)
mc.setBlock(x+10,y+ 74,z+ 59, a)
mc.setBlock(x+79,y+ 73,z+ 59, a)
mc.setBlock(x+3,y+ 33,z+ 68, a)
mc.setBlock(x+85,y+ 33,z+ 68, a)
mc.setBlock(x+9,y+ 73,z+ 59, a)
mc.setBlock(x+80,y+ 72,z+ 59, a)
mc.setBlock(x+3,y+ 34,z+ 68, a)
mc.setBlock(x+85,y+ 34,z+ 68, a)
mc.setBlock(x+8,y+ 72,z+ 59, a)
mc.setBlock(x+80,y+ 71,z+ 59, a)
mc.setBlock(x+2,y+ 35,z+ 68, a)
mc.setBlock(x+86,y+ 35,z+ 68, a)
mc.setBlock(x+8,y+ 71,z+ 59, a)
mc.setBlock(x+81,y+ 70,z+ 59, a)
mc.setBlock(x+2,y+ 36,z+ 68, a)
mc.setBlock(x+86,y+ 36,z+ 68, a)
mc.setBlock(x+7,y+ 70,z+ 59, a)
mc.setBlock(x+81,y+ 69,z+ 59, a)
mc.setBlock(x+7,y+ 69,z+ 59, a)
mc.setBlock(x+82,y+ 68,z+ 59, a)
mc.setBlock(x+2,y+ 37,z+ 68, a)
mc.setBlock(x+86,y+ 37,z+ 68, a)
mc.setBlock(x+6,y+ 68,z+ 59, a)
mc.setBlock(x+83,y+ 67,z+ 59, a)
mc.setBlock(x+2,y+ 38,z+ 68, a)
mc.setBlock(x+86,y+ 38,z+ 68, a)
mc.setBlock(x+5,y+ 67,z+ 59, a)
mc.setBlock(x+83,y+ 66,z+ 59, a)
mc.setBlock(x+2,y+ 39,z+ 68, a)
mc.setBlock(x+86,y+ 39,z+ 68, a)
mc.setBlock(x+5,y+ 66,z+ 59, a)
mc.setBlock(x+84,y+ 65,z+ 59, a)
mc.setBlock(x+2,y+ 40,z+ 68, a)
mc.setBlock(x+86,y+ 40,z+ 68, a)
mc.setBlock(x+4,y+ 65,z+ 59, a)
mc.setBlock(x+84,y+ 64,z+ 59, a)
mc.setBlock(x+2,y+ 41,z+ 68, a)
mc.setBlock(x+86,y+ 41,z+ 68, a)
mc.setBlock(x+4,y+ 64,z+ 59, a)
mc.setBlock(x+84,y+ 63,z+ 59, a)
mc.setBlock(x+4,y+ 63,z+ 59, a)
mc.setBlock(x+85,y+ 62,z+ 59, a)
mc.setBlock(x+2,y+ 42,z+ 68, a)
mc.setBlock(x+86,y+ 42,z+ 68, a)
mc.setBlock(x+3,y+ 62,z+ 59, a)
mc.setBlock(x+85,y+ 61,z+ 59, a)
mc.setBlock(x+3,y+ 61,z+ 59, a)
mc.setBlock(x+85,y+ 60,z+ 59, a)
mc.setBlock(x+3,y+ 60,z+ 59, a)
mc.setBlock(x+86,y+ 59,z+ 59, a)
mc.setBlock(x+2,y+ 43,z+ 68, a)
mc.setBlock(x+86,y+ 43,z+ 68, a)
mc.setBlock(x+2,y+ 59,z+ 59, a)
mc.setBlock(x+86,y+ 58,z+ 59, a)
mc.setBlock(x+2,y+ 58,z+ 59, a)
mc.setBlock(x+86,y+ 57,z+ 59, a)
mc.setBlock(x+2,y+ 57,z+ 59, a)
mc.setBlock(x+87,y+ 56,z+ 59, a)
mc.setBlock(x+2,y+ 44,z+ 68, a)
mc.setBlock(x+86,y+ 44,z+ 68, a)
mc.setBlock(x+1,y+ 56,z+ 59, a)
mc.setBlock(x+87,y+ 55,z+ 59, a)
mc.setBlock(x+2,y+ 45,z+ 68, a)
mc.setBlock(x+86,y+ 45,z+ 68, a)
mc.setBlock(x+1,y+ 55,z+ 59, a)
mc.setBlock(x+87,y+ 54,z+ 59, a)
mc.setBlock(x+1,y+ 54,z+ 59, a)
mc.setBlock(x+87,y+ 53,z+ 59, a)
mc.setBlock(x+1,y+ 53,z+ 59, a)
mc.setBlock(x+87,y+ 52,z+ 59, a)
mc.setBlock(x+1,y+ 52,z+ 59, a)
mc.setBlock(x+87,y+ 51,z+ 59, a)
mc.setBlock(x+1,y+ 51,z+ 59, a)
mc.setBlock(x+88,y+ 50,z+ 59, a)
mc.setBlock(x+2,y+ 46,z+ 68, a)
mc.setBlock(x+86,y+ 46,z+ 68, a)
mc.setBlock(x+0,y+ 50,z+ 59, a)
mc.setBlock(x+88,y+ 49,z+ 59, a)
mc.setBlock(x+2,y+ 47,z+ 68, a)
mc.setBlock(x+86,y+ 47,z+ 68, a)
mc.setBlock(x+0,y+ 49,z+ 59, a)
mc.setBlock(x+88,y+ 48,z+ 59, a)
mc.setBlock(x+0,y+ 48,z+ 59, a)
mc.setBlock(x+88,y+ 47,z+ 59, a)
mc.setBlock(x+0,y+ 47,z+ 59, a)
mc.setBlock(x+88,y+ 46,z+ 59, a)
mc.setBlock(x+0,y+ 46,z+ 59, a)
mc.setBlock(x+88,y+ 45,z+ 59, a)
mc.setBlock(x+0,y+ 45,z+ 59, a)
mc.setBlock(x+88,y+ 44,z+ 59, a)
mc.setBlock(x+0,y+ 44,z+ 59, a)
mc.setBlock(x+88,y+ 43,z+ 59, a)
mc.setBlock(x+0,y+ 43,z+ 59, a)
mc.setBlock(x+88,y+ 42,z+ 59, a)
mc.setBlock(x+0,y+ 42,z+ 59, a)
mc.setBlock(x+88,y+ 41,z+ 59, a)
mc.setBlock(x+0,y+ 41,z+ 59, a)
mc.setBlock(x+88,y+ 40,z+ 59, a)
mc.setBlock(x+0,y+ 40,z+ 59, a)
mc.setBlock(x+88,y+ 39,z+ 59, a)
mc.setBlock(x+2,y+ 48,z+ 68, a)
mc.setBlock(x+86,y+ 48,z+ 68, a)
mc.setBlock(x+0,y+ 39,z+ 59, a)
mc.setBlock(x+88,y+ 38,z+ 59, a)
mc.setBlock(x+2,y+ 49,z+ 68, a)
mc.setBlock(x+86,y+ 49,z+ 68, a)
mc.setBlock(x+0,y+ 38,z+ 59, a)
mc.setBlock(x+87,y+ 37,z+ 59, a)
mc.setBlock(x+1,y+ 37,z+ 59, a)
mc.setBlock(x+87,y+ 36,z+ 59, a)
mc.setBlock(x+1,y+ 36,z+ 59, a)
mc.setBlock(x+87,y+ 35,z+ 59, a)
mc.setBlock(x+1,y+ 35,z+ 59, a)
mc.setBlock(x+87,y+ 34,z+ 59, a)
mc.setBlock(x+1,y+ 34,z+ 59, a)
mc.setBlock(x+87,y+ 33,z+ 59, a)
mc.setBlock(x+2,y+ 50,z+ 68, a)
mc.setBlock(x+86,y+ 50,z+ 68, a)
mc.setBlock(x+1,y+ 33,z+ 59, a)
mc.setBlock(x+87,y+ 32,z+ 59, a)
mc.setBlock(x+2,y+ 51,z+ 68, a)
mc.setBlock(x+86,y+ 51,z+ 68, a)
mc.setBlock(x+1,y+ 32,z+ 59, a)
mc.setBlock(x+86,y+ 31,z+ 59, a)
mc.setBlock(x+2,y+ 31,z+ 59, a)
mc.setBlock(x+86,y+ 30,z+ 59, a)
mc.setBlock(x+2,y+ 30,z+ 59, a)
mc.setBlock(x+86,y+ 29,z+ 59, a)
mc.setBlock(x+2,y+ 52,z+ 68, a)
mc.setBlock(x+86,y+ 52,z+ 68, a)
mc.setBlock(x+2,y+ 29,z+ 59, a)
mc.setBlock(x+85,y+ 28,z+ 59, a)
mc.setBlock(x+3,y+ 28,z+ 59, a)
mc.setBlock(x+85,y+ 27,z+ 59, a)
mc.setBlock(x+3,y+ 27,z+ 59, a)
mc.setBlock(x+85,y+ 26,z+ 59, a)
mc.setBlock(x+2,y+ 53,z+ 68, a)
mc.setBlock(x+86,y+ 53,z+ 68, a)
mc.setBlock(x+3,y+ 26,z+ 59, a)
mc.setBlock(x+84,y+ 25,z+ 59, a)
mc.setBlock(x+4,y+ 25,z+ 59, a)
mc.setBlock(x+84,y+ 24,z+ 59, a)
mc.setBlock(x+3,y+ 54,z+ 68, a)
mc.setBlock(x+85,y+ 54,z+ 68, a)
mc.setBlock(x+4,y+ 24,z+ 59, a)
mc.setBlock(x+84,y+ 23,z+ 59, a)
mc.setBlock(x+3,y+ 55,z+ 68, a)
mc.setBlock(x+85,y+ 55,z+ 68, a)
mc.setBlock(x+4,y+ 23,z+ 59, a)
mc.setBlock(x+83,y+ 22,z+ 59, a)
mc.setBlock(x+3,y+ 56,z+ 68, a)
mc.setBlock(x+85,y+ 56,z+ 68, a)
mc.setBlock(x+5,y+ 22,z+ 59, a)
mc.setBlock(x+83,y+ 21,z+ 59, a)
mc.setBlock(x+3,y+ 57,z+ 68, a)
mc.setBlock(x+85,y+ 57,z+ 68, a)
mc.setBlock(x+5,y+ 21,z+ 59, a)
mc.setBlock(x+82,y+ 20,z+ 59, a)
mc.setBlock(x+4,y+ 58,z+ 68, a)
mc.setBlock(x+84,y+ 58,z+ 68, a)
mc.setBlock(x+6,y+ 20,z+ 59, a)
mc.setBlock(x+81,y+ 19,z+ 59, a)
mc.setBlock(x+7,y+ 19,z+ 59, a)
mc.setBlock(x+81,y+ 18,z+ 59, a)
mc.setBlock(x+4,y+ 59,z+ 68, a)
mc.setBlock(x+84,y+ 59,z+ 68, a)
mc.setBlock(x+7,y+ 18,z+ 59, a)
mc.setBlock(x+80,y+ 17,z+ 59, a)
mc.setBlock(x+4,y+ 60,z+ 68, a)
mc.setBlock(x+84,y+ 60,z+ 68, a)
mc.setBlock(x+8,y+ 17,z+ 59, a)
mc.setBlock(x+80,y+ 16,z+ 59, a)
mc.setBlock(x+5,y+ 61,z+ 68, a)
mc.setBlock(x+83,y+ 61,z+ 68, a)
mc.setBlock(x+8,y+ 16,z+ 59, a)
mc.setBlock(x+79,y+ 15,z+ 59, a)
mc.setBlock(x+5,y+ 62,z+ 68, a)
mc.setBlock(x+83,y+ 62,z+ 68, a)
mc.setBlock(x+9,y+ 15,z+ 59, a)
mc.setBlock(x+78,y+ 14,z+ 59, a)
mc.setBlock(x+5,y+ 63,z+ 68, a)
mc.setBlock(x+83,y+ 63,z+ 68, a)
mc.setBlock(x+10,y+ 14,z+ 59, a)
mc.setBlock(x+77,y+ 13,z+ 59, a)
mc.setBlock(x+6,y+ 64,z+ 68, a)
mc.setBlock(x+82,y+ 64,z+ 68, a)
mc.setBlock(x+11,y+ 13,z+ 59, a)
mc.setBlock(x+76,y+ 12,z+ 59, a)
mc.setBlock(x+6,y+ 65,z+ 68, a)
mc.setBlock(x+82,y+ 65,z+ 68, a)
mc.setBlock(x+12,y+ 12,z+ 59, a)
mc.setBlock(x+75,y+ 11,z+ 59, a)
mc.setBlock(x+7,y+ 66,z+ 68, a)
mc.setBlock(x+81,y+ 66,z+ 68, a)
mc.setBlock(x+13,y+ 11,z+ 59, a)
mc.setBlock(x+74,y+ 10,z+ 59, a)
mc.setBlock(x+7,y+ 67,z+ 68, a)
mc.setBlock(x+81,y+ 67,z+ 68, a)
mc.setBlock(x+14,y+ 10,z+ 59, a)
mc.setBlock(x+73,y+ 9,z+ 59, a)
mc.setBlock(x+8,y+ 68,z+ 68, a)
mc.setBlock(x+80,y+ 68,z+ 68, a)
mc.setBlock(x+8,y+ 69,z+ 68, a)
mc.setBlock(x+80,y+ 69,z+ 68, a)
mc.setBlock(x+15,y+ 9,z+ 59, a)
mc.setBlock(x+72,y+ 8,z+ 59, a)
mc.setBlock(x+71,y+ 8,z+ 59, a)
mc.setBlock(x+9,y+ 70,z+ 68, a)
mc.setBlock(x+79,y+ 70,z+ 68, a)
mc.setBlock(x+17,y+ 8,z+ 59, a)
mc.setBlock(x+16,y+ 8,z+ 59, a)
mc.setBlock(x+70,y+ 7,z+ 59, a)
mc.setBlock(x+10,y+ 71,z+ 68, a)
mc.setBlock(x+78,y+ 71,z+ 68, a)
mc.setBlock(x+11,y+ 72,z+ 68, a)
mc.setBlock(x+77,y+ 72,z+ 68, a)
mc.setBlock(x+18,y+ 7,z+ 59, a)
mc.setBlock(x+69,y+ 6,z+ 59, a)
mc.setBlock(x+68,y+ 6,z+ 59, a)
mc.setBlock(x+11,y+ 73,z+ 68, a)
mc.setBlock(x+77,y+ 73,z+ 68, a)
mc.setBlock(x+20,y+ 6,z+ 59, a)
mc.setBlock(x+19,y+ 6,z+ 59, a)
mc.setBlock(x+67,y+ 5,z+ 59, a)
mc.setBlock(x+66,y+ 5,z+ 59, a)
mc.setBlock(x+12,y+ 74,z+ 68, a)
mc.setBlock(x+76,y+ 74,z+ 68, a)
mc.setBlock(x+22,y+ 5,z+ 59, a)
mc.setBlock(x+21,y+ 5,z+ 59, a)
mc.setBlock(x+65,y+ 4,z+ 59, a)
mc.setBlock(x+64,y+ 4,z+ 59, a)
mc.setBlock(x+63,y+ 4,z+ 59, a)
mc.setBlock(x+13,y+ 75,z+ 68, a)
mc.setBlock(x+75,y+ 75,z+ 68, a)
mc.setBlock(x+25,y+ 4,z+ 59, a)
mc.setBlock(x+24,y+ 4,z+ 59, a)
mc.setBlock(x+23,y+ 4,z+ 59, a)
mc.setBlock(x+62,y+ 3,z+ 59, a)
mc.setBlock(x+61,y+ 3,z+ 59, a)
mc.setBlock(x+14,y+ 76,z+ 68, a)
mc.setBlock(x+74,y+ 76,z+ 68, a)
mc.setBlock(x+15,y+ 77,z+ 68, a)
mc.setBlock(x+16,y+ 77,z+ 68, a)
mc.setBlock(x+27,y+ 3,z+ 59, a)
mc.setBlock(x+26,y+ 3,z+ 59, a)
mc.setBlock(x+60,y+ 2,z+ 59, a)
mc.setBlock(x+59,y+ 2,z+ 59, a)
mc.setBlock(x+58,y+ 2,z+ 59, a)
mc.setBlock(x+57,y+ 2,z+ 59, a)
mc.setBlock(x+72,y+ 77,z+ 68, a)
mc.setBlock(x+73,y+ 77,z+ 68, a)
mc.setBlock(x+31,y+ 2,z+ 59, a)
mc.setBlock(x+30,y+ 2,z+ 59, a)
mc.setBlock(x+29,y+ 2,z+ 59, a)
mc.setBlock(x+28,y+ 2,z+ 59, a)
mc.setBlock(x+56,y+ 1,z+ 59, a)
mc.setBlock(x+55,y+ 1,z+ 59, a)
mc.setBlock(x+54,y+ 1,z+ 59, a)
mc.setBlock(x+53,y+ 1,z+ 59, a)
mc.setBlock(x+52,y+ 1,z+ 59, a)
mc.setBlock(x+51,y+ 1,z+ 59, a)
mc.setBlock(x+17,y+ 78,z+ 68, a)
mc.setBlock(x+71,y+ 78,z+ 68, a)
mc.setBlock(x+37,y+ 1,z+ 59, a)
mc.setBlock(x+36,y+ 1,z+ 59, a)
mc.setBlock(x+35,y+ 1,z+ 59, a)
mc.setBlock(x+34,y+ 1,z+ 59, a)
mc.setBlock(x+33,y+ 1,z+ 59, a)
mc.setBlock(x+32,y+ 1,z+ 59, a)
mc.setBlock(x+50,y+ 0,z+ 59, a)
mc.setBlock(x+49,y+ 0,z+ 59, a)
mc.setBlock(x+48,y+ 0,z+ 59, a)
mc.setBlock(x+47,y+ 0,z+ 59, a)
mc.setBlock(x+46,y+ 0,z+ 59, a)
mc.setBlock(x+45,y+ 0,z+ 59, a)
mc.setBlock(x+44,y+ 0,z+ 59, a)
mc.setBlock(x+43,y+ 0,z+ 59, a)
mc.setBlock(x+42,y+ 0,z+ 59, a)
mc.setBlock(x+41,y+ 0,z+ 59, a)
mc.setBlock(x+40,y+ 0,z+ 59, a)
mc.setBlock(x+39,y+ 0,z+ 59, a)
mc.setBlock(x+38,y+ 0,z+ 59, a)
mc.setBlock(x+51,y+ 88,z+ 58, a)
mc.setBlock(x+50,y+ 88,z+ 58, a)
mc.setBlock(x+49,y+ 88,z+ 58, a)
mc.setBlock(x+48,y+ 88,z+ 58, a)
mc.setBlock(x+47,y+ 88,z+ 58, a)
mc.setBlock(x+46,y+ 88,z+ 58, a)
mc.setBlock(x+45,y+ 88,z+ 58, a)
mc.setBlock(x+44,y+ 88,z+ 58, a)
mc.setBlock(x+43,y+ 88,z+ 58, a)
mc.setBlock(x+42,y+ 88,z+ 58, a)
mc.setBlock(x+41,y+ 88,z+ 58, a)
mc.setBlock(x+40,y+ 88,z+ 58, a)
mc.setBlock(x+39,y+ 88,z+ 58, a)
mc.setBlock(x+38,y+ 88,z+ 58, a)
mc.setBlock(x+37,y+ 88,z+ 58, a)
mc.setBlock(x+56,y+ 87,z+ 58, a)
mc.setBlock(x+55,y+ 87,z+ 58, a)
mc.setBlock(x+54,y+ 87,z+ 58, a)
mc.setBlock(x+53,y+ 87,z+ 58, a)
mc.setBlock(x+52,y+ 87,z+ 58, a)
mc.setBlock(x+18,y+ 79,z+ 68, a)
mc.setBlock(x+70,y+ 79,z+ 68, a)
mc.setBlock(x+36,y+ 87,z+ 58, a)
mc.setBlock(x+35,y+ 87,z+ 58, a)
mc.setBlock(x+34,y+ 87,z+ 58, a)
mc.setBlock(x+33,y+ 87,z+ 58, a)
mc.setBlock(x+32,y+ 87,z+ 58, a)
mc.setBlock(x+60,y+ 86,z+ 58, a)
mc.setBlock(x+59,y+ 86,z+ 58, a)
mc.setBlock(x+58,y+ 86,z+ 58, a)
mc.setBlock(x+57,y+ 86,z+ 58, a)
mc.setBlock(x+19,y+ 80,z+ 68, a)
mc.setBlock(x+20,y+ 80,z+ 68, a)
mc.setBlock(x+31,y+ 86,z+ 58, a)
mc.setBlock(x+30,y+ 86,z+ 58, a)
mc.setBlock(x+29,y+ 86,z+ 58, a)
mc.setBlock(x+28,y+ 86,z+ 58, a)
mc.setBlock(x+63,y+ 85,z+ 58, a)
mc.setBlock(x+62,y+ 85,z+ 58, a)
mc.setBlock(x+61,y+ 85,z+ 58, a)
mc.setBlock(x+68,y+ 80,z+ 68, a)
mc.setBlock(x+69,y+ 80,z+ 68, a)
mc.setBlock(x+27,y+ 85,z+ 58, a)
mc.setBlock(x+26,y+ 85,z+ 58, a)
mc.setBlock(x+25,y+ 85,z+ 58, a)
mc.setBlock(x+65,y+ 84,z+ 58, a)
mc.setBlock(x+64,y+ 84,z+ 58, a)
mc.setBlock(x+21,y+ 81,z+ 68, a)
mc.setBlock(x+22,y+ 81,z+ 68, a)
mc.setBlock(x+66,y+ 81,z+ 68, a)
mc.setBlock(x+67,y+ 81,z+ 68, a)
mc.setBlock(x+24,y+ 84,z+ 58, a)
mc.setBlock(x+23,y+ 84,z+ 58, a)
mc.setBlock(x+67,y+ 83,z+ 58, a)
mc.setBlock(x+66,y+ 83,z+ 58, a)
mc.setBlock(x+23,y+ 82,z+ 68, a)
mc.setBlock(x+24,y+ 82,z+ 68, a)
mc.setBlock(x+22,y+ 83,z+ 58, a)
mc.setBlock(x+21,y+ 83,z+ 58, a)
mc.setBlock(x+69,y+ 82,z+ 58, a)
mc.setBlock(x+68,y+ 82,z+ 58, a)
mc.setBlock(x+64,y+ 82,z+ 68, a)
mc.setBlock(x+65,y+ 82,z+ 68, a)
mc.setBlock(x+20,y+ 82,z+ 58, a)
mc.setBlock(x+19,y+ 82,z+ 58, a)
mc.setBlock(x+70,y+ 81,z+ 58, a)
mc.setBlock(x+25,y+ 83,z+ 68, a)
mc.setBlock(x+26,y+ 83,z+ 68, a)
mc.setBlock(x+18,y+ 81,z+ 58, a)
mc.setBlock(x+72,y+ 80,z+ 58, a)
mc.setBlock(x+71,y+ 80,z+ 58, a)
mc.setBlock(x+62,y+ 83,z+ 68, a)
mc.setBlock(x+63,y+ 83,z+ 68, a)
mc.setBlock(x+17,y+ 80,z+ 58, a)
mc.setBlock(x+16,y+ 80,z+ 58, a)
mc.setBlock(x+73,y+ 79,z+ 58, a)
mc.setBlock(x+27,y+ 84,z+ 68, a)
mc.setBlock(x+28,y+ 84,z+ 68, a)
mc.setBlock(x+15,y+ 79,z+ 58, a)
mc.setBlock(x+74,y+ 78,z+ 58, a)
mc.setBlock(x+29,y+ 84,z+ 68, a)
mc.setBlock(x+59,y+ 84,z+ 68, a)
mc.setBlock(x+14,y+ 78,z+ 58, a)
mc.setBlock(x+75,y+ 77,z+ 58, a)
mc.setBlock(x+60,y+ 84,z+ 68, a)
mc.setBlock(x+61,y+ 84,z+ 68, a)
mc.setBlock(x+13,y+ 77,z+ 58, a)
mc.setBlock(x+76,y+ 76,z+ 58, a)
mc.setBlock(x+30,y+ 85,z+ 68, a)
mc.setBlock(x+31,y+ 85,z+ 68, a)
mc.setBlock(x+12,y+ 76,z+ 58, a)
mc.setBlock(x+77,y+ 75,z+ 58, a)
mc.setBlock(x+32,y+ 85,z+ 68, a)
mc.setBlock(x+33,y+ 85,z+ 68, a)
mc.setBlock(x+11,y+ 75,z+ 58, a)
mc.setBlock(x+78,y+ 74,z+ 58, a)
mc.setBlock(x+55,y+ 85,z+ 68, a)
mc.setBlock(x+56,y+ 85,z+ 68, a)
mc.setBlock(x+10,y+ 74,z+ 58, a)
mc.setBlock(x+79,y+ 73,z+ 58, a)
mc.setBlock(x+57,y+ 85,z+ 68, a)
mc.setBlock(x+58,y+ 85,z+ 68, a)
mc.setBlock(x+9,y+ 73,z+ 58, a)
mc.setBlock(x+80,y+ 72,z+ 58, a)
mc.setBlock(x+34,y+ 86,z+ 68, a)
mc.setBlock(x+35,y+ 86,z+ 68, a)
mc.setBlock(x+8,y+ 72,z+ 58, a)
mc.setBlock(x+80,y+ 71,z+ 58, a)
mc.setBlock(x+8,y+ 71,z+ 58, a)
mc.setBlock(x+81,y+ 70,z+ 58, a)
mc.setBlock(x+36,y+ 86,z+ 68, a)
mc.setBlock(x+37,y+ 86,z+ 68, a)
mc.setBlock(x+7,y+ 70,z+ 58, a)
mc.setBlock(x+82,y+ 69,z+ 58, a)
mc.setBlock(x+38,y+ 86,z+ 68, a)
mc.setBlock(x+39,y+ 86,z+ 68, a)
mc.setBlock(x+6,y+ 69,z+ 58, a)
mc.setBlock(x+82,y+ 68,z+ 58, a)
mc.setBlock(x+6,y+ 68,z+ 58, a)
mc.setBlock(x+83,y+ 67,z+ 58, a)
mc.setBlock(x+40,y+ 86,z+ 68, a)
mc.setBlock(x+41,y+ 86,z+ 68, a)
mc.setBlock(x+5,y+ 67,z+ 58, a)
mc.setBlock(x+83,y+ 66,z+ 58, a)
mc.setBlock(x+5,y+ 66,z+ 58, a)
mc.setBlock(x+84,y+ 65,z+ 58, a)
mc.setBlock(x+47,y+ 86,z+ 68, a)
mc.setBlock(x+48,y+ 86,z+ 68, a)
mc.setBlock(x+4,y+ 65,z+ 58, a)
mc.setBlock(x+84,y+ 64,z+ 58, a)
mc.setBlock(x+4,y+ 64,z+ 58, a)
mc.setBlock(x+84,y+ 63,z+ 58, a)
mc.setBlock(x+4,y+ 63,z+ 58, a)
mc.setBlock(x+85,y+ 62,z+ 58, a)
mc.setBlock(x+49,y+ 86,z+ 68, a)
mc.setBlock(x+50,y+ 86,z+ 68, a)
mc.setBlock(x+3,y+ 62,z+ 58, a)
mc.setBlock(x+85,y+ 61,z+ 58, a)
mc.setBlock(x+3,y+ 61,z+ 58, a)
mc.setBlock(x+86,y+ 60,z+ 58, a)
mc.setBlock(x+51,y+ 86,z+ 68, a)
mc.setBlock(x+52,y+ 86,z+ 68, a)
mc.setBlock(x+2,y+ 60,z+ 58, a)
mc.setBlock(x+86,y+ 59,z+ 58, a)
mc.setBlock(x+53,y+ 86,z+ 68, a)
mc.setBlock(x+2,y+ 59,z+ 58, a)
mc.setBlock(x+86,y+ 58,z+ 58, a)
mc.setBlock(x+2,y+ 58,z+ 58, a)
mc.setBlock(x+86,y+ 57,z+ 58, a)
mc.setBlock(x+2,y+ 57,z+ 58, a)
mc.setBlock(x+87,y+ 56,z+ 58, a)
mc.setBlock(x+54,y+ 86,z+ 68, a)
mc.setBlock(x+42,y+ 87,z+ 68, a)
mc.setBlock(x+1,y+ 56,z+ 58, a)
mc.setBlock(x+87,y+ 55,z+ 58, a)
mc.setBlock(x+1,y+ 55,z+ 58, a)
mc.setBlock(x+87,y+ 54,z+ 58, a)
mc.setBlock(x+1,y+ 54,z+ 58, a)
mc.setBlock(x+87,y+ 53,z+ 58, a)
mc.setBlock(x+1,y+ 53,z+ 58, a)
mc.setBlock(x+87,y+ 52,z+ 58, a)
mc.setBlock(x+1,y+ 52,z+ 58, a)
mc.setBlock(x+88,y+ 51,z+ 58, a)
mc.setBlock(x+43,y+ 87,z+ 68, a)
mc.setBlock(x+44,y+ 87,z+ 68, a)
mc.setBlock(x+0,y+ 51,z+ 58, a)
mc.setBlock(x+88,y+ 50,z+ 58, a)
mc.setBlock(x+45,y+ 87,z+ 68, a)
mc.setBlock(x+46,y+ 87,z+ 68, a)
mc.setBlock(x+0,y+ 50,z+ 58, a)
mc.setBlock(x+88,y+ 49,z+ 58, a)
mc.setBlock(x+0,y+ 49,z+ 58, a)
mc.setBlock(x+88,y+ 48,z+ 58, a)
mc.setBlock(x+0,y+ 48,z+ 58, a)
mc.setBlock(x+88,y+ 47,z+ 58, a)
mc.setBlock(x+0,y+ 47,z+ 58, a)
mc.setBlock(x+88,y+ 46,z+ 58, a)
mc.setBlock(x+0,y+ 46,z+ 58, a)
mc.setBlock(x+88,y+ 45,z+ 58, a)
mc.setBlock(x+0,y+ 45,z+ 58, a)
mc.setBlock(x+88,y+ 44,z+ 58, a)
mc.setBlock(x+0,y+ 44,z+ 58, a)
mc.setBlock(x+88,y+ 43,z+ 58, a)
mc.setBlock(x+0,y+ 43,z+ 58, a)
mc.setBlock(x+88,y+ 42,z+ 58, a)
mc.setBlock(x+0,y+ 42,z+ 58, a)
mc.setBlock(x+88,y+ 41,z+ 58, a)
mc.setBlock(x+0,y+ 41,z+ 58, a)
mc.setBlock(x+88,y+ 40,z+ 58, a)
mc.setBlock(x+0,y+ 40,z+ 58, a)
mc.setBlock(x+88,y+ 39,z+ 58, a)
mc.setBlock(x+0,y+ 39,z+ 58, a)
mc.setBlock(x+88,y+ 38,z+ 58, a)
mc.setBlock(x+35,y+ 2,z+ 69, a)
mc.setBlock(x+36,y+ 2,z+ 69, a)
mc.setBlock(x+0,y+ 38,z+ 58, a)
mc.setBlock(x+88,y+ 37,z+ 58, a)
mc.setBlock(x+37,y+ 2,z+ 69, a)
mc.setBlock(x+38,y+ 2,z+ 69, a)
mc.setBlock(x+0,y+ 37,z+ 58, a)
mc.setBlock(x+87,y+ 36,z+ 58, a)
mc.setBlock(x+1,y+ 36,z+ 58, a)
mc.setBlock(x+87,y+ 35,z+ 58, a)
mc.setBlock(x+1,y+ 35,z+ 58, a)
mc.setBlock(x+87,y+ 34,z+ 58, a)
mc.setBlock(x+1,y+ 34,z+ 58, a)
mc.setBlock(x+87,y+ 33,z+ 58, a)
mc.setBlock(x+1,y+ 33,z+ 58, a)
mc.setBlock(x+87,y+ 32,z+ 58, a)
mc.setBlock(x+39,y+ 2,z+ 69, a)
mc.setBlock(x+40,y+ 2,z+ 69, a)
mc.setBlock(x+1,y+ 32,z+ 58, a)
mc.setBlock(x+86,y+ 31,z+ 58, a)
mc.setBlock(x+2,y+ 31,z+ 58, a)
mc.setBlock(x+86,y+ 30,z+ 58, a)
mc.setBlock(x+2,y+ 30,z+ 58, a)
mc.setBlock(x+86,y+ 29,z+ 58, a)
mc.setBlock(x+41,y+ 2,z+ 69, a)
mc.setBlock(x+2,y+ 29,z+ 58, a)
mc.setBlock(x+86,y+ 28,z+ 58, a)
mc.setBlock(x+42,y+ 2,z+ 69, a)
mc.setBlock(x+43,y+ 2,z+ 69, a)
mc.setBlock(x+2,y+ 28,z+ 58, a)
mc.setBlock(x+85,y+ 27,z+ 58, a)
mc.setBlock(x+3,y+ 27,z+ 58, a)
mc.setBlock(x+85,y+ 26,z+ 58, a)
mc.setBlock(x+44,y+ 2,z+ 69, a)
mc.setBlock(x+45,y+ 2,z+ 69, a)
mc.setBlock(x+3,y+ 26,z+ 58, a)
mc.setBlock(x+84,y+ 25,z+ 58, a)
mc.setBlock(x+4,y+ 25,z+ 58, a)
mc.setBlock(x+84,y+ 24,z+ 58, a)
mc.setBlock(x+4,y+ 24,z+ 58, a)
mc.setBlock(x+84,y+ 23,z+ 58, a)
mc.setBlock(x+46,y+ 2,z+ 69, a)
mc.setBlock(x+47,y+ 2,z+ 69, a)
mc.setBlock(x+4,y+ 23,z+ 58, a)
mc.setBlock(x+83,y+ 22,z+ 58, a)
mc.setBlock(x+5,y+ 22,z+ 58, a)
mc.setBlock(x+83,y+ 21,z+ 58, a)
mc.setBlock(x+48,y+ 2,z+ 69, a)
mc.setBlock(x+49,y+ 2,z+ 69, a)
mc.setBlock(x+5,y+ 21,z+ 58, a)
mc.setBlock(x+82,y+ 20,z+ 58, a)
mc.setBlock(x+6,y+ 20,z+ 58, a)
mc.setBlock(x+82,y+ 19,z+ 58, a)
mc.setBlock(x+50,y+ 2,z+ 69, a)
mc.setBlock(x+51,y+ 2,z+ 69, a)
mc.setBlock(x+6,y+ 19,z+ 58, a)
mc.setBlock(x+81,y+ 18,z+ 58, a)
mc.setBlock(x+52,y+ 2,z+ 69, a)
mc.setBlock(x+53,y+ 2,z+ 69, a)
mc.setBlock(x+7,y+ 18,z+ 58, a)
mc.setBlock(x+80,y+ 17,z+ 58, a)
mc.setBlock(x+8,y+ 17,z+ 58, a)
mc.setBlock(x+80,y+ 16,z+ 58, a)
mc.setBlock(x+31,y+ 3,z+ 69, a)
mc.setBlock(x+32,y+ 3,z+ 69, a)
mc.setBlock(x+8,y+ 16,z+ 58, a)
mc.setBlock(x+79,y+ 15,z+ 58, a)
mc.setBlock(x+33,y+ 3,z+ 69, a)
mc.setBlock(x+34,y+ 3,z+ 69, a)
mc.setBlock(x+9,y+ 15,z+ 58, a)
mc.setBlock(x+78,y+ 14,z+ 58, a)
mc.setBlock(x+54,y+ 3,z+ 69, a)
mc.setBlock(x+55,y+ 3,z+ 69, a)
mc.setBlock(x+10,y+ 14,z+ 58, a)
mc.setBlock(x+77,y+ 13,z+ 58, a)
mc.setBlock(x+56,y+ 3,z+ 69, a)
mc.setBlock(x+57,y+ 3,z+ 69, a)
mc.setBlock(x+11,y+ 13,z+ 58, a)
mc.setBlock(x+76,y+ 12,z+ 58, a)
mc.setBlock(x+28,y+ 4,z+ 69, a)
mc.setBlock(x+29,y+ 4,z+ 69, a)
mc.setBlock(x+12,y+ 12,z+ 58, a)
mc.setBlock(x+75,y+ 11,z+ 58, a)
mc.setBlock(x+30,y+ 4,z+ 69, a)
mc.setBlock(x+58,y+ 4,z+ 69, a)
mc.setBlock(x+13,y+ 11,z+ 58, a)
mc.setBlock(x+74,y+ 10,z+ 58, a)
mc.setBlock(x+59,y+ 4,z+ 69, a)
mc.setBlock(x+60,y+ 4,z+ 69, a)
mc.setBlock(x+14,y+ 10,z+ 58, a)
mc.setBlock(x+73,y+ 9,z+ 58, a)
mc.setBlock(x+25,y+ 5,z+ 69, a)
mc.setBlock(x+26,y+ 5,z+ 69, a)
mc.setBlock(x+15,y+ 9,z+ 58, a)
mc.setBlock(x+72,y+ 8,z+ 58, a)
mc.setBlock(x+71,y+ 8,z+ 58, a)
mc.setBlock(x+27,y+ 5,z+ 69, a)
mc.setBlock(x+61,y+ 5,z+ 69, a)
mc.setBlock(x+17,y+ 8,z+ 58, a)
mc.setBlock(x+16,y+ 8,z+ 58, a)
mc.setBlock(x+70,y+ 7,z+ 58, a)
mc.setBlock(x+62,y+ 5,z+ 69, a)
mc.setBlock(x+63,y+ 5,z+ 69, a)
mc.setBlock(x+18,y+ 7,z+ 58, a)
mc.setBlock(x+69,y+ 6,z+ 58, a)
mc.setBlock(x+68,y+ 6,z+ 58, a)
mc.setBlock(x+23,y+ 6,z+ 69, a)
mc.setBlock(x+24,y+ 6,z+ 69, a)
mc.setBlock(x+20,y+ 6,z+ 58, a)
mc.setBlock(x+19,y+ 6,z+ 58, a)
mc.setBlock(x+67,y+ 5,z+ 58, a)
mc.setBlock(x+66,y+ 5,z+ 58, a)
mc.setBlock(x+64,y+ 6,z+ 69, a)
mc.setBlock(x+65,y+ 6,z+ 69, a)
mc.setBlock(x+22,y+ 5,z+ 58, a)
mc.setBlock(x+21,y+ 5,z+ 58, a)
mc.setBlock(x+65,y+ 4,z+ 58, a)
mc.setBlock(x+64,y+ 4,z+ 58, a)
mc.setBlock(x+21,y+ 7,z+ 69, a)
mc.setBlock(x+22,y+ 7,z+ 69, a)
mc.setBlock(x+66,y+ 7,z+ 69, a)
mc.setBlock(x+67,y+ 7,z+ 69, a)
mc.setBlock(x+24,y+ 4,z+ 58, a)
mc.setBlock(x+23,y+ 4,z+ 58, a)
mc.setBlock(x+63,y+ 3,z+ 58, a)
mc.setBlock(x+62,y+ 3,z+ 58, a)
mc.setBlock(x+61,y+ 3,z+ 58, a)
mc.setBlock(x+20,y+ 8,z+ 69, a)
mc.setBlock(x+68,y+ 8,z+ 69, a)
mc.setBlock(x+27,y+ 3,z+ 58, a)
mc.setBlock(x+26,y+ 3,z+ 58, a)
mc.setBlock(x+25,y+ 3,z+ 58, a)
mc.setBlock(x+60,y+ 2,z+ 58, a)
mc.setBlock(x+59,y+ 2,z+ 58, a)
mc.setBlock(x+58,y+ 2,z+ 58, a)
mc.setBlock(x+57,y+ 2,z+ 58, a)
mc.setBlock(x+18,y+ 9,z+ 69, a)
mc.setBlock(x+19,y+ 9,z+ 69, a)
mc.setBlock(x+31,y+ 2,z+ 58, a)
mc.setBlock(x+30,y+ 2,z+ 58, a)
mc.setBlock(x+29,y+ 2,z+ 58, a)
mc.setBlock(x+28,y+ 2,z+ 58, a)
mc.setBlock(x+56,y+ 1,z+ 58, a)
mc.setBlock(x+55,y+ 1,z+ 58, a)
mc.setBlock(x+54,y+ 1,z+ 58, a)
mc.setBlock(x+53,y+ 1,z+ 58, a)
mc.setBlock(x+52,y+ 1,z+ 58, a)
mc.setBlock(x+69,y+ 9,z+ 69, a)
mc.setBlock(x+70,y+ 9,z+ 69, a)
mc.setBlock(x+36,y+ 1,z+ 58, a)
mc.setBlock(x+35,y+ 1,z+ 58, a)
mc.setBlock(x+34,y+ 1,z+ 58, a)
mc.setBlock(x+33,y+ 1,z+ 58, a)
mc.setBlock(x+32,y+ 1,z+ 58, a)
mc.setBlock(x+51,y+ 0,z+ 58, a)
mc.setBlock(x+50,y+ 0,z+ 58, a)
mc.setBlock(x+49,y+ 0,z+ 58, a)
mc.setBlock(x+48,y+ 0,z+ 58, a)
mc.setBlock(x+47,y+ 0,z+ 58, a)
mc.setBlock(x+46,y+ 0,z+ 58, a)
mc.setBlock(x+45,y+ 0,z+ 58, a)
mc.setBlock(x+44,y+ 0,z+ 58, a)
mc.setBlock(x+43,y+ 0,z+ 58, a)
mc.setBlock(x+42,y+ 0,z+ 58, a)
mc.setBlock(x+41,y+ 0,z+ 58, a)
mc.setBlock(x+40,y+ 0,z+ 58, a)
mc.setBlock(x+39,y+ 0,z+ 58, a)
mc.setBlock(x+38,y+ 0,z+ 58, a)
mc.setBlock(x+37,y+ 0,z+ 58, a)
mc.setBlock(x+52,y+ 88,z+ 57, a)
mc.setBlock(x+51,y+ 88,z+ 57, a)
mc.setBlock(x+50,y+ 88,z+ 57, a)
mc.setBlock(x+49,y+ 88,z+ 57, a)
mc.setBlock(x+48,y+ 88,z+ 57, a)
mc.setBlock(x+47,y+ 88,z+ 57, a)
mc.setBlock(x+46,y+ 88,z+ 57, a)
mc.setBlock(x+45,y+ 88,z+ 57, a)
mc.setBlock(x+44,y+ 88,z+ 57, a)
mc.setBlock(x+43,y+ 88,z+ 57, a)
mc.setBlock(x+42,y+ 88,z+ 57, a)
mc.setBlock(x+41,y+ 88,z+ 57, a)
mc.setBlock(x+40,y+ 88,z+ 57, a)
mc.setBlock(x+39,y+ 88,z+ 57, a)
mc.setBlock(x+38,y+ 88,z+ 57, a)
mc.setBlock(x+37,y+ 88,z+ 57, a)
mc.setBlock(x+57,y+ 87,z+ 57, a)
mc.setBlock(x+56,y+ 87,z+ 57, a)
mc.setBlock(x+55,y+ 87,z+ 57, a)
mc.setBlock(x+54,y+ 87,z+ 57, a)
mc.setBlock(x+53,y+ 87,z+ 57, a)
mc.setBlock(x+17,y+ 10,z+ 69, a)
mc.setBlock(x+71,y+ 10,z+ 69, a)
mc.setBlock(x+16,y+ 11,z+ 69, a)
mc.setBlock(x+36,y+ 87,z+ 57, a)
mc.setBlock(x+35,y+ 87,z+ 57, a)
mc.setBlock(x+34,y+ 87,z+ 57, a)
mc.setBlock(x+33,y+ 87,z+ 57, a)
mc.setBlock(x+32,y+ 87,z+ 57, a)
mc.setBlock(x+31,y+ 87,z+ 57, a)
mc.setBlock(x+60,y+ 86,z+ 57, a)
mc.setBlock(x+59,y+ 86,z+ 57, a)
mc.setBlock(x+58,y+ 86,z+ 57, a)
mc.setBlock(x+72,y+ 11,z+ 69, a)
mc.setBlock(x+15,y+ 12,z+ 69, a)
mc.setBlock(x+73,y+ 12,z+ 69, a)
mc.setBlock(x+13,y+ 13,z+ 69, a)
mc.setBlock(x+30,y+ 86,z+ 57, a)
mc.setBlock(x+29,y+ 86,z+ 57, a)
mc.setBlock(x+28,y+ 86,z+ 57, a)
mc.setBlock(x+63,y+ 85,z+ 57, a)
mc.setBlock(x+62,y+ 85,z+ 57, a)
mc.setBlock(x+61,y+ 85,z+ 57, a)
mc.setBlock(x+14,y+ 13,z+ 69, a)
mc.setBlock(x+74,y+ 13,z+ 69, a)
mc.setBlock(x+27,y+ 85,z+ 57, a)
mc.setBlock(x+26,y+ 85,z+ 57, a)
mc.setBlock(x+25,y+ 85,z+ 57, a)
mc.setBlock(x+65,y+ 84,z+ 57, a)
mc.setBlock(x+64,y+ 84,z+ 57, a)
mc.setBlock(x+75,y+ 13,z+ 69, a)
mc.setBlock(x+13,y+ 14,z+ 69, a)
mc.setBlock(x+24,y+ 84,z+ 57, a)
mc.setBlock(x+23,y+ 84,z+ 57, a)
mc.setBlock(x+67,y+ 83,z+ 57, a)
mc.setBlock(x+66,y+ 83,z+ 57, a)
mc.setBlock(x+75,y+ 14,z+ 69, a)
mc.setBlock(x+12,y+ 15,z+ 69, a)
mc.setBlock(x+22,y+ 83,z+ 57, a)
mc.setBlock(x+21,y+ 83,z+ 57, a)
mc.setBlock(x+69,y+ 82,z+ 57, a)
mc.setBlock(x+68,y+ 82,z+ 57, a)
mc.setBlock(x+76,y+ 15,z+ 69, a)
mc.setBlock(x+11,y+ 16,z+ 69, a)
mc.setBlock(x+20,y+ 82,z+ 57, a)
mc.setBlock(x+19,y+ 82,z+ 57, a)
mc.setBlock(x+70,y+ 81,z+ 57, a)
mc.setBlock(x+77,y+ 16,z+ 69, a)
mc.setBlock(x+10,y+ 17,z+ 69, a)
mc.setBlock(x+18,y+ 81,z+ 57, a)
mc.setBlock(x+72,y+ 80,z+ 57, a)
mc.setBlock(x+71,y+ 80,z+ 57, a)
mc.setBlock(x+78,y+ 17,z+ 69, a)
mc.setBlock(x+9,y+ 18,z+ 69, a)
mc.setBlock(x+17,y+ 80,z+ 57, a)
mc.setBlock(x+16,y+ 80,z+ 57, a)
mc.setBlock(x+73,y+ 79,z+ 57, a)
mc.setBlock(x+79,y+ 18,z+ 69, a)
mc.setBlock(x+9,y+ 19,z+ 69, a)
mc.setBlock(x+15,y+ 79,z+ 57, a)
mc.setBlock(x+74,y+ 78,z+ 57, a)
mc.setBlock(x+79,y+ 19,z+ 69, a)
mc.setBlock(x+8,y+ 20,z+ 69, a)
mc.setBlock(x+14,y+ 78,z+ 57, a)
mc.setBlock(x+75,y+ 77,z+ 57, a)
mc.setBlock(x+80,y+ 20,z+ 69, a)
mc.setBlock(x+8,y+ 21,z+ 69, a)
mc.setBlock(x+13,y+ 77,z+ 57, a)
mc.setBlock(x+76,y+ 76,z+ 57, a)
mc.setBlock(x+80,y+ 21,z+ 69, a)
mc.setBlock(x+7,y+ 22,z+ 69, a)
mc.setBlock(x+12,y+ 76,z+ 57, a)
mc.setBlock(x+77,y+ 75,z+ 57, a)
mc.setBlock(x+81,y+ 22,z+ 69, a)
mc.setBlock(x+7,y+ 23,z+ 69, a)
mc.setBlock(x+11,y+ 75,z+ 57, a)
mc.setBlock(x+78,y+ 74,z+ 57, a)
mc.setBlock(x+81,y+ 23,z+ 69, a)
mc.setBlock(x+6,y+ 24,z+ 69, a)
mc.setBlock(x+10,y+ 74,z+ 57, a)
mc.setBlock(x+79,y+ 73,z+ 57, a)
mc.setBlock(x+82,y+ 24,z+ 69, a)
mc.setBlock(x+6,y+ 25,z+ 69, a)
mc.setBlock(x+9,y+ 73,z+ 57, a)
mc.setBlock(x+80,y+ 72,z+ 57, a)
mc.setBlock(x+82,y+ 25,z+ 69, a)
mc.setBlock(x+5,y+ 26,z+ 69, a)
mc.setBlock(x+8,y+ 72,z+ 57, a)
mc.setBlock(x+80,y+ 71,z+ 57, a)
mc.setBlock(x+8,y+ 71,z+ 57, a)
mc.setBlock(x+81,y+ 70,z+ 57, a)
mc.setBlock(x+83,y+ 26,z+ 69, a)
mc.setBlock(x+5,y+ 27,z+ 69, a)
mc.setBlock(x+7,y+ 70,z+ 57, a)
mc.setBlock(x+82,y+ 69,z+ 57, a)
mc.setBlock(x+83,y+ 27,z+ 69, a)
mc.setBlock(x+5,y+ 28,z+ 69, a)
mc.setBlock(x+6,y+ 69,z+ 57, a)
mc.setBlock(x+82,y+ 68,z+ 57, a)
mc.setBlock(x+6,y+ 68,z+ 57, a)
mc.setBlock(x+83,y+ 67,z+ 57, a)
mc.setBlock(x+83,y+ 28,z+ 69, a)
mc.setBlock(x+4,y+ 29,z+ 69, a)
mc.setBlock(x+5,y+ 67,z+ 57, a)
mc.setBlock(x+83,y+ 66,z+ 57, a)
mc.setBlock(x+5,y+ 66,z+ 57, a)
mc.setBlock(x+84,y+ 65,z+ 57, a)
mc.setBlock(x+84,y+ 29,z+ 69, a)
mc.setBlock(x+4,y+ 30,z+ 69, a)
mc.setBlock(x+4,y+ 65,z+ 57, a)
mc.setBlock(x+84,y+ 64,z+ 57, a)
mc.setBlock(x+4,y+ 64,z+ 57, a)
mc.setBlock(x+85,y+ 63,z+ 57, a)
mc.setBlock(x+84,y+ 30,z+ 69, a)
mc.setBlock(x+4,y+ 31,z+ 69, a)
mc.setBlock(x+3,y+ 63,z+ 57, a)
mc.setBlock(x+85,y+ 62,z+ 57, a)
mc.setBlock(x+3,y+ 62,z+ 57, a)
mc.setBlock(x+85,y+ 61,z+ 57, a)
mc.setBlock(x+3,y+ 61,z+ 57, a)
mc.setBlock(x+86,y+ 60,z+ 57, a)
mc.setBlock(x+84,y+ 31,z+ 69, a)
mc.setBlock(x+3,y+ 32,z+ 69, a)
mc.setBlock(x+2,y+ 60,z+ 57, a)
mc.setBlock(x+86,y+ 59,z+ 57, a)
mc.setBlock(x+2,y+ 59,z+ 57, a)
mc.setBlock(x+86,y+ 58,z+ 57, a)
mc.setBlock(x+2,y+ 58,z+ 57, a)
mc.setBlock(x+86,y+ 57,z+ 57, a)
mc.setBlock(x+2,y+ 57,z+ 57, a)
mc.setBlock(x+87,y+ 56,z+ 57, a)
mc.setBlock(x+85,y+ 32,z+ 69, a)
mc.setBlock(x+3,y+ 33,z+ 69, a)
mc.setBlock(x+1,y+ 56,z+ 57, a)
mc.setBlock(x+87,y+ 55,z+ 57, a)
mc.setBlock(x+1,y+ 55,z+ 57, a)
mc.setBlock(x+87,y+ 54,z+ 57, a)
mc.setBlock(x+1,y+ 54,z+ 57, a)
mc.setBlock(x+87,y+ 53,z+ 57, a)
mc.setBlock(x+1,y+ 53,z+ 57, a)
mc.setBlock(x+87,y+ 52,z+ 57, a)
mc.setBlock(x+1,y+ 52,z+ 57, a)
mc.setBlock(x+88,y+ 51,z+ 57, a)
mc.setBlock(x+85,y+ 33,z+ 69, a)
mc.setBlock(x+3,y+ 34,z+ 69, a)
mc.setBlock(x+0,y+ 51,z+ 57, a)
mc.setBlock(x+88,y+ 50,z+ 57, a)
mc.setBlock(x+0,y+ 50,z+ 57, a)
mc.setBlock(x+88,y+ 49,z+ 57, a)
mc.setBlock(x+0,y+ 49,z+ 57, a)
mc.setBlock(x+88,y+ 48,z+ 57, a)
mc.setBlock(x+0,y+ 48,z+ 57, a)
mc.setBlock(x+88,y+ 47,z+ 57, a)
mc.setBlock(x+0,y+ 47,z+ 57, a)
mc.setBlock(x+88,y+ 46,z+ 57, a)
mc.setBlock(x+0,y+ 46,z+ 57, a)
mc.setBlock(x+88,y+ 45,z+ 57, a)
mc.setBlock(x+0,y+ 45,z+ 57, a)
mc.setBlock(x+88,y+ 44,z+ 57, a)
mc.setBlock(x+0,y+ 44,z+ 57, a)
mc.setBlock(x+88,y+ 43,z+ 57, a)
mc.setBlock(x+0,y+ 43,z+ 57, a)
mc.setBlock(x+88,y+ 42,z+ 57, a)
mc.setBlock(x+0,y+ 42,z+ 57, a)
mc.setBlock(x+88,y+ 41,z+ 57, a)
mc.setBlock(x+0,y+ 41,z+ 57, a)
mc.setBlock(x+88,y+ 40,z+ 57, a)
mc.setBlock(x+0,y+ 40,z+ 57, a)
mc.setBlock(x+88,y+ 39,z+ 57, a)
mc.setBlock(x+0,y+ 39,z+ 57, a)
mc.setBlock(x+88,y+ 38,z+ 57, a)
mc.setBlock(x+0,y+ 38,z+ 57, a)
mc.setBlock(x+88,y+ 37,z+ 57, a)
mc.setBlock(x+85,y+ 34,z+ 69, a)
mc.setBlock(x+3,y+ 35,z+ 69, a)
mc.setBlock(x+0,y+ 37,z+ 57, a)
mc.setBlock(x+87,y+ 36,z+ 57, a)
mc.setBlock(x+1,y+ 36,z+ 57, a)
mc.setBlock(x+87,y+ 35,z+ 57, a)
mc.setBlock(x+1,y+ 35,z+ 57, a)
mc.setBlock(x+87,y+ 34,z+ 57, a)
mc.setBlock(x+1,y+ 34,z+ 57, a)
mc.setBlock(x+87,y+ 33,z+ 57, a)
mc.setBlock(x+1,y+ 33,z+ 57, a)
mc.setBlock(x+87,y+ 32,z+ 57, a)
mc.setBlock(x+85,y+ 35,z+ 69, a)
mc.setBlock(x+3,y+ 36,z+ 69, a)
mc.setBlock(x+1,y+ 32,z+ 57, a)
mc.setBlock(x+86,y+ 31,z+ 57, a)
mc.setBlock(x+2,y+ 31,z+ 57, a)
mc.setBlock(x+86,y+ 30,z+ 57, a)
mc.setBlock(x+2,y+ 30,z+ 57, a)
mc.setBlock(x+86,y+ 29,z+ 57, a)
mc.setBlock(x+2,y+ 29,z+ 57, a)
mc.setBlock(x+86,y+ 28,z+ 57, a)
mc.setBlock(x+85,y+ 36,z+ 69, a)
mc.setBlock(x+2,y+ 37,z+ 69, a)
mc.setBlock(x+2,y+ 28,z+ 57, a)
mc.setBlock(x+85,y+ 27,z+ 57, a)
mc.setBlock(x+3,y+ 27,z+ 57, a)
mc.setBlock(x+85,y+ 26,z+ 57, a)
mc.setBlock(x+3,y+ 26,z+ 57, a)
mc.setBlock(x+85,y+ 25,z+ 57, a)
mc.setBlock(x+86,y+ 37,z+ 69, a)
mc.setBlock(x+2,y+ 38,z+ 69, a)
mc.setBlock(x+3,y+ 25,z+ 57, a)
mc.setBlock(x+84,y+ 24,z+ 57, a)
mc.setBlock(x+4,y+ 24,z+ 57, a)
mc.setBlock(x+84,y+ 23,z+ 57, a)
mc.setBlock(x+86,y+ 38,z+ 69, a)
mc.setBlock(x+2,y+ 39,z+ 69, a)
mc.setBlock(x+4,y+ 23,z+ 57, a)
mc.setBlock(x+83,y+ 22,z+ 57, a)
mc.setBlock(x+5,y+ 22,z+ 57, a)
mc.setBlock(x+83,y+ 21,z+ 57, a)
mc.setBlock(x+86,y+ 39,z+ 69, a)
